{
    "registryname": "YMG_Bee_Gardenx",
    "localizedname": "§b§lYMG§r§e§l—§f§l盈蜂翠庭 §r§e",
    "failure-action": "still",
    "requires-blueprint": false,
    "has-factory": true,
    "factory-only": true,
    "color": "FFFFFF",
    "parts": [
        {
            "x": 5,
            "y": 0,
            "z": 8,
            "elements": [
                "minecraft:stained_glass@0"
            ]
        },
        {
            "x": 5,
            "y": 0,
            "z": 9,
            "elements": [
                "minecraft:stained_glass@0"
            ]
        },
        {
            "x": 5,
            "y": 0,
            "z": 6,
            "elements": [
                "minecraft:stained_glass@0"
            ]
        },
        {
            "x": 2,
            "y": 3,
            "z": 1,
            "elements": [
                "botania:quartzstairssunny@5"
            ]
        },
        {
            "x": 5,
            "y": 0,
            "z": 7,
            "elements": [
                "minecraft:stained_glass@0"
            ]
        },
        {
            "x": 5,
            "y": 0,
            "z": 4,
            "elements": [
                "minecraft:stained_glass@0"
            ]
        },
        {
            "x": 5,
            "y": 0,
            "z": 5,
            "elements": [
                "minecraft:stained_glass@0"
            ]
        },
        {
            "x": 5,
            "y": 0,
            "z": 2,
            "elements": [
                "minecraft:stained_glass@0"
            ]
        },
        {
            "x": 5,
            "y": 0,
            "z": 3,
            "elements": [
                "minecraft:stained_glass@0"
            ]
        },
        {
            "x": 2,
            "y": 3,
            "z": 6,
            "elements": [
                "minecraft:stained_glass@0"
            ]
        },
        {
            "x": 3,
            "y": 4,
            "z": 10,
            "elements": [
                "botania:quartztypesunny@0"
            ]
        },
        {
            "x": 3,
            "y": 4,
            "z": 11,
            "elements": [
                "botania:quartztypesunny@0"
            ]
        },
        {
            "x": 2,
            "y": 3,
            "z": 7,
            "elements": [
                "minecraft:stained_glass@0"
            ]
        },
        {
            "x": 5,
            "y": 0,
            "z": 1,
            "elements": [
                "botania:livingrock0wall@0"
            ]
        },
        {
            "x": 3,
            "y": 4,
            "z": 8,
            "elements": [
                "botania:quartztypesunny@0"
            ]
        },
        {
            "x": 2,
            "y": 3,
            "z": 8,
            "elements": [
                "minecraft:stained_glass@0"
            ]
        },
        {
            "x": 2,
            "y": 3,
            "z": 9,
            "elements": [
                "minecraft:stained_glass@0"
            ]
        },
        {
            "x": 3,
            "y": 4,
            "z": 9,
            "elements": [
                "botania:quartztypesunny@0"
            ]
        },
        {
            "x": 2,
            "y": 3,
            "z": 2,
            "elements": [
                "minecraft:stained_glass@0"
            ]
        },
        {
            "x": 2,
            "y": 3,
            "z": 3,
            "elements": [
                "minecraft:stained_glass@0"
            ]
        },
        {
            "x": 2,
            "y": 3,
            "z": 4,
            "elements": [
                "minecraft:stained_glass@0"
            ]
        },
        {
            "x": 2,
            "y": 3,
            "z": 5,
            "elements": [
                "minecraft:stained_glass@0"
            ]
        },
        {
            "x": 3,
            "y": 4,
            "z": 2,
            "elements": [
                "botania:quartztypesunny@0"
            ]
        },
        {
            "x": 3,
            "y": 4,
            "z": 3,
            "elements": [
                "botania:quartztypesunny@0"
            ]
        },
        {
            "x": 3,
            "y": 4,
            "z": 1,
            "elements": [
                "botania:quartztypesunny@0"
            ]
        },
        {
            "x": 3,
            "y": 4,
            "z": 6,
            "elements": [
                "botania:quartztypesunny@0"
            ]
        },
        {
            "x": 3,
            "y": 4,
            "z": 7,
            "elements": [
                "botania:quartztypesunny@0"
            ]
        },
        {
            "x": 3,
            "y": 4,
            "z": 4,
            "elements": [
                "botania:quartztypesunny@0"
            ]
        },
        {
            "x": 3,
            "y": 4,
            "z": 5,
            "elements": [
                "botania:quartztypesunny@0"
            ]
        },
        {
            "x": 0,
            "y": 0,
            "z": 11,
            "elements": [
                "botania:quartztypesunny@1"
            ]
        },
        {
            "x": 3,
            "y": -2,
            "z": 1,

            "elements": [
                "modularmachinery:blockcasing@0",
                "Upgrade"
            ]
        },
        {
            "x": 1,
            "y": 2,
            "z": 11,
            "elements": [
                "minecraft:birch_fence@0"
            ]
        },
        {
            "x": 3,
            "y": -2,
            "z": 0,
            "elements": [
                "minecraft:quartz_stairs@2"
            ]
        },
        {
            "x": 1,
            "y": 2,
            "z": 10,
            "elements": [
                "minecraft:stained_glass@0"
            ]
        },
        {
            "x": 1,
            "y": 2,
            "z": 9,
            "elements": [
                "minecraft:stained_glass@0"
            ]
        },
        {
            "x": 1,
            "y": 2,
            "z": 8,
            "elements": [
                "minecraft:stained_glass@0"
            ]
        },
        {
            "x": 0,
            "y": 0,
            "z": 0,

            "elements": [
                "modularmachinery:blockcontroller@2"
            ]
        },
        {
            "x": 1,
            "y": 2,
            "z": 7,
            "elements": [
                "minecraft:stained_glass@0"
            ]
        },
        {
            "x": 3,
            "y": -2,
            "z": 5,
            "elements": [
                "minecraft:grass@0"
            ]
        },
        {
            "x": 3,
            "y": -2,
            "z": 4,
            "elements": [
                "minecraft:grass@0"
            ]
        },
        {
            "x": 1,
            "y": 2,
            "z": 6,
            "elements": [
                "minecraft:stained_glass@0"
            ]
        },
        {
            "x": 3,
            "y": -2,
            "z": 3,
            "elements": [
                "minecraft:grass@0"
            ]
        },
        {
            "x": 1,
            "y": 2,
            "z": 5,
            "elements": [
                "minecraft:stained_glass@0"
            ]
        },
        {
            "x": 1,
            "y": 2,
            "z": 4,
            "elements": [
                "minecraft:stained_glass@0"
            ]
        },
        {
            "x": 3,
            "y": -2,
            "z": 2,
            "elements": [
                "chisel:waterstone1@14"
            ]
        },
        {
            "x": 0,
            "y": 0,
            "z": 1,
            "elements": [
                "botania:quartztypesunny@1"
            ]
        },
        {
            "x": 3,
            "y": -2,
            "z": 9,
            "elements": [
                "minecraft:dirt@0"
            ]
        },
        {
            "x": 1,
            "y": 2,
            "z": 3,
            "elements": [
                "minecraft:stained_glass@0"
            ]
        },
        {
            "x": 3,
            "y": -2,
            "z": 8,
            "elements": [
                "minecraft:grass@0"
            ]
        },
        {
            "x": 1,
            "y": 2,
            "z": 2,
            "elements": [
                "minecraft:stained_glass@0"
            ]
        },
        {
            "x": 1,
            "y": 2,
            "z": 1,
            "elements": [
                "minecraft:birch_fence@0"
            ]
        },
        {
            "x": 3,
            "y": -2,
            "z": 7,
            "elements": [
                "minecraft:grass@0"
            ]
        },
        {
            "x": 3,
            "y": -2,
            "z": 6,
            "elements": [
                "minecraft:grass@0"
            ]
        },
        {
            "x": 3,
            "y": -2,
            "z": 11,
            "elements": [
                "minecraft:quartz_block@0"
            ]
        },
        {
            "x": 3,
            "y": -2,
            "z": 10,
            "elements": [
                "chisel:waterstone1@14"
            ]
        },
        {
            "x": 5,
            "y": 0,
            "z": 10,
            "elements": [
                "minecraft:stained_glass@0"
            ]
        },
        {
            "x": 5,
            "y": 0,
            "z": 11,
            "elements": [
                "botania:livingrock0wall@0"
            ]
        },
        {
            "x": 4,
            "y": -2,
            "z": 1,

            "elements": [
                "modularmachinery:blockcasing@0",
                "Upgrade"
            ]
        },
        {
            "x": 4,
            "y": -2,
            "z": 2,
            "elements": [
                "chisel:waterstone1@14"
            ]
        },
        {
            "x": 4,
            "y": -2,
            "z": 3,
            "elements": [
                "minecraft:grass@0"
            ]
        },
        {
            "x": 4,
            "y": -2,
            "z": 4,
            "elements": [
                "minecraft:grass@0"
            ]
        },
        {
            "x": 4,
            "y": -2,
            "z": 0,
            "elements": [
                "minecraft:quartz_stairs@2"
            ]
        },
        {
            "x": 1,
            "y": 1,
            "z": 4,
            "elements": [
                "minecraft:stained_glass@0"
            ]
        },
        {
            "x": 1,
            "y": 1,
            "z": 3,
            "elements": [
                "minecraft:stained_glass@0"
            ]
        },
        {
            "x": 1,
            "y": 1,
            "z": 2,
            "elements": [
                "minecraft:stained_glass@0"
            ]
        },
        {
            "x": 1,
            "y": 1,
            "z": 1,
            "elements": [
                "minecraft:end_rod@0"
            ]
        },
        {
            "x": 5,
            "y": -1,
            "z": 5,
            "elements": [
                "minecraft:stained_glass@0"
            ]
        },
        {
            "x": 1,
            "y": 1,
            "z": 8,
            "elements": [
                "minecraft:stained_glass@0"
            ]
        },
        {
            "x": 5,
            "y": -1,
            "z": 6,
            "elements": [
                "minecraft:stained_glass@0"
            ]
        },
        {
            "x": 1,
            "y": 1,
            "z": 7,
            "elements": [
                "minecraft:stained_glass@0"
            ]
        },
        {
            "x": 1,
            "y": 1,
            "z": 6,
            "elements": [
                "minecraft:stained_glass@0"
            ]
        },
        {
            "x": 5,
            "y": -1,
            "z": 3,
            "elements": [
                "minecraft:stained_glass@0"
            ]
        },
        {
            "x": 1,
            "y": 1,
            "z": 5,
            "elements": [
                "minecraft:stained_glass@0"
            ]
        },
        {
            "x": 5,
            "y": -1,
            "z": 4,
            "elements": [
                "minecraft:stained_glass@0"
            ]
        },
        {
            "x": 5,
            "y": -1,
            "z": 9,
            "elements": [
                "minecraft:stained_glass@0"
            ]
        },
        {
            "x": 1,
            "y": 1,
            "z": 11,
            "elements": [
                "minecraft:end_rod@0"
            ]
        },
        {
            "x": 5,
            "y": -1,
            "z": 10,
            "elements": [
                "minecraft:stained_glass@0"
            ]
        },
        {
            "x": 1,
            "y": 1,
            "z": 10,
            "elements": [
                "minecraft:stained_glass@0"
            ]
        },
        {
            "x": 5,
            "y": -1,
            "z": 7,
            "elements": [
                "minecraft:stained_glass@0"
            ]
        },
        {
            "x": 5,
            "y": -1,
            "z": 8,
            "elements": [
                "minecraft:stained_glass@0"
            ]
        },
        {
            "x": 1,
            "y": 1,
            "z": 9,
            "elements": [
                "minecraft:stained_glass@0"
            ]
        },
        {
            "x": 4,
            "y": -2,
            "z": 9,
            "elements": [
                "minecraft:dirt@0"
            ]
        },
        {
            "x": 4,
            "y": -2,
            "z": 10,
            "elements": [
                "chisel:waterstone1@14"
            ]
        },
        {
            "x": 5,
            "y": -1,
            "z": 11,
            "elements": [
                "botania:quartzstairssunny@0"
            ]
        },
        {
            "x": 4,
            "y": -2,
            "z": 11,
            "elements": [
                "minecraft:quartz_block@0"
            ]
        },
        {
            "x": 4,
            "y": 0,
            "z": 2,
            "elements": [
                "minecraft:stained_glass@0"
            ]
        },
        {
            "x": 4,
            "y": -2,
            "z": 5,
            "elements": [
                "minecraft:dirt@0"
            ]
        },
        {
            "x": 4,
            "y": -2,
            "z": 6,
            "elements": [
                "minecraft:grass@0"
            ]
        },
        {
            "x": 4,
            "y": -2,
            "z": 7,
            "elements": [
                "minecraft:grass@0"
            ]
        },
        {
            "x": 4,
            "y": -2,
            "z": 8,
            "elements": [
                "minecraft:grass@0"
            ]
        },
        {
            "x": 6,
            "y": 1,
            "z": 3,
            "elements": [
                "botania:quartzslabsunnyhalf@8"
            ]
        },
        {
            "x": 6,
            "y": 1,
            "z": 2,
            "elements": [
                "botania:quartzstairssunny@7"
            ]
        },
        {
            "x": 6,
            "y": 1,
            "z": 1,
            "elements": [
                "botania:quartztypesunny@1"
            ]
        },
        {
            "x": 5,
            "y": -1,
            "z": 1,
            "elements": [
                "botania:quartzstairssunny@0"
            ]
        },
        {
            "x": 6,
            "y": 1,
            "z": 7,
            "elements": [
                "botania:quartzslabsunnyhalf@8"
            ]
        },
        {
            "x": 5,
            "y": -1,
            "z": 2,
            "elements": [
                "minecraft:stained_glass@0"
            ]
        },
        {
            "x": 6,
            "y": 1,
            "z": 6,
            "elements": [
                "botania:quartzslabsunnyhalf@8"
            ]
        },
        {
            "x": 6,
            "y": 1,
            "z": 5,
            "elements": [
                "botania:quartzslabsunnyhalf@8"
            ]
        },
        {
            "x": 6,
            "y": 1,
            "z": 4,
            "elements": [
                "botania:quartzslabsunnyhalf@8"
            ]
        },
        {
            "x": 6,
            "y": 1,
            "z": 11,
            "elements": [
                "botania:quartztypesunny@1"
            ]
        },
        {
            "x": 6,
            "y": 1,
            "z": 10,
            "elements": [
                "botania:quartzstairssunny@6"
            ]
        },
        {
            "x": 6,
            "y": 1,
            "z": 9,
            "elements": [
                "botania:quartzslabsunnyhalf@8"
            ]
        },
        {
            "x": 6,
            "y": 1,
            "z": 8,
            "elements": [
                "botania:quartzslabsunnyhalf@8"
            ]
        },
        {
            "x": 2,
            "y": 3,
            "z": 10,
            "elements": [
                "minecraft:stained_glass@0"
            ]
        },
        {
            "x": 2,
            "y": 3,
            "z": 11,
            "elements": [
                "botania:quartzstairssunny@5"
            ]
        },
        {
            "x": 1,
            "y": 0,
            "z": 5,
            "elements": [
                "minecraft:stained_glass@0"
            ]
        },
        {
            "x": 1,
            "y": 0,
            "z": 4,
            "elements": [
                "minecraft:stained_glass@0"
            ]
        },
        {
            "x": 1,
            "y": 0,
            "z": 3,
            "elements": [
                "minecraft:stained_glass@0"
            ]
        },
        {
            "x": 1,
            "y": 0,
            "z": 2,
            "elements": [
                "minecraft:stained_glass@0"
            ]
        },
        {
            "x": 1,
            "y": 0,
            "z": 1,
            "elements": [
                "botania:livingrock0wall@0"
            ]
        },
        {
            "x": 1,
            "y": 0,
            "z": 11,
            "elements": [
                "botania:livingrock0wall@0"
            ]
        },
        {
            "x": 3,
            "y": -1,
            "z": 9,

            "elements": [
                "harvestcraft:apiary@2"
            ]
        },
        {
            "x": 1,
            "y": 0,
            "z": 10,
            "elements": [
                "minecraft:stained_glass@0"
            ]
        },
        {
            "x": 3,
            "y": -1,
            "z": 10,
            "elements": [
                "minecraft:stained_glass@0"
            ]
        },
        {
            "x": 1,
            "y": 0,
            "z": 9,
            "elements": [
                "minecraft:stained_glass@0"
            ]
        },
        {
            "x": 1,
            "y": 0,
            "z": 8,
            "elements": [
                "minecraft:stained_glass@0"
            ]
        },
        {
            "x": 1,
            "y": 0,
            "z": 7,
            "elements": [
                "minecraft:stained_glass@0"
            ]
        },
        {
            "x": 1,
            "y": 0,
            "z": 6,
            "elements": [
                "minecraft:stained_glass@0"
            ]
        },
        {
            "x": 1,
            "y": 3,
            "z": 11,
            "elements": [
                "botania:quartzstairssunny@0"
            ]
        },
        {
            "x": 3,
            "y": -1,
            "z": 2,
            "elements": [
                "minecraft:stained_glass@0"
            ]
        },
        {
            "x": 1,
            "y": 3,
            "z": 5,
            "elements": [
                "botania:quartzstairssunny@0"
            ]
        },
        {
            "x": 1,
            "y": 3,
            "z": 6,
            "elements": [
                "botania:quartzstairssunny@0"
            ]
        },
        {
            "x": 1,
            "y": 3,
            "z": 3,
            "elements": [
                "botania:quartzstairssunny@0"
            ]
        },
        {
            "x": 1,
            "y": 3,
            "z": 4,
            "elements": [
                "botania:quartzstairssunny@0"
            ]
        },
        {
            "x": 1,
            "y": 3,
            "z": 9,
            "elements": [
                "botania:quartzstairssunny@0"
            ]
        },
        {
            "x": 1,
            "y": 3,
            "z": 10,
            "elements": [
                "botania:quartzstairssunny@0"
            ]
        },
        {
            "x": 1,
            "y": 3,
            "z": 7,
            "elements": [
                "botania:quartzstairssunny@0"
            ]
        },
        {
            "x": 1,
            "y": 3,
            "z": 8,
            "elements": [
                "botania:quartzstairssunny@0"
            ]
        },
        {
            "x": 4,
            "y": 0,
            "z": 9,

            "elements": [
                "harvestcraft:apiary@2"
            ]
        },
        {
            "x": 4,
            "y": 0,
            "z": 10,
            "elements": [
                "minecraft:stained_glass@0"
            ]
        },
        {
            "x": 1,
            "y": 3,
            "z": 1,
            "elements": [
                "botania:quartzstairssunny@0"
            ]
        },
        {
            "x": 1,
            "y": 3,
            "z": 2,
            "elements": [
                "botania:quartzstairssunny@0"
            ]
        },
        {
            "x": 4,
            "y": 1,
            "z": 2,
            "elements": [
                "minecraft:stained_glass@0"
            ]
        },
        {
            "x": 6,
            "y": -1,
            "z": 11,
            "elements": [
                "botania:quartztypesunny@1"
            ]
        },
        {
            "x": 6,
            "y": -1,
            "z": 10,
            "elements": [
                "botania:quartzstairssunny@2"
            ]
        },
        {
            "x": 4,
            "y": 4,
            "z": 2,
            "elements": [
                "botania:quartzslabsunnyhalf@0"
            ]
        },
        {
            "x": 4,
            "y": 4,
            "z": 1,
            "elements": [
                "botania:quartzstairssunny@1"
            ]
        },
        {
            "x": 4,
            "y": 4,
            "z": 6,
            "elements": [
                "botania:quartzslabsunnyhalf@0"
            ]
        },
        {
            "x": 4,
            "y": 4,
            "z": 5,
            "elements": [
                "botania:quartzslabsunnyhalf@0"
            ]
        },
        {
            "x": 4,
            "y": 4,
            "z": 4,
            "elements": [
                "botania:quartzslabsunnyhalf@0"
            ]
        },
        {
            "x": 4,
            "y": 4,
            "z": 3,
            "elements": [
                "botania:quartzslabsunnyhalf@0"
            ]
        },
        {
            "x": 2,
            "y": 2,
            "z": 2,
            "elements": [
                "minecraft:stained_glass@0"
            ]
        },
        {
            "x": 4,
            "y": 4,
            "z": 10,
            "elements": [
                "botania:quartzslabsunnyhalf@0"
            ]
        },
        {
            "x": 4,
            "y": 4,
            "z": 9,
            "elements": [
                "botania:quartzslabsunnyhalf@0"
            ]
        },
        {
            "x": 4,
            "y": 4,
            "z": 8,
            "elements": [
                "botania:quartzslabsunnyhalf@0"
            ]
        },
        {
            "x": 4,
            "y": 4,
            "z": 7,
            "elements": [
                "botania:quartzslabsunnyhalf@0"
            ]
        },
        {
            "x": 4,
            "y": 4,
            "z": 11,
            "elements": [
                "botania:quartzstairssunny@1"
            ]
        },
        {
            "x": 0,
            "y": -2,
            "z": 0,

            "elements": [
                "ItemOutput"
            ]
        },
        {
            "x": 6,
            "y": 2,
            "z": 11,
            "elements": [
                "botania:quartzstairssunny@1"
            ]
        },
        {
            "x": 6,
            "y": 2,
            "z": 10,
            "elements": [
                "botania:quartzslabsunnyhalf@0"
            ]
        },
        {
            "x": 6,
            "y": 2,
            "z": 9,
            "elements": [
                "botania:quartzslabsunnyhalf@0"
            ]
        },
        {
            "x": 6,
            "y": 2,
            "z": 8,
            "elements": [
                "botania:quartzslabsunnyhalf@0"
            ]
        },
        {
            "x": 6,
            "y": 2,
            "z": 7,
            "elements": [
                "botania:quartzslabsunnyhalf@0"
            ]
        },
        {
            "x": 0,
            "y": -2,
            "z": 6,
            "elements": [
                "minecraft:quartz_block@0"
            ]
        },
        {
            "x": 6,
            "y": 2,
            "z": 6,
            "elements": [
                "botania:quartzslabsunnyhalf@0"
            ]
        },
        {
            "x": 6,
            "y": 2,
            "z": 5,
            "elements": [
                "botania:quartzslabsunnyhalf@0"
            ]
        },
        {
            "x": 0,
            "y": -2,
            "z": 5,
            "elements": [
                "minecraft:quartz_block@0"
            ]
        },
        {
            "x": 6,
            "y": 2,
            "z": 4,
            "elements": [
                "botania:quartzslabsunnyhalf@0"
            ]
        },
        {
            "x": 0,
            "y": -2,
            "z": 8,
            "elements": [
                "minecraft:quartz_block@0"
            ]
        },
        {
            "x": 0,
            "y": -2,
            "z": 7,
            "elements": [
                "minecraft:quartz_block@0"
            ]
        },
        {
            "x": 6,
            "y": 2,
            "z": 3,
            "elements": [
                "botania:quartzslabsunnyhalf@0"
            ]
        },
        {
            "x": 0,
            "y": -2,
            "z": 2,
            "elements": [
                "minecraft:quartz_block@0"
            ]
        },
        {
            "x": 6,
            "y": 2,
            "z": 2,
            "elements": [
                "botania:quartzslabsunnyhalf@0"
            ]
        },
        {
            "x": 0,
            "y": -2,
            "z": 1,
            "elements": [
                "minecraft:quartz_block@0"
            ]
        },
        {
            "x": 6,
            "y": 2,
            "z": 1,
            "elements": [
                "botania:quartzstairssunny@1"
            ]
        },
        {
            "x": 0,
            "y": -2,
            "z": 4,
            "elements": [
                "minecraft:quartz_block@0"
            ]
        },
        {
            "x": 0,
            "y": -2,
            "z": 3,
            "elements": [
                "minecraft:quartz_block@0"
            ]
        },
        {
            "x": 2,
            "y": 2,
            "z": 10,
            "elements": [
                "minecraft:stained_glass@0"
            ]
        },
        {
            "x": 2,
            "y": -1,
            "z": 3,
            "elements": [
                "minecraft:reeds@0"
            ]
        },
        {
            "x": 2,
            "y": -1,
            "z": 2,
            "elements": [
                "minecraft:stained_glass@0"
            ]
        },
        {
            "x": 2,
            "y": -1,
            "z": 5,
            "elements": [
                "minecraft:red_flower@1"
            ]
        },
        {
            "x": 6,
            "y": -1,
            "z": 2,
            "elements": [
                "botania:quartzstairssunny@3"
            ]
        },
        {
            "x": 0,
            "y": -2,
            "z": 10,
            "elements": [
                "minecraft:quartz_block@0"
            ]
        },
        {
            "x": 0,
            "y": -2,
            "z": 9,
            "elements": [
                "minecraft:quartz_block@0"
            ]
        },
        {
            "x": 0,
            "y": -2,
            "z": 11,
            "elements": [
                "minecraft:quartz_block@0"
            ]
        },
        {
            "x": 2,
            "y": -1,
            "z": 10,
            "elements": [
                "minecraft:stained_glass@0"
            ]
        },
        {
            "x": 6,
            "y": -1,
            "z": 1,
            "elements": [
                "botania:quartztypesunny@1"
            ]
        },
        {
            "x": 2,
            "y": -1,
            "z": 7,
            "elements": [
                "minecraft:red_flower@7"
            ]
        },
        {
            "x": 2,
            "y": -1,
            "z": 6,
            "elements": [
                "minecraft:double_plant@4"
            ]
        },
        {
            "x": 2,
            "y": -1,
            "z": 9,

            "elements": [
                "harvestcraft:apiary@2"
            ]
        },
        {
            "x": 0,
            "y": 1,
            "z": 7,
            "elements": [
                "botania:quartzslabsunnyhalf@8"
            ]
        },
        {
            "x": 0,
            "y": 1,
            "z": 6,
            "elements": [
                "botania:quartzslabsunnyhalf@8"
            ]
        },
        {
            "x": 0,
            "y": 1,
            "z": 9,
            "elements": [
                "botania:quartzslabsunnyhalf@8"
            ]
        },
        {
            "x": 0,
            "y": 1,
            "z": 8,
            "elements": [
                "botania:quartzslabsunnyhalf@8"
            ]
        },
        {
            "x": 0,
            "y": 1,
            "z": 11,
            "elements": [
                "botania:quartztypesunny@1"
            ]
        },
        {
            "x": 0,
            "y": 1,
            "z": 10,
            "elements": [
                "botania:quartzstairssunny@6"
            ]
        },
        {
            "x": 0,
            "y": 1,
            "z": 1,
            "elements": [
                "botania:quartztypesunny@1"
            ]
        },
        {
            "x": 0,
            "y": 1,
            "z": 3,
            "elements": [
                "botania:quartzslabsunnyhalf@8"
            ]
        },
        {
            "x": 0,
            "y": 1,
            "z": 2,
            "elements": [
                "botania:quartzstairssunny@7"
            ]
        },
        {
            "x": 0,
            "y": 1,
            "z": 5,
            "elements": [
                "botania:quartzslabsunnyhalf@8"
            ]
        },
        {
            "x": 0,
            "y": 1,
            "z": 4,
            "elements": [
                "botania:quartzslabsunnyhalf@8"
            ]
        },
        {
            "x": 6,
            "y": -2,
            "z": 3,
            "elements": [
                "minecraft:quartz_block@0"
            ]
        },
        {
            "x": 6,
            "y": -2,
            "z": 4,
            "elements": [
                "minecraft:quartz_block@0"
            ]
        },
        {
            "x": 6,
            "y": -2,
            "z": 5,
            "elements": [
                "minecraft:quartz_block@0"
            ]
        },
        {
            "x": 6,
            "y": -2,
            "z": 6,
            "elements": [
                "minecraft:quartz_block@0"
            ]
        },
        {
            "x": 6,
            "y": -2,
            "z": 7,
            "elements": [
                "minecraft:quartz_block@0"
            ]
        },
        {
            "x": 6,
            "y": -2,
            "z": 8,
            "elements": [
                "minecraft:quartz_block@0"
            ]
        },
        {
            "x": 4,
            "y": 2,
            "z": 10,
            "elements": [
                "minecraft:stained_glass@0"
            ]
        },
        {
            "x": 6,
            "y": -2,
            "z": 9,
            "elements": [
                "minecraft:quartz_block@0"
            ]
        },
        {
            "x": 6,
            "y": -2,
            "z": 10,
            "elements": [
                "minecraft:quartz_block@0"
            ]
        },
        {
            "x": 6,
            "y": -2,
            "z": 11,
            "elements": [
                "minecraft:quartz_block@0"
            ]
        },
        {
            "x": 3,
            "y": 1,
            "z": 2,
            "elements": [
                "minecraft:stained_glass@0"
            ]
        },
        {
            "x": 4,
            "y": 2,
            "z": 2,
            "elements": [
                "minecraft:stained_glass@0"
            ]
        },
        {
            "x": 1,
            "y": -2,
            "z": 11,
            "elements": [
                "minecraft:quartz_block@0"
            ]
        },
        {
            "x": 1,
            "y": -2,
            "z": 10,
            "elements": [
                "chisel:waterstone1@14"
            ]
        },
        {
            "x": 1,
            "y": -2,
            "z": 9,
            "elements": [
                "chisel:waterstone1@14"
            ]
        },
        {
            "x": 1,
            "y": -2,
            "z": 8,
            "elements": [
                "chisel:waterstone1@14"
            ]
        },
        {
            "x": 1,
            "y": -2,
            "z": 7,
            "elements": [
                "chisel:waterstone1@14"
            ]
        },
        {
            "x": 1,
            "y": -2,
            "z": 6,
            "elements": [
                "chisel:waterstone1@14"
            ]
        },
        {
            "x": 1,
            "y": -2,
            "z": 5,
            "elements": [
                "chisel:waterstone1@14"
            ]
        },
        {
            "x": 1,
            "y": -2,
            "z": 4,
            "elements": [
                "chisel:waterstone1@14"
            ]
        },
        {
            "x": 1,
            "y": -2,
            "z": 3,
            "elements": [
                "chisel:waterstone1@14"
            ]
        },
        {
            "x": 1,
            "y": -2,
            "z": 2,
            "elements": [
                "chisel:waterstone1@14"
            ]
        },
        {
            "x": 1,
            "y": -2,
            "z": 1,
            "elements": [
                "minecraft:quartz_block@0"
            ]
        },
        {
            "x": 1,
            "y": -2,
            "z": 0,

            "elements": [
                "ItemInput"
            ]
        },
        {
            "x": 5,
            "y": 3,
            "z": 2,
            "elements": [
                "botania:quartzstairssunny@1"
            ]
        },
        {
            "x": 5,
            "y": 3,
            "z": 1,
            "elements": [
                "botania:quartzstairssunny@1"
            ]
        },
        {
            "x": 5,
            "y": 3,
            "z": 4,
            "elements": [
                "botania:quartzstairssunny@3"
            ]
        },
        {
            "x": 5,
            "y": 3,
            "z": 3,
            "elements": [
                "botania:quartzstairssunny@1"
            ]
        },
        {
            "x": 5,
            "y": 3,
            "z": 6,
            "elements": [
                "botania:quartzslabsunnyhalf@0"
            ]
        },
        {
            "x": 5,
            "y": 3,
            "z": 5,
            "elements": [
                "botania:quartzslabsunnyhalf@0"
            ]
        },
        {
            "x": 5,
            "y": 3,
            "z": 8,
            "elements": [
                "botania:quartzstairssunny@2"
            ]
        },
        {
            "x": 5,
            "y": 3,
            "z": 7,
            "elements": [
                "botania:quartzslabsunnyhalf@0"
            ]
        },
        {
            "x": 5,
            "y": 3,
            "z": 10,
            "elements": [
                "botania:quartzstairssunny@1"
            ]
        },
        {
            "x": 5,
            "y": 3,
            "z": 9,
            "elements": [
                "botania:quartzstairssunny@1"
            ]
        },
        {
            "x": 5,
            "y": 3,
            "z": 11,
            "elements": [
                "botania:quartzstairssunny@1"
            ]
        },
        {
            "x": 1,
            "y": -1,
            "z": 2,
            "elements": [
                "minecraft:stained_glass@0"
            ]
        },
        {
            "x": 1,
            "y": -1,
            "z": 1,
            "elements": [
                "botania:quartzstairssunny@1"
            ]
        },
        {
            "x": 3,
            "y": 1,
            "z": 10,
            "elements": [
                "minecraft:stained_glass@0"
            ]
        },
        {
            "x": 1,
            "y": -1,
            "z": 6,
            "elements": [
                "minecraft:stained_glass@0"
            ]
        },
        {
            "x": 1,
            "y": -1,
            "z": 5,
            "elements": [
                "minecraft:stained_glass@0"
            ]
        },
        {
            "x": 1,
            "y": -1,
            "z": 4,
            "elements": [
                "minecraft:stained_glass@0"
            ]
        },
        {
            "x": 1,
            "y": -1,
            "z": 3,
            "elements": [
                "minecraft:stained_glass@0"
            ]
        },
        {
            "x": 4,
            "y": 3,
            "z": 7,
            "elements": [
                "minecraft:stained_glass@0"
            ]
        },
        {
            "x": 1,
            "y": -1,
            "z": 10,
            "elements": [
                "minecraft:stained_glass@0"
            ]
        },
        {
            "x": 1,
            "y": -1,
            "z": 9,
            "elements": [
                "minecraft:stained_glass@0"
            ]
        },
        {
            "x": 4,
            "y": 3,
            "z": 6,
            "elements": [
                "minecraft:stained_glass@0"
            ]
        },
        {
            "x": 1,
            "y": -1,
            "z": 8,
            "elements": [
                "minecraft:stained_glass@0"
            ]
        },
        {
            "x": 4,
            "y": 3,
            "z": 5,
            "elements": [
                "minecraft:stained_glass@0"
            ]
        },
        {
            "x": 1,
            "y": -1,
            "z": 7,
            "elements": [
                "minecraft:stained_glass@0"
            ]
        },
        {
            "x": 4,
            "y": 3,
            "z": 4,
            "elements": [
                "minecraft:stained_glass@0"
            ]
        },
        {
            "x": 4,
            "y": 3,
            "z": 3,
            "elements": [
                "minecraft:stained_glass@0"
            ]
        },
        {
            "x": 4,
            "y": 3,
            "z": 2,
            "elements": [
                "minecraft:stained_glass@0"
            ]
        },
        {
            "x": 4,
            "y": 3,
            "z": 1,
            "elements": [
                "botania:quartzstairssunny@4"
            ]
        },
        {
            "x": 1,
            "y": -1,
            "z": 11,
            "elements": [
                "botania:quartzstairssunny@1"
            ]
        },
        {
            "x": 4,
            "y": 1,
            "z": 10,
            "elements": [
                "minecraft:stained_glass@0"
            ]
        },
        {
            "x": 4,
            "y": 3,
            "z": 11,
            "elements": [
                "botania:quartzstairssunny@4"
            ]
        },
        {
            "x": 4,
            "y": 3,
            "z": 10,
            "elements": [
                "minecraft:stained_glass@0"
            ]
        },
        {
            "x": 4,
            "y": 3,
            "z": 9,
            "elements": [
                "minecraft:stained_glass@0"
            ]
        },
        {
            "x": 4,
            "y": 3,
            "z": 8,
            "elements": [
                "minecraft:stained_glass@0"
            ]
        },
        {
            "x": 3,
            "y": 2,
            "z": 2,
            "elements": [
                "minecraft:stained_glass@0"
            ]
        },
        {
            "x": 2,
            "y": 0,
            "z": 6,
            "elements": [
                "minecraft:double_plant@10"
            ]
        },
        {
            "x": 3,
            "y": 2,
            "z": 10,
            "elements": [
                "minecraft:stained_glass@0"
            ]
        },
        {
            "x": 2,
            "y": 0,
            "z": 10,
            "elements": [
                "minecraft:stained_glass@0"
            ]
        },
        {
            "x": 5,
            "y": 2,
            "z": 9,
            "elements": [
                "minecraft:stained_glass@0"
            ]
        },
        {
            "x": 5,
            "y": 2,
            "z": 8,
            "elements": [
                "minecraft:stained_glass@0"
            ]
        },
        {
            "x": 2,
            "y": 0,
            "z": 9,

            "elements": [
                "harvestcraft:apiary@2"
            ]
        },
        {
            "x": 5,
            "y": 2,
            "z": 11,
            "elements": [
                "minecraft:birch_fence@0"
            ]
        },
        {
            "x": 5,
            "y": 2,
            "z": 10,
            "elements": [
                "minecraft:stained_glass@0"
            ]
        },
        {
            "x": 5,
            "y": 2,
            "z": 5,
            "elements": [
                "minecraft:stained_glass@0"
            ]
        },
        {
            "x": 5,
            "y": 2,
            "z": 4,
            "elements": [
                "minecraft:stained_glass@0"
            ]
        },
        {
            "x": 5,
            "y": 2,
            "z": 7,
            "elements": [
                "minecraft:stained_glass@0"
            ]
        },
        {
            "x": 5,
            "y": 2,
            "z": 6,
            "elements": [
                "minecraft:stained_glass@0"
            ]
        },
        {
            "x": 2,
            "y": 0,
            "z": 2,
            "elements": [
                "minecraft:stained_glass@0"
            ]
        },
        {
            "x": 5,
            "y": 2,
            "z": 1,
            "elements": [
                "minecraft:birch_fence@0"
            ]
        },
        {
            "x": 6,
            "y": -2,
            "z": 0,
            "elements": [
                "minecraft:quartz_stairs@2"
            ]
        },
        {
            "x": 6,
            "y": -2,
            "z": 1,
            "elements": [
                "minecraft:quartz_block@0"
            ]
        },
        {
            "x": 5,
            "y": 2,
            "z": 3,
            "elements": [
                "minecraft:stained_glass@0"
            ]
        },
        {
            "x": 6,
            "y": -2,
            "z": 2,
            "elements": [
                "minecraft:quartz_block@0"
            ]
        },
        {
            "x": 2,
            "y": 0,
            "z": 3,
            "elements": [
                "minecraft:reeds@0"
            ]
        },
        {
            "x": 5,
            "y": 2,
            "z": 2,
            "elements": [
                "minecraft:stained_glass@0"
            ]
        },
        {
            "x": 2,
            "y": -2,
            "z": 0,
            "elements": [
                "minecraft:quartz_stairs@2"
            ]
        },
        {
            "x": 0,
            "y": 2,
            "z": 10,
            "elements": [
                "botania:quartzslabsunnyhalf@0"
            ]
        },
        {
            "x": 0,
            "y": 2,
            "z": 9,
            "elements": [
                "botania:quartzslabsunnyhalf@0"
            ]
        },
        {
            "x": 2,
            "y": -2,
            "z": 2,
            "elements": [
                "chisel:waterstone1@14"
            ]
        },
        {
            "x": 2,
            "y": -2,
            "z": 1,

            "elements": [
                "modularmachinery:blockcasing@0",
                "Upgrade"
            ]
        },
        {
            "x": 0,
            "y": 2,
            "z": 11,
            "elements": [
                "botania:quartzstairssunny@0"
            ]
        },
        {
            "x": 2,
            "y": -2,
            "z": 4,
            "elements": [
                "minecraft:water@0"
            ]
        },
        {
            "x": 0,
            "y": 2,
            "z": 6,
            "elements": [
                "botania:quartzslabsunnyhalf@0"
            ]
        },
        {
            "x": 2,
            "y": -2,
            "z": 3,
            "elements": [
                "minecraft:grass@0"
            ]
        },
        {
            "x": 0,
            "y": 2,
            "z": 5,
            "elements": [
                "botania:quartzslabsunnyhalf@0"
            ]
        },
        {
            "x": 0,
            "y": 2,
            "z": 8,
            "elements": [
                "botania:quartzslabsunnyhalf@0"
            ]
        },
        {
            "x": 2,
            "y": -2,
            "z": 6,
            "elements": [
                "minecraft:grass@0"
            ]
        },
        {
            "x": 0,
            "y": 2,
            "z": 7,
            "elements": [
                "botania:quartzslabsunnyhalf@0"
            ]
        },
        {
            "x": 2,
            "y": -2,
            "z": 5,
            "elements": [
                "minecraft:grass@0"
            ]
        },
        {
            "x": 2,
            "y": 1,
            "z": 10,
            "elements": [
                "minecraft:stained_glass@0"
            ]
        },
        {
            "x": 0,
            "y": 2,
            "z": 2,
            "elements": [
                "botania:quartzslabsunnyhalf@0"
            ]
        },
        {
            "x": 0,
            "y": 2,
            "z": 1,
            "elements": [
                "botania:quartzstairssunny@0"
            ]
        },
        {
            "x": 0,
            "y": 2,
            "z": 4,
            "elements": [
                "botania:quartzslabsunnyhalf@0"
            ]
        },
        {
            "x": 2,
            "y": 1,
            "z": 2,
            "elements": [
                "minecraft:stained_glass@0"
            ]
        },
        {
            "x": 2,
            "y": 1,
            "z": 3,
            "elements": [
                "minecraft:reeds@0"
            ]
        },
        {
            "x": 0,
            "y": 2,
            "z": 3,
            "elements": [
                "botania:quartzslabsunnyhalf@0"
            ]
        },
        {
            "x": 6,
            "y": 0,
            "z": 1,
            "elements": [
                "botania:quartztypesunny@1"
            ]
        },
        {
            "x": 6,
            "y": 0,
            "z": 11,
            "elements": [
                "botania:quartztypesunny@1"
            ]
        },
        {
            "x": 0,
            "y": -1,
            "z": 1,
            "elements": [
                "botania:quartztypesunny@1"
            ]
        },
        {
            "x": 0,
            "y": -1,
            "z": 0,
            "elements": [
                "minecraft:birch_fence@0"
            ]
        },
        {
            "x": 0,
            "y": -1,
            "z": 2,
            "elements": [
                "botania:quartzstairssunny@3"
            ]
        },
        {
            "x": 2,
            "y": -2,
            "z": 8,
            "elements": [
                "minecraft:grass@0"
            ]
        },
        {
            "x": 2,
            "y": -2,
            "z": 7,
            "elements": [
                "minecraft:grass@0"
            ]
        },
        {
            "x": 0,
            "y": -1,
            "z": 11,
            "elements": [
                "botania:quartztypesunny@1"
            ]
        },
        {
            "x": 2,
            "y": -2,
            "z": 10,
            "elements": [
                "chisel:waterstone1@14"
            ]
        },
        {
            "x": 2,
            "y": -2,
            "z": 9,
            "elements": [
                "minecraft:dirt@0"
            ]
        },
        {
            "x": 0,
            "y": -1,
            "z": 10,
            "elements": [
                "botania:quartzstairssunny@2"
            ]
        },
        {
            "x": 2,
            "y": -2,
            "z": 11,
            "elements": [
                "minecraft:quartz_block@0"
            ]
        },
        {
            "x": 3,
            "y": 0,
            "z": 10,
            "elements": [
                "minecraft:stained_glass@0"
            ]
        },
        {
            "x": 3,
            "y": 0,
            "z": 9,

            "elements": [
                "harvestcraft:apiary@2"
            ]
        },
        {
            "x": 3,
            "y": 0,
            "z": 2,
            "elements": [
                "minecraft:stained_glass@0"
            ]
        },
        {
            "x": 5,
            "y": 1,
            "z": 10,
            "elements": [
                "minecraft:stained_glass@0"
            ]
        },
        {
            "x": 2,
            "y": 4,
            "z": 1,
            "elements": [
                "botania:quartzstairssunny@0"
            ]
        },
        {
            "x": 2,
            "y": 4,
            "z": 2,
            "elements": [
                "botania:quartzslabsunnyhalf@0"
            ]
        },
        {
            "x": 5,
            "y": 1,
            "z": 9,
            "elements": [
                "minecraft:stained_glass@0"
            ]
        },
        {
            "x": 2,
            "y": 4,
            "z": 3,
            "elements": [
                "botania:quartzslabsunnyhalf@0"
            ]
        },
        {
            "x": 2,
            "y": 4,
            "z": 4,
            "elements": [
                "botania:quartzslabsunnyhalf@0"
            ]
        },
        {
            "x": 5,
            "y": 1,
            "z": 11,
            "elements": [
                "minecraft:end_rod@0"
            ]
        },
        {
            "x": 2,
            "y": 4,
            "z": 5,
            "elements": [
                "botania:quartzslabsunnyhalf@0"
            ]
        },
        {
            "x": 2,
            "y": 4,
            "z": 6,
            "elements": [
                "botania:quartzslabsunnyhalf@0"
            ]
        },
        {
            "x": 2,
            "y": 4,
            "z": 7,
            "elements": [
                "botania:quartzslabsunnyhalf@0"
            ]
        },
        {
            "x": 2,
            "y": 4,
            "z": 8,
            "elements": [
                "botania:quartzslabsunnyhalf@0"
            ]
        },
        {
            "x": 5,
            "y": 1,
            "z": 2,
            "elements": [
                "minecraft:stained_glass@0"
            ]
        },
        {
            "x": 2,
            "y": 4,
            "z": 9,
            "elements": [
                "botania:quartzslabsunnyhalf@0"
            ]
        },
        {
            "x": 2,
            "y": 4,
            "z": 10,
            "elements": [
                "botania:quartzslabsunnyhalf@0"
            ]
        },
        {
            "x": 5,
            "y": 1,
            "z": 1,
            "elements": [
                "minecraft:end_rod@0"
            ]
        },
        {
            "x": 5,
            "y": 1,
            "z": 4,
            "elements": [
                "minecraft:stained_glass@0"
            ]
        },
        {
            "x": 2,
            "y": 4,
            "z": 11,
            "elements": [
                "botania:quartzstairssunny@0"
            ]
        },
        {
            "x": 5,
            "y": 1,
            "z": 3,
            "elements": [
                "minecraft:stained_glass@0"
            ]
        },
        {
            "x": 5,
            "y": 1,
            "z": 6,
            "elements": [
                "minecraft:stained_glass@0"
            ]
        },
        {
            "x": 5,
            "y": 1,
            "z": 5,
            "elements": [
                "minecraft:stained_glass@0"
            ]
        },
        {
            "x": 5,
            "y": 1,
            "z": 8,
            "elements": [
                "minecraft:stained_glass@0"
            ]
        },
        {
            "x": 5,
            "y": 1,
            "z": 7,
            "elements": [
                "minecraft:stained_glass@0"
            ]
        },
        {
            "x": 5,
            "y": -2,
            "z": 2,
            "elements": [
                "chisel:waterstone1@14"
            ]
        },
        {
            "x": 5,
            "y": -2,
            "z": 3,
            "elements": [
                "chisel:waterstone1@14"
            ]
        },
        {
            "x": 5,
            "y": -2,
            "z": 0,
            "elements": [
                "minecraft:quartz_stairs@2"
            ]
        },
        {
            "x": 5,
            "y": -2,
            "z": 1,
            "elements": [
                "minecraft:quartz_block@0"
            ]
        },
        {
            "x": 5,
            "y": -2,
            "z": 10,
            "elements": [
                "chisel:waterstone1@14"
            ]
        },
        {
            "x": 5,
            "y": -2,
            "z": 11,
            "elements": [
                "minecraft:quartz_block@0"
            ]
        },
        {
            "x": 5,
            "y": -2,
            "z": 8,
            "elements": [
                "chisel:waterstone1@14"
            ]
        },
        {
            "x": 5,
            "y": -2,
            "z": 9,
            "elements": [
                "chisel:waterstone1@14"
            ]
        },
        {
            "x": 5,
            "y": -2,
            "z": 6,
            "elements": [
                "chisel:waterstone1@14"
            ]
        },
        {
            "x": 5,
            "y": -2,
            "z": 7,
            "elements": [
                "chisel:waterstone1@14"
            ]
        },
        {
            "x": 5,
            "y": -2,
            "z": 4,
            "elements": [
                "chisel:waterstone1@14"
            ]
        },
        {
            "x": 5,
            "y": -2,
            "z": 5,
            "elements": [
                "chisel:waterstone1@14"
            ]
        },
        {
            "x": 4,
            "y": -1,
            "z": 5,
            "elements": [
                "minecraft:pumpkin@2"
            ]
        },
        {
            "x": 4,
            "y": -1,
            "z": 6,
            "elements": [
                "botania:flower@1"
            ]
        },
        {
            "x": 4,
            "y": -1,
            "z": 8,
            "elements": [
                "minecraft:red_flower@8"
            ]
        },
        {
            "x": 4,
            "y": -1,
            "z": 9,

            "elements": [
                "harvestcraft:apiary@4"
            ]
        },
        {
            "x": 3,
            "y": 3,
            "z": 9,
            "elements": [
                "minecraft:sea_lantern@0"
            ]
        },
        {
            "x": 4,
            "y": -1,
            "z": 10,
            "elements": [
                "minecraft:stained_glass@0"
            ]
        },
        {
            "x": 3,
            "y": 3,
            "z": 10,
            "elements": [
                "minecraft:stained_glass@0"
            ]
        },
        {
            "x": 3,
            "y": 3,
            "z": 7,
            "elements": [
                "minecraft:sea_lantern@0"
            ]
        },
        {
            "x": 3,
            "y": 3,
            "z": 8,
            "elements": [
                "minecraft:stained_glass@0"
            ]
        },
        {
            "x": 3,
            "y": 3,
            "z": 5,
            "elements": [
                "minecraft:sea_lantern@0"
            ]
        },
        {
            "x": 3,
            "y": 3,
            "z": 6,
            "elements": [
                "minecraft:stained_glass@0"
            ]
        },
        {
            "x": 3,
            "y": 3,
            "z": 3,
            "elements": [
                "minecraft:sea_lantern@0"
            ]
        },
        {
            "x": 3,
            "y": 3,
            "z": 4,
            "elements": [
                "minecraft:stained_glass@0"
            ]
        },
        {
            "x": 4,
            "y": -1,
            "z": 2,
            "elements": [
                "minecraft:stained_glass@0"
            ]
        },
        {
            "x": 3,
            "y": 3,
            "z": 2,
            "elements": [
                "minecraft:stained_glass@0"
            ]
        },
        {
            "x": 4,
            "y": -1,
            "z": 3,
            "elements": [
                "minecraft:red_flower@2"
            ]
        }
    ]}