{
    "registryname": "YMG_Gaia_Guardian_Annihilation_Altar",
    "localizedname": "§b§lYMG§r§e§l—§f§l盖亚湮灭者 §r§e",
    "failure-action": "still",
    "requires-blueprint": false,
    "color": "FF33FF",
    "parts": [
        {
            "x": 0,
            "y": 7,
            "z": 8,
            "elements": [
                "botania:dreamwood0stairs@7"
            ]
        },
        {
            "x": 5,
            "y": 0,
            "z": 2,

            "elements": [
                "mekanism:reinforcedplasticblock@13",
                "ItemInput",
                "ItemOutput",
                "FluidInput"
            ]
        },
        {
            "x": 5,
            "y": 0,
            "z": 3,

            "elements": [
                "mekanism:reinforcedplasticblock@13",
                "ItemInput",
                "ItemOutput",
                "FluidInput"
            ]
        },
        {
            "x": -1,
            "y": -1,
            "z": 9,
            "elements": [
                "enderio:block_alloy@8"
            ]
        },
        {
            "x": -1,
            "y": -1,
            "z": 10,
            "elements": [
                "botania:storage@0"
            ]
        },
        {
            "x": -1,
            "y": -1,
            "z": 11,
            "elements": [
                "extrabotany:blockphotonium@0"
            ]
        },
        {
            "x": -3,
            "y": 10,
            "z": 4,
            "elements": [
                "botania:shimmerrock0slab@0"
            ]
        },
        {
            "x": -1,
            "y": -1,
            "z": 12,
            "elements": [
                "botania:storage@2"
            ]
        },
        {
            "x": -3,
            "y": 10,
            "z": 5,
            "elements": [
                "botania:shimmerrock0slab@0"
            ]
        },
        {
            "x": -1,
            "y": -1,
            "z": 13,
            "elements": [
                "mekanism:reinforcedplasticblock@13"
            ]
        },
        {
            "x": -1,
            "y": -1,
            "z": 14,
            "elements": [
                "botania:shimmerrock0stairs@7"
            ]
        },
        {
            "x": -1,
            "y": -1,
            "z": 1,
            "elements": [
                "mekanism:reinforcedplasticblock@13"
            ]
        },
        {
            "x": -1,
            "y": -1,
            "z": 2,
            "elements": [
                "botania:storage@2"
            ]
        },
        {
            "x": -1,
            "y": -1,
            "z": 3,
            "elements": [
                "extrabotany:blockphotonium@0"
            ]
        },
        {
            "x": -1,
            "y": -1,
            "z": 4,
            "elements": [
                "botania:storage@0"
            ]
        },
        {
            "x": -1,
            "y": -1,
            "z": 5,
            "elements": [
                "enderio:block_alloy@8"
            ]
        },
        {
            "x": -3,
            "y": 10,
            "z": 10,
            "elements": [
                "botania:shimmerrock0slab@0"
            ]
        },
        {
            "x": -1,
            "y": -1,
            "z": 6,
            "elements": [
                "avaritiatweaks:gaia_block@0"
            ]
        },
        {
            "x": -1,
            "y": -1,
            "z": 7,
            "elements": [
                "avaritiatweaks:gaia_block@0"
            ]
        },
        {
            "x": -3,
            "y": 10,
            "z": 9,
            "elements": [
                "botania:shimmerrock0slab@0"
            ]
        },
        {
            "x": -1,
            "y": -1,
            "z": 8,
            "elements": [
                "avaritiatweaks:gaia_block@0"
            ]
        },
        {
            "x": 1,
            "y": 8,
            "z": 7,
            "elements": [
                "botania:dreamwood0wall@0"
            ]
        },
        {
            "x": 1,
            "y": 15,
            "z": 7,
            "elements": [
                "botania:dreamwood0wall@0"
            ]
        },
        {
            "x": 0,
            "y": 0,
            "z": 14,

            "elements": [
                "mekanism:reinforcedplasticblock@13",
                "ItemInput",
                "ItemOutput",
                "FluidInput"
            ]
        },
        {
            "x": 0,
            "y": 14,
            "z": 8,
            "elements": [
                "botania:dreamwood0wall@0"
            ]
        },
        {
            "x": 0,
            "y": 14,
            "z": 7,
            "elements": [
                "botania:bifrostperm@0"
            ]
        },
        {
            "x": 0,
            "y": 0,
            "z": 7,

            "elements": [
                "minecraft:beacon@0"
            ]
        },
        {
            "x": 0,
            "y": 7,
            "z": 6,
            "elements": [
                "botania:dreamwood0stairs@6"
            ]
        },
        {
            "x": 0,
            "y": 14,
            "z": 6,
            "elements": [
                "botania:dreamwood0wall@0"
            ]
        },
        {
            "x": 0,
            "y": 7,
            "z": 7,
            "elements": [
                "botania:bifrostperm@0"
            ]
        },
        {
            "x": -1,
            "y": -1,
            "z": 0,
            "elements": [
                "botania:shimmerrock0stairs@6"
            ]
        },
        {
            "x": -6,
            "y": -1,
            "z": 11,
            "elements": [
                "botania:shimmerrock0slab@8"
            ]
        },
        {
            "x": -6,
            "y": -1,
            "z": 10,
            "elements": [
                "botania:shimmerrock0stairs@4"
            ]
        },
        {
            "x": 0,
            "y": 0,
            "z": 0,

            "elements": [
                "modularmachinery:blockcontroller@2"
            ]
        },
        {
            "x": -6,
            "y": -1,
            "z": 9,
            "elements": [
                "mekanism:reinforcedplasticblock@13"
            ]
        },
        {
            "x": -6,
            "y": -1,
            "z": 8,
            "elements": [
                "mekanism:reinforcedplasticblock@13"
            ]
        },
        {
            "x": -6,
            "y": -1,
            "z": 7,
            "elements": [
                "botania:blazeblock@0"
            ]
        },
        {
            "x": -6,
            "y": -1,
            "z": 6,
            "elements": [
                "mekanism:reinforcedplasticblock@13"
            ]
        },
        {
            "x": 0,
            "y": 13,
            "z": 8,
            "elements": [
                "botania:dreamwood@0"
            ]
        },
        {
            "x": 0,
            "y": 13,
            "z": 7,
            "elements": [
                "botania:bifrostperm@0"
            ]
        },
        {
            "x": 0,
            "y": 13,
            "z": 6,
            "elements": [
                "botania:dreamwood@0"
            ]
        },
        {
            "x": -6,
            "y": -1,
            "z": 5,
            "elements": [
                "mekanism:reinforcedplasticblock@13"
            ]
        },
        {
            "x": -6,
            "y": -1,
            "z": 4,
            "elements": [
                "botania:shimmerrock0stairs@4"
            ]
        },
        {
            "x": 1,
            "y": 9,
            "z": 7,
            "elements": [
                "botania:dreamwood0wall@0"
            ]
        },
        {
            "x": 5,
            "y": 0,
            "z": 12,

            "elements": [
                "mekanism:reinforcedplasticblock@13",
                "ItemInput",
                "ItemOutput",
                "FluidInput"
            ]
        },
        {
            "x": 5,
            "y": 0,
            "z": 11,

            "elements": [
                "mekanism:reinforcedplasticblock@13",
                "ItemInput",
                "ItemOutput",
                "FluidInput"
            ]
        },
        {
            "x": -5,
            "y": 0,
            "z": 3,

            "elements": [
                "mekanism:reinforcedplasticblock@13",
                "ItemInput",
                "ItemOutput",
                "FluidInput"
            ]
        },
        {
            "x": 3,
            "y": 10,
            "z": 5,
            "elements": [
                "botania:shimmerrock0slab@0"
            ]
        },
        {
            "x": 3,
            "y": 10,
            "z": 4,
            "elements": [
                "botania:shimmerrock0slab@0"
            ]
        },
        {
            "x": -5,
            "y": 0,
            "z": 2,

            "elements": [
                "mekanism:reinforcedplasticblock@13",
                "ItemInput",
                "ItemOutput",
                "FluidInput"
            ]
        },
        {
            "x": -7,
            "y": -1,
            "z": 8,
            "elements": [
                "botania:shimmerrock0stairs@4"
            ]
        },
        {
            "x": -7,
            "y": -1,
            "z": 7,
            "elements": [
                "mekanism:reinforcedplasticblock@13"
            ]
        },
        {
            "x": 3,
            "y": 10,
            "z": 9,
            "elements": [
                "botania:shimmerrock0slab@0"
            ]
        },
        {
            "x": 3,
            "y": 10,
            "z": 10,
            "elements": [
                "botania:shimmerrock0slab@0"
            ]
        },
        {
            "x": -7,
            "y": -1,
            "z": 6,
            "elements": [
                "botania:shimmerrock0stairs@4"
            ]
        },
        {
            "x": 5,
            "y": -1,
            "z": 5,
            "elements": [
                "botania:storage@2"
            ]
        },
        {
            "x": 5,
            "y": -1,
            "z": 6,
            "elements": [
                "botania:storage@2"
            ]
        },
        {
            "x": 5,
            "y": -1,
            "z": 3,
            "elements": [
                "botania:shimmerrock0stairs@6"
            ]
        },
        {
            "x": 5,
            "y": -1,
            "z": 4,
            "elements": [
                "botania:blazeblock@0"
            ]
        },
        {
            "x": 5,
            "y": -1,
            "z": 9,
            "elements": [
                "botania:storage@2"
            ]
        },
        {
            "x": 5,
            "y": -1,
            "z": 10,
            "elements": [
                "botania:blazeblock@0"
            ]
        },
        {
            "x": 5,
            "y": -1,
            "z": 7,
            "elements": [
                "extrabotany:blockshadowium@0"
            ]
        },
        {
            "x": 5,
            "y": -1,
            "z": 8,
            "elements": [
                "botania:storage@2"
            ]
        },
        {
            "x": 5,
            "y": -1,
            "z": 11,
            "elements": [
                "botania:shimmerrock0stairs@7"
            ]
        },
        {
            "x": 5,
            "y": -1,
            "z": 12,
            "elements": [
                "botania:shimmerrock0slab@8"
            ]
        },
        {
            "x": 4,
            "y": 0,
            "z": 2,

            "elements": [
                "mekanism:reinforcedplasticblock@13",
                "ItemInput",
                "ItemOutput",
                "FluidInput"
            ]
        },
        {
            "x": -1,
            "y": 12,
            "z": 7,
            "elements": [
                "botania:dreamwood0wall@0"
            ]
        },
        {
            "x": 1,
            "y": 7,
            "z": 7,
            "elements": [
                "botania:dreamwood0stairs@5"
            ]
        },
        {
            "x": -2,
            "y": -1,
            "z": 12,
            "elements": [
                "botania:storage@2"
            ]
        },
        {
            "x": -2,
            "y": -1,
            "z": 13,
            "elements": [
                "mekanism:reinforcedplasticblock@13"
            ]
        },
        {
            "x": -2,
            "y": -1,
            "z": 10,
            "elements": [
                "botania:storage@0"
            ]
        },
        {
            "x": -2,
            "y": -1,
            "z": 11,
            "elements": [
                "extrabotany:blockshadowium@0"
            ]
        },
        {
            "x": -2,
            "y": -1,
            "z": 8,
            "elements": [
                "enderio:block_alloy@8"
            ]
        },
        {
            "x": -2,
            "y": -1,
            "z": 9,
            "elements": [
                "botania:storage@0"
            ]
        },
        {
            "x": -2,
            "y": -1,
            "z": 6,
            "elements": [
                "enderio:block_alloy@8"
            ]
        },
        {
            "x": -2,
            "y": -1,
            "z": 7,
            "elements": [
                "enderio:block_alloy@8"
            ]
        },
        {
            "x": -2,
            "y": -1,
            "z": 4,
            "elements": [
                "botania:storage@0"
            ]
        },
        {
            "x": 5,
            "y": -1,
            "z": 2,
            "elements": [
                "botania:shimmerrock0slab@8"
            ]
        },
        {
            "x": -2,
            "y": -1,
            "z": 5,
            "elements": [
                "botania:storage@0"
            ]
        },
        {
            "x": -2,
            "y": -1,
            "z": 2,
            "elements": [
                "botania:storage@2"
            ]
        },
        {
            "x": -2,
            "y": -1,
            "z": 3,
            "elements": [
                "extrabotany:blockshadowium@0"
            ]
        },
        {
            "x": -2,
            "y": -1,
            "z": 1,
            "elements": [
                "mekanism:reinforcedplasticblock@13"
            ]
        },
        {
            "x": 0,
            "y": 8,
            "z": 7,
            "elements": [
                "botania:bifrostperm@0"
            ]
        },
        {
            "x": -4,
            "y": 10,
            "z": 9,
            "elements": [
                "botania:shimmerrock0stairs@3"
            ]
        },
        {
            "x": 0,
            "y": 8,
            "z": 8,
            "elements": [
                "botania:dreamwood0wall@0"
            ]
        },
        {
            "x": -4,
            "y": 10,
            "z": 6,
            "elements": [
                "botania:shimmerrock0slab@0"
            ]
        },
        {
            "x": -4,
            "y": 10,
            "z": 5,
            "elements": [
                "botania:shimmerrock0stairs@2"
            ]
        },
        {
            "x": -5,
            "y": 0,
            "z": 11,

            "elements": [
                "mekanism:reinforcedplasticblock@13",
                "ItemInput",
                "ItemOutput",
                "FluidInput"
            ]
        },
        {
            "x": -4,
            "y": 10,
            "z": 8,
            "elements": [
                "botania:shimmerrock0slab@0"
            ]
        },
        {
            "x": -4,
            "y": 10,
            "z": 7,
            "elements": [
                "botania:shimmerrock0slab@0"
            ]
        },
        {
            "x": 0,
            "y": 8,
            "z": 6,
            "elements": [
                "botania:dreamwood0wall@0"
            ]
        },
        {
            "x": 1,
            "y": 10,
            "z": 3,
            "elements": [
                "botania:shimmerrock0slab@0"
            ]
        },
        {
            "x": 1,
            "y": 0,
            "z": 0,

            "elements": [
                "mekanism:reinforcedplasticblock@13",
                "ItemInput",
                "ItemOutput",
                "FluidInput"
            ]
        },
        {
            "x": 3,
            "y": -1,
            "z": 13,
            "elements": [
                "botania:shimmerrock0stairs@7"
            ]
        },
        {
            "x": 3,
            "y": -1,
            "z": 11,
            "elements": [
                "botania:storage@2"
            ]
        },
        {
            "x": 3,
            "y": -1,
            "z": 12,
            "elements": [
                "botania:blazeblock@0"
            ]
        },
        {
            "x": 3,
            "y": -1,
            "z": 9,
            "elements": [
                "botania:storage@0"
            ]
        },
        {
            "x": 3,
            "y": -1,
            "z": 10,
            "elements": [
                "extrabotany:blockphotonium@0"
            ]
        },
        {
            "x": 3,
            "y": -1,
            "z": 7,
            "elements": [
                "enderio:block_alloy@8"
            ]
        },
        {
            "x": -1,
            "y": 14,
            "z": 7,
            "elements": [
                "botania:dreamwood0wall@0"
            ]
        },
        {
            "x": 3,
            "y": -1,
            "z": 8,
            "elements": [
                "botania:storage@0"
            ]
        },
        {
            "x": 3,
            "y": -1,
            "z": 5,
            "elements": [
                "botania:storage@0"
            ]
        },
        {
            "x": 3,
            "y": -1,
            "z": 6,
            "elements": [
                "botania:storage@0"
            ]
        },
        {
            "x": 3,
            "y": -1,
            "z": 3,
            "elements": [
                "botania:storage@2"
            ]
        },
        {
            "x": 3,
            "y": -1,
            "z": 4,
            "elements": [
                "extrabotany:blockphotonium@0"
            ]
        },
        {
            "x": 3,
            "y": -1,
            "z": 1,
            "elements": [
                "botania:shimmerrock0stairs@6"
            ]
        },
        {
            "x": 3,
            "y": -1,
            "z": 2,
            "elements": [
                "botania:blazeblock@0"
            ]
        },
        {
            "x": -5,
            "y": -1,
            "z": 2,
            "elements": [
                "botania:shimmerrock0slab@8"
            ]
        },
        {
            "x": -5,
            "y": -1,
            "z": 4,
            "elements": [
                "botania:blazeblock@0"
            ]
        },
        {
            "x": -5,
            "y": -1,
            "z": 3,
            "elements": [
                "botania:shimmerrock0stairs@6"
            ]
        },
        {
            "x": -5,
            "y": -1,
            "z": 6,
            "elements": [
                "botania:storage@2"
            ]
        },
        {
            "x": -5,
            "y": -1,
            "z": 5,
            "elements": [
                "botania:storage@2"
            ]
        },
        {
            "x": 4,
            "y": 10,
            "z": 9,
            "elements": [
                "botania:shimmerrock0stairs@3"
            ]
        },
        {
            "x": -5,
            "y": -1,
            "z": 8,
            "elements": [
                "botania:storage@2"
            ]
        },
        {
            "x": 1,
            "y": 10,
            "z": 11,
            "elements": [
                "botania:shimmerrock0slab@0"
            ]
        },
        {
            "x": -5,
            "y": -1,
            "z": 7,
            "elements": [
                "extrabotany:blockshadowium@0"
            ]
        },
        {
            "x": -1,
            "y": 11,
            "z": 7,
            "elements": [
                "botania:dreamwood0wall@0"
            ]
        },
        {
            "x": -5,
            "y": -1,
            "z": 10,
            "elements": [
                "botania:blazeblock@0"
            ]
        },
        {
            "x": -5,
            "y": -1,
            "z": 9,
            "elements": [
                "botania:storage@2"
            ]
        },
        {
            "x": 1,
            "y": 10,
            "z": 7,
            "elements": [
                "botania:dreamwood@0"
            ]
        },
        {
            "x": -5,
            "y": -1,
            "z": 11,
            "elements": [
                "botania:shimmerrock0stairs@7"
            ]
        },
        {
            "x": -2,
            "y": 0,
            "z": 1,

            "elements": [
                "mekanism:reinforcedplasticblock@13",
                "ItemInput",
                "ItemOutput",
                "FluidInput"
            ]
        },
        {
            "x": 4,
            "y": 1,
            "z": 5,

            "elements": [
                "botania:pylon@2"
            ]
        },
        {
            "x": 6,
            "y": -1,
            "z": 10,
            "elements": [
                "botania:shimmerrock0stairs@5"
            ]
        },
        {
            "x": 4,
            "y": 0,
            "z": 12,

            "elements": [
                "mekanism:reinforcedplasticblock@13",
                "ItemInput",
                "ItemOutput",
                "FluidInput"
            ]
        },
        {
            "x": 1,
            "y": 13,
            "z": 7,
            "elements": [
                "botania:dreamwood@0"
            ]
        },
        {
            "x": 4,
            "y": 1,
            "z": 9,

            "elements": [
                "botania:pylon@2"
            ]
        },
        {
            "x": -4,
            "y": 1,
            "z": 5,

            "elements": [
                "botania:pylon@2"
            ]
        },
        {
            "x": -4,
            "y": 1,
            "z": 9,

            "elements": [
                "botania:pylon@2"
            ]
        },
        {
            "x": 1,
            "y": 16,
            "z": 7,
            "elements": [
                "botania:dreamwood0stairs@1"
            ]
        },
        {
            "x": -2,
            "y": 0,
            "z": 13,

            "elements": [
                "mekanism:reinforcedplasticblock@13",
                "ItemInput",
                "ItemOutput",
                "FluidInput"
            ]
        },
        {
            "x": 6,
            "y": -1,
            "z": 5,
            "elements": [
                "mekanism:reinforcedplasticblock@13"
            ]
        },
        {
            "x": 2,
            "y": -1,
            "z": 3,
            "elements": [
                "extrabotany:blockshadowium@0"
            ]
        },
        {
            "x": 2,
            "y": -1,
            "z": 2,
            "elements": [
                "botania:storage@2"
            ]
        },
        {
            "x": 6,
            "y": -1,
            "z": 4,
            "elements": [
                "botania:shimmerrock0stairs@5"
            ]
        },
        {
            "x": 2,
            "y": -1,
            "z": 5,
            "elements": [
                "botania:storage@0"
            ]
        },
        {
            "x": 2,
            "y": -1,
            "z": 4,
            "elements": [
                "botania:storage@0"
            ]
        },
        {
            "x": 6,
            "y": -1,
            "z": 9,
            "elements": [
                "mekanism:reinforcedplasticblock@13"
            ]
        },
        {
            "x": 6,
            "y": -1,
            "z": 8,
            "elements": [
                "mekanism:reinforcedplasticblock@13"
            ]
        },
        {
            "x": 2,
            "y": -1,
            "z": 1,
            "elements": [
                "mekanism:reinforcedplasticblock@13"
            ]
        },
        {
            "x": 6,
            "y": -1,
            "z": 7,
            "elements": [
                "botania:blazeblock@0"
            ]
        },
        {
            "x": 6,
            "y": -1,
            "z": 6,
            "elements": [
                "mekanism:reinforcedplasticblock@13"
            ]
        },
        {
            "x": 2,
            "y": -1,
            "z": 11,
            "elements": [
                "extrabotany:blockshadowium@0"
            ]
        },
        {
            "x": 2,
            "y": -1,
            "z": 10,
            "elements": [
                "botania:storage@0"
            ]
        },
        {
            "x": 2,
            "y": -1,
            "z": 13,
            "elements": [
                "mekanism:reinforcedplasticblock@13"
            ]
        },
        {
            "x": 2,
            "y": -1,
            "z": 12,
            "elements": [
                "botania:storage@2"
            ]
        },
        {
            "x": 2,
            "y": -1,
            "z": 7,
            "elements": [
                "enderio:block_alloy@8"
            ]
        },
        {
            "x": 2,
            "y": -1,
            "z": 6,
            "elements": [
                "enderio:block_alloy@8"
            ]
        },
        {
            "x": 2,
            "y": -1,
            "z": 9,
            "elements": [
                "botania:storage@0"
            ]
        },
        {
            "x": 2,
            "y": -1,
            "z": 8,
            "elements": [
                "enderio:block_alloy@8"
            ]
        },
        {
            "x": 4,
            "y": 10,
            "z": 7,
            "elements": [
                "botania:shimmerrock0slab@0"
            ]
        },
        {
            "x": -6,
            "y": 0,
            "z": 4,

            "elements": [
                "mekanism:reinforcedplasticblock@13",
                "ItemInput",
                "ItemOutput",
                "FluidInput"
            ]
        },
        {
            "x": 4,
            "y": 10,
            "z": 8,
            "elements": [
                "botania:shimmerrock0slab@0"
            ]
        },
        {
            "x": 4,
            "y": 10,
            "z": 5,
            "elements": [
                "botania:shimmerrock0stairs@2"
            ]
        },
        {
            "x": 4,
            "y": 10,
            "z": 6,
            "elements": [
                "botania:shimmerrock0slab@0"
            ]
        },
        {
            "x": -6,
            "y": 0,
            "z": 5,

            "elements": [
                "mekanism:reinforcedplasticblock@13",
                "ItemInput",
                "ItemOutput",
                "FluidInput"
            ]
        },
        {
            "x": -6,
            "y": 0,
            "z": 11,

            "elements": [
                "mekanism:reinforcedplasticblock@13",
                "ItemInput",
                "ItemOutput",
                "FluidInput"
            ]
        },
        {
            "x": -1,
            "y": 8,
            "z": 7,
            "elements": [
                "botania:dreamwood0wall@0"
            ]
        },
        {
            "x": -6,
            "y": 0,
            "z": 10,

            "elements": [
                "mekanism:reinforcedplasticblock@13",
                "ItemInput",
                "ItemOutput",
                "FluidInput"
            ]
        },
        {
            "x": -6,
            "y": 0,
            "z": 9,

            "elements": [
                "mekanism:reinforcedplasticblock@13",
                "ItemInput",
                "ItemOutput",
                "FluidInput"
            ]
        },
        {
            "x": 1,
            "y": 0,
            "z": 14,

            "elements": [
                "mekanism:reinforcedplasticblock@13",
                "ItemInput",
                "ItemOutput",
                "FluidInput"
            ]
        },
        {
            "x": -1,
            "y": 9,
            "z": 7,
            "elements": [
                "botania:dreamwood0wall@0"
            ]
        },
        {
            "x": -3,
            "y": 0,
            "z": 13,

            "elements": [
                "mekanism:reinforcedplasticblock@13",
                "ItemInput",
                "ItemOutput",
                "FluidInput"
            ]
        },
        {
            "x": -4,
            "y": -1,
            "z": 2,
            "elements": [
                "botania:shimmerrock0stairs@4"
            ]
        },
        {
            "x": -2,
            "y": 1,
            "z": 3,

            "elements": [
                "botania:pylon@2"
            ]
        },
        {
            "x": -4,
            "y": -1,
            "z": 3,
            "elements": [
                "mekanism:reinforcedplasticblock@13"
            ]
        },
        {
            "x": -1,
            "y": 16,
            "z": 7,
            "elements": [
                "botania:dreamwood0stairs@0"
            ]
        },
        {
            "x": -2,
            "y": 1,
            "z": 11,

            "elements": [
                "botania:pylon@2"
            ]
        },
        {
            "x": -3,
            "y": 0,
            "z": 1,

            "elements": [
                "mekanism:reinforcedplasticblock@13",
                "ItemInput",
                "ItemOutput",
                "FluidInput"
            ]
        },
        {
            "x": 1,
            "y": 12,
            "z": 7,
            "elements": [
                "botania:dreamwood0wall@0"
            ]
        },
        {
            "x": 0,
            "y": 10,
            "z": 3,
            "elements": [
                "botania:shimmerrock0slab@0"
            ]
        },
        {
            "x": 0,
            "y": 10,
            "z": 11,
            "elements": [
                "botania:shimmerrock0slab@0"
            ]
        },
        {
            "x": 0,
            "y": 10,
            "z": 6,
            "elements": [
                "botania:dreamwood@0"
            ]
        },
        {
            "x": 0,
            "y": 10,
            "z": 7,
            "elements": [
                "botania:bifrostperm@0"
            ]
        },
        {
            "x": 0,
            "y": 10,
            "z": 8,
            "elements": [
                "botania:dreamwood@0"
            ]
        },
        {
            "x": 7,
            "y": -1,
            "z": 6,
            "elements": [
                "botania:shimmerrock0stairs@5"
            ]
        },
        {
            "x": 1,
            "y": -1,
            "z": 2,
            "elements": [
                "botania:storage@2"
            ]
        },
        {
            "x": 1,
            "y": -1,
            "z": 1,
            "elements": [
                "mekanism:reinforcedplasticblock@13"
            ]
        },
        {
            "x": 7,
            "y": -1,
            "z": 8,
            "elements": [
                "botania:shimmerrock0stairs@5"
            ]
        },
        {
            "x": 1,
            "y": -1,
            "z": 0,
            "elements": [
                "botania:shimmerrock0stairs@6"
            ]
        },
        {
            "x": 7,
            "y": -1,
            "z": 7,
            "elements": [
                "mekanism:reinforcedplasticblock@13"
            ]
        },
        {
            "x": 1,
            "y": -1,
            "z": 6,
            "elements": [
                "avaritiatweaks:gaia_block@0"
            ]
        },
        {
            "x": 1,
            "y": -1,
            "z": 5,
            "elements": [
                "enderio:block_alloy@8"
            ]
        },
        {
            "x": 1,
            "y": -1,
            "z": 4,
            "elements": [
                "botania:storage@0"
            ]
        },
        {
            "x": 1,
            "y": -1,
            "z": 3,
            "elements": [
                "extrabotany:blockphotonium@0"
            ]
        },
        {
            "x": 7,
            "y": 0,
            "z": 8,

            "elements": [
                "mekanism:reinforcedplasticblock@13",
                "ItemInput",
                "ItemOutput",
                "FluidInput"
            ]
        },
        {
            "x": 1,
            "y": -1,
            "z": 10,
            "elements": [
                "botania:storage@0"
            ]
        },
        {
            "x": 1,
            "y": -1,
            "z": 9,
            "elements": [
                "enderio:block_alloy@8"
            ]
        },
        {
            "x": 1,
            "y": -1,
            "z": 8,
            "elements": [
                "avaritiatweaks:gaia_block@0"
            ]
        },
        {
            "x": 0,
            "y": 16,
            "z": 8,
            "elements": [
                "botania:dreamwood0stairs@3"
            ]
        },
        {
            "x": 1,
            "y": -1,
            "z": 7,
            "elements": [
                "avaritiatweaks:gaia_block@0"
            ]
        },
        {
            "x": 0,
            "y": 11,
            "z": 8,
            "elements": [
                "botania:dreamwood0wall@0"
            ]
        },
        {
            "x": 0,
            "y": 16,
            "z": 7,
            "elements": [
                "botania:bifrostperm@0"
            ]
        },
        {
            "x": -1,
            "y": 15,
            "z": 7,
            "elements": [
                "botania:dreamwood0wall@0"
            ]
        },
        {
            "x": 0,
            "y": 11,
            "z": 7,
            "elements": [
                "botania:bifrostperm@0"
            ]
        },
        {
            "x": 1,
            "y": -1,
            "z": 14,
            "elements": [
                "botania:shimmerrock0stairs@7"
            ]
        },
        {
            "x": 1,
            "y": -1,
            "z": 13,
            "elements": [
                "mekanism:reinforcedplasticblock@13"
            ]
        },
        {
            "x": 0,
            "y": 11,
            "z": 6,
            "elements": [
                "botania:dreamwood0wall@0"
            ]
        },
        {
            "x": 1,
            "y": -1,
            "z": 12,
            "elements": [
                "botania:storage@2"
            ]
        },
        {
            "x": 1,
            "y": -1,
            "z": 11,
            "elements": [
                "extrabotany:blockphotonium@0"
            ]
        },
        {
            "x": 0,
            "y": 16,
            "z": 6,
            "elements": [
                "botania:dreamwood0stairs@2"
            ]
        },
        {
            "x": 7,
            "y": 0,
            "z": 7,

            "elements": [
                "mekanism:reinforcedplasticblock@13",
                "ItemInput",
                "ItemOutput",
                "FluidInput"
            ]
        },
        {
            "x": 7,
            "y": 0,
            "z": 6,

            "elements": [
                "mekanism:reinforcedplasticblock@13",
                "ItemInput",
                "ItemOutput",
                "FluidInput"
            ]
        },
        {
            "x": -4,
            "y": -1,
            "z": 12,
            "elements": [
                "botania:shimmerrock0stairs@4"
            ]
        },
        {
            "x": -4,
            "y": -1,
            "z": 6,
            "elements": [
                "extrabotany:blockphotonium@0"
            ]
        },
        {
            "x": -4,
            "y": -1,
            "z": 7,
            "elements": [
                "enderio:block_alloy@8"
            ]
        },
        {
            "x": 2,
            "y": 0,
            "z": 13,

            "elements": [
                "mekanism:reinforcedplasticblock@13",
                "ItemInput",
                "ItemOutput",
                "FluidInput"
            ]
        },
        {
            "x": -4,
            "y": -1,
            "z": 4,
            "elements": [
                "botania:storage@2"
            ]
        },
        {
            "x": -4,
            "y": -1,
            "z": 5,
            "elements": [
                "extrabotany:blockshadowium@0"
            ]
        },
        {
            "x": -4,
            "y": -1,
            "z": 10,
            "elements": [
                "botania:storage@2"
            ]
        },
        {
            "x": -4,
            "y": -1,
            "z": 11,
            "elements": [
                "mekanism:reinforcedplasticblock@13"
            ]
        },
        {
            "x": -4,
            "y": -1,
            "z": 8,
            "elements": [
                "extrabotany:blockphotonium@0"
            ]
        },
        {
            "x": -4,
            "y": -1,
            "z": 9,
            "elements": [
                "extrabotany:blockshadowium@0"
            ]
        },
        {
            "x": 2,
            "y": 0,
            "z": 1,

            "elements": [
                "mekanism:reinforcedplasticblock@13",
                "ItemInput",
                "ItemOutput",
                "FluidInput"
            ]
        },
        {
            "x": 0,
            "y": 12,
            "z": 6,
            "elements": [
                "botania:dreamwood0wall@0"
            ]
        },
        {
            "x": 0,
            "y": 12,
            "z": 8,
            "elements": [
                "botania:dreamwood0wall@0"
            ]
        },
        {
            "x": 0,
            "y": 12,
            "z": 7,
            "elements": [
                "botania:bifrostperm@0"
            ]
        },
        {
            "x": 2,
            "y": 1,
            "z": 11,

            "elements": [
                "botania:pylon@2"
            ]
        },
        {
            "x": -4,
            "y": 0,
            "z": 12,

            "elements": [
                "mekanism:reinforcedplasticblock@13",
                "ItemInput",
                "ItemOutput",
                "FluidInput"
            ]
        },
        {
            "x": -7,
            "y": 0,
            "z": 7,

            "elements": [
                "mekanism:reinforcedplasticblock@13",
                "ItemInput",
                "ItemOutput",
                "FluidInput"
            ]
        },
        {
            "x": -7,
            "y": 0,
            "z": 6,

            "elements": [
                "mekanism:reinforcedplasticblock@13",
                "ItemInput",
                "ItemOutput",
                "FluidInput"
            ]
        },
        {
            "x": 2,
            "y": 1,
            "z": 3,

            "elements": [
                "botania:pylon@2"
            ]
        },
        {
            "x": -7,
            "y": 0,
            "z": 8,

            "elements": [
                "mekanism:reinforcedplasticblock@13",
                "ItemInput",
                "ItemOutput",
                "FluidInput"
            ]
        },
        {
            "x": -1,
            "y": 7,
            "z": 7,
            "elements": [
                "botania:dreamwood0stairs@4"
            ]
        },
        {
            "x": 6,
            "y": 0,
            "z": 5,

            "elements": [
                "mekanism:reinforcedplasticblock@13",
                "ItemInput",
                "ItemOutput",
                "FluidInput"
            ]
        },
        {
            "x": -2,
            "y": 10,
            "z": 3,
            "elements": [
                "botania:shimmerrock0stairs@0"
            ]
        },
        {
            "x": 6,
            "y": 0,
            "z": 4,

            "elements": [
                "mekanism:reinforcedplasticblock@13",
                "ItemInput",
                "ItemOutput",
                "FluidInput"
            ]
        },
        {
            "x": -2,
            "y": 10,
            "z": 4,
            "elements": [
                "botania:shimmerrock0slab@0"
            ]
        },
        {
            "x": 0,
            "y": 9,
            "z": 6,
            "elements": [
                "botania:dreamwood0wall@0"
            ]
        },
        {
            "x": 0,
            "y": 9,
            "z": 7,
            "elements": [
                "botania:bifrostperm@0"
            ]
        },
        {
            "x": 0,
            "y": 9,
            "z": 8,
            "elements": [
                "botania:dreamwood0wall@0"
            ]
        },
        {
            "x": -2,
            "y": 10,
            "z": 10,
            "elements": [
                "botania:shimmerrock0slab@0"
            ]
        },
        {
            "x": -2,
            "y": 10,
            "z": 11,
            "elements": [
                "botania:shimmerrock0stairs@0"
            ]
        },
        {
            "x": 6,
            "y": 0,
            "z": 10,

            "elements": [
                "mekanism:reinforcedplasticblock@13",
                "ItemInput",
                "ItemOutput",
                "FluidInput"
            ]
        },
        {
            "x": 6,
            "y": 0,
            "z": 9,

            "elements": [
                "mekanism:reinforcedplasticblock@13",
                "ItemInput",
                "ItemOutput",
                "FluidInput"
            ]
        },
        {
            "x": 0,
            "y": -1,
            "z": 1,
            "elements": [
                "botania:blazeblock@0"
            ]
        },
        {
            "x": 0,
            "y": -1,
            "z": 0,
            "elements": [
                "mekanism:reinforcedplasticblock@13"
            ]
        },
        {
            "x": 0,
            "y": -1,
            "z": 3,
            "elements": [
                "enderio:block_alloy@8"
            ]
        },
        {
            "x": 0,
            "y": -1,
            "z": 2,
            "elements": [
                "extrabotany:blockshadowium@0"
            ]
        },
        {
            "x": 0,
            "y": -1,
            "z": 5,
            "elements": [
                "enderio:block_alloy@8"
            ]
        },
        {
            "x": 0,
            "y": -1,
            "z": 4,
            "elements": [
                "enderio:block_alloy@8"
            ]
        },
        {
            "x": 0,
            "y": -1,
            "z": 7,
            "elements": [
                "avaritiatweaks:gaia_block@0"
            ]
        },
        {
            "x": 0,
            "y": -1,
            "z": 6,
            "elements": [
                "avaritiatweaks:gaia_block@0"
            ]
        },
        {
            "x": 0,
            "y": -1,
            "z": 9,
            "elements": [
                "enderio:block_alloy@8"
            ]
        },
        {
            "x": 0,
            "y": -1,
            "z": 8,
            "elements": [
                "avaritiatweaks:gaia_block@0"
            ]
        },
        {
            "x": 0,
            "y": -1,
            "z": 11,
            "elements": [
                "enderio:block_alloy@8"
            ]
        },
        {
            "x": -1,
            "y": 10,
            "z": 7,
            "elements": [
                "botania:dreamwood@0"
            ]
        },
        {
            "x": 0,
            "y": -1,
            "z": 10,
            "elements": [
                "enderio:block_alloy@8"
            ]
        },
        {
            "x": 0,
            "y": -1,
            "z": 13,
            "elements": [
                "botania:blazeblock@0"
            ]
        },
        {
            "x": 0,
            "y": -1,
            "z": 12,
            "elements": [
                "extrabotany:blockshadowium@0"
            ]
        },
        {
            "x": -1,
            "y": 10,
            "z": 11,
            "elements": [
                "botania:shimmerrock0slab@0"
            ]
        },
        {
            "x": 0,
            "y": -1,
            "z": 14,
            "elements": [
                "mekanism:reinforcedplasticblock@13"
            ]
        },
        {
            "x": -1,
            "y": 0,
            "z": 0,

            "elements": [
                "mekanism:reinforcedplasticblock@13",
                "ItemInput",
                "ItemOutput",
                "FluidInput"
            ]
        },
        {
            "x": -3,
            "y": -1,
            "z": 11,
            "elements": [
                "botania:storage@2"
            ]
        },
        {
            "x": -3,
            "y": -1,
            "z": 12,
            "elements": [
                "botania:blazeblock@0"
            ]
        },
        {
            "x": -3,
            "y": -1,
            "z": 13,
            "elements": [
                "botania:shimmerrock0stairs@7"
            ]
        },
        {
            "x": -1,
            "y": 10,
            "z": 3,
            "elements": [
                "botania:shimmerrock0slab@0"
            ]
        },
        {
            "x": 1,
            "y": 14,
            "z": 7,
            "elements": [
                "botania:dreamwood0wall@0"
            ]
        },
        {
            "x": -1,
            "y": 0,
            "z": 14,

            "elements": [
                "mekanism:reinforcedplasticblock@13",
                "ItemInput",
                "ItemOutput",
                "FluidInput"
            ]
        },
        {
            "x": 3,
            "y": 0,
            "z": 1,

            "elements": [
                "mekanism:reinforcedplasticblock@13",
                "ItemInput",
                "ItemOutput",
                "FluidInput"
            ]
        },
        {
            "x": -1,
            "y": 13,
            "z": 7,
            "elements": [
                "botania:dreamwood@0"
            ]
        },
        {
            "x": 3,
            "y": 0,
            "z": 13,

            "elements": [
                "mekanism:reinforcedplasticblock@13",
                "ItemInput",
                "ItemOutput",
                "FluidInput"
            ]
        },
        {
            "x": -4,
            "y": 0,
            "z": 2,

            "elements": [
                "mekanism:reinforcedplasticblock@13",
                "ItemInput",
                "ItemOutput",
                "FluidInput"
            ]
        },
        {
            "x": 4,
            "y": -1,
            "z": 12,
            "elements": [
                "botania:shimmerrock0stairs@5"
            ]
        },
        {
            "x": 2,
            "y": 10,
            "z": 10,
            "elements": [
                "botania:shimmerrock0slab@0"
            ]
        },
        {
            "x": 2,
            "y": 10,
            "z": 4,
            "elements": [
                "botania:shimmerrock0slab@0"
            ]
        },
        {
            "x": 2,
            "y": 10,
            "z": 3,
            "elements": [
                "botania:shimmerrock0stairs@1"
            ]
        },
        {
            "x": 4,
            "y": -1,
            "z": 4,
            "elements": [
                "botania:storage@2"
            ]
        },
        {
            "x": 4,
            "y": -1,
            "z": 5,
            "elements": [
                "extrabotany:blockshadowium@0"
            ]
        },
        {
            "x": -3,
            "y": -1,
            "z": 1,
            "elements": [
                "botania:shimmerrock0stairs@6"
            ]
        },
        {
            "x": 4,
            "y": -1,
            "z": 6,
            "elements": [
                "extrabotany:blockphotonium@0"
            ]
        },
        {
            "x": 4,
            "y": -1,
            "z": 7,
            "elements": [
                "enderio:block_alloy@8"
            ]
        },
        {
            "x": -3,
            "y": -1,
            "z": 2,
            "elements": [
                "botania:blazeblock@0"
            ]
        },
        {
            "x": 4,
            "y": -1,
            "z": 8,
            "elements": [
                "extrabotany:blockphotonium@0"
            ]
        },
        {
            "x": 1,
            "y": 11,
            "z": 7,
            "elements": [
                "botania:dreamwood0wall@0"
            ]
        },
        {
            "x": 4,
            "y": -1,
            "z": 9,
            "elements": [
                "extrabotany:blockshadowium@0"
            ]
        },
        {
            "x": 4,
            "y": -1,
            "z": 10,
            "elements": [
                "botania:storage@2"
            ]
        },
        {
            "x": 4,
            "y": -1,
            "z": 11,
            "elements": [
                "mekanism:reinforcedplasticblock@13"
            ]
        },
        {
            "x": 0,
            "y": 15,
            "z": 8,
            "elements": [
                "botania:dreamwood0wall@0"
            ]
        },
        {
            "x": 2,
            "y": 10,
            "z": 11,
            "elements": [
                "botania:shimmerrock0stairs@1"
            ]
        },
        {
            "x": -3,
            "y": -1,
            "z": 7,
            "elements": [
                "enderio:block_alloy@8"
            ]
        },
        {
            "x": 0,
            "y": 15,
            "z": 7,
            "elements": [
                "botania:bifrostperm@0"
            ]
        },
        {
            "x": -3,
            "y": -1,
            "z": 8,
            "elements": [
                "botania:storage@0"
            ]
        },
        {
            "x": 0,
            "y": 15,
            "z": 6,
            "elements": [
                "botania:dreamwood0wall@0"
            ]
        },
        {
            "x": -3,
            "y": -1,
            "z": 9,
            "elements": [
                "botania:storage@0"
            ]
        },
        {
            "x": -3,
            "y": -1,
            "z": 10,
            "elements": [
                "extrabotany:blockphotonium@0"
            ]
        },
        {
            "x": -3,
            "y": -1,
            "z": 3,
            "elements": [
                "botania:storage@2"
            ]
        },
        {
            "x": -3,
            "y": -1,
            "z": 4,
            "elements": [
                "extrabotany:blockphotonium@0"
            ]
        },
        {
            "x": 4,
            "y": -1,
            "z": 2,
            "elements": [
                "botania:shimmerrock0stairs@5"
            ]
        },
        {
            "x": -3,
            "y": -1,
            "z": 5,
            "elements": [
                "botania:storage@0"
            ]
        },
        {
            "x": -3,
            "y": -1,
            "z": 6,
            "elements": [
                "botania:storage@0"
            ]
        },
        {
            "x": 4,
            "y": -1,
            "z": 3,
            "elements": [
                "mekanism:reinforcedplasticblock@13"
            ]
        }
    ]}