{
    "registryname": "YMG_Rune_Well",
    "localizedname": "§b§lYMG§r§e§l—§f§l符文灵井 §r§e",
    "failure-action": "still",
    "requires-blueprint": false,
    "has-factory": true,
    "factory-only": true,
    "color": "FFFFFF",
    "parts": [
        {
            "x": -4,
            "y": 2,
            "z": 1,
            "elements": [
                "botania:petalblock@0"
            ]
        },
        {
            "x": 5,
            "y": 0,
            "z": 3,
            "elements": [
                "botania:managlasspane@0"
            ]
        },
        {
            "x": -4,
            "y": 2,
            "z": 2,
            "elements": [
                "astralsorcery:blockmarbleslab@0"
            ]
        },
        {
            "x": 5,
            "y": 0,
            "z": 0,
            "elements": [
                "astralsorcery:blockmarbleslab@0"
            ]
        },
        {
            "x": -4,
            "y": 2,
            "z": -1,
            "elements": [
                "botania:petalblock@0"
            ]
        },
        {
            "x": -4,
            "y": 2,
            "z": 0,
            "elements": [
                "astralsorcery:blockmarbleslab@0"
            ]
        },
        {
            "x": 5,
            "y": 0,
            "z": 1,
            "elements": [
                "botania:managlasspane@0"
            ]
        },
        {
            "x": 5,
            "y": 0,
            "z": -1,
            "elements": [
                "botania:managlasspane@0"
            ]
        },
        {
            "x": -4,
            "y": 2,
            "z": -2,
            "elements": [
                "astralsorcery:blockmarbleslab@0"
            ]
        },
        {
            "x": 5,
            "y": 0,
            "z": -3,
            "elements": [
                "botania:managlasspane@0"
            ]
        },
        {
            "x": -5,
            "y": 1,
            "z": 3,
            "elements": [
                "astralsorcery:blockmarbleslab@0"
            ]
        },
        {
            "x": -1,
            "y": 6,
            "z": 2,
            "elements": [
                "botania:petalblock@0"
            ]
        },
        {
            "x": -1,
            "y": 6,
            "z": 3,
            "elements": [
                "astralsorcery:blockmarbleslab@0"
            ]
        },
        {
            "x": -1,
            "y": 6,
            "z": -3,
            "elements": [
                "astralsorcery:blockmarbleslab@0"
            ]
        },
        {
            "x": -5,
            "y": 1,
            "z": -3,
            "elements": [
                "astralsorcery:blockmarbleslab@0"
            ]
        },
        {
            "x": -5,
            "y": 1,
            "z": -1,
            "elements": [
                "botania:managlasspane@0"
            ]
        },
        {
            "x": -1,
            "y": 6,
            "z": -2,
            "elements": [
                "botania:petalblock@0"
            ]
        },
        {
            "x": -5,
            "y": 1,
            "z": 1,
            "elements": [
                "botania:managlasspane@0"
            ]
        },
        {
            "x": 3,
            "y": -2,
            "z": 1,
            "elements": [
                "astralsorcery:blockmarbleslab@0"
            ]
        },
        {
            "x": 3,
            "y": -2,
            "z": 0,
            "elements": [
                "astralsorcery:blockmarbleslab@0"
            ]
        },
        {
            "x": 3,
            "y": -2,
            "z": -1,
            "elements": [
                "astralsorcery:blockmarbleslab@0"
            ]
        },
        {
            "x": 3,
            "y": -2,
            "z": 5,
            "elements": [
                "astralsorcery:blockmarblestairs@7"
            ]
        },
        {
            "x": 3,
            "y": -2,
            "z": 4,
            "elements": [
                "botania:petalblock@4"
            ]
        },
        {
            "x": 3,
            "y": -2,
            "z": -4,
            "elements": [
                "botania:petalblock@4"
            ]
        },
        {
            "x": 3,
            "y": -2,
            "z": -5,
            "elements": [
                "astralsorcery:blockmarblestairs@6"
            ]
        },
        {
            "x": -5,
            "y": 0,
            "z": 1,
            "elements": [
                "botania:managlasspane@0"
            ]
        },
        {
            "x": 4,
            "y": -2,
            "z": 1,
            "elements": [
                "botania:managlasspane@0"
            ]
        },
        {
            "x": -5,
            "y": 0,
            "z": 0,
            "elements": [
                "astralsorcery:blockmarbleslab@0"
            ]
        },
        {
            "x": -5,
            "y": 0,
            "z": 3,
            "elements": [
                "botania:managlasspane@0"
            ]
        },
        {
            "x": 4,
            "y": -2,
            "z": 3,
            "elements": [
                "botania:petalblock@4"
            ]
        },
        {
            "x": 4,
            "y": -2,
            "z": 4,
            "elements": [
                "astralsorcery:blockmarbleslab@0"
            ]
        },
        {
            "x": 4,
            "y": -2,
            "z": -3,
            "elements": [
                "botania:petalblock@4"
            ]
        },
        {
            "x": -5,
            "y": 0,
            "z": -3,
            "elements": [
                "botania:managlasspane@0"
            ]
        },
        {
            "x": -5,
            "y": 0,
            "z": -1,
            "elements": [
                "botania:managlasspane@0"
            ]
        },
        {
            "x": 4,
            "y": -2,
            "z": -1,
            "elements": [
                "botania:managlasspane@0"
            ]
        },
        {
            "x": 4,
            "y": -2,
            "z": 0,
            "elements": [
                "astralsorcery:blockmarblestairs@0"
            ]
        },
        {
            "x": 2,
            "y": -3,
            "z": 5,
            "elements": [
                "botania:petalblock@13"
            ]
        },
        {
            "x": 2,
            "y": -3,
            "z": 4,
            "elements": [
                "botania:petalblock@4"
            ]
        },
        {
            "x": 2,
            "y": -3,
            "z": 7,
            "elements": [
                "astralsorcery:blockmarblestairs@1"
            ]
        },
        {
            "x": 4,
            "y": -2,
            "z": -5,
            "elements": [
                "astralsorcery:blockmarbleslab@0"
            ]
        },
        {
            "x": 4,
            "y": -2,
            "z": -4,
            "elements": [
                "astralsorcery:blockmarbleslab@0"
            ]
        },
        {
            "x": 2,
            "y": -3,
            "z": 6,
            "elements": [
                "botania:petalblock@13"
            ]
        },
        {
            "x": 2,
            "y": -3,
            "z": 1,
            "elements": [
                "botania:petalblock@0"
            ]
        },
        {
            "x": 2,
            "y": -3,
            "z": 0,
            "elements": [
                "botania:petalblock@0"
            ]
        },
        {
            "x": 2,
            "y": -3,
            "z": 3,
            "elements": [
                "botania:petalblock@0"
            ]
        },
        {
            "x": 2,
            "y": -3,
            "z": 2,
            "elements": [
                "botania:petalblock@0"
            ]
        },
        {
            "x": 5,
            "y": -1,
            "z": 3,
            "elements": [
                "botania:managlasspane@0"
            ]
        },
        {
            "x": 4,
            "y": 0,
            "z": -1,
            "elements": [
                "botania:petalblock@0"
            ]
        },
        {
            "x": 4,
            "y": 0,
            "z": 0,
            "elements": [
                "astralsorcery:blockmarblestairs@1"
            ]
        },
        {
            "x": 4,
            "y": 0,
            "z": 1,
            "elements": [
                "botania:petalblock@0"
            ]
        },
        {
            "x": 4,
            "y": -2,
            "z": 5,
            "elements": [
                "astralsorcery:blockmarbleslab@0"
            ]
        },
        {
            "x": 4,
            "y": 0,
            "z": -3,
            "elements": [
                "botania:managlass@0"
            ]
        },
        {
            "x": -2,
            "y": 5,
            "z": 3,
            "elements": [
                "astralsorcery:blockmarblestairs@4"
            ]
        },
        {
            "x": -3,
            "y": 3,
            "z": -3,
            "elements": [
                "astralsorcery:blockmarbleslab@0"
            ]
        },
        {
            "x": -2,
            "y": 5,
            "z": 2,
            "elements": [
                "astralsorcery:blockmarbleslab@8"
            ]
        },
        {
            "x": -3,
            "y": 3,
            "z": -2,
            "elements": [
                "astralsorcery:blockmarbleslab@0"
            ]
        },
        {
            "x": -2,
            "y": 5,
            "z": -3,
            "elements": [
                "astralsorcery:blockmarblestairs@4"
            ]
        },
        {
            "x": -7,
            "y": -3,
            "z": 1,

            "elements": [
                "modularmachinery:blockcasing@0",
                "ItemInput",
                "ItemOutput",
                "FluidInput",
                "gugu-utils:sparkmanahatch@0"
            ]
        },
        {
            "x": -2,
            "y": 5,
            "z": -2,
            "elements": [
                "astralsorcery:blockmarbleslab@8"
            ]
        },
        {
            "x": -7,
            "y": -3,
            "z": 2,
            "elements": [
                "astralsorcery:blockmarblestairs@3"
            ]
        },
        {
            "x": -3,
            "y": 3,
            "z": 3,
            "elements": [
                "astralsorcery:blockmarbleslab@0"
            ]
        },
        {
            "x": 5,
            "y": -1,
            "z": -3,
            "elements": [
                "botania:managlasspane@0"
            ]
        },
        {
            "x": 5,
            "y": -1,
            "z": 1,
            "elements": [
                "botania:petalblock@0"
            ]
        },
        {
            "x": -3,
            "y": 3,
            "z": -1,
            "elements": [
                "botania:petalblock@0"
            ]
        },
        {
            "x": -3,
            "y": 3,
            "z": 0,
            "elements": [
                "botania:managlass@0"
            ]
        },
        {
            "x": -3,
            "y": 3,
            "z": 1,
            "elements": [
                "botania:petalblock@0"
            ]
        },
        {
            "x": 5,
            "y": -1,
            "z": -1,
            "elements": [
                "botania:petalblock@0"
            ]
        },
        {
            "x": -3,
            "y": 3,
            "z": 2,
            "elements": [
                "astralsorcery:blockmarbleslab@0"
            ]
        },
        {
            "x": 5,
            "y": -1,
            "z": 0,
            "elements": [
                "astralsorcery:blockmarblestairs@5"
            ]
        },
        {
            "x": 2,
            "y": -3,
            "z": -3,
            "elements": [
                "botania:petalblock@0"
            ]
        },
        {
            "x": 2,
            "y": -3,
            "z": -4,
            "elements": [
                "botania:petalblock@4"
            ]
        },
        {
            "x": 2,
            "y": -3,
            "z": -1,
            "elements": [
                "botania:petalblock@0"
            ]
        },
        {
            "x": 2,
            "y": -3,
            "z": -2,
            "elements": [
                "botania:petalblock@0"
            ]
        },
        {
            "x": 2,
            "y": -3,
            "z": -7,
            "elements": [
                "astralsorcery:blockmarblestairs@1"
            ]
        },
        {
            "x": 2,
            "y": -3,
            "z": -5,
            "elements": [
                "botania:petalblock@13"
            ]
        },
        {
            "x": 2,
            "y": -3,
            "z": -6,
            "elements": [
                "botania:petalblock@13"
            ]
        },
        {
            "x": -2,
            "y": 3,
            "z": -3,
            "elements": [
                "astralsorcery:blockmarbleslab@0"
            ]
        },
        {
            "x": 3,
            "y": -1,
            "z": 5,
            "elements": [
                "botania:managlasspane@0"
            ]
        },
        {
            "x": -5,
            "y": -1,
            "z": -3,
            "elements": [
                "botania:managlasspane@0"
            ]
        },
        {
            "x": -2,
            "y": 6,
            "z": 3,
            "elements": [
                "astralsorcery:blockmarblestairs@3"
            ]
        },
        {
            "x": 3,
            "y": -1,
            "z": 4,
            "elements": [
                "botania:managlass@0"
            ]
        },
        {
            "x": -5,
            "y": -1,
            "z": 0,
            "elements": [
                "astralsorcery:blockmarblestairs@4"
            ]
        },
        {
            "x": -5,
            "y": -1,
            "z": -1,
            "elements": [
                "botania:petalblock@0"
            ]
        },
        {
            "x": -5,
            "y": -1,
            "z": 1,
            "elements": [
                "botania:petalblock@0"
            ]
        },
        {
            "x": -5,
            "y": -1,
            "z": 3,
            "elements": [
                "botania:managlasspane@0"
            ]
        },
        {
            "x": 3,
            "y": -1,
            "z": -5,
            "elements": [
                "botania:managlasspane@0"
            ]
        },
        {
            "x": -2,
            "y": 3,
            "z": 3,
            "elements": [
                "astralsorcery:blockmarbleslab@0"
            ]
        },
        {
            "x": -2,
            "y": 3,
            "z": 2,
            "elements": [
                "botania:managlass@0"
            ]
        },
        {
            "x": 3,
            "y": -1,
            "z": -4,
            "elements": [
                "botania:managlass@0"
            ]
        },
        {
            "x": -4,
            "y": 4,
            "z": 1,
            "elements": [
                "botania:managlasspane@0"
            ]
        },
        {
            "x": -2,
            "y": 3,
            "z": -1,
            "elements": [
                "astralsorcery:blockmarblestairs@5"
            ]
        },
        {
            "x": -2,
            "y": 3,
            "z": -2,
            "elements": [
                "botania:managlass@0"
            ]
        },
        {
            "x": -2,
            "y": 3,
            "z": 1,
            "elements": [
                "astralsorcery:blockmarblestairs@5"
            ]
        },
        {
            "x": -4,
            "y": 4,
            "z": -1,
            "elements": [
                "botania:managlasspane@0"
            ]
        },
        {
            "x": -2,
            "y": 3,
            "z": 0,
            "elements": [
                "botania:managlass@0"
            ]
        },
        {
            "x": 4,
            "y": 1,
            "z": -3,
            "elements": [
                "astralsorcery:blockmarblestairs@2"
            ]
        },
        {
            "x": 4,
            "y": 0,
            "z": 3,
            "elements": [
                "botania:managlass@0"
            ]
        },
        {
            "x": 4,
            "y": 1,
            "z": -2,
            "elements": [
                "astralsorcery:blockmarbleslab@8"
            ]
        },
        {
            "x": 4,
            "y": 1,
            "z": -1,
            "elements": [
                "botania:petalblock@0"
            ]
        },
        {
            "x": 4,
            "y": 1,
            "z": 0,
            "elements": [
                "astralsorcery:blockmarblestairs@5"
            ]
        },
        {
            "x": 4,
            "y": 1,
            "z": 1,
            "elements": [
                "botania:petalblock@0"
            ]
        },
        {
            "x": 4,
            "y": 1,
            "z": 2,
            "elements": [
                "astralsorcery:blockmarbleslab@8"
            ]
        },
        {
            "x": 4,
            "y": 1,
            "z": 3,
            "elements": [
                "astralsorcery:blockmarblestairs@3"
            ]
        },
        {
            "x": -4,
            "y": 1,
            "z": -3,
            "elements": [
                "astralsorcery:blockmarblestairs@2"
            ]
        },
        {
            "x": -4,
            "y": 1,
            "z": 0,
            "elements": [
                "astralsorcery:blockmarblestairs@4"
            ]
        },
        {
            "x": 4,
            "y": -3,
            "z": -6,
            "elements": [
                "astralsorcery:blockmarblestairs@1"
            ]
        },
        {
            "x": 4,
            "y": -3,
            "z": -5,
            "elements": [
                "botania:petalblock@13"
            ]
        },
        {
            "x": -4,
            "y": 1,
            "z": 1,
            "elements": [
                "botania:petalblock@0"
            ]
        },
        {
            "x": 4,
            "y": -3,
            "z": -4,
            "elements": [
                "botania:petalblock@0"
            ]
        },
        {
            "x": -4,
            "y": 1,
            "z": -2,
            "elements": [
                "astralsorcery:blockmarbleslab@8"
            ]
        },
        {
            "x": -4,
            "y": 1,
            "z": -1,
            "elements": [
                "botania:petalblock@0"
            ]
        },
        {
            "x": 4,
            "y": -3,
            "z": -3,
            "elements": [
                "botania:petalblock@13"
            ]
        },
        {
            "x": -3,
            "y": 1,
            "z": 5,
            "elements": [
                "astralsorcery:blockmarbleslab@0"
            ]
        },
        {
            "x": 4,
            "y": -3,
            "z": -2,
            "elements": [
                "botania:petalblock@4"
            ]
        },
        {
            "x": 4,
            "y": -3,
            "z": -1,
            "elements": [
                "botania:petalblock@4"
            ]
        },
        {
            "x": -4,
            "y": 1,
            "z": 2,
            "elements": [
                "astralsorcery:blockmarbleslab@8"
            ]
        },
        {
            "x": 4,
            "y": -3,
            "z": 0,
            "elements": [
                "botania:petalblock@0"
            ]
        },
        {
            "x": -4,
            "y": 1,
            "z": 3,
            "elements": [
                "astralsorcery:blockmarblestairs@3"
            ]
        },
        {
            "x": 4,
            "y": -3,
            "z": 1,
            "elements": [
                "botania:petalblock@4"
            ]
        },
        {
            "x": 1,
            "y": 6,
            "z": 2,
            "elements": [
                "botania:petalblock@0"
            ]
        },
        {
            "x": 4,
            "y": -3,
            "z": 2,
            "elements": [
                "botania:petalblock@4"
            ]
        },
        {
            "x": 1,
            "y": 6,
            "z": 3,
            "elements": [
                "astralsorcery:blockmarbleslab@0"
            ]
        },
        {
            "x": 4,
            "y": -3,
            "z": 3,
            "elements": [
                "botania:petalblock@13"
            ]
        },
        {
            "x": 4,
            "y": -3,
            "z": 4,
            "elements": [
                "botania:petalblock@0"
            ]
        },
        {
            "x": -3,
            "y": 1,
            "z": 4,
            "elements": [
                "astralsorcery:blockmarblestairs@0"
            ]
        },
        {
            "x": 4,
            "y": -3,
            "z": 5,
            "elements": [
                "botania:petalblock@13"
            ]
        },
        {
            "x": 4,
            "y": -3,
            "z": 6,
            "elements": [
                "astralsorcery:blockmarblestairs@1"
            ]
        },
        {
            "x": 1,
            "y": 6,
            "z": -2,
            "elements": [
                "botania:petalblock@0"
            ]
        },
        {
            "x": 1,
            "y": 6,
            "z": -3,
            "elements": [
                "astralsorcery:blockmarbleslab@0"
            ]
        },
        {
            "x": -3,
            "y": 1,
            "z": 0,
            "elements": [
                "astralsorcery:blockmarblestairs@1"
            ]
        },
        {
            "x": -3,
            "y": 1,
            "z": -5,
            "elements": [
                "astralsorcery:blockmarbleslab@0"
            ]
        },
        {
            "x": -3,
            "y": 1,
            "z": -4,
            "elements": [
                "astralsorcery:blockmarblestairs@0"
            ]
        },
        {
            "x": -6,
            "y": -3,
            "z": 4,
            "elements": [
                "astralsorcery:blockmarblestairs@3"
            ]
        },
        {
            "x": -6,
            "y": -3,
            "z": 3,
            "elements": [
                "botania:petalblock@13"
            ]
        },
        {
            "x": -1,
            "y": 5,
            "z": -3,
            "elements": [
                "botania:petalblock@0"
            ]
        },
        {
            "x": -6,
            "y": -3,
            "z": 2,
            "elements": [
                "botania:petalblock@13"
            ]
        },
        {
            "x": -6,
            "y": -3,
            "z": 1,
            "elements": [
                "botania:petalblock@13"
            ]
        },
        {
            "x": -6,
            "y": -3,
            "z": 0,
            "elements": [
                "botania:petalblock@0"
            ]
        },
        {
            "x": -6,
            "y": -3,
            "z": -1,
            "elements": [
                "botania:petalblock@13"
            ]
        },
        {
            "x": -6,
            "y": -3,
            "z": -2,
            "elements": [
                "botania:petalblock@13"
            ]
        },
        {
            "x": -6,
            "y": -3,
            "z": -3,
            "elements": [
                "botania:petalblock@13"
            ]
        },
        {
            "x": -6,
            "y": -3,
            "z": -4,
            "elements": [
                "astralsorcery:blockmarblestairs@2"
            ]
        },
        {
            "x": -3,
            "y": 4,
            "z": 1,
            "elements": [
                "botania:petalblock@0"
            ]
        },
        {
            "x": -3,
            "y": 4,
            "z": 0,
            "elements": [
                "botania:managlass@0"
            ]
        },
        {
            "x": -3,
            "y": 4,
            "z": -1,
            "elements": [
                "botania:petalblock@0"
            ]
        },
        {
            "x": 2,
            "y": -1,
            "z": 0,
            "elements": [
                "botania:managlasspane@0"
            ]
        },
        {
            "x": -7,
            "y": -2,
            "z": -1,
            "elements": [
                "astralsorcery:blockmarbleslab@0"
            ]
        },
        {
            "x": -7,
            "y": -2,
            "z": 0,
            "elements": [
                "astralsorcery:blockmarblestairs@1"
            ]
        },
        {
            "x": -2,
            "y": 6,
            "z": -2,
            "elements": [
                "botania:petalblock@0"
            ]
        },
        {
            "x": -2,
            "y": 6,
            "z": -3,
            "elements": [
                "astralsorcery:blockmarblestairs@2"
            ]
        },
        {
            "x": -7,
            "y": -2,
            "z": 1,
            "elements": [
                "astralsorcery:blockmarbleslab@0"
            ]
        },
        {
            "x": -2,
            "y": 6,
            "z": 0,
            "elements": [
                "astralsorcery:blockmarbleslab@0"
            ]
        },
        {
            "x": -2,
            "y": 6,
            "z": -1,
            "elements": [
                "botania:petalblock@0"
            ]
        },
        {
            "x": 0,
            "y": 4,
            "z": 3,
            "elements": [
                "botania:managlass@0"
            ]
        },
        {
            "x": -2,
            "y": 6,
            "z": 2,
            "elements": [
                "botania:petalblock@0"
            ]
        },
        {
            "x": -2,
            "y": 6,
            "z": 1,
            "elements": [
                "botania:petalblock@0"
            ]
        },
        {
            "x": 1,
            "y": -3,
            "z": -4,
            "elements": [
                "botania:petalblock@4"
            ]
        },
        {
            "x": 1,
            "y": -3,
            "z": -5,
            "elements": [
                "botania:petalblock@13"
            ]
        },
        {
            "x": 1,
            "y": -3,
            "z": -6,
            "elements": [
                "botania:petalblock@13"
            ]
        },
        {
            "x": 1,
            "y": -3,
            "z": -7,

            "elements": [
                "modularmachinery:blockcasing@0",
                "ItemInput",
                "ItemOutput",
                "FluidInput",
                "gugu-utils:sparkmanahatch@0"
            ]
        },
        {
            "x": 1,
            "y": -3,
            "z": 0,
            "elements": [
                "botania:petalblock@4"
            ]
        },
        {
            "x": 1,
            "y": -3,
            "z": -1,
            "elements": [
                "botania:petalblock@0"
            ]
        },
        {
            "x": 1,
            "y": -3,
            "z": -2,
            "elements": [
                "botania:petalblock@0"
            ]
        },
        {
            "x": 1,
            "y": -3,
            "z": -3,
            "elements": [
                "botania:petalblock@4"
            ]
        },
        {
            "x": 1,
            "y": -3,
            "z": 4,
            "elements": [
                "botania:petalblock@4"
            ]
        },
        {
            "x": 1,
            "y": -3,
            "z": 3,
            "elements": [
                "botania:petalblock@4"
            ]
        },
        {
            "x": 1,
            "y": -3,
            "z": 2,
            "elements": [
                "botania:petalblock@0"
            ]
        },
        {
            "x": 1,
            "y": -3,
            "z": 1,
            "elements": [
                "botania:petalblock@0"
            ]
        },
        {
            "x": 1,
            "y": -3,
            "z": 7,

            "elements": [
                "modularmachinery:blockcasing@0",
                "ItemInput",
                "ItemOutput",
                "FluidInput",
                "gugu-utils:sparkmanahatch@0"
            ]
        },
        {
            "x": 1,
            "y": -3,
            "z": 6,
            "elements": [
                "botania:petalblock@13"
            ]
        },
        {
            "x": -1,
            "y": 5,
            "z": 3,
            "elements": [
                "botania:petalblock@0"
            ]
        },
        {
            "x": 1,
            "y": -3,
            "z": 5,
            "elements": [
                "botania:petalblock@13"
            ]
        },
        {
            "x": -3,
            "y": 0,
            "z": 4,
            "elements": [
                "botania:managlass@0"
            ]
        },
        {
            "x": -3,
            "y": 0,
            "z": 5,
            "elements": [
                "botania:managlasspane@0"
            ]
        },
        {
            "x": 3,
            "y": 1,
            "z": 0,
            "elements": [
                "astralsorcery:blockmarblestairs@0"
            ]
        },
        {
            "x": 4,
            "y": 2,
            "z": 1,
            "elements": [
                "botania:petalblock@0"
            ]
        },
        {
            "x": 4,
            "y": 2,
            "z": 2,
            "elements": [
                "astralsorcery:blockmarbleslab@0"
            ]
        },
        {
            "x": 3,
            "y": 1,
            "z": -5,
            "elements": [
                "astralsorcery:blockmarbleslab@0"
            ]
        },
        {
            "x": 3,
            "y": 1,
            "z": -4,
            "elements": [
                "astralsorcery:blockmarblestairs@1"
            ]
        },
        {
            "x": 4,
            "y": 2,
            "z": -2,
            "elements": [
                "astralsorcery:blockmarbleslab@0"
            ]
        },
        {
            "x": -2,
            "y": 1,
            "z": 4,
            "elements": [
                "astralsorcery:blockmarbleslab@8"
            ]
        },
        {
            "x": 4,
            "y": 2,
            "z": -1,
            "elements": [
                "botania:petalblock@0"
            ]
        },
        {
            "x": 4,
            "y": 2,
            "z": 0,
            "elements": [
                "astralsorcery:blockmarbleslab@0"
            ]
        },
        {
            "x": -2,
            "y": 1,
            "z": 0,
            "elements": [
                "astralsorcery:blockmarbleslab@0"
            ]
        },
        {
            "x": -3,
            "y": 0,
            "z": -5,
            "elements": [
                "botania:managlasspane@0"
            ]
        },
        {
            "x": -3,
            "y": 0,
            "z": -4,
            "elements": [
                "botania:managlass@0"
            ]
        },
        {
            "x": -1,
            "y": 3,
            "z": -4,
            "elements": [
                "botania:managlasspane@0"
            ]
        },
        {
            "x": -1,
            "y": 3,
            "z": 4,
            "elements": [
                "botania:managlasspane@0"
            ]
        },
        {
            "x": -1,
            "y": 3,
            "z": 3,
            "elements": [
                "botania:petalblock@0"
            ]
        },
        {
            "x": -1,
            "y": 3,
            "z": 2,
            "elements": [
                "astralsorcery:blockmarblestairs@6"
            ]
        },
        {
            "x": -2,
            "y": 1,
            "z": -4,
            "elements": [
                "astralsorcery:blockmarbleslab@8"
            ]
        },
        {
            "x": 5,
            "y": -3,
            "z": 5,
            "elements": [
                "botania:petalblock@13"
            ]
        },
        {
            "x": -1,
            "y": 3,
            "z": 1,
            "elements": [
                "astralsorcery:blockmarbleslab@8"
            ]
        },
        {
            "x": -1,
            "y": 3,
            "z": 0,
            "elements": [
                "botania:managlass@0"
            ]
        },
        {
            "x": -1,
            "y": 3,
            "z": -1,
            "elements": [
                "astralsorcery:blockmarbleslab@8"
            ]
        },
        {
            "x": -1,
            "y": 3,
            "z": -2,
            "elements": [
                "astralsorcery:blockmarblestairs@7"
            ]
        },
        {
            "x": -1,
            "y": 3,
            "z": -3,
            "elements": [
                "botania:petalblock@0"
            ]
        },
        {
            "x": 5,
            "y": -3,
            "z": -1,
            "elements": [
                "botania:petalblock@13"
            ]
        },
        {
            "x": 5,
            "y": -3,
            "z": 0,
            "elements": [
                "botania:petalblock@0"
            ]
        },
        {
            "x": 5,
            "y": -3,
            "z": -3,
            "elements": [
                "botania:petalblock@13"
            ]
        },
        {
            "x": 5,
            "y": -3,
            "z": -2,
            "elements": [
                "botania:petalblock@13"
            ]
        },
        {
            "x": 3,
            "y": 1,
            "z": 5,
            "elements": [
                "astralsorcery:blockmarbleslab@0"
            ]
        },
        {
            "x": 5,
            "y": -3,
            "z": 3,
            "elements": [
                "botania:petalblock@13"
            ]
        },
        {
            "x": 5,
            "y": -3,
            "z": 4,
            "elements": [
                "botania:petalblock@13"
            ]
        },
        {
            "x": 5,
            "y": -3,
            "z": 1,
            "elements": [
                "botania:petalblock@13"
            ]
        },
        {
            "x": 3,
            "y": 1,
            "z": 4,
            "elements": [
                "astralsorcery:blockmarblestairs@1"
            ]
        },
        {
            "x": 5,
            "y": -3,
            "z": 2,
            "elements": [
                "botania:petalblock@13"
            ]
        },
        {
            "x": -4,
            "y": -2,
            "z": 5,
            "elements": [
                "astralsorcery:blockmarbleslab@0"
            ]
        },
        {
            "x": -4,
            "y": -2,
            "z": 4,
            "elements": [
                "astralsorcery:blockmarbleslab@0"
            ]
        },
        {
            "x": -4,
            "y": -2,
            "z": 3,
            "elements": [
                "botania:petalblock@4"
            ]
        },
        {
            "x": -4,
            "y": -2,
            "z": 1,
            "elements": [
                "botania:managlasspane@0"
            ]
        },
        {
            "x": 5,
            "y": -3,
            "z": -5,
            "elements": [
                "botania:petalblock@13"
            ]
        },
        {
            "x": -4,
            "y": -2,
            "z": 0,
            "elements": [
                "astralsorcery:blockmarblestairs@1"
            ]
        },
        {
            "x": 5,
            "y": -3,
            "z": -4,
            "elements": [
                "botania:petalblock@13"
            ]
        },
        {
            "x": -4,
            "y": -2,
            "z": -1,
            "elements": [
                "botania:managlasspane@0"
            ]
        },
        {
            "x": -4,
            "y": -2,
            "z": -3,
            "elements": [
                "botania:petalblock@4"
            ]
        },
        {
            "x": -4,
            "y": -2,
            "z": -4,
            "elements": [
                "astralsorcery:blockmarbleslab@0"
            ]
        },
        {
            "x": 4,
            "y": 3,
            "z": -1,
            "elements": [
                "botania:managlasspane@0"
            ]
        },
        {
            "x": -4,
            "y": -2,
            "z": -5,
            "elements": [
                "astralsorcery:blockmarbleslab@0"
            ]
        },
        {
            "x": 4,
            "y": 3,
            "z": 1,
            "elements": [
                "botania:managlasspane@0"
            ]
        },
        {
            "x": 0,
            "y": 5,
            "z": 3,
            "elements": [
                "botania:managlass@0"
            ]
        },
        {
            "x": 0,
            "y": 5,
            "z": -3,
            "elements": [
                "botania:managlass@0"
            ]
        },
        {
            "x": 0,
            "y": 5,
            "z": 0,

            "elements": [
                "botania:pylon@2"
            ]
        },
        {
            "x": -3,
            "y": 6,
            "z": 2,
            "elements": [
                "astralsorcery:blockmarblestairs@0"
            ]
        },
        {
            "x": -3,
            "y": 6,
            "z": 1,
            "elements": [
                "astralsorcery:blockmarbleslab@0"
            ]
        },
        {
            "x": -3,
            "y": 6,
            "z": -1,
            "elements": [
                "astralsorcery:blockmarbleslab@0"
            ]
        },
        {
            "x": -2,
            "y": 2,
            "z": -4,
            "elements": [
                "astralsorcery:blockmarbleslab@0"
            ]
        },
        {
            "x": -3,
            "y": 6,
            "z": -2,
            "elements": [
                "astralsorcery:blockmarblestairs@0"
            ]
        },
        {
            "x": -2,
            "y": 2,
            "z": -3,
            "elements": [
                "botania:petalblock@4"
            ]
        },
        {
            "x": -2,
            "y": 2,
            "z": 4,
            "elements": [
                "astralsorcery:blockmarbleslab@0"
            ]
        },
        {
            "x": -2,
            "y": 2,
            "z": 3,
            "elements": [
                "botania:petalblock@4"
            ]
        },
        {
            "x": -3,
            "y": 5,
            "z": 0,
            "elements": [
                "botania:managlass@0"
            ]
        },
        {
            "x": 2,
            "y": -2,
            "z": 0,
            "elements": [
                "botania:managlasspane@0"
            ]
        },
        {
            "x": 2,
            "y": -2,
            "z": -1,
            "elements": [
                "astralsorcery:blockmarblestairs@1"
            ]
        },
        {
            "x": -3,
            "y": 5,
            "z": -1,
            "elements": [
                "botania:petalblock@0"
            ]
        },
        {
            "x": -3,
            "y": 5,
            "z": -2,
            "elements": [
                "astralsorcery:blockmarblestairs@6"
            ]
        },
        {
            "x": -4,
            "y": -3,
            "z": 6,
            "elements": [
                "astralsorcery:blockmarblestairs@0"
            ]
        },
        {
            "x": 2,
            "y": -2,
            "z": 1,
            "elements": [
                "astralsorcery:blockmarblestairs@1"
            ]
        },
        {
            "x": -6,
            "y": -2,
            "z": -2,
            "elements": [
                "astralsorcery:blockmarbleslab@0"
            ]
        },
        {
            "x": -3,
            "y": 5,
            "z": 2,
            "elements": [
                "astralsorcery:blockmarblestairs@7"
            ]
        },
        {
            "x": 2,
            "y": -2,
            "z": 6,
            "elements": [
                "astralsorcery:blockmarbleslab@0"
            ]
        },
        {
            "x": -3,
            "y": 5,
            "z": 1,
            "elements": [
                "botania:petalblock@0"
            ]
        },
        {
            "x": 2,
            "y": -2,
            "z": 5,
            "elements": [
                "astralsorcery:blockmarblestairs@3"
            ]
        },
        {
            "x": 3,
            "y": 6,
            "z": -1,
            "elements": [
                "astralsorcery:blockmarbleslab@0"
            ]
        },
        {
            "x": 3,
            "y": 6,
            "z": -2,
            "elements": [
                "astralsorcery:blockmarblestairs@1"
            ]
        },
        {
            "x": 3,
            "y": 6,
            "z": 1,
            "elements": [
                "astralsorcery:blockmarbleslab@0"
            ]
        },
        {
            "x": 0,
            "y": -1,
            "z": -5,
            "elements": [
                "astralsorcery:blockmarblestairs@6"
            ]
        },
        {
            "x": 2,
            "y": -2,
            "z": -6,
            "elements": [
                "astralsorcery:blockmarbleslab@0"
            ]
        },
        {
            "x": 3,
            "y": 6,
            "z": 2,
            "elements": [
                "astralsorcery:blockmarblestairs@1"
            ]
        },
        {
            "x": 2,
            "y": -2,
            "z": -5,
            "elements": [
                "astralsorcery:blockmarblestairs@2"
            ]
        },
        {
            "x": 0,
            "y": -1,
            "z": -2,
            "elements": [
                "botania:managlasspane@0"
            ]
        },
        {
            "x": -1,
            "y": 4,
            "z": -3,
            "elements": [
                "botania:petalblock@0"
            ]
        },
        {
            "x": -1,
            "y": 4,
            "z": -4,
            "elements": [
                "botania:managlasspane@0"
            ]
        },
        {
            "x": -1,
            "y": 4,
            "z": 3,
            "elements": [
                "botania:petalblock@0"
            ]
        },
        {
            "x": -4,
            "y": -3,
            "z": -3,
            "elements": [
                "botania:petalblock@13"
            ]
        },
        {
            "x": -4,
            "y": -3,
            "z": -4,
            "elements": [
                "botania:petalblock@0"
            ]
        },
        {
            "x": -4,
            "y": -3,
            "z": -5,
            "elements": [
                "botania:petalblock@13"
            ]
        },
        {
            "x": -4,
            "y": -3,
            "z": -6,
            "elements": [
                "astralsorcery:blockmarblestairs@0"
            ]
        },
        {
            "x": -7,
            "y": -3,
            "z": -1,

            "elements": [
                "modularmachinery:blockcasing@0",
                "ItemInput",
                "ItemOutput",
                "FluidInput",
                "gugu-utils:sparkmanahatch@0"
            ]
        },
        {
            "x": -4,
            "y": -3,
            "z": 1,
            "elements": [
                "botania:petalblock@4"
            ]
        },
        {
            "x": -6,
            "y": -2,
            "z": 2,
            "elements": [
                "astralsorcery:blockmarbleslab@0"
            ]
        },
        {
            "x": -6,
            "y": -2,
            "z": 1,
            "elements": [
                "astralsorcery:blockmarblestairs@0"
            ]
        },
        {
            "x": -4,
            "y": -3,
            "z": 0,
            "elements": [
                "botania:petalblock@0"
            ]
        },
        {
            "x": -7,
            "y": -3,
            "z": 0,

            "elements": [
                "modularmachinery:blockcasing@0",
                "ItemInput",
                "ItemOutput",
                "FluidInput",
                "gugu-utils:sparkmanahatch@0"
            ]
        },
        {
            "x": -4,
            "y": -3,
            "z": -1,
            "elements": [
                "botania:petalblock@4"
            ]
        },
        {
            "x": -6,
            "y": -2,
            "z": 0,
            "elements": [
                "astralsorcery:blockmarbleslab@0"
            ]
        },
        {
            "x": -4,
            "y": -3,
            "z": -2,
            "elements": [
                "botania:petalblock@4"
            ]
        },
        {
            "x": -7,
            "y": -3,
            "z": -2,
            "elements": [
                "astralsorcery:blockmarblestairs@2"
            ]
        },
        {
            "x": -1,
            "y": 4,
            "z": 4,
            "elements": [
                "botania:managlasspane@0"
            ]
        },
        {
            "x": -6,
            "y": -2,
            "z": -1,
            "elements": [
                "astralsorcery:blockmarblestairs@0"
            ]
        },
        {
            "x": -4,
            "y": -3,
            "z": 5,
            "elements": [
                "botania:petalblock@13"
            ]
        },
        {
            "x": -4,
            "y": -3,
            "z": 4,
            "elements": [
                "botania:petalblock@0"
            ]
        },
        {
            "x": -4,
            "y": -3,
            "z": 3,
            "elements": [
                "botania:petalblock@13"
            ]
        },
        {
            "x": -4,
            "y": -3,
            "z": 2,
            "elements": [
                "botania:petalblock@4"
            ]
        },
        {
            "x": 0,
            "y": 6,
            "z": -2,
            "elements": [
                "astralsorcery:blockmarbleslab@0"
            ]
        },
        {
            "x": 0,
            "y": -1,
            "z": 0,
            "elements": [
                "astralsorcery:blockmarble@2"
            ]
        },
        {
            "x": 0,
            "y": -1,
            "z": 2,
            "elements": [
                "botania:managlasspane@0"
            ]
        },
        {
            "x": 0,
            "y": -1,
            "z": 5,
            "elements": [
                "astralsorcery:blockmarblestairs@7"
            ]
        },
        {
            "x": 0,
            "y": 6,
            "z": 2,
            "elements": [
                "astralsorcery:blockmarbleslab@0"
            ]
        },
        {
            "x": 3,
            "y": 0,
            "z": 4,
            "elements": [
                "botania:managlass@0"
            ]
        },
        {
            "x": 3,
            "y": 0,
            "z": 5,
            "elements": [
                "botania:managlasspane@0"
            ]
        },
        {
            "x": -4,
            "y": 3,
            "z": -1,
            "elements": [
                "botania:managlasspane@0"
            ]
        },
        {
            "x": 3,
            "y": 0,
            "z": -4,
            "elements": [
                "botania:managlass@0"
            ]
        },
        {
            "x": -1,
            "y": -3,
            "z": -7,

            "elements": [
                "modularmachinery:blockcasing@0",
                "ItemInput",
                "ItemOutput",
                "FluidInput",
                "gugu-utils:sparkmanahatch@0"
            ]
        },
        {
            "x": -1,
            "y": -3,
            "z": -6,
            "elements": [
                "botania:petalblock@13"
            ]
        },
        {
            "x": -1,
            "y": -3,
            "z": -5,
            "elements": [
                "botania:petalblock@13"
            ]
        },
        {
            "x": -1,
            "y": -3,
            "z": -4,
            "elements": [
                "botania:petalblock@4"
            ]
        },
        {
            "x": -1,
            "y": -3,
            "z": -3,
            "elements": [
                "botania:petalblock@4"
            ]
        },
        {
            "x": -1,
            "y": -3,
            "z": -2,
            "elements": [
                "botania:petalblock@0"
            ]
        },
        {
            "x": -1,
            "y": -3,
            "z": -1,
            "elements": [
                "botania:petalblock@0"
            ]
        },
        {
            "x": -1,
            "y": -3,
            "z": 0,
            "elements": [
                "botania:petalblock@4"
            ]
        },
        {
            "x": -1,
            "y": -3,
            "z": 1,
            "elements": [
                "botania:petalblock@0"
            ]
        },
        {
            "x": -1,
            "y": -3,
            "z": 2,
            "elements": [
                "botania:petalblock@0"
            ]
        },
        {
            "x": -1,
            "y": -3,
            "z": 3,
            "elements": [
                "botania:petalblock@4"
            ]
        },
        {
            "x": -1,
            "y": -3,
            "z": 4,
            "elements": [
                "botania:petalblock@4"
            ]
        },
        {
            "x": -1,
            "y": -3,
            "z": 5,
            "elements": [
                "botania:petalblock@13"
            ]
        },
        {
            "x": -1,
            "y": -3,
            "z": 6,
            "elements": [
                "botania:petalblock@13"
            ]
        },
        {
            "x": -1,
            "y": -3,
            "z": 7,

            "elements": [
                "modularmachinery:blockcasing@0",
                "ItemInput",
                "ItemOutput",
                "FluidInput",
                "gugu-utils:sparkmanahatch@0"
            ]
        },
        {
            "x": 5,
            "y": -2,
            "z": 2,
            "elements": [
                "astralsorcery:blockmarblestairs@1"
            ]
        },
        {
            "x": 5,
            "y": -2,
            "z": 3,
            "elements": [
                "astralsorcery:blockmarblestairs@5"
            ]
        },
        {
            "x": 5,
            "y": -2,
            "z": 0,
            "elements": [
                "astralsorcery:blockmarblestairs@1"
            ]
        },
        {
            "x": 5,
            "y": -2,
            "z": 1,
            "elements": [
                "botania:petalblock@0"
            ]
        },
        {
            "x": 5,
            "y": -2,
            "z": -2,
            "elements": [
                "astralsorcery:blockmarblestairs@1"
            ]
        },
        {
            "x": 5,
            "y": -2,
            "z": -1,
            "elements": [
                "botania:petalblock@0"
            ]
        },
        {
            "x": 5,
            "y": -2,
            "z": -4,
            "elements": [
                "astralsorcery:blockmarbleslab@0"
            ]
        },
        {
            "x": 5,
            "y": -2,
            "z": -3,
            "elements": [
                "astralsorcery:blockmarblestairs@5"
            ]
        },
        {
            "x": 5,
            "y": -2,
            "z": 4,
            "elements": [
                "astralsorcery:blockmarbleslab@0"
            ]
        },
        {
            "x": -3,
            "y": -1,
            "z": -5,
            "elements": [
                "botania:managlasspane@0"
            ]
        },
        {
            "x": 3,
            "y": 0,
            "z": -5,
            "elements": [
                "botania:managlasspane@0"
            ]
        },
        {
            "x": -3,
            "y": -1,
            "z": -4,
            "elements": [
                "botania:managlass@0"
            ]
        },
        {
            "x": -4,
            "y": 3,
            "z": 1,
            "elements": [
                "botania:managlasspane@0"
            ]
        },
        {
            "x": -3,
            "y": -1,
            "z": 4,
            "elements": [
                "botania:managlass@0"
            ]
        },
        {
            "x": -3,
            "y": -1,
            "z": 5,
            "elements": [
                "botania:managlasspane@0"
            ]
        },
        {
            "x": 2,
            "y": 3,
            "z": -2,
            "elements": [
                "botania:managlass@0"
            ]
        },
        {
            "x": 2,
            "y": 3,
            "z": -1,
            "elements": [
                "astralsorcery:blockmarblestairs@4"
            ]
        },
        {
            "x": -2,
            "y": -2,
            "z": -5,
            "elements": [
                "astralsorcery:blockmarblestairs@2"
            ]
        },
        {
            "x": 2,
            "y": 3,
            "z": 0,
            "elements": [
                "botania:managlass@0"
            ]
        },
        {
            "x": 2,
            "y": 3,
            "z": 1,
            "elements": [
                "astralsorcery:blockmarblestairs@4"
            ]
        },
        {
            "x": -2,
            "y": -2,
            "z": 1,
            "elements": [
                "astralsorcery:blockmarblestairs@0"
            ]
        },
        {
            "x": -2,
            "y": -2,
            "z": -1,
            "elements": [
                "astralsorcery:blockmarblestairs@0"
            ]
        },
        {
            "x": -2,
            "y": -2,
            "z": 0,
            "elements": [
                "botania:managlasspane@0"
            ]
        },
        {
            "x": 2,
            "y": 3,
            "z": -3,
            "elements": [
                "astralsorcery:blockmarbleslab@0"
            ]
        },
        {
            "x": -2,
            "y": -2,
            "z": 5,
            "elements": [
                "astralsorcery:blockmarblestairs@3"
            ]
        },
        {
            "x": -2,
            "y": -2,
            "z": 6,
            "elements": [
                "astralsorcery:blockmarbleslab@0"
            ]
        },
        {
            "x": 2,
            "y": 3,
            "z": 2,
            "elements": [
                "botania:managlass@0"
            ]
        },
        {
            "x": 2,
            "y": 3,
            "z": 3,
            "elements": [
                "astralsorcery:blockmarbleslab@0"
            ]
        },
        {
            "x": -3,
            "y": -3,
            "z": -6,
            "elements": [
                "botania:petalblock@13"
            ]
        },
        {
            "x": 3,
            "y": 4,
            "z": 0,
            "elements": [
                "botania:managlass@0"
            ]
        },
        {
            "x": -3,
            "y": -3,
            "z": -5,
            "elements": [
                "botania:petalblock@13"
            ]
        },
        {
            "x": -3,
            "y": -3,
            "z": -4,
            "elements": [
                "botania:petalblock@13"
            ]
        },
        {
            "x": 3,
            "y": 4,
            "z": 1,
            "elements": [
                "botania:petalblock@0"
            ]
        },
        {
            "x": -1,
            "y": -1,
            "z": 4,
            "elements": [
                "botania:managlasspane@0"
            ]
        },
        {
            "x": -1,
            "y": -1,
            "z": 5,
            "elements": [
                "botania:petalblock@0"
            ]
        },
        {
            "x": -1,
            "y": -1,
            "z": -5,
            "elements": [
                "botania:petalblock@0"
            ]
        },
        {
            "x": -1,
            "y": -1,
            "z": -4,
            "elements": [
                "botania:managlasspane@0"
            ]
        },
        {
            "x": -2,
            "y": -2,
            "z": -6,
            "elements": [
                "astralsorcery:blockmarbleslab@0"
            ]
        },
        {
            "x": 3,
            "y": 4,
            "z": -1,
            "elements": [
                "botania:petalblock@0"
            ]
        },
        {
            "x": 0,
            "y": 0,
            "z": 4,
            "elements": [
                "astralsorcery:blockmarblestairs@3"
            ]
        },
        {
            "x": 0,
            "y": 0,
            "z": 5,
            "elements": [
                "astralsorcery:blockmarbleslab@0"
            ]
        },
        {
            "x": 0,
            "y": 0,
            "z": 0,

            "elements": [
                "modularmachinery:blockcontroller@2"
            ]
        },
        {
            "x": -3,
            "y": -3,
            "z": 5,
            "elements": [
                "botania:petalblock@13"
            ]
        },
        {
            "x": -3,
            "y": -3,
            "z": 6,
            "elements": [
                "botania:petalblock@13"
            ]
        },
        {
            "x": 0,
            "y": 0,
            "z": 2,
            "elements": [
                "astralsorcery:blockmarblestairs@6"
            ]
        },
        {
            "x": 1,
            "y": 2,
            "z": 4,
            "elements": [
                "botania:petalblock@0"
            ]
        },
        {
            "x": 0,
            "y": 0,
            "z": -4,
            "elements": [
                "astralsorcery:blockmarblestairs@2"
            ]
        },
        {
            "x": -3,
            "y": -3,
            "z": 1,
            "elements": [
                "botania:petalblock@4"
            ]
        },
        {
            "x": 0,
            "y": 0,
            "z": -5,
            "elements": [
                "astralsorcery:blockmarbleslab@0"
            ]
        },
        {
            "x": -3,
            "y": -3,
            "z": 2,
            "elements": [
                "botania:petalblock@0"
            ]
        },
        {
            "x": -3,
            "y": -3,
            "z": 3,
            "elements": [
                "botania:petalblock@0"
            ]
        },
        {
            "x": 0,
            "y": 0,
            "z": -2,
            "elements": [
                "astralsorcery:blockmarblestairs@7"
            ]
        },
        {
            "x": -3,
            "y": -3,
            "z": 4,
            "elements": [
                "botania:petalblock@13"
            ]
        },
        {
            "x": -3,
            "y": -3,
            "z": -3,
            "elements": [
                "botania:petalblock@0"
            ]
        },
        {
            "x": -3,
            "y": -3,
            "z": -2,
            "elements": [
                "botania:petalblock@0"
            ]
        },
        {
            "x": -3,
            "y": -3,
            "z": -1,
            "elements": [
                "botania:petalblock@4"
            ]
        },
        {
            "x": 1,
            "y": 2,
            "z": -4,
            "elements": [
                "botania:petalblock@0"
            ]
        },
        {
            "x": -3,
            "y": -3,
            "z": 0,
            "elements": [
                "botania:petalblock@0"
            ]
        },
        {
            "x": -1,
            "y": 0,
            "z": -5,
            "elements": [
                "botania:managlasspane@0"
            ]
        },
        {
            "x": 3,
            "y": 5,
            "z": -2,
            "elements": [
                "astralsorcery:blockmarblestairs@6"
            ]
        },
        {
            "x": -1,
            "y": 0,
            "z": -4,
            "elements": [
                "botania:petalblock@0"
            ]
        },
        {
            "x": 1,
            "y": 1,
            "z": -4,
            "elements": [
                "botania:petalblock@0"
            ]
        },
        {
            "x": -2,
            "y": -3,
            "z": 6,
            "elements": [
                "botania:petalblock@13"
            ]
        },
        {
            "x": 3,
            "y": 5,
            "z": 0,
            "elements": [
                "botania:managlass@0"
            ]
        },
        {
            "x": -2,
            "y": -3,
            "z": 7,
            "elements": [
                "astralsorcery:blockmarblestairs@0"
            ]
        },
        {
            "x": 3,
            "y": 5,
            "z": -1,
            "elements": [
                "botania:petalblock@0"
            ]
        },
        {
            "x": 1,
            "y": 1,
            "z": -5,
            "elements": [
                "botania:managlasspane@0"
            ]
        },
        {
            "x": 3,
            "y": 5,
            "z": 2,
            "elements": [
                "astralsorcery:blockmarblestairs@7"
            ]
        },
        {
            "x": -2,
            "y": -3,
            "z": 4,
            "elements": [
                "botania:petalblock@4"
            ]
        },
        {
            "x": 3,
            "y": 5,
            "z": 1,
            "elements": [
                "botania:petalblock@0"
            ]
        },
        {
            "x": -2,
            "y": -3,
            "z": 5,
            "elements": [
                "botania:petalblock@13"
            ]
        },
        {
            "x": 1,
            "y": 1,
            "z": 4,
            "elements": [
                "botania:petalblock@0"
            ]
        },
        {
            "x": 7,
            "y": -3,
            "z": 0,

            "elements": [
                "modularmachinery:blockcasing@0",
                "ItemInput",
                "ItemOutput",
                "FluidInput",
                "gugu-utils:sparkmanahatch@0"
            ]
        },
        {
            "x": 7,
            "y": -3,
            "z": -1,

            "elements": [
                "modularmachinery:blockcasing@0",
                "ItemInput",
                "ItemOutput",
                "FluidInput",
                "gugu-utils:sparkmanahatch@0"
            ]
        },
        {
            "x": 7,
            "y": -3,
            "z": 2,
            "elements": [
                "astralsorcery:blockmarblestairs@3"
            ]
        },
        {
            "x": 1,
            "y": 1,
            "z": 5,
            "elements": [
                "botania:managlasspane@0"
            ]
        },
        {
            "x": 7,
            "y": -3,
            "z": 1,

            "elements": [
                "modularmachinery:blockcasing@0",
                "ItemInput",
                "ItemOutput",
                "FluidInput",
                "gugu-utils:sparkmanahatch@0"
            ]
        },
        {
            "x": 7,
            "y": -3,
            "z": -2,
            "elements": [
                "astralsorcery:blockmarblestairs@2"
            ]
        },
        {
            "x": -1,
            "y": -2,
            "z": -2,
            "elements": [
                "astralsorcery:blockmarblestairs@2"
            ]
        },
        {
            "x": -1,
            "y": -2,
            "z": -6,
            "elements": [
                "astralsorcery:blockmarblestairs@2"
            ]
        },
        {
            "x": -1,
            "y": -2,
            "z": -5,
            "elements": [
                "botania:petalblock@0"
            ]
        },
        {
            "x": -1,
            "y": -2,
            "z": -4,
            "elements": [
                "botania:managlasspane@0"
            ]
        },
        {
            "x": -1,
            "y": -2,
            "z": -3,
            "elements": [
                "astralsorcery:blockmarbleslab@0"
            ]
        },
        {
            "x": -1,
            "y": -2,
            "z": -7,
            "elements": [
                "astralsorcery:blockmarbleslab@0"
            ]
        },
        {
            "x": -2,
            "y": -1,
            "z": 0,
            "elements": [
                "botania:managlasspane@0"
            ]
        },
        {
            "x": -1,
            "y": -2,
            "z": 6,
            "elements": [
                "astralsorcery:blockmarblestairs@3"
            ]
        },
        {
            "x": -1,
            "y": -2,
            "z": 7,
            "elements": [
                "astralsorcery:blockmarbleslab@0"
            ]
        },
        {
            "x": -1,
            "y": -2,
            "z": 2,
            "elements": [
                "astralsorcery:blockmarblestairs@3"
            ]
        },
        {
            "x": -1,
            "y": -2,
            "z": 3,
            "elements": [
                "astralsorcery:blockmarbleslab@0"
            ]
        },
        {
            "x": -1,
            "y": -2,
            "z": 4,
            "elements": [
                "botania:managlasspane@0"
            ]
        },
        {
            "x": -1,
            "y": -2,
            "z": 5,
            "elements": [
                "botania:petalblock@0"
            ]
        },
        {
            "x": 1,
            "y": 0,
            "z": 5,
            "elements": [
                "botania:managlasspane@0"
            ]
        },
        {
            "x": 1,
            "y": 0,
            "z": 4,
            "elements": [
                "botania:petalblock@0"
            ]
        },
        {
            "x": -3,
            "y": -2,
            "z": 4,
            "elements": [
                "botania:petalblock@4"
            ]
        },
        {
            "x": 1,
            "y": 0,
            "z": -4,
            "elements": [
                "botania:petalblock@0"
            ]
        },
        {
            "x": -3,
            "y": -2,
            "z": 5,
            "elements": [
                "astralsorcery:blockmarblestairs@7"
            ]
        },
        {
            "x": 1,
            "y": 0,
            "z": -5,
            "elements": [
                "botania:managlasspane@0"
            ]
        },
        {
            "x": 1,
            "y": 3,
            "z": 3,
            "elements": [
                "botania:petalblock@0"
            ]
        },
        {
            "x": 1,
            "y": 3,
            "z": 4,
            "elements": [
                "botania:managlasspane@0"
            ]
        },
        {
            "x": -3,
            "y": -2,
            "z": -4,
            "elements": [
                "botania:petalblock@4"
            ]
        },
        {
            "x": 1,
            "y": 3,
            "z": -3,
            "elements": [
                "botania:petalblock@0"
            ]
        },
        {
            "x": 1,
            "y": 3,
            "z": -2,
            "elements": [
                "astralsorcery:blockmarblestairs@7"
            ]
        },
        {
            "x": 1,
            "y": 3,
            "z": -4,
            "elements": [
                "botania:managlasspane@0"
            ]
        },
        {
            "x": -3,
            "y": -2,
            "z": -1,
            "elements": [
                "astralsorcery:blockmarbleslab@0"
            ]
        },
        {
            "x": 1,
            "y": 3,
            "z": 1,
            "elements": [
                "astralsorcery:blockmarbleslab@8"
            ]
        },
        {
            "x": -3,
            "y": -2,
            "z": 0,
            "elements": [
                "astralsorcery:blockmarbleslab@0"
            ]
        },
        {
            "x": 1,
            "y": 3,
            "z": 2,
            "elements": [
                "astralsorcery:blockmarblestairs@6"
            ]
        },
        {
            "x": -3,
            "y": -2,
            "z": 1,
            "elements": [
                "astralsorcery:blockmarbleslab@0"
            ]
        },
        {
            "x": 2,
            "y": 5,
            "z": 2,
            "elements": [
                "astralsorcery:blockmarbleslab@8"
            ]
        },
        {
            "x": 1,
            "y": 3,
            "z": -1,
            "elements": [
                "astralsorcery:blockmarbleslab@8"
            ]
        },
        {
            "x": 2,
            "y": 5,
            "z": 3,
            "elements": [
                "astralsorcery:blockmarblestairs@5"
            ]
        },
        {
            "x": 1,
            "y": 3,
            "z": 0,
            "elements": [
                "botania:managlass@0"
            ]
        },
        {
            "x": 2,
            "y": 5,
            "z": -3,
            "elements": [
                "astralsorcery:blockmarblestairs@5"
            ]
        },
        {
            "x": 2,
            "y": 5,
            "z": -2,
            "elements": [
                "astralsorcery:blockmarbleslab@8"
            ]
        },
        {
            "x": -2,
            "y": 0,
            "z": 0,
            "elements": [
                "astralsorcery:blockmarblestairs@5"
            ]
        },
        {
            "x": -3,
            "y": -2,
            "z": -5,
            "elements": [
                "astralsorcery:blockmarblestairs@6"
            ]
        },
        {
            "x": -2,
            "y": -3,
            "z": -6,
            "elements": [
                "botania:petalblock@13"
            ]
        },
        {
            "x": 2,
            "y": 2,
            "z": -4,
            "elements": [
                "astralsorcery:blockmarbleslab@0"
            ]
        },
        {
            "x": -2,
            "y": -3,
            "z": -5,
            "elements": [
                "botania:petalblock@13"
            ]
        },
        {
            "x": 4,
            "y": 4,
            "z": 1,
            "elements": [
                "botania:managlasspane@0"
            ]
        },
        {
            "x": 2,
            "y": 2,
            "z": -3,
            "elements": [
                "botania:petalblock@4"
            ]
        },
        {
            "x": -2,
            "y": -3,
            "z": -7,
            "elements": [
                "astralsorcery:blockmarblestairs@0"
            ]
        },
        {
            "x": 4,
            "y": 4,
            "z": -1,
            "elements": [
                "botania:managlasspane@0"
            ]
        },
        {
            "x": -2,
            "y": -3,
            "z": 2,
            "elements": [
                "botania:petalblock@0"
            ]
        },
        {
            "x": -2,
            "y": -3,
            "z": 3,
            "elements": [
                "botania:petalblock@0"
            ]
        },
        {
            "x": -2,
            "y": -3,
            "z": 0,
            "elements": [
                "botania:petalblock@0"
            ]
        },
        {
            "x": -2,
            "y": -3,
            "z": 1,
            "elements": [
                "botania:petalblock@0"
            ]
        },
        {
            "x": -2,
            "y": -3,
            "z": -2,
            "elements": [
                "botania:petalblock@0"
            ]
        },
        {
            "x": -2,
            "y": -3,
            "z": -1,
            "elements": [
                "botania:petalblock@0"
            ]
        },
        {
            "x": -2,
            "y": -3,
            "z": -4,
            "elements": [
                "botania:petalblock@4"
            ]
        },
        {
            "x": -2,
            "y": -3,
            "z": -3,
            "elements": [
                "botania:petalblock@0"
            ]
        },
        {
            "x": 0,
            "y": -2,
            "z": -2,
            "elements": [
                "botania:managlasspane@0"
            ]
        },
        {
            "x": 0,
            "y": -2,
            "z": -3,
            "elements": [
                "astralsorcery:blockmarbleslab@0"
            ]
        },
        {
            "x": 0,
            "y": -2,
            "z": 0,
            "elements": [
                "astralsorcery:blockmarble@2"
            ]
        },
        {
            "x": 0,
            "y": -2,
            "z": -6,
            "elements": [
                "astralsorcery:blockmarbleslab@0"
            ]
        },
        {
            "x": 0,
            "y": -2,
            "z": -7,
            "elements": [
                "astralsorcery:blockmarblestairs@3"
            ]
        },
        {
            "x": 0,
            "y": -2,
            "z": -4,
            "elements": [
                "astralsorcery:blockmarblestairs@3"
            ]
        },
        {
            "x": 0,
            "y": -2,
            "z": -5,
            "elements": [
                "astralsorcery:blockmarblestairs@2"
            ]
        },
        {
            "x": 0,
            "y": -2,
            "z": 6,
            "elements": [
                "astralsorcery:blockmarbleslab@0"
            ]
        },
        {
            "x": 2,
            "y": 2,
            "z": 3,
            "elements": [
                "botania:petalblock@4"
            ]
        },
        {
            "x": 2,
            "y": 2,
            "z": 4,
            "elements": [
                "astralsorcery:blockmarbleslab@0"
            ]
        },
        {
            "x": 0,
            "y": -2,
            "z": 5,
            "elements": [
                "astralsorcery:blockmarblestairs@3"
            ]
        },
        {
            "x": 0,
            "y": -2,
            "z": 7,
            "elements": [
                "astralsorcery:blockmarblestairs@2"
            ]
        },
        {
            "x": 0,
            "y": -2,
            "z": 2,
            "elements": [
                "botania:managlasspane@0"
            ]
        },
        {
            "x": 0,
            "y": -2,
            "z": 4,
            "elements": [
                "astralsorcery:blockmarblestairs@2"
            ]
        },
        {
            "x": 0,
            "y": -2,
            "z": 3,
            "elements": [
                "astralsorcery:blockmarbleslab@0"
            ]
        },
        {
            "x": 0,
            "y": 1,
            "z": -3,
            "elements": [
                "astralsorcery:blockmarblestairs@3"
            ]
        },
        {
            "x": 0,
            "y": 1,
            "z": -4,
            "elements": [
                "astralsorcery:blockmarblestairs@6"
            ]
        },
        {
            "x": 7,
            "y": -2,
            "z": -1,
            "elements": [
                "astralsorcery:blockmarbleslab@0"
            ]
        },
        {
            "x": -1,
            "y": 2,
            "z": 4,
            "elements": [
                "botania:petalblock@0"
            ]
        },
        {
            "x": 7,
            "y": -2,
            "z": 1,
            "elements": [
                "astralsorcery:blockmarbleslab@0"
            ]
        },
        {
            "x": 7,
            "y": -2,
            "z": 0,
            "elements": [
                "astralsorcery:blockmarblestairs@0"
            ]
        },
        {
            "x": -1,
            "y": 2,
            "z": -4,
            "elements": [
                "botania:petalblock@0"
            ]
        },
        {
            "x": 0,
            "y": 1,
            "z": -2,
            "elements": [
                "astralsorcery:blockmarbleslab@0"
            ]
        },
        {
            "x": 0,
            "y": 1,
            "z": 0,
            "elements": [
                "astralsorcery:blockmarble@2"
            ]
        },
        {
            "x": 0,
            "y": 1,
            "z": 3,
            "elements": [
                "astralsorcery:blockmarblestairs@2"
            ]
        },
        {
            "x": 0,
            "y": 1,
            "z": 2,
            "elements": [
                "astralsorcery:blockmarbleslab@0"
            ]
        },
        {
            "x": 0,
            "y": 1,
            "z": 4,
            "elements": [
                "astralsorcery:blockmarblestairs@7"
            ]
        },
        {
            "x": 1,
            "y": 5,
            "z": 3,
            "elements": [
                "botania:petalblock@0"
            ]
        },
        {
            "x": 0,
            "y": -3,
            "z": 4,
            "elements": [
                "botania:petalblock@0"
            ]
        },
        {
            "x": 0,
            "y": -3,
            "z": 5,
            "elements": [
                "botania:petalblock@0"
            ]
        },
        {
            "x": 0,
            "y": -3,
            "z": 2,
            "elements": [
                "botania:petalblock@0"
            ]
        },
        {
            "x": 0,
            "y": -3,
            "z": 3,
            "elements": [
                "botania:petalblock@0"
            ]
        },
        {
            "x": 0,
            "y": -3,
            "z": 6,
            "elements": [
                "botania:petalblock@0"
            ]
        },
        {
            "x": 0,
            "y": -3,
            "z": 7,

            "elements": [
                "modularmachinery:blockcasing@0",
                "ItemInput",
                "ItemOutput",
                "FluidInput",
                "gugu-utils:sparkmanahatch@0"
            ]
        },
        {
            "x": 0,
            "y": -3,
            "z": -4,
            "elements": [
                "botania:petalblock@0"
            ]
        },
        {
            "x": 0,
            "y": 4,
            "z": 0,

            "elements": [
                "botania:runealtar@0"
            ]
        },
        {
            "x": -4,
            "y": -1,
            "z": -1,
            "elements": [
                "botania:managlasspane@0"
            ]
        },
        {
            "x": 0,
            "y": -3,
            "z": -3,
            "elements": [
                "botania:petalblock@0"
            ]
        },
        {
            "x": 0,
            "y": -3,
            "z": -6,
            "elements": [
                "botania:petalblock@0"
            ]
        },
        {
            "x": -4,
            "y": -1,
            "z": -3,
            "elements": [
                "botania:managlass@0"
            ]
        },
        {
            "x": 0,
            "y": -3,
            "z": -5,
            "elements": [
                "botania:petalblock@0"
            ]
        },
        {
            "x": 0,
            "y": -3,
            "z": 0,
            "elements": [
                "botania:petalblock@4"
            ]
        },
        {
            "x": 0,
            "y": -3,
            "z": 1,
            "elements": [
                "botania:petalblock@4"
            ]
        },
        {
            "x": -4,
            "y": -1,
            "z": 3,
            "elements": [
                "botania:managlass@0"
            ]
        },
        {
            "x": 0,
            "y": -3,
            "z": -2,
            "elements": [
                "botania:petalblock@0"
            ]
        },
        {
            "x": 0,
            "y": 4,
            "z": -3,
            "elements": [
                "botania:managlass@0"
            ]
        },
        {
            "x": 0,
            "y": -3,
            "z": -1,
            "elements": [
                "botania:petalblock@4"
            ]
        },
        {
            "x": -4,
            "y": -1,
            "z": 1,
            "elements": [
                "botania:managlasspane@0"
            ]
        },
        {
            "x": 2,
            "y": 6,
            "z": -1,
            "elements": [
                "botania:petalblock@0"
            ]
        },
        {
            "x": 1,
            "y": -2,
            "z": 7,
            "elements": [
                "astralsorcery:blockmarbleslab@0"
            ]
        },
        {
            "x": 1,
            "y": -2,
            "z": 6,
            "elements": [
                "astralsorcery:blockmarblestairs@3"
            ]
        },
        {
            "x": 2,
            "y": 6,
            "z": 0,
            "elements": [
                "astralsorcery:blockmarbleslab@0"
            ]
        },
        {
            "x": 2,
            "y": 6,
            "z": 1,
            "elements": [
                "botania:petalblock@0"
            ]
        },
        {
            "x": 1,
            "y": -2,
            "z": 5,
            "elements": [
                "botania:petalblock@0"
            ]
        },
        {
            "x": 2,
            "y": 6,
            "z": 2,
            "elements": [
                "botania:petalblock@0"
            ]
        },
        {
            "x": 1,
            "y": -2,
            "z": 4,
            "elements": [
                "botania:managlasspane@0"
            ]
        },
        {
            "x": 2,
            "y": 6,
            "z": 3,
            "elements": [
                "astralsorcery:blockmarblestairs@3"
            ]
        },
        {
            "x": 1,
            "y": -2,
            "z": 3,
            "elements": [
                "astralsorcery:blockmarbleslab@0"
            ]
        },
        {
            "x": 1,
            "y": -2,
            "z": 2,
            "elements": [
                "astralsorcery:blockmarblestairs@3"
            ]
        },
        {
            "x": 0,
            "y": -3,
            "z": -7,

            "elements": [
                "modularmachinery:blockcasing@0",
                "ItemInput",
                "ItemOutput",
                "FluidInput",
                "gugu-utils:sparkmanahatch@0"
            ]
        },
        {
            "x": 1,
            "y": 5,
            "z": -3,
            "elements": [
                "botania:petalblock@0"
            ]
        },
        {
            "x": -5,
            "y": -2,
            "z": -3,
            "elements": [
                "astralsorcery:blockmarblestairs@4"
            ]
        },
        {
            "x": -5,
            "y": -2,
            "z": -4,
            "elements": [
                "astralsorcery:blockmarbleslab@0"
            ]
        },
        {
            "x": 2,
            "y": 6,
            "z": -3,
            "elements": [
                "astralsorcery:blockmarblestairs@2"
            ]
        },
        {
            "x": 2,
            "y": 6,
            "z": -2,
            "elements": [
                "botania:petalblock@0"
            ]
        },
        {
            "x": -5,
            "y": -2,
            "z": 3,
            "elements": [
                "astralsorcery:blockmarblestairs@4"
            ]
        },
        {
            "x": -5,
            "y": -2,
            "z": 2,
            "elements": [
                "astralsorcery:blockmarblestairs@0"
            ]
        },
        {
            "x": -5,
            "y": -2,
            "z": 4,
            "elements": [
                "astralsorcery:blockmarbleslab@0"
            ]
        },
        {
            "x": -5,
            "y": -2,
            "z": -1,
            "elements": [
                "botania:petalblock@0"
            ]
        },
        {
            "x": -5,
            "y": -2,
            "z": -2,
            "elements": [
                "astralsorcery:blockmarblestairs@0"
            ]
        },
        {
            "x": -5,
            "y": -2,
            "z": 1,
            "elements": [
                "botania:petalblock@0"
            ]
        },
        {
            "x": -5,
            "y": -2,
            "z": 0,
            "elements": [
                "astralsorcery:blockmarblestairs@0"
            ]
        },
        {
            "x": 1,
            "y": -1,
            "z": 5,
            "elements": [
                "botania:petalblock@0"
            ]
        },
        {
            "x": 1,
            "y": -1,
            "z": 4,
            "elements": [
                "botania:managlasspane@0"
            ]
        },
        {
            "x": 1,
            "y": -1,
            "z": -4,
            "elements": [
                "botania:managlasspane@0"
            ]
        },
        {
            "x": 1,
            "y": -1,
            "z": -5,
            "elements": [
                "botania:petalblock@0"
            ]
        },
        {
            "x": 0,
            "y": 3,
            "z": -3,
            "elements": [
                "botania:managlass@0"
            ]
        },
        {
            "x": 0,
            "y": 3,
            "z": -1,
            "elements": [
                "botania:managlass@0"
            ]
        },
        {
            "x": 0,
            "y": 3,
            "z": -2,
            "elements": [
                "botania:managlass@0"
            ]
        },
        {
            "x": 0,
            "y": 3,
            "z": 1,
            "elements": [
                "botania:managlass@0"
            ]
        },
        {
            "x": 0,
            "y": 3,
            "z": 0,
            "elements": [
                "botania:managlass@0"
            ]
        },
        {
            "x": 0,
            "y": 3,
            "z": 3,
            "elements": [
                "botania:managlass@0"
            ]
        },
        {
            "x": 0,
            "y": 3,
            "z": 2,
            "elements": [
                "botania:managlass@0"
            ]
        },
        {
            "x": 3,
            "y": 2,
            "z": -3,
            "elements": [
                "botania:petalblock@4"
            ]
        },
        {
            "x": 3,
            "y": 2,
            "z": 0,
            "elements": [
                "botania:managlass@0"
            ]
        },
        {
            "x": 3,
            "y": 2,
            "z": -2,
            "elements": [
                "botania:petalblock@4"
            ]
        },
        {
            "x": 3,
            "y": 2,
            "z": 2,
            "elements": [
                "botania:petalblock@4"
            ]
        },
        {
            "x": 3,
            "y": 2,
            "z": 3,
            "elements": [
                "botania:petalblock@4"
            ]
        },
        {
            "x": 1,
            "y": -2,
            "z": -2,
            "elements": [
                "astralsorcery:blockmarblestairs@2"
            ]
        },
        {
            "x": 1,
            "y": -2,
            "z": -3,
            "elements": [
                "astralsorcery:blockmarbleslab@0"
            ]
        },
        {
            "x": 1,
            "y": -2,
            "z": -4,
            "elements": [
                "botania:managlasspane@0"
            ]
        },
        {
            "x": 1,
            "y": -2,
            "z": -5,
            "elements": [
                "botania:petalblock@0"
            ]
        },
        {
            "x": 1,
            "y": -2,
            "z": -6,
            "elements": [
                "astralsorcery:blockmarblestairs@2"
            ]
        },
        {
            "x": 1,
            "y": -2,
            "z": -7,
            "elements": [
                "astralsorcery:blockmarbleslab@0"
            ]
        },
        {
            "x": -5,
            "y": -3,
            "z": 0,
            "elements": [
                "botania:petalblock@0"
            ]
        },
        {
            "x": -5,
            "y": -3,
            "z": -1,
            "elements": [
                "botania:petalblock@13"
            ]
        },
        {
            "x": -5,
            "y": -3,
            "z": 2,
            "elements": [
                "botania:petalblock@13"
            ]
        },
        {
            "x": -5,
            "y": -3,
            "z": 1,
            "elements": [
                "botania:petalblock@13"
            ]
        },
        {
            "x": -5,
            "y": -3,
            "z": 4,
            "elements": [
                "botania:petalblock@13"
            ]
        },
        {
            "x": -5,
            "y": -3,
            "z": 3,
            "elements": [
                "botania:petalblock@13"
            ]
        },
        {
            "x": -5,
            "y": -3,
            "z": 5,
            "elements": [
                "botania:petalblock@13"
            ]
        },
        {
            "x": -5,
            "y": -3,
            "z": -4,
            "elements": [
                "botania:petalblock@13"
            ]
        },
        {
            "x": 1,
            "y": 4,
            "z": -4,
            "elements": [
                "botania:managlasspane@0"
            ]
        },
        {
            "x": -5,
            "y": -3,
            "z": -5,
            "elements": [
                "botania:petalblock@13"
            ]
        },
        {
            "x": 1,
            "y": 4,
            "z": -3,
            "elements": [
                "botania:petalblock@0"
            ]
        },
        {
            "x": -5,
            "y": -3,
            "z": -2,
            "elements": [
                "botania:petalblock@13"
            ]
        },
        {
            "x": -5,
            "y": -3,
            "z": -3,
            "elements": [
                "botania:petalblock@13"
            ]
        },
        {
            "x": 2,
            "y": 0,
            "z": 0,
            "elements": [
                "astralsorcery:blockmarblestairs@4"
            ]
        },
        {
            "x": 6,
            "y": -2,
            "z": -2,
            "elements": [
                "astralsorcery:blockmarbleslab@0"
            ]
        },
        {
            "x": 1,
            "y": 4,
            "z": 4,
            "elements": [
                "botania:managlasspane@0"
            ]
        },
        {
            "x": 6,
            "y": -2,
            "z": -1,
            "elements": [
                "astralsorcery:blockmarblestairs@1"
            ]
        },
        {
            "x": 6,
            "y": -2,
            "z": 0,
            "elements": [
                "astralsorcery:blockmarbleslab@0"
            ]
        },
        {
            "x": 6,
            "y": -2,
            "z": 1,
            "elements": [
                "astralsorcery:blockmarblestairs@1"
            ]
        },
        {
            "x": 1,
            "y": 4,
            "z": 3,
            "elements": [
                "botania:petalblock@0"
            ]
        },
        {
            "x": 6,
            "y": -2,
            "z": 2,
            "elements": [
                "astralsorcery:blockmarbleslab@0"
            ]
        },
        {
            "x": -1,
            "y": 1,
            "z": 5,
            "elements": [
                "botania:managlasspane@0"
            ]
        },
        {
            "x": -1,
            "y": 1,
            "z": 4,
            "elements": [
                "botania:petalblock@0"
            ]
        },
        {
            "x": 0,
            "y": 2,
            "z": -4,
            "elements": [
                "astralsorcery:blockmarbleslab@0"
            ]
        },
        {
            "x": 2,
            "y": 1,
            "z": 4,
            "elements": [
                "astralsorcery:blockmarbleslab@8"
            ]
        },
        {
            "x": -3,
            "y": 2,
            "z": -3,
            "elements": [
                "botania:petalblock@4"
            ]
        },
        {
            "x": -3,
            "y": 2,
            "z": -2,
            "elements": [
                "botania:petalblock@4"
            ]
        },
        {
            "x": 2,
            "y": 1,
            "z": 0,
            "elements": [
                "astralsorcery:blockmarbleslab@0"
            ]
        },
        {
            "x": 0,
            "y": 2,
            "z": 4,
            "elements": [
                "astralsorcery:blockmarbleslab@0"
            ]
        },
        {
            "x": -1,
            "y": 1,
            "z": -4,
            "elements": [
                "botania:petalblock@0"
            ]
        },
        {
            "x": -1,
            "y": 1,
            "z": -5,
            "elements": [
                "botania:managlasspane@0"
            ]
        },
        {
            "x": 0,
            "y": 2,
            "z": 3,
            "elements": [
                "botania:managlass@0"
            ]
        },
        {
            "x": 2,
            "y": 1,
            "z": -4,
            "elements": [
                "astralsorcery:blockmarbleslab@8"
            ]
        },
        {
            "x": 0,
            "y": 2,
            "z": -3,
            "elements": [
                "botania:managlass@0"
            ]
        },
        {
            "x": 0,
            "y": 2,
            "z": 0,
            "elements": [
                "astralsorcery:blockmarble@2"
            ]
        },
        {
            "x": 5,
            "y": 1,
            "z": -3,
            "elements": [
                "astralsorcery:blockmarbleslab@0"
            ]
        },
        {
            "x": -1,
            "y": 0,
            "z": 5,
            "elements": [
                "botania:managlasspane@0"
            ]
        },
        {
            "x": 5,
            "y": 1,
            "z": -1,
            "elements": [
                "botania:managlasspane@0"
            ]
        },
        {
            "x": -1,
            "y": 0,
            "z": 4,
            "elements": [
                "botania:petalblock@0"
            ]
        },
        {
            "x": 3,
            "y": -3,
            "z": -2,
            "elements": [
                "botania:petalblock@0"
            ]
        },
        {
            "x": 6,
            "y": -3,
            "z": 0,
            "elements": [
                "botania:petalblock@0"
            ]
        },
        {
            "x": 6,
            "y": -3,
            "z": 1,
            "elements": [
                "botania:petalblock@13"
            ]
        },
        {
            "x": 3,
            "y": -3,
            "z": -3,
            "elements": [
                "botania:petalblock@0"
            ]
        },
        {
            "x": 3,
            "y": -3,
            "z": -4,
            "elements": [
                "botania:petalblock@13"
            ]
        },
        {
            "x": 6,
            "y": -3,
            "z": 2,
            "elements": [
                "botania:petalblock@13"
            ]
        },
        {
            "x": 3,
            "y": -3,
            "z": -5,
            "elements": [
                "botania:petalblock@13"
            ]
        },
        {
            "x": 6,
            "y": -3,
            "z": 3,
            "elements": [
                "botania:petalblock@13"
            ]
        },
        {
            "x": 6,
            "y": -3,
            "z": -4,
            "elements": [
                "astralsorcery:blockmarblestairs@2"
            ]
        },
        {
            "x": 3,
            "y": -3,
            "z": -6,
            "elements": [
                "botania:petalblock@13"
            ]
        },
        {
            "x": 6,
            "y": -3,
            "z": -3,
            "elements": [
                "botania:petalblock@13"
            ]
        },
        {
            "x": 6,
            "y": -3,
            "z": -2,
            "elements": [
                "botania:petalblock@13"
            ]
        },
        {
            "x": 6,
            "y": -3,
            "z": -1,
            "elements": [
                "botania:petalblock@13"
            ]
        },
        {
            "x": 3,
            "y": -3,
            "z": 6,
            "elements": [
                "botania:petalblock@13"
            ]
        },
        {
            "x": 3,
            "y": -3,
            "z": 5,
            "elements": [
                "botania:petalblock@13"
            ]
        },
        {
            "x": 5,
            "y": 1,
            "z": 1,
            "elements": [
                "botania:managlasspane@0"
            ]
        },
        {
            "x": 3,
            "y": -3,
            "z": 4,
            "elements": [
                "botania:petalblock@13"
            ]
        },
        {
            "x": 5,
            "y": 1,
            "z": 3,
            "elements": [
                "astralsorcery:blockmarbleslab@0"
            ]
        },
        {
            "x": 3,
            "y": -3,
            "z": 3,
            "elements": [
                "botania:petalblock@0"
            ]
        },
        {
            "x": 6,
            "y": -3,
            "z": 4,
            "elements": [
                "astralsorcery:blockmarblestairs@3"
            ]
        },
        {
            "x": 3,
            "y": -3,
            "z": 2,
            "elements": [
                "botania:petalblock@0"
            ]
        },
        {
            "x": 3,
            "y": -3,
            "z": 1,
            "elements": [
                "botania:petalblock@4"
            ]
        },
        {
            "x": 3,
            "y": -3,
            "z": 0,
            "elements": [
                "botania:petalblock@0"
            ]
        },
        {
            "x": 3,
            "y": -3,
            "z": -1,
            "elements": [
                "botania:petalblock@4"
            ]
        },
        {
            "x": -4,
            "y": 0,
            "z": 1,
            "elements": [
                "botania:petalblock@0"
            ]
        },
        {
            "x": 3,
            "y": 3,
            "z": -1,
            "elements": [
                "botania:petalblock@0"
            ]
        },
        {
            "x": 3,
            "y": 3,
            "z": 0,
            "elements": [
                "botania:managlass@0"
