{
    "registryname": "YMG_Elemental_Refinery",
    "localizedname": "§b§lYMG§r§e§l—§f§l元素精炼机 §r§e",
    "failure-action": "still",
    "requires-blueprint": false,
    "color": "707070",
    "parts": [
        {
            "x": 0,
            "y": 7,
            "z": 8,
            "elements": [
                "mekanism:basicblock@8"
            ]
        },
        {
            "x": 5,
            "y": 0,
            "z": 8,
            "elements": [
                "appliedenergistics2:smooth_sky_stone_stairs@3"
            ]
        },
        {
            "x": 0,
            "y": 7,
            "z": 9,
            "elements": [
                "mekanism:basicblock@8"
            ]
        },
        {
            "x": 0,
            "y": 7,
            "z": 10,
            "elements": [
                "appliedenergistics2:smooth_sky_stone_slab@0"
            ]
        },
        {
            "x": 5,
            "y": 0,
            "z": 6,
            "elements": [
                "enderio:block_alloy@6"
            ]
        },
        {
            "x": 5,
            "y": 0,
            "z": 7,
            "elements": [
                "enderio:block_alloy@6"
            ]
        },
        {
            "x": 5,
            "y": 0,
            "z": 4,
            "elements": [
                "appliedenergistics2:smooth_sky_stone_stairs@2"
            ]
        },
        {
            "x": 5,
            "y": 0,
            "z": 5,
            "elements": [
                "enderio:block_alloy@6"
            ]
        },
        {
            "x": -1,
            "y": 6,
            "z": 4,
            "elements": [
                "appliedenergistics2:quartz_vibrant_glass@0"
            ]
        },
        {
            "x": -1,
            "y": 6,
            "z": 5,
            "elements": [
                "appliedenergistics2:quartz_vibrant_glass@0"
            ]
        },
        {
            "x": -5,
            "y": 1,
            "z": 5,
            "elements": [
                "mekanism:plasticfence@7"
            ]
        },
        {
            "x": -1,
            "y": 6,
            "z": 2,
            "elements": [
                "appliedenergistics2:smooth_sky_stone_stairs@0"
            ]
        },
        {
            "x": -5,
            "y": 1,
            "z": 6,

            "elements": [
                "modularmachinery:blockcasing@4",
                "ItemInputStrengthen",
                "FluidInputStrengthen",
                "FluidOutputStrengthen",
                "EnergyInputStrengthen"
            ]
        },
        {
            "x": -1,
            "y": 6,
            "z": 3,
            "elements": [
                "appliedenergistics2:smooth_sky_stone_slab@0"
            ]
        },
        {
            "x": -5,
            "y": 1,
            "z": 7,
            "elements": [
                "mekanism:plasticfence@7"
            ]
        },
        {
            "x": 1,
            "y": 8,
            "z": 8,
            "elements": [
                "appliedenergistics2:smooth_sky_stone_slab@0"
            ]
        },
        {
            "x": -1,
            "y": 6,
            "z": 8,
            "elements": [
                "appliedenergistics2:quartz_vibrant_glass@0"
            ]
        },
        {
            "x": -3,
            "y": 3,
            "z": 7,
            "elements": [
                "minecraft:end_rod@3"
            ]
        },
        {
            "x": -1,
            "y": 6,
            "z": 9,
            "elements": [
                "appliedenergistics2:smooth_sky_stone_slab@0"
            ]
        },
        {
            "x": -1,
            "y": 6,
            "z": 6,
            "elements": [
                "appliedenergistics2:quartz_vibrant_glass@0"
            ]
        },
        {
            "x": 1,
            "y": 8,
            "z": 6,
            "elements": [
                "mekanism:basicblock@8"
            ]
        },
        {
            "x": 1,
            "y": 8,
            "z": 7,
            "elements": [
                "appliedenergistics2:quartz_vibrant_glass@0"
            ]
        },
        {
            "x": -1,
            "y": 6,
            "z": 7,
            "elements": [
                "appliedenergistics2:quartz_vibrant_glass@0"
            ]
        },
        {
            "x": 0,
            "y": 7,
            "z": 2,
            "elements": [
                "appliedenergistics2:smooth_sky_stone_slab@0"
            ]
        },
        {
            "x": 0,
            "y": 7,
            "z": 3,
            "elements": [
                "mekanism:basicblock@8"
            ]
        },
        {
            "x": 0,
            "y": 7,
            "z": 4,
            "elements": [
                "mekanism:basicblock@8"
            ]
        },
        {
            "x": -1,
            "y": 6,
            "z": 1,
            "elements": [
                "appliedenergistics2:smooth_sky_stone_slab@0"
            ]
        },
        {
            "x": 0,
            "y": 7,
            "z": 5,
            "elements": [
                "appliedenergistics2:quartz_vibrant_glass@0"
            ]
        },
        {
            "x": 0,
            "y": 7,
            "z": 6,
            "elements": [
                "appliedenergistics2:quartz_vibrant_glass@0"
            ]
        },
        {
            "x": 0,
            "y": 7,
            "z": 7,
            "elements": [
                "appliedenergistics2:quartz_vibrant_glass@0"
            ]
        },
        {
            "x": -2,
            "y": 4,
            "z": 6,
            "elements": [
                "appliedenergistics2:quartz_vibrant_glass@0"
            ]
        },
        {
            "x": -2,
            "y": 4,
            "z": 5,
            "elements": [
                "appliedenergistics2:quartz_vibrant_glass@0"
            ]
        },
        {
            "x": -2,
            "y": 4,
            "z": 8,
            "elements": [
                "appliedenergistics2:quartz_vibrant_glass@0"
            ]
        },
        {
            "x": -1,
            "y": 6,
            "z": 10,
            "elements": [
                "appliedenergistics2:smooth_sky_stone_stairs@0"
            ]
        },
        {
            "x": -1,
            "y": 6,
            "z": 11,
            "elements": [
                "appliedenergistics2:smooth_sky_stone_slab@0"
            ]
        },
        {
            "x": -2,
            "y": 4,
            "z": 7,
            "elements": [
                "appliedenergistics2:quartz_vibrant_glass@0"
            ]
        },
        {
            "x": -2,
            "y": 4,
            "z": 9,
            "elements": [
                "appliedenergistics2:smooth_sky_stone_slab@8"
            ]
        },
        {
            "x": -2,
            "y": 4,
            "z": 4,
            "elements": [
                "appliedenergistics2:quartz_vibrant_glass@0"
            ]
        },
        {
            "x": -2,
            "y": 4,
            "z": 3,
            "elements": [
                "appliedenergistics2:smooth_sky_stone_slab@8"
            ]
        },
        {
            "x": 1,
            "y": 9,
            "z": 6,
            "elements": [
                "appliedenergistics2:smooth_sky_stone_slab@0"
            ]
        },
        {
            "x": 1,
            "y": 7,
            "z": 9,
            "elements": [
                "minecraft:end_rod@5"
            ]
        },
        {
            "x": -2,
            "y": 5,
            "z": 3,
            "elements": [
                "ic2:fence@0"
            ]
        },
        {
            "x": 1,
            "y": 7,
            "z": 7,
            "elements": [
                "appliedenergistics2:quartz_vibrant_glass@0"
            ]
        },
        {
            "x": 1,
            "y": 7,
            "z": 8,
            "elements": [
                "appliedenergistics2:quartz_vibrant_glass@0"
            ]
        },
        {
            "x": -2,
            "y": 5,
            "z": 9,
            "elements": [
                "ic2:fence@0"
            ]
        },
        {
            "x": -2,
            "y": 5,
            "z": 8,
            "elements": [
                "appliedenergistics2:quartz_vibrant_glass@0"
            ]
        },
        {
            "x": -3,
            "y": 3,
            "z": 5,
            "elements": [
                "minecraft:end_rod@2"
            ]
        },
        {
            "x": -3,
            "y": 3,
            "z": 6,
            "elements": [
                "mekanism:basicblock@8"
            ]
        },
        {
            "x": 1,
            "y": 7,
            "z": 5,
            "elements": [
                "appliedenergistics2:quartz_vibrant_glass@0"
            ]
        },
        {
            "x": -2,
            "y": 5,
            "z": 5,
            "elements": [
                "appliedenergistics2:quartz_vibrant_glass@0"
            ]
        },
        {
            "x": 1,
            "y": 7,
            "z": 6,
            "elements": [
                "appliedenergistics2:quartz_vibrant_glass@0"
            ]
        },
        {
            "x": -2,
            "y": 5,
            "z": 4,
            "elements": [
                "appliedenergistics2:quartz_vibrant_glass@0"
            ]
        },
        {
            "x": 6,
            "y": 1,
            "z": 6,
            "elements": [
                "appliedenergistics2:smooth_sky_stone_slab@0"
            ]
        },
        {
            "x": -2,
            "y": 5,
            "z": 7,
            "elements": [
                "appliedenergistics2:quartz_vibrant_glass@0"
            ]
        },
        {
            "x": 1,
            "y": 7,
            "z": 3,
            "elements": [
                "minecraft:end_rod@5"
            ]
        },
        {
            "x": -2,
            "y": 5,
            "z": 6,
            "elements": [
                "appliedenergistics2:quartz_vibrant_glass@0"
            ]
        },
        {
            "x": 1,
            "y": 7,
            "z": 4,
            "elements": [
                "appliedenergistics2:quartz_vibrant_glass@0"
            ]
        },
        {
            "x": 0,
            "y": 8,
            "z": 7,
            "elements": [
                "mekanism:basicblock@8"
            ]
        },
        {
            "x": 0,
            "y": 8,
            "z": 8,
            "elements": [
                "appliedenergistics2:smooth_sky_stone_stairs@3"
            ]
        },
        {
            "x": 0,
            "y": 8,
            "z": 9,
            "elements": [
                "appliedenergistics2:smooth_sky_stone_slab@0"
            ]
        },
        {
            "x": 0,
            "y": 8,
            "z": 3,
            "elements": [
                "appliedenergistics2:smooth_sky_stone_slab@0"
            ]
        },
        {
            "x": -5,
            "y": 0,
            "z": 8,
            "elements": [
                "appliedenergistics2:smooth_sky_stone_stairs@3"
            ]
        },
        {
            "x": 0,
            "y": 8,
            "z": 4,
            "elements": [
                "appliedenergistics2:smooth_sky_stone_stairs@2"
            ]
        },
        {
            "x": 0,
            "y": 8,
            "z": 5,
            "elements": [
                "mekanism:basicblock@8"
            ]
        },
        {
            "x": 0,
            "y": 8,
            "z": 6,
            "elements": [
                "mekanism:basicblock@8"
            ]
        },
        {
            "x": -5,
            "y": 0,
            "z": 5,
            "elements": [
                "enderio:block_alloy@6"
            ]
        },
        {
            "x": -5,
            "y": 0,
            "z": 4,
            "elements": [
                "appliedenergistics2:smooth_sky_stone_stairs@2"
            ]
        },
        {
            "x": -5,
            "y": 0,
            "z": 7,
            "elements": [
                "enderio:block_alloy@6"
            ]
        },
        {
            "x": -5,
            "y": 0,
            "z": 6,
            "elements": [
                "enderio:block_alloy@6"
            ]
        },
        {
            "x": -2,
            "y": 6,
            "z": 4,
            "elements": [
                "appliedenergistics2:quartz_vibrant_glass@0"
            ]
        },
        {
            "x": -2,
            "y": 6,
            "z": 3,
            "elements": [
                "appliedenergistics2:smooth_sky_stone_slab@0"
            ]
        },
        {
            "x": -2,
            "y": 6,
            "z": 6,
            "elements": [
                "appliedenergistics2:quartz_vibrant_glass@0"
            ]
        },
        {
            "x": -2,
            "y": 6,
            "z": 5,
            "elements": [
                "appliedenergistics2:quartz_vibrant_glass@0"
            ]
        },
        {
            "x": -2,
            "y": 6,
            "z": 8,
            "elements": [
                "appliedenergistics2:quartz_vibrant_glass@0"
            ]
        },
        {
            "x": -2,
            "y": 3,
            "z": 7,
            "elements": [
                "appliedenergistics2:quartz_vibrant_glass@0"
            ]
        },
        {
            "x": 2,
            "y": 8,
            "z": 7,
            "elements": [
                "appliedenergistics2:smooth_sky_stone_slab@0"
            ]
        },
        {
            "x": -2,
            "y": 3,
            "z": 6,
            "elements": [
                "mekanism:basicblock@8"
            ]
        },
        {
            "x": -2,
            "y": 6,
            "z": 7,
            "elements": [
                "appliedenergistics2:quartz_vibrant_glass@0"
            ]
        },
        {
            "x": 2,
            "y": 8,
            "z": 6,
            "elements": [
                "appliedenergistics2:smooth_sky_stone_stairs@1"
            ]
        },
        {
            "x": -2,
            "y": 6,
            "z": 9,
            "elements": [
                "appliedenergistics2:smooth_sky_stone_slab@0"
            ]
        },
        {
            "x": -2,
            "y": 3,
            "z": 8,
            "elements": [
                "appliedenergistics2:smooth_sky_stone_slab@8"
            ]
        },
        {
            "x": 2,
            "y": 8,
            "z": 5,
            "elements": [
                "appliedenergistics2:smooth_sky_stone_slab@0"
            ]
        },
        {
            "x": -4,
            "y": 4,
            "z": 5,
            "elements": [
                "appliedenergistics2:smooth_sky_stone_stairs@6"
            ]
        },
        {
            "x": -4,
            "y": 4,
            "z": 6,
            "elements": [
                "enderio:block_alloy@6"
            ]
        },
        {
            "x": -2,
            "y": 3,
            "z": 5,
            "elements": [
                "appliedenergistics2:quartz_vibrant_glass@0"
            ]
        },
        {
            "x": -2,
            "y": 3,
            "z": 4,
            "elements": [
                "appliedenergistics2:smooth_sky_stone_slab@8"
            ]
        },
        {
            "x": 4,
            "y": 0,
            "z": 7,
            "elements": [
                "enderio:block_alloy@6"
            ]
        },
        {
            "x": -5,
            "y": 2,
            "z": 6,

            "elements": [
                "modularmachinery:blockcasing@4",
                "ItemInputStrengthen",
                "FluidInputStrengthen",
                "FluidOutputStrengthen",
                "EnergyInputStrengthen"
            ]
        },
        {
            "x": -5,
            "y": 2,
            "z": 7,
            "elements": [
                "mekanism:plasticfence@7"
            ]
        },
        {
            "x": 4,
            "y": 0,
            "z": 8,
            "elements": [
                "enderio:block_alloy@6"
            ]
        },
        {
            "x": 4,
            "y": 0,
            "z": 9,
            "elements": [
                "enderio:block_alloy@6"
            ]
        },
        {
            "x": 4,
            "y": 0,
            "z": 3,
            "elements": [
                "enderio:block_alloy@6"
            ]
        },
        {
            "x": 4,
            "y": 0,
            "z": 4,
            "elements": [
                "enderio:block_alloy@6"
            ]
        },
        {
            "x": 4,
            "y": 0,
            "z": 5,
            "elements": [
                "enderio:block_alloy@6"
            ]
        },
        {
            "x": -4,
            "y": 4,
            "z": 7,
            "elements": [
                "appliedenergistics2:smooth_sky_stone_stairs@7"
            ]
        },
        {
            "x": -5,
            "y": 2,
            "z": 5,
            "elements": [
                "mekanism:plasticfence@7"
            ]
        },
        {
            "x": 4,
            "y": 0,
            "z": 6,
            "elements": [
                "enderio:block_alloy@0"
            ]
        },
        {
            "x": 1,
            "y": 6,
            "z": 10,
            "elements": [
                "appliedenergistics2:smooth_sky_stone_stairs@1"
            ]
        },
        {
            "x": 1,
            "y": 6,
            "z": 11,
            "elements": [
                "appliedenergistics2:smooth_sky_stone_slab@0"
            ]
        },
        {
            "x": 1,
            "y": 6,
            "z": 8,
            "elements": [
                "appliedenergistics2:quartz_vibrant_glass@0"
            ]
        },
        {
            "x": 1,
            "y": 6,
            "z": 9,
            "elements": [
                "appliedenergistics2:smooth_sky_stone_slab@0"
            ]
        },
        {
            "x": -3,
            "y": 1,
            "z": 5,
            "elements": [
                "appliedenergistics2:smooth_sky_stone_slab@0"
            ]
        },
        {
            "x": 1,
            "y": 6,
            "z": 6,
            "elements": [
                "appliedenergistics2:quartz_vibrant_glass@0"
            ]
        },
        {
            "x": 1,
            "y": 6,
            "z": 7,
            "elements": [
                "appliedenergistics2:quartz_vibrant_glass@0"
            ]
        },
        {
            "x": -3,
            "y": 1,
            "z": 7,
            "elements": [
                "appliedenergistics2:smooth_sky_stone_slab@0"
            ]
        },
        {
            "x": 1,
            "y": 6,
            "z": 4,
            "elements": [
                "appliedenergistics2:quartz_vibrant_glass@0"
            ]
        },
        {
            "x": -3,
            "y": 1,
            "z": 8,
            "elements": [
                "mekanism:plasticfence@7"
            ]
        },
        {
            "x": 1,
            "y": 6,
            "z": 5,
            "elements": [
                "appliedenergistics2:quartz_vibrant_glass@0"
            ]
        },
        {
            "x": 1,
            "y": 6,
            "z": 2,
            "elements": [
                "appliedenergistics2:smooth_sky_stone_stairs@1"
            ]
        },
        {
            "x": 1,
            "y": 6,
            "z": 3,
            "elements": [
                "appliedenergistics2:smooth_sky_stone_slab@0"
            ]
        },
        {
            "x": 1,
            "y": 6,
            "z": 1,
            "elements": [
                "appliedenergistics2:smooth_sky_stone_slab@0"
            ]
        },
        {
            "x": -3,
            "y": 1,
            "z": 4,
            "elements": [
                "mekanism:plasticfence@7"
            ]
        },
        {
            "x": -1,
            "y": 5,
            "z": 2,
            "elements": [
                "minecraft:end_rod@3"
            ]
        },
        {
            "x": -1,
            "y": 5,
            "z": 1,

            "elements": [
                "modularmachinery:blockcasing@4",
                "ItemInputStrengthen",
                "FluidInputStrengthen",
                "FluidOutputStrengthen",
                "EnergyInputStrengthen"
            ]
        },
        {
            "x": -3,
            "y": 4,
            "z": 8,
            "elements": [
                "appliedenergistics2:smooth_sky_stone_slab@8"
            ]
        },
        {
            "x": -3,
            "y": 4,
            "z": 7,
            "elements": [
                "appliedenergistics2:smooth_sky_stone_slab@8"
            ]
        },
        {
            "x": -3,
            "y": 4,
            "z": 6,
            "elements": [
                "mekanism:basicblock@8"
            ]
        },
        {
            "x": -3,
            "y": 4,
            "z": 5,
            "elements": [
                "appliedenergistics2:smooth_sky_stone_slab@8"
            ]
        },
        {
            "x": -3,
            "y": 4,
            "z": 4,
            "elements": [
                "appliedenergistics2:smooth_sky_stone_slab@8"
            ]
        },
        {
            "x": 0,
            "y": 4,
            "z": 11,

            "elements": [
                "modularmachinery:blockcasing@4",
                "ItemInputStrengthen",
                "FluidInputStrengthen",
                "FluidOutputStrengthen",
                "EnergyInputStrengthen"
            ]
        },
        {
            "x": 0,
            "y": 4,
            "z": 8,
            "elements": [
                "appliedenergistics2:quartz_vibrant_glass@0"
            ]
        },
        {
            "x": 0,
            "y": 4,
            "z": 7,
            "elements": [
                "appliedenergistics2:quartz_vibrant_glass@0"
            ]
        },
        {
            "x": -6,
            "y": 0,
            "z": 7,
            "elements": [
                "appliedenergistics2:smooth_sky_stone_stairs@0"
            ]
        },
        {
            "x": -6,
            "y": 0,
            "z": 6,
            "elements": [
                "enderio:block_alloy@6"
            ]
        },
        {
            "x": 0,
            "y": 4,
            "z": 10,
            "elements": [
                "enderio:block_alloy@6"
            ]
        },
        {
            "x": -6,
            "y": 0,
            "z": 5,
            "elements": [
                "appliedenergistics2:smooth_sky_stone_stairs@0"
            ]
        },
        {
            "x": 0,
            "y": 4,
            "z": 9,
            "elements": [
                "mekanism:basicblock@8"
            ]
        },
        {
            "x": 0,
            "y": 4,
            "z": 4,
            "elements": [
                "appliedenergistics2:quartz_vibrant_glass@0"
            ]
        },
        {
            "x": -1,
            "y": 8,
            "z": 6,
            "elements": [
                "mekanism:basicblock@8"
            ]
        },
        {
            "x": 0,
            "y": 4,
            "z": 3,
            "elements": [
                "mekanism:basicblock@8"
            ]
        },
        {
            "x": -1,
            "y": 8,
            "z": 7,
            "elements": [
                "appliedenergistics2:quartz_vibrant_glass@0"
            ]
        },
        {
            "x": 0,
            "y": 4,
            "z": 6,

            "elements": [
                "environmentaltech:structure_frame_2@0"
            ]
        },
        {
            "x": -1,
            "y": 8,
            "z": 4,
            "elements": [
                "appliedenergistics2:smooth_sky_stone_slab@0"
            ]
        },
        {
            "x": -1,
            "y": 8,
            "z": 5,
            "elements": [
                "appliedenergistics2:quartz_vibrant_glass@0"
            ]
        },
        {
            "x": 0,
            "y": 4,
            "z": 5,
            "elements": [
                "appliedenergistics2:quartz_vibrant_glass@0"
            ]
        },
        {
            "x": -1,
            "y": 8,
            "z": 8,
            "elements": [
                "appliedenergistics2:smooth_sky_stone_slab@0"
            ]
        },
        {
            "x": -1,
            "y": 5,
            "z": 11,

            "elements": [
                "modularmachinery:blockcasing@4",
                "ItemInputStrengthen",
                "FluidInputStrengthen",
                "FluidOutputStrengthen",
                "EnergyInputStrengthen"
            ]
        },
        {
            "x": -1,
            "y": 5,
            "z": 10,
            "elements": [
                "minecraft:end_rod@2"
            ]
        },
        {
            "x": -1,
            "y": 5,
            "z": 9,
            "elements": [
                "contenttweaker:mysteriousicecasing@0"
            ]
        },
        {
            "x": -1,
            "y": 5,
            "z": 8,
            "elements": [
                "appliedenergistics2:quartz_vibrant_glass@0"
            ]
        },
        {
            "x": -1,
            "y": 5,
            "z": 7,
            "elements": [
                "appliedenergistics2:quartz_vibrant_glass@0"
            ]
        },
        {
            "x": -1,
            "y": 5,
            "z": 6,

            "elements": [
                "environmentaltech:structure_frame_2@0"
            ]
        },
        {
            "x": -1,
            "y": 5,
            "z": 5,
            "elements": [
                "appliedenergistics2:quartz_vibrant_glass@0"
            ]
        },
        {
            "x": -1,
            "y": 5,
            "z": 4,
            "elements": [
                "appliedenergistics2:quartz_vibrant_glass@0"
            ]
        },
        {
            "x": -1,
            "y": 5,
            "z": 3,
            "elements": [
                "contenttweaker:mysteriousicecasing@0"
            ]
        },
        {
            "x": -3,
            "y": 0,
            "z": 2,
            "elements": [
                "enderio:block_alloy@6"
            ]
        },
        {
            "x": -3,
            "y": 0,
            "z": 3,
            "elements": [
                "enderio:block_alloy@8"
            ]
        },
        {
            "x": -3,
            "y": 0,
            "z": 4,
            "elements": [
                "enderio:block_alloy@8"
            ]
        },
        {
            "x": -3,
            "y": 0,
            "z": 5,
            "elements": [
                "fluxnetworks:fluxblock@0"
            ]
        },
        {
            "x": -3,
            "y": 0,
            "z": 6,
            "elements": [
                "enderio:block_alloy@0"
            ]
        },
        {
            "x": -3,
            "y": 0,
            "z": 7,
            "elements": [
                "fluxnetworks:fluxblock@0"
            ]
        },
        {
            "x": -3,
            "y": 0,
            "z": 8,
            "elements": [
                "enderio:block_alloy@8"
            ]
        },
        {
            "x": -3,
            "y": 0,
            "z": 9,
            "elements": [
                "enderio:block_alloy@8"
            ]
        },
        {
            "x": -3,
            "y": 0,
            "z": 10,
            "elements": [
                "enderio:block_alloy@6"
            ]
        },
        {
            "x": -1,
            "y": 9,
            "z": 6,
            "elements": [
                "appliedenergistics2:smooth_sky_stone_slab@0"
            ]
        },
        {
            "x": -2,
            "y": 1,
            "z": 7,
            "elements": [
                "appliedenergistics2:smooth_sky_stone_slab@0"
            ]
        },
        {
            "x": -2,
            "y": 1,
            "z": 4,
            "elements": [
                "appliedenergistics2:smooth_sky_stone_slab@0"
            ]
        },
        {
            "x": -2,
            "y": 1,
            "z": 5,
            "elements": [
                "appliedenergistics2:smooth_sky_stone_slab@0"
            ]
        },
        {
            "x": -2,
            "y": 1,
            "z": 3,
            "elements": [
                "mekanism:plasticfence@7"
            ]
        },
        {
            "x": -2,
            "y": 8,
            "z": 5,
            "elements": [
                "appliedenergistics2:smooth_sky_stone_slab@0"
            ]
        },
        {
            "x": -2,
            "y": 8,
            "z": 6,
            "elements": [
                "appliedenergistics2:smooth_sky_stone_stairs@0"
            ]
        },
        {
            "x": -2,
            "y": 1,
            "z": 8,
            "elements": [
                "appliedenergistics2:smooth_sky_stone_slab@0"
            ]
        },
        {
            "x": -2,
            "y": 8,
            "z": 7,
            "elements": [
                "appliedenergistics2:smooth_sky_stone_slab@0"
            ]
        },
        {
            "x": -2,
            "y": 1,
            "z": 9,
            "elements": [
                "mekanism:plasticfence@7"
            ]
        },
        {
            "x": 5,
            "y": 3,
            "z": 6,

            "elements": [
                "modularmachinery:blockcasing@4",
                "ItemInputStrengthen",
                "FluidInputStrengthen",
                "FluidOutputStrengthen",
                "EnergyInputStrengthen"
            ]
        },
        {
            "x": 5,
            "y": 3,
            "z": 5,
            "elements": [
                "mekanism:plasticfence@7"
            ]
        },
        {
            "x": -1,
            "y": 3,
            "z": 4,
            "elements": [
                "appliedenergistics2:quartz_vibrant_glass@0"
            ]
        },
        {
            "x": -1,
            "y": 3,
            "z": 3,
            "elements": [
                "minecraft:end_rod@4"
            ]
        },
        {
            "x": 5,
            "y": 3,
            "z": 7,
            "elements": [
                "mekanism:plasticfence@7"
            ]
        },
        {
            "x": -1,
            "y": 3,
            "z": 1,
            "elements": [
                "mekanism:plasticfence@7"
            ]
        },
        {
            "x": -1,
            "y": 3,
            "z": 11,
            "elements": [
                "mekanism:plasticfence@7"
            ]
        },
        {
            "x": 3,
            "y": 1,
            "z": 7,
            "elements": [
                "appliedenergistics2:smooth_sky_stone_slab@0"
            ]
        },
        {
            "x": 5,
            "y": 4,
            "z": 5,
            "elements": [
                "appliedenergistics2:smooth_sky_stone_stairs@6"
            ]
        },
        {
            "x": 3,
            "y": 1,
            "z": 8,
            "elements": [
                "mekanism:plasticfence@7"
            ]
        },
        {
            "x": -1,
            "y": 3,
            "z": 9,
            "elements": [
                "minecraft:end_rod@4"
            ]
        },
        {
            "x": 3,
            "y": 1,
            "z": 5,
            "elements": [
                "appliedenergistics2:smooth_sky_stone_slab@0"
            ]
        },
        {
            "x": -1,
            "y": 3,
            "z": 8,
            "elements": [
                "appliedenergistics2:quartz_vibrant_glass@0"
            ]
        },
        {
            "x": -1,
            "y": 3,
            "z": 7,
            "elements": [
                "appliedenergistics2:quartz_vibrant_glass@0"
            ]
        },
        {
            "x": -1,
            "y": 3,
            "z": 6,
            "elements": [
                "appliedenergistics2:quartz_vibrant_glass@0"
            ]
        },
        {
            "x": 3,
            "y": 1,
            "z": 4,
            "elements": [
                "mekanism:plasticfence@7"
            ]
        },
        {
            "x": -1,
            "y": 3,
            "z": 5,
            "elements": [
                "appliedenergistics2:quartz_vibrant_glass@0"
            ]
        },
        {
            "x": -2,
            "y": 7,
            "z": 7,
            "elements": [
                "appliedenergistics2:quartz_vibrant_glass@0"
            ]
        },
        {
            "x": -2,
            "y": 2,
            "z": 7,
            "elements": [
                "appliedenergistics2:smooth_sky_stone_slab@8"
            ]
        },
        {
            "x": -2,
            "y": 7,
            "z": 6,
            "elements": [
                "mekanism:basicblock@8"
            ]
        },
        {
            "x": -2,
            "y": 7,
            "z": 8,
            "elements": [
                "appliedenergistics2:smooth_sky_stone_slab@0"
            ]
        },
        {
            "x": -2,
            "y": 2,
            "z": 9,
            "elements": [
                "appliedenergistics2:smooth_sky_stone_slab@0"
            ]
        },
        {
            "x": -2,
            "y": 7,
            "z": 5,
            "elements": [
                "appliedenergistics2:quartz_vibrant_glass@0"
            ]
        },
        {
            "x": -2,
            "y": 7,
            "z": 4,
            "elements": [
                "appliedenergistics2:smooth_sky_stone_slab@0"
            ]
        },
        {
            "x": 4,
            "y": 3,
            "z": 6,
            "elements": [
                "appliedenergistics2:smooth_sky_stone_slab@8"
            ]
        },
        {
            "x": 0,
            "y": 5,
            "z": 2,
            "elements": [
                "enderio:block_alloy@6"
            ]
        },
        {
            "x": 0,
            "y": 5,
            "z": 3,
            "elements": [
                "mekanism:basicblock@8"
            ]
        },
        {
            "x": 0,
            "y": 5,
            "z": 4,
            "elements": [
                "appliedenergistics2:quartz_vibrant_glass@0"
            ]
        },
        {
            "x": 0,
            "y": 5,
            "z": 5,

            "elements": [
                "environmentaltech:structure_frame_2@0"
            ]
        },
        {
            "x": 0,
            "y": 5,
            "z": 6,
            "elements": [
                "enderio:block_alloy_endergy@4"
            ]
        },
        {
            "x": 3,
            "y": 7,
            "z": 6,
            "elements": [
                "mekanism:basicblock@8"
            ]
        },
        {
            "x": 3,
            "y": 7,
            "z": 5,
            "elements": [
                "minecraft:end_rod@2"
            ]
        },
        {
            "x": 0,
            "y": 5,
            "z": 7,

            "elements": [
                "environmentaltech:structure_frame_2@0"
            ]
        },
        {
            "x": 0,
            "y": 5,
            "z": 8,
            "elements": [
                "appliedenergistics2:quartz_vibrant_glass@0"
            ]
        },
        {
            "x": 0,
            "y": 5,
            "z": 9,
            "elements": [
                "mekanism:basicblock@8"
            ]
        },
        {
            "x": 3,
            "y": 7,
            "z": 7,
            "elements": [
                "minecraft:end_rod@3"
            ]
        },
        {
            "x": 0,
            "y": 5,
            "z": 1,

            "elements": [
                "modularmachinery:blockcasing@4",
                "ItemInputStrengthen",
                "FluidInputStrengthen",
                "FluidOutputStrengthen",
                "EnergyInputStrengthen"
            ]
        },
        {
            "x": -3,
            "y": 6,
            "z": 8,
            "elements": [
                "appliedenergistics2:smooth_sky_stone_slab@0"
            ]
        },
        {
            "x": -3,
            "y": 6,
            "z": 7,
            "elements": [
                "appliedenergistics2:smooth_sky_stone_slab@0"
            ]
        },
        {
            "x": -3,
            "y": 6,
            "z": 6,
            "elements": [
                "mekanism:basicblock@8"
            ]
        },
        {
            "x": -2,
            "y": 2,
            "z": 3,
            "elements": [
                "appliedenergistics2:smooth_sky_stone_slab@0"
            ]
        },
        {
            "x": -3,
            "y": 6,
            "z": 5,
            "elements": [
                "appliedenergistics2:smooth_sky_stone_slab@0"
            ]
        },
        {
            "x": -2,
            "y": 2,
            "z": 6,
            "elements": [
                "appliedenergistics2:smooth_sky_stone_stairs@4"
            ]
        },
        {
            "x": -2,
            "y": 2,
            "z": 5,
            "elements": [
                "appliedenergistics2:smooth_sky_stone_slab@8"
            ]
        },
        {
            "x": -3,
            "y": 6,
            "z": 4,
            "elements": [
                "appliedenergistics2:smooth_sky_stone_slab@0"
            ]
        },
        {
            "x": 5,
            "y": 5,
            "z": 6,

            "elements": [
                "modularmachinery:blockcasing@4",
                "ItemInputStrengthen",
                "FluidInputStrengthen",
                "FluidOutputStrengthen",
                "EnergyInputStrengthen"
            ]
        },
        {
            "x": 5,
            "y": 5,
            "z": 5,

            "elements": [
                "modularmachinery:blockcasing@4",
                "ItemInputStrengthen",
                "FluidInputStrengthen",
                "FluidOutputStrengthen",
                "EnergyInputStrengthen"
            ]
        },
        {
            "x": 5,
            "y": 5,
            "z": 7,

            "elements": [
                "modularmachinery:blockcasing@4",
                "ItemInputStrengthen",
                "FluidInputStrengthen",
                "FluidOutputStrengthen",
                "EnergyInputStrengthen"
            ]
        },
        {
            "x": -3,
            "y": 5,
            "z": 4,
            "elements": [
                "ic2:fence@0"
            ]
        },
        {
            "x": 3,
            "y": 6,
            "z": 5,
            "elements": [
                "appliedenergistics2:smooth_sky_stone_slab@0"
            ]
        },
        {
            "x": 3,
            "y": 6,
            "z": 4,
            "elements": [
                "appliedenergistics2:smooth_sky_stone_slab@0"
            ]
        },
        {
            "x": -1,
            "y": 4,
            "z": 3,
            "elements": [
                "appliedenergistics2:smooth_sky_stone_slab@8"
            ]
        },
        {
            "x": -1,
            "y": 4,
            "z": 2,
            "elements": [
                "appliedenergistics2:smooth_sky_stone_stairs@4"
            ]
        },
        {
            "x": -1,
            "y": 4,
            "z": 1,
            "elements": [
                "appliedenergistics2:smooth_sky_stone_stairs@4"
            ]
        },
        {
            "x": -1,
            "y": 4,
            "z": 7,
            "elements": [
                "appliedenergistics2:quartz_vibrant_glass@0"
            ]
        },
        {
            "x": -3,
            "y": 5,
            "z": 8,
            "elements": [
                "ic2:fence@0"
            ]
        },
        {
            "x": 0,
            "y": 5,
            "z": 10,
            "elements": [
                "enderio:block_alloy@6"
            ]
        },
        {
            "x": 0,
            "y": 5,
            "z": 11,

            "elements": [
                "modularmachinery:blockcasing@4",
                "ItemInputStrengthen",
                "FluidInputStrengthen",
                "FluidOutputStrengthen",
                "EnergyInputStrengthen"
            ]
        },
        {
            "x": -1,
            "y": 4,
            "z": 6,
            "elements": [
                "appliedenergistics2:quartz_vibrant_glass@0"
            ]
        },
        {
            "x": -3,
            "y": 5,
            "z": 7,
            "elements": [
                "contenttweaker:mysteriousicecasing@0"
            ]
        },
        {
            "x": -3,
            "y": 5,
            "z": 6,
            "elements": [
                "mekanism:basicblock@8"
            ]
        },
        {
            "x": -1,
            "y": 4,
            "z": 5,
            "elements": [
                "appliedenergistics2:quartz_vibrant_glass@0"
            ]
        },
        {
            "x": -1,
            "y": 4,
            "z": 4,
            "elements": [
                "appliedenergistics2:quartz_vibrant_glass@0"
            ]
        },
        {
            "x": -3,
            "y": 5,
            "z": 5,
            "elements": [
                "contenttweaker:mysteriousicecasing@0"
            ]
        },
        {
            "x": -1,
            "y": 4,
            "z": 11,
            "elements": [
                "appliedenergistics2:smooth_sky_stone_stairs@4"
            ]
        },
        {
            "x": -1,
            "y": 4,
            "z": 10,
            "elements": [
                "appliedenergistics2:smooth_sky_stone_stairs@4"
            ]
        },
        {
            "x": -1,
            "y": 4,
            "z": 9,
            "elements": [
                "appliedenergistics2:smooth_sky_stone_slab@8"
            ]
        },
        {
            "x": -1,
            "y": 4,
            "z": 8,
            "elements": [
                "appliedenergistics2:quartz_vibrant_glass@0"
            ]
        },
        {
            "x": 6,
            "y": 0,
            "z": 7,
            "elements": [
                "appliedenergistics2:smooth_sky_stone_stairs@1"
            ]
        },
        {
            "x": 6,
            "y": 0,
            "z": 6,
            "elements": [
                "enderio:block_alloy@6"
            ]
        },
        {
            "x": 6,
            "y": 0,
            "z": 5,
            "elements": [
                "appliedenergistics2:smooth_sky_stone_stairs@1"
            ]
        },
        {
            "x": 0,
            "y": 6,
            "z": 5,
            "elements": [
                "appliedenergistics2:quartz_vibrant_glass@0"
            ]
        },
        {
            "x": 0,
            "y": 6,
            "z": 6,

            "elements": [
                "environmentaltech:structure_frame_2@0"
            ]
        },
        {
            "x": 0,
            "y": 6,
            "z": 7,
            "elements": [
                "appliedenergistics2:quartz_vibrant_glass@0"
            ]
        },
        {
            "x": 0,
            "y": 6,
            "z": 8,
            "elements": [
                "appliedenergistics2:quartz_vibrant_glass@0"
            ]
        },
        {
            "x": 0,
            "y": 6,
            "z": 1,
            "elements": [
                "appliedenergistics2:smooth_sky_stone_slab@0"
            ]
        },
        {
            "x": 0,
            "y": 6,
            "z": 2,
            "elements": [
                "extendedcrafting:lamp@1"
            ]
        },
        {
            "x": 0,
            "y": 6,
            "z": 3,
            "elements": [
                "mekanism:basicblock@8"
            ]
        },
        {
            "x": 0,
            "y": 6,
            "z": 4,
            "elements": [
                "appliedenergistics2:quartz_vibrant_glass@0"
            ]
        },
        {
            "x": 0,
            "y": 6,
            "z": 9,
            "elements": [
                "mekanism:basicblock@8"
            ]
        },
        {
            "x": 0,
            "y": 6,
            "z": 10,
            "elements": [
                "extendedcrafting:lamp@1"
            ]
        },
        {
            "x": 0,
            "y": 6,
            "z": 11,
            "elements": [
                "appliedenergistics2:smooth_sky_stone_slab@0"
            ]
        },
        {
            "x": 3,
            "y": 0,
            "z": 6,
            "elements": [
                "enderio:block_alloy@0"
            ]
        },
        {
            "x": 3,
            "y": 0,
            "z": 7,
            "elements": [
                "fluxnetworks:fluxblock@0"
            ]
        },
        {
            "x": 3,
            "y": 0,
            "z": 4,
            "elements": [
                "enderio:block_alloy@8"
            ]
        },
        {
            "x": 3,
            "y": 0,
            "z": 5,
            "elements": [
                "fluxnetworks:fluxblock@0"
            ]
        },
        {
            "x": 3,
            "y": 0,
            "z": 10,
            "elements": [
                "enderio:block_alloy@6"
            ]
        },
        {
            "x": 3,
            "y": 0,
            "z": 8,
            "elements": [
                "enderio:block_alloy@8"
            ]
        },
        {
            "x": 3,
            "y": 0,
            "z": 9,
            "elements": [
                "enderio:block_alloy@8"
            ]
        },
        {
            "x": 3,
            "y": 0,
            "z": 2,
            "elements": [
                "enderio:block_alloy@6"
            ]
        },
        {
            "x": 5,
            "y": 4,
            "z": 7,
            "elements": [
                "appliedenergistics2:smooth_sky_stone_stairs@7"
            ]
        },
        {
            "x": 3,
            "y": 0,
            "z": 3,
            "elements": [
                "enderio:block_alloy@8"
            ]
        },
        {
            "x": 5,
            "y": 4,
            "z": 6,

            "elements": [
                "modularmachinery:blockcasing@4",
                "ItemInputStrengthen",
                "FluidInputStrengthen",
                "FluidOutputStrengthen",
                "EnergyInputStrengthen"
            ]
        },
        {
            "x": 2,
            "y": 4,
            "z": 3,
            "elements": [
                "appliedenergistics2:smooth_sky_stone_slab@8"
            ]
        },
        {
            "x": 2,
            "y": 4,
            "z": 4,
            "elements": [
                "appliedenergistics2:quartz_vibrant_glass@0"
            ]
        },
        {
            "x": 2,
            "y": 4,
            "z": 5,
            "elements": [
                "appliedenergistics2:quartz_vibrant_glass@0"
            ]
        },
        {
            "x": 2,
            "y": 4,
            "z": 6,
            "elements": [
                "appliedenergistics2:quartz_vibrant_glass@0"
            ]
        },
        {
            "x": 2,
            "y": 4,
            "z": 7,
            "elements": [
                "appliedenergistics2:quartz_vibrant_glass@0"
            ]
        },
        {
            "x": 2,
            "y": 4,
            "z": 8,
            "elements": [
                "appliedenergistics2:quartz_vibrant_glass@0"
            ]
        },
        {
            "x": 2,
            "y": 4,
            "z": 9,
            "elements": [
                "appliedenergistics2:smooth_sky_stone_slab@8"
            ]
        },
        {
            "x": 1,
            "y": 8,
            "z": 4,
            "elements": [
                "appliedenergistics2:smooth_sky_stone_slab@0"
            ]
        },
        {
            "x": 1,
            "y": 8,
            "z": 5,
            "elements": [
                "appliedenergistics2:quartz_vibrant_glass@0"
            ]
        },
        {
            "x": 3,
            "y": 6,
            "z": 7,
            "elements": [
                "appliedenergistics2:smooth_sky_stone_slab@0"
            ]
        },
        {
            "x": 3,
            "y": 6,
            "z": 6,
            "elements": [
                "mekanism:basicblock@8"
            ]
        },
        {
            "x": 3,
            "y": 6,
            "z": 8,
            "elements": [
                "appliedenergistics2:smooth_sky_stone_slab@0"
            ]
        },
        {
            "x": -4,
            "y": 3,
            "z": 6,
            "elements": [
                "appliedenergistics2:smooth_sky_stone_slab@8"
            ]
        },
        {
            "x": 2,
            "y": 3,
            "z": 6,
            "elements": [
                "mekanism:basicblock@8"
            ]
        },
        {
            "x": 2,
            "y": 3,
            "z": 7,
            "elements": [
                "appliedenergistics2:quartz_vibrant_glass@0"
            ]
        },
        {
            "x": 3,
            "y": 4,
            "z": 8,
            "elements": [
                "appliedenergistics2:smooth_sky_stone_slab@8"
            ]
        },
        {
            "x": 2,
            "y": 3,
            "z": 8,
            "elements": [
                "appliedenergistics2:smooth_sky_stone_slab@8"
            ]
        },
        {
            "x": 2,
            "y": 3,
            "z": 4,
            "elements": [
                "appliedenergistics2:smooth_sky_stone_slab@8"
            ]
        },
        {
            "x": 2,
            "y": 3,
            "z": 5,
            "elements": [
                "appliedenergistics2:quartz_vibrant_glass@0"
            ]
        },
        {
            "x": 3,
            "y": 4,
            "z": 6,
            "elements": [
                "mekanism:basicblock@8"
            ]
        },
        {
            "x": 3,
            "y": 4,
            "z": 7,
            "elements": [
                "appliedenergistics2:smooth_sky_stone_slab@8"
            ]
        },
        {
            "x": 3,
            "y": 4,
            "z": 4,
            "elements": [
                "appliedenergistics2:smooth_sky_stone_slab@8"
            ]
        },
        {
            "x": 3,
            "y": 4,
            "z": 5,
            "elements": [
                "appliedenergistics2:smooth_sky_stone_slab@8"
            ]
        },
        {
            "x": 0,
            "y": 0,
            "z": 12,
            "elements": [
                "enderio:block_alloy@6"
            ]
        },
        {
            "x": 0,
            "y": 0,
            "z": 11,
            "elements": [
                "enderio:block_alloy@6"
            ]
        },
        {
            "x": 0,
            "y": 0,
            "z": 8,
            "elements": [
                "enderio:block_alloy@0"
            ]
        },
        {
            "x": 0,
            "y": 0,
            "z": 7,
            "elements": [
                "fluxnetworks:fluxblock@0"
            ]
        },
        {
            "x": 4,
            "y": 5,
            "z": 7,
            "elements": [
                "minecraft:end_rod@4"
            ]
        },
        {
            "x": 0,
            "y": 0,
            "z": 10,
            "elements": [
                "enderio:block_alloy@0"
            ]
        },
        {
            "x": 4,
            "y": 5,
            "z": 6,
            "elements": [
                "enderio:block_alloy@6"
            ]
        },
        {
            "x": 0,
            "y": 0,
            "z": 9,
            "elements": [
                "enderio:block_alloy@0"
            ]
        },
        {
            "x": 1,
            "y": 2,
            "z": 11,
            "elements": [
                "mekanism:plasticfence@7"
            ]
        },
        {
            "x": 4,
            "y": 5,
            "z": 5,
            "elements": [
                "minecraft:end_rod@4"
            ]
        },
        {
            "x": 0,
            "y": 0,
            "z": 4,
            "elements": [
                "enderio:block_alloy@0"
            ]
        },
        {
            "x": 0,
            "y": 0,
            "z": 3,
            "elements": [
                "enderio:block_alloy@0"
            ]
        },
        {
            "x": 0,
            "y": 0,
            "z": 6,
            "elements": [
                "fluxnetworks:fluxblock@0"
            ]
        },
        {
            "x": 0,
            "y": 0,
            "z": 5,
            "elements": [
                "fluxnetworks:fluxblock@0"
            ]
        },
        {
            "x": 1,
            "y": 2,
            "z": 8,
            "elements": [
                "appliedenergistics2:smooth_sky_stone_slab@8"
            ]
        },
        {
            "x": 1,
            "y": 2,
            "z": 7,
            "elements": [
                "appliedenergistics2:quartz_vibrant_glass@0"
            ]
        },
        {
            "x": 0,
            "y": 0,
            "z": 0,

            "elements": [
                "modularmachinery:blockcontroller@2"
            ]
        },
        {
            "x": 1,
            "y": 2,
            "z": 6,
            "elements": [
                "mekanism:basicblock@8"
            ]
        },
        {
            "x": 1,
            "y": 2,
            "z": 5,
            "elements": [
                "appliedenergistics2:quartz_vibrant_glass@0"
            ]
        },
        {
            "x": 0,
            "y": 0,
            "z": 2,
            "elements": [
                "enderio:block_alloy@0"
            ]
        },
        {
            "x": 1,
            "y": 2,
            "z": 4,
            "elements": [
                "appliedenergistics2:smooth_sky_stone_slab@8"
            ]
        },
        {
            "x": 0,
            "y": 0,
            "z": 1,
            "elements": [
                "enderio:block_alloy@6"
            ]
        },
        {
            "x": 1,
            "y": 2,
            "z": 1,
            "elements": [
                "mekanism:plasticfence@7"
            ]
        },
        {
            "x": 3,
            "y": 5,
            "z": 4,
            "elements": [
                "ic2:fence@0"
            ]
        },
        {
            "x": 3,
            "y": 5,
            "z": 6,
            "elements": [
                "mekanism:basicblock@8"
            ]
        },
        {
            "x": 3,
            "y": 5,
            "z": 5,
            "elements": [
                "contenttweaker:mysteriousicecasing@0"
            ]
        },
        {
            "x": 1,
            "y": 1,
            "z": 4,
            "elements": [
                "appliedenergistics2:smooth_sky_stone_slab@0"
            ]
        },
        {
            "x": 3,
            "y": 5,
            "z": 8,
            "elements": [
                "ic2:fence@0"
            ]
        },
        {
            "x": 1,
            "y": 1,
            "z": 3,
            "elements": [
                "appliedenergistics2:smooth_sky_stone_slab@0"
            ]
        },
        {
            "x": 3,
            "y": 5,
            "z": 7,
            "elements": [
                "contenttweaker:mysteriousicecasing@0"
            ]
        },
        {
            "x": 1,
            "y": 1,
            "z": 1,
            "elements": [
                "mekanism:plasticfence@7"
            ]
        },
        {
            "x": 1,
            "y": 1,
            "z": 8,
            "elements": [
                "appliedenergistics2:smooth_sky_stone_slab@0"
            ]
        },
        {
            "x": 1,
            "y": 1,
            "z": 6,
            "elements": [
                "appliedenergistics2:smooth_sky_stone_slab@8"
            ]
        },
        {
            "x": 1,
            "y": 1,
            "z": 11,
            "elements": [
                "mekanism:plasticfence@7"
            ]
        },
        {
            "x": 1,
            "y": 1,
            "z": 9,
            "elements": [
                "appliedenergistics2:smooth_sky_stone_slab@0"
            ]
        },
        {
            "x": 4,
            "y": 6,
            "z": 7,
            "elements": [
                "appliedenergistics2:smooth_sky_stone_stairs@3"
            ]
        },
        {
            "x": 4,
            "y": 6,
            "z": 6,
            "elements": [
                "extendedcrafting:lamp@1"
            ]
        },
        {
            "x": 4,
            "y": 6,
            "z": 5,
            "elements": [
                "appliedenergistics2:smooth_sky_stone_stairs@2"
            ]
        },
        {
            "x": 1,
            "y": 0,
            "z": 5,
            "elements": [
                "fluxnetworks:fluxblock@0"
            ]
        },
        {
            "x": 1,
            "y": 0,
            "z": 4,
            "elements": [
                "enderio:block_alloy@0"
            ]
        },
        {
            "x": 1,
            "y": 0,
            "z": 3,
            "elements": [
                "fluxnetworks:fluxblock@0"
            ]
        },
        {
            "x": -4,
            "y": 7,
            "z": 6,
            "elements": [
                "appliedenergistics2:smooth_sky_stone_slab@0"
            ]
        },
        {
            "x": 1,
            "y": 0,
            "z": 2,
            "elements": [
                "enderio:block_alloy@6"
            ]
        },
        {
            "x": 1,
            "y": 0,
            "z": 1,
            "elements": [
                "enderio:block_alloy@6"
            ]
        },
        {
            "x": 1,
            "y": 0,
            "z": 0,
            "elements": [
                "appliedenergistics2:smooth_sky_stone_stairs@2"
            ]
        },
        {
            "x": 4,
            "y": 7,
            "z": 6,
            "elements": [
                "appliedenergistics2:smooth_sky_stone_slab@0"
            ]
        },
        {
            "x": 1,
            "y": 0,
            "z": 12,
            "elements": [
                "appliedenergistics2:smooth_sky_stone_stairs@3"
            ]
        },
        {
            "x": 1,
            "y": 0,
            "z": 11,
            "elements": [
                "enderio:block_alloy@6"
            ]
        },
        {
            "x": 1,
            "y": 0,
            "z": 10,
            "elements": [
                "enderio:block_alloy@6"
            ]
        },
        {
            "x": 1,
            "y": 0,
            "z": 9,
            "elements": [
                "fluxnetworks:fluxblock@0"
            ]
        },
        {
            "x": 1,
            "y": 0,
            "z": 8,
            "elements": [
                "enderio:block_alloy@0"
            ]
        },
        {
            "x": 1,
            "y": 0,
            "z": 7,
            "elements": [
                "fluxnetworks:fluxblock@0"
            ]
        },
        {
            "x": 1,
            "y": 0,
            "z": 6,
            "elements": [
                "fluxnetworks:fluxblock@0"
            ]
        },
        {
            "x": 1,
            "y": 3,
            "z": 11,
            "elements": [
                "mekanism:plasticfence@7"
            ]
        },
        {
            "x": -5,
            "y": 6,
            "z": 5,
            "elements": [
                "appliedenergistics2:smooth_sky_stone_slab@0"
            ]
        },
        {
            "x": 1,
            "y": 3,
            "z": 5,
            "elements": [
                "appliedenergistics2:quartz_vibrant_glass@0"
            ]
        },
        {
            "x": 1,
            "y": 3,
            "z": 6,
            "elements": [
                "appliedenergistics2:quartz_vibrant_glass@0"
            ]
        },
        {
            "x": 1,
            "y": 3,
            "z": 3,
            "elements": [
                "minecraft:end_rod@5"
            ]
        },
        {
            "x": 1,
            "y": 3,
            "z": 4,
            "elements": [
                "appliedenergistics2:quartz_vibrant_glass@0"
            ]
        },
        {
            "x": -5,
            "y": 6,
            "z": 6,
            "elements": [
                "appliedenergistics2:smooth_sky_stone_slab@0"
            ]
        },
        {
            "x": 1,
            "y": 3,
            "z": 9,
            "elements": [
                "minecraft:end_rod@5"
            ]
        },
        {
            "x": -5,
            "y": 6,
            "z": 7,
            "elements": [
                "appliedenergistics2:smooth_sky_stone_slab@0"
            ]
        },
        {
            "x": 1,
            "y": 3,
            "z": 7,
            "elements": [
                "appliedenergistics2:quartz_vibrant_glass@0"
            ]
        },
        {
            "x": 1,
            "y": 3,
            "z": 8,
            "elements": [
                "appliedenergistics2:quartz_vibrant_glass@0"
            ]
        },
        {
            "x": -2,
            "y": 0,
            "z": 3,
            "elements": [
                "enderio:block_alloy@8"
            ]
        },
        {
            "x": 2,
            "y": 5,
            "z": 4,
            "elements": [
                "appliedenergistics2:quartz_vibrant_glass@0"
            ]
        },
        {
            "x": 2,
            "y": 5,
            "z": 5,
            "elements": [
                "appliedenergistics2:quartz_vibrant_glass@0"
            ]
        },
        {
            "x": -2,
            "y": 0,
            "z": 4,
            "elements": [
                "fluxnetworks:fluxblock@0"
            ]
        },
        {
            "x": 2,
            "y": 5,
            "z": 6,
            "elements": [
                "appliedenergistics2:quartz_vibrant_glass@0"
            ]
        },
        {
            "x": -2,
            "y": 0,
            "z": 1,
            "elements": [
                "appliedenergistics2:smooth_sky_stone_stairs@0"
            ]
        },
        {
            "x": 2,
            "y": 5,
            "z": 7,
            "elements": [
                "appliedenergistics2:quartz_vibrant_glass@0"
            ]
        },
        {
            "x": -2,
            "y": 0,
            "z": 2,
            "elements": [
                "enderio:block_alloy@6"
            ]
        },
        {
            "x": 1,
            "y": 3,
            "z": 1,
            "elements": [
                "mekanism:plasticfence@7"
            ]
        },
        {
            "x": -2,
            "y": 0,
            "z": 7,
            "elements": [
                "enderio:block_alloy@0"
            ]
        },
        {
            "x": -2,
            "y": 0,
            "z": 8,
            "elements": [
                "fluxnetworks:fluxblock@0"
            ]
        },
        {
            "x": -2,
            "y": 0,
            "z": 5,
            "elements": [
                "enderio:block_alloy@0"
            ]
        },
        {
            "x": -2,
            "y": 0,
            "z": 6,
            "elements": [
                "enderio:block_alloy@0"
            ]
        },
        {
            "x": 2,
            "y": 5,
            "z": 3,
            "elements": [
                "ic2:fence@0"
            ]
        },
        {
            "x": 4,
            "y": 4,
            "z": 6,
            "elements": [
                "enderio:block_alloy@6"
            ]
        },
        {
            "x": 4,
            "y": 4,
            "z": 5,
            "elements": [
                "appliedenergistics2:smooth_sky_stone_stairs@6"
            ]
        },
        {
            "x": -5,
            "y": 5,
            "z": 7,

            "elements": [
                "modularmachinery:blockcasing@4",
                "ItemInputStrengthen",
                "FluidInputStrengthen",
                "FluidOutputStrengthen",
                "EnergyInputStrengthen"
            ]
        },
        {
            "x": -2,
            "y": 0,
            "z": 11,
            "elements": [
                "appliedenergistics2:smooth_sky_stone_stairs@0"
            ]
        },
        {
            "x": -2,
            "y": 0,
            "z": 9,
            "elements": [
                "enderio:block_alloy@8"
            ]
        },
        {
            "x": -2,
            "y": 0,
            "z": 10,
            "elements": [
                "enderio:block_alloy@6"
            ]
        },
        {
            "x": 4,
            "y": 4,
            "z": 7,
            "elements": [
                "appliedenergistics2:smooth_sky_stone_stairs@7"
            ]
        },
        {
            "x": 2,
            "y": 5,
            "z": 8,
            "elements": [
                "appliedenergistics2:quartz_vibrant_glass@0"
            ]
        },
        {
            "x": 2,
            "y": 5,
            "z": 9,
            "elements": [
                "ic2:fence@0"
            ]
        },
        {
            "x": 2,
            "y": 2,
            "z": 3,
            "elements": [
                "appliedenergistics2:smooth_sky_stone_slab@0"
            ]
        },
        {
            "x": 2,
            "y": 2,
            "z": 5,
            "elements": [
                "appliedenergistics2:smooth_sky_stone_slab@8"
            ]
        },
        {
            "x": 2,
            "y": 2,
            "z": 6,
            "elements": [
                "appliedenergistics2:smooth_sky_stone_stairs@5"
            ]
        },
        {
            "x": 2,
            "y": 2,
            "z": 7,
            "elements": [
                "appliedenergistics2:smooth_sky_stone_slab@8"
            ]
        },
        {
            "x": 2,
            "y": 2,
            "z": 9,
            "elements": [
                "appliedenergistics2:smooth_sky_stone_slab@0"
            ]
        },
        {
            "x": 5,
            "y": 6,
            "z": 5,
            "elements": [
                "appliedenergistics2:smooth_sky_stone_slab@0"
            ]
        },
        {
            "x": 5,
            "y": 6,
            "z": 7,
            "elements": [
                "appliedenergistics2:smooth_sky_stone_slab@0"
            ]
        },
        {
            "x": 5,
            "y": 6,
            "z": 6,
            "elements": [
                "appliedenergistics2:smooth_sky_stone_slab@0"
            ]
        },
        {
            "x": -1,
            "y": 2,
            "z": 8,
            "elements": [
                "appliedenergistics2:smooth_sky_stone_slab@8"
            ]
        },
        {
            "x": -1,
            "y": 2,
            "z": 7,
            "elements": [
                "appliedenergistics2:quartz_vibrant_glass@0"
            ]
        },
        {
            "x": -1,
            "y": 2,
            "z": 6,
            "elements": [
                "mekanism:basicblock@8"
            ]
        },
        {
            "x": -1,
            "y": 2,
            "z": 11,
            "elements": [
                "mekanism:plasticfence@7"
            ]
        },
        {
            "x": -1,
            "y": 2,
            "z": 1,
            "elements": [
                "mekanism:plasticfence@7"
            ]
        },
        {
            "x": -1,
            "y": 2,
            "z": 5,
            "elements": [
                "appliedenergistics2:quartz_vibrant_glass@0"
            ]
        },
        {
            "x": -1,
            "y": 2,
            "z": 4,
            "elements": [
                "appliedenergistics2:smooth_sky_stone_slab@8"
            ]
        },
        {
            "x": 0,
            "y": 1,
            "z": 7,
            "elements": [
                "appliedenergistics2:smooth_sky_stone_slab@8"
            ]
        },
        {
            "x": 0,
            "y": 1,
            "z": 6,
            "elements": [
                "appliedenergistics2:smooth_sky_stone_slab@8"
            ]
        },
        {
            "x": 0,
            "y": 1,
            "z": 11,

            "elements": [
                "modularmachinery:blockcasing@4",
                "ItemInputStrengthen",
                "FluidInputStrengthen",
                "FluidOutputStrengthen",
                "EnergyInputStrengthen"
            ]
        },
        {
            "x": 0,
            "y": 1,
            "z": 12,
            "elements": [
                "appliedenergistics2:smooth_sky_stone_slab@0"
            ]
        },
        {
            "x": 0,
            "y": 1,
            "z": 1,

            "elements": [
                "modularmachinery:blockcasing@4",
                "ItemInputStrengthen",
                "FluidInputStrengthen",
                "FluidOutputStrengthen",
                "EnergyInputStrengthen"
            ]
        },
        {
            "x": 0,
            "y": 1,
            "z": 0,
            "elements": [
                "appliedenergistics2:smooth_sky_stone_slab@0"
            ]
        },
        {
            "x": 0,
            "y": 1,
            "z": 5,
            "elements": [
                "appliedenergistics2:smooth_sky_stone_slab@8"
            ]
        },
        {
            "x": 1,
            "y": 5,
            "z": 3,
            "elements": [
                "contenttweaker:mysteriousicecasing@0"
            ]
        },
        {
            "x": 1,
            "y": 5,
            "z": 4,
            "elements": [
                "appliedenergistics2:quartz_vibrant_glass@0"
            ]
        },
        {
            "x": 1,
            "y": 5,
            "z": 1,

            "elements": [
                "modularmachinery:blockcasing@4",
                "ItemInputStrengthen",
                "FluidInputStrengthen",
                "FluidOutputStrengthen",
                "EnergyInputStrengthen"
            ]
        },
        {
            "x": 1,
            "y": 5,
            "z": 2,
            "elements": [
                "minecraft:end_rod@3"
            ]
        },
        {
            "x": 1,
            "y": 5,
            "z": 7,
            "elements": [
                "appliedenergistics2:quartz_vibrant_glass@0"
            ]
        },
        {
            "x": 1,
            "y": 5,
            "z": 8,
            "elements": [
                "appliedenergistics2:quartz_vibrant_glass@0"
            ]
        },
        {
            "x": 1,
            "y": 5,
            "z": 5,
            "elements": [
                "appliedenergistics2:quartz_vibrant_glass@0"
            ]
        },
        {
            "x": 1,
            "y": 5,
            "z": 6,

            "elements": [
                "environmentaltech:structure_frame_2@0"
            ]
        },
        {
            "x": 1,
            "y": 5,
            "z": 11,

            "elements": [
                "modularmachinery:blockcasing@4",
                "ItemInputStrengthen",
                "FluidInputStrengthen",
                "FluidOutputStrengthen",
                "EnergyInputStrengthen"
            ]
        },
        {
            "x": -5,
            "y": 4,
            "z": 5,
            "elements": [
                "appliedenergistics2:smooth_sky_stone_stairs@6"
            ]
        },
        {
            "x": 1,
            "y": 5,
            "z": 9,
            "elements": [
                "contenttweaker:mysteriousicecasing@0"
            ]
        },
        {
            "x": -5,
            "y": 4,
            "z": 6,

            "elements": [
                "modularmachinery:blockcasing@4",
                "ItemInputStrengthen",
                "FluidInputStrengthen",
                "FluidOutputStrengthen",
                "EnergyInputStrengthen"
            ]
        },
        {
            "x": -5,
            "y": 4,
            "z": 7,
            "elements": [
                "appliedenergistics2:smooth_sky_stone_stairs@7"
            ]
        },
        {
            "x": 1,
            "y": 5,
            "z": 10,
            "elements": [
                "minecraft:end_rod@2"
            ]
        },
        {
            "x": 2,
            "y": 6,
            "z": 7,
            "elements": [
                "appliedenergistics2:quartz_vibrant_glass@0"
            ]
        },
        {
            "x": 2,
            "y": 6,
            "z": 8,
            "elements": [
                "appliedenergistics2:quartz_vibrant_glass@0"
            ]
        },
        {
            "x": 2,
            "y": 6,
            "z": 9,
            "elements": [
                "appliedenergistics2:smooth_sky_stone_slab@0"
            ]
        },
        {
            "x": 0,
            "y": 4,
            "z": 1,

            "elements": [
                "modularmachinery:blockcasing@4",
                "ItemInputStrengthen",
                "FluidInputStrengthen",
                "FluidOutputStrengthen",
                "EnergyInputStrengthen"
            ]
        },
        {
            "x": 0,
            "y": 4,
            "z": 2,
            "elements": [
                "enderio:block_alloy@6"
            ]
        },
        {
            "x": 2,
            "y": 6,
            "z": 3,
            "elements": [
                "appliedenergistics2:smooth_sky_stone_slab@0"
            ]
        },
        {
            "x": 2,
            "y": 6,
            "z": 4,
            "elements": [
                "appliedenergistics2:quartz_vibrant_glass@0"
            ]
        },
        {
            "x": 2,
            "y": 6,
            "z": 5,
            "elements": [
                "appliedenergistics2:quartz_vibrant_glass@0"
            ]
        },
        {
            "x": 2,
            "y": 6,
            "z": 6,
            "elements": [
                "appliedenergistics2:quartz_vibrant_glass@0"
            ]
        },
        {
            "x": -3,
            "y": 7,
            "z": 6,
            "elements": [
                "mekanism:basicblock@8"
            ]
        },
        {
            "x": -3,
            "y": 7,
            "z": 5,
            "elements": [
                "minecraft:end_rod@2"
            ]
        },
        {
            "x": -4,
            "y": 5,
            "z": 5,
            "elements": [
                "minecraft:end_rod@5"
            ]
        },
        {
            "x": -3,
            "y": 7,
            "z": 7,
            "elements": [
                "minecraft:end_rod@3"
            ]
        },
        {
            "x": -4,
            "y": 5,
            "z": 6,
            "elements": [
                "enderio:block_alloy@6"
            ]
        },
        {
            "x": -4,
            "y": 5,
            "z": 7,
            "elements": [
                "minecraft:end_rod@5"
            ]
        },
        {
            "x": 3,
            "y": 8,
            "z": 6,
            "elements": [
                "appliedenergistics2:smooth_sky_stone_slab@0"
            ]
        },
        {
            "x": 0,
            "y": 3,
            "z": 1,

            "elements": [
                "modularmachinery:blockcasing@4",
                "ItemInputStrengthen",
                "FluidInputStrengthen",
                "FluidOutputStrengthen",
                "EnergyInputStrengthen"
            ]
        },
        {
            "x": 0,
            "y": 3,
            "z": 3,
            "elements": [
                "mekanism:basicblock@8"
            ]
        },
        {
            "x": 1,
            "y": 4,
            "z": 10,
            "elements": [
                "appliedenergistics2:smooth_sky_stone_stairs@5"
            ]
        },
        {
            "x": -5,
            "y": 5,
            "z": 5,

            "elements": [
                "modularmachinery:blockcasing@4",
                "ItemInputStrengthen",
                "FluidInputStrengthen",
                "FluidOutputStrengthen",
                "EnergyInputStrengthen"
            ]
        },
        {
            "x": 0,
            "y": 3,
            "z": 2,
            "elements": [
                "appliedenergistics2:smooth_sky_stone_slab@8"
            ]
        },
        {
            "x": -5,
            "y": 5,
            "z": 6,

            "elements": [
                "modularmachinery:blockcasing@4",
                "ItemInputStrengthen",
                "FluidInputStrengthen",
                "FluidOutputStrengthen",
                "EnergyInputStrengthen"
            ]
        },
        {
            "x": 1,
            "y": 4,
            "z": 11,
            "elements": [
                "appliedenergistics2:smooth_sky_stone_stairs@5"
            ]
        },
        {
            "x": 0,
            "y": 3,
            "z": 5,
            "elements": [
                "appliedenergistics2:quartz_vibrant_glass@0"
            ]
        },
        {
            "x": 0,
            "y": 3,
            "z": 4,
            "elements": [
                "mekanism:basicblock@8"
            ]
        },
        {
            "x": 0,
            "y": 3,
            "z": 7,
            "elements": [
                "appliedenergistics2:quartz_vibrant_glass@0"
            ]
        },
        {
            "x": 0,
            "y": 3,
            "z": 6,
            "elements": [
                "appliedenergistics2:quartz_vibrant_glass@0"
            ]
        },
        {
            "x": 0,
            "y": 3,
            "z": 9,
            "elements": [
                "mekanism:basicblock@8"
            ]
        },
        {
            "x": 0,
            "y": 3,
            "z": 8,
            "elements": [
                "mekanism:basicblock@8"
            ]
        },
        {
            "x": 0,
            "y": 3,
            "z": 11,

            "elements": [
                "modularmachinery:blockcasing@4",
                "ItemInputStrengthen",
                "FluidInputStrengthen",
                "FluidOutputStrengthen",
                "EnergyInputStrengthen"
            ]
        },
        {
            "x": 0,
            "y": 3,
            "z": 10,
            "elements": [
                "appliedenergistics2:smooth_sky_stone_slab@8"
            ]
        },
        {
            "x": 3,
            "y": 2,
            "z": 4,
            "elements": [
                "appliedenergistics2:smooth_sky_stone_slab@0"
            ]
        },
        {
            "x": 3,
            "y": 2,
            "z": 8,
            "elements": [
                "appliedenergistics2:smooth_sky_stone_slab@0"
            ]
        },
        {
            "x": 3,
            "y": 2,
            "z": 6,
            "elements": [
                "appliedenergistics2:smooth_sky_stone_slab@8"
            ]
        },
        {
            "x": 2,
            "y": 0,
            "z": 6,
            "elements": [
                "enderio:block_alloy@0"
            ]
        },
        {
            "x": 2,
            "y": 0,
            "z": 5,
            "elements": [
                "enderio:block_alloy@0"
            ]
        },
        {
            "x": 2,
            "y": 0,
            "z": 8,
            "elements": [
                "fluxnetworks:fluxblock@0"
            ]
        },
        {
            "x": 2,
            "y": 0,
            "z": 7,
            "elements": [
                "enderio:block_alloy@0"
            ]
        },
        {
            "x": 2,
            "y": 0,
            "z": 10,
            "elements": [
                "enderio:block_alloy@6"
            ]
        },
        {
            "x": 2,
            "y": 0,
            "z": 9,
            "elements": [
                "enderio:block_alloy@8"
            ]
        },
        {
            "x": 2,
            "y": 0,
            "z": 11,
            "elements": [
                "appliedenergistics2:smooth_sky_stone_stairs@1"
            ]
        },
        {
            "x": -1,
            "y": 1,
            "z": 11,
            "elements": [
                "mekanism:plasticfence@7"
            ]
        },
        {
            "x": -5,
            "y": 3,
            "z": 5,
            "elements": [
                "mekanism:plasticfence@7"
            ]
        },
        {
            "x": -5,
            "y": 3,
            "z": 6,

            "elements": [
                "modularmachinery:blockcasing@4",
                "ItemInputStrengthen",
                "FluidInputStrengthen",
                "FluidOutputStrengthen",
                "EnergyInputStrengthen"
            ]
        },
        {
            "x": -1,
            "y": 1,
            "z": 9,
            "elements": [
                "appliedenergistics2:smooth_sky_stone_slab@0"
            ]
        },
        {
            "x": -1,
            "y": 1,
            "z": 8,
            "elements": [
                "appliedenergistics2:smooth_sky_stone_slab@0"
            ]
        },
        {
            "x": -5,
            "y": 3,
            "z": 7,
            "elements": [
                "mekanism:plasticfence@7"
            ]
        },
        {
            "x": 1,
            "y": 4,
            "z": 1,
            "elements": [
                "appliedenergistics2:smooth_sky_stone_stairs@5"
            ]
        },
        {
            "x": 5,
            "y": 2,
            "z": 5,
            "elements": [
                "mekanism:plasticfence@7"
            ]
        },
        {
            "x": 1,
            "y": 4,
            "z": 8,
            "elements": [
                "appliedenergistics2:quartz_vibrant_glass@0"
            ]
        },
        {
            "x": 1,
            "y": 4,
            "z": 9,
            "elements": [
                "appliedenergistics2:smooth_sky_stone_slab@8"
            ]
        },
        {
            "x": 5,
            "y": 2,
            "z": 7,
            "elements": [
                "mekanism:plasticfence@7"
            ]
        },
        {
            "x": 1,
            "y": 4,
            "z": 6,
            "elements": [
                "appliedenergistics2:quartz_vibrant_glass@0"
            ]
        },
        {
            "x": 1,
            "y": 4,
            "z": 7,
            "elements": [
                "appliedenergistics2:quartz_vibrant_glass@0"
            ]
        },
        {
            "x": 5,
            "y": 2,
            "z": 6,

            "elements": [
                "modularmachinery:blockcasing@4",
                "ItemInputStrengthen",
                "FluidInputStrengthen",
                "FluidOutputStrengthen",
                "EnergyInputStrengthen"
            ]
        },
        {
            "x": 1,
            "y": 4,
            "z": 4,
            "elements": [
                "appliedenergistics2:quartz_vibrant_glass@0"
            ]
        },
        {
            "x": 2,
            "y": 0,
            "z": 2,
            "elements": [
                "enderio:block_alloy@6"
            ]
        },
        {
            "x": 1,
            "y": 4,
            "z": 5,
            "elements": [
                "appliedenergistics2:quartz_vibrant_glass@0"
            ]
        },
        {
            "x": 2,
            "y": 0,
            "z": 1,
            "elements": [
                "appliedenergistics2:smooth_sky_stone_stairs@1"
            ]
        },
        {
            "x": 1,
            "y": 4,
            "z": 2,
            "elements": [
                "appliedenergistics2:smooth_sky_stone_stairs@5"
            ]
        },
        {
            "x": 2,
            "y": 0,
            "z": 4,
            "elements": [
                "fluxnetworks:fluxblock@0"
            ]
        },
        {
            "x": 1,
            "y": 4,
            "z": 3,
            "elements": [
                "appliedenergistics2:smooth_sky_stone_slab@8"
            ]
        },
        {
            "x": 2,
            "y": 0,
            "z": 3,
            "elements": [
                "enderio:block_alloy@8"
            ]
        },
        {
            "x": 0,
            "y": 2,
            "z": 9,
            "elements": [
                "appliedenergistics2:smooth_sky_stone_slab@8"
            ]
        },
        {
            "x": 0,
            "y": 2,
            "z": 11,

            "elements": [
                "modularmachinery:blockcasing@4",
                "ItemInputStrengthen",
                "FluidInputStrengthen",
                "FluidOutputStrengthen",
                "EnergyInputStrengthen"
            ]
        },
        {
            "x": 0,
            "y": 2,
            "z": 6,
            "elements": [
                "mekanism:basicblock@8"
            ]
        },
        {
            "x": 0,
            "y": 2,
            "z": 5,
            "elements": [
                "mekanism:basicblock@8"
            ]
        },
        {
            "x": 0,
            "y": 2,
            "z": 8,
            "elements": [
                "appliedenergistics2:smooth_sky_stone_stairs@7"
            ]
        },
        {
            "x": 0,
            "y": 2,
            "z": 7,
            "elements": [
                "mekanism:basicblock@8"
            ]
        },
        {
            "x": -6,
            "y": 1,
            "z": 6,
            "elements": [
                "appliedenergistics2:smooth_sky_stone_slab@0"
            ]
        },
        {
            "x": -1,
            "y": 1,
            "z": 6,
            "elements": [
                "appliedenergistics2:smooth_sky_stone_slab@8"
            ]
        },
        {
            "x": 2,
            "y": 1,
            "z": 8,
            "elements": [
                "appliedenergistics2:smooth_sky_stone_slab@0"
            ]
        },
        {
            "x": 2,
            "y": 1,
            "z": 9,
            "elements": [
                "mekanism:plasticfence@7"
            ]
        },
        {
            "x": -1,
            "y": 1,
            "z": 4,
            "elements": [
                "appliedenergistics2:smooth_sky_stone_slab@0"
            ]
        },
        {
            "x": -1,
            "y": 1,
            "z": 3,
            "elements": [
                "appliedenergistics2:smooth_sky_stone_slab@0"
            ]
        },
        {
            "x": 2,
            "y": 1,
            "z": 4,
            "elements": [
                "appliedenergistics2:smooth_sky_stone_slab@0"
            ]
        },
        {
            "x": 2,
            "y": 1,
            "z": 5,
            "elements": [
                "appliedenergistics2:smooth_sky_stone_slab@0"
            ]
        },
        {
            "x": -1,
            "y": 1,
            "z": 1,
            "elements": [
                "mekanism:plasticfence@7"
            ]
        },
        {
            "x": 2,
            "y": 1,
            "z": 7,
            "elements": [
                "appliedenergistics2:smooth_sky_stone_slab@0"
            ]
        },
        {
            "x": 0,
            "y": 9,
            "z": 5,
            "elements": [
                "appliedenergistics2:smooth_sky_stone_slab@0"
            ]
        },
        {
            "x": 0,
            "y": 2,
            "z": 1,

            "elements": [
                "modularmachinery:blockcasing@4",
                "ItemInputStrengthen",
                "FluidInputStrengthen",
                "FluidOutputStrengthen",
                "EnergyInputStrengthen"
            ]
        },
        {
            "x": 0,
            "y": 2,
            "z": 4,
            "elements": [
                "appliedenergistics2:smooth_sky_stone_stairs@6"
            ]
        },
        {
            "x": 2,
            "y": 1,
            "z": 3,
            "elements": [
                "mekanism:plasticfence@7"
            ]
        },
        {
            "x": 0,
            "y": 2,
            "z": 3,
            "elements": [
                "appliedenergistics2:smooth_sky_stone_slab@8"
            ]
        },
        {
            "x": -1,
            "y": 7,
            "z": 7,
            "elements": [
                "appliedenergistics2:quartz_vibrant_glass@0"
            ]
        },
        {
            "x": -1,
            "y": 7,
            "z": 8,
            "elements": [
                "appliedenergistics2:quartz_vibrant_glass@0"
            ]
        },
        {
            "x": -1,
            "y": 7,
            "z": 5,
            "elements": [
                "appliedenergistics2:quartz_vibrant_glass@0"
            ]
        },
        {
            "x": -1,
            "y": 7,
            "z": 6,
            "elements": [
                "appliedenergistics2:quartz_vibrant_glass@0"
            ]
        },
        {
            "x": -1,
            "y": 7,
            "z": 3,
            "elements": [
                "minecraft:end_rod@4"
            ]
        },
        {
            "x": -1,
            "y": 7,
            "z": 4,
            "elements": [
                "appliedenergistics2:quartz_vibrant_glass@0"
            ]
        },
        {
            "x": 0,
            "y": 9,
            "z": 6,
            "elements": [
                "appliedenergistics2:smooth_sky_stone_slab@0"
            ]
        },
        {
            "x": 0,
            "y": 9,
            "z": 7,
            "elements": [
                "appliedenergistics2:smooth_sky_stone_slab@0"
            ]
        },
        {
            "x": -1,
            "y": 7,
            "z": 9,
            "elements": [
                "minecraft:end_rod@4"
            ]
        },
        {
            "x": -3,
            "y": 8,
            "z": 6,
            "elements": [
                "appliedenergistics2:smooth_sky_stone_slab@0"
            ]
        },
        {
            "x": -1,
            "y": 0,
            "z": 3,
            "elements": [
                "fluxnetworks:fluxblock@0"
            ]
        },
        {
            "x": 2,
            "y": 7,
            "z": 8,
            "elements": [
                "appliedenergistics2:smooth_sky_stone_slab@0"
            ]
        },
        {
            "x": -1,
            "y": 0,
            "z": 2,
            "elements": [
                "enderio:block_alloy@6"
            ]
        },
        {
            "x": -1,
            "y": 0,
            "z": 1,
            "elements": [
                "enderio:block_alloy@6"
            ]
        },
        {
            "x": 2,
            "y": 7,
            "z": 7,
            "elements": [
                "appliedenergistics2:quartz_vibrant_glass@0"
            ]
        },
        {
            "x": -1,
            "y": 0,
            "z": 0,
            "elements": [
                "appliedenergistics2:smooth_sky_stone_stairs@2"
            ]
        },
        {
            "x": 2,
            "y": 7,
            "z": 6,
            "elements": [
                "mekanism:basicblock@8"
            ]
        },
        {
            "x": -1,
            "y": 0,
            "z": 7,
            "elements": [
                "fluxnetworks:fluxblock@0"
            ]
        },
        {
            "x": -1,
            "y": 0,
            "z": 6,
            "elements": [
                "fluxnetworks:fluxblock@0"
            ]
        },
        {
            "x": -1,
            "y": 0,
            "z": 5,
            "elements": [
                "fluxnetworks:fluxblock@0"
            ]
        },
        {
            "x": -1,
            "y": 0,
            "z": 4,
            "elements": [
                "enderio:block_alloy@0"
            ]
        },
        {
            "x": -1,
            "y": 0,
            "z": 11,
            "elements": [
                "enderio:block_alloy@6"
            ]
        },
        {
            "x": -1,
            "y": 0,
            "z": 10,
            "elements": [
                "enderio:block_alloy@6"
            ]
        },
        {
            "x": -1,
            "y": 0,
            "z": 9,
            "elements": [
                "fluxnetworks:fluxblock@0"
            ]
        },
        {
            "x": -1,
            "y": 0,
            "z": 8,
            "elements": [
                "enderio:block_alloy@0"
            ]
        },
        {
            "x": -4,
            "y": 6,
            "z": 6,
            "elements": [
                "extendedcrafting:lamp@1"
            ]
        },
        {
            "x": -4,
            "y": 6,
            "z": 5,
            "elements": [
                "appliedenergistics2:smooth_sky_stone_stairs@2"
            ]
        },
        {
            "x": -1,
            "y": 0,
            "z": 12,
            "elements": [
                "appliedenergistics2:smooth_sky_stone_stairs@3"
            ]
        },
        {
            "x": -4,
            "y": 6,
            "z": 7,
            "elements": [
                "appliedenergistics2:smooth_sky_stone_stairs@3"
            ]
        },
        {
            "x": 5,
            "y": 1,
            "z": 6,

            "elements": [
                "modularmachinery:blockcasing@4",
                "ItemInputStrengthen",
                "FluidInputStrengthen",
                "FluidOutputStrengthen",
                "EnergyInputStrengthen"
            ]
        },
        {
            "x": 5,
            "y": 1,
            "z": 5,
            "elements": [
                "mekanism:plasticfence@7"
            ]
        },
        {
            "x": 5,
            "y": 1,
            "z": 7,
            "elements": [
                "mekanism:plasticfence@7"
            ]
        },
        {
            "x": -3,
            "y": 2,
            "z": 8,
            "elements": [
                "appliedenergistics2:smooth_sky_stone_slab@0"
            ]
        },
        {
            "x": -4,
            "y": 0,
            "z": 9,
            "elements": [
                "enderio:block_alloy@6"
            ]
        },
        {
            "x": -4,
            "y": 0,
            "z": 7,
            "elements": [
                "enderio:block_alloy@6"
            ]
        },
        {
            "x": -4,
            "y": 0,
            "z": 8,
            "elements": [
                "enderio:block_alloy@6"
            ]
        },
        {
            "x": -3,
            "y": 2,
            "z": 4,
            "elements": [
                "appliedenergistics2:smooth_sky_stone_slab@0"
            ]
        },
        {
            "x": -4,
            "y": 0,
            "z": 5,
            "elements": [
                "enderio:block_alloy@6"
            ]
        },
        {
            "x": -4,
            "y": 0,
            "z": 6,
            "elements": [
                "enderio:block_alloy@0"
            ]
        },
        {
            "x": -4,
            "y": 0,
            "z": 3,
            "elements": [
                "enderio:block_alloy@6"
            ]
        },
        {
            "x": -3,
            "y": 2,
            "z": 6,
            "elements": [
                "appliedenergistics2:smooth_sky_stone_slab@8"
            ]
        },
        {
            "x": -4,
            "y": 0,
            "z": 4,
            "elements": [
                "enderio:block_alloy@6"
            ]
        },
        {
            "x": 3,
            "y": 3,
            "z": 7,
            "elements": [
                "minecraft:end_rod@3"
            ]
        },
        {
            "x": 3,
            "y": 3,
            "z": 5,
            "elements": [
                "minecraft:end_rod@2"
            ]
        },
        {
            "x": 3,
            "y": 3,
            "z": 6,
            "elements": [
                "mekanism:basicblock@8"
            ]
        },
        {
            "x": 2,
            "y": 7,
            "z": 5,
            "elements": [
                "appliedenergistics2:quartz_vibrant_glass@0"
            ]
        },
        {
            "x": 2,
            "y": 7,
            "z": 4,
            "elements": [
                "appliedenergistics2:smooth_sky_stone_slab@0"
            ]
        }
    ]}