{
    "registryname": "YMG_Kitchen_Generator",
    "localizedname": "§b§lYMG§r§e§l—§f§l厨余发电机 §r§e",
    "failure-action": "still",
    "requires-blueprint": false,
    "color": "FFFFFF",
    "parts": [
        {
            "x": 2,
            "y": 3,
            "z": 0,
            "elements": [
                "ic2:fence@0"
            ]
        },
        {
            "x": 2,
            "y": 3,
            "z": 1,
            "elements": [
                "ic2:fence@0"
            ]
        },
        {
            "x": 2,
            "y": 3,
            "z": 6,
            "elements": [
                "ic2:fence@0"
            ]
        },
        {
            "x": 2,
            "y": 3,
            "z": 2,
            "elements": [
                "astralsorcery:blockmarble@1"
            ]
        },
        {
            "x": 2,
            "y": 3,
            "z": 3,
            "elements": [
                "actuallyadditions:block_crystal_empowered@5"
            ]
        },
        {
            "x": 2,
            "y": 3,
            "z": 4,
            "elements": [
                "astralsorcery:blockmarble@1"
            ]
        },
        {
            "x": 2,
            "y": 3,
            "z": 5,
            "elements": [
                "ic2:fence@0"
            ]
        },
        {
            "x": -1,
            "y": -1,
            "z": 1,
            "elements": [
                "cookingforblockheads:kitchen_floor@0"
            ]
        },
        {
            "x": 3,
            "y": 4,
            "z": 2,
            "elements": [
                "astralsorcery:blockmarbleslab@0"
            ]
        },
        {
            "x": -1,
            "y": 6,
            "z": 4,
            "elements": [
                "astralsorcery:blockmarble@1"
            ]
        },
        {
            "x": -1,
            "y": -1,
            "z": 2,
            "elements": [
                "cookingforblockheads:kitchen_floor@0"
            ]
        },
        {
            "x": 3,
            "y": 4,
            "z": 3,
            "elements": [
                "astralsorcery:blockmarbleslab@0"
            ]
        },
        {
            "x": -1,
            "y": 6,
            "z": 5,
            "elements": [
                "astralsorcery:blockmarble@1"
            ]
        },
        {
            "x": -1,
            "y": 6,
            "z": 2,
            "elements": [
                "astralsorcery:blockmarble@1"
            ]
        },
        {
            "x": -1,
            "y": -1,
            "z": 3,
            "elements": [
                "cookingforblockheads:kitchen_floor@0"
            ]
        },
        {
            "x": 3,
            "y": 4,
            "z": 1,
            "elements": [
                "astralsorcery:blockmarbleslab@0"
            ]
        },
        {
            "x": -1,
            "y": 6,
            "z": 3,
            "elements": [
                "astralsorcery:blockmarble@1"
            ]
        },
        {
            "x": -1,
            "y": -1,
            "z": 4,
            "elements": [
                "cookingforblockheads:kitchen_floor@0"
            ]
        },
        {
            "x": -1,
            "y": -1,
            "z": 5,
            "elements": [
                "cookingforblockheads:kitchen_floor@0"
            ]
        },
        {
            "x": -1,
            "y": -1,
            "z": 6,

            "elements": [
                "modularmachinery:blockcasing@0",
                "ItemInput",
                "EnergyOutput"
            ]
        },
        {
            "x": 3,
            "y": 4,
            "z": 4,
            "elements": [
                "astralsorcery:blockmarbleslab@0"
            ]
        },
        {
            "x": 3,
            "y": 4,
            "z": 5,
            "elements": [
                "astralsorcery:blockmarbleslab@0"
            ]
        },
        {
            "x": 0,
            "y": 7,
            "z": 1,
            "elements": [
                "astralsorcery:blockmarblestairs@6"
            ]
        },
        {
            "x": 0,
            "y": 7,
            "z": 2,
            "elements": [
                "astralsorcery:blockmarble@1"
            ]
        },
        {
            "x": 0,
            "y": 7,
            "z": 3,
            "elements": [
                "astralsorcery:blockmarble@1"
            ]
        },
        {
            "x": 0,
            "y": 7,
            "z": 4,
            "elements": [
                "astralsorcery:blockmarble@1"
            ]
        },
        {
            "x": -1,
            "y": 6,
            "z": 1,
            "elements": [
                "astralsorcery:blockmarble@1"
            ]
        },
        {
            "x": 0,
            "y": 7,
            "z": 5,
            "elements": [
                "astralsorcery:blockmarblestairs@7"
            ]
        },
        {
            "x": -1,
            "y": -1,
            "z": 0,

            "elements": [
                "modularmachinery:blockcasing@0",
                "ItemInput",
                "EnergyOutput"
            ]
        },
        {
            "x": 0,
            "y": 0,
            "z": 3,
            "elements": [
                "enderio:block_alloy@8"
            ]
        },
        {
            "x": 0,
            "y": 0,
            "z": 6,
            "elements": [
                "astralsorcery:blockmarble@1"
            ]
        },
        {
            "x": 0,
            "y": 0,
            "z": 5,

            "elements": [
                "modularmachinery:blockcasing@2"
            ]
        },
        {
            "x": 0,
            "y": 0,
            "z": 0,

            "elements": [
                "modularmachinery:blockcontroller@2"
            ]
        },
        {
            "x": 1,
            "y": 2,
            "z": 6,
            "elements": [
                "astralsorcery:blockmarble@1"
            ]
        },
        {
            "x": 0,
            "y": 0,
            "z": 1,

            "elements": [
                "modularmachinery:blockcasing@2"
            ]
        },
        {
            "x": -2,
            "y": 4,
            "z": 6,
            "elements": [
                "astralsorcery:blockmarbleslab@0"
            ]
        },
        {
            "x": -2,
            "y": 4,
            "z": 5,
            "elements": [
                "astralsorcery:blockmarbleslab@0"
            ]
        },
        {
            "x": 1,
            "y": 2,
            "z": 0,
            "elements": [
                "astralsorcery:blockmarble@1"
            ]
        },
        {
            "x": 2,
            "y": 9,
            "z": 4,
            "elements": [
                "ic2:fence@0"
            ]
        },
        {
            "x": -2,
            "y": 4,
            "z": 0,
            "elements": [
                "astralsorcery:blockmarbleslab@0"
            ]
        },
        {
            "x": -2,
            "y": 4,
            "z": 2,
            "elements": [
                "astralsorcery:blockmarble@1"
            ]
        },
        {
            "x": 1,
            "y": 9,
            "z": 2,
            "elements": [
                "ic2:fence@0"
            ]
        },
        {
            "x": 2,
            "y": 9,
            "z": 3,
            "elements": [
                "astralsorcery:blockmarblestairs@5"
            ]
        },
        {
            "x": -2,
            "y": 4,
            "z": 1,
            "elements": [
                "astralsorcery:blockmarbleslab@0"
            ]
        },
        {
            "x": 1,
            "y": 9,
            "z": 1,
            "elements": [
                "ic2:fence@0"
            ]
        },
        {
            "x": 2,
            "y": 9,
            "z": 2,
            "elements": [
                "ic2:fence@0"
            ]
        },
        {
            "x": -2,
            "y": 4,
            "z": 4,
            "elements": [
                "astralsorcery:blockmarble@1"
            ]
        },
        {
            "x": 1,
            "y": 9,
            "z": 4,
            "elements": [
                "ic2:fence@0"
            ]
        },
        {
            "x": -2,
            "y": 4,
            "z": 3,
            "elements": [
                "astralsorcery:blockmarble@1"
            ]
        },
        {
            "x": 1,
            "y": 9,
            "z": 3,
            "elements": [
                "astralsorcery:blockmarble@1"
            ]
        },
        {
            "x": 1,
            "y": 9,
            "z": 5,
            "elements": [
                "ic2:fence@0"
            ]
        },
        {
            "x": 1,
            "y": 1,
            "z": 0,
            "elements": [
                "astralsorcery:blockmarble@1"
            ]
        },
        {
            "x": 1,
            "y": 1,
            "z": 6,
            "elements": [
                "astralsorcery:blockmarble@1"
            ]
        },
        {
            "x": -2,
            "y": 5,
            "z": 3,
            "elements": [
                "astralsorcery:blockmarblestairs@4"
            ]
        },
        {
            "x": -2,
            "y": 5,
            "z": 2,
            "elements": [
                "ic2:fence@0"
            ]
        },
        {
            "x": 1,
            "y": 7,
            "z": 1,
            "elements": [
                "ic2:fence@0"
            ]
        },
        {
            "x": -3,
            "y": 3,
            "z": 3,
            "elements": [
                "astralsorcery:blockmarblestairs@0"
            ]
        },
        {
            "x": 1,
            "y": 7,
            "z": 2,
            "elements": [
                "ic2:fence@0"
            ]
        },
        {
            "x": -3,
            "y": 3,
            "z": 4,
            "elements": [
                "astralsorcery:blockmarblestairs@2"
            ]
        },
        {
            "x": -3,
            "y": 3,
            "z": 5,
            "elements": [
                "ic2:fence@0"
            ]
        },
        {
            "x": -2,
            "y": -1,
            "z": 6,

            "elements": [
                "modularmachinery:blockcasing@0",
                "ItemInput",
                "EnergyOutput"
            ]
        },
        {
            "x": -2,
            "y": -1,
            "z": 4,
            "elements": [
                "cookingforblockheads:kitchen_floor@0"
            ]
        },
        {
            "x": 1,
            "y": 7,
            "z": 5,
            "elements": [
                "ic2:fence@0"
            ]
        },
        {
            "x": -2,
            "y": 5,
            "z": 4,
            "elements": [
                "ic2:fence@0"
            ]
        },
        {
            "x": -2,
            "y": -1,
            "z": 5,
            "elements": [
                "cookingforblockheads:kitchen_floor@0"
            ]
        },
        {
            "x": -3,
            "y": 3,
            "z": 1,
            "elements": [
                "ic2:fence@0"
            ]
        },
        {
            "x": -2,
            "y": -1,
            "z": 2,
            "elements": [
                "cookingforblockheads:kitchen_floor@0"
            ]
        },
        {
            "x": 1,
            "y": 7,
            "z": 3,
            "elements": [
                "astralsorcery:blockmarble@1"
            ]
        },
        {
            "x": -3,
            "y": 3,
            "z": 2,
            "elements": [
                "astralsorcery:blockmarblestairs@3"
            ]
        },
        {
            "x": -2,
            "y": -1,
            "z": 3,
            "elements": [
                "astralsorcery:blockmarble@1"
            ]
        },
        {
            "x": 1,
            "y": 7,
            "z": 4,
            "elements": [
                "ic2:fence@0"
            ]
        },
        {
            "x": -2,
            "y": -1,
            "z": 0,

            "elements": [
                "modularmachinery:blockcasing@0",
                "ItemInput",
                "EnergyOutput"
            ]
        },
        {
            "x": -2,
            "y": -1,
            "z": 1,
            "elements": [
                "cookingforblockheads:kitchen_floor@0"
            ]
        },
        {
            "x": 0,
            "y": 8,
            "z": 3,
            "elements": [
                "astralsorcery:blockmarble@1"
            ]
        },
        {
            "x": 0,
            "y": 8,
            "z": 4,
            "elements": [
                "astralsorcery:blockmarble@1"
            ]
        },
        {
            "x": 0,
            "y": 8,
            "z": 5,
            "elements": [
                "astralsorcery:blockmarble@1"
            ]
        },
        {
            "x": 0,
            "y": 8,
            "z": 1,
            "elements": [
                "astralsorcery:blockmarble@1"
            ]
        },
        {
            "x": 0,
            "y": 8,
            "z": 2,
            "elements": [
                "astralsorcery:blockmarble@1"
            ]
        },
        {
            "x": 1,
            "y": 10,
            "z": 1,
            "elements": [
                "astralsorcery:blockmarbleslab@0"
            ]
        },
        {
            "x": 1,
            "y": 10,
            "z": 3,

            "elements": [
                "modularmachinery:blockcasing@1"
            ]
        },
        {
            "x": 1,
            "y": 10,
            "z": 2,
            "elements": [
                "astralsorcery:blockmarble@1"
            ]
        },
        {
            "x": 1,
            "y": 0,
            "z": 0,
            "elements": [
                "astralsorcery:blockmarble@1"
            ]
        },
        {
            "x": 3,
            "y": -1,
            "z": 5,

            "elements": [
                "modularmachinery:blockcasing@0",
                "ItemInput",
                "EnergyOutput"
            ]
        },
        {
            "x": 1,
            "y": 0,
            "z": 6,
            "elements": [
                "astralsorcery:blockmarble@1"
            ]
        },
        {
            "x": 3,
            "y": -1,
            "z": 3,
            "elements": [
                "astralsorcery:blockmarblestairs@1"
            ]
        },
        {
            "x": -2,
            "y": 6,
            "z": 4,
            "elements": [
                "astralsorcery:blockmarble@1"
            ]
        },
        {
            "x": -2,
            "y": 6,
            "z": 3,
            "elements": [
                "astralsorcery:blockmarble@1"
            ]
        },
        {
            "x": 3,
            "y": -1,
            "z": 4,

            "elements": [
                "modularmachinery:blockcasing@0",
                "ItemInput",
                "EnergyOutput"
            ]
        },
        {
            "x": 3,
            "y": -1,
            "z": 1,

            "elements": [
                "modularmachinery:blockcasing@0",
                "ItemInput",
                "EnergyOutput"
            ]
        },
        {
            "x": 3,
            "y": -1,
            "z": 2,

            "elements": [
                "modularmachinery:blockcasing@0",
                "ItemInput",
                "EnergyOutput"
            ]
        },
        {
            "x": -2,
            "y": 3,
            "z": 6,
            "elements": [
                "ic2:fence@0"
            ]
        },
        {
            "x": -2,
            "y": 3,
            "z": 3,
            "elements": [
                "actuallyadditions:block_crystal_empowered@5"
            ]
        },
        {
            "x": 2,
            "y": 8,
            "z": 4,
            "elements": [
                "astralsorcery:blockmarble@1"
            ]
        },
        {
            "x": 1,
            "y": 3,
            "z": 5,
            "elements": [
                "astralsorcery:blockmarble@1"
            ]
        },
        {
            "x": -2,
            "y": 3,
            "z": 2,
            "elements": [
                "astralsorcery:blockmarble@1"
            ]
        },
        {
            "x": 2,
            "y": 8,
            "z": 3,
            "elements": [
                "astralsorcery:blockmarble@1"
            ]
        },
        {
            "x": 1,
            "y": 3,
            "z": 6,
            "elements": [
                "astralsorcery:blockmarblestairs@0"
            ]
        },
        {
            "x": 2,
            "y": 8,
            "z": 2,
            "elements": [
                "astralsorcery:blockmarble@1"
            ]
        },
        {
            "x": 1,
            "y": 3,
            "z": 3,
            "elements": [
                "mekanism:basicblock@8"
            ]
        },
        {
            "x": -2,
            "y": 3,
            "z": 5,
            "elements": [
                "ic2:fence@0"
            ]
        },
        {
            "x": -2,
            "y": 3,
            "z": 4,
            "elements": [
                "astralsorcery:blockmarble@1"
            ]
        },
        {
            "x": 1,
            "y": 3,
            "z": 4,
            "elements": [
                "mekanism:basicblock@8"
            ]
        },
        {
            "x": 1,
            "y": 10,
            "z": 5,
            "elements": [
                "astralsorcery:blockmarbleslab@0"
            ]
        },
        {
            "x": 1,
            "y": 10,
            "z": 4,
            "elements": [
                "astralsorcery:blockmarble@1"
            ]
        },
        {
            "x": -2,
            "y": 3,
            "z": 1,
            "elements": [
                "ic2:fence@0"
            ]
        },
        {
            "x": -2,
            "y": 3,
            "z": 0,
            "elements": [
                "ic2:fence@0"
            ]
        },
        {
            "x": -2,
            "y": 0,
            "z": 3,

            "elements": [
                "modularmachinery:blockcasing@2"
            ]
        },
        {
            "x": 2,
            "y": 5,
            "z": 4,
            "elements": [
                "ic2:fence@0"
            ]
        },
        {
            "x": 1,
            "y": 3,
            "z": 1,
            "elements": [
                "astralsorcery:blockmarble@1"
            ]
        },
        {
            "x": 1,
            "y": 3,
            "z": 2,
            "elements": [
                "mekanism:basicblock@8"
            ]
        },
        {
            "x": 2,
            "y": 5,
            "z": 2,
            "elements": [
                "ic2:fence@0"
            ]
        },
        {
            "x": 1,
            "y": 3,
            "z": 0,
            "elements": [
                "astralsorcery:blockmarblestairs@0"
            ]
        },
        {
            "x": 2,
            "y": 5,
            "z": 3,
            "elements": [
                "astralsorcery:blockmarblestairs@5"
            ]
        },
        {
            "x": -2,
            "y": 0,
            "z": 6,
            "elements": [
                "thermalfoundation:glass@7"
            ]
        },
        {
            "x": -2,
            "y": 0,
            "z": 0,
            "elements": [
                "thermalfoundation:glass@7"
            ]
        },
        {
            "x": -3,
            "y": 1,
            "z": 5,
            "elements": [
                "thermalfoundation:glass@7"
            ]
        },
        {
            "x": 1,
            "y": 6,
            "z": 4,
            "elements": [
                "astralsorcery:blockmarble@1"
            ]
        },
        {
            "x": 1,
            "y": 6,
            "z": 5,
            "elements": [
                "astralsorcery:blockmarble@1"
            ]
        },
        {
            "x": -3,
            "y": 1,
            "z": 1,
            "elements": [
                "thermalfoundation:glass@7"
            ]
        },
        {
            "x": 1,
            "y": 6,
            "z": 2,
            "elements": [
                "astralsorcery:blockmarble@1"
            ]
        },
        {
            "x": 2,
            "y": 2,
            "z": 0,
            "elements": [
                "astralsorcery:blockmarblestairs@1"
            ]
        },
        {
            "x": -3,
            "y": 1,
            "z": 2,
            "elements": [
                "astralsorcery:blockmarble@1"
            ]
        },
        {
            "x": 1,
            "y": 6,
            "z": 3,
            "elements": [
                "astralsorcery:blockmarble@1"
            ]
        },
        {
            "x": 2,
            "y": 2,
            "z": 1,
            "elements": [
                "astralsorcery:blockmarble@1"
            ]
        },
        {
            "x": -3,
            "y": 1,
            "z": 3,
            "elements": [
                "ic2:fence@0"
            ]
        },
        {
            "x": 1,
            "y": 6,
            "z": 1,
            "elements": [
                "astralsorcery:blockmarble@1"
            ]
        },
        {
            "x": -3,
            "y": 1,
            "z": 4,
            "elements": [
                "astralsorcery:blockmarble@1"
            ]
        },
        {
            "x": -1,
            "y": 5,
            "z": 2,
            "elements": [
                "ic2:fence@0"
            ]
        },
        {
            "x": -1,
            "y": 5,
            "z": 1,
            "elements": [
                "ic2:fence@0"
            ]
        },
        {
            "x": 2,
            "y": 2,
            "z": 3,

            "elements": [
                "modularmachinery:blockcasing@2"
            ]
        },
        {
            "x": -3,
            "y": 4,
            "z": 5,
            "elements": [
                "astralsorcery:blockmarbleslab@0"
            ]
        },
        {
            "x": -3,
            "y": 4,
            "z": 4,
            "elements": [
                "astralsorcery:blockmarbleslab@0"
            ]
        },
        {
            "x": -3,
            "y": 4,
            "z": 3,
            "elements": [
                "astralsorcery:blockmarbleslab@0"
            ]
        },
        {
            "x": 2,
            "y": 2,
            "z": 5,
            "elements": [
                "astralsorcery:blockmarble@1"
            ]
        },
        {
            "x": -3,
            "y": 4,
            "z": 2,
            "elements": [
                "astralsorcery:blockmarbleslab@0"
            ]
        },
        {
            "x": 2,
            "y": 2,
            "z": 6,
            "elements": [
                "astralsorcery:blockmarblestairs@1"
            ]
        },
        {
            "x": -3,
            "y": 4,
            "z": 1,
            "elements": [
                "astralsorcery:blockmarbleslab@0"
            ]
        },
        {
            "x": 2,
            "y": -1,
            "z": 3,
            "elements": [
                "astralsorcery:blockmarble@1"
            ]
        },
        {
            "x": 2,
            "y": -1,
            "z": 2,
            "elements": [
                "cookingforblockheads:kitchen_floor@0"
            ]
        },
        {
            "x": 2,
            "y": -1,
            "z": 5,
            "elements": [
                "cookingforblockheads:kitchen_floor@0"
            ]
        },
        {
            "x": 2,
            "y": -1,
            "z": 4,
            "elements": [
                "cookingforblockheads:kitchen_floor@0"
            ]
        },
        {
            "x": 2,
            "y": -1,
            "z": 1,
            "elements": [
                "cookingforblockheads:kitchen_floor@0"
            ]
        },
        {
            "x": 2,
            "y": -1,
            "z": 0,

            "elements": [
                "modularmachinery:blockcasing@0",
                "ItemInput",
                "EnergyOutput"
            ]
        },
        {
            "x": 2,
            "y": -1,
            "z": 6,

            "elements": [
                "modularmachinery:blockcasing@0",
                "ItemInput",
                "EnergyOutput"
            ]
        },
        {
            "x": -1,
            "y": 2,
            "z": 6,
            "elements": [
                "astralsorcery:blockmarble@1"
            ]
        },
        {
            "x": -1,
            "y": 8,
            "z": 2,
            "elements": [
                "astralsorcery:blockmarble@1"
            ]
        },
        {
            "x": -1,
            "y": 2,
            "z": 0,
            "elements": [
                "astralsorcery:blockmarble@1"
            ]
        },
        {
            "x": -1,
            "y": 8,
            "z": 3,
            "elements": [
                "astralsorcery:blockmarble@1"
            ]
        },
        {
            "x": -1,
            "y": 8,
            "z": 1,
            "elements": [
                "astralsorcery:blockmarble@1"
            ]
        },
        {
            "x": 0,
            "y": 4,
            "z": 4,
            "elements": [
                "astralsorcery:blockmarble@1"
            ]
        },
        {
            "x": 0,
            "y": 4,
            "z": 3,
            "elements": [
                "astralsorcery:blockmarble@1"
            ]
        },
        {
            "x": -2,
            "y": 6,
            "z": 2,
            "elements": [
                "astralsorcery:blockmarble@1"
            ]
        },
        {
            "x": -1,
            "y": 8,
            "z": 4,
            "elements": [
                "astralsorcery:blockmarble@1"
            ]
        },
        {
            "x": 0,
            "y": 4,
            "z": 6,
            "elements": [
                "astralsorcery:blockmarbleslab@0"
            ]
        },
        {
            "x": 0,
            "y": 4,
            "z": 5,
            "elements": [
                "astralsorcery:blockmarble@1"
            ]
        },
        {
            "x": -1,
            "y": 8,
            "z": 5,
            "elements": [
                "astralsorcery:blockmarble@1"
            ]
        },
        {
            "x": 0,
            "y": 1,
            "z": 6,
            "elements": [
                "ic2:fence@0"
            ]
        },
        {
            "x": -2,
            "y": 9,
            "z": 4,
            "elements": [
                "ic2:fence@0"
            ]
        },
        {
            "x": 0,
            "y": 1,
            "z": 1,

            "elements": [
                "modularmachinery:blockcasing@2"
            ]
        },
        {
            "x": 0,
            "y": 1,
            "z": 0,
            "elements": [
                "ic2:fence@0"
            ]
        },
        {
            "x": 0,
            "y": 1,
            "z": 3,
            "elements": [
                "enderio:block_alloy@8"
            ]
        },
        {
            "x": -1,
            "y": 5,
            "z": 5,
            "elements": [
                "ic2:fence@0"
            ]
        },
        {
            "x": -2,
            "y": 9,
            "z": 2,
            "elements": [
                "ic2:fence@0"
            ]
        },
        {
            "x": -1,
            "y": 5,
            "z": 4,
            "elements": [
                "ic2:fence@0"
            ]
        },
        {
            "x": 0,
            "y": 1,
            "z": 5,

            "elements": [
                "modularmachinery:blockcasing@2"
            ]
        },
        {
            "x": -1,
            "y": 5,
            "z": 3,
            "elements": [
                "astralsorcery:blockmarble@1"
            ]
        },
        {
            "x": -2,
            "y": 9,
            "z": 3,
            "elements": [
                "astralsorcery:blockmarblestairs@4"
            ]
        },
        {
            "x": -3,
            "y": 0,
            "z": 2,
            "elements": [
                "astralsorcery:blockmarble@1"
            ]
        },
        {
            "x": 1,
            "y": 5,
            "z": 3,
            "elements": [
                "astralsorcery:blockmarble@1"
            ]
        },
        {
            "x": -3,
            "y": 0,
            "z": 3,
            "elements": [
                "astralsorcery:blockmarble@1"
            ]
        },
        {
            "x": 1,
            "y": 5,
            "z": 4,
            "elements": [
                "ic2:fence@0"
            ]
        },
        {
            "x": 1,
            "y": 5,
            "z": 1,
            "elements": [
                "ic2:fence@0"
            ]
        },
        {
            "x": -3,
            "y": 0,
            "z": 4,
            "elements": [
                "astralsorcery:blockmarble@1"
            ]
        },
        {
            "x": 1,
            "y": 5,
            "z": 2,
            "elements": [
                "ic2:fence@0"
            ]
        },
        {
            "x": -3,
            "y": 0,
            "z": 5,
            "elements": [
                "thermalfoundation:glass@7"
            ]
        },
        {
            "x": 1,
            "y": 5,
            "z": 5,
            "elements": [
                "ic2:fence@0"
            ]
        },
        {
            "x": 3,
            "y": 1,
            "z": 1,
            "elements": [
                "thermalfoundation:glass@7"
            ]
        },
        {
            "x": -1,
            "y": 9,
            "z": 5,
            "elements": [
                "ic2:fence@0"
            ]
        },
        {
            "x": 3,
            "y": 1,
            "z": 2,
            "elements": [
                "astralsorcery:blockmarble@1"
            ]
        },
        {
            "x": -1,
            "y": 9,
            "z": 3,
            "elements": [
                "astralsorcery:blockmarble@1"
            ]
        },
        {
            "x": -1,
            "y": 9,
            "z": 4,
            "elements": [
                "ic2:fence@0"
            ]
        },
        {
            "x": -1,
            "y": 9,
            "z": 1,
            "elements": [
                "ic2:fence@0"
            ]
        },
        {
            "x": -1,
            "y": 9,
            "z": 2,
            "elements": [
                "ic2:fence@0"
            ]
        },
        {
            "x": -2,
            "y": 1,
            "z": 6,
            "elements": [
                "thermalfoundation:glass@7"
            ]
        },
        {
            "x": 0,
            "y": 4,
            "z": 0,
            "elements": [
                "astralsorcery:blockmarbleslab@0"
            ]
        },
        {
            "x": 0,
            "y": 4,
            "z": 1,
            "elements": [
                "astralsorcery:blockmarble@1"
            ]
        },
        {
            "x": 0,
            "y": 4,
            "z": 2,
            "elements": [
                "astralsorcery:blockmarble@1"
            ]
        },
        {
            "x": -2,
            "y": 1,
            "z": 3,

            "elements": [
                "modularmachinery:blockcasing@2"
            ]
        },
        {
            "x": -2,
            "y": 1,
            "z": 0,
            "elements": [
                "thermalfoundation:glass@7"
            ]
        },
        {
            "x": -2,
            "y": 8,
            "z": 2,
            "elements": [
                "astralsorcery:blockmarble@1"
            ]
        },
        {
            "x": -2,
            "y": 8,
            "z": 3,
            "elements": [
                "astralsorcery:blockmarble@1"
            ]
        },
        {
            "x": 2,
            "y": 6,
            "z": 2,
            "elements": [
                "astralsorcery:blockmarble@1"
            ]
        },
        {
            "x": -2,
            "y": 8,
            "z": 4,
            "elements": [
                "astralsorcery:blockmarble@1"
            ]
        },
        {
            "x": 2,
            "y": 6,
            "z": 3,
            "elements": [
                "astralsorcery:blockmarble@1"
            ]
        },
        {
            "x": 2,
            "y": 6,
            "z": 4,
            "elements": [
                "astralsorcery:blockmarble@1"
            ]
        },
        {
            "x": -3,
            "y": 0,
            "z": 1,
            "elements": [
                "thermalfoundation:glass@7"
            ]
        },
        {
            "x": 0,
            "y": 10,
            "z": 1,
            "elements": [
                "astralsorcery:blockmarblestairs@2"
            ]
        },
        {
            "x": 0,
            "y": 10,
            "z": 2,

            "elements": [
                "modularmachinery:blockcasing@1"
            ]
        },
        {
            "x": 0,
            "y": 10,
            "z": 3,

            "elements": [
                "modularmachinery:blockcasing@1"
            ]
        },
        {
            "x": 0,
            "y": 10,
            "z": 4,

            "elements": [
                "modularmachinery:blockcasing@1"
            ]
        },
        {
            "x": -1,
            "y": 3,
            "z": 4,
            "elements": [
                "mekanism:basicblock@8"
            ]
        },
        {
            "x": -1,
            "y": 3,
            "z": 3,
            "elements": [
                "mekanism:basicblock@8"
            ]
        },
        {
            "x": -1,
            "y": 3,
            "z": 2,
            "elements": [
                "mekanism:basicblock@8"
            ]
        },
        {
            "x": -1,
            "y": 3,
            "z": 1,
            "elements": [
                "astralsorcery:blockmarble@1"
            ]
        },
        {
            "x": -1,
            "y": 3,
            "z": 0,
            "elements": [
                "astralsorcery:blockmarblestairs@1"
            ]
        },
        {
            "x": 0,
            "y": 10,
            "z": 5,
            "elements": [
                "astralsorcery:blockmarblestairs@3"
            ]
        },
        {
            "x": 1,
            "y": -1,
            "z": 2,
            "elements": [
                "cookingforblockheads:kitchen_floor@0"
            ]
        },
        {
            "x": 1,
            "y": -1,
            "z": 1,
            "elements": [
                "cookingforblockheads:kitchen_floor@0"
            ]
        },
        {
            "x": 1,
            "y": -1,
            "z": 0,

            "elements": [
                "modularmachinery:blockcasing@0",
                "ItemInput",
                "EnergyOutput"
            ]
        },
        {
            "x": 3,
            "y": 1,
            "z": 5,
            "elements": [
                "thermalfoundation:glass@7"
            ]
        },
        {
            "x": 1,
            "y": -1,
            "z": 6,

            "elements": [
                "modularmachinery:blockcasing@0",
                "ItemInput",
                "EnergyOutput"
            ]
        },
        {
            "x": 1,
            "y": -1,
            "z": 5,
            "elements": [
                "cookingforblockheads:kitchen_floor@0"
            ]
        },
        {
            "x": 3,
            "y": 1,
            "z": 3,
            "elements": [
                "ic2:fence@0"
            ]
        },
        {
            "x": 1,
            "y": -1,
            "z": 4,
            "elements": [
                "cookingforblockheads:kitchen_floor@0"
            ]
        },
        {
            "x": -1,
            "y": 3,
            "z": 6,
            "elements": [
                "astralsorcery:blockmarblestairs@1"
            ]
        },
        {
            "x": 1,
            "y": -1,
            "z": 3,
            "elements": [
                "cookingforblockheads:kitchen_floor@0"
            ]
        },
        {
            "x": 3,
            "y": 1,
            "z": 4,
            "elements": [
                "astralsorcery:blockmarble@1"
            ]
        },
        {
            "x": -1,
            "y": 3,
            "z": 5,
            "elements": [
                "astralsorcery:blockmarble@1"
            ]
        },
        {
            "x": 0,
            "y": 3,
            "z": 1,
            "elements": [
                "actuallyadditions:block_crystal_empowered@5"
            ]
        },
        {
            "x": -2,
            "y": 7,
            "z": 3,
            "elements": [
                "astralsorcery:blockmarblestairs@4"
            ]
        },
        {
            "x": 0,
            "y": 3,
            "z": 0,
            "elements": [
                "astralsorcery:blockmarblestairs@2"
            ]
        },
        {
            "x": -2,
            "y": 7,
            "z": 2,
            "elements": [
                "ic2:fence@0"
            ]
        },
        {
            "x": 0,
            "y": 3,
            "z": 3,
            "elements": [
                "enderio:block_alloy@8"
            ]
        },
        {
            "x": 0,
            "y": 3,
            "z": 2,
            "elements": [
                "mekanism:basicblock@8"
            ]
        },
        {
            "x": -2,
            "y": 7,
            "z": 4,
            "elements": [
                "ic2:fence@0"
            ]
        },
        {
            "x": 0,
            "y": 3,
            "z": 5,
            "elements": [
                "actuallyadditions:block_crystal_empowered@5"
            ]
        },
        {
            "x": 0,
            "y": 3,
            "z": 4,
            "elements": [
                "mekanism:basicblock@8"
            ]
        },
        {
            "x": 0,
            "y": 3,
            "z": 6,
            "elements": [
                "astralsorcery:blockmarblestairs@3"
            ]
        },
        {
            "x": 3,
            "y": 2,
            "z": 1,
            "elements": [
                "astralsorcery:blockmarblestairs@2"
            ]
        },
        {
            "x": 3,
            "y": 2,
            "z": 4,
            "elements": [
                "astralsorcery:blockmarble@1"
            ]
        },
        {
            "x": 3,
            "y": 2,
            "z": 5,
            "elements": [
                "astralsorcery:blockmarblestairs@3"
            ]
        },
        {
            "x": 3,
            "y": 2,
            "z": 2,
            "elements": [
                "astralsorcery:blockmarble@1"
            ]
        },
        {
            "x": 3,
            "y": 2,
            "z": 3,
            "elements": [
                "ic2:fence@0"
            ]
        },
        {
            "x": 0,
            "y": 5,
            "z": 2,
            "elements": [
                "astralsorcery:blockmarble@1"
            ]
        },
        {
            "x": 2,
            "y": 0,
            "z": 6,
            "elements": [
                "thermalfoundation:glass@7"
            ]
        },
        {
            "x": 0,
            "y": 5,
            "z": 3,
            "elements": [
                "astralsorcery:blockmarble@1"
            ]
        },
        {
            "x": 0,
            "y": 5,
            "z": 4,
            "elements": [
                "astralsorcery:blockmarble@1"
            ]
        },
        {
            "x": 0,
            "y": 5,
            "z": 5,
            "elements": [
                "astralsorcery:blockmarblestairs@7"
            ]
        },
        {
            "x": 0,
            "y": 5,
            "z": 1,
            "elements": [
                "astralsorcery:blockmarblestairs@6"
            ]
        },
        {
            "x": 1,
            "y": 4,
            "z": 0,
            "elements": [
                "astralsorcery:blockmarbleslab@0"
            ]
        },
        {
            "x": 1,
            "y": 4,
            "z": 1,
            "elements": [
                "astralsorcery:blockmarble@1"
            ]
        },
        {
            "x": -2,
            "y": 2,
            "z": 0,
            "elements": [
                "astralsorcery:blockmarblestairs@0"
            ]
        },
        {
            "x": 2,
            "y": 0,
            "z": 0,
            "elements": [
                "thermalfoundation:glass@7"
            ]
        },
        {
            "x": 1,
            "y": 4,
            "z": 6,
            "elements": [
                "astralsorcery:blockmarbleslab@0"
            ]
        },
        {
            "x": -2,
            "y": 2,
            "z": 1,
            "elements": [
                "astralsorcery:blockmarble@1"
            ]
        },
        {
            "x": 1,
            "y": 4,
            "z": 4,
            "elements": [
                "astralsorcery:blockmarble@1"
            ]
        },
        {
            "x": -2,
            "y": 2,
            "z": 3,

            "elements": [
                "modularmachinery:blockcasing@2"
            ]
        },
        {
            "x": 1,
            "y": 4,
            "z": 5,
            "elements": [
                "astralsorcery:blockmarble@1"
            ]
        },
        {
            "x": 1,
            "y": 4,
            "z": 2,
            "elements": [
                "astralsorcery:blockmarble@1"
            ]
        },
        {
            "x": -2,
            "y": 2,
            "z": 6,
            "elements": [
                "astralsorcery:blockmarblestairs@0"
            ]
        },
        {
            "x": 2,
            "y": 0,
            "z": 3,

            "elements": [
                "modularmachinery:blockcasing@2"
            ]
        },
        {
            "x": 1,
            "y": 4,
            "z": 3,
            "elements": [
                "astralsorcery:blockmarble@1"
            ]
        },
        {
            "x": -2,
            "y": 2,
            "z": 5,
            "elements": [
                "astralsorcery:blockmarble@1"
            ]
        },
        {
            "x": 0,
            "y": 2,
            "z": 6,
            "elements": [
                "ic2:fence@0"
            ]
        },
        {
            "x": 0,
            "y": 2,
            "z": 5,

            "elements": [
                "modularmachinery:blockcasing@2"
            ]
        },
        {
            "x": -1,
            "y": 1,
            "z": 6,
            "elements": [
                "astralsorcery:blockmarble@1"
            ]
        },
        {
            "x": 0,
            "y": 9,
            "z": 1,
            "elements": [
                "astralsorcery:blockmarblestairs@6"
            ]
        },
        {
            "x": 0,
            "y": 9,
            "z": 2,
            "elements": [
                "astralsorcery:blockmarble@1"
            ]
        },
        {
            "x": -1,
            "y": 4,
            "z": 3,
            "elements": [
                "astralsorcery:blockmarble@1"
            ]
        },
        {
            "x": -1,
            "y": 4,
            "z": 2,
            "elements": [
                "astralsorcery:blockmarble@1"
            ]
        },
        {
            "x": 0,
            "y": 9,
            "z": 3,
            "elements": [
                "astralsorcery:blockmarble@1"
            ]
        },
        {
            "x": -1,
            "y": 1,
            "z": 0,
            "elements": [
                "astralsorcery:blockmarble@1"
            ]
        },
        {
            "x": -1,
            "y": 4,
            "z": 1,
            "elements": [
                "astralsorcery:blockmarble@1"
            ]
        },
        {
            "x": 0,
            "y": 9,
            "z": 4,
            "elements": [
                "astralsorcery:blockmarble@1"
            ]
        },
        {
            "x": 2,
            "y": 1,
            "z": 6,
            "elements": [
                "thermalfoundation:glass@7"
            ]
        },
        {
            "x": -1,
            "y": 4,
            "z": 0,
            "elements": [
                "astralsorcery:blockmarbleslab@0"
            ]
        },
        {
            "x": 0,
            "y": 9,
            "z": 5,
            "elements": [
                "astralsorcery:blockmarblestairs@7"
            ]
        },
        {
            "x": 2,
            "y": 1,
            "z": 0,
            "elements": [
                "thermalfoundation:glass@7"
            ]
        },
        {
            "x": 0,
            "y": 2,
            "z": 1,

            "elements": [
                "modularmachinery:blockcasing@2"
            ]
        },
        {
            "x": -1,
            "y": 4,
            "z": 6,
            "elements": [
                "astralsorcery:blockmarbleslab@0"
            ]
        },
        {
            "x": -1,
            "y": 4,
            "z": 5,
            "elements": [
                "astralsorcery:blockmarble@1"
            ]
        },
        {
            "x": 2,
            "y": 1,
            "z": 3,

            "elements": [
                "modularmachinery:blockcasing@2"
            ]
        },
        {
            "x": 0,
            "y": 2,
            "z": 3,
            "elements": [
                "enderio:block_alloy@8"
            ]
        },
        {
            "x": -1,
            "y": 4,
            "z": 4,
            "elements": [
                "astralsorcery:blockmarble@1"
            ]
        },
        {
            "x": 0,
            "y": 2,
            "z": 0,
            "elements": [
                "ic2:fence@0"
            ]
        },
        {
            "x": -1,
            "y": 7,
            "z": 5,
            "elements": [
                "ic2:fence@0"
            ]
        },
        {
            "x": -2,
            "y": 10,
            "z": 2,
            "elements": [
                "astralsorcery:blockmarbleslab@0"
            ]
        },
        {
            "x": -1,
            "y": 7,
            "z": 3,
            "elements": [
                "astralsorcery:blockmarble@1"
            ]
        },
        {
            "x": -2,
            "y": 10,
            "z": 3,
            "elements": [
                "astralsorcery:blockmarblestairs@0"
            ]
        },
        {
            "x": -1,
            "y": 7,
            "z": 4,
            "elements": [
                "ic2:fence@0"
            ]
        },
        {
            "x": -2,
            "y": 10,
            "z": 4,
            "elements": [
                "astralsorcery:blockmarbleslab@0"
            ]
        },
        {
            "x": -1,
            "y": 7,
            "z": 1,
            "elements": [
                "ic2:fence@0"
            ]
        },
        {
            "x": -1,
            "y": 7,
            "z": 2,
            "elements": [
                "ic2:fence@0"
            ]
        },
        {
            "x": 0,
            "y": -1,
            "z": 1,
            "elements": [
                "astralsorcery:blockmarble@1"
            ]
        },
        {
            "x": 0,
            "y": 6,
            "z": 5,
            "elements": [
                "astralsorcery:blockmarble@1"
            ]
        },
        {
            "x": 0,
            "y": -1,
            "z": 0,
            "elements": [
                "astralsorcery:blockmarblestairs@2"
            ]
        },
        {
            "x": 0,
            "y": -1,
            "z": 3,
            "elements": [
                "cookingforblockheads:kitchen_floor@0"
            ]
        },
        {
            "x": 0,
            "y": -1,
            "z": 2,
            "elements": [
                "cookingforblockheads:kitchen_floor@0"
            ]
        },
        {
            "x": 0,
            "y": 6,
            "z": 1,
            "elements": [
                "astralsorcery:blockmarble@1"
            ]
        },
        {
            "x": 0,
            "y": -1,
            "z": 5,
            "elements": [
                "astralsorcery:blockmarble@1"
            ]
        },
        {
            "x": 0,
            "y": 6,
            "z": 2,
            "elements": [
                "astralsorcery:blockmarble@1"
            ]
        },
        {
            "x": 0,
            "y": -1,
            "z": 4,
            "elements": [
                "cookingforblockheads:kitchen_floor@0"
            ]
        },
        {
            "x": 0,
            "y": 6,
            "z": 3,
            "elements": [
                "astralsorcery:blockmarble@1"
            ]
        },
        {
            "x": 0,
            "y": 6,
            "z": 4,
            "elements": [
                "astralsorcery:blockmarble@1"
            ]
        },
        {
            "x": 0,
            "y": -1,
            "z": 6,
            "elements": [
                "astralsorcery:blockmarblestairs@3"
            ]
        },
        {
            "x": -1,
            "y": 10,
            "z": 1,
            "elements": [
                "astralsorcery:blockmarbleslab@0"
            ]
        },
        {
            "x": 3,
            "y": 0,
            "z": 4,
            "elements": [
                "astralsorcery:blockmarble@1"
            ]
        },
        {
            "x": -1,
            "y": 0,
            "z": 0,
            "elements": [
                "astralsorcery:blockmarble@1"
            ]
        },
        {
            "x": 3,
            "y": 0,
            "z": 5,
            "elements": [
                "thermalfoundation:glass@7"
            ]
        },
        {
            "x": -1,
            "y": 10,
            "z": 4,
            "elements": [
                "astralsorcery:blockmarble@1"
            ]
        },
        {
            "x": -1,
            "y": 10,
            "z": 5,
            "elements": [
                "astralsorcery:blockmarbleslab@0"
            ]
        },
        {
            "x": -1,
            "y": 0,
            "z": 6,
            "elements": [
                "astralsorcery:blockmarble@1"
            ]
        },
        {
            "x": -1,
            "y": 10,
            "z": 2,
            "elements": [
                "astralsorcery:blockmarble@1"
            ]
        },
        {
            "x": -1,
            "y": 10,
            "z": 3,

            "elements": [
                "modularmachinery:blockcasing@1"
            ]
        },
        {
            "x": 3,
            "y": 0,
            "z": 2,
            "elements": [
                "astralsorcery:blockmarble@1"
            ]
        },
        {
            "x": 3,
            "y": 0,
            "z": 3,
            "elements": [
                "astralsorcery:blockmarble@1"
            ]
        },
        {
            "x": 2,
            "y": 4,
            "z": 0,
            "elements": [
                "astralsorcery:blockmarbleslab@0"
            ]
        },
        {
            "x": 3,
            "y": 0,
            "z": 1,
            "elements": [
                "thermalfoundation:glass@7"
            ]
        },
        {
            "x": 2,
            "y": 4,
            "z": 1,
            "elements": [
                "astralsorcery:blockmarbleslab@0"
            ]
        },
        {
            "x": 2,
            "y": 4,
            "z": 2,
            "elements": [
                "astralsorcery:blockmarble@1"
            ]
        },
        {
            "x": 2,
            "y": 4,
            "z": 3,
            "elements": [
                "astralsorcery:blockmarble@1"
            ]
        },
        {
            "x": 2,
            "y": 4,
            "z": 4,
            "elements": [
                "astralsorcery:blockmarble@1"
            ]
        },
        {
            "x": 2,
            "y": 4,
            "z": 5,
            "elements": [
                "astralsorcery:blockmarbleslab@0"
            ]
        },
        {
            "x": 2,
            "y": 4,
            "z": 6,
            "elements": [
                "astralsorcery:blockmarbleslab@0"
            ]
        },
        {
            "x": 2,
            "y": 10,
            "z": 2,
            "elements": [
                "astralsorcery:blockmarbleslab@0"
            ]
        },
        {
            "x": 1,
            "y": 8,
            "z": 4,
            "elements": [
                "astralsorcery:blockmarble@1"
            ]
        },
        {
            "x": -3,
            "y": 2,
            "z": 1,
            "elements": [
                "astralsorcery:blockmarblestairs@2"
            ]
        },
        {
            "x": 1,
            "y": 8,
            "z": 5,
            "elements": [
                "astralsorcery:blockmarble@1"
            ]
        },
        {
            "x": -3,
            "y": 2,
            "z": 2,
            "elements": [
                "astralsorcery:blockmarble@1"
            ]
        },
        {
            "x": 1,
            "y": 8,
            "z": 2,
            "elements": [
                "astralsorcery:blockmarble@1"
            ]
        },
        {
            "x": -3,
            "y": 2,
            "z": 3,
            "elements": [
                "ic2:fence@0"
            ]
        },
        {
            "x": 1,
            "y": 8,
            "z": 3,
            "elements": [
                "astralsorcery:blockmarble@1"
            ]
        },
        {
            "x": -3,
            "y": 2,
            "z": 4,
            "elements": [
                "astralsorcery:blockmarble@1"
            ]
        },
        {
            "x": 1,
            "y": 8,
            "z": 1,
            "elements": [
                "astralsorcery:blockmarble@1"
            ]
        },
        {
            "x": -3,
            "y": 2,
            "z": 5,
            "elements": [
                "astralsorcery:blockmarblestairs@3"
            ]
        },
        {
            "x": 2,
            "y": 10,
            "z": 4,
            "elements": [
                "astralsorcery:blockmarbleslab@0"
            ]
        },
        {
            "x": 2,
            "y": 10,
            "z": 3,
            "elements": [
                "astralsorcery:blockmarblestairs@1"
            ]
        },
        {
            "x": -3,
            "y": -1,
            "z": 1,

            "elements": [
                "modularmachinery:blockcasing@0",
                "ItemInput",
                "EnergyOutput"
            ]
        },
        {
            "x": -3,
            "y": -1,
            "z": 2,

            "elements": [
                "modularmachinery:blockcasing@0",
                "ItemInput",
                "EnergyOutput"
            ]
        },
        {
            "x": 3,
            "y": 3,
            "z": 5,
            "elements": [
                "ic2:fence@0"
            ]
        },
        {
            "x": -3,
            "y": -1,
            "z": 3,
            "elements": [
                "astralsorcery:blockmarblestairs@0"
            ]
        },
        {
            "x": 3,
            "y": 3,
            "z": 3,
            "elements": [
                "astralsorcery:blockmarblestairs@1"
            ]
        },
        {
            "x": -3,
            "y": -1,
            "z": 4,

            "elements": [
                "modularmachinery:blockcasing@0",
                "ItemInput",
                "EnergyOutput"
            ]
        },
        {
            "x": 3,
            "y": 3,
            "z": 4,
            "elements": [
                "astralsorcery:blockmarblestairs@2"
            ]
        },
        {
            "x": 2,
            "y": 7,
            "z": 4,
            "elements": [
                "ic2:fence@0"
            ]
        },
        {
            "x": 3,
            "y": 3,
            "z": 1,
            "elements": [
                "ic2:fence@0"
            ]
        },
        {
            "x": 2,
            "y": 7,
            "z": 3,
            "elements": [
                "astralsorcery:blockmarblestairs@5"
            ]
        },
        {
            "x": -3,
            "y": -1,
            "z": 5,

            "elements": [
                "modularmachinery:blockcasing@0",
                "ItemInput",
                "EnergyOutput"
            ]
        },
        {
            "x": 3,
            "y": 3,
            "z": 2,
            "elements": [
                "astralsorcery:blockmarblestairs@3"
            ]
        },
        {
            "x": 2,
            "y": 7,
            "z": 2,
            "elements": [
                "ic2:fence@0"
            ]
        }
    ]}