{
    "registryname": "YMG_Core_Pressure_Analog_Devices",
    "localizedname": "§b§lYMG§r§e§l—§f§l地核压力模拟装置 §r§e",
    "failure-action": "still",
    "requires-blueprint": false,
    "color": "452B2B",
    "parts": [
        {
            "x": 0,
            "y": 0,
            "z": 0,

            "elements": [
                "modularmachinery:blockcontroller@2"
            ]
        },
        {
            "x": -3,
            "y": -2,
            "z": 5,

            "elements": [
                "mekanismgenerators:reactor@1"
            ]
        },
        {
            "x": 3,
            "y": 3,
            "z": 2,

            "elements": [
                "mekanismgenerators:reactorglass@0"
            ]
        },
        {
            "x": 4,
            "y": 1,
            "z": 4,

            "elements": [
                "mekanismgenerators:reactor@1"
            ]
        },
        {
            "x": 0,
            "y": -2,
            "z": 0,

            "elements": [
                "modularmachinery:blockcasing@4",
                "ItemInputStrengthen",
                "ItemOutputStrengthen",
                "EnergyInputStrengthen",
                "EnergyOutputStrengthen",
                "FluidInputStrengthen",
                "FluidOutputStrengthen"
            ]
        },
        {
            "x": -1,
            "y": 2,
            "z": 7,

            "elements": [
                "mekanismgenerators:reactor@1"
            ]
        },
        {
            "x": -3,
            "y": 2,
            "z": 5,

            "elements": [
                "mekanismgenerators:reactor@1"
            ]
        },
        {
            "x": 0,
            "y": -1,
            "z": 0,

            "elements": [
                "mekanismgenerators:reactor@1"
            ]
        },
        {
            "x": 4,
            "y": 2,
            "z": 4,

            "elements": [
                "mekanismgenerators:reactor@1"
            ]
        },
        {
            "x": -1,
            "y": 1,
            "z": 0,

            "elements": [
                "mekanismgenerators:reactorglass@0"
            ]
        },
        {
            "x": 3,
            "y": 2,
            "z": 2,

            "elements": [
                "mekanismgenerators:reactor@1"
            ]
        },
        {
            "x": 2,
            "y": 3,
            "z": 6,

            "elements": [
                "mekanismgenerators:reactorglass@0"
            ]
        },
        {
            "x": 1,
            "y": 4,
            "z": 4,

            "elements": [
                "mekanismgenerators:reactorglass@0"
            ]
        },
        {
            "x": 0,
            "y": 4,
            "z": 2,

            "elements": [
                "mekanismgenerators:reactorglass@0"
            ]
        },
        {
            "x": -4,
            "y": 0,
            "z": 3,

            "elements": [
                "mekanismgenerators:reactorglass@0"
            ]
        },
        {
            "x": -2,
            "y": -2,
            "z": 3,

            "elements": [
                "mekanismgenerators:reactor@1"
            ]
        },
        {
            "x": -1,
            "y": 3,
            "z": 7,

            "elements": [
                "mekanismgenerators:reactorglass@0"
            ]
        },
        {
            "x": 1,
            "y": -2,
            "z": 7,

            "elements": [
                "mekanismgenerators:reactor@1"
            ]
        },
        {
            "x": 1,
            "y": 0,
            "z": 0,

            "elements": [
                "mekanismgenerators:reactorglass@0"
            ]
        },
        {
            "x": -4,
            "y": -2,
            "z": 5,

            "elements": [
                "modularmachinery:blockcasing@4",
                "ItemInputStrengthen",
                "ItemOutputStrengthen",
                "EnergyInputStrengthen",
                "EnergyOutputStrengthen",
                "FluidInputStrengthen",
                "FluidOutputStrengthen"
            ]
        },
        {
            "x": 1,
            "y": -2,
            "z": 0,

            "elements": [
                "modularmachinery:blockcasing@4",
                "ItemInputStrengthen",
                "ItemOutputStrengthen",
                "EnergyInputStrengthen",
                "EnergyOutputStrengthen",
                "FluidInputStrengthen",
                "FluidOutputStrengthen"
            ]
        },
        {
            "x": -4,
            "y": 1,
            "z": 3,

            "elements": [
                "mekanismgenerators:reactorglass@0"
            ]
        },
        {
            "x": 3,
            "y": 1,
            "z": 2,

            "elements": [
                "mekanismgenerators:reactorglass@0"
            ]
        },
        {
            "x": 3,
            "y": -1,
            "z": 4,

            "elements": [
                "mekanismgenerators:reactor@1"
            ]
        },
        {
            "x": -1,
            "y": 4,
            "z": 7,

            "elements": [
                "mekanismgenerators:reactorglass@0"
            ]
        },
        {
            "x": 1,
            "y": -1,
            "z": 0,

            "elements": [
                "mekanismgenerators:reactorglass@0"
            ]
        },
        {
            "x": 2,
            "y": 0,
            "z": 7,

            "elements": [
                "mekanismgenerators:reactorglass@0"
            ]
        },
        {
            "x": -4,
            "y": -1,
            "z": 5,

            "elements": [
                "mekanismgenerators:reactorglass@0"
            ]
        },
        {
            "x": 1,
            "y": 4,
            "z": 2,

            "elements": [
                "mekanismgenerators:reactorglass@0"
            ]
        },
        {
            "x": 4,
            "y": -2,
            "z": 4,

            "elements": [
                "modularmachinery:blockcasing@4",
                "ItemInputStrengthen",
                "ItemOutputStrengthen",
                "EnergyInputStrengthen",
                "EnergyOutputStrengthen",
                "FluidInputStrengthen",
                "FluidOutputStrengthen"
            ]
        },
        {
            "x": 4,
            "y": 0,
            "z": 4,

            "elements": [
                "mekanismgenerators:reactor@1"
            ]
        },
        {
            "x": 1,
            "y": -2,
            "z": 3,

            "elements": [
                "mekanismgenerators:reactor@1"
            ]
        },
        {
            "x": 3,
            "y": 0,
            "z": 2,

            "elements": [
                "mekanismgenerators:reactorglass@0"
            ]
        },
        {
            "x": 2,
            "y": -2,
            "z": 2,

            "elements": [
                "mekanismgenerators:reactor@1"
            ]
        },
        {
            "x": 0,
            "y": -1,
            "z": 8,

            "elements": [
                "mekanismgenerators:reactor@1"
            ]
        },
        {
            "x": 1,
            "y": -1,
            "z": 3,

            "elements": [
                "environmentaltech:lightning_rod@0"
            ]
        },
        {
            "x": 3,
            "y": 3,
            "z": 4,

            "elements": [
                "mekanismgenerators:reactor@1"
            ]
        },
        {
            "x": -1,
            "y": -2,
            "z": 5,

            "elements": [
                "mekanismgenerators:reactor@1"
            ]
        },
        {
            "x": -1,
            "y": 4,
            "z": 6,

            "elements": [
                "mekanismgenerators:reactorglass@0"
            ]
        },
        {
            "x": 3,
            "y": 4,
            "z": 4,

            "elements": [
                "mekanismgenerators:reactorglass@0"
            ]
        },
        {
            "x": -3,
            "y": 3,
            "z": 2,

            "elements": [
                "mekanismgenerators:reactorglass@0"
            ]
        },
        {
            "x": 4,
            "y": -1,
            "z": 4,

            "elements": [
                "mekanismgenerators:reactor@1"
            ]
        },
        {
            "x": 0,
            "y": 1,
            "z": 2,
            "elements": [
                "minecraft:end_rod@3"
            ]
        },
        {
            "x": -1,
            "y": 4,
            "z": 3,

            "elements": [
                "mekanismgenerators:reactorglass@0"
            ]
        },
        {
            "x": 0,
            "y": -2,
            "z": 8,

            "elements": [
                "modularmachinery:blockcasing@4",
                "ItemInputStrengthen",
                "ItemOutputStrengthen",
                "EnergyInputStrengthen",
                "EnergyOutputStrengthen",
                "FluidInputStrengthen",
                "FluidOutputStrengthen"
            ]
        },
        {
            "x": 4,
            "y": -2,
            "z": 3,

            "elements": [
                "modularmachinery:blockcasing@4",
                "ItemInputStrengthen",
                "ItemOutputStrengthen",
                "EnergyInputStrengthen",
                "EnergyOutputStrengthen",
                "FluidInputStrengthen",
                "FluidOutputStrengthen"
            ]
        },
        {
            "x": 1,
            "y": 1,
            "z": 0,

            "elements": [
                "mekanismgenerators:reactorglass@0"
            ]
        },
        {
            "x": -1,
            "y": -1,
            "z": 5,

            "elements": [
                "environmentaltech:lightning_rod@0"
            ]
        },
        {
            "x": 1,
            "y": 0,
            "z": 8,

            "elements": [
                "mekanismgenerators:reactorglass@0"
            ]
        },
        {
            "x": 1,
            "y": -2,
            "z": 6,

            "elements": [
                "mekanismgenerators:reactor@1"
            ]
        },
        {
            "x": 2,
            "y": 1,
            "z": 7,

            "elements": [
                "mekanismgenerators:reactorglass@0"
            ]
        },
        {
            "x": -1,
            "y": 3,
            "z": 3,
            "elements": [
                "appliedenergistics2:smooth_sky_stone_slab@0"
            ]
        },
        {
            "x": -3,
            "y": 2,
            "z": 2,

            "elements": [
                "mekanismgenerators:reactor@1"
            ]
        },
        {
            "x": -1,
            "y": 0,
            "z": 0,

            "elements": [
                "mekanismgenerators:reactorglass@0"
            ]
        },
        {
            "x": -1,
            "y": 1,
            "z": 8,

            "elements": [
                "mekanismgenerators:reactorglass@0"
            ]
        },
        {
            "x": -3,
            "y": 0,
            "z": 2,

            "elements": [
                "mekanismgenerators:reactorglass@0"
            ]
        },
        {
            "x": 0,
            "y": 0,
            "z": 5,
            "elements": [
                "enderio:block_reinforced_obsidian@0"
            ]
        },
        {
            "x": 0,
            "y": 4,
            "z": 3,

            "elements": [
                "mekanismgenerators:reactorglass@0"
            ]
        },
        {
            "x": 0,
            "y": 2,
            "z": 5,
            "elements": [
                "enderio:block_reinforced_obsidian@0"
            ]
        },
        {
            "x": -3,
            "y": 1,
            "z": 2,

            "elements": [
                "mekanismgenerators:reactorglass@0"
            ]
        },
        {
            "x": -3,
            "y": 4,
            "z": 5,

            "elements": [
                "mekanismgenerators:reactorglass@0"
            ]
        },
        {
            "x": -2,
            "y": -1,
            "z": 7,

            "elements": [
                "mekanismgenerators:reactorglass@0"
            ]
        },
        {
            "x": 0,
            "y": -2,
            "z": 6,

            "elements": [
                "mekanismgenerators:reactor@1"
            ]
        },
        {
            "x": -3,
            "y": 3,
            "z": 5,

            "elements": [
                "mekanismgenerators:reactorglass@0"
            ]
        },
        {
            "x": -2,
            "y": -2,
            "z": 7,

            "elements": [
                "modularmachinery:blockcasing@4",
                "ItemInputStrengthen",
                "ItemOutputStrengthen",
                "EnergyInputStrengthen",
                "EnergyOutputStrengthen",
                "FluidInputStrengthen",
                "FluidOutputStrengthen"
            ]
        },
        {
            "x": 0,
            "y": 1,
            "z": 5,
            "elements": [
                "enderio:block_reinforced_obsidian@0"
            ]
        },
        {
            "x": 0,
            "y": -2,
            "z": 2,

            "elements": [
                "mekanismgenerators:reactor@1"
            ]
        },
        {
            "x": 1,
            "y": -2,
            "z": 5,

            "elements": [
                "mekanismgenerators:reactor@1"
            ]
        },
        {
            "x": 1,
            "y": 4,
            "z": 6,

            "elements": [
                "mekanismgenerators:reactorglass@0"
            ]
        },
        {
            "x": 2,
            "y": -2,
            "z": 4,

            "elements": [
                "mekanismgenerators:reactor@1"
            ]
        },
        {
            "x": 0,
            "y": 4,
            "z": 5,

            "elements": [
                "mekanismgenerators:reactorglass@0"
            ]
        },
        {
            "x": 3,
            "y": -2,
            "z": 6,

            "elements": [
                "modularmachinery:blockcasing@4",
                "ItemInputStrengthen",
                "ItemOutputStrengthen",
                "EnergyInputStrengthen",
                "EnergyOutputStrengthen",
                "FluidInputStrengthen",
                "FluidOutputStrengthen"
            ]
        },
        {
            "x": -3,
            "y": 3,
            "z": 4,

            "elements": [
                "mekanismgenerators:reactor@1"
            ]
        },
        {
            "x": 3,
            "y": 2,
            "z": 7,

            "elements": [
                "mekanismgenerators:reactor@1"
            ]
        },
        {
            "x": 0,
            "y": 1,
            "z": 4,
            "elements": [
                "contenttweaker:tungstenblock@0"
            ]
        },
        {
            "x": -3,
            "y": 4,
            "z": 4,

            "elements": [
                "mekanismgenerators:reactorglass@0"
            ]
        },
        {
            "x": -1,
            "y": 0,
            "z": 8,

            "elements": [
                "mekanismgenerators:reactorglass@0"
            ]
        },
        {
            "x": -1,
            "y": -1,
            "z": 4,
            "elements": [
                "appliedenergistics2:smooth_sky_stone_slab@0"
            ]
        },
        {
            "x": 1,
            "y": -1,
            "z": 5,

            "elements": [
                "environmentaltech:lightning_rod@0"
            ]
        },
        {
            "x": 0,
            "y": 2,
            "z": 4,
            "elements": [
                "enderio:block_reinforced_obsidian@0"
            ]
        },
        {
            "x": 3,
            "y": -1,
            "z": 6,

            "elements": [
                "mekanismgenerators:reactorglass@0"
            ]
        },
        {
            "x": 3,
            "y": 0,
            "z": 4,
            "elements": [
                "ic2:fence@0"
            ]
        },
        {
            "x": 2,
            "y": 2,
            "z": 7,

            "elements": [
                "mekanismgenerators:reactor@1"
            ]
        },
        {
            "x": -1,
            "y": -2,
            "z": 2,

            "elements": [
                "mekanismgenerators:reactor@1"
            ]
        },
        {
            "x": -3,
            "y": 0,
            "z": 4,
            "elements": [
                "ic2:fence@0"
            ]
        },
        {
            "x": 4,
            "y": -1,
            "z": 3,

            "elements": [
                "mekanismgenerators:reactorglass@0"
            ]
        },
        {
            "x": 1,
            "y": 3,
            "z": 1,

            "elements": [
                "mekanismgenerators:reactorglass@0"
            ]
        },
        {
            "x": -1,
            "y": 4,
            "z": 5,

            "elements": [
                "mekanismgenerators:reactorglass@0"
            ]
        },
        {
            "x": -2,
            "y": 3,
            "z": 2,

            "elements": [
                "mekanismgenerators:reactorglass@0"
            ]
        },
        {
            "x": 1,
            "y": 2,
            "z": 1,

            "elements": [
                "mekanismgenerators:reactor@1"
            ]
        },
        {
            "x": 2,
            "y": 4,
            "z": 3,

            "elements": [
                "mekanismgenerators:reactorglass@0"
            ]
        },
        {
            "x": 3,
            "y": 1,
            "z": 4,
            "elements": [
                "fluxnetworks:fluxblock@0"
            ]
        },
        {
            "x": 3,
            "y": 2,
            "z": 3,

            "elements": [
                "mekanismgenerators:reactor@1"
            ]
        },
        {
            "x": 3,
            "y": 2,
            "z": 4,

            "elements": [
                "mekanismgenerators:reactor@1"
            ]
        },
        {
            "x": -4,
            "y": -1,
            "z": 4,

            "elements": [
                "mekanismgenerators:reactor@1"
            ]
        },
        {
            "x": 0,
            "y": 0,
            "z": 4,
            "elements": [
                "enderio:block_reinforced_obsidian@0"
            ]
        },
        {
            "x": 2,
            "y": 3,
            "z": 7,

            "elements": [
                "mekanismgenerators:reactorglass@0"
            ]
        },
        {
            "x": -1,
            "y": 3,
            "z": 5,
            "elements": [
                "appliedenergistics2:smooth_sky_stone_slab@0"
            ]
        },
        {
            "x": 3,
            "y": -2,
            "z": 1,

            "elements": [
                "modularmachinery:blockcasing@4",
                "ItemInputStrengthen",
                "ItemOutputStrengthen",
                "EnergyInputStrengthen",
                "EnergyOutputStrengthen",
                "FluidInputStrengthen",
                "FluidOutputStrengthen"
            ]
        },
        {
            "x": -4,
            "y": -2,
            "z": 4,

            "elements": [
                "modularmachinery:blockcasing@4",
                "ItemInputStrengthen",
                "ItemOutputStrengthen",
                "EnergyInputStrengthen",
                "EnergyOutputStrengthen",
                "FluidInputStrengthen",
                "FluidOutputStrengthen"
            ]
        },
        {
            "x": -2,
            "y": -2,
            "z": 2,

            "elements": [
                "mekanismgenerators:reactor@1"
            ]
        },
        {
            "x": 3,
            "y": 4,
            "z": 3,

            "elements": [
                "mekanismgenerators:reactorglass@0"
            ]
        },
        {
            "x": -1,
            "y": 0,
            "z": 5,

            "elements": [
                "environmentaltech:lightning_rod@0"
            ]
        },
        {
            "x": 0,
            "y": 4,
            "z": 7,

            "elements": [
                "mekanismgenerators:reactorglass@0"
            ]
        },
        {
            "x": -2,
            "y": 4,
            "z": 2,

            "elements": [
                "mekanismgenerators:reactorglass@0"
            ]
        },
        {
            "x": 1,
            "y": 4,
            "z": 1,

            "elements": [
                "mekanismgenerators:reactorglass@0"
            ]
        },
        {
            "x": -1,
            "y": 2,
            "z": 5,
            "elements": [
                "ic2:fence@0"
            ]
        },
        {
            "x": 3,
            "y": 0,
            "z": 7,

            "elements": [
                "mekanismgenerators:reactorglass@0"
            ]
        },
        {
            "x": 3,
            "y": 3,
            "z": 3,

            "elements": [
                "mekanismgenerators:reactorglass@0"
            ]
        },
        {
            "x": 2,
            "y": 4,
            "z": 6,

            "elements": [
                "mekanismgenerators:reactorglass@0"
            ]
        },
        {
            "x": -1,
            "y": 1,
            "z": 5,
            "elements": [
                "enderio:block_reinforced_obsidian@0"
            ]
        },
        {
            "x": 3,
            "y": -1,
            "z": 1,

            "elements": [
                "mekanismgenerators:reactorglass@0"
            ]
        },
        {
            "x": -2,
            "y": -2,
            "z": 5,

            "elements": [
                "mekanismgenerators:reactor@1"
            ]
        },
        {
            "x": 1,
            "y": -2,
            "z": 2,

            "elements": [
                "mekanismgenerators:reactor@1"
            ]
        },
        {
            "x": 3,
            "y": 2,
            "z": 6,

            "elements": [
                "mekanismgenerators:reactor@1"
            ]
        },
        {
            "x": 2,
            "y": -1,
            "z": 7,

            "elements": [
                "mekanismgenerators:reactorglass@0"
            ]
        },
        {
            "x": -4,
            "y": 0,
            "z": 5,

            "elements": [
                "mekanismgenerators:reactorglass@0"
            ]
        },
        {
            "x": 0,
            "y": 2,
            "z": 7,

            "elements": [
                "mekanismgenerators:reactor@1"
            ]
        },
        {
            "x": 2,
            "y": -2,
            "z": 7,

            "elements": [
                "modularmachinery:blockcasing@4",
                "ItemInputStrengthen",
                "ItemOutputStrengthen",
                "EnergyInputStrengthen",
                "EnergyOutputStrengthen",
                "FluidInputStrengthen",
                "FluidOutputStrengthen"
            ]
        },
        {
            "x": 3,
            "y": 3,
            "z": 6,

            "elements": [
                "mekanismgenerators:reactorglass@0"
            ]
        },
        {
            "x": 0,
            "y": 4,
            "z": 4,

            "elements": [
                "mekanismgenerators:reactorglass@0"
            ]
        },
        {
            "x": 3,
            "y": 1,
            "z": 7,

            "elements": [
                "mekanismgenerators:reactorglass@0"
            ]
        },
        {
            "x": -4,
            "y": 1,
            "z": 5,

            "elements": [
                "mekanismgenerators:reactorglass@0"
            ]
        },
        {
            "x": 0,
            "y": 3,
            "z": 7,

            "elements": [
                "mekanismgenerators:reactor@1"
            ]
        },
        {
            "x": 0,
            "y": 1,
            "z": 8,

            "elements": [
                "mekanismgenerators:reactor@1"
            ]
        },
        {
            "x": 1,
            "y": 1,
            "z": 3,
            "elements": [
                "enderio:block_reinforced_obsidian@0"
            ]
        },
        {
            "x": -3,
            "y": 0,
            "z": 1,

            "elements": [
                "mekanismgenerators:reactorglass@0"
            ]
        },
        {
            "x": -2,
            "y": -2,
            "z": 4,

            "elements": [
                "mekanismgenerators:reactor@1"
            ]
        },
        {
            "x": 0,
            "y": 3,
            "z": 1,

            "elements": [
                "mekanismgenerators:reactor@1"
            ]
        },
        {
            "x": -4,
            "y": 0,
            "z": 4,

            "elements": [
                "mekanismgenerators:reactor@1"
            ]
        },
        {
            "x": -3,
            "y": -2,
            "z": 1,

            "elements": [
                "modularmachinery:blockcasing@4",
                "ItemInputStrengthen",
                "ItemOutputStrengthen",
                "EnergyInputStrengthen",
                "EnergyOutputStrengthen",
                "FluidInputStrengthen",
                "FluidOutputStrengthen"
            ]
        },
        {
            "x": 1,
            "y": 4,
            "z": 3,

            "elements": [
                "mekanismgenerators:reactorglass@0"
            ]
        },
        {
            "x": -4,
            "y": 1,
            "z": 4,

            "elements": [
                "mekanismgenerators:reactor@1"
            ]
        },
        {
            "x": 0,
            "y": 2,
            "z": 1,

            "elements": [
                "mekanismgenerators:reactor@1"
            ]
        },
        {
            "x": 3,
            "y": 0,
            "z": 6,

            "elements": [
                "mekanismgenerators:reactorglass@0"
            ]
        },
        {
            "x": 4,
            "y": 0,
            "z": 3,

            "elements": [
                "mekanismgenerators:reactorglass@0"
            ]
        },
        {
            "x": 3,
            "y": 1,
            "z": 6,

            "elements": [
                "mekanismgenerators:reactorglass@0"
            ]
        },
        {
            "x": -3,
            "y": -1,
            "z": 1,

            "elements": [
                "mekanismgenerators:reactorglass@0"
            ]
        },
        {
            "x": -1,
            "y": -2,
            "z": 6,

            "elements": [
                "mekanismgenerators:reactor@1"
            ]
        },
        {
            "x": -1,
            "y": 4,
            "z": 1,

            "elements": [
                "mekanismgenerators:reactorglass@0"
            ]
        },
        {
            "x": -4,
            "y": 2,
            "z": 4,

            "elements": [
                "mekanismgenerators:reactor@1"
            ]
        },
        {
            "x": -1,
            "y": 0,
            "z": 4,
            "elements": [
                "enderio:block_reinforced_obsidian@0"
            ]
        },
        {
            "x": -3,
            "y": 1,
            "z": 1,

            "elements": [
                "mekanismgenerators:reactorglass@0"
            ]
        },
        {
            "x": 4,
            "y": 1,
            "z": 3,

            "elements": [
                "mekanismgenerators:reactorglass@0"
            ]
        },
        {
            "x": 0,
            "y": 2,
            "z": 8,

            "elements": [
                "mekanismgenerators:reactor@1"
            ]
        },
        {
            "x": 1,
            "y": 3,
            "z": 3,
            "elements": [
                "appliedenergistics2:smooth_sky_stone_slab@0"
            ]
        },
        {
            "x": 3,
            "y": -1,
            "z": 2,

            "elements": [
                "mekanismgenerators:reactorglass@0"
            ]
        },
        {
            "x": 0,
            "y": -1,
            "z": 7,

            "elements": [
                "mekanismgenerators:reactor@1"
            ]
        },
        {
            "x": 2,
            "y": -2,
            "z": 1,

            "elements": [
                "modularmachinery:blockcasing@4",
                "ItemInputStrengthen",
                "ItemOutputStrengthen",
                "EnergyInputStrengthen",
                "EnergyOutputStrengthen",
                "FluidInputStrengthen",
                "FluidOutputStrengthen"
            ]
        },
        {
            "x": 3,
            "y": -2,
            "z": 2,

            "elements": [
                "modularmachinery:blockcasing@4",
                "ItemInputStrengthen",
                "ItemOutputStrengthen",
                "EnergyInputStrengthen",
                "EnergyOutputStrengthen",
                "FluidInputStrengthen",
                "FluidOutputStrengthen"
            ]
        },
        {
            "x": 3,
            "y": 4,
            "z": 5,

            "elements": [
                "mekanismgenerators:reactorglass@0"
            ]
        },
        {
            "x": 2,
            "y": 3,
            "z": 2,

            "elements": [
                "mekanismgenerators:reactorglass@0"
            ]
        },
        {
            "x": 1,
            "y": -2,
            "z": 4,

            "elements": [
                "mekanismgenerators:reactor@1"
            ]
        },
        {
            "x": -1,
            "y": 1,
            "z": 4,
            "elements": [
                "enderio:block_reinforced_obsidian@0"
            ]
        },
        {
            "x": 2,
            "y": -2,
            "z": 6,

            "elements": [
                "mekanismgenerators:reactor@1"
            ]
        },
        {
            "x": -3,
            "y": 2,
            "z": 1,

            "elements": [
                "mekanismgenerators:reactor@1"
            ]
        },
        {
            "x": 4,
            "y": -2,
            "z": 5,

            "elements": [
                "modularmachinery:blockcasing@4",
                "ItemInputStrengthen",
                "ItemOutputStrengthen",
                "EnergyInputStrengthen",
                "EnergyOutputStrengthen",
                "FluidInputStrengthen",
                "FluidOutputStrengthen"
            ]
        },
        {
            "x": 0,
            "y": -1,
            "z": 3,
            "elements": [
                "appliedenergistics2:smooth_sky_stone_slab@0"
            ]
        },
        {
            "x": -3,
            "y": 2,
            "z": 6,

            "elements": [
                "mekanismgenerators:reactor@1"
            ]
        },
        {
            "x": -1,
            "y": -2,
            "z": 8,

            "elements": [
                "modularmachinery:blockcasing@4",
                "ItemInputStrengthen",
                "ItemOutputStrengthen",
                "EnergyInputStrengthen",
                "EnergyOutputStrengthen",
                "FluidInputStrengthen",
                "FluidOutputStrengthen"
            ]
        },
        {
            "x": 0,
            "y": 0,
            "z": 1,
            "elements": [
                "ic2:fence@0"
            ]
        },
        {
            "x": -2,
            "y": 4,
            "z": 3,

            "elements": [
                "mekanismgenerators:reactorglass@0"
            ]
        },
        {
            "x": -2,
            "y": 4,
            "z": 4,

            "elements": [
                "mekanismgenerators:reactorglass@0"
            ]
        },
        {
            "x": -3,
            "y": 3,
            "z": 6,

            "elements": [
                "mekanismgenerators:reactorglass@0"
            ]
        },
        {
            "x": 1,
            "y": 0,
            "z": 3,

            "elements": [
                "environmentaltech:lightning_rod@0"
            ]
        },
        {
            "x": -2,
            "y": 3,
            "z": 7,

            "elements": [
                "mekanismgenerators:reactorglass@0"
            ]
        },
        {
            "x": 0,
            "y": 1,
            "z": 6,
            "elements": [
                "minecraft:end_rod@2"
            ]
        },
        {
            "x": 2,
            "y": -1,
            "z": 1,

            "elements": [
                "mekanismgenerators:reactorglass@0"
            ]
        },
        {
            "x": 0,
            "y": 1,
            "z": 1,
            "elements": [
                "fluxnetworks:fluxblock@0"
            ]
        },
        {
            "x": 3,
            "y": 3,
            "z": 5,

            "elements": [
                "mekanismgenerators:reactorglass@0"
            ]
        },
        {
            "x": -1,
            "y": 2,
            "z": 4,
            "elements": [
                "enderio:block_reinforced_obsidian@0"
            ]
        },
        {
            "x": 0,
            "y": -2,
            "z": 7,

            "elements": [
                "mekanismgenerators:reactor@1"
            ]
        },
        {
            "x": 4,
            "y": -1,
            "z": 5,

            "elements": [
                "mekanismgenerators:reactorglass@0"
            ]
        },
        {
            "x": 0,
            "y": -2,
            "z": 4,

            "elements": [
                "mekanismgenerators:reactor@1"
            ]
        },
        {
            "x": 3,
            "y": -1,
            "z": 7,

            "elements": [
                "mekanismgenerators:reactorglass@0"
            ]
        },
        {
            "x": -1,
            "y": -2,
            "z": 1,

            "elements": [
                "mekanismgenerators:reactor@1"
            ]
        },
        {
            "x": -2,
            "y": 2,
            "z": 1,

            "elements": [
                "mekanismgenerators:reactor@1"
            ]
        },
        {
            "x": -2,
            "y": 1,
            "z": 4,
            "elements": [
                "minecraft:end_rod@5"
            ]
        },
        {
            "x": 2,
            "y": 4,
            "z": 5,

            "elements": [
                "mekanismgenerators:reactorglass@0"
            ]
        },
        {
            "x": 1,
            "y": 2,
            "z": 7,

            "elements": [
                "mekanismgenerators:reactor@1"
            ]
        },
        {
            "x": 3,
            "y": 2,
            "z": 5,

            "elements": [
                "mekanismgenerators:reactor@1"
            ]
        },
        {
            "x": 3,
            "y": -2,
            "z": 7,

            "elements": [
                "modularmachinery:blockcasing@4",
                "ItemInputStrengthen",
                "ItemOutputStrengthen",
                "EnergyInputStrengthen",
                "EnergyOutputStrengthen",
                "FluidInputStrengthen",
                "FluidOutputStrengthen"
            ]
        },
        {
            "x": 2,
            "y": 4,
            "z": 2,

            "elements": [
                "mekanismgenerators:reactorglass@0"
            ]
        },
        {
            "x": -3,
            "y": -1,
            "z": 4,

            "elements": [
                "mekanismgenerators:reactor@1"
            ]
        },
        {
            "x": -2,
            "y": 2,
            "z": 7,

            "elements": [
                "mekanismgenerators:reactor@1"
            ]
        },
        {
            "x": -2,
            "y": 3,
            "z": 1,

            "elements": [
                "mekanismgenerators:reactorglass@0"
            ]
        },
        {
            "x": -4,
            "y": -2,
            "z": 3,

            "elements": [
                "modularmachinery:blockcasing@4",
                "ItemInputStrengthen",
                "ItemOutputStrengthen",
                "EnergyInputStrengthen",
                "EnergyOutputStrengthen",
                "FluidInputStrengthen",
                "FluidOutputStrengthen"
            ]
        },
        {
            "x": 1,
            "y": 3,
            "z": 7,

            "elements": [
                "mekanismgenerators:reactorglass@0"
            ]
        },
        {
            "x": 0,
            "y": -2,
            "z": 1,

            "elements": [
                "mekanismgenerators:reactor@1"
            ]
        },
        {
            "x": -1,
            "y": -2,
            "z": 4,

            "elements": [
                "mekanismgenerators:reactor@1"
            ]
        },
        {
            "x": -2,
            "y": 0,
            "z": 1,

            "elements": [
                "mekanismgenerators:reactorglass@0"
            ]
        },
        {
            "x": -1,
            "y": -1,
            "z": 8,

            "elements": [
                "mekanismgenerators:reactorglass@0"
            ]
        },
        {
            "x": 0,
            "y": 4,
            "z": 6,

            "elements": [
                "mekanismgenerators:reactorglass@0"
            ]
        },
        {
            "x": -1,
            "y": 3,
            "z": 1,

            "elements": [
                "mekanismgenerators:reactorglass@0"
            ]
        },
        {
            "x": 2,
            "y": -2,
            "z": 5,

            "elements": [
                "mekanismgenerators:reactor@1"
            ]
        },
        {
            "x": -3,
            "y": -2,
            "z": 2,

            "elements": [
                "modularmachinery:blockcasing@4",
                "ItemInputStrengthen",
                "ItemOutputStrengthen",
                "EnergyInputStrengthen",
                "EnergyOutputStrengthen",
                "FluidInputStrengthen",
                "FluidOutputStrengthen"
            ]
        },
        {
            "x": -1,
            "y": 2,
            "z": 1,

            "elements": [
                "mekanismgenerators:reactor@1"
            ]
        },
        {
            "x": -3,
            "y": 1,
            "z": 4,
            "elements": [
                "fluxnetworks:fluxblock@0"
            ]
        },
        {
            "x": 1,
            "y": 2,
            "z": 3,
            "elements": [
                "ic2:fence@0"
            ]
        },
        {
            "x": 1,
            "y": 4,
            "z": 7,

            "elements": [
                "mekanismgenerators:reactorglass@0"
            ]
        },
        {
            "x": 0,
            "y": -1,
            "z": 1,

            "elements": [
                "mekanismgenerators:reactor@1"
            ]
        },
        {
            "x": -3,
            "y": -1,
            "z": 2,

            "elements": [
                "mekanismgenerators:reactorglass@0"
            ]
        },
        {
            "x": -1,
            "y": 4,
            "z": 2,

            "elements": [
                "mekanismgenerators:reactorglass@0"
            ]
        },
        {
            "x": 0,
            "y": 0,
            "z": 8,

            "elements": [
                "mekanismgenerators:reactor@1"
            ]
        },
        {
            "x": 3,
            "y": -2,
            "z": 3,

            "elements": [
                "mekanismgenerators:reactor@1"
            ]
        },
        {
            "x": -2,
            "y": 1,
            "z": 1,

            "elements": [
                "mekanismgenerators:reactorglass@0"
            ]
        },
        {
            "x": -3,
            "y": 2,
            "z": 4,

            "elements": [
                "mekanismgenerators:reactor@1"
            ]
        },
        {
            "x": -3,
            "y": 1,
            "z": 7,

            "elements": [
                "mekanismgenerators:reactorglass@0"
            ]
        },
        {
            "x": 1,
            "y": -2,
            "z": 1,

            "elements": [
                "mekanismgenerators:reactor@1"
            ]
        },
        {
            "x": 1,
            "y": 0,
            "z": 5,

            "elements": [
                "environmentaltech:lightning_rod@0"
            ]
        },
        {
            "x": -1,
            "y": -1,
            "z": 3,

            "elements": [
                "environmentaltech:lightning_rod@0"
            ]
        },
        {
            "x": -3,
            "y": 4,
            "z": 3,

            "elements": [
                "mekanismgenerators:reactorglass@0"
            ]
        },
        {
            "x": 1,
            "y": 2,
            "z": 5,
            "elements": [
                "ic2:fence@0"
            ]
        },
        {
            "x": -2,
            "y": 3,
            "z": 6,

            "elements": [
                "mekanismgenerators:reactorglass@0"
            ]
        },
        {
            "x": -3,
            "y": -1,
            "z": 7,

            "elements": [
                "mekanismgenerators:reactorglass@0"
            ]
        },
        {
            "x": 1,
            "y": -2,
            "z": 8,

            "elements": [
                "modularmachinery:blockcasing@4",
                "ItemInputStrengthen",
                "ItemOutputStrengthen",
                "EnergyInputStrengthen",
                "EnergyOutputStrengthen",
                "FluidInputStrengthen",
                "FluidOutputStrengthen"
            ]
        },
        {
            "x": -3,
            "y": 0,
            "z": 7,

            "elements": [
                "mekanismgenerators:reactorglass@0"
            ]
        },
        {
            "x": -3,
            "y": 2,
            "z": 3,

            "elements": [
                "mekanismgenerators:reactor@1"
            ]
        },
        {
            "x": 0,
            "y": 0,
            "z": 3,
            "elements": [
                "enderio:block_reinforced_obsidian@0"
            ]
        },
        {
            "x": 1,
            "y": 1,
            "z": 5,
            "elements": [
                "enderio:block_reinforced_obsidian@0"
            ]
        },
        {
            "x": 2,
            "y": -2,
            "z": 3,

            "elements": [
                "mekanismgenerators:reactor@1"
            ]
        },
        {
            "x": -3,
            "y": -2,
            "z": 7,

            "elements": [
                "modularmachinery:blockcasing@4",
                "ItemInputStrengthen",
                "ItemOutputStrengthen",
                "EnergyInputStrengthen",
                "EnergyOutputStrengthen",
                "FluidInputStrengthen",
                "FluidOutputStrengthen"
            ]
        },
        {
            "x": 0,
            "y": 1,
            "z": 3,
            "elements": [
                "enderio:block_reinforced_obsidian@0"
            ]
        },
        {
            "x": -2,
            "y": 1,
            "z": 7,

            "elements": [
                "mekanismgenerators:reactorglass@0"
            ]
        },
        {
            "x": -3,
            "y": -2,
            "z": 4,

            "elements": [
                "mekanismgenerators:reactor@1"
            ]
        },
        {
            "x": 1,
            "y": -1,
            "z": 8,

            "elements": [
                "mekanismgenerators:reactorglass@0"
            ]
        },
        {
            "x": -2,
            "y": 4,
            "z": 6,

            "elements": [
                "mekanismgenerators:reactorglass@0"
            ]
        },
        {
            "x": -2,
            "y": -2,
            "z": 1,

            "elements": [
                "modularmachinery:blockcasing@4",
                "ItemInputStrengthen",
                "ItemOutputStrengthen",
                "EnergyInputStrengthen",
                "EnergyOutputStrengthen",
                "FluidInputStrengthen",
                "FluidOutputStrengthen"
            ]
        },
        {
            "x": 0,
            "y": -2,
            "z": 5,

            "elements": [
                "mekanismgenerators:reactor@1"
            ]
        },
        {
            "x": -4,
            "y": -1,
            "z": 3,

            "elements": [
                "mekanismgenerators:reactorglass@0"
            ]
        },
        {
            "x": 1,
            "y": 1,
            "z": 8,

            "elements": [
                "mekanismgenerators:reactorglass@0"
            ]
        },
        {
            "x": -2,
            "y": 0,
            "z": 7,

            "elements": [
                "mekanismgenerators:reactorglass@0"
            ]
        },
        {
            "x": 0,
            "y": 2,
            "z": 3,
            "elements": [
                "enderio:block_reinforced_obsidian@0"
            ]
        },
        {
            "x": -2,
            "y": -1,
            "z": 1,

            "elements": [
                "mekanismgenerators:reactorglass@0"
            ]
        },
        {
            "x": -2,
            "y": -2,
            "z": 6,

            "elements": [
                "mekanismgenerators:reactor@1"
            ]
        },
        {
            "x": 2,
            "y": 4,
            "z": 4,

            "elements": [
                "mekanismgenerators:reactorglass@0"
            ]
        },
        {
            "x": 0,
            "y": -1,
            "z": 5,
            "elements": [
                "appliedenergistics2:smooth_sky_stone_slab@0"
            ]
        },
        {
            "x": -3,
            "y": -2,
            "z": 3,

            "elements": [
                "mekanismgenerators:reactor@1"
            ]
        },
        {
            "x": 0,
            "y": -1,
            "z": 4,
            "elements": [
                "appliedenergistics2:smooth_sky_stone_slab@0"
            ]
        },
        {
            "x": 2,
            "y": 3,
            "z": 1,

            "elements": [
                "mekanismgenerators:reactorglass@0"
            ]
        },
        {
            "x": -3,
            "y": -1,
            "z": 6,

            "elements": [
                "mekanismgenerators:reactorglass@0"
            ]
        },
        {
            "x": -1,
            "y": 1,
            "z": 3,
            "elements": [
                "enderio:block_reinforced_obsidian@0"
            ]
        },
        {
            "x": -3,
            "y": 0,
            "z": 6,

            "elements": [
                "mekanismgenerators:reactorglass@0"
            ]
        },
        {
            "x": -2,
            "y": 4,
            "z": 5,

            "elements": [
                "mekanismgenerators:reactorglass@0"
            ]
        },
        {
            "x": 3,
            "y": -2,
            "z": 5,

            "elements": [
                "mekanismgenerators:reactor@1"
            ]
        },
        {
            "x": 3,
            "y": 0,
            "z": 1,

            "elements": [
                "mekanismgenerators:reactorglass@0"
            ]
        },
        {
            "x": 2,
            "y": 1,
            "z": 4,
            "elements": [
                "minecraft:end_rod@4"
            ]
        },
        {
            "x": -3,
            "y": -2,
            "z": 6,

            "elements": [
                "modularmachinery:blockcasing@4",
                "ItemInputStrengthen",
                "ItemOutputStrengthen",
                "EnergyInputStrengthen",
                "EnergyOutputStrengthen",
                "FluidInputStrengthen",
                "FluidOutputStrengthen"
            ]
        },
        {
            "x": -1,
            "y": 2,
            "z": 3,
            "elements": [
                "ic2:fence@0"
            ]
        },
        {
            "x": 2,
            "y": 2,
            "z": 1,

            "elements": [
                "mekanismgenerators:reactor@1"
            ]
        },
        {
            "x": -1,
            "y": 4,
            "z": 4,

            "elements": [
                "mekanismgenerators:reactorglass@0"
            ]
        },
        {
            "x": 3,
            "y": 1,
            "z": 1,

            "elements": [
                "mekanismgenerators:reactorglass@0"
            ]
        },
        {
            "x": 3,
            "y": -2,
            "z": 4,

            "elements": [
                "mekanismgenerators:reactor@1"
            ]
        },
        {
            "x": -3,
            "y": 1,
            "z": 6,

            "elements": [
                "mekanismgenerators:reactorglass@0"
            ]
        },
        {
            "x": 1,
            "y": 0,
            "z": 4,
            "elements": [
                "enderio:block_reinforced_obsidian@0"
            ]
        },
        {
            "x": -1,
            "y": -2,
            "z": 7,

            "elements": [
                "mekanismgenerators:reactor@1"
            ]
        },
        {
            "x": 0,
            "y": -2,
            "z": 3,

            "elements": [
                "mekanismgenerators:reactor@1"
            ]
        },
        {
            "x": -3,
            "y": 3,
            "z": 3,

            "elements": [
                "mekanismgenerators:reactorglass@0"
            ]
        },
        {
            "x": 4,
            "y": 1,
            "z": 5,

            "elements": [
                "mekanismgenerators:reactorglass@0"
            ]
        },
        {
            "x": 0,
            "y": 2,
            "z": 0,

            "elements": [
                "mekanismgenerators:reactor@1"
            ]
        },
        {
            "x": -1,
            "y": -2,
            "z": 0,

            "elements": [
                "modularmachinery:blockcasing@4",
                "ItemInputStrengthen",
                "ItemOutputStrengthen",
                "EnergyInputStrengthen",
                "EnergyOutputStrengthen",
                "FluidInputStrengthen",
                "FluidOutputStrengthen"
            ]
        },
        {
            "x": 0,
            "y": 1,
            "z": 7,
            "elements": [
                "fluxnetworks:fluxblock@0"
            ]
        },
        {
            "x": 1,
            "y": -1,
            "z": 4,
            "elements": [
                "appliedenergistics2:smooth_sky_stone_slab@0"
            ]
        },
        {
            "x": 4,
            "y": 0,
            "z": 5,

            "elements": [
                "mekanismgenerators:reactorglass@0"
            ]
        },
        {
            "x": 1,
            "y": 4,
            "z": 5,

            "elements": [
                "mekanismgenerators:reactorglass@0"
            ]
        },
        {
            "x": 2,
            "y": 0,
            "z": 1,

            "elements": [
                "mekanismgenerators:reactorglass@0"
            ]
        },
        {
            "x": 1,
            "y": 1,
            "z": 4,
            "elements": [
                "enderio:block_reinforced_obsidian@0"
            ]
        },
        {
            "x": 0,
            "y": 1,
            "z": 0,

            "elements": [
                "mekanismgenerators:reactor@1"
            ]
        },
        {
            "x": 3,
            "y": 2,
            "z": 1,

            "elements": [
                "mekanismgenerators:reactor@1"
            ]
        },
        {
            "x": 1,
            "y": 2,
            "z": 4,
            "elements": [
                "enderio:block_reinforced_obsidian@0"
            ]
        },
        {
            "x": -1,
            "y": -1,
            "z": 0,

            "elements": [
                "mekanismgenerators:reactorglass@0"
            ]
        },
        {
            "x": 0,
            "y": 0,
            "z": 7,
            "elements": [
                "ic2:fence@0"
            ]
        },
        {
            "x": -1,
            "y": 0,
            "z": 3,

            "elements": [
                "environmentaltech:lightning_rod@0"
            ]
        },
        {
            "x": 0,
            "y": 4,
            "z": 1,

            "elements": [
                "mekanismgenerators:reactorglass@0"
            ]
        },
        {
            "x": -3,
            "y": 2,
            "z": 7,

            "elements": [
                "mekanismgenerators:reactor@1"
            ]
        },
        {
            "x": -1,
            "y": -2,
            "z": 3,

            "elements": [
                "mekanismgenerators:reactor@1"
            ]
        },
        {
            "x": 1,
            "y": 3,
            "z": 5,
            "elements": [
                "appliedenergistics2:smooth_sky_stone_slab@0"
            ]
        },
        {
            "x": 2,
            "y": 1,
            "z": 1,

            "elements": [
                "mekanismgenerators:reactorglass@0"
            ]
        }
    ]}