{
    "registryname": "YMG_Jumping_Rift",
    "localizedname": "§b§lYMG§r§e§l—#942DCE§l折跃裂隙 §r§e",
    "failure-action": "still",
    "requires-blueprint": false,
    "color": "BF68F0",
    "parts": [
        {
            "x": 1,
            "y": -5,
            "z": 7,
            "elements": [
                "minecraft:end_rod@0"
            ]
        },
        {
            "x": 0,
            "y": 7,
            "z": 8,
            "elements": [
                "minecraft:stained_glass@10"
            ]
        },
        {
            "x": -4,
            "y": 2,
            "z": 7,
            "elements": [
                "minecraft:purpur_stairs@1"
            ]
        },
        {
            "x": 5,
            "y": 0,
            "z": 8,
            "elements": [
                "minecraft:purpur_block@0"
            ]
        },
        {
            "x": 5,
            "y": 0,
            "z": 9,
            "elements": [
                "minecraft:purpur_block@0"
            ]
        },
        {
            "x": -4,
            "y": 2,
            "z": 8,
            "elements": [
                "minecraft:stained_glass@0"
            ]
        },
        {
            "x": -4,
            "y": 2,
            "z": 5,
            "elements": [
                "minecraft:end_rod@1"
            ]
        },
        {
            "x": 5,
            "y": 0,
            "z": 6,
            "elements": [
                "minecraft:purpur_block@0"
            ]
        },
        {
            "x": 5,
            "y": 0,
            "z": 7,
            "elements": [
                "minecraft:purpur_block@0"
            ]
        },
        {
            "x": -4,
            "y": 2,
            "z": 6,
            "elements": [
                "minecraft:stained_glass@0"
            ]
        },
        {
            "x": 5,
            "y": 0,
            "z": 5,
            "elements": [
                "minecraft:purpur_block@0"
            ]
        },
        {
            "x": -2,
            "y": -9,
            "z": 9,

            "elements": [
                "environmentaltech:lightning_rod@0"
            ]
        },
        {
            "x": -5,
            "y": 1,
            "z": 6,
            "elements": [
                "minecraft:stained_glass@10"
            ]
        },
        {
            "x": -1,
            "y": 6,
            "z": 3,
            "elements": [
                "minecraft:stained_glass@10"
            ]
        },
        {
            "x": -5,
            "y": 1,
            "z": 7,

            "elements": [
                "modularmachinery:blockcasing@4"
            ]
        },
        {
            "x": -2,
            "y": -9,
            "z": 5,

            "elements": [
                "environmentaltech:lightning_rod@0"
            ]
        },
        {
            "x": -5,
            "y": 1,
            "z": 8,
            "elements": [
                "minecraft:stained_glass@10"
            ]
        },
        {
            "x": -3,
            "y": 3,
            "z": 8,
            "elements": [
                "minecraft:stained_glass@0"
            ]
        },
        {
            "x": -3,
            "y": 3,
            "z": 9,

            "elements": [
                "modularmachinery:blockcasing@4"
            ]
        },
        {
            "x": 1,
            "y": 8,
            "z": 7,
            "elements": [
                "minecraft:end_rod@1"
            ]
        },
        {
            "x": -3,
            "y": 3,
            "z": 10,
            "elements": [
                "minecraft:stained_glass@0"
            ]
        },
        {
            "x": -1,
            "y": 6,
            "z": 7,
            "elements": [
                "minecraft:stained_glass@10"
            ]
        },
        {
            "x": 0,
            "y": 7,
            "z": 6,
            "elements": [
                "minecraft:stained_glass@10"
            ]
        },
        {
            "x": -4,
            "y": 2,
            "z": 9,
            "elements": [
                "minecraft:end_rod@1"
            ]
        },
        {
            "x": 0,
            "y": 7,
            "z": 7,
            "elements": [
                "minecraft:stained_glass@0"
            ]
        },
        {
            "x": 3,
            "y": -3,
            "z": 10,
            "elements": [
                "minecraft:stained_glass@0"
            ]
        },
        {
            "x": -6,
            "y": -1,
            "z": 8,
            "elements": [
                "minecraft:stained_glass@0"
            ]
        },
        {
            "x": 3,
            "y": -2,
            "z": 4,
            "elements": [
                "minecraft:stained_glass@0"
            ]
        },
        {
            "x": -6,
            "y": -1,
            "z": 7,

            "elements": [
                "modularmachinery:blockcasing@4"
            ]
        },
        {
            "x": -6,
            "y": -1,
            "z": 6,
            "elements": [
                "minecraft:stained_glass@0"
            ]
        },
        {
            "x": -2,
            "y": 4,
            "z": 5,

            "elements": [
                "modularmachinery:blockcasing@4"
            ]
        },
        {
            "x": 2,
            "y": 9,
            "z": 5,

            "elements": [
                "modularmachinery:blockcasing@4"
            ]
        },
        {
            "x": -1,
            "y": 6,
            "z": 11,
            "elements": [
                "minecraft:stained_glass@10"
            ]
        },
        {
            "x": -2,
            "y": 4,
            "z": 10,
            "elements": [
                "minecraft:quartz_stairs@3"
            ]
        },
        {
            "x": -2,
            "y": 4,
            "z": 9,

            "elements": [
                "modularmachinery:blockcasing@4"
            ]
        },
        {
            "x": 2,
            "y": 9,
            "z": 9,

            "elements": [
                "modularmachinery:blockcasing@4"
            ]
        },
        {
            "x": 3,
            "y": -2,
            "z": 10,
            "elements": [
                "minecraft:stained_glass@0"
            ]
        },
        {
            "x": -2,
            "y": 4,
            "z": 4,
            "elements": [
                "minecraft:quartz_stairs@2"
            ]
        },
        {
            "x": -7,
            "y": -1,
            "z": 8,
            "elements": [
                "minecraft:end_rod@0"
            ]
        },
        {
            "x": 2,
            "y": -3,
            "z": 9,

            "elements": [
                "modularmachinery:blockcasing@4"
            ]
        },
        {
            "x": -7,
            "y": -1,
            "z": 7,
            "elements": [
                "minecraft:stone_slab@15"
            ]
        },
        {
            "x": 2,
            "y": -3,
            "z": 11,
            "elements": [
                "minecraft:stained_glass@10"
            ]
        },
        {
            "x": 2,
            "y": -3,
            "z": 5,

            "elements": [
                "modularmachinery:blockcasing@4"
            ]
        },
        {
            "x": -7,
            "y": -1,
            "z": 6,
            "elements": [
                "minecraft:end_rod@0"
            ]
        },
        {
            "x": 2,
            "y": -3,
            "z": 3,
            "elements": [
                "minecraft:stained_glass@10"
            ]
        },
        {
            "x": 5,
            "y": -1,
            "z": 5,
            "elements": [
                "minecraft:purpur_slab@8"
            ]
        },
        {
            "x": 5,
            "y": -1,
            "z": 6,
            "elements": [
                "minecraft:stained_glass@0"
            ]
        },
        {
            "x": 1,
            "y": -4,
            "z": 7,
            "elements": [
                "minecraft:stained_glass@10"
            ]
        },
        {
            "x": 5,
            "y": -1,
            "z": 9,
            "elements": [
                "minecraft:purpur_slab@8"
            ]
        },
        {
            "x": 5,
            "y": -1,
            "z": 7,
            "elements": [
                "minecraft:purpur_stairs@4"
            ]
        },
        {
            "x": 5,
            "y": -1,
            "z": 8,
            "elements": [
                "minecraft:stained_glass@0"
            ]
        },
        {
            "x": 4,
            "y": -2,
            "z": 9,
            "elements": [
                "minecraft:stained_glass@10"
            ]
        },
        {
            "x": 4,
            "y": -2,
            "z": 5,
            "elements": [
                "minecraft:stained_glass@10"
            ]
        },
        {
            "x": 4,
            "y": -2,
            "z": 6,
            "elements": [
                "minecraft:stained_glass@0"
            ]
        },
        {
            "x": 4,
            "y": -2,
            "z": 8,
            "elements": [
                "minecraft:stained_glass@0"
            ]
        },
        {
            "x": 1,
            "y": 7,
            "z": 7,
            "elements": [
                "minecraft:stained_glass@10"
            ]
        },
        {
            "x": 0,
            "y": 19,
            "z": 7,
            "elements": [
                "minecraft:stained_glass@0"
            ]
        },
        {
            "x": 1,
            "y": 7,
            "z": 11,
            "elements": [
                "minecraft:end_rod@1"
            ]
        },
        {
            "x": -2,
            "y": 5,
            "z": 9,

            "elements": [
                "modularmachinery:blockcasing@4"
            ]
        },
        {
            "x": -3,
            "y": 3,
            "z": 4,
            "elements": [
                "minecraft:stained_glass@0"
            ]
        },
        {
            "x": -3,
            "y": 3,
            "z": 5,

            "elements": [
                "modularmachinery:blockcasing@4"
            ]
        },
        {
            "x": -3,
            "y": 3,
            "z": 6,
            "elements": [
                "minecraft:stained_glass@0"
            ]
        },
        {
            "x": 6,
            "y": 1,
            "z": 7,

            "elements": [
                "modularmachinery:blockcasing@4"
            ]
        },
        {
            "x": -2,
            "y": 5,
            "z": 5,

            "elements": [
                "modularmachinery:blockcasing@4"
            ]
        },
        {
            "x": 1,
            "y": 7,
            "z": 3,
            "elements": [
                "minecraft:end_rod@1"
            ]
        },
        {
            "x": 3,
            "y": -4,
            "z": 10,
            "elements": [
                "minecraft:stained_glass@0"
            ]
        },
        {
            "x": 0,
            "y": 8,
            "z": 7,
            "elements": [
                "minecraft:stained_glass@0"
            ]
        },
        {
            "x": 0,
            "y": 8,
            "z": 8,
            "elements": [
                "minecraft:end_rod@1"
            ]
        },
        {
            "x": -5,
            "y": 0,
            "z": 9,
            "elements": [
                "minecraft:purpur_block@0"
            ]
        },
        {
            "x": -5,
            "y": 0,
            "z": 8,
            "elements": [
                "minecraft:purpur_block@0"
            ]
        },
        {
            "x": 0,
            "y": 8,
            "z": 6,
            "elements": [
                "minecraft:end_rod@1"
            ]
        },
        {
            "x": -5,
            "y": 0,
            "z": 5,
            "elements": [
                "minecraft:purpur_block@0"
            ]
        },
        {
            "x": 0,
            "y": -6,
            "z": 7,
            "elements": [
                "minecraft:stained_glass@0"
            ]
        },
        {
            "x": -5,
            "y": 0,
            "z": 7,
            "elements": [
                "minecraft:purpur_block@0"
            ]
        },
        {
            "x": -5,
            "y": 0,
            "z": 6,
            "elements": [
                "minecraft:purpur_block@0"
            ]
        },
        {
            "x": 3,
            "y": -4,
            "z": 4,
            "elements": [
                "minecraft:stained_glass@0"
            ]
        },
        {
            "x": 0,
            "y": -8,
            "z": 7,
            "elements": [
                "minecraft:stained_glass@0"
            ]
        },
        {
            "x": 3,
            "y": -1,
            "z": 11,
            "elements": [
                "minecraft:end_rod@0"
            ]
        },
        {
            "x": 3,
            "y": -1,
            "z": 9,
            "elements": [
                "minecraft:quartz_stairs@5"
            ]
        },
        {
            "x": -2,
            "y": -7,
            "z": 5,

            "elements": [
                "modularmachinery:blockcasing@4"
            ]
        },
        {
            "x": 3,
            "y": -1,
            "z": 10,
            "elements": [
                "minecraft:stained_glass@0"
            ]
        },
        {
            "x": 3,
            "y": -1,
            "z": 7,
            "elements": [
                "minecraft:purpur_slab@8"
            ]
        },
        {
            "x": 3,
            "y": -1,
            "z": 8,
            "elements": [
                "minecraft:purpur_slab@8"
            ]
        },
        {
            "x": 3,
            "y": -1,
            "z": 5,
            "elements": [
                "minecraft:quartz_stairs@5"
            ]
        },
        {
            "x": 3,
            "y": -1,
            "z": 6,
            "elements": [
                "minecraft:purpur_slab@8"
            ]
        },
        {
            "x": 3,
            "y": -1,
            "z": 3,
            "elements": [
                "minecraft:end_rod@0"
            ]
        },
        {
            "x": 2,
            "y": 11,
            "z": 5,

            "elements": [
                "environmentaltech:lightning_rod@0"
            ]
        },
        {
            "x": -2,
            "y": 3,
            "z": 10,

            "elements": [
                "modularmachinery:blockcasing@4"
            ]
        },
        {
            "x": 3,
            "y": -1,
            "z": 4,
            "elements": [
                "minecraft:stained_glass@0"
            ]
        },
        {
            "x": 2,
            "y": 8,
            "z": 9,

            "elements": [
                "modularmachinery:blockcasing@4"
            ]
        },
        {
            "x": -2,
            "y": 6,
            "z": 5,

            "elements": [
                "modularmachinery:blockcasing@4"
            ]
        },
        {
            "x": 2,
            "y": 11,
            "z": 9,

            "elements": [
                "environmentaltech:lightning_rod@0"
            ]
        },
        {
            "x": -2,
            "y": 3,
            "z": 9,

            "elements": [
                "modularmachinery:blockcasing@4"
            ]
        },
        {
            "x": -2,
            "y": 6,
            "z": 9,

            "elements": [
                "modularmachinery:blockcasing@4"
            ]
        },
        {
            "x": 2,
            "y": 8,
            "z": 5,

            "elements": [
                "modularmachinery:blockcasing@4"
            ]
        },
        {
            "x": -5,
            "y": -1,
            "z": 6,
            "elements": [
                "minecraft:stained_glass@0"
            ]
        },
        {
            "x": -5,
            "y": -1,
            "z": 5,
            "elements": [
                "minecraft:purpur_slab@8"
            ]
        },
        {
            "x": -4,
            "y": 4,
            "z": 6,
            "elements": [
                "minecraft:stained_glass@10"
            ]
        },
        {
            "x": -5,
            "y": -1,
            "z": 8,
            "elements": [
                "minecraft:stained_glass@0"
            ]
        },
        {
            "x": -2,
            "y": 3,
            "z": 5,

            "elements": [
                "modularmachinery:blockcasing@4"
            ]
        },
        {
            "x": -5,
            "y": -1,
            "z": 7,
            "elements": [
                "minecraft:purpur_stairs@5"
            ]
        },
        {
            "x": -2,
            "y": 3,
            "z": 4,

            "elements": [
                "modularmachinery:blockcasing@4"
            ]
        },
        {
            "x": -5,
            "y": -1,
            "z": 9,
            "elements": [
                "minecraft:purpur_slab@8"
            ]
        },
        {
            "x": 4,
            "y": 0,
            "z": 7,
            "elements": [
                "minecraft:purpur_block@0"
            ]
        },
        {
            "x": 0,
            "y": -5,
            "z": 6,
            "elements": [
                "minecraft:end_rod@0"
            ]
        },
        {
            "x": -5,
            "y": 2,
            "z": 6,
            "elements": [
                "minecraft:stained_glass@10"
            ]
        },
        {
            "x": -2,
            "y": -10,
            "z": 5,

            "elements": [
                "environmentaltech:lightning_rod@0"
            ]
        },
        {
            "x": 0,
            "y": -5,
            "z": 7,
            "elements": [
                "minecraft:stained_glass@0"
            ]
        },
        {
            "x": -5,
            "y": 2,
            "z": 7,

            "elements": [
                "EnergyInputStrengthen"
            ]
        },
        {
            "x": 4,
            "y": 0,
            "z": 8,
            "elements": [
                "minecraft:stained_glass@0"
            ]
        },
        {
            "x": 4,
            "y": 0,
            "z": 9,
            "elements": [
                "minecraft:stained_glass@0"
            ]
        },
        {
            "x": -5,
            "y": 2,
            "z": 8,
            "elements": [
                "minecraft:stained_glass@10"
            ]
        },
        {
            "x": 4,
            "y": 0,
            "z": 10,
            "elements": [
                "minecraft:purpur_slab@0"
            ]
        },
        {
            "x": 4,
            "y": 0,
            "z": 3,
            "elements": [
                "minecraft:purpur_block@0"
            ]
        },
        {
            "x": -2,
            "y": -10,
            "z": 9,

            "elements": [
                "environmentaltech:lightning_rod@0"
            ]
        },
        {
            "x": 4,
            "y": 0,
            "z": 4,
            "elements": [
                "minecraft:purpur_slab@0"
            ]
        },
        {
            "x": 4,
            "y": 0,
            "z": 5,
            "elements": [
                "minecraft:stained_glass@0"
            ]
        },
        {
            "x": 0,
            "y": -5,
            "z": 8,
            "elements": [
                "minecraft:end_rod@0"
            ]
        },
        {
            "x": 4,
            "y": 0,
            "z": 6,
            "elements": [
                "minecraft:stained_glass@0"
            ]
        },
        {
            "x": -4,
            "y": 4,
            "z": 8,
            "elements": [
                "minecraft:stained_glass@10"
            ]
        },
        {
            "x": 4,
            "y": 1,
            "z": 3,
            "elements": [
                "minecraft:end_rod@1"
            ]
        },
        {
            "x": 4,
            "y": 1,
            "z": 5,
            "elements": [
                "minecraft:quartz_stairs@5"
            ]
        },
        {
            "x": 4,
            "y": 0,
            "z": 11,
            "elements": [
                "minecraft:purpur_block@0"
            ]
        },
        {
            "x": -3,
            "y": 1,
            "z": 9,

            "elements": [
                "modularmachinery:blockcasing@4"
            ]
        },
        {
            "x": 4,
            "y": 1,
            "z": 6,
            "elements": [
                "minecraft:stained_glass@0"
            ]
        },
        {
            "x": 4,
            "y": 1,
            "z": 7,
            "elements": [
                "minecraft:purpur_block@0"
            ]
        },
        {
            "x": 1,
            "y": 6,
            "z": 11,
            "elements": [
                "minecraft:stained_glass@10"
            ]
        },
        {
            "x": -3,
            "y": 1,
            "z": 10,
            "elements": [
                "minecraft:stained_glass@0"
            ]
        },
        {
            "x": 4,
            "y": 1,
            "z": 8,
            "elements": [
                "minecraft:stained_glass@0"
            ]
        },
        {
            "x": 4,
            "y": 1,
            "z": 9,
            "elements": [
                "minecraft:quartz_stairs@5"
            ]
        },
        {
            "x": -3,
            "y": 1,
            "z": 5,

            "elements": [
                "modularmachinery:blockcasing@4"
            ]
        },
        {
            "x": -4,
            "y": 1,
            "z": 5,
            "elements": [
                "minecraft:quartz_stairs@4"
            ]
        },
        {
            "x": -3,
            "y": 1,
            "z": 6,
            "elements": [
                "environmentaltech:structure_frame_1@0"
            ]
        },
        {
            "x": 1,
            "y": 6,
            "z": 7,
            "elements": [
                "minecraft:stained_glass@10"
            ]
        },
        {
            "x": -3,
            "y": 1,
            "z": 7,
            "elements": [
                "environmentaltech:structure_frame_1@0"
            ]
        },
        {
            "x": -4,
            "y": 1,
            "z": 3,
            "elements": [
                "minecraft:end_rod@1"
            ]
        },
        {
            "x": -3,
            "y": 1,
            "z": 8,
            "elements": [
                "environmentaltech:structure_frame_1@0"
            ]
        },
        {
            "x": -4,
            "y": 1,
            "z": 8,
            "elements": [
                "minecraft:stained_glass@0"
            ]
        },
        {
            "x": 1,
            "y": 6,
            "z": 3,
            "elements": [
                "minecraft:stained_glass@10"
            ]
        },
        {
            "x": -4,
            "y": 1,
            "z": 9,
            "elements": [
                "minecraft:quartz_stairs@4"
            ]
        },
        {
            "x": -4,
            "y": 1,
            "z": 6,
            "elements": [
                "minecraft:stained_glass@0"
            ]
        },
        {
            "x": -2,
            "y": -7,
            "z": 9,

            "elements": [
                "modularmachinery:blockcasing@4"
            ]
        },
        {
            "x": -3,
            "y": 1,
            "z": 4,
            "elements": [
                "minecraft:stained_glass@0"
            ]
        },
        {
            "x": -4,
            "y": 1,
            "z": 7,
            "elements": [
                "minecraft:purpur_block@0"
            ]
        },
        {
            "x": 4,
            "y": -3,
            "z": 5,
            "elements": [
                "minecraft:stained_glass@10"
            ]
        },
        {
            "x": 4,
            "y": -3,
            "z": 9,
            "elements": [
                "minecraft:stained_glass@10"
            ]
        },
        {
            "x": -4,
            "y": 1,
            "z": 11,
            "elements": [
                "minecraft:end_rod@1"
            ]
        },
        {
            "x": -6,
            "y": -3,
            "z": 7,
            "elements": [
                "modularmachinery:blockcasing@4",
                "ItemInputStrengthen",
                "ItemOutputStrengthen",
                "FluidInputStrengthen",
                "FluidOutputStrengthen"
            ]
        },
        {
            "x": 2,
            "y": 12,
            "z": 5,
            "elements": [
                "minecraft:end_rod@1"
            ]
        },
        {
            "x": -3,
            "y": 4,
            "z": 9,
            "elements": [
                "minecraft:quartz_stairs@0"
            ]
        },
        {
            "x": -3,
            "y": 4,
            "z": 8,
            "elements": [
                "minecraft:purpur_slab@0"
            ]
        },
        {
            "x": -3,
            "y": 4,
            "z": 6,
            "elements": [
                "minecraft:purpur_slab@0"
            ]
        },
        {
            "x": -3,
            "y": 4,
            "z": 5,
            "elements": [
                "minecraft:quartz_stairs@0"
            ]
        },
        {
            "x": 2,
            "y": -1,
            "z": 3,
            "elements": [
                "minecraft:stained_glass@10"
            ]
        },
        {
            "x": 2,
            "y": -1,
            "z": 2,
            "elements": [
                "minecraft:purpur_slab@8"
            ]
        },
        {
            "x": 2,
            "y": -1,
            "z": 5,

            "elements": [
                "modularmachinery:blockcasing@4"
            ]
        },
        {
            "x": 2,
            "y": -1,
            "z": 4,
            "elements": [
                "minecraft:quartz_stairs@6"
            ]
        },
        {
            "x": 6,
            "y": -1,
            "z": 8,
            "elements": [
                "minecraft:stained_glass@0"
            ]
        },
        {
            "x": 6,
            "y": -1,
            "z": 7,

            "elements": [
                "modularmachinery:blockcasing@4"
            ]
        },
        {
            "x": 6,
            "y": -1,
            "z": 6,
            "elements": [
                "minecraft:stained_glass@0"
            ]
        },
        {
            "x": 2,
            "y": -1,
            "z": 11,
            "elements": [
                "minecraft:stained_glass@10"
            ]
        },
        {
            "x": 2,
            "y": -1,
            "z": 10,
            "elements": [
                "minecraft:quartz_stairs@7"
            ]
        },
        {
            "x": 2,
            "y": -1,
            "z": 12,
            "elements": [
                "minecraft:purpur_slab@8"
            ]
        },
        {
            "x": 2,
            "y": -1,
            "z": 9,

            "elements": [
                "modularmachinery:blockcasing@4"
            ]
        },
        {
            "x": -6,
            "y": 0,
            "z": 8,
            "elements": [
                "minecraft:purpur_slab@0"
            ]
        },
        {
            "x": 0,
            "y": 4,
            "z": 8,
            "elements": [
                "minecraft:stained_glass@10"
            ]
        },
        {
            "x": 0,
            "y": 4,
            "z": 7,
            "elements": [
                "minecraft:stained_glass@0"
            ]
        },
        {
            "x": -6,
            "y": 0,
            "z": 7,

            "elements": [
                "modularmachinery:blockcasing@4"
            ]
        },
        {
            "x": -6,
            "y": 0,
            "z": 6,
            "elements": [
                "minecraft:purpur_slab@0"
            ]
        },
        {
            "x": 2,
            "y": -4,
            "z": 3,
            "elements": [
                "minecraft:stained_glass@10"
            ]
        },
        {
            "x": -1,
            "y": 8,
            "z": 7,
            "elements": [
                "minecraft:end_rod@1"
            ]
        },
        {
            "x": 2,
            "y": -4,
            "z": 5,

            "elements": [
                "modularmachinery:blockcasing@4"
            ]
        },
        {
            "x": 0,
            "y": 4,
            "z": 6,
            "elements": [
                "minecraft:stained_glass@10"
            ]
        },
        {
            "x": 2,
            "y": -4,
            "z": 9,

            "elements": [
                "modularmachinery:blockcasing@4"
            ]
        },
        {
            "x": 2,
            "y": -4,
            "z": 11,
            "elements": [
                "minecraft:stained_glass@10"
            ]
        },
        {
            "x": 7,
            "y": 1,
            "z": 7,
            "elements": [
                "minecraft:quartz_stairs@1"
            ]
        },
        {
            "x": -1,
            "y": 5,
            "z": 11,
            "elements": [
                "minecraft:stained_glass@10"
            ]
        },
        {
            "x": -1,
            "y": 5,
            "z": 8,
            "elements": [
                "minecraft:stained_glass_pane@10"
            ]
        },
        {
            "x": 2,
            "y": -7,
            "z": 9,

            "elements": [
                "modularmachinery:blockcasing@4"
            ]
        },
        {
            "x": -1,
            "y": 5,
            "z": 7,
            "elements": [
                "minecraft:stained_glass@10"
            ]
        },
        {
            "x": -1,
            "y": 5,
            "z": 6,
            "elements": [
                "minecraft:stained_glass_pane@10"
            ]
        },
        {
            "x": 1,
            "y": -3,
            "z": 7,
            "elements": [
                "minecraft:stained_glass@10"
            ]
        },
        {
            "x": -7,
            "y": 1,
            "z": 7,
            "elements": [
                "minecraft:quartz_stairs@0"
            ]
        },
        {
            "x": -1,
            "y": 5,
            "z": 3,
            "elements": [
                "minecraft:stained_glass@10"
            ]
        },
        {
            "x": 2,
            "y": -7,
            "z": 5,

            "elements": [
                "modularmachinery:blockcasing@4"
            ]
        },
        {
            "x": -3,
            "y": 0,
            "z": 3,
            "elements": [
                "minecraft:purpur_slab@0"
            ]
        },
        {
            "x": -3,
            "y": 0,
            "z": 4,
            "elements": [
                "contenttweaker:mysteriousicecasing@0"
            ]
        },
        {
            "x": -3,
            "y": 0,
            "z": 5,

            "elements": [
                "modularmachinery:blockcasing@4"
            ]
        },
        {
            "x": -3,
            "y": 0,
            "z": 6,
            "elements": [
                "environmentaltech:structure_frame_1@0"
            ]
        },
        {
            "x": 4,
            "y": 2,
            "z": 9,
            "elements": [
                "minecraft:end_rod@1"
            ]
        },
        {
            "x": -3,
            "y": 0,
            "z": 7,
            "elements": [
                "environmentaltech:structure_frame_1@0"
            ]
        },
        {
            "x": -3,
            "y": 0,
            "z": 8,
            "elements": [
                "environmentaltech:structure_frame_1@0"
            ]
        },
        {
            "x": -3,
            "y": 0,
            "z": 9,

            "elements": [
                "modularmachinery:blockcasing@4"
            ]
        },
        {
            "x": 4,
            "y": 2,
            "z": 5,
            "elements": [
                "minecraft:end_rod@1"
            ]
        },
        {
            "x": -3,
            "y": 0,
            "z": 10,
            "elements": [
                "contenttweaker:mysteriousicecasing@0"
            ]
        },
        {
            "x": -3,
            "y": 0,
            "z": 11,
            "elements": [
                "minecraft:purpur_slab@0"
            ]
        },
        {
            "x": 4,
            "y": 2,
            "z": 6,
            "elements": [
                "minecraft:stained_glass@0"
            ]
        },
        {
            "x": 4,
            "y": 2,
            "z": 7,
            "elements": [
                "minecraft:purpur_stairs@0"
            ]
        },
        {
            "x": 4,
            "y": 2,
            "z": 8,
            "elements": [
                "minecraft:stained_glass@0"
            ]
        },
        {
            "x": 0,
            "y": 17,
            "z": 7,
            "elements": [
                "minecraft:stained_glass@0"
            ]
        },
        {
            "x": -2,
            "y": 8,
            "z": 9,

            "elements": [
                "modularmachinery:blockcasing@4"
            ]
        },
        {
            "x": -2,
            "y": 1,
            "z": 7,
            "elements": [
                "environmentaltech:structure_frame_1@0"
            ]
        },
        {
            "x": -2,
            "y": 1,
            "z": 4,

            "elements": [
                "modularmachinery:blockcasing@4"
            ]
        },
        {
            "x": -2,
            "y": 1,
            "z": 5,

            "elements": [
                "modularmachinery:blockcasing@4"
            ]
        },
        {
            "x": -2,
            "y": 1,
            "z": 3,
            "elements": [
                "minecraft:quartz_stairs@6"
            ]
        },
        {
            "x": -2,
            "y": 1,
            "z": 10,

            "elements": [
                "modularmachinery:blockcasing@4"
            ]
        },
        {
            "x": -2,
            "y": 8,
            "z": 5,

            "elements": [
                "modularmachinery:blockcasing@4"
            ]
        },
        {
            "x": -2,
            "y": 1,
            "z": 11,
            "elements": [
                "minecraft:quartz_stairs@7"
            ]
        },
        {
            "x": -2,
            "y": 1,
            "z": 9,

            "elements": [
                "modularmachinery:blockcasing@4"
            ]
        },
        {
            "x": -1,
            "y": 3,
            "z": 4,
            "elements": [
                "minecraft:stained_glass@0"
            ]
        },
        {
            "x": -1,
            "y": 3,
            "z": 3,
            "elements": [
                "minecraft:stained_glass@10"
            ]
        },
        {
            "x": 5,
            "y": 3,
            "z": 7,
            "elements": [
                "minecraft:quartz_stairs@1"
            ]
        },
        {
            "x": 3,
            "y": 1,
            "z": 9,

            "elements": [
                "modularmachinery:blockcasing@4"
            ]
        },
        {
            "x": 3,
            "y": 1,
            "z": 10,
            "elements": [
                "minecraft:stained_glass@0"
            ]
        },
        {
            "x": -1,
            "y": 3,
            "z": 11,
            "elements": [
                "minecraft:stained_glass@10"
            ]
        },
        {
            "x": 3,
            "y": 1,
            "z": 7,
            "elements": [
                "environmentaltech:structure_frame_1@0"
            ]
        },
        {
            "x": -1,
            "y": 3,
            "z": 10,
            "elements": [
                "minecraft:stained_glass@0"
            ]
        },
        {
            "x": 3,
            "y": 1,
            "z": 8,
            "elements": [
                "environmentaltech:structure_frame_1@0"
            ]
        },
        {
            "x": -4,
            "y": -2,
            "z": 9,
            "elements": [
                "minecraft:stained_glass@10"
            ]
        },
        {
            "x": 3,
            "y": 1,
            "z": 5,

            "elements": [
                "modularmachinery:blockcasing@4"
            ]
        },
        {
            "x": -4,
            "y": -2,
            "z": 8,
            "elements": [
                "minecraft:stained_glass@0"
            ]
        },
        {
            "x": -1,
            "y": 3,
            "z": 8,
            "elements": [
                "minecraft:stained_glass_pane@10"
            ]
        },
        {
            "x": 3,
            "y": 1,
            "z": 6,
            "elements": [
                "environmentaltech:structure_frame_1@0"
            ]
        },
        {
            "x": -1,
            "y": 3,
            "z": 7,
            "elements": [
                "minecraft:stained_glass@10"
            ]
        },
        {
            "x": -4,
            "y": -2,
            "z": 6,
            "elements": [
                "minecraft:stained_glass@0"
            ]
        },
        {
            "x": -1,
            "y": 3,
            "z": 6,
            "elements": [
                "minecraft:stained_glass_pane@10"
            ]
        },
        {
            "x": 3,
            "y": 1,
            "z": 4,
            "elements": [
                "minecraft:stained_glass@0"
            ]
        },
        {
            "x": -1,
            "y": -4,
            "z": 7,
            "elements": [
                "minecraft:stained_glass@10"
            ]
        },
        {
            "x": -4,
            "y": -2,
            "z": 5,
            "elements": [
                "minecraft:stained_glass@10"
            ]
        },
        {
            "x": -2,
            "y": 2,
            "z": 7,
            "elements": [
                "minecraft:purpur_stairs@0"
            ]
        },
        {
            "x": -2,
            "y": 2,
            "z": 10,

            "elements": [
                "modularmachinery:blockcasing@4"
            ]
        },
        {
            "x": -2,
            "y": 7,
            "z": 9,

            "elements": [
                "modularmachinery:blockcasing@4"
            ]
        },
        {
            "x": -2,
            "y": 2,
            "z": 9,

            "elements": [
                "modularmachinery:blockcasing@4"
            ]
        },
        {
            "x": -2,
            "y": 2,
            "z": 11,
            "elements": [
                "minecraft:end_rod@1"
            ]
        },
        {
            "x": -2,
            "y": 7,
            "z": 5,

            "elements": [
                "modularmachinery:blockcasing@4"
            ]
        },
        {
            "x": 4,
            "y": 3,
            "z": 6,
            "elements": [
                "minecraft:stained_glass@10"
            ]
        },
        {
            "x": 0,
            "y": 11,
            "z": 7,
            "elements": [
                "minecraft:stained_glass@0"
            ]
        },
        {
            "x": 4,
            "y": 1,
            "z": 11,
            "elements": [
                "minecraft:end_rod@1"
            ]
        },
        {
            "x": -2,
            "y": -6,
            "z": 5,

            "elements": [
                "modularmachinery:blockcasing@4"
            ]
        },
        {
            "x": -2,
            "y": -6,
            "z": 3,
            "elements": [
                "minecraft:stained_glass@10"
            ]
        },
        {
            "x": 4,
            "y": 3,
            "z": 8,
            "elements": [
                "minecraft:stained_glass@10"
            ]
        },
        {
            "x": -2,
            "y": -6,
            "z": 9,

            "elements": [
                "modularmachinery:blockcasing@4"
            ]
        },
        {
            "x": 2,
            "y": -8,
            "z": 5,

            "elements": [
                "modularmachinery:blockcasing@4"
            ]
        },
        {
            "x": 2,
            "y": -8,
            "z": 9,

            "elements": [
                "modularmachinery:blockcasing@4"
            ]
        },
        {
            "x": -2,
            "y": -6,
            "z": 11,
            "elements": [
                "minecraft:stained_glass@10"
            ]
        },
        {
            "x": 4,
            "y": -5,
            "z": 9,
            "elements": [
                "minecraft:stained_glass@10"
            ]
        },
        {
            "x": 0,
            "y": 5,
            "z": 6,
            "elements": [
                "minecraft:stained_glass@10"
            ]
        },
        {
            "x": 0,
            "y": 5,
            "z": 7,
            "elements": [
                "minecraft:stained_glass@0"
            ]
        },
        {
            "x": 0,
            "y": 5,
            "z": 8,
            "elements": [
                "minecraft:stained_glass@10"
            ]
        },
        {
            "x": 4,
            "y": -5,
            "z": 5,
            "elements": [
                "minecraft:stained_glass@10"
            ]
        },
        {
            "x": -2,
            "y": 2,
            "z": 4,

            "elements": [
                "modularmachinery:blockcasing@4"
            ]
        },
        {
            "x": -2,
            "y": 2,
            "z": 3,
            "elements": [
                "minecraft:end_rod@1"
            ]
        },
        {
            "x": -2,
            "y": 2,
            "z": 5,

            "elements": [
                "modularmachinery:blockcasing@4"
            ]
        },
        {
            "x": -4,
            "y": -3,
            "z": 9,
            "elements": [
                "minecraft:stained_glass@10"
            ]
        },
        {
            "x": 2,
            "y": -2,
            "z": 3,
            "elements": [
                "minecraft:stained_glass@10"
            ]
        },
        {
            "x": 2,
            "y": -2,
            "z": 5,

            "elements": [
                "modularmachinery:blockcasing@4"
            ]
        },
        {
            "x": 0,
            "y": 12,
            "z": 7,
            "elements": [
                "minecraft:stained_glass@0"
            ]
        },
        {
            "x": -6,
            "y": -2,
            "z": 7,
            "elements": [
                "modularmachinery:blockcasing@4",
                "ItemInputStrengthen",
                "ItemOutputStrengthen",
                "FluidInputStrengthen",
                "FluidOutputStrengthen"
            ]
        },
        {
            "x": -1,
            "y": 4,
            "z": 3,
            "elements": [
                "minecraft:stained_glass@10"
            ]
        },
        {
            "x": -1,
            "y": 4,
            "z": 7,
            "elements": [
                "minecraft:stained_glass@10"
            ]
        },
        {
            "x": -1,
            "y": 4,
            "z": 6,
            "elements": [
                "minecraft:stained_glass_pane@10"
            ]
        },
        {
            "x": -1,
            "y": 4,
            "z": 4,
            "elements": [
                "minecraft:purpur_slab@0"
            ]
        },
        {
            "x": -1,
            "y": 4,
            "z": 11,
            "elements": [
                "minecraft:stained_glass@10"
            ]
        },
        {
            "x": -4,
            "y": -3,
            "z": 5,
            "elements": [
                "minecraft:stained_glass@10"
            ]
        },
        {
            "x": -1,
            "y": 4,
            "z": 10,
            "elements": [
                "minecraft:purpur_slab@0"
            ]
        },
        {
            "x": -1,
            "y": 4,
            "z": 8,
            "elements": [
                "minecraft:stained_glass_pane@10"
            ]
        },
        {
            "x": 6,
            "y": 0,
            "z": 8,
            "elements": [
                "minecraft:purpur_slab@0"
            ]
        },
        {
            "x": 6,
            "y": 0,
            "z": 7,

            "elements": [
                "modularmachinery:blockcasing@4"
            ]
        },
        {
            "x": 6,
            "y": 0,
            "z": 6,
            "elements": [
                "minecraft:purpur_slab@0"
            ]
        },
        {
            "x": 2,
            "y": -9,
            "z": 5,

            "elements": [
                "environmentaltech:lightning_rod@0"
            ]
        },
        {
            "x": 0,
            "y": -1,
            "z": 1,

            "elements": [
                "modularmachinery:blockcasing@4"
            ]
        },
        {
            "x": 0,
            "y": -1,
            "z": 0,
            "elements": [
                "minecraft:stone_slab@15"
            ]
        },
        {
            "x": 0,
            "y": 6,
            "z": 6,
            "elements": [
                "minecraft:stained_glass@10"
            ]
        },
        {
            "x": 0,
            "y": -1,
            "z": 3,
            "elements": [
                "minecraft:purpur_slab@8"
            ]
        },
        {
            "x": 0,
            "y": 6,
            "z": 7,
            "elements": [
                "minecraft:stained_glass@0"
            ]
        },
        {
            "x": 0,
            "y": 6,
            "z": 8,
            "elements": [
                "minecraft:stained_glass@10"
            ]
        },
        {
            "x": 0,
            "y": -1,
            "z": 2,
            "elements": [
                "minecraft:purpur_stairs@7"
            ]
        },
        {
            "x": 2,
            "y": -9,
            "z": 9,

            "elements": [
                "environmentaltech:lightning_rod@0"
            ]
        },
        {
            "x": 0,
            "y": -1,
            "z": 4,
            "elements": [
                "minecraft:purpur_slab@8"
            ]
        },
        {
            "x": 0,
            "y": -1,
            "z": 7,
            "elements": [
                "minecraft:purpur_block@0"
            ]
        },
        {
            "x": 0,
            "y": -1,
            "z": 6,
            "elements": [
                "minecraft:stained_glass@10"
            ]
        },
        {
            "x": 0,
            "y": -1,
            "z": 8,
            "elements": [
                "minecraft:stained_glass@10"
            ]
        },
        {
            "x": 0,
            "y": -1,
            "z": 11,
            "elements": [
                "minecraft:purpur_slab@8"
            ]
        },
        {
            "x": 2,
            "y": -2,
            "z": 9,

            "elements": [
                "modularmachinery:blockcasing@4"
            ]
        },
        {
            "x": 0,
            "y": -1,
            "z": 10,
            "elements": [
                "minecraft:purpur_slab@8"
            ]
        },
        {
            "x": 0,
            "y": -1,
            "z": 13,

            "elements": [
                "modularmachinery:blockcasing@4"
            ]
        },
        {
            "x": 0,
            "y": -1,
            "z": 12,
            "elements": [
                "minecraft:purpur_stairs@6"
            ]
        },
        {
            "x": 2,
            "y": -2,
            "z": 11,
            "elements": [
                "minecraft:stained_glass@10"
            ]
        },
        {
            "x": 0,
            "y": -1,
            "z": 14,
            "elements": [
                "minecraft:stone_slab@15"
            ]
        },
        {
            "x": 3,
            "y": 0,
            "z": 6,
            "elements": [
                "environmentaltech:structure_frame_1@0"
            ]
        },
        {
            "x": 3,
            "y": 0,
            "z": 7,
            "elements": [
                "environmentaltech:structure_frame_1@0"
            ]
        },
        {
            "x": 3,
            "y": 0,
            "z": 4,
            "elements": [
                "contenttweaker:mysteriousicecasing@0"
            ]
        },
        {
            "x": 3,
            "y": 0,
            "z": 5,

            "elements": [
                "modularmachinery:blockcasing@4"
            ]
        },
        {
            "x": -3,
            "y": -1,
            "z": 11,
            "elements": [
                "minecraft:end_rod@0"
            ]
        },
        {
            "x": 3,
            "y": 0,
            "z": 10,
            "elements": [
                "contenttweaker:mysteriousicecasing@0"
            ]
        },
        {
            "x": 3,
            "y": 0,
            "z": 11,
            "elements": [
                "minecraft:purpur_slab@0"
            ]
        },
        {
            "x": 3,
            "y": 0,
            "z": 8,
            "elements": [
                "environmentaltech:structure_frame_1@0"
            ]
        },
        {
            "x": 3,
            "y": 0,
            "z": 9,

            "elements": [
                "modularmachinery:blockcasing@4"
            ]
        },
        {
            "x": 3,
            "y": 0,
            "z": 3,
            "elements": [
                "minecraft:purpur_slab@0"
            ]
        },
        {
            "x": 2,
            "y": 4,
            "z": 4,
            "elements": [
                "minecraft:quartz_stairs@2"
            ]
        },
        {
            "x": 2,
            "y": 4,
            "z": 5,

            "elements": [
                "modularmachinery:blockcasing@4"
            ]
        },
        {
            "x": 4,
            "y": -4,
            "z": 9,
            "elements": [
                "minecraft:stained_glass@10"
            ]
        },
        {
            "x": 2,
            "y": 4,
            "z": 9,

            "elements": [
                "modularmachinery:blockcasing@4"
            ]
        },
        {
            "x": 2,
            "y": 4,
            "z": 10,
            "elements": [
                "minecraft:quartz_stairs@3"
            ]
        },
        {
            "x": 0,
            "y": -7,
            "z": 7,
            "elements": [
                "minecraft:stained_glass@0"
            ]
        },
        {
            "x": -1,
            "y": -3,
            "z": 7,
            "elements": [
                "minecraft:stained_glass@10"
            ]
        },
        {
            "x": -2,
            "y": -5,
            "z": 5,

            "elements": [
                "modularmachinery:blockcasing@4"
            ]
        },
        {
            "x": -2,
            "y": -5,
            "z": 3,
            "elements": [
                "minecraft:stained_glass@10"
            ]
        },
        {
            "x": 2,
            "y": 10,
            "z": 9,

            "elements": [
                "modularmachinery:blockcasing@4"
            ]
        },
        {
            "x": 4,
            "y": -4,
            "z": 5,
            "elements": [
                "minecraft:stained_glass@10"
            ]
        },
        {
            "x": 2,
            "y": 10,
            "z": 5,

            "elements": [
                "modularmachinery:blockcasing@4"
            ]
        },
        {
            "x": 0,
            "y": 18,
            "z": 7,
            "elements": [
                "minecraft:stained_glass@0"
            ]
        },
        {
            "x": -4,
            "y": 3,
            "z": 8,
            "elements": [
                "minecraft:stained_glass@10"
            ]
        },
        {
            "x": -3,
            "y": -1,
            "z": 7,
            "elements": [
                "minecraft:purpur_slab@8"
            ]
        },
        {
            "x": 0,
            "y": -13,
            "z": 7,
            "elements": [
                "minecraft:stained_glass@0"
            ]
        },
        {
            "x": -3,
            "y": -1,
            "z": 8,
            "elements": [
                "minecraft:purpur_slab@8"
            ]
        },
        {
            "x": -3,
            "y": -1,
            "z": 9,
            "elements": [
                "minecraft:quartz_stairs@4"
            ]
        },
        {
            "x": -2,
            "y": -5,
            "z": 11,
            "elements": [
                "minecraft:stained_glass@10"
            ]
        },
        {
            "x": -3,
            "y": -1,
            "z": 10,
            "elements": [
                "minecraft:stained_glass@0"
            ]
        },
        {
            "x": -3,
            "y": -1,
            "z": 3,
            "elements": [
                "minecraft:end_rod@0"
            ]
        },
        {
            "x": -4,
            "y": 3,
            "z": 6,
            "elements": [
                "minecraft:stained_glass@10"
            ]
        },
        {
            "x": -3,
            "y": -1,
            "z": 4,
            "elements": [
                "minecraft:stained_glass@0"
            ]
        },
        {
            "x": -2,
            "y": -5,
            "z": 9,

            "elements": [
                "modularmachinery:blockcasing@4"
            ]
        },
        {
            "x": -3,
            "y": -1,
            "z": 5,
            "elements": [
                "minecraft:quartz_stairs@4"
            ]
        },
        {
            "x": -3,
            "y": -1,
            "z": 6,
            "elements": [
                "minecraft:purpur_slab@8"
            ]
        },
        {
            "x": -2,
            "y": -2,
            "z": 5,

            "elements": [
                "modularmachinery:blockcasing@4"
            ]
        },
        {
            "x": -1,
            "y": -1,
            "z": 10,
            "elements": [
                "minecraft:purpur_slab@8"
            ]
        },
        {
            "x": 3,
            "y": 4,
            "z": 8,
            "elements": [
                "minecraft:purpur_slab@0"
            ]
        },
        {
            "x": -1,
            "y": -1,
            "z": 11,
            "elements": [
                "minecraft:stained_glass@0"
            ]
        },
        {
            "x": -2,
            "y": -2,
            "z": 3,
            "elements": [
                "minecraft:stained_glass@10"
            ]
        },
        {
            "x": 3,
            "y": 4,
            "z": 9,
            "elements": [
                "minecraft:quartz_stairs@1"
            ]
        },
        {
            "x": -1,
            "y": -1,
            "z": 12,
            "elements": [
                "minecraft:stained_glass@0"
            ]
        },
        {
            "x": 2,
            "y": 3,
            "z": 9,

            "elements": [
                "modularmachinery:blockcasing@4"
            ]
        },
        {
            "x": -2,
            "y": -2,
            "z": 9,

            "elements": [
                "modularmachinery:blockcasing@4"
            ]
        },
        {
            "x": -1,
            "y": -1,
            "z": 13,
            "elements": [
                "minecraft:stained_glass@0"
            ]
        },
        {
            "x": -1,
            "y": -1,
            "z": 14,
            "elements": [
                "minecraft:end_rod@0"
            ]
        },
        {
            "x": 2,
            "y": 3,
            "z": 4,

            "elements": [
                "modularmachinery:blockcasing@4"
            ]
        },
        {
            "x": -2,
            "y": 11,
            "z": 9,

            "elements": [
                "environmentaltech:lightning_rod@0"
            ]
        },
        {
            "x": 2,
            "y": 3,
            "z": 5,

            "elements": [
                "modularmachinery:blockcasing@4"
            ]
        },
        {
            "x": -1,
            "y": -1,
            "z": 1,
            "elements": [
                "minecraft:stained_glass@0"
            ]
        },
        {
            "x": -1,
            "y": -1,
            "z": 2,
            "elements": [
                "minecraft:stained_glass@0"
            ]
        },
        {
            "x": -1,
            "y": -1,
            "z": 3,
            "elements": [
                "minecraft:stained_glass@0"
            ]
        },
        {
            "x": -1,
            "y": -1,
            "z": 4,
            "elements": [
                "minecraft:purpur_slab@8"
            ]
        },
        {
            "x": 3,
            "y": 4,
            "z": 6,
            "elements": [
                "minecraft:purpur_slab@0"
            ]
        },
        {
            "x": -1,
            "y": -1,
            "z": 6,
            "elements": [
                "minecraft:end_rod@0"
            ]
        },
        {
            "x": -1,
            "y": -1,
            "z": 7,
            "elements": [
                "minecraft:stained_glass@10"
            ]
        },
        {
            "x": -1,
            "y": -1,
            "z": 8,
            "elements": [
                "minecraft:end_rod@0"
            ]
        },
        {
            "x": 3,
            "y": 4,
            "z": 5,
            "elements": [
                "minecraft:quartz_stairs@1"
            ]
        },
        {
            "x": 0,
            "y": 0,
            "z": 12,
            "elements": [
                "minecraft:purpur_block@0"
            ]
        },
        {
            "x": 0,
            "y": 0,
            "z": 11,
            "elements": [
                "minecraft:purpur_block@0"
            ]
        },
        {
            "x": 0,
            "y": 0,
            "z": 14,
            "elements": [
                "modularmachinery:blockcasing@4",
                "ItemInputStrengthen",
                "ItemOutputStrengthen",
                "FluidInputStrengthen",
                "FluidOutputStrengthen"
            ]
        },
        {
            "x": -4,
            "y": -5,
            "z": 9,
            "elements": [
                "minecraft:stained_glass@10"
            ]
        },
        {
            "x": 0,
            "y": 0,
            "z": 13,

            "elements": [
                "modularmachinery:blockcasing@4"
            ]
        },
        {
            "x": 0,
            "y": 0,
            "z": 8,
            "elements": [
                "minecraft:purpur_stairs@7"
            ]
        },
        {
            "x": 0,
            "y": 14,
            "z": 7,
            "elements": [
                "minecraft:stained_glass@0"
            ]
        },
        {
            "x": 4,
            "y": 5,
            "z": 8,
            "elements": [
                "minecraft:stained_glass@10"
            ]
        },
        {
            "x": 0,
            "y": 0,
            "z": 7,
            "elements": [
                "avaritia:block_resource@2"
            ]
        },
        {
            "x": 0,
            "y": 0,
            "z": 10,
            "elements": [
                "environmentaltech:structure_frame_1@0"
            ]
        },
        {
            "x": -1,
            "y": -1,
            "z": 0,
            "elements": [
                "minecraft:end_rod@0"
            ]
        },
        {
            "x": 4,
            "y": 5,
            "z": 6,
            "elements": [
                "minecraft:stained_glass@10"
            ]
        },
        {
            "x": 0,
            "y": 0,
            "z": 9,
            "elements": [
                "minecraft:purpur_slab@8"
            ]
        },
        {
            "x": 1,
            "y": 2,
            "z": 11,
            "elements": [
                "minecraft:stained_glass@0"
            ]
        },
        {
            "x": 0,
            "y": 0,
            "z": 4,
            "elements": [
                "environmentaltech:structure_frame_1@0"
            ]
        },
        {
            "x": 0,
            "y": 0,
            "z": 3,
            "elements": [
                "minecraft:purpur_block@0"
            ]
        },
        {
            "x": -3,
            "y": -3,
            "z": 10,
            "elements": [
                "minecraft:stained_glass@0"
            ]
        },
        {
            "x": 1,
            "y": 2,
            "z": 10,
            "elements": [
                "minecraft:stained_glass@0"
            ]
        },
        {
            "x": 0,
            "y": 0,
            "z": 6,
            "elements": [
                "minecraft:purpur_stairs@6"
            ]
        },
        {
            "x": 0,
            "y": 0,
            "z": 5,
            "elements": [
                "minecraft:purpur_slab@8"
            ]
        },
        {
            "x": 1,
            "y": 2,
            "z": 8,
            "elements": [
                "minecraft:stained_glass_pane@10"
            ]
        },
        {
            "x": 1,
            "y": 2,
            "z": 7,
            "elements": [
                "minecraft:purpur_block@0"
            ]
        },
        {
            "x": 0,
            "y": 0,
            "z": 0,

            "elements": [
                "modularmachinery:blockcontroller@2"
            ]
        },
        {
            "x": 1,
            "y": 2,
            "z": 6,
            "elements": [
                "minecraft:stained_glass_pane@10"
            ]
        },
        {
            "x": -4,
            "y": -5,
            "z": 5,
            "elements": [
                "minecraft:stained_glass@10"
            ]
        },
        {
            "x": 0,
            "y": 0,
            "z": 2,
            "elements": [
                "minecraft:purpur_block@0"
            ]
        },
        {
            "x": 1,
            "y": 2,
            "z": 4,
            "elements": [
                "minecraft:stained_glass@0"
            ]
        },
        {
            "x": 0,
            "y": 0,
            "z": 1,

            "elements": [
                "modularmachinery:blockcasing@4"
            ]
        },
        {
            "x": 1,
            "y": 2,
            "z": 3,
            "elements": [
                "minecraft:stained_glass@0"
            ]
        },
        {
            "x": 1,
            "y": 2,
            "z": 2,
            "elements": [
                "minecraft:stained_glass@10"
            ]
        },
        {
            "x": -3,
            "y": -3,
            "z": 4,
            "elements": [
                "minecraft:stained_glass@0"
            ]
        },
        {
            "x": 0,
            "y": 13,
            "z": 7,
            "elements": [
                "minecraft:stained_glass@0"
            ]
        },
        {
            "x": -2,
            "y": 11,
            "z": 5,

            "elements": [
                "environmentaltech:lightning_rod@0"
            ]
        },
        {
            "x": 1,
            "y": 2,
            "z": 12,
            "elements": [
                "minecraft:stained_glass@10"
            ]
        },
        {
            "x": -2,
            "y": -3,
            "z": 11,
            "elements": [
                "minecraft:stained_glass@10"
            ]
        },
        {
            "x": -2,
            "y": -3,
            "z": 9,

            "elements": [
                "modularmachinery:blockcasing@4"
            ]
        },
        {
            "x": -2,
            "y": -3,
            "z": 5,

            "elements": [
                "modularmachinery:blockcasing@4"
            ]
        },
        {
            "x": 1,
            "y": 1,
            "z": 4,
            "elements": [
                "environmentaltech:structure_frame_1@0"
            ]
        },
        {
            "x": 1,
            "y": 1,
            "z": 3,
            "elements": [
                "minecraft:stained_glass@0"
            ]
        },
        {
            "x": 1,
            "y": 1,
            "z": 2,
            "elements": [
                "minecraft:stained_glass@10"
            ]
        },
        {
            "x": 1,
            "y": 1,
            "z": 8,
            "elements": [
                "minecraft:stained_glass_pane@0"
            ]
        },
        {
            "x": 1,
            "y": 1,
            "z": 7,
            "elements": [
                "avaritia:block_resource@2"
            ]
        },
        {
            "x": 1,
            "y": 1,
            "z": 6,
            "elements": [
                "minecraft:stained_glass_pane@0"
            ]
        },
        {
            "x": 1,
            "y": 1,
            "z": 12,
            "elements": [
                "minecraft:stained_glass@10"
            ]
        },
        {
            "x": 0,
            "y": -14,
            "z": 7,
            "elements": [
                "minecraft:stained_glass@0"
            ]
        },
        {
            "x": 1,
            "y": 1,
            "z": 11,
            "elements": [
                "minecraft:stained_glass@0"
            ]
        },
        {
            "x": 1,
            "y": 1,
            "z": 10,
            "elements": [
                "environmentaltech:structure_frame_1@0"
            ]
        },
        {
            "x": 0,
            "y": -12,
            "z": 7,
            "elements": [
                "minecraft:stained_glass@0"
            ]
        },
        {
            "x": -2,
            "y": -1,
            "z": 12,
            "elements": [
                "minecraft:purpur_slab@8"
            ]
        },
        {
            "x": -2,
            "y": -1,
            "z": 10,
            "elements": [
                "minecraft:quartz_stairs@7"
            ]
        },
        {
            "x": -2,
            "y": -1,
            "z": 11,
            "elements": [
                "minecraft:stained_glass@10"
            ]
        },
        {
            "x": -2,
            "y": -1,
            "z": 9,

            "elements": [
                "modularmachinery:blockcasing@4"
            ]
        },
        {
            "x": -2,
            "y": -1,
            "z": 4,
            "elements": [
                "minecraft:quartz_stairs@6"
            ]
        },
        {
            "x": -2,
            "y": -1,
            "z": 5,

            "elements": [
                "modularmachinery:blockcasing@4"
            ]
        },
        {
            "x": -2,
            "y": -1,
            "z": 2,
            "elements": [
                "minecraft:purpur_slab@8"
            ]
        },
        {
            "x": -2,
            "y": -1,
            "z": 3,
            "elements": [
                "minecraft:stained_glass@10"
            ]
        },
        {
            "x": 4,
            "y": 6,
            "z": 8,
            "elements": [
                "minecraft:stained_glass@10"
            ]
        },
        {
            "x": -4,
            "y": -4,
            "z": 5,
            "elements": [
                "minecraft:stained_glass@10"
            ]
        },
        {
            "x": 4,
            "y": 6,
            "z": 6,
            "elements": [
                "minecraft:stained_glass@10"
            ]
        },
        {
            "x": 2,
            "y": 3,
            "z": 10,

            "elements": [
                "modularmachinery:blockcasing@4"
            ]
        },
        {
            "x": -1,
            "y": -2,
            "z": 11,
            "elements": [
                "minecraft:stained_glass@0"
            ]
        },
        {
            "x": -1,
            "y": -2,
            "z": 7,
            "elements": [
                "minecraft:stained_glass@10"
            ]
        },
        {
            "x": -4,
            "y": -4,
            "z": 9,
            "elements": [
                "minecraft:stained_glass@10"
            ]
        },
        {
            "x": -1,
            "y": -2,
            "z": 3,
            "elements": [
                "minecraft:stained_glass@0"
            ]
        },
        {
            "x": 1,
            "y": 0,
            "z": 4,
            "elements": [
                "environmentaltech:structure_frame_1@0"
            ]
        },
        {
            "x": 1,
            "y": 0,
            "z": 3,
            "elements": [
                "minecraft:stained_glass@0"
            ]
        },
        {
            "x": 4,
            "y": 7,
            "z": 8,
            "elements": [
                "minecraft:end_rod@1"
            ]
        },
        {
            "x": -4,
            "y": 7,
            "z": 6,
            "elements": [
                "minecraft:end_rod@1"
            ]
        },
        {
            "x": 1,
            "y": 0,
            "z": 2,
            "elements": [
                "minecraft:purpur_block@0"
            ]
        },
        {
            "x": 1,
            "y": 0,
            "z": 1,
            "elements": [
                "minecraft:purpur_slab@0"
            ]
        },
        {
            "x": -4,
            "y": 7,
            "z": 8,
            "elements": [
                "minecraft:end_rod@1"
            ]
        },
        {
            "x": 1,
            "y": 0,
            "z": 0,
            "elements": [
                "minecraft:purpur_slab@0"
            ]
        },
        {
            "x": 4,
            "y": 7,
            "z": 6,
            "elements": [
                "minecraft:end_rod@1"
            ]
        },
        {
            "x": 1,
            "y": 0,
            "z": 13,
            "elements": [
                "minecraft:purpur_slab@0"
            ]
        },
        {
            "x": 1,
            "y": 0,
            "z": 12,
            "elements": [
                "minecraft:purpur_block@0"
            ]
        },
        {
            "x": 1,
            "y": 0,
            "z": 11,
            "elements": [
                "minecraft:stained_glass@0"
            ]
        },
        {
            "x": 1,
            "y": 0,
            "z": 10,
            "elements": [
                "environmentaltech:structure_frame_1@0"
            ]
        },
        {
            "x": 1,
            "y": 0,
            "z": 8,
            "elements": [
                "minecraft:stained_glass_pane@0"
            ]
        },
        {
            "x": 1,
            "y": 0,
            "z": 7,
            "elements": [
                "minecraft:purpur_stairs@5"
            ]
        },
        {
            "x": 1,
            "y": 0,
            "z": 6,
            "elements": [
                "minecraft:stained_glass_pane@0"
            ]
        },
        {
            "x": -2,
            "y": -4,
            "z": 5,

            "elements": [
                "modularmachinery:blockcasing@4"
            ]
        },
        {
            "x": 1,
            "y": 3,
            "z": 11,
            "elements": [
                "minecraft:stained_glass@10"
            ]
        },
        {
            "x": -2,
            "y": -4,
            "z": 11,
            "elements": [
                "minecraft:stained_glass@10"
            ]
        },
        {
            "x": -2,
            "y": -4,
            "z": 9,

            "elements": [
                "modularmachinery:blockcasing@4"
            ]
        },
        {
            "x": -3,
            "y": -2,
            "z": 4,
            "elements": [
                "minecraft:stained_glass@0"
            ]
        },
        {
            "x": 1,
            "y": 3,
            "z": 6,
            "elements": [
                "minecraft:stained_glass_pane@10"
            ]
        },
        {
            "x": 1,
            "y": 3,
            "z": 3,
            "elements": [
                "minecraft:stained_glass@10"
            ]
        },
        {
            "x": 1,
            "y": 3,
            "z": 4,
            "elements": [
                "minecraft:stained_glass@0"
            ]
        },
        {
            "x": -2,
            "y": -4,
            "z": 3,
            "elements": [
                "minecraft:stained_glass@10"
            ]
        },
        {
            "x": 1,
            "y": 3,
            "z": 10,
            "elements": [
                "minecraft:stained_glass@0"
            ]
        },
        {
            "x": 1,
            "y": 3,
            "z": 7,
            "elements": [
                "minecraft:stained_glass@10"
            ]
        },
        {
            "x": -3,
            "y": -2,
            "z": 10,
            "elements": [
                "minecraft:stained_glass@0"
            ]
        },
        {
            "x": 1,
            "y": 3,
            "z": 8,
            "elements": [
                "minecraft:stained_glass_pane@10"
            ]
        },
        {
            "x": -2,
            "y": 0,
            "z": 3,
            "elements": [
                "minecraft:stained_glass@0"
            ]
        },
        {
            "x": 2,
            "y": 5,
            "z": 5,

            "elements": [
                "modularmachinery:blockcasing@4"
            ]
        },
        {
            "x": -2,
            "y": 0,
            "z": 4,

            "elements": [
                "modularmachinery:blockcasing@4"
            ]
        },
        {
            "x": 0,
            "y": -15,
            "z": 7,
            "elements": [
                "minecraft:stained_glass@0"
            ]
        },
        {
            "x": -2,
            "y": 0,
            "z": 2,
            "elements": [
                "minecraft:purpur_block@0"
            ]
        },
        {
            "x": -2,
            "y": 0,
            "z": 7,
            "elements": [
                "minecraft:purpur_slab@8"
            ]
        },
        {
            "x": -2,
            "y": 0,
            "z": 5,

            "elements": [
                "modularmachinery:blockcasing@4"
            ]
        },
        {
            "x": 4,
            "y": -6,
            "z": 9,
            "elements": [
                "minecraft:stained_glass@10"
            ]
        },
        {
            "x": 4,
            "y": -6,
            "z": 5,
            "elements": [
                "minecraft:stained_glass@10"
            ]
        },
        {
            "x": 4,
            "y": 4,
            "z": 6,
            "elements": [
                "minecraft:stained_glass@10"
            ]
        },
        {
            "x": 0,
            "y": -11,
            "z": 7,
            "elements": [
                "minecraft:stained_glass@0"
            ]
        },
        {
            "x": -2,
            "y": 0,
            "z": 11,
            "elements": [
                "minecraft:stained_glass@0"
            ]
        },
        {
            "x": -2,
            "y": -3,
            "z": 3,
            "elements": [
                "minecraft:stained_glass@10"
            ]
        },
        {
            "x": -2,
            "y": 0,
            "z": 12,
            "elements": [
                "minecraft:purpur_block@0"
            ]
        },
        {
            "x": 6,
            "y": -4,
            "z": 7,
            "elements": [
                "minecraft:quartz_stairs@5"
            ]
        },
        {
            "x": 4,
            "y": 4,
            "z": 8,
            "elements": [
                "minecraft:stained_glass@10"
            ]
        },
        {
            "x": -2,
            "y": 0,
            "z": 9,

            "elements": [
                "modularmachinery:blockcasing@4"
            ]
        },
        {
            "x": -2,
            "y": 0,
            "z": 10,

            "elements": [
                "modularmachinery:blockcasing@4"
            ]
        },
        {
            "x": 2,
            "y": 5,
            "z": 9,

            "elements": [
                "modularmachinery:blockcasing@4"
            ]
        },
        {
            "x": -2,
            "y": 12,
            "z": 5,
            "elements": [
                "minecraft:end_rod@1"
            ]
        },
        {
            "x": 2,
            "y": 2,
            "z": 11,
            "elements": [
                "minecraft:end_rod@1"
            ]
        },
        {
            "x": -2,
            "y": 12,
            "z": 9,
            "elements": [
                "minecraft:end_rod@1"
            ]
        },
        {
            "x": 0,
            "y": -2,
            "z": 6,
            "elements": [
                "minecraft:stained_glass@10"
            ]
        },
        {
            "x": 2,
            "y": 2,
            "z": 3,
            "elements": [
                "minecraft:end_rod@1"
            ]
        },
        {
            "x": 2,
            "y": 2,
            "z": 4,

            "elements": [
                "modularmachinery:blockcasing@4"
            ]
        },
        {
            "x": 0,
            "y": 1,
            "z": 14,
            "elements": [
                "minecraft:quartz_stairs@3"
            ]
        },
        {
            "x": 0,
            "y": -2,
            "z": 8,
            "elements": [
                "minecraft:stained_glass@10"
            ]
        },
        {
            "x": 2,
            "y": 2,
            "z": 5,

            "elements": [
                "modularmachinery:blockcasing@4"
            ]
        },
        {
            "x": 0,
            "y": -2,
            "z": 7,
            "elements": [
                "minecraft:stained_glass@0"
            ]
        },
        {
            "x": 2,
            "y": 2,
            "z": 7,
            "elements": [
                "minecraft:purpur_stairs@1"
            ]
        },
        {
            "x": 0,
            "y": -2,
            "z": 1,
            "elements": [
                "modularmachinery:blockcasing@4",
                "ItemInputStrengthen",
                "ItemOutputStrengthen",
                "FluidInputStrengthen",
                "FluidOutputStrengthen"
            ]
        },
        {
            "x": 2,
            "y": 2,
            "z": 9,

            "elements": [
                "modularmachinery:blockcasing@4"
            ]
        },
        {
            "x": 2,
            "y": 2,
            "z": 10,

            "elements": [
                "modularmachinery:blockcasing@4"
            ]
        },
        {
            "x": 0,
            "y": -2,
            "z": 13,
            "elements": [
                "modularmachinery:blockcasing@4",
                "ItemInputStrengthen",
                "ItemOutputStrengthen",
                "FluidInputStrengthen",
                "FluidOutputStrengthen"
            ]
        },
        {
            "x": 2,
            "y": -10,
            "z": 9,

            "elements": [
                "environmentaltech:lightning_rod@0"
            ]
        },
        {
            "x": -1,
            "y": 2,
            "z": 8,
            "elements": [
                "minecraft:stained_glass_pane@10"
            ]
        },
        {
            "x": -1,
            "y": 2,
            "z": 7,
            "elements": [
                "minecraft:purpur_block@0"
            ]
        },
        {
            "x": -1,
            "y": 2,
            "z": 6,
            "elements": [
                "minecraft:stained_glass_pane@10"
            ]
        },
        {
            "x": -2,
            "y": 9,
            "z": 9,

            "elements": [
                "modularmachinery:blockcasing@4"
            ]
        },
        {
            "x": -1,
            "y": 2,
            "z": 12,
            "elements": [
                "minecraft:stained_glass@10"
            ]
        },
        {
            "x": -1,
            "y": 2,
            "z": 11,
            "elements": [
                "minecraft:stained_glass@0"
            ]
        },
        {
            "x": -1,
            "y": 2,
            "z": 10,
            "elements": [
                "minecraft:stained_glass@0"
            ]
        },
        {
            "x": 2,
            "y": -10,
            "z": 5,

            "elements": [
                "environmentaltech:lightning_rod@0"
            ]
        },
        {
            "x": -1,
            "y": 2,
            "z": 4,
            "elements": [
                "minecraft:stained_glass@0"
            ]
        },
        {
            "x": -1,
            "y": 2,
            "z": 3,
            "elements": [
                "minecraft:stained_glass@0"
            ]
        },
        {
            "x": -1,
            "y": 2,
            "z": 2,
            "elements": [
                "minecraft:stained_glass@10"
            ]
        },
        {
            "x": 0,
            "y": 1,
            "z": 7,
            "elements": [
                "avaritia:block_resource@2"
            ]
        },
        {
            "x": 0,
            "y": 1,
            "z": 6,
            "elements": [
                "avaritia:block_resource@2"
            ]
        },
        {
            "x": 0,
            "y": 1,
            "z": 9,
            "elements": [
                "environmentaltech:structure_frame_1@0"
            ]
        },
        {
            "x": 0,
            "y": 1,
            "z": 8,
            "elements": [
                "avaritia:block_resource@2"
            ]
        },
        {
            "x": 0,
            "y": 1,
            "z": 11,
            "elements": [
                "minecraft:purpur_block@0"
            ]
        },
        {
            "x": 0,
            "y": 1,
            "z": 10,
            "elements": [
                "environmentaltech:structure_frame_1@0"
            ]
        },
        {
            "x": 0,
            "y": 1,
            "z": 13,

            "elements": [
                "modularmachinery:blockcasing@4"
            ]
        },
        {
            "x": 1,
            "y": 0,
            "z": 14,
            "elements": [
                "minecraft:purpur_slab@0"
            ]
        },
        {
            "x": 0,
            "y": 1,
            "z": 12,

            "elements": [
                "modularmachinery:blockcasing@4"
            ]
        },
        {
            "x": -2,
            "y": 9,
            "z": 5,

            "elements": [
                "modularmachinery:blockcasing@4"
            ]
        },
        {
            "x": 0,
            "y": 1,
            "z": 1,

            "elements": [
                "modularmachinery:blockcasing@4"
            ]
        },
        {
            "x": 0,
            "y": 1,
            "z": 0,
            "elements": [
                "minecraft:quartz_stairs@2"
            ]
        },
        {
            "x": 0,
            "y": 1,
            "z": 3,
            "elements": [
                "minecraft:purpur_block@0"
            ]
        },
        {
            "x": 0,
            "y": 1,
            "z": 2,

            "elements": [
                "modularmachinery:blockcasing@4"
            ]
        },
        {
            "x": 0,
            "y": 1,
            "z": 5,
            "elements": [
                "environmentaltech:structure_frame_1@0"
            ]
        },
        {
            "x": 0,
            "y": 1,
            "z": 4,
            "elements": [
                "environmentaltech:structure_frame_1@0"
            ]
        },
        {
            "x": 1,
            "y": 5,
            "z": 3,
            "elements": [
                "minecraft:stained_glass@10"
            ]
        },
        {
            "x": 0,
            "y": -3,
            "z": 13,
            "elements": [
                "modularmachinery:blockcasing@4",
                "ItemInputStrengthen",
                "ItemOutputStrengthen",
                "FluidInputStrengthen",
                "FluidOutputStrengthen"
            ]
        },
        {
            "x": 6,
            "y": -2,
            "z": 7,
            "elements": [
                "modularmachinery:blockcasing@4",
                "ItemInputStrengthen",
                "ItemOutputStrengthen",
                "FluidInputStrengthen",
                "FluidOutputStrengthen"
            ]
        },
        {
            "x": 1,
            "y": 5,
            "z": 7,
            "elements": [
                "minecraft:stained_glass@10"
            ]
        },
        {
            "x": 1,
            "y": 5,
            "z": 8,
            "elements": [
                "minecraft:stained_glass_pane@10"
            ]
        },
        {
            "x": 1,
            "y": 5,
            "z": 6,
            "elements": [
                "minecraft:stained_glass_pane@10"
            ]
        },
        {
            "x": 1,
            "y": 5,
            "z": 11,
            "elements": [
                "minecraft:stained_glass@10"
            ]
        },
        {
            "x": 0,
            "y": -3,
            "z": 8,
            "elements": [
                "minecraft:stained_glass@10"
            ]
        },
        {
            "x": 0,
            "y": -3,
            "z": 6,
            "elements": [
                "minecraft:stained_glass@10"
            ]
        },
        {
            "x": 0,
            "y": -3,
            "z": 7,
            "elements": [
                "minecraft:stained_glass@0"
            ]
        },
        {
            "x": 0,
            "y": -16,
            "z": 7,
            "elements": [
                "minecraft:stained_glass@0"
            ]
        },
        {
            "x": 2,
            "y": 6,
            "z": 9,

            "elements": [
                "modularmachinery:blockcasing@4"
            ]
        },
        {
            "x": -6,
            "y": -4,
            "z": 7,
            "elements": [
                "minecraft:quartz_stairs@4"
            ]
        },
        {
            "x": 1,
            "y": -2,
            "z": 11,
            "elements": [
                "minecraft:stained_glass@0"
            ]
        },
        {
            "x": 0,
            "y": -3,
            "z": 1,
            "elements": [
                "modularmachinery:blockcasing@4",
                "ItemInputStrengthen",
                "ItemOutputStrengthen",
                "FluidInputStrengthen",
                "FluidOutputStrengthen"
            ]
        },
        {
            "x": -4,
            "y": -1,
            "z": 3,
            "elements": [
                "minecraft:purpur_slab@8"
            ]
        },
        {
            "x": 1,
            "y": -2,
            "z": 7,
            "elements": [
                "minecraft:stained_glass@10"
            ]
        },
        {
            "x": 1,
            "y": -2,
            "z": 3,
            "elements": [
                "minecraft:stained_glass@0"
            ]
        },
        {
            "x": 2,
            "y": 6,
            "z": 5,

            "elements": [
                "modularmachinery:blockcasing@4"
            ]
        },
        {
            "x": -4,
            "y": 5,
            "z": 8,
            "elements": [
                "minecraft:stained_glass@10"
            ]
        },
        {
            "x": -4,
            "y": 5,
            "z": 6,
            "elements": [
                "minecraft:stained_glass@10"
            ]
        },
        {
            "x": 0,
            "y": 10,
            "z": 7,
            "elements": [
                "minecraft:stained_glass@0"
            ]
        },
        {
            "x": 7,
            "y": -1,
            "z": 6,
            "elements": [
                "minecraft:end_rod@0"
            ]
        },
        {
            "x": 1,
            "y": -1,
            "z": 2,
            "elements": [
                "minecraft:stained_glass@0"
            ]
        },
        {
            "x": 1,
            "y": -1,
            "z": 1,
            "elements": [
                "minecraft:stained_glass@0"
            ]
        },
        {
            "x": 7,
            "y": -1,
            "z": 8,
            "elements": [
                "minecraft:end_rod@0"
            ]
        },
        {
            "x": 1,
            "y": -1,
            "z": 0,
            "elements": [
                "minecraft:end_rod@0"
            ]
        },
        {
            "x": 7,
            "y": -1,
            "z": 7,
            "elements": [
                "minecraft:stone_slab@15"
            ]
        },
        {
            "x": 1,
            "y": -1,
            "z": 6,
            "elements": [
                "minecraft:end_rod@0"
            ]
        },
        {
            "x": 1,
            "y": -1,
            "z": 4,
            "elements": [
                "minecraft:purpur_slab@8"
            ]
        },
        {
            "x": 1,
            "y": -1,
            "z": 3,
            "elements": [
                "minecraft:stained_glass@0"
            ]
        },
        {
            "x": 2,
            "y": 12,
            "z": 9,
            "elements": [
                "minecraft:end_rod@1"
            ]
        },
        {
            "x": 7,
            "y": 0,
            "z": 8,
            "elements": [
                "minecraft:purpur_slab@0"
            ]
        },
        {
            "x": -1,
            "y": -5,
            "z": 7,
            "elements": [
                "minecraft:end_rod@0"
            ]
        },
        {
            "x": 1,
            "y": 4,
            "z": 10,
            "elements": [
                "minecraft:purpur_slab@0"
            ]
        },
        {
            "x": 0,
            "y": 3,
            "z": 2,
            "elements": [
                "minecraft:quartz_stairs@2"
            ]
        },
        {
            "x": 1,
            "y": 4,
            "z": 11,
            "elements": [
                "minecraft:stained_glass@10"
            ]
        },
        {
            "x": 1,
            "y": -1,
            "z": 10,
            "elements": [
                "minecraft:purpur_slab@8"
            ]
        },
        {
            "x": 1,
            "y": -1,
            "z": 8,
            "elements": [
                "minecraft:end_rod@0"
            ]
        },
        {
            "x": 0,
            "y": 3,
            "z": 7,
            "elements": [
                "minecraft:stained_glass@0"
            ]
        },
        {
            "x": 1,
            "y": -1,
            "z": 7,
            "elements": [
                "minecraft:stained_glass@10"
            ]
        },
        {
            "x": 0,
            "y": 16,
            "z": 7,
            "elements": [
                "minecraft:stained_glass@0"
            ]
        },
        {
            "x": 0,
            "y": 3,
            "z": 6,
            "elements": [
                "minecraft:stained_glass@10"
            ]
        },
        {
            "x": 1,
            "y": -1,
            "z": 14,
            "elements": [
                "minecraft:end_rod@0"
            ]
        },
        {
            "x": 0,
            "y": 3,
            "z": 8,
            "elements": [
                "minecraft:stained_glass@10"
            ]
        },
        {
            "x": 1,
            "y": -1,
            "z": 13,
            "elements": [
                "minecraft:stained_glass@0"
            ]
        },
        {
            "x": 1,
            "y": -1,
            "z": 12,
            "elements": [
                "minecraft:stained_glass@0"
            ]
        },
        {
            "x": 1,
            "y": -1,
            "z": 11,
            "elements": [
                "minecraft:stained_glass@0"
            ]
        },
        {
            "x": 2,
            "y": -6,
            "z": 3,
            "elements": [
                "minecraft:stained_glass@10"
            ]
        },
        {
            "x": 0,
            "y": 3,
            "z": 12,
            "elements": [
                "minecraft:quartz_stairs@3"
            ]
        },
        {
            "x": 2,
            "y": -6,
            "z": 5,

            "elements": [
                "modularmachinery:blockcasing@4"
            ]
        },
        {
            "x": 2,
            "y": -6,
            "z": 9,

            "elements": [
                "modularmachinery:blockcasing@4"
            ]
        },
        {
            "x": 3,
            "y": 2,
            "z": 4,
            "elements": [
                "minecraft:stained_glass@0"
            ]
        },
        {
            "x": 3,
            "y": 2,
            "z": 5,

            "elements": [
                "modularmachinery:blockcasing@4"
            ]
        },
        {
            "x": 3,
            "y": 2,
            "z": 8,
            "elements": [
                "minecraft:stained_glass@0"
            ]
        },
        {
            "x": 3,
            "y": 2,
            "z": 9,

            "elements": [
                "modularmachinery:blockcasing@4"
            ]
        },
        {
            "x": 7,
            "y": 0,
            "z": 7,
            "elements": [
                "modularmachinery:blockcasing@4",
                "ItemInputStrengthen",
                "ItemOutputStrengthen",
                "FluidInputStrengthen",
                "FluidOutputStrengthen"
            ]
        },
        {
            "x": 3,
            "y": 2,
            "z": 6,
            "elements": [
                "minecraft:stained_glass@0"
            ]
        },
        {
            "x": 7,
            "y": 0,
            "z": 6,
            "elements": [
                "minecraft:purpur_slab@0"
            ]
        },
        {
            "x": 3,
            "y": 2,
            "z": 7,
            "elements": [
                "minecraft:purpur_slab@0"
            ]
        },
        {
            "x": 2,
            "y": 0,
            "z": 5,

            "elements": [
                "modularmachinery:blockcasing@4"
            ]
        },
        {
            "x": 3,
            "y": 2,
            "z": 10,
            "elements": [
                "minecraft:stained_glass@0"
            ]
        },
        {
            "x": 2,
            "y": 0,
            "z": 7,
            "elements": [
                "minecraft:purpur_slab@8"
            ]
        },
        {
            "x": 2,
            "y": 0,
            "z": 10,

            "elements": [
                "modularmachinery:blockcasing@4"
            ]
        },
        {
            "x": 5,
            "y": 2,
            "z": 8,
            "elements": [
                "minecraft:stained_glass@10"
            ]
        },
        {
            "x": 2,
            "y": 0,
            "z": 9,

            "elements": [
                "modularmachinery:blockcasing@4"
            ]
        },
        {
            "x": 2,
            "y": 0,
            "z": 12,
            "elements": [
                "minecraft:purpur_block@0"
            ]
        },
        {
            "x": 2,
            "y": 0,
            "z": 11,
            "elements": [
                "minecraft:stained_glass@0"
            ]
        },
        {
            "x": -4,
            "y": -1,
            "z": 6,
            "elements": [
                "minecraft:stained_glass@0"
            ]
        },
        {
            "x": -4,
            "y": -1,
            "z": 7,
            "elements": [
                "minecraft:purpur_slab@8"
            ]
        },
        {
            "x": -4,
            "y": -1,
            "z": 4,
            "elements": [
                "minecraft:end_rod@0"
            ]
        },
        {
            "x": -1,
            "y": 1,
            "z": 12,
            "elements": [
                "minecraft:stained_glass@10"
            ]
        },
        {
            "x": -4,
            "y": -1,
            "z": 5,
            "elements": [
                "minecraft:stained_glass@10"
            ]
        },
        {
            "x": -1,
            "y": 1,
            "z": 11,
            "elements": [
                "minecraft:stained_glass@0"
            ]
        },
        {
            "x": -1,
            "y": 1,
            "z": 10,
            "elements": [
                "environmentaltech:structure_frame_1@0"
            ]
        },
        {
            "x": 0,
            "y": -9,
            "z": 7,
            "elements": [
                "minecraft:stained_glass@0"
            ]
        },
        {
            "x": -4,
            "y": -1,
            "z": 10,
            "elements": [
                "minecraft:end_rod@0"
            ]
        },
        {
            "x": -4,
            "y": -1,
            "z": 11,
            "elements": [
                "minecraft:purpur_slab@8"
            ]
        },
        {
            "x": -4,
            "y": -1,
            "z": 8,
            "elements": [
                "minecraft:stained_glass@0"
            ]
        },
        {
            "x": -1,
            "y": 1,
            "z": 8,
            "elements": [
                "minecraft:stained_glass_pane@0"
            ]
        },
        {
            "x": -5,
            "y": 3,
            "z": 7,
            "elements": [
                "minecraft:quartz_stairs@0"
            ]
        },
        {
            "x": -1,
            "y": 1,
            "z": 7,
            "elements": [
                "avaritia:block_resource@2"
            ]
        },
        {
            "x": -4,
            "y": -1,
            "z": 9,
            "elements": [
                "minecraft:stained_glass@10"
            ]
        },
        {
            "x": 1,
            "y": 4,
            "z": 8,
            "elements": [
                "minecraft:stained_glass_pane@10"
