{
    "registryname": "YMG_Core_Pressure_Analog_Devices",
    "localizedname": "§b§lYMG§r§e§l—#FF0000§l地核压力模拟装置 §r§e",
    "failure-action": "still",
    "requires-blueprint": false,
    "color": "000000",
    "parts": [
        {
            "x": -3,
            "y": 10,
            "z": -1,
            "elements": [
                "enderio:block_reinforced_obsidian@0"
            ]
        },
        {
            "x": 2,
            "y": 3,
            "z": 0,
            "elements": [
                "enderio:block_reinforced_obsidian@0"
            ]
        },
        {
            "x": 5,
            "y": 0,
            "z": 0,
            "elements": [
                "modularmachinery:blockcasing@4",
                "ItemInputStrengthen",
                "ItemOutputStrengthen",
                "EnergyInputStrengthen",
                "EnergyOutputStrengthen",
                "FluidInputStrengthen",
                "FluidOutputStrengthen"
            ]
        },
        {
            "x": -3,
            "y": 10,
            "z": 0,
            "elements": [
                "enderio:block_reinforced_obsidian@0"
            ]
        },
        {
            "x": -3,
            "y": 10,
            "z": 1,
            "elements": [
                "enderio:block_reinforced_obsidian@0"
            ]
        },
        {
            "x": 1,
            "y": 2,
            "z": -5,
            "elements": [
                "appliedenergistics2:smooth_sky_stone_slab@0"
            ]
        },
        {
            "x": -1,
            "y": -1,
            "z": 1,

            "elements": [
                "modularmachinery:blockcasing@4"
            ]
        },
        {
            "x": -1,
            "y": 6,
            "z": 4,
            "elements": [
                "enderio:block_reinforced_obsidian@0"
            ]
        },
        {
            "x": -1,
            "y": -1,
            "z": 2,
            "elements": [
                "appliedenergistics2:smooth_sky_stone_stairs@3"
            ]
        },
        {
            "x": 3,
            "y": 4,
            "z": 0,
            "elements": [
                "enderio:block_reinforced_obsidian@0"
            ]
        },
        {
            "x": -1,
            "y": -1,
            "z": 3,
            "elements": [
                "appliedenergistics2:smooth_sky_stone_stairs@0"
            ]
        },
        {
            "x": 3,
            "y": 4,
            "z": 1,
            "elements": [
                "enderio:block_reinforced_obsidian@0"
            ]
        },
        {
            "x": -1,
            "y": -1,
            "z": 4,
            "elements": [
                "appliedenergistics2:smooth_sky_stone_stairs@0"
            ]
        },
        {
            "x": 0,
            "y": 7,
            "z": -4,
            "elements": [
                "enderio:block_reinforced_obsidian@0"
            ]
        },
        {
            "x": -1,
            "y": -1,
            "z": 5,
            "elements": [
                "appliedenergistics2:smooth_sky_stone_stairs@0"
            ]
        },
        {
            "x": -1,
            "y": -1,
            "z": 6,
            "elements": [
                "appliedenergistics2:smooth_sky_stone_slab@0"
            ]
        },
        {
            "x": -4,
            "y": 9,
            "z": 0,
            "elements": [
                "enderio:block_reinforced_obsidian@0"
            ]
        },
        {
            "x": -1,
            "y": 6,
            "z": -4,
            "elements": [
                "enderio:block_reinforced_obsidian@0"
            ]
        },
        {
            "x": -1,
            "y": -1,
            "z": -6,
            "elements": [
                "appliedenergistics2:smooth_sky_stone_slab@0"
            ]
        },
        {
            "x": -1,
            "y": -1,
            "z": -5,
            "elements": [
                "appliedenergistics2:smooth_sky_stone_stairs@0"
            ]
        },
        {
            "x": -1,
            "y": -1,
            "z": -4,
            "elements": [
                "appliedenergistics2:smooth_sky_stone_stairs@0"
            ]
        },
        {
            "x": -1,
            "y": -1,
            "z": -3,
            "elements": [
                "appliedenergistics2:smooth_sky_stone_stairs@0"
            ]
        },
        {
            "x": -5,
            "y": 1,
            "z": -1,
            "elements": [
                "appliedenergistics2:smooth_sky_stone_stairs@6"
            ]
        },
        {
            "x": 0,
            "y": 7,
            "z": 4,
            "elements": [
                "enderio:block_reinforced_obsidian@0"
            ]
        },
        {
            "x": -1,
            "y": -1,
            "z": -2,
            "elements": [
                "appliedenergistics2:smooth_sky_stone_stairs@0"
            ]
        },
        {
            "x": 3,
            "y": 4,
            "z": -1,
            "elements": [
                "enderio:block_reinforced_obsidian@0"
            ]
        },
        {
            "x": -5,
            "y": 1,
            "z": 0,
            "elements": [
                "modularmachinery:blockcasing@4",
                "ItemInputStrengthen",
                "ItemOutputStrengthen",
                "EnergyInputStrengthen",
                "EnergyOutputStrengthen",
                "FluidInputStrengthen",
                "FluidOutputStrengthen"
            ]
        },
        {
            "x": -1,
            "y": -1,
            "z": -1,

            "elements": [
                "modularmachinery:blockcasing@4"
            ]
        },
        {
            "x": -5,
            "y": 1,
            "z": 1,
            "elements": [
                "appliedenergistics2:smooth_sky_stone_stairs@7"
            ]
        },
        {
            "x": -1,
            "y": -1,
            "z": 0,

            "elements": [
                "modularmachinery:blockcasing@4"
            ]
        },
        {
            "x": 0,
            "y": 0,
            "z": 4,
            "elements": [
                "appliedenergistics2:smooth_sky_stone_slab@0"
            ]
        },
        {
            "x": 0,
            "y": 0,
            "z": 3,
            "elements": [
                "appliedenergistics2:smooth_sky_stone_slab@0"
            ]
        },
        {
            "x": 0,
            "y": 0,
            "z": 5,
            "elements": [
                "modularmachinery:blockcasing@4",
                "ItemInputStrengthen",
                "ItemOutputStrengthen",
                "EnergyInputStrengthen",
                "EnergyOutputStrengthen",
                "FluidInputStrengthen",
                "FluidOutputStrengthen"
            ]
        },
        {
            "x": 0,
            "y": 0,
            "z": 0,

            "elements": [
                "modularmachinery:blockcontroller@2"
            ]
        },
        {
            "x": 0,
            "y": 0,
            "z": -1,
            "elements": [
                "appliedenergistics2:smooth_sky_stone_stairs@3"
            ]
        },
        {
            "x": 4,
            "y": 5,
            "z": 0,
            "elements": [
                "enderio:block_reinforced_obsidian@0"
            ]
        },
        {
            "x": 0,
            "y": 0,
            "z": 2,
            "elements": [
                "appliedenergistics2:smooth_sky_stone_slab@0"
            ]
        },
        {
            "x": 1,
            "y": 2,
            "z": 5,
            "elements": [
                "appliedenergistics2:smooth_sky_stone_slab@0"
            ]
        },
        {
            "x": 0,
            "y": 0,
            "z": 1,
            "elements": [
                "appliedenergistics2:smooth_sky_stone_stairs@2"
            ]
        },
        {
            "x": 0,
            "y": 0,
            "z": -4,
            "elements": [
                "appliedenergistics2:smooth_sky_stone_slab@0"
            ]
        },
        {
            "x": 0,
            "y": 0,
            "z": -5,
            "elements": [
                "modularmachinery:blockcasing@4",
                "ItemInputStrengthen",
                "ItemOutputStrengthen",
                "EnergyInputStrengthen",
                "EnergyOutputStrengthen",
                "FluidInputStrengthen",
                "FluidOutputStrengthen"
            ]
        },
        {
            "x": 0,
            "y": 0,
            "z": -2,
            "elements": [
                "appliedenergistics2:smooth_sky_stone_slab@0"
            ]
        },
        {
            "x": 0,
            "y": 0,
            "z": -3,
            "elements": [
                "appliedenergistics2:smooth_sky_stone_slab@0"
            ]
        },
        {
            "x": -2,
            "y": 4,
            "z": -2,
            "elements": [
                "enderio:block_reinforced_obsidian@0"
            ]
        },
        {
            "x": 1,
            "y": 9,
            "z": -3,
            "elements": [
                "enderio:block_reinforced_obsidian@0"
            ]
        },
        {
            "x": 2,
            "y": 9,
            "z": -3,
            "elements": [
                "enderio:block_reinforced_obsidian@0"
            ]
        },
        {
            "x": -2,
            "y": 4,
            "z": -1,
            "elements": [
                "enderio:block_reinforced_obsidian@0"
            ]
        },
        {
            "x": -2,
            "y": 4,
            "z": 2,
            "elements": [
                "enderio:block_reinforced_obsidian@0"
            ]
        },
        {
            "x": 2,
            "y": 9,
            "z": 3,
            "elements": [
                "enderio:block_reinforced_obsidian@0"
            ]
        },
        {
            "x": -2,
            "y": 4,
            "z": 1,
            "elements": [
                "enderio:block_reinforced_obsidian@0"
            ]
        },
        {
            "x": -2,
            "y": 11,
            "z": 0,
            "elements": [
                "enderio:block_reinforced_obsidian@0"
            ]
        },
        {
            "x": 1,
            "y": 9,
            "z": 3,
            "elements": [
                "enderio:block_reinforced_obsidian@0"
            ]
        },
        {
            "x": 3,
            "y": 5,
            "z": -2,
            "elements": [
                "enderio:block_reinforced_obsidian@0"
            ]
        },
        {
            "x": -1,
            "y": 0,
            "z": -1,
            "elements": [
                "appliedenergistics2:smooth_sky_stone_slab@0"
            ]
        },
        {
            "x": -6,
            "y": -1,
            "z": 1,
            "elements": [
                "appliedenergistics2:smooth_sky_stone_slab@0"
            ]
        },
        {
            "x": -6,
            "y": -1,
            "z": 0,
            "elements": [
                "appliedenergistics2:smooth_sky_stone_stairs@0"
            ]
        },
        {
            "x": -6,
            "y": -1,
            "z": -1,
            "elements": [
                "appliedenergistics2:smooth_sky_stone_slab@0"
            ]
        },
        {
            "x": 0,
            "y": 8,
            "z": -4,
            "elements": [
                "enderio:block_reinforced_obsidian@0"
            ]
        },
        {
            "x": -5,
            "y": 0,
            "z": 0,
            "elements": [
                "modularmachinery:blockcasing@4",
                "ItemInputStrengthen",
                "ItemOutputStrengthen",
                "EnergyInputStrengthen",
                "EnergyOutputStrengthen",
                "FluidInputStrengthen",
                "FluidOutputStrengthen"
            ]
        },
        {
            "x": 1,
            "y": 1,
            "z": -5,
            "elements": [
                "appliedenergistics2:smooth_sky_stone_stairs@5"
            ]
        },
        {
            "x": 3,
            "y": 5,
            "z": -1,
            "elements": [
                "enderio:block_reinforced_obsidian@0"
            ]
        },
        {
            "x": 3,
            "y": 5,
            "z": 2,
            "elements": [
                "enderio:block_reinforced_obsidian@0"
            ]
        },
        {
            "x": 3,
            "y": 5,
            "z": 1,
            "elements": [
                "enderio:block_reinforced_obsidian@0"
            ]
        },
        {
            "x": -3,
            "y": 9,
            "z": 2,
            "elements": [
                "enderio:block_reinforced_obsidian@0"
            ]
        },
        {
            "x": -3,
            "y": 9,
            "z": 1,
            "elements": [
                "enderio:block_reinforced_obsidian@0"
            ]
        },
        {
            "x": 5,
            "y": -1,
            "z": 3,
            "elements": [
                "appliedenergistics2:smooth_sky_stone_slab@0"
            ]
        },
        {
            "x": 1,
            "y": 1,
            "z": 5,
            "elements": [
                "appliedenergistics2:smooth_sky_stone_stairs@5"
            ]
        },
        {
            "x": -3,
            "y": 9,
            "z": -1,
            "elements": [
                "enderio:block_reinforced_obsidian@0"
            ]
        },
        {
            "x": -3,
            "y": 9,
            "z": -2,
            "elements": [
                "enderio:block_reinforced_obsidian@0"
            ]
        },
        {
            "x": 4,
            "y": 0,
            "z": 0,
            "elements": [
                "appliedenergistics2:smooth_sky_stone_slab@0"
            ]
        },
        {
            "x": -2,
            "y": 5,
            "z": 3,
            "elements": [
                "enderio:block_reinforced_obsidian@0"
            ]
        },
        {
            "x": -2,
            "y": 5,
            "z": -3,
            "elements": [
                "enderio:block_reinforced_obsidian@0"
            ]
        },
        {
            "x": 5,
            "y": -1,
            "z": -3,
            "elements": [
                "appliedenergistics2:smooth_sky_stone_slab@0"
            ]
        },
        {
            "x": 5,
            "y": -1,
            "z": -2,
            "elements": [
                "appliedenergistics2:smooth_sky_stone_slab@0"
            ]
        },
        {
            "x": 5,
            "y": -1,
            "z": 1,
            "elements": [
                "appliedenergistics2:smooth_sky_stone_stairs@3"
            ]
        },
        {
            "x": -2,
            "y": -1,
            "z": 4,
            "elements": [
                "appliedenergistics2:smooth_sky_stone_stairs@3"
            ]
        },
        {
            "x": 2,
            "y": 11,
            "z": 0,
            "elements": [
                "enderio:block_reinforced_obsidian@0"
            ]
        },
        {
            "x": 5,
            "y": -1,
            "z": 2,
            "elements": [
                "appliedenergistics2:smooth_sky_stone_slab@0"
            ]
        },
        {
            "x": -2,
            "y": -1,
            "z": 5,
            "elements": [
                "appliedenergistics2:smooth_sky_stone_slab@0"
            ]
        },
        {
            "x": 5,
            "y": -1,
            "z": -1,
            "elements": [
                "appliedenergistics2:smooth_sky_stone_stairs@2"
            ]
        },
        {
            "x": -2,
            "y": -1,
            "z": 2,
            "elements": [
                "appliedenergistics2:smooth_sky_stone_stairs@0"
            ]
        },
        {
            "x": 5,
            "y": -1,
            "z": 0,

            "elements": [
                "modularmachinery:blockcasing@4"
            ]
        },
        {
            "x": -2,
            "y": -1,
            "z": 3,
            "elements": [
                "appliedenergistics2:smooth_sky_stone_stairs@1"
            ]
        },
        {
            "x": 1,
            "y": 7,
            "z": 4,
            "elements": [
                "enderio:block_reinforced_obsidian@0"
            ]
        },
        {
            "x": -2,
            "y": -1,
            "z": 0,

            "elements": [
                "modularmachinery:blockcasing@4"
            ]
        },
        {
            "x": -2,
            "y": -1,
            "z": 1,
            "elements": [
                "appliedenergistics2:smooth_sky_stone_stairs@3"
            ]
        },
        {
            "x": -2,
            "y": -1,
            "z": -2,
            "elements": [
                "appliedenergistics2:smooth_sky_stone_stairs@2"
            ]
        },
        {
            "x": -2,
            "y": -1,
            "z": -1,
            "elements": [
                "appliedenergistics2:smooth_sky_stone_stairs@0"
            ]
        },
        {
            "x": -2,
            "y": -1,
            "z": -4,
            "elements": [
                "appliedenergistics2:smooth_sky_stone_stairs@1"
            ]
        },
        {
            "x": -2,
            "y": -1,
            "z": -3,
            "elements": [
                "appliedenergistics2:smooth_sky_stone_stairs@1"
            ]
        },
        {
            "x": -2,
            "y": -1,
            "z": -5,
            "elements": [
                "appliedenergistics2:smooth_sky_stone_slab@0"
            ]
        },
        {
            "x": 4,
            "y": 6,
            "z": 0,
            "elements": [
                "enderio:block_reinforced_obsidian@0"
            ]
        },
        {
            "x": 4,
            "y": 6,
            "z": -1,
            "elements": [
                "enderio:block_reinforced_obsidian@0"
            ]
        },
        {
            "x": 0,
            "y": 8,
            "z": 4,
            "elements": [
                "enderio:block_reinforced_obsidian@0"
            ]
        },
        {
            "x": 3,
            "y": 10,
            "z": -1,
            "elements": [
                "enderio:block_reinforced_obsidian@0"
            ]
        },
        {
            "x": 3,
            "y": 10,
            "z": 1,
            "elements": [
                "enderio:block_reinforced_obsidian@0"
            ]
        },
        {
            "x": 3,
            "y": 10,
            "z": 0,
            "elements": [
                "enderio:block_reinforced_obsidian@0"
            ]
        },
        {
            "x": 4,
            "y": 6,
            "z": 1,
            "elements": [
                "enderio:block_reinforced_obsidian@0"
            ]
        },
        {
            "x": 1,
            "y": 10,
            "z": 3,
            "elements": [
                "enderio:block_reinforced_obsidian@0"
            ]
        },
        {
            "x": 1,
            "y": 10,
            "z": 2,
            "elements": [
                "enderio:block_reinforced_obsidian@0"
            ]
        },
        {
            "x": 1,
            "y": 10,
            "z": -3,
            "elements": [
                "enderio:block_reinforced_obsidian@0"
            ]
        },
        {
            "x": 1,
            "y": 0,
            "z": 1,
            "elements": [
                "appliedenergistics2:smooth_sky_stone_slab@0"
            ]
        },
        {
            "x": 1,
            "y": 0,
            "z": 0,
            "elements": [
                "appliedenergistics2:smooth_sky_stone_stairs@0"
            ]
        },
        {
            "x": 1,
            "y": 0,
            "z": -1,
            "elements": [
                "appliedenergistics2:smooth_sky_stone_slab@0"
            ]
        },
        {
            "x": 1,
            "y": 10,
            "z": -2,
            "elements": [
                "enderio:block_reinforced_obsidian@0"
            ]
        },
        {
            "x": -4,
            "y": 7,
            "z": -1,
            "elements": [
                "enderio:block_reinforced_obsidian@0"
            ]
        },
        {
            "x": -4,
            "y": 7,
            "z": -2,
            "elements": [
                "enderio:block_reinforced_obsidian@0"
            ]
        },
        {
            "x": -4,
            "y": 7,
            "z": 1,
            "elements": [
                "enderio:block_reinforced_obsidian@0"
            ]
        },
        {
            "x": -4,
            "y": 7,
            "z": 0,
            "elements": [
                "enderio:block_reinforced_obsidian@0"
            ]
        },
        {
            "x": 3,
            "y": -1,
            "z": 5,
            "elements": [
                "appliedenergistics2:smooth_sky_stone_slab@0"
            ]
        },
        {
            "x": -4,
            "y": 7,
            "z": 2,
            "elements": [
                "enderio:block_reinforced_obsidian@0"
            ]
        },
        {
            "x": -5,
            "y": -1,
            "z": -2,
            "elements": [
                "appliedenergistics2:smooth_sky_stone_slab@0"
            ]
        },
        {
            "x": 3,
            "y": -1,
            "z": 3,

            "elements": [
                "modularmachinery:blockcasing@4"
            ]
        },
        {
            "x": -5,
            "y": -1,
            "z": -3,
            "elements": [
                "appliedenergistics2:smooth_sky_stone_slab@0"
            ]
        },
        {
            "x": -2,
            "y": 6,
            "z": 3,
            "elements": [
                "enderio:block_reinforced_obsidian@0"
            ]
        },
        {
            "x": 3,
            "y": -1,
            "z": 4,
            "elements": [
                "appliedenergistics2:smooth_sky_stone_stairs@3"
            ]
        },
        {
            "x": -5,
            "y": -1,
            "z": 0,

            "elements": [
                "modularmachinery:blockcasing@4"
            ]
        },
        {
            "x": 3,
            "y": -1,
            "z": 1,
            "elements": [
                "appliedenergistics2:smooth_sky_stone_stairs@3"
            ]
        },
        {
            "x": -1,
            "y": 11,
            "z": 1,
            "elements": [
                "enderio:block_reinforced_obsidian@0"
            ]
        },
        {
            "x": -5,
            "y": -1,
            "z": -1,
            "elements": [
                "appliedenergistics2:smooth_sky_stone_stairs@2"
            ]
        },
        {
            "x": 3,
            "y": -1,
            "z": 2,
            "elements": [
                "appliedenergistics2:smooth_sky_stone_stairs@2"
            ]
        },
        {
            "x": 3,
            "y": -1,
            "z": -1,
            "elements": [
                "appliedenergistics2:smooth_sky_stone_stairs@2"
            ]
        },
        {
            "x": -1,
            "y": 11,
            "z": -1,
            "elements": [
                "enderio:block_reinforced_obsidian@0"
            ]
        },
        {
            "x": -5,
            "y": -1,
            "z": 2,
            "elements": [
                "appliedenergistics2:smooth_sky_stone_slab@0"
            ]
        },
        {
            "x": 3,
            "y": -1,
            "z": 0,

            "elements": [
                "modularmachinery:blockcasing@4"
            ]
        },
        {
            "x": -1,
            "y": 11,
            "z": 0,
            "elements": [
                "enderio:block_reinforced_obsidian@0"
            ]
        },
        {
            "x": -5,
            "y": -1,
            "z": 1,
            "elements": [
                "appliedenergistics2:smooth_sky_stone_stairs@3"
            ]
        },
        {
            "x": 3,
            "y": -1,
            "z": -3,

            "elements": [
                "modularmachinery:blockcasing@4"
            ]
        },
        {
            "x": 1,
            "y": 7,
            "z": -4,
            "elements": [
                "enderio:block_reinforced_obsidian@0"
            ]
        },
        {
            "x": 3,
            "y": -1,
            "z": -2,
            "elements": [
                "appliedenergistics2:smooth_sky_stone_stairs@3"
            ]
        },
        {
            "x": -5,
            "y": -1,
            "z": 3,
            "elements": [
                "appliedenergistics2:smooth_sky_stone_slab@0"
            ]
        },
        {
            "x": 3,
            "y": -1,
            "z": -5,
            "elements": [
                "appliedenergistics2:smooth_sky_stone_slab@0"
            ]
        },
        {
            "x": 3,
            "y": -1,
            "z": -4,
            "elements": [
                "appliedenergistics2:smooth_sky_stone_stairs@2"
            ]
        },
        {
            "x": 4,
            "y": 7,
            "z": 2,
            "elements": [
                "enderio:block_reinforced_obsidian@0"
            ]
        },
        {
            "x": 2,
            "y": 8,
            "z": 3,
            "elements": [
                "enderio:block_reinforced_obsidian@0"
            ]
        },
        {
            "x": 4,
            "y": 7,
            "z": 1,
            "elements": [
                "enderio:block_reinforced_obsidian@0"
            ]
        },
        {
            "x": 4,
            "y": 7,
            "z": 0,
            "elements": [
                "enderio:block_reinforced_obsidian@0"
            ]
        },
        {
            "x": 4,
            "y": 7,
            "z": -1,
            "elements": [
                "enderio:block_reinforced_obsidian@0"
            ]
        },
        {
            "x": 4,
            "y": 7,
            "z": -2,
            "elements": [
                "enderio:block_reinforced_obsidian@0"
            ]
        },
        {
            "x": 2,
            "y": 8,
            "z": -3,
            "elements": [
                "enderio:block_reinforced_obsidian@0"
            ]
        },
        {
            "x": -2,
            "y": 3,
            "z": 0,
            "elements": [
                "enderio:block_reinforced_obsidian@0"
            ]
        },
        {
            "x": 1,
            "y": 3,
            "z": 1,
            "elements": [
                "enderio:block_reinforced_obsidian@0"
            ]
        },
        {
            "x": 1,
            "y": 3,
            "z": -1,
            "elements": [
                "enderio:block_reinforced_obsidian@0"
            ]
        },
        {
            "x": 1,
            "y": 3,
            "z": 0,
            "elements": [
                "enderio:block_reinforced_obsidian@0"
            ]
        },
        {
            "x": 2,
            "y": 5,
            "z": 3,
            "elements": [
                "enderio:block_reinforced_obsidian@0"
            ]
        },
        {
            "x": 2,
            "y": 5,
            "z": -3,
            "elements": [
                "enderio:block_reinforced_obsidian@0"
            ]
        },
        {
            "x": -2,
            "y": 0,
            "z": 0,
            "elements": [
                "appliedenergistics2:smooth_sky_stone_slab@0"
            ]
        },
        {
            "x": 1,
            "y": 6,
            "z": 4,
            "elements": [
                "enderio:block_reinforced_obsidian@0"
            ]
        },
        {
            "x": -3,
            "y": 1,
            "z": 3,
            "elements": [
                "appliedenergistics2:smooth_sky_stone_slab@0"
            ]
        },
        {
            "x": -3,
            "y": 1,
            "z": -3,
            "elements": [
                "appliedenergistics2:smooth_sky_stone_slab@0"
            ]
        },
        {
            "x": -5,
            "y": 2,
            "z": -1,
            "elements": [
                "appliedenergistics2:smooth_sky_stone_slab@0"
            ]
        },
        {
            "x": 1,
            "y": 6,
            "z": -4,
            "elements": [
                "enderio:block_reinforced_obsidian@0"
            ]
        },
        {
            "x": -5,
            "y": 2,
            "z": 0,
            "elements": [
                "appliedenergistics2:smooth_sky_stone_stairs@0"
            ]
        },
        {
            "x": -5,
            "y": 2,
            "z": 1,
            "elements": [
                "appliedenergistics2:smooth_sky_stone_slab@0"
            ]
        },
        {
            "x": -1,
            "y": 5,
            "z": -3,
            "elements": [
                "enderio:block_reinforced_obsidian@0"
            ]
        },
        {
            "x": 2,
            "y": -1,
            "z": -5,
            "elements": [
                "appliedenergistics2:smooth_sky_stone_slab@0"
            ]
        },
        {
            "x": -4,
            "y": 8,
            "z": 0,
            "elements": [
                "enderio:block_reinforced_obsidian@0"
            ]
        },
        {
            "x": -4,
            "y": 8,
            "z": -1,
            "elements": [
                "enderio:block_reinforced_obsidian@0"
            ]
        },
        {
            "x": 2,
            "y": -1,
            "z": -3,
            "elements": [
                "appliedenergistics2:smooth_sky_stone_stairs@0"
            ]
        },
        {
            "x": 2,
            "y": -1,
            "z": -4,
            "elements": [
                "appliedenergistics2:smooth_sky_stone_stairs@2"
            ]
        },
        {
            "x": -4,
            "y": 8,
            "z": 1,
            "elements": [
                "enderio:block_reinforced_obsidian@0"
            ]
        },
        {
            "x": -3,
            "y": 4,
            "z": 1,
            "elements": [
                "enderio:block_reinforced_obsidian@0"
            ]
        },
        {
            "x": -3,
            "y": 4,
            "z": 0,
            "elements": [
                "enderio:block_reinforced_obsidian@0"
            ]
        },
        {
            "x": -3,
            "y": 4,
            "z": -1,
            "elements": [
                "enderio:block_reinforced_obsidian@0"
            ]
        },
        {
            "x": 2,
            "y": -1,
            "z": 3,
            "elements": [
                "appliedenergistics2:smooth_sky_stone_stairs@0"
            ]
        },
        {
            "x": 2,
            "y": -1,
            "z": 2,
            "elements": [
                "appliedenergistics2:smooth_sky_stone_stairs@3"
            ]
        },
        {
            "x": 2,
            "y": -1,
            "z": 5,
            "elements": [
                "appliedenergistics2:smooth_sky_stone_slab@0"
            ]
        },
        {
            "x": 2,
            "y": -1,
            "z": 4,
            "elements": [
                "appliedenergistics2:smooth_sky_stone_stairs@3"
            ]
        },
        {
            "x": 2,
            "y": -1,
            "z": -1,
            "elements": [
                "appliedenergistics2:smooth_sky_stone_stairs@2"
            ]
        },
        {
            "x": 2,
            "y": -1,
            "z": -2,
            "elements": [
                "appliedenergistics2:smooth_sky_stone_stairs@1"
            ]
        },
        {
            "x": 2,
            "y": -1,
            "z": 1,
            "elements": [
                "appliedenergistics2:smooth_sky_stone_stairs@1"
            ]
        },
        {
            "x": 2,
            "y": -1,
            "z": 0,

            "elements": [
                "modularmachinery:blockcasing@4"
            ]
        },
        {
            "x": 6,
            "y": -1,
            "z": 1,
            "elements": [
                "appliedenergistics2:smooth_sky_stone_slab@0"
            ]
        },
        {
            "x": 6,
            "y": -1,
            "z": 0,
            "elements": [
                "appliedenergistics2:smooth_sky_stone_stairs@1"
            ]
        },
        {
            "x": 6,
            "y": -1,
            "z": -1,
            "elements": [
                "appliedenergistics2:smooth_sky_stone_slab@0"
            ]
        },
        {
            "x": 0,
            "y": 1,
            "z": -5,
            "elements": [
                "modularmachinery:blockcasing@4",
                "ItemInputStrengthen",
                "ItemOutputStrengthen",
                "EnergyInputStrengthen",
                "EnergyOutputStrengthen",
                "FluidInputStrengthen",
                "FluidOutputStrengthen"
            ]
        },
        {
            "x": -1,
            "y": 8,
            "z": -4,
            "elements": [
                "enderio:block_reinforced_obsidian@0"
            ]
        },
        {
            "x": -2,
            "y": 6,
            "z": -3,
            "elements": [
                "enderio:block_reinforced_obsidian@0"
            ]
        },
        {
            "x": -1,
            "y": 2,
            "z": 5,
            "elements": [
                "appliedenergistics2:smooth_sky_stone_slab@0"
            ]
        },
        {
            "x": 0,
            "y": 4,
            "z": 3,
            "elements": [
                "enderio:block_reinforced_obsidian@0"
            ]
        },
        {
            "x": -1,
            "y": 8,
            "z": 4,
            "elements": [
                "enderio:block_reinforced_obsidian@0"
            ]
        },
        {
            "x": -2,
            "y": 9,
            "z": -3,
            "elements": [
                "enderio:block_reinforced_obsidian@0"
            ]
        },
        {
            "x": -1,
            "y": 2,
            "z": -5,
            "elements": [
                "appliedenergistics2:smooth_sky_stone_slab@0"
            ]
        },
        {
            "x": 0,
            "y": 1,
            "z": 5,
            "elements": [
                "modularmachinery:blockcasing@4",
                "ItemInputStrengthen",
                "ItemOutputStrengthen",
                "EnergyInputStrengthen",
                "EnergyOutputStrengthen",
                "FluidInputStrengthen",
                "FluidOutputStrengthen"
            ]
        },
        {
            "x": -1,
            "y": 5,
            "z": 3,
            "elements": [
                "enderio:block_reinforced_obsidian@0"
            ]
        },
        {
            "x": -2,
            "y": 9,
            "z": 3,
            "elements": [
                "enderio:block_reinforced_obsidian@0"
            ]
        },
        {
            "x": 1,
            "y": 5,
            "z": 3,
            "elements": [
                "enderio:block_reinforced_obsidian@0"
            ]
        },
        {
            "x": -3,
            "y": 0,
            "z": 3,
            "elements": [
                "modularmachinery:blockcasing@4",
                "ItemInputStrengthen",
                "ItemOutputStrengthen",
                "EnergyInputStrengthen",
                "EnergyOutputStrengthen",
                "FluidInputStrengthen",
                "FluidOutputStrengthen"
            ]
        },
        {
            "x": -2,
            "y": 8,
            "z": -3,
            "elements": [
                "enderio:block_reinforced_obsidian@0"
            ]
        },
        {
            "x": -1,
            "y": 9,
            "z": 3,
            "elements": [
                "enderio:block_reinforced_obsidian@0"
            ]
        },
        {
            "x": 3,
            "y": 1,
            "z": -3,
            "elements": [
                "appliedenergistics2:smooth_sky_stone_slab@0"
            ]
        },
        {
            "x": -4,
            "y": -1,
            "z": -2,
            "elements": [
                "appliedenergistics2:smooth_sky_stone_stairs@0"
            ]
        },
        {
            "x": -4,
            "y": -1,
            "z": -1,
            "elements": [
                "appliedenergistics2:smooth_sky_stone_stairs@2"
            ]
        },
        {
            "x": 4,
            "y": 9,
            "z": 0,
            "elements": [
                "enderio:block_reinforced_obsidian@0"
            ]
        },
        {
            "x": -4,
            "y": -1,
            "z": -4,
            "elements": [
                "appliedenergistics2:smooth_sky_stone_slab@0"
            ]
        },
        {
            "x": -4,
            "y": -1,
            "z": -3,
            "elements": [
                "appliedenergistics2:smooth_sky_stone_stairs@0"
            ]
        },
        {
            "x": -4,
            "y": -1,
            "z": 2,
            "elements": [
                "appliedenergistics2:smooth_sky_stone_stairs@0"
            ]
        },
        {
            "x": -4,
            "y": -1,
            "z": 3,
            "elements": [
                "appliedenergistics2:smooth_sky_stone_stairs@0"
            ]
        },
        {
            "x": 0,
            "y": 4,
            "z": -3,
            "elements": [
                "enderio:block_reinforced_obsidian@0"
            ]
        },
        {
            "x": -4,
            "y": -1,
            "z": 0,

            "elements": [
                "modularmachinery:blockcasing@4"
            ]
        },
        {
            "x": -4,
            "y": -1,
            "z": 1,
            "elements": [
                "appliedenergistics2:smooth_sky_stone_stairs@3"
            ]
        },
        {
            "x": -3,
            "y": 7,
            "z": -3,
            "elements": [
                "enderio:block_reinforced_obsidian@0"
            ]
        },
        {
            "x": -2,
            "y": 8,
            "z": 3,
            "elements": [
                "enderio:block_reinforced_obsidian@0"
            ]
        },
        {
            "x": -3,
            "y": 0,
            "z": -3,
            "elements": [
                "modularmachinery:blockcasing@4",
                "ItemInputStrengthen",
                "ItemOutputStrengthen",
                "EnergyInputStrengthen",
                "EnergyOutputStrengthen",
                "FluidInputStrengthen",
                "FluidOutputStrengthen"
            ]
        },
        {
            "x": 2,
            "y": 6,
            "z": 3,
            "elements": [
                "enderio:block_reinforced_obsidian@0"
            ]
        },
        {
            "x": 1,
            "y": 5,
            "z": -3,
            "elements": [
                "enderio:block_reinforced_obsidian@0"
            ]
        },
        {
            "x": -3,
            "y": 0,
            "z": 0,
            "elements": [
                "appliedenergistics2:smooth_sky_stone_slab@0"
            ]
        },
        {
            "x": 3,
            "y": 8,
            "z": -3,
            "elements": [
                "enderio:block_reinforced_obsidian@0"
            ]
        },
        {
            "x": -4,
            "y": 5,
            "z": 0,
            "elements": [
                "enderio:block_reinforced_obsidian@0"
            ]
        },
        {
            "x": 0,
            "y": 10,
            "z": 3,
            "elements": [
                "enderio:block_reinforced_obsidian@0"
            ]
        },
        {
            "x": 3,
            "y": 8,
            "z": -2,
            "elements": [
                "enderio:block_reinforced_obsidian@0"
            ]
        },
        {
            "x": -3,
            "y": 7,
            "z": 3,
            "elements": [
                "enderio:block_reinforced_obsidian@0"
            ]
        },
        {
            "x": 0,
            "y": 10,
            "z": -3,
            "elements": [
                "enderio:block_reinforced_obsidian@0"
            ]
        },
        {
            "x": 2,
            "y": 6,
            "z": -3,
            "elements": [
                "enderio:block_reinforced_obsidian@0"
            ]
        },
        {
            "x": 3,
            "y": 8,
            "z": 3,
            "elements": [
                "enderio:block_reinforced_obsidian@0"
            ]
        },
        {
            "x": 3,
            "y": 8,
            "z": 2,
            "elements": [
                "enderio:block_reinforced_obsidian@0"
            ]
        },
        {
            "x": -1,
            "y": 3,
            "z": 1,
            "elements": [
                "enderio:block_reinforced_obsidian@0"
            ]
        },
        {
            "x": -1,
            "y": 3,
            "z": 0,
            "elements": [
                "enderio:block_reinforced_obsidian@0"
            ]
        },
        {
            "x": -1,
            "y": 3,
            "z": -1,
            "elements": [
                "enderio:block_reinforced_obsidian@0"
            ]
        },
        {
            "x": 1,
            "y": -1,
            "z": 2,
            "elements": [
                "appliedenergistics2:smooth_sky_stone_stairs@1"
            ]
        },
        {
            "x": 1,
            "y": -1,
            "z": 1,

            "elements": [
                "modularmachinery:blockcasing@4"
            ]
        },
        {
            "x": 1,
            "y": -1,
            "z": 0,

            "elements": [
                "modularmachinery:blockcasing@4"
            ]
        },
        {
            "x": 1,
            "y": -1,
            "z": -1,

            "elements": [
                "modularmachinery:blockcasing@4"
            ]
        },
        {
            "x": 1,
            "y": -1,
            "z": 6,
            "elements": [
                "appliedenergistics2:smooth_sky_stone_slab@0"
            ]
        },
        {
            "x": 1,
            "y": -1,
            "z": 5,
            "elements": [
                "appliedenergistics2:smooth_sky_stone_stairs@1"
            ]
        },
        {
            "x": 3,
            "y": 1,
            "z": 3,
            "elements": [
                "appliedenergistics2:smooth_sky_stone_slab@0"
            ]
        },
        {
            "x": 1,
            "y": -1,
            "z": 4,
            "elements": [
                "appliedenergistics2:smooth_sky_stone_stairs@1"
            ]
        },
        {
            "x": 1,
            "y": -1,
            "z": 3,
            "elements": [
                "appliedenergistics2:smooth_sky_stone_stairs@1"
            ]
        },
        {
            "x": 1,
            "y": -1,
            "z": -6,
            "elements": [
                "appliedenergistics2:smooth_sky_stone_slab@0"
            ]
        },
        {
            "x": 1,
            "y": -1,
            "z": -2,
            "elements": [
                "appliedenergistics2:smooth_sky_stone_stairs@2"
            ]
        },
        {
            "x": 1,
            "y": -1,
            "z": -3,
            "elements": [
                "appliedenergistics2:smooth_sky_stone_stairs@1"
            ]
        },
        {
            "x": 1,
            "y": -1,
            "z": -4,
            "elements": [
                "appliedenergistics2:smooth_sky_stone_stairs@1"
            ]
        },
        {
            "x": 1,
            "y": -1,
            "z": -5,
            "elements": [
                "appliedenergistics2:smooth_sky_stone_stairs@1"
            ]
        },
        {
            "x": 0,
            "y": 3,
            "z": -1,
            "elements": [
                "enderio:block_reinforced_obsidian@0"
            ]
        },
        {
            "x": 0,
            "y": 3,
            "z": -2,
            "elements": [
                "enderio:block_reinforced_obsidian@0"
            ]
        },
        {
            "x": 0,
            "y": 3,
            "z": 1,
            "elements": [
                "enderio:block_reinforced_obsidian@0"
            ]
        },
        {
            "x": 0,
            "y": 3,
            "z": 0,
            "elements": [
                "enderio:block_reinforced_obsidian@0"
            ]
        },
        {
            "x": 0,
            "y": 3,
            "z": 2,
            "elements": [
                "enderio:block_reinforced_obsidian@0"
            ]
        },
        {
            "x": -2,
            "y": 7,
            "z": 4,
            "elements": [
                "enderio:block_reinforced_obsidian@0"
            ]
        },
        {
            "x": -2,
            "y": 7,
            "z": -4,
            "elements": [
                "enderio:block_reinforced_obsidian@0"
            ]
        },
        {
            "x": 0,
            "y": 11,
            "z": 2,
            "elements": [
                "enderio:block_reinforced_obsidian@0"
            ]
        },
        {
            "x": 0,
            "y": 11,
            "z": 1,
            "elements": [
                "enderio:block_reinforced_obsidian@0"
            ]
        },
        {
            "x": 0,
            "y": 11,
            "z": 0,
            "elements": [
                "enderio:block_reinforced_obsidian@0"
            ]
        },
        {
            "x": 0,
            "y": 11,
            "z": -1,
            "elements": [
                "enderio:block_reinforced_obsidian@0"
            ]
        },
        {
            "x": 0,
            "y": 11,
            "z": -2,
            "elements": [
                "enderio:block_reinforced_obsidian@0"
            ]
        },
        {
            "x": 0,
            "y": 5,
            "z": 4,
            "elements": [
                "enderio:block_reinforced_obsidian@0"
            ]
        },
        {
            "x": 0,
            "y": 5,
            "z": -4,
            "elements": [
                "enderio:block_reinforced_obsidian@0"
            ]
        },
        {
            "x": -4,
            "y": -1,
            "z": 4,
            "elements": [
                "appliedenergistics2:smooth_sky_stone_slab@0"
            ]
        },
        {
            "x": 3,
            "y": 7,
            "z": 3,
            "elements": [
                "enderio:block_reinforced_obsidian@0"
            ]
        },
        {
            "x": 3,
            "y": 7,
            "z": -3,
            "elements": [
                "enderio:block_reinforced_obsidian@0"
            ]
        },
        {
            "x": -1,
            "y": 9,
            "z": -3,
            "elements": [
                "enderio:block_reinforced_obsidian@0"
            ]
        },
        {
            "x": -3,
            "y": 6,
            "z": 3,
            "elements": [
                "enderio:block_reinforced_obsidian@0"
            ]
        },
        {
            "x": -3,
            "y": 6,
            "z": 2,
            "elements": [
                "enderio:block_reinforced_obsidian@0"
            ]
        },
        {
            "x": 1,
            "y": 4,
            "z": -2,
            "elements": [
                "enderio:block_reinforced_obsidian@0"
            ]
        },
        {
            "x": 5,
            "y": 2,
            "z": -1,
            "elements": [
                "appliedenergistics2:smooth_sky_stone_slab@0"
            ]
        },
        {
            "x": 1,
            "y": 4,
            "z": -3,
            "elements": [
                "enderio:block_reinforced_obsidian@0"
            ]
        },
        {
            "x": -3,
            "y": 6,
            "z": -2,
            "elements": [
                "enderio:block_reinforced_obsidian@0"
            ]
        },
        {
            "x": -3,
            "y": 6,
            "z": -3,
            "elements": [
                "enderio:block_reinforced_obsidian@0"
            ]
        },
        {
            "x": 2,
            "y": 0,
            "z": 0,
            "elements": [
                "appliedenergistics2:smooth_sky_stone_slab@0"
            ]
        },
        {
            "x": 5,
            "y": 2,
            "z": 1,
            "elements": [
                "appliedenergistics2:smooth_sky_stone_slab@0"
            ]
        },
        {
            "x": 5,
            "y": 2,
            "z": 0,
            "elements": [
                "appliedenergistics2:smooth_sky_stone_stairs@1"
            ]
        },
        {
            "x": 1,
            "y": 4,
            "z": 2,
            "elements": [
                "enderio:block_reinforced_obsidian@0"
            ]
        },
        {
            "x": 1,
            "y": 4,
            "z": 3,
            "elements": [
                "enderio:block_reinforced_obsidian@0"
            ]
        },
        {
            "x": -3,
            "y": 5,
            "z": -1,
            "elements": [
                "enderio:block_reinforced_obsidian@0"
            ]
        },
        {
            "x": -3,
            "y": 5,
            "z": -2,
            "elements": [
                "enderio:block_reinforced_obsidian@0"
            ]
        },
        {
            "x": 0,
            "y": 2,
            "z": 5,
            "elements": [
                "appliedenergistics2:smooth_sky_stone_stairs@3"
            ]
        },
        {
            "x": 3,
            "y": 6,
            "z": -3,
            "elements": [
                "enderio:block_reinforced_obsidian@0"
            ]
        },
        {
            "x": -3,
            "y": 5,
            "z": 2,
            "elements": [
                "enderio:block_reinforced_obsidian@0"
            ]
        },
        {
            "x": -3,
            "y": 5,
            "z": 1,
            "elements": [
                "enderio:block_reinforced_obsidian@0"
            ]
        },
        {
            "x": 3,
            "y": 6,
            "z": -2,
            "elements": [
                "enderio:block_reinforced_obsidian@0"
            ]
        },
        {
            "x": 0,
            "y": -1,
            "z": -5,

            "elements": [
                "modularmachinery:blockcasing@4"
            ]
        },
        {
            "x": 0,
            "y": -1,
            "z": -6,
            "elements": [
                "appliedenergistics2:smooth_sky_stone_stairs@2"
            ]
        },
        {
            "x": 0,
            "y": -1,
            "z": -3,

            "elements": [
                "modularmachinery:blockcasing@4"
            ]
        },
        {
            "x": 3,
            "y": 6,
            "z": 3,
            "elements": [
                "enderio:block_reinforced_obsidian@0"
            ]
        },
        {
            "x": 0,
            "y": -1,
            "z": -4,

            "elements": [
                "modularmachinery:blockcasing@4"
            ]
        },
        {
            "x": 3,
            "y": 6,
            "z": 2,
            "elements": [
                "enderio:block_reinforced_obsidian@0"
            ]
        },
        {
            "x": 0,
            "y": -1,
            "z": -1,

            "elements": [
                "modularmachinery:blockcasing@4"
            ]
        },
        {
            "x": 0,
            "y": -1,
            "z": -2,

            "elements": [
                "modularmachinery:blockcasing@4"
            ]
        },
        {
            "x": -1,
            "y": 4,
            "z": -2,
            "elements": [
                "enderio:block_reinforced_obsidian@0"
            ]
        },
        {
            "x": 3,
            "y": 9,
            "z": -1,
            "elements": [
                "enderio:block_reinforced_obsidian@0"
            ]
        },
        {
            "x": -1,
            "y": 1,
            "z": 5,
            "elements": [
                "appliedenergistics2:smooth_sky_stone_stairs@4"
            ]
        },
        {
            "x": -1,
            "y": 4,
            "z": -3,
            "elements": [
                "enderio:block_reinforced_obsidian@0"
            ]
        },
        {
            "x": 3,
            "y": 9,
            "z": 2,
            "elements": [
                "enderio:block_reinforced_obsidian@0"
            ]
        },
        {
            "x": 0,
            "y": 2,
            "z": -5,
            "elements": [
                "appliedenergistics2:smooth_sky_stone_stairs@2"
            ]
        },
        {
            "x": 3,
            "y": 9,
            "z": 1,
            "elements": [
                "enderio:block_reinforced_obsidian@0"
            ]
        },
        {
            "x": -1,
            "y": 4,
            "z": 3,
            "elements": [
                "enderio:block_reinforced_obsidian@0"
            ]
        },
        {
            "x": -1,
            "y": 4,
            "z": 2,
            "elements": [
                "enderio:block_reinforced_obsidian@0"
            ]
        },
        {
            "x": 3,
            "y": 9,
            "z": -2,
            "elements": [
                "enderio:block_reinforced_obsidian@0"
            ]
        },
        {
            "x": 0,
            "y": 9,
            "z": 4,
            "elements": [
                "enderio:block_reinforced_obsidian@0"
            ]
        },
        {
            "x": -1,
            "y": 1,
            "z": -5,
            "elements": [
                "appliedenergistics2:smooth_sky_stone_stairs@4"
            ]
        },
        {
            "x": 0,
            "y": 9,
            "z": -4,
            "elements": [
                "enderio:block_reinforced_obsidian@0"
            ]
        },
        {
            "x": -2,
            "y": 10,
            "z": -2,
            "elements": [
                "enderio:block_reinforced_obsidian@0"
            ]
        },
        {
            "x": -2,
            "y": 10,
            "z": -1,
            "elements": [
                "enderio:block_reinforced_obsidian@0"
            ]
        },
        {
            "x": -2,
            "y": 10,
            "z": 1,
            "elements": [
                "enderio:block_reinforced_obsidian@0"
            ]
        },
        {
            "x": -2,
            "y": 10,
            "z": 2,
            "elements": [
                "enderio:block_reinforced_obsidian@0"
            ]
        },
        {
            "x": -1,
            "y": 7,
            "z": 4,
            "elements": [
                "enderio:block_reinforced_obsidian@0"
            ]
        },
        {
            "x": 0,
            "y": 6,
            "z": -4,
            "elements": [
                "enderio:block_reinforced_obsidian@0"
            ]
        },
        {
            "x": 0,
            "y": -1,
            "z": 1,

            "elements": [
                "modularmachinery:blockcasing@4"
            ]
        },
        {
            "x": 0,
            "y": -1,
            "z": 0,

            "elements": [
                "modularmachinery:blockcasing@4"
            ]
        },
        {
            "x": 0,
            "y": -1,
            "z": 3,

            "elements": [
                "modularmachinery:blockcasing@4"
            ]
        },
        {
            "x": 0,
            "y": -1,
            "z": 2,

            "elements": [
                "modularmachinery:blockcasing@4"
            ]
        },
        {
            "x": 0,
            "y": -1,
            "z": 5,

            "elements": [
                "modularmachinery:blockcasing@4"
            ]
        },
        {
            "x": 0,
            "y": -1,
            "z": 4,

            "elements": [
                "modularmachinery:blockcasing@4"
            ]
        },
        {
            "x": -3,
            "y": 8,
            "z": 3,
            "elements": [
                "enderio:block_reinforced_obsidian@0"
            ]
        },
        {
            "x": -3,
            "y": 8,
            "z": 2,
            "elements": [
                "enderio:block_reinforced_obsidian@0"
            ]
        },
        {
            "x": 0,
            "y": 6,
            "z": 4,
            "elements": [
                "enderio:block_reinforced_obsidian@0"
            ]
        },
        {
            "x": 0,
            "y": -1,
            "z": 6,
            "elements": [
                "appliedenergistics2:smooth_sky_stone_stairs@3"
            ]
        },
        {
            "x": -3,
            "y": 8,
            "z": -2,
            "elements": [
                "enderio:block_reinforced_obsidian@0"
            ]
        },
        {
            "x": -3,
            "y": 8,
            "z": -3,
            "elements": [
                "enderio:block_reinforced_obsidian@0"
            ]
        },
        {
            "x": -1,
            "y": 7,
            "z": -4,
            "elements": [
                "enderio:block_reinforced_obsidian@0"
            ]
        },
        {
            "x": -1,
            "y": 10,
            "z": -2,
            "elements": [
                "enderio:block_reinforced_obsidian@0"
            ]
        },
        {
            "x": -1,
            "y": 0,
            "z": 1,
            "elements": [
                "appliedenergistics2:smooth_sky_stone_slab@0"
            ]
        },
        {
            "x": -1,
            "y": 0,
            "z": 0,
            "elements": [
                "appliedenergistics2:smooth_sky_stone_stairs@1"
            ]
        },
        {
            "x": 4,
            "y": 8,
            "z": 1,
            "elements": [
                "enderio:block_reinforced_obsidian@0"
            ]
        },
        {
            "x": 5,
            "y": 1,
            "z": 0,
            "elements": [
                "modularmachinery:blockcasing@4",
                "ItemInputStrengthen",
                "ItemOutputStrengthen",
                "EnergyInputStrengthen",
                "EnergyOutputStrengthen",
                "FluidInputStrengthen",
                "FluidOutputStrengthen"
            ]
        },
        {
            "x": 4,
            "y": 8,
            "z": 0,
            "elements": [
                "enderio:block_reinforced_obsidian@0"
            ]
        },
        {
            "x": -1,
            "y": 10,
            "z": 2,
            "elements": [
                "enderio:block_reinforced_obsidian@0"
            ]
        },
        {
            "x": 5,
            "y": 1,
            "z": -1,
            "elements": [
                "appliedenergistics2:smooth_sky_stone_stairs@6"
            ]
        },
        {
            "x": 4,
            "y": 8,
            "z": -1,
            "elements": [
                "enderio:block_reinforced_obsidian@0"
            ]
        },
        {
            "x": -1,
            "y": 10,
            "z": 3,
            "elements": [
                "enderio:block_reinforced_obsidian@0"
            ]
        },
        {
            "x": 3,
            "y": 0,
            "z": -3,
            "elements": [
                "modularmachinery:blockcasing@4",
                "ItemInputStrengthen",
                "ItemOutputStrengthen",
                "EnergyInputStrengthen",
                "EnergyOutputStrengthen",
                "FluidInputStrengthen",
                "FluidOutputStrengthen"
            ]
        },
        {
            "x": -1,
            "y": 10,
            "z": -3,
            "elements": [
                "enderio:block_reinforced_obsidian@0"
            ]
        },
        {
            "x": 2,
            "y": 4,
            "z": -2,
            "elements": [
                "enderio:block_reinforced_obsidian@0"
            ]
        },
        {
            "x": 3,
            "y": 0,
            "z": 3,
            "elements": [
                "modularmachinery:blockcasing@4",
                "ItemInputStrengthen",
                "ItemOutputStrengthen",
                "EnergyInputStrengthen",
                "EnergyOutputStrengthen",
                "FluidInputStrengthen",
                "FluidOutputStrengthen"
            ]
        },
        {
            "x": 2,
            "y": 4,
            "z": -1,
            "elements": [
                "enderio:block_reinforced_obsidian@0"
            ]
        },
        {
            "x": 3,
            "y": 0,
            "z": 0,
            "elements": [
                "appliedenergistics2:smooth_sky_stone_slab@0"
            ]
        },
        {
            "x": 2,
            "y": 4,
            "z": 1,
            "elements": [
                "enderio:block_reinforced_obsidian@0"
            ]
        },
        {
            "x": -4,
            "y": 6,
            "z": 1,
            "elements": [
                "enderio:block_reinforced_obsidian@0"
            ]
        },
        {
            "x": 2,
            "y": 4,
            "z": 2,
            "elements": [
                "enderio:block_reinforced_obsidian@0"
            ]
        },
        {
            "x": -4,
            "y": 6,
            "z": 0,
            "elements": [
                "enderio:block_reinforced_obsidian@0"
            ]
        },
        {
            "x": -4,
            "y": 6,
            "z": -1,
            "elements": [
                "enderio:block_reinforced_obsidian@0"
            ]
        },
        {
            "x": 5,
            "y": 1,
            "z": 1,
            "elements": [
                "appliedenergistics2:smooth_sky_stone_stairs@7"
            ]
        },
        {
            "x": 1,
            "y": 8,
            "z": -4,
            "elements": [
                "enderio:block_reinforced_obsidian@0"
            ]
        },
        {
            "x": 2,
            "y": 10,
            "z": 2,
            "elements": [
                "enderio:block_reinforced_obsidian@0"
            ]
        },
        {
            "x": 2,
            "y": 10,
            "z": 1,
            "elements": [
                "enderio:block_reinforced_obsidian@0"
            ]
        },
        {
            "x": 2,
            "y": 10,
            "z": -1,
            "elements": [
                "enderio:block_reinforced_obsidian@0"
            ]
        },
        {
            "x": -4,
            "y": 0,
            "z": 0,
            "elements": [
                "appliedenergistics2:smooth_sky_stone_slab@0"
            ]
        },
        {
            "x": 2,
            "y": 10,
            "z": -2,
            "elements": [
                "enderio:block_reinforced_obsidian@0"
            ]
        },
        {
            "x": 1,
            "y": 8,
            "z": 4,
            "elements": [
                "enderio:block_reinforced_obsidian@0"
            ]
        },
        {
            "x": -3,
            "y": -1,
            "z": -1,
            "elements": [
                "appliedenergistics2:smooth_sky_stone_stairs@2"
            ]
        },
        {
            "x": 4,
            "y": -1,
            "z": 4,
            "elements": [
                "appliedenergistics2:smooth_sky_stone_slab@0"
            ]
        },
        {
            "x": -3,
            "y": -1,
            "z": 0,

            "elements": [
                "modularmachinery:blockcasing@4"
            ]
        },
        {
            "x": -3,
            "y": -1,
            "z": 1,
            "elements": [
                "appliedenergistics2:smooth_sky_stone_stairs@3"
            ]
        },
        {
            "x": -3,
            "y": -1,
            "z": 2,
            "elements": [
                "appliedenergistics2:smooth_sky_stone_stairs@2"
            ]
        },
        {
            "x": -3,
            "y": -1,
            "z": -5,
            "elements": [
                "appliedenergistics2:smooth_sky_stone_slab@0"
            ]
        },
        {
            "x": -3,
            "y": -1,
            "z": -4,
            "elements": [
                "appliedenergistics2:smooth_sky_stone_stairs@2"
            ]
        },
        {
            "x": 2,
            "y": 7,
            "z": -4,
            "elements": [
                "enderio:block_reinforced_obsidian@0"
            ]
        },
        {
            "x": -3,
            "y": -1,
            "z": -3,

            "elements": [
                "modularmachinery:blockcasing@4"
            ]
        },
        {
            "x": -3,
            "y": -1,
            "z": -2,
            "elements": [
                "appliedenergistics2:smooth_sky_stone_stairs@3"
            ]
        },
        {
            "x": 4,
            "y": -1,
            "z": -4,
            "elements": [
                "appliedenergistics2:smooth_sky_stone_slab@0"
            ]
        },
        {
            "x": 4,
            "y": -1,
            "z": -3,
            "elements": [
                "appliedenergistics2:smooth_sky_stone_stairs@1"
            ]
        },
        {
            "x": 4,
            "y": -1,
            "z": -2,
            "elements": [
                "appliedenergistics2:smooth_sky_stone_stairs@1"
            ]
        },
        {
            "x": 4,
            "y": -1,
            "z": -1,
            "elements": [
                "appliedenergistics2:smooth_sky_stone_stairs@2"
            ]
        },
        {
            "x": 4,
            "y": -1,
            "z": 0,

            "elements": [
                "modularmachinery:blockcasing@4"
            ]
        },
        {
            "x": 1,
            "y": 11,
            "z": 0,
            "elements": [
                "enderio:block_reinforced_obsidian@0"
            ]
        },
        {
            "x": -3,
            "y": -1,
            "z": 3,

            "elements": [
                "modularmachinery:blockcasing@4"
            ]
        },
        {
            "x": 1,
            "y": 11,
            "z": -1,
            "elements": [
                "enderio:block_reinforced_obsidian@0"
            ]
        },
        {
            "x": 4,
            "y": -1,
            "z": 1,
            "elements": [
                "appliedenergistics2:smooth_sky_stone_stairs@3"
            ]
        },
        {
            "x": -3,
            "y": -1,
            "z": 4,
            "elements": [
                "appliedenergistics2:smooth_sky_stone_stairs@3"
            ]
        },
        {
            "x": 2,
            "y": 7,
            "z": 4,
            "elements": [
                "enderio:block_reinforced_obsidian@0"
            ]
        },
        {
            "x": 4,
            "y": -1,
            "z": 2,
            "elements": [
                "appliedenergistics2:smooth_sky_stone_stairs@2"
            ]
        },
        {
            "x": -3,
            "y": -1,
            "z": 5,
            "elements": [
                "appliedenergistics2:smooth_sky_stone_slab@0"
            ]
        },
        {
            "x": 1,
            "y": 11,
            "z": 1,
            "elements": [
                "enderio:block_reinforced_obsidian@0"
            ]
        },
        {
            "x": 4,
            "y": -1,
            "z": 3,
            "elements": [
                "appliedenergistics2:smooth_sky_stone_stairs@1"
            ]
        }
    ]}