{
    "registryname": "YMG_Builder_Altar_3",
    "localizedname": "§b§lYMG§r§e§l—§f§l五彩祭坛 §r§e",
    "failure-action": "still",
    "requires-blueprint": false,
    "color": "FFFFFF",
    "parts": [
        {
            "x": -4,
            "y": 2,
            "z": 4,
            "elements": [
                "astralsorcery:blockmarble@2"
            ]
        },
        {
            "x": 4,
            "y": -1,
            "z": -5,
            "elements": [
                "astralsorcery:blockmarble@1"
            ]
        },
        {
            "x": -4,
            "y": 2,
            "z": -4,
            "elements": [
                "astralsorcery:blockmarble@2"
            ]
        },
        {
            "x": 4,
            "y": 2,
            "z": 4,
            "elements": [
                "astralsorcery:blockmarble@2"
            ]
        },
        {
            "x": -1,
            "y": -1,
            "z": 1,
            "elements": [
                "astralsorcery:blockblackmarble@0"
            ]
        },
        {
            "x": 3,
            "y": 4,
            "z": 2,
            "elements": [
                "astralsorcery:blockmarble@1"
            ]
        },
        {
            "x": -4,
            "y": -1,
            "z": -2,
            "elements": [
                "astralsorcery:blockmarble@1"
            ]
        },
        {
            "x": -4,
            "y": -1,
            "z": -1,
            "elements": [
                "astralsorcery:blockmarble@1"
            ]
        },
        {
            "x": -1,
            "y": -1,
            "z": 2,
            "elements": [
                "astralsorcery:blockblackmarble@0"
            ]
        },
        {
            "x": 3,
            "y": 4,
            "z": 3,
            "elements": [
                "astralsorcery:blockmarble@1"
            ]
        },
        {
            "x": -1,
            "y": -1,
            "z": 3,
            "elements": [
                "astralsorcery:blockblackmarble@0"
            ]
        },
        {
            "x": -4,
            "y": -1,
            "z": -4,
            "elements": [
                "astralsorcery:blockmarble@0"
            ]
        },
        {
            "x": -1,
            "y": -1,
            "z": 4,
            "elements": [
                "astralsorcery:blockmarble@1"
            ]
        },
        {
            "x": 3,
            "y": 4,
            "z": 1,
            "elements": [
                "astralsorcery:blockmarble@1"
            ]
        },
        {
            "x": -4,
            "y": -1,
            "z": -3,
            "elements": [
                "astralsorcery:blockmarble@0"
            ]
        },
        {
            "x": -4,
            "y": -1,
            "z": 2,
            "elements": [
                "astralsorcery:blockmarble@1"
            ]
        },
        {
            "x": -4,
            "y": -1,
            "z": 3,
            "elements": [
                "astralsorcery:blockmarble@0"
            ]
        },
        {
            "x": -4,
            "y": -1,
            "z": 0,
            "elements": [
                "astralsorcery:blockmarble@1"
            ]
        },
        {
            "x": 4,
            "y": 2,
            "z": -4,
            "elements": [
                "astralsorcery:blockmarble@2"
            ]
        },
        {
            "x": -4,
            "y": -1,
            "z": 1,
            "elements": [
                "astralsorcery:blockmarble@1"
            ]
        },
        {
            "x": -1,
            "y": -1,
            "z": -4,
            "elements": [
                "astralsorcery:blockmarble@1"
            ]
        },
        {
            "x": -1,
            "y": -1,
            "z": -3,
            "elements": [
                "astralsorcery:blockblackmarble@0"
            ]
        },
        {
            "x": 3,
            "y": 4,
            "z": -2,
            "elements": [
                "astralsorcery:blockmarble@1"
            ]
        },
        {
            "x": -4,
            "y": -1,
            "z": -5,
            "elements": [
                "astralsorcery:blockmarble@1"
            ]
        },
        {
            "x": 3,
            "y": 4,
            "z": -1,
            "elements": [
                "astralsorcery:blockmarble@1"
            ]
        },
        {
            "x": -1,
            "y": -1,
            "z": -2,
            "elements": [
                "astralsorcery:blockblackmarble@0"
            ]
        },
        {
            "x": -1,
            "y": -1,
            "z": -1,
            "elements": [
                "astralsorcery:blockblackmarble@0"
            ]
        },
        {
            "x": 3,
            "y": 4,
            "z": -3,
            "elements": [
                "astralsorcery:blockmarble@1"
            ]
        },
        {
            "x": -1,
            "y": -1,
            "z": 0,
            "elements": [
                "astralsorcery:blockblackmarble@0"
            ]
        },
        {
            "x": 0,
            "y": 0,
            "z": 0,

            "elements": [
                "modularmachinery:blockcontroller@2"
            ]
        },
        {
            "x": 1,
            "y": -1,
            "z": 2,
            "elements": [
                "astralsorcery:blockblackmarble@0"
            ]
        },
        {
            "x": 1,
            "y": -1,
            "z": 1,
            "elements": [
                "astralsorcery:blockblackmarble@0"
            ]
        },
        {
            "x": -2,
            "y": 4,
            "z": -3,
            "elements": [
                "astralsorcery:blockmarble@1"
            ]
        },
        {
            "x": 1,
            "y": -1,
            "z": 0,
            "elements": [
                "astralsorcery:blockblackmarble@0"
            ]
        },
        {
            "x": 1,
            "y": -1,
            "z": -1,
            "elements": [
                "astralsorcery:blockblackmarble@0"
            ]
        },
        {
            "x": 1,
            "y": -1,
            "z": 4,
            "elements": [
                "astralsorcery:blockmarble@1"
            ]
        },
        {
            "x": -2,
            "y": 4,
            "z": 3,
            "elements": [
                "astralsorcery:blockmarble@1"
            ]
        },
        {
            "x": 1,
            "y": -1,
            "z": 3,
            "elements": [
                "astralsorcery:blockblackmarble@0"
            ]
        },
        {
            "x": 1,
            "y": -1,
            "z": -2,
            "elements": [
                "astralsorcery:blockblackmarble@0"
            ]
        },
        {
            "x": 1,
            "y": -1,
            "z": -3,
            "elements": [
                "astralsorcery:blockblackmarble@0"
            ]
        },
        {
            "x": 1,
            "y": -1,
            "z": -4,
            "elements": [
                "astralsorcery:blockmarble@1"
            ]
        },
        {
            "x": 4,
            "y": 3,
            "z": -3,
            "elements": [
                "astralsorcery:blockmarble@1"
            ]
        },
        {
            "x": 4,
            "y": 3,
            "z": -4,
            "elements": [
                "astralsorcery:blockmarble@4"
            ]
        },
        {
            "x": 4,
            "y": 3,
            "z": 4,
            "elements": [
                "astralsorcery:blockmarble@4"
            ]
        },
        {
            "x": 4,
            "y": 3,
            "z": 3,
            "elements": [
                "astralsorcery:blockmarble@1"
            ]
        },
        {
            "x": 5,
            "y": -1,
            "z": 5,
            "elements": [
                "astralsorcery:blockmarble@1"
            ]
        },
        {
            "x": 5,
            "y": -1,
            "z": 3,
            "elements": [
                "astralsorcery:blockmarble@1"
            ]
        },
        {
            "x": 5,
            "y": -1,
            "z": 4,
            "elements": [
                "astralsorcery:blockmarble@1"
            ]
        },
        {
            "x": 4,
            "y": 0,
            "z": -4,
            "elements": [
                "astralsorcery:blockmarble@6"
            ]
        },
        {
            "x": -3,
            "y": 3,
            "z": -4,
            "elements": [
                "astralsorcery:blockmarble@1"
            ]
        },
        {
            "x": 5,
            "y": -1,
            "z": -3,
            "elements": [
                "astralsorcery:blockmarble@1"
            ]
        },
        {
            "x": -3,
            "y": 3,
            "z": 4,
            "elements": [
                "astralsorcery:blockmarble@1"
            ]
        },
        {
            "x": -4,
            "y": -1,
            "z": 4,
            "elements": [
                "astralsorcery:blockmarble@0"
            ]
        },
        {
            "x": 5,
            "y": -1,
            "z": -5,
            "elements": [
                "astralsorcery:blockmarble@1"
            ]
        },
        {
            "x": -4,
            "y": -1,
            "z": 5,
            "elements": [
                "astralsorcery:blockmarble@1"
            ]
        },
        {
            "x": 5,
            "y": -1,
            "z": -4,
            "elements": [
                "astralsorcery:blockmarble@1"
            ]
        },
        {
            "x": -2,
            "y": -1,
            "z": 4,
            "elements": [
                "astralsorcery:blockmarble@1"
            ]
        },
        {
            "x": -2,
            "y": -1,
            "z": 2,
            "elements": [
                "astralsorcery:blockblackmarble@0"
            ]
        },
        {
            "x": -2,
            "y": -1,
            "z": 3,
            "elements": [
                "astralsorcery:blockblackmarble@0"
            ]
        },
        {
            "x": -2,
            "y": -1,
            "z": 0,
            "elements": [
                "astralsorcery:blockblackmarble@0"
            ]
        },
        {
            "x": -2,
            "y": -1,
            "z": 1,
            "elements": [
                "astralsorcery:blockblackmarble@0"
            ]
        },
        {
            "x": -2,
            "y": -1,
            "z": -2,
            "elements": [
                "astralsorcery:blockblackmarble@0"
            ]
        },
        {
            "x": -2,
            "y": -1,
            "z": -1,
            "elements": [
                "astralsorcery:blockblackmarble@0"
            ]
        },
        {
            "x": -2,
            "y": -1,
            "z": -4,
            "elements": [
                "astralsorcery:blockmarble@1"
            ]
        },
        {
            "x": 1,
            "y": 4,
            "z": -3,
            "elements": [
                "astralsorcery:blockmarble@1"
            ]
        },
        {
            "x": -2,
            "y": -1,
            "z": -3,
            "elements": [
                "astralsorcery:blockblackmarble@0"
            ]
        },
        {
            "x": 1,
            "y": 4,
            "z": 3,
            "elements": [
                "astralsorcery:blockmarble@1"
            ]
        },
        {
            "x": 0,
            "y": -1,
            "z": -3,
            "elements": [
                "astralsorcery:blockblackmarble@0"
            ]
        },
        {
            "x": 0,
            "y": -1,
            "z": -4,
            "elements": [
                "astralsorcery:blockmarble@1"
            ]
        },
        {
            "x": 0,
            "y": -1,
            "z": -1,
            "elements": [
                "astralsorcery:blockblackmarble@0"
            ]
        },
        {
            "x": 3,
            "y": -1,
            "z": 5,
            "elements": [
                "astralsorcery:blockmarble@1"
            ]
        },
        {
            "x": 0,
            "y": -1,
            "z": -2,
            "elements": [
                "astralsorcery:blockblackmarble@0"
            ]
        },
        {
            "x": 3,
            "y": -1,
            "z": 3,
            "elements": [
                "astralsorcery:blockblackmarble@0"
            ]
        },
        {
            "x": 3,
            "y": -1,
            "z": 4,
            "elements": [
                "astralsorcery:blockmarble@0"
            ]
        },
        {
            "x": -5,
            "y": -1,
            "z": -3,
            "elements": [
                "astralsorcery:blockmarble@1"
            ]
        },
        {
            "x": 3,
            "y": -1,
            "z": 1,
            "elements": [
                "astralsorcery:blockblackmarble@0"
            ]
        },
        {
            "x": -1,
            "y": 4,
            "z": -3,
            "elements": [
                "astralsorcery:blockmarble@1"
            ]
        },
        {
            "x": 3,
            "y": -1,
            "z": 2,
            "elements": [
                "astralsorcery:blockblackmarble@0"
            ]
        },
        {
            "x": 3,
            "y": -1,
            "z": -1,
            "elements": [
                "astralsorcery:blockblackmarble@0"
            ]
        },
        {
            "x": -1,
            "y": 4,
            "z": 3,
            "elements": [
                "astralsorcery:blockmarble@1"
            ]
        },
        {
            "x": 3,
            "y": -1,
            "z": 0,
            "elements": [
                "astralsorcery:blockblackmarble@0"
            ]
        },
        {
            "x": -5,
            "y": -1,
            "z": 4,
            "elements": [
                "astralsorcery:blockmarble@1"
            ]
        },
        {
            "x": 3,
            "y": -1,
            "z": -3,
            "elements": [
                "astralsorcery:blockblackmarble@0"
            ]
        },
        {
            "x": 3,
            "y": -1,
            "z": -2,
            "elements": [
                "astralsorcery:blockblackmarble@0"
            ]
        },
        {
            "x": -5,
            "y": -1,
            "z": 3,
            "elements": [
                "astralsorcery:blockmarble@1"
            ]
        },
        {
            "x": 3,
            "y": -1,
            "z": -5,
            "elements": [
                "astralsorcery:blockmarble@1"
            ]
        },
        {
            "x": -5,
            "y": -1,
            "z": 5,
            "elements": [
                "astralsorcery:blockmarble@1"
            ]
        },
        {
            "x": 3,
            "y": -1,
            "z": -4,
            "elements": [
                "astralsorcery:blockmarble@0"
            ]
        },
        {
            "x": 4,
            "y": 1,
            "z": -4,
            "elements": [
                "astralsorcery:blockmarble@2"
            ]
        },
        {
            "x": 4,
            "y": 0,
            "z": 4,
            "elements": [
                "astralsorcery:blockmarble@6"
            ]
        },
        {
            "x": -4,
            "y": 1,
            "z": -4,
            "elements": [
                "astralsorcery:blockmarble@2"
            ]
        },
        {
            "x": 4,
            "y": 1,
            "z": 4,
            "elements": [
                "astralsorcery:blockmarble@2"
            ]
        },
        {
            "x": -5,
            "y": -1,
            "z": -4,
            "elements": [
                "astralsorcery:blockmarble@1"
            ]
        },
        {
            "x": -5,
            "y": -1,
            "z": -5,
            "elements": [
                "astralsorcery:blockmarble@1"
            ]
        },
        {
            "x": 0,
            "y": -1,
            "z": 1,
            "elements": [
                "astralsorcery:blockblackmarble@0"
            ]
        },
        {
            "x": -4,
            "y": 1,
            "z": 4,
            "elements": [
                "astralsorcery:blockmarble@2"
            ]
        },
        {
            "x": 0,
            "y": -1,
            "z": 0,
            "elements": [
                "astralsorcery:blockblackmarble@0"
            ]
        },
        {
            "x": 0,
            "y": -1,
            "z": 3,
            "elements": [
                "astralsorcery:blockblackmarble@0"
            ]
        },
        {
            "x": 0,
            "y": -1,
            "z": 2,
            "elements": [
                "astralsorcery:blockblackmarble@0"
            ]
        },
        {
            "x": 0,
            "y": -1,
            "z": 4,
            "elements": [
                "astralsorcery:blockmarble@1"
            ]
        },
        {
            "x": -4,
            "y": 3,
            "z": -4,
            "elements": [
                "astralsorcery:blockmarble@4"
            ]
        },
        {
            "x": -4,
            "y": 3,
            "z": -3,
            "elements": [
                "astralsorcery:blockmarble@1"
            ]
        },
        {
            "x": 2,
            "y": -1,
            "z": -3,
            "elements": [
                "astralsorcery:blockblackmarble@0"
            ]
        },
        {
            "x": -3,
            "y": 4,
            "z": 3,
            "elements": [
                "astralsorcery:blockmarble@1"
            ]
        },
        {
            "x": -3,
            "y": 4,
            "z": 2,
            "elements": [
                "astralsorcery:blockmarble@1"
            ]
        },
        {
            "x": 2,
            "y": -1,
            "z": -4,
            "elements": [
                "astralsorcery:blockmarble@1"
            ]
        },
        {
            "x": 2,
            "y": 4,
            "z": -3,
            "elements": [
                "astralsorcery:blockmarble@1"
            ]
        },
        {
            "x": -3,
            "y": 4,
            "z": 1,
            "elements": [
                "astralsorcery:blockmarble@1"
            ]
        },
        {
            "x": -3,
            "y": 4,
            "z": -1,
            "elements": [
                "astralsorcery:blockmarble@1"
            ]
        },
        {
            "x": -3,
            "y": 4,
            "z": -2,
            "elements": [
                "astralsorcery:blockmarble@1"
            ]
        },
        {
            "x": -3,
            "y": 4,
            "z": -3,
            "elements": [
                "astralsorcery:blockmarble@1"
            ]
        },
        {
            "x": 2,
            "y": -1,
            "z": 3,
            "elements": [
                "astralsorcery:blockblackmarble@0"
            ]
        },
        {
            "x": 2,
            "y": -1,
            "z": 2,
            "elements": [
                "astralsorcery:blockblackmarble@0"
            ]
        },
        {
            "x": 2,
            "y": 4,
            "z": 3,
            "elements": [
                "astralsorcery:blockmarble@1"
            ]
        },
        {
            "x": 2,
            "y": -1,
            "z": 4,
            "elements": [
                "astralsorcery:blockmarble@1"
            ]
        },
        {
            "x": 2,
            "y": -1,
            "z": -1,
            "elements": [
                "astralsorcery:blockblackmarble@0"
            ]
        },
        {
            "x": 2,
            "y": -1,
            "z": -2,
            "elements": [
                "astralsorcery:blockblackmarble@0"
            ]
        },
        {
            "x": 2,
            "y": -1,
            "z": 1,
            "elements": [
                "astralsorcery:blockblackmarble@0"
            ]
        },
        {
            "x": 2,
            "y": -1,
            "z": 0,
            "elements": [
                "astralsorcery:blockblackmarble@0"
            ]
        },
        {
            "x": 3,
            "y": 3,
            "z": -4,
            "elements": [
                "astralsorcery:blockmarble@1"
            ]
        },
        {
            "x": -4,
            "y": 0,
            "z": -4,
            "elements": [
                "astralsorcery:blockmarble@6"
            ]
        },
        {
            "x": -4,
            "y": 0,
            "z": 4,
            "elements": [
                "astralsorcery:blockmarble@6"
            ]
        },
        {
            "x": -3,
            "y": -1,
            "z": -1,
            "elements": [
                "astralsorcery:blockblackmarble@0"
            ]
        },
        {
            "x": 4,
            "y": -1,
            "z": 4,
            "elements": [
                "astralsorcery:blockmarble@0"
            ]
        },
        {
            "x": -3,
            "y": -1,
            "z": 0,
            "elements": [
                "astralsorcery:blockblackmarble@0"
            ]
        },
        {
            "x": 4,
            "y": -1,
            "z": 5,
            "elements": [
                "astralsorcery:blockmarble@1"
            ]
        },
        {
            "x": -3,
            "y": -1,
            "z": 1,
            "elements": [
                "astralsorcery:blockblackmarble@0"
            ]
        },
        {
            "x": -3,
            "y": -1,
            "z": 2,
            "elements": [
                "astralsorcery:blockblackmarble@0"
            ]
        },
        {
            "x": -3,
            "y": -1,
            "z": -5,
            "elements": [
                "astralsorcery:blockmarble@1"
            ]
        },
        {
            "x": -3,
            "y": -1,
            "z": -4,
            "elements": [
                "astralsorcery:blockmarble@0"
            ]
        },
        {
            "x": -3,
            "y": -1,
            "z": -3,
            "elements": [
                "astralsorcery:blockblackmarble@0"
            ]
        },
        {
            "x": -3,
            "y": -1,
            "z": -2,
            "elements": [
                "astralsorcery:blockblackmarble@0"
            ]
        },
        {
            "x": 4,
            "y": -1,
            "z": -4,
            "elements": [
                "astralsorcery:blockmarble@0"
            ]
        },
        {
            "x": -4,
            "y": 3,
            "z": 3,
            "elements": [
                "astralsorcery:blockmarble@1"
            ]
        },
        {
            "x": 4,
            "y": -1,
            "z": -3,
            "elements": [
                "astralsorcery:blockmarble@0"
            ]
        },
        {
            "x": 4,
            "y": -1,
            "z": -2,
            "elements": [
                "astralsorcery:blockmarble@1"
            ]
        },
        {
            "x": 4,
            "y": -1,
            "z": -1,
            "elements": [
                "astralsorcery:blockmarble@1"
            ]
        },
        {
            "x": 4,
            "y": -1,
            "z": 0,
            "elements": [
                "astralsorcery:blockmarble@1"
            ]
        },
        {
            "x": -3,
            "y": -1,
            "z": 3,
            "elements": [
                "astralsorcery:blockblackmarble@0"
            ]
        },
        {
            "x": -3,
            "y": -1,
            "z": 4,
            "elements": [
                "astralsorcery:blockmarble@0"
            ]
        },
        {
            "x": 4,
            "y": -1,
            "z": 1,
            "elements": [
                "astralsorcery:blockmarble@1"
            ]
        },
        {
            "x": 3,
            "y": 3,
            "z": 4,
            "elements": [
                "astralsorcery:blockmarble@1"
            ]
        },
        {
            "x": 4,
            "y": -1,
            "z": 2,
            "elements": [
                "astralsorcery:blockmarble@1"
            ]
        },
        {
            "x": -3,
            "y": -1,
            "z": 5,
            "elements": [
                "astralsorcery:blockmarble@1"
            ]
        },
        {
            "x": -4,
            "y": 3,
            "z": 4,
            "elements": [
                "astralsorcery:blockmarble@4"
            ]
        },
        {
            "x": 4,
            "y": -1,
            "z": 3,
            "elements": [
                "astralsorcery:blockmarble@0"
            ]
        }
    ]}