{
    "registryname": "YMG_Magnetic_Flux_Metal_Fused",
    "localizedname": "§b§lYMG§r§e§l—§f§l磁通量金属融合器 §r§e",
    "failure-action": "still",
    "requires-blueprint": false,
    "has-factory": true,
    "factory-only": true,
    "color": "707070",
    "parts": [
        {
            "x": 0,
            "y": 7,
            "z": 8,
            "elements": [
                "enderio:block_fused_quartz@0"
            ]
        },
        {
            "x": 5,
            "y": 0,
            "z": 6,
            "elements": [
                "modularmachinery:blockcasing@4",
                "ItemInputStrengthen",
                "ItemOutputStrengthen",
                "FluidInputStrengthen",
                "EnergyInputStrengthen"
            ]
        },
        {
            "x": 5,
            "y": 0,
            "z": 4,
            "elements": [
                "modularmachinery:blockcasing@4",
                "ItemInputStrengthen",
                "ItemOutputStrengthen",
                "FluidInputStrengthen",
                "EnergyInputStrengthen"
            ]
        },
        {
            "x": 5,
            "y": 0,
            "z": 5,
            "elements": [
                "modularmachinery:blockcasing@4",
                "ItemInputStrengthen",
                "ItemOutputStrengthen",
                "FluidInputStrengthen",
                "EnergyInputStrengthen"
            ]
        },
        {
            "x": 3,
            "y": 11,
            "z": 6,
            "elements": [
                "fluxnetworks:fluxblock@0"
            ]
        },
        {
            "x": 3,
            "y": 11,
            "z": 5,
            "elements": [
                "enderio:block_fused_quartz@0"
            ]
        },
        {
            "x": -1,
            "y": 6,
            "z": 2,
            "elements": [
                "enderio:block_fused_quartz@0"
            ]
        },
        {
            "x": -1,
            "y": 6,
            "z": 3,
            "elements": [
                "ic2:fence@0"
            ]
        },
        {
            "x": 1,
            "y": 8,
            "z": 8,
            "elements": [
                "enderio:block_fused_quartz@0"
            ]
        },
        {
            "x": -1,
            "y": 6,
            "z": 8,
            "elements": [
                "enderio:block_fused_quartz@0"
            ]
        },
        {
            "x": 3,
            "y": 11,
            "z": 4,
            "elements": [
                "fluxnetworks:fluxblock@0"
            ]
        },
        {
            "x": 1,
            "y": 8,
            "z": 7,
            "elements": [
                "ic2:fence@0"
            ]
        },
        {
            "x": -1,
            "y": 6,
            "z": 7,
            "elements": [
                "ic2:fence@0"
            ]
        },
        {
            "x": 0,
            "y": 7,
            "z": 2,
            "elements": [
                "enderio:block_fused_quartz@0"
            ]
        },
        {
            "x": 0,
            "y": 7,
            "z": 4,

            "elements": [
                "mekanismgenerators:generator@9"
            ]
        },
        {
            "x": 0,
            "y": 7,
            "z": 5,
            "elements": [
                "contenttweaker:tungstenblock@0"
            ]
        },
        {
            "x": 0,
            "y": 7,
            "z": 6,

            "elements": [
                "mekanismgenerators:generator@9"
            ]
        },
        {
            "x": -2,
            "y": 4,
            "z": 6,
            "elements": [
                "ic2:fence@0"
            ]
        },
        {
            "x": 2,
            "y": 9,
            "z": 7,
            "elements": [
                "enderio:block_fused_quartz@0"
            ]
        },
        {
            "x": 2,
            "y": 9,
            "z": 6,
            "elements": [
                "ic2:fence@0"
            ]
        },
        {
            "x": 2,
            "y": 9,
            "z": 4,
            "elements": [
                "ic2:fence@0"
            ]
        },
        {
            "x": -2,
            "y": 4,
            "z": 7,
            "elements": [
                "enderio:block_fused_quartz@0"
            ]
        },
        {
            "x": -2,
            "y": 18,
            "z": 7,
            "elements": [
                "enderio:block_alloy@6"
            ]
        },
        {
            "x": -2,
            "y": 18,
            "z": 6,
            "elements": [
                "appliedenergistics2:smooth_sky_stone_stairs@2"
            ]
        },
        {
            "x": -2,
            "y": 18,
            "z": 5,
            "elements": [
                "appliedenergistics2:smooth_sky_stone_slab@0"
            ]
        },
        {
            "x": -2,
            "y": 18,
            "z": 4,
            "elements": [
                "appliedenergistics2:smooth_sky_stone_stairs@3"
            ]
        },
        {
            "x": -2,
            "y": 18,
            "z": 3,
            "elements": [
                "enderio:block_alloy@6"
            ]
        },
        {
            "x": 2,
            "y": 9,
            "z": 3,
            "elements": [
                "enderio:block_fused_quartz@0"
            ]
        },
        {
            "x": 1,
            "y": 9,
            "z": 2,
            "elements": [
                "fluxnetworks:fluxblock@0"
            ]
        },
        {
            "x": -2,
            "y": 4,
            "z": 4,
            "elements": [
                "ic2:fence@0"
            ]
        },
        {
            "x": 1,
            "y": 9,
            "z": 4,

            "elements": [
                "mekanismgenerators:generator@9"
            ]
        },
        {
            "x": -2,
            "y": 4,
            "z": 3,
            "elements": [
                "enderio:block_fused_quartz@0"
            ]
        },
        {
            "x": 1,
            "y": 9,
            "z": 3,
            "elements": [
                "ic2:fence@0"
            ]
        },
        {
            "x": 1,
            "y": 9,
            "z": 6,

            "elements": [
                "mekanismgenerators:generator@9"
            ]
        },
        {
            "x": 1,
            "y": 9,
            "z": 5,

            "elements": [
                "mekanismgenerators:generator@9"
            ]
        },
        {
            "x": 1,
            "y": 9,
            "z": 8,
            "elements": [
                "fluxnetworks:fluxblock@0"
            ]
        },
        {
            "x": 1,
            "y": 9,
            "z": 7,
            "elements": [
                "ic2:fence@0"
            ]
        },
        {
            "x": 3,
            "y": 10,
            "z": 5,
            "elements": [
                "enderio:block_fused_quartz@0"
            ]
        },
        {
            "x": 3,
            "y": 10,
            "z": 4,
            "elements": [
                "enderio:block_fused_quartz@0"
            ]
        },
        {
            "x": 3,
            "y": 10,
            "z": 6,
            "elements": [
                "enderio:block_fused_quartz@0"
            ]
        },
        {
            "x": -1,
            "y": 18,
            "z": 7,
            "elements": [
                "appliedenergistics2:smooth_sky_stone_stairs@1"
            ]
        },
        {
            "x": -1,
            "y": 18,
            "z": 6,

            "elements": [
                "modularmachinery:blockcasing@4"
            ]
        },
        {
            "x": -1,
            "y": 18,
            "z": 8,
            "elements": [
                "appliedenergistics2:smooth_sky_stone_slab@0"
            ]
        },
        {
            "x": 4,
            "y": 0,
            "z": 2,
            "elements": [
                "modularmachinery:blockcasing@4",
                "ItemInputStrengthen",
                "ItemOutputStrengthen",
                "FluidInputStrengthen",
                "EnergyInputStrengthen"
            ]
        },
        {
            "x": -1,
            "y": 18,
            "z": 3,
            "elements": [
                "appliedenergistics2:smooth_sky_stone_stairs@1"
            ]
        },
        {
            "x": -1,
            "y": 18,
            "z": 2,
            "elements": [
                "appliedenergistics2:smooth_sky_stone_slab@0"
            ]
        },
        {
            "x": -1,
            "y": 18,
            "z": 5,

            "elements": [
                "modularmachinery:blockcasing@1"
            ]
        },
        {
            "x": -1,
            "y": 18,
            "z": 4,

            "elements": [
                "modularmachinery:blockcasing@4"
            ]
        },
        {
            "x": -3,
            "y": 17,
            "z": 4,
            "elements": [
                "appliedenergistics2:smooth_sky_stone_stairs@0"
            ]
        },
        {
            "x": -2,
            "y": 5,
            "z": 3,
            "elements": [
                "enderio:block_fused_quartz@0"
            ]
        },
        {
            "x": 0,
            "y": 19,
            "z": 8,
            "elements": [
                "appliedenergistics2:smooth_sky_stone_slab@0"
            ]
        },
        {
            "x": -2,
            "y": 19,
            "z": 7,
            "elements": [
                "appliedenergistics2:smooth_sky_stone_slab@0"
            ]
        },
        {
            "x": 1,
            "y": 7,
            "z": 7,
            "elements": [
                "ic2:fence@0"
            ]
        },
        {
            "x": 1,
            "y": 7,
            "z": 8,
            "elements": [
                "fluxnetworks:fluxblock@0"
            ]
        },
        {
            "x": -3,
            "y": 17,
            "z": 6,
            "elements": [
                "appliedenergistics2:smooth_sky_stone_stairs@0"
            ]
        },
        {
            "x": -3,
            "y": 17,
            "z": 5,
            "elements": [
                "enderio:block_fused_quartz@0"
            ]
        },
        {
            "x": 0,
            "y": 19,
            "z": 2,
            "elements": [
                "appliedenergistics2:smooth_sky_stone_slab@0"
            ]
        },
        {
            "x": 1,
            "y": 7,
            "z": 2,
            "elements": [
                "fluxnetworks:fluxblock@0"
            ]
        },
        {
            "x": -3,
            "y": 3,
            "z": 4,
            "elements": [
                "fluxnetworks:fluxblock@0"
            ]
        },
        {
            "x": -3,
            "y": 3,
            "z": 5,
            "elements": [
                "enderio:block_fused_quartz@0"
            ]
        },
        {
            "x": -3,
            "y": 3,
            "z": 6,
            "elements": [
                "fluxnetworks:fluxblock@0"
            ]
        },
        {
            "x": 1,
            "y": 7,
            "z": 5,

            "elements": [
                "mekanismgenerators:generator@9"
            ]
        },
        {
            "x": 1,
            "y": 7,
            "z": 6,

            "elements": [
                "mekanismgenerators:generator@9"
            ]
        },
        {
            "x": -2,
            "y": 5,
            "z": 4,
            "elements": [
                "ic2:fence@0"
            ]
        },
        {
            "x": -2,
            "y": 19,
            "z": 3,
            "elements": [
                "appliedenergistics2:smooth_sky_stone_slab@0"
            ]
        },
        {
            "x": -2,
            "y": 5,
            "z": 7,
            "elements": [
                "enderio:block_fused_quartz@0"
            ]
        },
        {
            "x": 1,
            "y": 7,
            "z": 3,
            "elements": [
                "ic2:fence@0"
            ]
        },
        {
            "x": -2,
            "y": 5,
            "z": 6,
            "elements": [
                "ic2:fence@0"
            ]
        },
        {
            "x": 1,
            "y": 7,
            "z": 4,

            "elements": [
                "mekanismgenerators:generator@9"
            ]
        },
        {
            "x": 0,
            "y": 8,
            "z": 8,
            "elements": [
                "enderio:block_fused_quartz@0"
            ]
        },
        {
            "x": 0,
            "y": 8,
            "z": 5,
            "elements": [
                "contenttweaker:tungstenblock@0"
            ]
        },
        {
            "x": -5,
            "y": 0,
            "z": 5,
            "elements": [
                "modularmachinery:blockcasing@4",
                "ItemInputStrengthen",
                "ItemOutputStrengthen",
                "FluidInputStrengthen",
                "EnergyInputStrengthen"
            ]
        },
        {
            "x": -5,
            "y": 0,
            "z": 4,
            "elements": [
                "modularmachinery:blockcasing@4",
                "ItemInputStrengthen",
                "ItemOutputStrengthen",
                "FluidInputStrengthen",
                "EnergyInputStrengthen"
            ]
        },
        {
            "x": -5,
            "y": 0,
            "z": 6,
            "elements": [
                "modularmachinery:blockcasing@4",
                "ItemInputStrengthen",
                "ItemOutputStrengthen",
                "FluidInputStrengthen",
                "EnergyInputStrengthen"
            ]
        },
        {
            "x": 0,
            "y": 8,
            "z": 2,
            "elements": [
                "enderio:block_fused_quartz@0"
            ]
        },
        {
            "x": 1,
            "y": 10,
            "z": 3,
            "elements": [
                "ic2:fence@0"
            ]
        },
        {
            "x": 1,
            "y": 10,
            "z": 2,
            "elements": [
                "enderio:block_fused_quartz@0"
            ]
        },
        {
            "x": -2,
            "y": 6,
            "z": 4,
            "elements": [
                "ic2:fence@0"
            ]
        },
        {
            "x": -2,
            "y": 6,
            "z": 3,
            "elements": [
                "enderio:block_fused_quartz@0"
            ]
        },
        {
            "x": 2,
            "y": 11,
            "z": 4,
            "elements": [
                "ic2:fence@0"
            ]
        },
        {
            "x": 2,
            "y": 11,
            "z": 3,
            "elements": [
                "enderio:block_fused_quartz@0"
            ]
        },
        {
            "x": -2,
            "y": 6,
            "z": 6,
            "elements": [
                "ic2:fence@0"
            ]
        },
        {
            "x": -2,
            "y": 3,
            "z": 7,
            "elements": [
                "enderio:block_fused_quartz@0"
            ]
        },
        {
            "x": 2,
            "y": 8,
            "z": 7,
            "elements": [
                "enderio:block_fused_quartz@0"
            ]
        },
        {
            "x": -2,
            "y": 3,
            "z": 6,
            "elements": [
                "ic2:fence@0"
            ]
        },
        {
            "x": -2,
            "y": 6,
            "z": 7,
            "elements": [
                "enderio:block_fused_quartz@0"
            ]
        },
        {
            "x": 2,
            "y": 11,
            "z": 7,
            "elements": [
                "enderio:block_fused_quartz@0"
            ]
        },
        {
            "x": 2,
            "y": 8,
            "z": 6,
            "elements": [
                "ic2:fence@0"
            ]
        },
        {
            "x": 2,
            "y": 11,
            "z": 6,
            "elements": [
                "ic2:fence@0"
            ]
        },
        {
            "x": -2,
            "y": 3,
            "z": 3,
            "elements": [
                "enderio:block_fused_quartz@0"
            ]
        },
        {
            "x": 2,
            "y": 8,
            "z": 4,
            "elements": [
                "ic2:fence@0"
            ]
        },
        {
            "x": 1,
            "y": 10,
            "z": 8,
            "elements": [
                "enderio:block_fused_quartz@0"
            ]
        },
        {
            "x": 2,
            "y": 8,
            "z": 3,
            "elements": [
                "enderio:block_fused_quartz@0"
            ]
        },
        {
            "x": -2,
            "y": 3,
            "z": 4,
            "elements": [
                "ic2:fence@0"
            ]
        },
        {
            "x": 1,
            "y": 10,
            "z": 7,
            "elements": [
                "ic2:fence@0"
            ]
        },
        {
            "x": -1,
            "y": 17,
            "z": 4,
            "elements": [
                "contenttweaker:tungstencasing@0"
            ]
        },
        {
            "x": 4,
            "y": 0,
            "z": 7,
            "elements": [
                "modularmachinery:blockcasing@4",
                "ItemInputStrengthen",
                "ItemOutputStrengthen",
                "FluidInputStrengthen",
                "EnergyInputStrengthen"
            ]
        },
        {
            "x": -1,
            "y": 17,
            "z": 3,
            "elements": [
                "contenttweaker:tungstencasing@0"
            ]
        },
        {
            "x": 4,
            "y": 0,
            "z": 8,
            "elements": [
                "modularmachinery:blockcasing@4",
                "ItemInputStrengthen",
                "ItemOutputStrengthen",
                "FluidInputStrengthen",
                "EnergyInputStrengthen"
            ]
        },
        {
            "x": -1,
            "y": 17,
            "z": 6,
            "elements": [
                "contenttweaker:tungstencasing@0"
            ]
        },
        {
            "x": -1,
            "y": 17,
            "z": 5,
            "elements": [
                "ic2:resource@13"
            ]
        },
        {
            "x": 4,
            "y": 0,
            "z": 3,
            "elements": [
                "modularmachinery:blockcasing@4",
                "ItemInputStrengthen",
                "ItemOutputStrengthen",
                "FluidInputStrengthen",
                "EnergyInputStrengthen"
            ]
        },
        {
            "x": 4,
            "y": 0,
            "z": 4,
            "elements": [
                "enderio:block_reinforced_obsidian@0"
            ]
        },
        {
            "x": 4,
            "y": 0,
            "z": 5,
            "elements": [
                "enderio:block_alloy@6"
            ]
        },
        {
            "x": -1,
            "y": 17,
            "z": 2,
            "elements": [
                "appliedenergistics2:smooth_sky_stone_stairs@2"
            ]
        },
        {
            "x": 4,
            "y": 0,
            "z": 6,
            "elements": [
                "enderio:block_reinforced_obsidian@0"
            ]
        },
        {
            "x": 4,
            "y": 1,
            "z": 4,
            "elements": [
                "appliedenergistics2:smooth_sky_stone_stairs@1"
            ]
        },
        {
            "x": 4,
            "y": 1,
            "z": 5,
            "elements": [
                "appliedenergistics2:smooth_sky_stone_slab@0"
            ]
        },
        {
            "x": 4,
            "y": 1,
            "z": 6,
            "elements": [
                "appliedenergistics2:smooth_sky_stone_stairs@1"
            ]
        },
        {
            "x": 1,
            "y": 6,
            "z": 8,
            "elements": [
                "enderio:block_fused_quartz@0"
            ]
        },
        {
            "x": -3,
            "y": 1,
            "z": 5,
            "elements": [
                "enderio:block_alloy_endergy@1"
            ]
        },
        {
            "x": -4,
            "y": 1,
            "z": 4,
            "elements": [
                "appliedenergistics2:smooth_sky_stone_stairs@0"
            ]
        },
        {
            "x": -4,
            "y": 1,
            "z": 5,
            "elements": [
                "appliedenergistics2:smooth_sky_stone_slab@0"
            ]
        },
        {
            "x": -3,
            "y": 1,
            "z": 6,
            "elements": [
                "contenttweaker:tungstencasing@0"
            ]
        },
        {
            "x": 1,
            "y": 6,
            "z": 7,
            "elements": [
                "ic2:fence@0"
            ]
        },
        {
            "x": -3,
            "y": 1,
            "z": 7,
            "elements": [
                "appliedenergistics2:smooth_sky_stone_stairs@3"
            ]
        },
        {
            "x": -3,
            "y": 1,
            "z": 8,
            "elements": [
                "appliedenergistics2:smooth_sky_stone_slab@0"
            ]
        },
        {
            "x": 1,
            "y": 6,
            "z": 2,
            "elements": [
                "enderio:block_fused_quartz@0"
            ]
        },
        {
            "x": -3,
            "y": 1,
            "z": 2,
            "elements": [
                "appliedenergistics2:smooth_sky_stone_slab@0"
            ]
        },
        {
            "x": 1,
            "y": 6,
            "z": 3,
            "elements": [
                "ic2:fence@0"
            ]
        },
        {
            "x": -4,
            "y": 1,
            "z": 6,
            "elements": [
                "appliedenergistics2:smooth_sky_stone_stairs@0"
            ]
        },
        {
            "x": -3,
            "y": 1,
            "z": 3,
            "elements": [
                "appliedenergistics2:smooth_sky_stone_stairs@2"
            ]
        },
        {
            "x": -3,
            "y": 1,
            "z": 4,
            "elements": [
                "contenttweaker:tungstencasing@0"
            ]
        },
        {
            "x": -1,
            "y": 17,
            "z": 8,
            "elements": [
                "appliedenergistics2:smooth_sky_stone_stairs@3"
            ]
        },
        {
            "x": -1,
            "y": 17,
            "z": 7,
            "elements": [
                "contenttweaker:tungstencasing@0"
            ]
        },
        {
            "x": -1,
            "y": 5,
            "z": 2,
            "elements": [
                "fluxnetworks:fluxblock@0"
            ]
        },
        {
            "x": 2,
            "y": 12,
            "z": 7,
            "elements": [
                "enderio:block_fused_quartz@0"
            ]
        },
        {
            "x": 2,
            "y": 12,
            "z": 6,
            "elements": [
                "ic2:fence@0"
            ]
        },
        {
            "x": 2,
            "y": 12,
            "z": 4,
            "elements": [
                "ic2:fence@0"
            ]
        },
        {
            "x": 2,
            "y": 12,
            "z": 3,
            "elements": [
                "enderio:block_fused_quartz@0"
            ]
        },
        {
            "x": -3,
            "y": 4,
            "z": 6,
            "elements": [
                "enderio:block_fused_quartz@0"
            ]
        },
        {
            "x": -3,
            "y": 4,
            "z": 5,
            "elements": [
                "enderio:block_fused_quartz@0"
            ]
        },
        {
            "x": -3,
            "y": 4,
            "z": 4,
            "elements": [
                "enderio:block_fused_quartz@0"
            ]
        },
        {
            "x": -2,
            "y": 15,
            "z": 4,
            "elements": [
                "ic2:fence@0"
            ]
        },
        {
            "x": -2,
            "y": 15,
            "z": 3,
            "elements": [
                "enderio:block_fused_quartz@0"
            ]
        },
        {
            "x": -2,
            "y": 15,
            "z": 7,
            "elements": [
                "enderio:block_fused_quartz@0"
            ]
        },
        {
            "x": -3,
            "y": 19,
            "z": 5,
            "elements": [
                "appliedenergistics2:smooth_sky_stone_slab@0"
            ]
        },
        {
            "x": -2,
            "y": 15,
            "z": 6,
            "elements": [
                "ic2:fence@0"
            ]
        },
        {
            "x": -1,
            "y": 8,
            "z": 2,
            "elements": [
                "enderio:block_fused_quartz@0"
            ]
        },
        {
            "x": 0,
            "y": 4,
            "z": 8,
            "elements": [
                "enderio:block_fused_quartz@0"
            ]
        },
        {
            "x": -1,
            "y": 8,
            "z": 3,
            "elements": [
                "ic2:fence@0"
            ]
        },
        {
            "x": -3,
            "y": 16,
            "z": 6,
            "elements": [
                "enderio:block_fused_quartz@0"
            ]
        },
        {
            "x": -3,
            "y": 16,
            "z": 4,
            "elements": [
                "enderio:block_fused_quartz@0"
            ]
        },
        {
            "x": -1,
            "y": 8,
            "z": 7,
            "elements": [
                "ic2:fence@0"
            ]
        },
        {
            "x": -3,
            "y": 16,
            "z": 5,
            "elements": [
                "enderio:block_fused_quartz@0"
            ]
        },
        {
            "x": 0,
            "y": 4,
            "z": 5,
            "elements": [
                "contenttweaker:tungstenblock@0"
            ]
        },
        {
            "x": -1,
            "y": 8,
            "z": 8,
            "elements": [
                "enderio:block_fused_quartz@0"
            ]
        },
        {
            "x": -1,
            "y": 5,
            "z": 8,
            "elements": [
                "fluxnetworks:fluxblock@0"
            ]
        },
        {
            "x": -1,
            "y": 5,
            "z": 7,
            "elements": [
                "ic2:fence@0"
            ]
        },
        {
            "x": -1,
            "y": 5,
            "z": 6,

            "elements": [
                "mekanismgenerators:generator@9"
            ]
        },
        {
            "x": -1,
            "y": 5,
            "z": 5,

            "elements": [
                "mekanismgenerators:generator@9"
            ]
        },
        {
            "x": -1,
            "y": 5,
            "z": 4,

            "elements": [
                "mekanismgenerators:generator@9"
            ]
        },
        {
            "x": -1,
            "y": 5,
            "z": 3,
            "elements": [
                "ic2:fence@0"
            ]
        },
        {
            "x": 0,
            "y": 17,
            "z": 4,
            "elements": [
                "ic2:resource@13"
            ]
        },
        {
            "x": -3,
            "y": 0,
            "z": 2,
            "elements": [
                "enderio:block_reinforced_obsidian@0"
            ]
        },
        {
            "x": -3,
            "y": 0,
            "z": 3,
            "elements": [
                "enderio:block_reinforced_obsidian@0"
            ]
        },
        {
            "x": 0,
            "y": 17,
            "z": 5,
            "elements": [
                "ic2:resource@13"
            ]
        },
        {
            "x": 0,
            "y": 17,
            "z": 2,
            "elements": [
                "enderio:block_fused_quartz@0"
            ]
        },
        {
            "x": -3,
            "y": 0,
            "z": 4,
            "elements": [
                "enderio:block_reinforced_obsidian@0"
            ]
        },
        {
            "x": -3,
            "y": 0,
            "z": 5,
            "elements": [
                "enderio:block_alloy@6"
            ]
        },
        {
            "x": 0,
            "y": 17,
            "z": 3,
            "elements": [
                "enderio:block_reinforced_obsidian@0"
            ]
        },
        {
            "x": -3,
            "y": 0,
            "z": 6,
            "elements": [
                "enderio:block_reinforced_obsidian@0"
            ]
        },
        {
            "x": -3,
            "y": 0,
            "z": 7,
            "elements": [
                "enderio:block_reinforced_obsidian@0"
            ]
        },
        {
            "x": -3,
            "y": 0,
            "z": 8,
            "elements": [
                "enderio:block_reinforced_obsidian@0"
            ]
        },
        {
            "x": -1,
            "y": 9,
            "z": 7,
            "elements": [
                "ic2:fence@0"
            ]
        },
        {
            "x": -1,
            "y": 9,
            "z": 8,
            "elements": [
                "fluxnetworks:fluxblock@0"
            ]
        },
        {
            "x": -3,
            "y": 0,
            "z": 9,
            "elements": [
                "modularmachinery:blockcasing@4",
                "ItemInputStrengthen",
                "ItemOutputStrengthen",
                "FluidInputStrengthen",
                "EnergyInputStrengthen"
            ]
        },
        {
            "x": -1,
            "y": 9,
            "z": 5,

            "elements": [
                "mekanismgenerators:generator@9"
            ]
        },
        {
            "x": 3,
            "y": 1,
            "z": 2,
            "elements": [
                "appliedenergistics2:smooth_sky_stone_slab@0"
            ]
        },
        {
            "x": -1,
            "y": 9,
            "z": 6,

            "elements": [
                "mekanismgenerators:generator@9"
            ]
        },
        {
            "x": -1,
            "y": 9,
            "z": 3,
            "elements": [
                "ic2:fence@0"
            ]
        },
        {
            "x": -1,
            "y": 9,
            "z": 4,

            "elements": [
                "mekanismgenerators:generator@9"
            ]
        },
        {
            "x": 0,
            "y": 17,
            "z": 8,
            "elements": [
                "enderio:block_fused_quartz@0"
            ]
        },
        {
            "x": -1,
            "y": 9,
            "z": 2,
            "elements": [
                "fluxnetworks:fluxblock@0"
            ]
        },
        {
            "x": 0,
            "y": 17,
            "z": 6,
            "elements": [
                "ic2:resource@13"
            ]
        },
        {
            "x": 0,
            "y": 17,
            "z": 7,
            "elements": [
                "enderio:block_reinforced_obsidian@0"
            ]
        },
        {
            "x": -2,
            "y": 1,
            "z": 6,
            "elements": [
                "contenttweaker:tungstencasing@0"
            ]
        },
        {
            "x": -2,
            "y": 1,
            "z": 7,
            "elements": [
                "appliedenergistics2:smooth_sky_stone_slab@0"
            ]
        },
        {
            "x": -2,
            "y": 1,
            "z": 4,
            "elements": [
                "contenttweaker:tungstencasing@0"
            ]
        },
        {
            "x": -1,
            "y": 16,
            "z": 3,
            "elements": [
                "ic2:fence@0"
            ]
        },
        {
            "x": -2,
            "y": 1,
            "z": 5,
            "elements": [
                "appliedenergistics2:smooth_sky_stone_stairs@0"
            ]
        },
        {
            "x": -1,
            "y": 16,
            "z": 2,
            "elements": [
                "enderio:block_fused_quartz@0"
            ]
        },
        {
            "x": -2,
            "y": 1,
            "z": 2,
            "elements": [
                "appliedenergistics2:smooth_sky_stone_stairs@0"
            ]
        },
        {
            "x": -2,
            "y": 1,
            "z": 3,
            "elements": [
                "appliedenergistics2:smooth_sky_stone_slab@0"
            ]
        },
        {
            "x": -1,
            "y": 16,
            "z": 7,
            "elements": [
                "ic2:fence@0"
            ]
        },
        {
            "x": -1,
            "y": 16,
            "z": 8,
            "elements": [
                "enderio:block_fused_quartz@0"
            ]
        },
        {
            "x": -2,
            "y": 8,
            "z": 3,
            "elements": [
                "enderio:block_fused_quartz@0"
            ]
        },
        {
            "x": -2,
            "y": 8,
            "z": 4,
            "elements": [
                "ic2:fence@0"
            ]
        },
        {
            "x": -2,
            "y": 8,
            "z": 6,
            "elements": [
                "ic2:fence@0"
            ]
        },
        {
            "x": -2,
            "y": 1,
            "z": 8,
            "elements": [
                "appliedenergistics2:smooth_sky_stone_stairs@0"
            ]
        },
        {
            "x": -2,
            "y": 8,
            "z": 7,
            "elements": [
                "enderio:block_fused_quartz@0"
            ]
        },
        {
            "x": -3,
            "y": 0,
            "z": 1,
            "elements": [
                "modularmachinery:blockcasing@4",
                "ItemInputStrengthen",
                "ItemOutputStrengthen",
                "FluidInputStrengthen",
                "EnergyInputStrengthen"
            ]
        },
        {
            "x": -1,
            "y": 3,
            "z": 4,

            "elements": [
                "mekanismgenerators:generator@9"
            ]
        },
        {
            "x": -1,
            "y": 3,
            "z": 3,
            "elements": [
                "ic2:fence@0"
            ]
        },
        {
            "x": -1,
            "y": 3,
            "z": 2,
            "elements": [
                "fluxnetworks:fluxblock@0"
            ]
        },
        {
            "x": 3,
            "y": 1,
            "z": 7,
            "elements": [
                "appliedenergistics2:smooth_sky_stone_stairs@3"
            ]
        },
        {
            "x": 3,
            "y": 1,
            "z": 8,
            "elements": [
                "appliedenergistics2:smooth_sky_stone_slab@0"
            ]
        },
        {
            "x": 3,
            "y": 1,
            "z": 5,
            "elements": [
                "enderio:block_alloy_endergy@1"
            ]
        },
        {
            "x": -1,
            "y": 3,
            "z": 8,
            "elements": [
                "fluxnetworks:fluxblock@0"
            ]
        },
        {
            "x": 3,
            "y": 1,
            "z": 6,
            "elements": [
                "contenttweaker:tungstencasing@0"
            ]
        },
        {
            "x": -1,
            "y": 3,
            "z": 7,
            "elements": [
                "ic2:fence@0"
            ]
        },
        {
            "x": 3,
            "y": 1,
            "z": 3,
            "elements": [
                "appliedenergistics2:smooth_sky_stone_stairs@2"
            ]
        },
        {
            "x": -1,
            "y": 3,
            "z": 6,

            "elements": [
                "mekanismgenerators:generator@9"
            ]
        },
        {
            "x": 3,
            "y": 1,
            "z": 4,
            "elements": [
                "contenttweaker:tungstencasing@0"
            ]
        },
        {
            "x": -1,
            "y": 3,
            "z": 5,

            "elements": [
                "mekanismgenerators:generator@9"
            ]
        },
        {
            "x": -2,
            "y": 14,
            "z": 3,
            "elements": [
                "enderio:block_fused_quartz@0"
            ]
        },
        {
            "x": -2,
            "y": 14,
            "z": 4,
            "elements": [
                "ic2:fence@0"
            ]
        },
        {
            "x": -2,
            "y": 14,
            "z": 6,
            "elements": [
                "ic2:fence@0"
            ]
        },
        {
            "x": -2,
            "y": 14,
            "z": 7,
            "elements": [
                "enderio:block_fused_quartz@0"
            ]
        },
        {
            "x": -2,
            "y": 7,
            "z": 7,
            "elements": [
                "enderio:block_fused_quartz@0"
            ]
        },
        {
            "x": -2,
            "y": 2,
            "z": 7,
            "elements": [
                "enderio:block_fused_quartz@0"
            ]
        },
        {
            "x": -2,
            "y": 7,
            "z": 6,
            "elements": [
                "ic2:fence@0"
            ]
        },
        {
            "x": -2,
            "y": 7,
            "z": 3,
            "elements": [
                "enderio:block_fused_quartz@0"
            ]
        },
        {
            "x": -2,
            "y": 7,
            "z": 4,
            "elements": [
                "ic2:fence@0"
            ]
        },
        {
            "x": -1,
            "y": 15,
            "z": 6,

            "elements": [
                "mekanismgenerators:generator@9"
            ]
        },
        {
            "x": -1,
            "y": 15,
            "z": 5,

            "elements": [
                "mekanismgenerators:generator@9"
            ]
        },
        {
            "x": -1,
            "y": 15,
            "z": 8,
            "elements": [
                "fluxnetworks:fluxblock@0"
            ]
        },
        {
            "x": 0,
            "y": 11,
            "z": 8,
            "elements": [
                "enderio:block_fused_quartz@0"
            ]
        },
        {
            "x": -1,
            "y": 15,
            "z": 7,
            "elements": [
                "ic2:fence@0"
            ]
        },
        {
            "x": -1,
            "y": 15,
            "z": 2,
            "elements": [
                "fluxnetworks:fluxblock@0"
            ]
        },
        {
            "x": 0,
            "y": 11,
            "z": 6,

            "elements": [
                "mekanismgenerators:generator@9"
            ]
        },
        {
            "x": -1,
            "y": 15,
            "z": 4,

            "elements": [
                "mekanismgenerators:generator@9"
            ]
        },
        {
            "x": 0,
            "y": 11,
            "z": 5,
            "elements": [
                "contenttweaker:tungstenblock@0"
            ]
        },
        {
            "x": 0,
            "y": 11,
            "z": 4,

            "elements": [
                "mekanismgenerators:generator@9"
            ]
        },
        {
            "x": -1,
            "y": 15,
            "z": 3,
            "elements": [
                "ic2:fence@0"
            ]
        },
        {
            "x": 0,
            "y": 11,
            "z": 2,
            "elements": [
                "enderio:block_fused_quartz@0"
            ]
        },
        {
            "x": -3,
            "y": 12,
            "z": 6,
            "elements": [
                "enderio:block_fused_quartz@0"
            ]
        },
        {
            "x": 0,
            "y": 5,
            "z": 2,
            "elements": [
                "enderio:block_fused_quartz@0"
            ]
        },
        {
            "x": 0,
            "y": 5,
            "z": 4,

            "elements": [
                "mekanismgenerators:generator@9"
            ]
        },
        {
            "x": 0,
            "y": 5,
            "z": 5,
            "elements": [
                "contenttweaker:tungstenblock@0"
            ]
        },
        {
            "x": 0,
            "y": 5,
            "z": 6,

            "elements": [
                "mekanismgenerators:generator@9"
            ]
        },
        {
            "x": 3,
            "y": 7,
            "z": 6,
            "elements": [
                "fluxnetworks:fluxblock@0"
            ]
        },
        {
            "x": 3,
            "y": 7,
            "z": 5,
            "elements": [
                "enderio:block_fused_quartz@0"
            ]
        },
        {
            "x": 0,
            "y": 5,
            "z": 8,
            "elements": [
                "enderio:block_fused_quartz@0"
            ]
        },
        {
            "x": 3,
            "y": 13,
            "z": 4,
            "elements": [
                "fluxnetworks:fluxblock@0"
            ]
        },
        {
            "x": 3,
            "y": 13,
            "z": 5,
            "elements": [
                "enderio:block_fused_quartz@0"
            ]
        },
        {
            "x": 3,
            "y": 7,
            "z": 4,
            "elements": [
                "fluxnetworks:fluxblock@0"
            ]
        },
        {
            "x": 3,
            "y": 13,
            "z": 6,
            "elements": [
                "fluxnetworks:fluxblock@0"
            ]
        },
        {
            "x": -2,
            "y": 2,
            "z": 4,
            "elements": [
                "ic2:fence@0"
            ]
        },
        {
            "x": -3,
            "y": 6,
            "z": 6,
            "elements": [
                "enderio:block_fused_quartz@0"
            ]
        },
        {
            "x": -2,
            "y": 2,
            "z": 3,
            "elements": [
                "enderio:block_fused_quartz@0"
            ]
        },
        {
            "x": -3,
            "y": 6,
            "z": 5,
            "elements": [
                "enderio:block_fused_quartz@0"
            ]
        },
        {
            "x": -2,
            "y": 2,
            "z": 6,
            "elements": [
                "ic2:fence@0"
            ]
        },
        {
            "x": -3,
            "y": 6,
            "z": 4,
            "elements": [
                "enderio:block_fused_quartz@0"
            ]
        },
        {
            "x": 0,
            "y": 12,
            "z": 5,
            "elements": [
                "contenttweaker:tungstenblock@0"
            ]
        },
        {
            "x": -3,
            "y": 5,
            "z": 4,
            "elements": [
                "fluxnetworks:fluxblock@0"
            ]
        },
        {
            "x": 0,
            "y": 12,
            "z": 8,
            "elements": [
                "enderio:block_fused_quartz@0"
            ]
        },
        {
            "x": -2,
            "y": 13,
            "z": 3,
            "elements": [
                "enderio:block_fused_quartz@0"
            ]
        },
        {
            "x": 0,
            "y": 12,
            "z": 2,
            "elements": [
                "enderio:block_fused_quartz@0"
            ]
        },
        {
            "x": 3,
            "y": 6,
            "z": 5,
            "elements": [
                "enderio:block_fused_quartz@0"
            ]
        },
        {
            "x": 3,
            "y": 19,
            "z": 5,
            "elements": [
                "appliedenergistics2:smooth_sky_stone_slab@0"
            ]
        },
        {
            "x": 3,
            "y": 6,
            "z": 4,
            "elements": [
                "enderio:block_fused_quartz@0"
            ]
        },
        {
            "x": -1,
            "y": 4,
            "z": 3,
            "elements": [
                "ic2:fence@0"
            ]
        },
        {
            "x": -2,
            "y": 13,
            "z": 4,
            "elements": [
                "ic2:fence@0"
            ]
        },
        {
            "x": -1,
            "y": 4,
            "z": 2,
            "elements": [
                "enderio:block_fused_quartz@0"
            ]
        },
        {
            "x": -2,
            "y": 13,
            "z": 6,
            "elements": [
                "ic2:fence@0"
            ]
        },
        {
            "x": -2,
            "y": 13,
            "z": 7,
            "elements": [
                "enderio:block_fused_quartz@0"
            ]
        },
        {
            "x": -1,
            "y": 4,
            "z": 7,
            "elements": [
                "ic2:fence@0"
            ]
        },
        {
            "x": -3,
            "y": 5,
            "z": 6,
            "elements": [
                "fluxnetworks:fluxblock@0"
            ]
        },
        {
            "x": -3,
            "y": 5,
            "z": 5,
            "elements": [
                "enderio:block_fused_quartz@0"
            ]
        },
        {
            "x": -1,
            "y": 4,
            "z": 8,
            "elements": [
                "enderio:block_fused_quartz@0"
            ]
        },
        {
            "x": -3,
            "y": 12,
            "z": 4,
            "elements": [
                "enderio:block_fused_quartz@0"
            ]
        },
        {
            "x": -3,
            "y": 12,
            "z": 5,
            "elements": [
                "enderio:block_fused_quartz@0"
            ]
        },
        {
            "x": 3,
            "y": 12,
            "z": 4,
            "elements": [
                "enderio:block_fused_quartz@0"
            ]
        },
        {
            "x": 3,
            "y": 12,
            "z": 5,
            "elements": [
                "enderio:block_fused_quartz@0"
            ]
        },
        {
            "x": 3,
            "y": 12,
            "z": 6,
            "elements": [
                "enderio:block_fused_quartz@0"
            ]
        },
        {
            "x": 0,
            "y": 6,
            "z": 5,
            "elements": [
                "contenttweaker:tungstenblock@0"
            ]
        },
        {
            "x": -3,
            "y": 18,
            "z": 5,
            "elements": [
                "enderio:block_alloy@6"
            ]
        },
        {
            "x": -3,
            "y": 18,
            "z": 4,
            "elements": [
                "appliedenergistics2:smooth_sky_stone_slab@0"
            ]
        },
        {
            "x": 0,
            "y": 6,
            "z": 8,
            "elements": [
                "enderio:block_fused_quartz@0"
            ]
        },
        {
            "x": -3,
            "y": 18,
            "z": 6,
            "elements": [
                "appliedenergistics2:smooth_sky_stone_slab@0"
            ]
        },
        {
            "x": -3,
            "y": 11,
            "z": 5,
            "elements": [
                "enderio:block_fused_quartz@0"
            ]
        },
        {
            "x": 0,
            "y": 6,
            "z": 2,
            "elements": [
                "enderio:block_fused_quartz@0"
            ]
        },
        {
            "x": -3,
            "y": 11,
            "z": 6,
            "elements": [
                "fluxnetworks:fluxblock@0"
            ]
        },
        {
            "x": -3,
            "y": 11,
            "z": 4,
            "elements": [
                "fluxnetworks:fluxblock@0"
            ]
        },
        {
            "x": -1,
            "y": 10,
            "z": 8,
            "elements": [
                "enderio:block_fused_quartz@0"
            ]
        },
        {
            "x": -1,
            "y": 10,
            "z": 7,
            "elements": [
                "ic2:fence@0"
            ]
        },
        {
            "x": 3,
            "y": 0,
            "z": 6,
            "elements": [
                "enderio:block_reinforced_obsidian@0"
            ]
        },
        {
            "x": 3,
            "y": 0,
            "z": 7,
            "elements": [
                "enderio:block_reinforced_obsidian@0"
            ]
        },
        {
            "x": 3,
            "y": 0,
            "z": 4,
            "elements": [
                "enderio:block_reinforced_obsidian@0"
            ]
        },
        {
            "x": 3,
            "y": 0,
            "z": 5,
            "elements": [
                "enderio:block_alloy@6"
            ]
        },
        {
            "x": 1,
            "y": 14,
            "z": 8,
            "elements": [
                "enderio:block_fused_quartz@0"
            ]
        },
        {
            "x": 3,
            "y": 0,
            "z": 8,
            "elements": [
                "enderio:block_reinforced_obsidian@0"
            ]
        },
        {
            "x": -1,
            "y": 10,
            "z": 2,
            "elements": [
                "enderio:block_fused_quartz@0"
            ]
        },
        {
            "x": -1,
            "y": 10,
            "z": 3,
            "elements": [
                "ic2:fence@0"
            ]
        },
        {
            "x": 3,
            "y": 0,
            "z": 9,
            "elements": [
                "modularmachinery:blockcasing@4",
                "ItemInputStrengthen",
                "ItemOutputStrengthen",
                "FluidInputStrengthen",
                "EnergyInputStrengthen"
            ]
        },
        {
            "x": 1,
            "y": 14,
            "z": 7,
            "elements": [
                "ic2:fence@0"
            ]
        },
        {
            "x": 0,
            "y": 18,
            "z": 3,
            "elements": [
                "appliedenergistics2:smooth_sky_stone_slab@0"
            ]
        },
        {
            "x": 3,
            "y": 0,
            "z": 2,
            "elements": [
                "enderio:block_reinforced_obsidian@0"
            ]
        },
        {
            "x": 3,
            "y": 0,
            "z": 3,
            "elements": [
                "enderio:block_reinforced_obsidian@0"
            ]
        },
        {
            "x": 0,
            "y": 18,
            "z": 4,

            "elements": [
                "modularmachinery:blockcasing@1"
            ]
        },
        {
            "x": 1,
            "y": 14,
            "z": 3,
            "elements": [
                "ic2:fence@0"
            ]
        },
        {
            "x": 0,
            "y": 18,
            "z": 2,
            "elements": [
                "enderio:block_alloy@6"
            ]
        },
        {
            "x": 1,
            "y": 14,
            "z": 2,
            "elements": [
                "enderio:block_fused_quartz@0"
            ]
        },
        {
            "x": 3,
            "y": 0,
            "z": 1,
            "elements": [
                "modularmachinery:blockcasing@4",
                "ItemInputStrengthen",
                "ItemOutputStrengthen",
                "FluidInputStrengthen",
                "EnergyInputStrengthen"
            ]
        },
        {
            "x": 2,
            "y": 4,
            "z": 3,
            "elements": [
                "enderio:block_fused_quartz@0"
            ]
        },
        {
            "x": 2,
            "y": 4,
            "z": 4,
            "elements": [
                "ic2:fence@0"
            ]
        },
        {
            "x": 2,
            "y": 4,
            "z": 6,
            "elements": [
                "ic2:fence@0"
            ]
        },
        {
            "x": 2,
            "y": 4,
            "z": 7,
            "elements": [
                "enderio:block_fused_quartz@0"
            ]
        },
        {
            "x": 1,
            "y": 8,
            "z": 2,
            "elements": [
                "enderio:block_fused_quartz@0"
            ]
        },
        {
            "x": 2,
            "y": 10,
            "z": 7,
            "elements": [
                "enderio:block_fused_quartz@0"
            ]
        },
        {
            "x": 1,
            "y": 8,
            "z": 3,
            "elements": [
                "ic2:fence@0"
            ]
        },
        {
            "x": 2,
            "y": 10,
            "z": 6,
            "elements": [
                "ic2:fence@0"
            ]
        },
        {
            "x": 2,
            "y": 10,
            "z": 4,
            "elements": [
                "ic2:fence@0"
            ]
        },
        {
            "x": 2,
            "y": 10,
            "z": 3,
            "elements": [
                "enderio:block_fused_quartz@0"
            ]
        },
        {
            "x": 0,
            "y": 18,
            "z": 7,
            "elements": [
                "appliedenergistics2:smooth_sky_stone_slab@0"
            ]
        },
        {
            "x": 3,
            "y": 6,
            "z": 6,
            "elements": [
                "enderio:block_fused_quartz@0"
            ]
        },
        {
            "x": 0,
            "y": 18,
            "z": 8,
            "elements": [
                "enderio:block_alloy@6"
            ]
        },
        {
            "x": 0,
            "y": 18,
            "z": 5,

            "elements": [
                "modularmachinery:blockcasing@1"
            ]
        },
        {
            "x": 0,
            "y": 18,
            "z": 6,

            "elements": [
                "modularmachinery:blockcasing@1"
            ]
        },
        {
            "x": 1,
            "y": 15,
            "z": 2,
            "elements": [
                "fluxnetworks:fluxblock@0"
            ]
        },
        {
            "x": 1,
            "y": 15,
            "z": 4,

            "elements": [
                "mekanismgenerators:generator@9"
            ]
        },
        {
            "x": 1,
            "y": 15,
            "z": 3,
            "elements": [
                "ic2:fence@0"
            ]
        },
        {
            "x": 1,
            "y": 15,
            "z": 6,

            "elements": [
                "mekanismgenerators:generator@9"
            ]
        },
        {
            "x": 1,
            "y": 15,
            "z": 5,

            "elements": [
                "mekanismgenerators:generator@9"
            ]
        },
        {
            "x": -3,
            "y": 10,
            "z": 6,
            "elements": [
                "enderio:block_fused_quartz@0"
            ]
        },
        {
            "x": 2,
            "y": 3,
            "z": 6,
            "elements": [
                "ic2:fence@0"
            ]
        },
        {
            "x": 2,
            "y": 3,
            "z": 7,
            "elements": [
                "enderio:block_fused_quartz@0"
            ]
        },
        {
            "x": -3,
            "y": 10,
            "z": 4,
            "elements": [
                "enderio:block_fused_quartz@0"
            ]
        },
        {
            "x": -3,
            "y": 10,
            "z": 5,
            "elements": [
                "enderio:block_fused_quartz@0"
            ]
        },
        {
            "x": 2,
            "y": 16,
            "z": 7,
            "elements": [
                "enderio:block_fused_quartz@0"
            ]
        },
        {
            "x": -2,
            "y": 11,
            "z": 6,
            "elements": [
                "ic2:fence@0"
            ]
        },
        {
            "x": -2,
            "y": 11,
            "z": 7,
            "elements": [
                "enderio:block_fused_quartz@0"
            ]
        },
        {
            "x": 2,
            "y": 3,
            "z": 3,
            "elements": [
                "enderio:block_fused_quartz@0"
            ]
        },
        {
            "x": 2,
            "y": 3,
            "z": 4,
            "elements": [
                "ic2:fence@0"
            ]
        },
        {
            "x": 2,
            "y": 16,
            "z": 6,
            "elements": [
                "ic2:fence@0"
            ]
        },
        {
            "x": 3,
            "y": 4,
            "z": 6,
            "elements": [
                "enderio:block_fused_quartz@0"
            ]
        },
        {
            "x": 3,
            "y": 4,
            "z": 4,
            "elements": [
                "enderio:block_fused_quartz@0"
            ]
        },
        {
            "x": 3,
            "y": 4,
            "z": 5,
            "elements": [
                "enderio:block_fused_quartz@0"
            ]
        },
        {
            "x": 1,
            "y": 15,
            "z": 8,
            "elements": [
                "fluxnetworks:fluxblock@0"
            ]
        },
        {
            "x": 1,
            "y": 15,
            "z": 7,
            "elements": [
                "ic2:fence@0"
            ]
        },
        {
            "x": 0,
            "y": 14,
            "z": 2,
            "elements": [
                "enderio:block_fused_quartz@0"
            ]
        },
        {
            "x": 0,
            "y": 0,
            "z": 8,
            "elements": [
                "enderio:block_alloy@6"
            ]
        },
        {
            "x": 0,
            "y": 14,
            "z": 8,
            "elements": [
                "enderio:block_fused_quartz@0"
            ]
        },
        {
            "x": 0,
            "y": 0,
            "z": 7,
            "elements": [
                "enderio:block_alloy@6"
            ]
        },
        {
            "x": 0,
            "y": 0,
            "z": 10,
            "elements": [
                "modularmachinery:blockcasing@4",
                "ItemInputStrengthen",
                "ItemOutputStrengthen",
                "FluidInputStrengthen",
                "EnergyInputStrengthen"
            ]
        },
        {
            "x": 0,
            "y": 14,
            "z": 5,
            "elements": [
                "contenttweaker:tungstenblock@0"
            ]
        },
        {
            "x": 0,
            "y": 0,
            "z": 9,
            "elements": [
                "enderio:block_alloy@6"
            ]
        },
        {
            "x": 0,
            "y": 0,
            "z": 4,
            "elements": [
                "enderio:block_alloy@6"
            ]
        },
        {
            "x": 0,
            "y": 0,
            "z": 3,
            "elements": [
                "enderio:block_alloy@6"
            ]
        },
        {
            "x": 0,
            "y": 0,
            "z": 6,
            "elements": [
                "enderio:block_alloy@6"
            ]
        },
        {
            "x": 0,
            "y": 0,
            "z": 5,
            "elements": [
                "enderio:block_alloy@6"
            ]
        },
        {
            "x": 1,
            "y": 2,
            "z": 8,
            "elements": [
                "enderio:block_fused_quartz@0"
            ]
        },
        {
            "x": 1,
            "y": 2,
            "z": 7,
            "elements": [
                "ic2:fence@0"
            ]
        },
        {
            "x": 0,
            "y": 0,
            "z": 0,

            "elements": [
                "modularmachinery:blockcontroller@2"
            ]
        },
        {
            "x": 0,
            "y": 0,
            "z": 2,
            "elements": [
                "enderio:block_alloy@6"
            ]
        },
        {
            "x": 0,
            "y": 0,
            "z": 1,
            "elements": [
                "enderio:block_alloy@6"
            ]
        },
        {
            "x": 1,
            "y": 2,
            "z": 3,
            "elements": [
                "ic2:fence@0"
            ]
        },
        {
            "x": 1,
            "y": 2,
            "z": 2,
            "elements": [
                "enderio:block_fused_quartz@0"
            ]
        },
        {
            "x": 2,
            "y": 16,
            "z": 3,
            "elements": [
                "enderio:block_fused_quartz@0"
            ]
        },
        {
            "x": 2,
            "y": 16,
            "z": 4,
            "elements": [
                "ic2:fence@0"
            ]
        },
        {
            "x": 0,
            "y": 13,
            "z": 8,
            "elements": [
                "enderio:block_fused_quartz@0"
            ]
        },
        {
            "x": -2,
            "y": 11,
            "z": 3,
            "elements": [
                "enderio:block_fused_quartz@0"
            ]
        },
        {
            "x": -2,
            "y": 11,
            "z": 4,
            "elements": [
                "ic2:fence@0"
            ]
        },
        {
            "x": 0,
            "y": 13,
            "z": 6,

            "elements": [
                "mekanismgenerators:generator@9"
            ]
        },
        {
            "x": 0,
            "y": 13,
            "z": 5,
            "elements": [
                "contenttweaker:tungstenblock@0"
            ]
        },
        {
            "x": 0,
            "y": 13,
            "z": 4,

            "elements": [
                "mekanismgenerators:generator@9"
            ]
        },
        {
            "x": 0,
            "y": 13,
            "z": 2,
            "elements": [
                "enderio:block_fused_quartz@0"
            ]
        },
        {
            "x": 2,
            "y": 17,
            "z": 6,
            "elements": [
                "contenttweaker:tungstencasing@0"
            ]
        },
        {
            "x": 3,
            "y": 5,
            "z": 4,
            "elements": [
                "fluxnetworks:fluxblock@0"
            ]
        },
        {
            "x": 2,
            "y": 17,
            "z": 7,
            "elements": [
                "enderio:block_fused_quartz@0"
            ]
        },
        {
            "x": 2,
            "y": 17,
            "z": 4,
            "elements": [
                "contenttweaker:tungstencasing@0"
            ]
        },
        {
            "x": 3,
            "y": 5,
            "z": 6,
            "elements": [
                "fluxnetworks:fluxblock@0"
            ]
        },
        {
            "x": 3,
            "y": 5,
            "z": 5,
            "elements": [
                "enderio:block_fused_quartz@0"
            ]
        },
        {
            "x": 2,
            "y": 17,
            "z": 5,
            "elements": [
                "enderio:block_reinforced_obsidian@0"
            ]
        },
        {
            "x": -3,
            "y": 9,
            "z": 4,
            "elements": [
                "fluxnetworks:fluxblock@0"
            ]
        },
        {
            "x": 1,
            "y": 1,
            "z": 4,
            "elements": [
                "actuallyadditions:block_crystal_empowered@5"
            ]
        },
        {
            "x": 2,
            "y": 17,
            "z": 3,
            "elements": [
                "enderio:block_fused_quartz@0"
            ]
        },
        {
            "x": 1,
            "y": 1,
            "z": 3,
            "elements": [
                "contenttweaker:tungstencasing@0"
            ]
        },
        {
            "x": 1,
            "y": 1,
            "z": 2,
            "elements": [
                "contenttweaker:tungstencasing@0"
            ]
        },
        {
            "x": -3,
            "y": 9,
            "z": 6,
            "elements": [
                "fluxnetworks:fluxblock@0"
            ]
        },
        {
            "x": -3,
            "y": 9,
            "z": 5,
            "elements": [
                "enderio:block_fused_quartz@0"
            ]
        },
        {
            "x": 1,
            "y": 1,
            "z": 1,
            "elements": [
                "appliedenergistics2:smooth_sky_stone_stairs@2"
            ]
        },
        {
            "x": 1,
            "y": 1,
            "z": 8,
            "elements": [
                "contenttweaker:tungstencasing@0"
            ]
        },
        {
            "x": 1,
            "y": 1,
            "z": 7,
            "elements": [
                "contenttweaker:tungstencasing@0"
            ]
        },
        {
            "x": 1,
            "y": 1,
            "z": 6,
            "elements": [
                "actuallyadditions:block_crystal_empowered@5"
            ]
        },
        {
            "x": 1,
            "y": 1,
            "z": 5,
            "elements": [
                "ic2:resource@13"
            ]
        },
        {
            "x": 3,
            "y": 18,
            "z": 6,
            "elements": [
                "appliedenergistics2:smooth_sky_stone_slab@0"
            ]
        },
        {
            "x": 3,
            "y": 18,
            "z": 5,
            "elements": [
                "enderio:block_alloy@6"
            ]
        },
        {
            "x": 3,
            "y": 18,
            "z": 4,
            "elements": [
                "appliedenergistics2:smooth_sky_stone_slab@0"
            ]
        },
        {
            "x": 1,
            "y": 1,
            "z": 9,
            "elements": [
                "appliedenergistics2:smooth_sky_stone_stairs@3"
            ]
        },
        {
            "x": -1,
            "y": 12,
            "z": 7,
            "elements": [
                "ic2:fence@0"
            ]
        },
        {
            "x": -1,
            "y": 12,
            "z": 8,
            "elements": [
                "enderio:block_fused_quartz@0"
            ]
        },
        {
            "x": -1,
            "y": 12,
            "z": 2,
            "elements": [
                "enderio:block_fused_quartz@0"
            ]
        },
        {
            "x": -1,
            "y": 12,
            "z": 3,
            "elements": [
                "ic2:fence@0"
            ]
        },
        {
            "x": 1,
            "y": 0,
            "z": 5,
            "elements": [
                "enderio:block_alloy@6"
            ]
        },
        {
            "x": 1,
            "y": 0,
            "z": 4,
            "elements": [
                "enderio:block_alloy@6"
            ]
        },
        {
            "x": 1,
            "y": 0,
            "z": 3,
            "elements": [
                "enderio:block_alloy@6"
            ]
        },
        {
            "x": 1,
            "y": 0,
            "z": 2,
            "elements": [
                "enderio:block_reinforced_obsidian@0"
            ]
        },
        {
            "x": 1,
            "y": 0,
            "z": 1,
            "elements": [
                "enderio:block_reinforced_obsidian@0"
            ]
        },
        {
            "x": 1,
            "y": 0,
            "z": 0,
            "elements": [
                "modularmachinery:blockcasing@4",
                "ItemInputStrengthen",
                "ItemOutputStrengthen",
                "FluidInputStrengthen",
                "EnergyInputStrengthen"
            ]
        },
        {
            "x": -1,
            "y": 14,
            "z": 3,
            "elements": [
                "ic2:fence@0"
            ]
        },
        {
            "x": -1,
            "y": 14,
            "z": 2,
            "elements": [
                "enderio:block_fused_quartz@0"
            ]
        },
        {
            "x": 1,
            "y": 0,
            "z": 10,
            "elements": [
                "modularmachinery:blockcasing@4",
                "ItemInputStrengthen",
                "ItemOutputStrengthen",
                "FluidInputStrengthen",
                "EnergyInputStrengthen"
            ]
        },
        {
            "x": -1,
            "y": 14,
            "z": 7,
            "elements": [
                "ic2:fence@0"
            ]
        },
        {
            "x": 1,
            "y": 0,
            "z": 9,
            "elements": [
                "enderio:block_reinforced_obsidian@0"
            ]
        },
        {
            "x": 1,
            "y": 0,
            "z": 8,
            "elements": [
                "enderio:block_reinforced_obsidian@0"
            ]
        },
        {
            "x": 1,
            "y": 0,
            "z": 7,
            "elements": [
                "enderio:block_alloy@6"
            ]
        },
        {
            "x": 1,
            "y": 0,
            "z": 6,
            "elements": [
                "enderio:block_alloy@6"
            ]
        },
        {
            "x": -1,
            "y": 14,
            "z": 8,
            "elements": [
                "enderio:block_fused_quartz@0"
            ]
        },
        {
            "x": -1,
            "y": 11,
            "z": 3,
            "elements": [
                "ic2:fence@0"
            ]
        },
        {
            "x": -1,
            "y": 11,
            "z": 4,

            "elements": [
                "mekanismgenerators:generator@9"
            ]
        },
        {
            "x": 2,
            "y": 18,
            "z": 7,
            "elements": [
                "enderio:block_alloy@6"
            ]
        },
        {
            "x": -1,
            "y": 11,
            "z": 2,
            "elements": [
                "fluxnetworks:fluxblock@0"
            ]
        },
        {
            "x": 2,
            "y": 18,
            "z": 5,
            "elements": [
                "appliedenergistics2:smooth_sky_stone_slab@0"
            ]
        },
        {
            "x": 2,
            "y": 18,
            "z": 6,
            "elements": [
                "appliedenergistics2:smooth_sky_stone_stairs@2"
            ]
        },
        {
            "x": 2,
            "y": 18,
            "z": 3,
            "elements": [
                "enderio:block_alloy@6"
            ]
        },
        {
            "x": 2,
            "y": 18,
            "z": 4,
            "elements": [
                "appliedenergistics2:smooth_sky_stone_stairs@3"
            ]
        },
        {
            "x": 1,
            "y": 3,
            "z": 5,

            "elements": [
                "mekanismgenerators:generator@9"
            ]
        },
        {
            "x": 1,
            "y": 3,
            "z": 6,

            "elements": [
                "mekanismgenerators:generator@9"
            ]
        },
        {
            "x": 1,
            "y": 3,
            "z": 3,
            "elements": [
                "ic2:fence@0"
            ]
        },
        {
            "x": 1,
            "y": 3,
            "z": 4,

            "elements": [
                "mekanismgenerators:generator@9"
            ]
        },
        {
            "x": -1,
            "y": 11,
            "z": 7,
            "elements": [
                "ic2:fence@0"
            ]
        },
        {
            "x": -1,
            "y": 11,
            "z": 8,
            "elements": [
                "fluxnetworks:fluxblock@0"
            ]
        },
        {
            "x": 1,
            "y": 3,
            "z": 7,
            "elements": [
                "ic2:fence@0"
            ]
        },
        {
            "x": -1,
            "y": 11,
            "z": 5,

            "elements": [
                "mekanismgenerators:generator@9"
            ]
        },
        {
            "x": -1,
            "y": 11,
            "z": 6,

            "elements": [
                "mekanismgenerators:generator@9"
            ]
        },
        {
            "x": 1,
            "y": 3,
            "z": 8,
            "elements": [
                "fluxnetworks:fluxblock@0"
            ]
        },
        {
            "x": -2,
            "y": 0,
            "z": 3,
            "elements": [
                "enderio:block_reinforced_obsidian@0"
            ]
        },
        {
            "x": 2,
            "y": 5,
            "z": 4,
            "elements": [
                "ic2:fence@0"
            ]
        },
        {
            "x": -2,
            "y": 0,
            "z": 4,
            "elements": [
                "enderio:block_alloy@6"
            ]
        },
        {
            "x": 2,
            "y": 5,
            "z": 6,
            "elements": [
                "ic2:fence@0"
            ]
        },
        {
            "x": -2,
            "y": 0,
            "z": 1,
            "elements": [
                "modularmachinery:blockcasing@4",
                "ItemInputStrengthen",
                "ItemOutputStrengthen",
                "FluidInputStrengthen",
                "EnergyInputStrengthen"
            ]
        },
        {
            "x": 2,
            "y": 5,
            "z": 7,
            "elements": [
                "enderio:block_fused_quartz@0"
            ]
        },
        {
            "x": -2,
            "y": 0,
            "z": 2,
            "elements": [
                "enderio:block_reinforced_obsidian@0"
            ]
        },
        {
            "x": 2,
            "y": 15,
            "z": 4,
            "elements": [
                "ic2:fence@0"
            ]
        },
        {
            "x": -2,
            "y": 0,
            "z": 7,
            "elements": [
                "enderio:block_reinforced_obsidian@0"
            ]
        },
        {
            "x": 1,
            "y": 3,
            "z": 2,
            "elements": [
                "fluxnetworks:fluxblock@0"
            ]
        },
        {
            "x": -2,
            "y": 0,
            "z": 8,
            "elements": [
                "enderio:block_reinforced_obsidian@0"
            ]
        },
        {
            "x": -2,
            "y": 0,
            "z": 5,
            "elements": [
                "enderio:block_alloy@6"
            ]
        },
        {
            "x": -2,
            "y": 0,
            "z": 6,
            "elements": [
                "enderio:block_alloy@6"
            ]
        },
        {
            "x": 2,
            "y": 5,
            "z": 3,
            "elements": [
                "enderio:block_fused_quartz@0"
            ]
        },
        {
            "x": 2,
            "y": 15,
            "z": 3,
            "elements": [
                "enderio:block_fused_quartz@0"
            ]
        },
        {
            "x": 1,
            "y": 13,
            "z": 2,
            "elements": [
                "fluxnetworks:fluxblock@0"
            ]
        },
        {
            "x": 1,
            "y": 13,
            "z": 4,

            "elements": [
                "mekanismgenerators:generator@9"
            ]
        },
        {
            "x": 2,
            "y": 15,
            "z": 6,
            "elements": [
                "ic2:fence@0"
            ]
        },
        {
            "x": 2,
            "y": 15,
            "z": 7,
            "elements": [
                "enderio:block_fused_quartz@0"
            ]
        },
        {
            "x": 1,
            "y": 13,
            "z": 3,
            "elements": [
                "ic2:fence@0"
            ]
        },
        {
            "x": 1,
            "y": 13,
            "z": 6,

            "elements": [
                "mekanismgenerators:generator@9"
            ]
        },
        {
            "x": 1,
            "y": 13,
            "z": 5,

            "elements": [
                "mekanismgenerators:generator@9"
            ]
        },
        {
            "x": 1,
            "y": 13,
            "z": 8,
            "elements": [
                "fluxnetworks:fluxblock@0"
            ]
        },
        {
            "x": 1,
            "y": 13,
            "z": 7,
            "elements": [
                "ic2:fence@0"
            ]
        },
        {
            "x": 1,
            "y": 16,
            "z": 2,
            "elements": [
                "enderio:block_fused_quartz@0"
            ]
        },
        {
            "x": 1,
            "y": 16,
            "z": 3,
            "elements": [
                "ic2:fence@0"
            ]
        },
        {
            "x": -2,
            "y": 0,
            "z": 9,
            "elements": [
                "modularmachinery:blockcasing@4",
                "ItemInputStrengthen",
                "ItemOutputStrengthen",
                "FluidInputStrengthen",
                "EnergyInputStrengthen"
            ]
        },
        {
            "x": 1,
            "y": 16,
            "z": 7,
            "elements": [
                "ic2:fence@0"
            ]
        },
        {
            "x": 1,
            "y": 16,
            "z": 8,
            "elements": [
                "enderio:block_fused_quartz@0"
            ]
        },
        {
            "x": -2,
            "y": 12,
            "z": 6,
            "elements": [
                "ic2:fence@0"
            ]
        },
        {
            "x": -2,
            "y": 12,
            "z": 7,
            "elements": [
                "enderio:block_fused_quartz@0"
            ]
        },
        {
            "x": 2,
            "y": 2,
            "z": 3,
            "elements": [
                "enderio:block_fused_quartz@0"
            ]
        },
        {
            "x": 2,
            "y": 2,
            "z": 4,
            "elements": [
                "ic2:fence@0"
            ]
        },
        {
            "x": 2,
            "y": 2,
            "z": 6,
            "elements": [
                "ic2:fence@0"
            ]
        },
        {
            "x": 2,
            "y": 2,
            "z": 7,
            "elements": [
                "enderio:block_fused_quartz@0"
            ]
        },
        {
            "x": -2,
            "y": 12,
            "z": 3,
            "elements": [
                "enderio:block_fused_quartz@0"
            ]
        },
        {
            "x": -2,
            "y": 12,
            "z": 4,
            "elements": [
                "ic2:fence@0"
            ]
        },
        {
            "x": -1,
            "y": 2,
            "z": 8,
            "elements": [
                "enderio:block_fused_quartz@0"
            ]
        },
        {
            "x": -1,
            "y": 2,
            "z": 7,
            "elements": [
                "ic2:fence@0"
            ]
        },
        {
            "x": 3,
            "y": 17,
            "z": 4,
            "elements": [
                "appliedenergistics2:smooth_sky_stone_stairs@1"
            ]
        },
        {
            "x": 3,
            "y": 17,
            "z": 5,
            "elements": [
                "enderio:block_fused_quartz@0"
            ]
        },
        {
            "x": 3,
            "y": 17,
            "z": 6,
            "elements": [
                "appliedenergistics2:smooth_sky_stone_stairs@1"
            ]
        },
        {
            "x": -1,
            "y": 2,
            "z": 3,
            "elements": [
                "ic2:fence@0"
            ]
        },
        {
            "x": -1,
            "y": 2,
            "z": 2,
            "elements": [
                "enderio:block_fused_quartz@0"
            ]
        },
        {
            "x": 0,
            "y": 1,
            "z": 7,
            "elements": [
                "appliedenergistics2:smooth_sky_stone_stairs@3"
            ]
        },
        {
            "x": 0,
            "y": 1,
            "z": 6,
            "elements": [
                "ic2:resource@13"
            ]
        },
        {
            "x": -3,
            "y": 13,
            "z": 5,
            "elements": [
                "enderio:block_fused_quartz@0"
            ]
        },
        {
            "x": 0,
            "y": 1,
            "z": 9,
            "elements": [
                "appliedenergistics2:smooth_sky_stone_slab@0"
            ]
        },
        {
            "x": -3,
            "y": 13,
            "z": 6,
            "elements": [
                "fluxnetworks:fluxblock@0"
            ]
        },
        {
            "x": 0,
            "y": 1,
            "z": 8,
            "elements": [
                "enderio:block_alloy_endergy@1"
            ]
        },
        {
            "x": -2,
            "y": 9,
            "z": 4,
            "elements": [
                "ic2:fence@0"
            ]
        },
        {
            "x": -2,
            "y": 9,
            "z": 6,
            "elements": [
                "ic2:fence@0"
            ]
        },
        {
            "x": 0,
            "y": 1,
            "z": 1,
            "elements": [
                "appliedenergistics2:smooth_sky_stone_slab@0"
            ]
        },
        {
            "x": -2,
            "y": 9,
            "z": 7,
            "elements": [
                "enderio:block_fused_quartz@0"
            ]
        },
        {
            "x": 0,
            "y": 1,
            "z": 3,
            "elements": [
                "appliedenergistics2:smooth_sky_stone_stairs@2"
            ]
        },
        {
            "x": 0,
            "y": 1,
            "z": 2,
            "elements": [
                "enderio:block_alloy_endergy@1"
            ]
        },
        {
            "x": -3,
            "y": 13,
            "z": 4,
            "elements": [
                "fluxnetworks:fluxblock@0"
            ]
        },
        {
            "x": 0,
            "y": 1,
            "z": 5,
            "elements": [
                "ic2:resource@13"
            ]
        },
        {
            "x": 0,
            "y": 1,
            "z": 4,
            "elements": [
                "ic2:resource@13"
            ]
        },
        {
            "x": -2,
            "y": 9,
            "z": 3,
            "elements": [
                "enderio:block_fused_quartz@0"
            ]
        },
        {
            "x": 1,
            "y": 5,
            "z": 3,
            "elements": [
                "ic2:fence@0"
            ]
        },
        {
            "x": 1,
            "y": 5,
            "z": 4,

            "elements": [
                "mekanismgenerators:generator@9"
            ]
        },
        {
            "x": 1,
            "y": 5,
            "z": 2,
            "elements": [
                "fluxnetworks:fluxblock@0"
            ]
        },
        {
            "x": 1,
            "y": 5,
            "z": 7,
            "elements": [
                "ic2:fence@0"
            ]
        },
        {
            "x": 1,
            "y": 5,
            "z": 8,
            "elements": [
                "fluxnetworks:fluxblock@0"
            ]
        },
        {
            "x": 1,
            "y": 5,
            "z": 5,

            "elements": [
                "mekanismgenerators:generator@9"
            ]
        },
        {
            "x": 1,
            "y": 5,
            "z": 6,

            "elements": [
                "mekanismgenerators:generator@9"
            ]
        },
        {
            "x": 2,
            "y": 6,
            "z": 7,
            "elements": [
                "enderio:block_fused_quartz@0"
            ]
        },
        {
            "x": 0,
            "y": 4,
            "z": 2,
            "elements": [
                "enderio:block_fused_quartz@0"
            ]
        },
        {
            "x": 3,
            "y": 14,
            "z": 4,
            "elements": [
                "enderio:block_fused_quartz@0"
            ]
        },
        {
            "x": 3,
            "y": 14,
            "z": 5,
            "elements": [
                "enderio:block_fused_quartz@0"
            ]
        },
        {
            "x": 2,
            "y": 13,
            "z": 3,
            "elements": [
                "enderio:block_fused_quartz@0"
            ]
        },
        {
            "x": 3,
            "y": 14,
            "z": 6,
            "elements": [
                "enderio:block_fused_quartz@0"
            ]
        },
        {
            "x": 2,
            "y": 13,
            "z": 7,
            "elements": [
                "enderio:block_fused_quartz@0"
            ]
        },
        {
            "x": 2,
            "y": 6,
            "z": 3,
            "elements": [
                "enderio:block_fused_quartz@0"
            ]
        },
        {
            "x": 2,
            "y": 13,
            "z": 6,
            "elements": [
                "ic2:fence@0"
            ]
        },
        {
            "x": 2,
            "y": 6,
            "z": 4,
            "elements": [
                "ic2:fence@0"
            ]
        },
        {
            "x": 2,
            "y": 6,
            "z": 6,
            "elements": [
                "ic2:fence@0"
            ]
        },
        {
            "x": 2,
            "y": 13,
            "z": 4,
            "elements": [
                "ic2:fence@0"
            ]
        },
        {
            "x": -3,
            "y": 7,
            "z": 6,
            "elements": [
                "fluxnetworks:fluxblock@0"
            ]
        },
        {
            "x": 1,
            "y": 12,
            "z": 7,
            "elements": [
                "ic2:fence@0"
            ]
        },
        {
            "x": -3,
            "y": 7,
            "z": 5,
            "elements": [
                "enderio:block_fused_quartz@0"
            ]
        },
        {
            "x": 0,
            "y": 10,
            "z": 2,
            "elements": [
                "enderio:block_fused_quartz@0"
            ]
        },
        {
            "x": -3,
            "y": 7,
            "z": 4,
            "elements": [
                "fluxnetworks:fluxblock@0"
            ]
        },
        {
            "x": 1,
            "y": 12,
            "z": 8,
            "elements": [
                "enderio:block_fused_quartz@0"
            ]
        },
        {
            "x": 1,
            "y": 12,
            "z": 3,
            "elements": [
                "ic2:fence@0"
            ]
        },
        {
            "x": 1,
            "y": 12,
            "z": 2,
            "elements": [
                "enderio:block_fused_quartz@0"
            ]
        },
        {
            "x": 0,
            "y": 10,
            "z": 5,
            "elements": [
                "contenttweaker:tungstenblock@0"
            ]
        },
        {
            "x": 0,
            "y": 10,
            "z": 8,
            "elements": [
                "enderio:block_fused_quartz@0"
            ]
        },
        {
            "x": 3,
            "y": 8,
            "z": 5,
            "elements": [
                "enderio:block_fused_quartz@0"
            ]
        },
        {
            "x": 3,
            "y": 8,
            "z": 4,
            "elements": [
                "enderio:block_fused_quartz@0"
            ]
        },
        {
            "x": 2,
            "y": 19,
            "z": 3,
            "elements": [
                "appliedenergistics2:smooth_sky_stone_slab@0"
            ]
        },
        {
            "x": 3,
            "y": 8,
            "z": 6,
            "elements": [
                "enderio:block_fused_quartz@0"
            ]
        },
        {
            "x": 2,
            "y": 19,
            "z": 7,
            "elements": [
                "appliedenergistics2:smooth_sky_stone_slab@0"
            ]
        },
        {
            "x": 3,
            "y": 15,
            "z": 4,
            "elements": [
                "fluxnetworks:fluxblock@0"
            ]
        },
        {
            "x": -3,
            "y": 14,
            "z": 6,
            "elements": [
                "enderio:block_fused_quartz@0"
            ]
        },
        {
            "x": -3,
            "y": 14,
            "z": 4,
            "elements": [
                "enderio:block_fused_quartz@0"
            ]
        },
        {
            "x": -3,
            "y": 14,
            "z": 5,
            "elements": [
                "enderio:block_fused_quartz@0"
            ]
        },
        {
            "x": 0,
            "y": 3,
            "z": 2,
            "elements": [
                "enderio:block_fused_quartz@0"
            ]
        },
        {
            "x": 0,
            "y": 3,
            "z": 5,
            "elements": [
                "contenttweaker:tungstenblock@0"
            ]
        },
        {
            "x": 0,
            "y": 3,
            "z": 4,

            "elements": [
                "mekanismgenerators:generator@9"
            ]
        },
        {
            "x": 0,
            "y": 16,
            "z": 8,
            "elements": [
                "enderio:block_fused_quartz@0"
            ]
        },
        {
            "x": 0,
            "y": 3,
            "z": 6,

            "elements": [
                "mekanismgenerators:generator@9"
            ]
        },
        {
            "x": 0,
            "y": 3,
            "z": 8,
            "elements": [
                "enderio:block_fused_quartz@0"
            ]
        },
        {
            "x": 0,
            "y": 16,
            "z": 2,
            "elements": [
                "enderio:block_fused_quartz@0"
            ]
        },
        {
            "x": 0,
            "y": 16,
            "z": 5,
            "elements": [
                "contenttweaker:tungstenblock@0"
            ]
        },
        {
            "x": 3,
            "y": 2,
            "z": 4,
            "elements": [
                "enderio:block_fused_quartz@0"
            ]
        },
        {
            "x": 3,
            "y": 2,
            "z": 5,
            "elements": [
                "enderio:block_fused_quartz@0"
            ]
        },
        {
            "x": 3,
            "y": 2,
            "z": 6,
            "elements": [
                "enderio:block_fused_quartz@0"
            ]
        },
        {
            "x": 2,
            "y": 0,
            "z": 6,
            "elements": [
                "enderio:block_alloy@6"
            ]
        },
        {
            "x": 2,
            "y": 0,
            "z": 5,
            "elements": [
                "enderio:block_alloy@6"
            ]
        },
        {
            "x": 2,
            "y": 0,
            "z": 8,
            "elements": [
                "enderio:block_reinforced_obsidian@0"
            ]
        },
        {
            "x": 2,
            "y": 0,
            "z": 7,
            "elements": [
                "enderio:block_reinforced_obsidian@0"
            ]
        },
        {
            "x": 2,
            "y": 0,
            "z": 9,
            "elements": [
                "modularmachinery:blockcasing@4",
                "ItemInputStrengthen",
                "ItemOutputStrengthen",
                "FluidInputStrengthen",
                "EnergyInputStrengthen"
            ]
        },
        {
            "x": 2,
            "y": 14,
            "z": 7,
            "elements": [
                "enderio:block_fused_quartz@0"
            ]
        },
        {
            "x": -1,
            "y": 1,
            "z": 9,
            "elements": [
                "appliedenergistics2:smooth_sky_stone_stairs@3"
            ]
        },
        {
            "x": -1,
            "y": 1,
            "z": 8,
            "elements": [
                "contenttweaker:tungstencasing@0"
            ]
        },
        {
            "x": -1,
            "y": 1,
            "z": 7,
            "elements": [
                "contenttweaker:tungstencasing@0"
            ]
        },
        {
            "x": 1,
            "y": 18,
            "z": 8,
            "elements": [
                "appliedenergistics2:smooth_sky_stone_slab@0"
            ]
        },
        {
            "x": 1,
            "y": 18,
            "z": 4,

            "elements": [
                "modularmachinery:blockcasing@4"
            ]
        },
        {
            "x": 1,
            "y": 18,
            "z": 5,

            "elements": [
                "modularmachinery:blockcasing@1"
            ]
        },
        {
            "x": 1,
            "y": 18,
            "z": 6,

            "elements": [
                "modularmachinery:blockcasing@4"
            ]
        },
        {
            "x": 1,
            "y": 18,
            "z": 7,
            "elements": [
                "appliedenergistics2:smooth_sky_stone_stairs@0"
            ]
        },
        {
            "x": 1,
            "y": 4,
            "z": 8,
            "elements": [
                "enderio:block_fused_quartz@0"
            ]
        },
        {
            "x": -2,
            "y": 16,
            "z": 7,
            "elements": [
                "enderio:block_fused_quartz@0"
            ]
        },
        {
            "x": 2,
            "y": 14,
            "z": 6,
            "elements": [
                "ic2:fence@0"
            ]
        },
        {
            "x": 1,
            "y": 18,
            "z": 2,
            "elements": [
                "appliedenergistics2:smooth_sky_stone_slab@0"
            ]
        },
        {
            "x": -2,
            "y": 16,
            "z": 6,
            "elements": [
                "ic2:fence@0"
            ]
        },
        {
            "x": 2,
            "y": 14,
            "z": 3,
            "elements": [
                "enderio:block_fused_quartz@0"
            ]
        },
        {
            "x": 2,
            "y": 14,
            "z": 4,
            "elements": [
                "ic2:fence@0"
            ]
        },
        {
            "x": 1,
            "y": 18,
            "z": 3,
            "elements": [
                "appliedenergistics2:smooth_sky_stone_stairs@0"
            ]
        },
        {
            "x": 1,
            "y": 4,
            "z": 7,
            "elements": [
                "ic2:fence@0"
            ]
        },
        {
            "x": -2,
            "y": 16,
            "z": 4,
            "elements": [
                "ic2:fence@0"
            ]
        },
        {
            "x": 2,
            "y": 0,
            "z": 2,
            "elements": [
                "enderio:block_reinforced_obsidian@0"
            ]
        },
        {
            "x": -2,
            "y": 16,
            "z": 3,
            "elements": [
                "enderio:block_fused_quartz@0"
            ]
        },
        {
            "x": 2,
            "y": 0,
            "z": 1,
            "elements": [
                "modularmachinery:blockcasing@4",
                "ItemInputStrengthen",
                "ItemOutputStrengthen",
                "FluidInputStrengthen",
                "EnergyInputStrengthen"
            ]
        },
        {
            "x": 1,
            "y": 4,
            "z": 2,
            "elements": [
                "enderio:block_fused_quartz@0"
            ]
        },
        {
            "x": 2,
            "y": 0,
            "z": 4,
            "elements": [
                "enderio:block_alloy@6"
            ]
        },
        {
            "x": 1,
            "y": 4,
            "z": 3,
            "elements": [
                "ic2:fence@0"
            ]
        },
        {
            "x": 2,
            "y": 0,
            "z": 3,
            "elements": [
                "enderio:block_reinforced_obsidian@0"
            ]
        },
        {
            "x": 0,
            "y": 2,
            "z": 5,
            "elements": [
                "contenttweaker:tungstenblock@0"
            ]
        },
        {
            "x": 0,
            "y": 2,
            "z": 8,
            "elements": [
                "enderio:block_fused_quartz@0"
            ]
        },
        {
            "x": -3,
            "y": 15,
            "z": 5,
            "elements": [
                "enderio:block_fused_quartz@0"
            ]
        },
        {
            "x": -3,
            "y": 15,
            "z": 6,
            "elements": [
                "fluxnetworks:fluxblock@0"
            ]
        },
        {
            "x": -3,
            "y": 15,
            "z": 4,
            "elements": [
                "fluxnetworks:fluxblock@0"
            ]
        },
        {
            "x": 3,
            "y": 16,
            "z": 4,
            "elements": [
                "enderio:block_fused_quartz@0"
            ]
        },
        {
            "x": -1,
            "y": 1,
            "z": 6,
            "elements": [
                "actuallyadditions:block_crystal_empowered@5"
            ]
        },
        {
            "x": 2,
            "y": 1,
            "z": 8,
            "elements": [
                "appliedenergistics2:smooth_sky_stone_stairs@1"
            ]
        },
        {
            "x": -1,
            "y": 1,
            "z": 5,
            "elements": [
                "ic2:resource@13"
            ]
        },
        {
            "x": 3,
            "y": 16,
            "z": 5,
            "elements": [
                "enderio:block_fused_quartz@0"
            ]
        },
        {
            "x": -1,
            "y": 1,
            "z": 4,
            "elements": [
                "actuallyadditions:block_crystal_empowered@5"
            ]
        },
        {
            "x": 3,
            "y": 16,
            "z": 6,
            "elements": [
                "enderio:block_fused_quartz@0"
            ]
        },
        {
            "x": -1,
            "y": 1,
            "z": 3,
            "elements": [
                "contenttweaker:tungstencasing@0"
            ]
        },
        {
            "x": 2,
            "y": 1,
            "z": 4,
            "elements": [
                "contenttweaker:tungstencasing@0"
            ]
        },
        {
            "x": -1,
            "y": 1,
            "z": 2,
            "elements": [
                "contenttweaker:tungstencasing@0"
            ]
        },
        {
            "x": 0,
            "y": 9,
            "z": 2,
            "elements": [
                "enderio:block_fused_quartz@0"
            ]
        },
        {
            "x": 2,
            "y": 1,
            "z": 5,
            "elements": [
                "appliedenergistics2:smooth_sky_stone_stairs@1"
            ]
        },
        {
            "x": -1,
            "y": 1,
            "z": 1,
            "elements": [
