{
    "registryname": "YMG_Thermal_Ionization_Distillation_Column",
    "localizedname": "§b§lYMG§r§e§l—#FFFFFF§l热电离蒸馏塔 §r§e",
    "failure-action": "still",
    "requires-blueprint": false,
    "color": "FFFFFF",
    "parts": [
        {
            "x": -1,
            "y": 6,
            "z": 5,

            "elements": [
                "mekanism:basicblock2@0"
            ]
        },
        {
            "x": 3,
            "y": 11,
            "z": 5,
            "elements": [
                "mekanism:basicblock@8"
            ]
        },
        {
            "x": 3,
            "y": 11,
            "z": 2,
            "elements": [
                "mekanism:basicblock@8"
            ]
        },
        {
            "x": 3,
            "y": 11,
            "z": 1,
            "elements": [
                "mekanism:basicblock@8"
            ]
        },
        {
            "x": -1,
            "y": 6,
            "z": 6,
            "elements": [
                "enderio:block_alloy@0"
            ]
        },
        {
            "x": 3,
            "y": 11,
            "z": 4,
            "elements": [
                "mekanism:basicblock@8"
            ]
        },
        {
            "x": 1,
            "y": 8,
            "z": 6,
            "elements": [
                "ic2:fence@0"
            ]
        },
        {
            "x": 3,
            "y": 11,
            "z": 3,

            "elements": [
                "modularmachinery:blockcasing@0",
                "FluidOutput"
            ]
        },
        {
            "x": 0,
            "y": 7,
            "z": 0,
            "elements": [
                "enderio:block_alloy@0"
            ]
        },
        {
            "x": 0,
            "y": 7,
            "z": 1,

            "elements": [
                "mekanism:basicblock2@0"
            ]
        },
        {
            "x": 0,
            "y": 7,
            "z": 3,

            "elements": [
                "environmentaltech:lightning_rod_insulated@0"
            ]
        },
        {
            "x": -1,
            "y": 6,
            "z": 0,
            "elements": [
                "enderio:block_alloy@0"
            ]
        },
        {
            "x": -1,
            "y": 6,
            "z": 1,

            "elements": [
                "mekanism:basicblock2@0"
            ]
        },
        {
            "x": 0,
            "y": 7,
            "z": 5,

            "elements": [
                "mekanism:basicblock2@0"
            ]
        },
        {
            "x": 0,
            "y": 7,
            "z": 6,
            "elements": [
                "enderio:block_alloy@0"
            ]
        },
        {
            "x": -2,
            "y": 4,
            "z": 6,
            "elements": [
                "ic2:fence@0"
            ]
        },
        {
            "x": 2,
            "y": 9,
            "z": 6,
            "elements": [
                "mekanism:basicblock@8"
            ]
        },
        {
            "x": -2,
            "y": 4,
            "z": 5,

            "elements": [
                "mekanism:basicblock2@0"
            ]
        },
        {
            "x": 2,
            "y": 9,
            "z": 5,

            "elements": [
                "mekanism:basicblock2@0"
            ]
        },
        {
            "x": 2,
            "y": 9,
            "z": 4,

            "elements": [
                "mekanism:basicblock2@0"
            ]
        },
        {
            "x": -2,
            "y": 4,
            "z": 0,
            "elements": [
                "ic2:fence@0"
            ]
        },
        {
            "x": 1,
            "y": 9,
            "z": 0,
            "elements": [
                "mekanism:basicblock@8"
            ]
        },
        {
            "x": -2,
            "y": 4,
            "z": 2,

            "elements": [
                "mekanism:basicblock2@0"
            ]
        },
        {
            "x": 2,
            "y": 9,
            "z": 3,

            "elements": [
                "mekanism:basicblock2@0"
            ]
        },
        {
            "x": 1,
            "y": 9,
            "z": 1,

            "elements": [
                "mekanism:basicblock2@0"
            ]
        },
        {
            "x": -2,
            "y": 4,
            "z": 1,

            "elements": [
                "mekanism:basicblock2@0"
            ]
        },
        {
            "x": 2,
            "y": 9,
            "z": 2,

            "elements": [
                "mekanism:basicblock2@0"
            ]
        },
        {
            "x": -2,
            "y": 4,
            "z": 4,

            "elements": [
                "mekanism:basicblock2@0"
            ]
        },
        {
            "x": 2,
            "y": 9,
            "z": 1,

            "elements": [
                "mekanism:basicblock2@0"
            ]
        },
        {
            "x": -2,
            "y": 4,
            "z": 3,

            "elements": [
                "mekanism:basicblock2@0"
            ]
        },
        {
            "x": 2,
            "y": 9,
            "z": 0,
            "elements": [
                "mekanism:basicblock@8"
            ]
        },
        {
            "x": 1,
            "y": 9,
            "z": 6,
            "elements": [
                "mekanism:basicblock@8"
            ]
        },
        {
            "x": 1,
            "y": 9,
            "z": 5,

            "elements": [
                "mekanism:basicblock2@0"
            ]
        },
        {
            "x": 3,
            "y": 10,
            "z": 3,
            "elements": [
                "enderio:block_alloy@0"
            ]
        },
        {
            "x": 3,
            "y": 10,
            "z": 2,
            "elements": [
                "ic2:fence@0"
            ]
        },
        {
            "x": 3,
            "y": 10,
            "z": 5,
            "elements": [
                "ic2:fence@0"
            ]
        },
        {
            "x": 3,
            "y": 10,
            "z": 4,
            "elements": [
                "ic2:fence@0"
            ]
        },
        {
            "x": -2,
            "y": 5,
            "z": 1,

            "elements": [
                "mekanism:basicblock2@0"
            ]
        },
        {
            "x": -2,
            "y": 5,
            "z": 0,
            "elements": [
                "mekanism:basicblock@8"
            ]
        },
        {
            "x": -2,
            "y": 5,
            "z": 3,

            "elements": [
                "mekanism:basicblock2@0"
            ]
        },
        {
            "x": -2,
            "y": 5,
            "z": 2,

            "elements": [
                "mekanism:basicblock2@0"
            ]
        },
        {
            "x": -3,
            "y": 3,
            "z": 3,
            "elements": [
                "appliedenergistics2:smooth_sky_stone_block@0"
            ]
        },
        {
            "x": 1,
            "y": 7,
            "z": 1,

            "elements": [
                "mekanism:basicblock2@0"
            ]
        },
        {
            "x": -3,
            "y": 3,
            "z": 4,
            "elements": [
                "enderio:block_alloy@0"
            ]
        },
        {
            "x": -3,
            "y": 3,
            "z": 5,
            "elements": [
                "mekanism:basicblock@8"
            ]
        },
        {
            "x": 1,
            "y": 7,
            "z": 0,
            "elements": [
                "mekanism:basicblock@8"
            ]
        },
        {
            "x": 1,
            "y": 7,
            "z": 5,

            "elements": [
                "mekanism:basicblock2@0"
            ]
        },
        {
            "x": 2,
            "y": 11,
            "z": 1,

            "elements": [
                "mekanism:basicblock2@0"
            ]
        },
        {
            "x": -2,
            "y": 5,
            "z": 5,

            "elements": [
                "mekanism:basicblock2@0"
            ]
        },
        {
            "x": 2,
            "y": 11,
            "z": 0,
            "elements": [
                "mekanism:basicblock@8"
            ]
        },
        {
            "x": 1,
            "y": 7,
            "z": 6,
            "elements": [
                "mekanism:basicblock@8"
            ]
        },
        {
            "x": -2,
            "y": 5,
            "z": 4,

            "elements": [
                "mekanism:basicblock2@0"
            ]
        },
        {
            "x": -3,
            "y": 3,
            "z": 1,
            "elements": [
                "mekanism:basicblock@8"
            ]
        },
        {
            "x": -3,
            "y": 3,
            "z": 2,
            "elements": [
                "enderio:block_alloy@0"
            ]
        },
        {
            "x": -2,
            "y": 5,
            "z": 6,
            "elements": [
                "mekanism:basicblock@8"
            ]
        },
        {
            "x": 0,
            "y": 8,
            "z": 3,

            "elements": [
                "environmentaltech:lightning_rod_insulated@0"
            ]
        },
        {
            "x": 0,
            "y": 8,
            "z": 5,

            "elements": [
                "mekanism:basicblock2@0"
            ]
        },
        {
            "x": 0,
            "y": 8,
            "z": 6,
            "elements": [
                "enderio:block_alloy@0"
            ]
        },
        {
            "x": 0,
            "y": 8,
            "z": 0,
            "elements": [
                "enderio:block_alloy@0"
            ]
        },
        {
            "x": 0,
            "y": 8,
            "z": 1,

            "elements": [
                "mekanism:basicblock2@0"
            ]
        },
        {
            "x": 3,
            "y": 10,
            "z": 1,
            "elements": [
                "ic2:fence@0"
            ]
        },
        {
            "x": 1,
            "y": 10,
            "z": 1,

            "elements": [
                "mekanism:basicblock2@0"
            ]
        },
        {
            "x": 1,
            "y": 10,
            "z": 0,
            "elements": [
                "ic2:fence@0"
            ]
        },
        {
            "x": 3,
            "y": -1,
            "z": 5,
            "elements": [
                "appliedenergistics2:smooth_sky_stone_stairs@3"
            ]
        },
        {
            "x": 3,
            "y": -1,
            "z": 3,
            "elements": [
                "enderio:block_reinforced_obsidian@0"
            ]
        },
        {
            "x": 2,
            "y": 11,
            "z": 5,

            "elements": [
                "mekanism:basicblock2@0"
            ]
        },
        {
            "x": -2,
            "y": 6,
            "z": 4,

            "elements": [
                "mekanism:basicblock2@0"
            ]
        },
        {
            "x": -2,
            "y": 6,
            "z": 3,

            "elements": [
                "mekanism:basicblock2@0"
            ]
        },
        {
            "x": 2,
            "y": 11,
            "z": 4,

            "elements": [
                "mekanism:basicblock2@0"
            ]
        },
        {
            "x": 3,
            "y": -1,
            "z": 4,
            "elements": [
                "enderio:block_reinforced_obsidian@0"
            ]
        },
        {
            "x": 2,
            "y": 11,
            "z": 3,

            "elements": [
                "mekanism:basicblock2@0"
            ]
        },
        {
            "x": 3,
            "y": -1,
            "z": 1,
            "elements": [
                "appliedenergistics2:smooth_sky_stone_stairs@2"
            ]
        },
        {
            "x": -2,
            "y": 6,
            "z": 6,
            "elements": [
                "ic2:fence@0"
            ]
        },
        {
            "x": 2,
            "y": 11,
            "z": 2,

            "elements": [
                "mekanism:basicblock2@0"
            ]
        },
        {
            "x": 3,
            "y": -1,
            "z": 2,
            "elements": [
                "enderio:block_reinforced_obsidian@0"
            ]
        },
        {
            "x": -2,
            "y": 6,
            "z": 5,

            "elements": [
                "mekanism:basicblock2@0"
            ]
        },
        {
            "x": -2,
            "y": 3,
            "z": 6,
            "elements": [
                "mekanism:basicblock@8"
            ]
        },
        {
            "x": 2,
            "y": 8,
            "z": 6,
            "elements": [
                "ic2:fence@0"
            ]
        },
        {
            "x": 2,
            "y": 11,
            "z": 6,
            "elements": [
                "mekanism:basicblock@8"
            ]
        },
        {
            "x": 2,
            "y": 8,
            "z": 5,

            "elements": [
                "mekanism:basicblock2@0"
            ]
        },
        {
            "x": -2,
            "y": 3,
            "z": 3,

            "elements": [
                "mekanism:basicblock2@0"
            ]
        },
        {
            "x": 2,
            "y": 8,
            "z": 4,

            "elements": [
                "mekanism:basicblock2@0"
            ]
        },
        {
            "x": -2,
            "y": 3,
            "z": 2,

            "elements": [
                "mekanism:basicblock2@0"
            ]
        },
        {
            "x": 2,
            "y": 8,
            "z": 3,

            "elements": [
                "mekanism:basicblock2@0"
            ]
        },
        {
            "x": 2,
            "y": 8,
            "z": 2,

            "elements": [
                "mekanism:basicblock2@0"
            ]
        },
        {
            "x": -2,
            "y": 3,
            "z": 5,

            "elements": [
                "mekanism:basicblock2@0"
            ]
        },
        {
            "x": 2,
            "y": 8,
            "z": 1,

            "elements": [
                "mekanism:basicblock2@0"
            ]
        },
        {
            "x": -2,
            "y": 3,
            "z": 4,

            "elements": [
                "mekanism:basicblock2@0"
            ]
        },
        {
            "x": 2,
            "y": 8,
            "z": 0,
            "elements": [
                "ic2:fence@0"
            ]
        },
        {
            "x": 1,
            "y": 10,
            "z": 5,

            "elements": [
                "mekanism:basicblock2@0"
            ]
        },
        {
            "x": -2,
            "y": 3,
            "z": 1,

            "elements": [
                "mekanism:basicblock2@0"
            ]
        },
        {
            "x": 1,
            "y": 10,
            "z": 6,
            "elements": [
                "ic2:fence@0"
            ]
        },
        {
            "x": -2,
            "y": 3,
            "z": 0,
            "elements": [
                "mekanism:basicblock@8"
            ]
        },
        {
            "x": -1,
            "y": 17,
            "z": 4,
            "elements": [
                "appliedenergistics2:quartz_vibrant_glass@0"
            ]
        },
        {
            "x": -1,
            "y": 17,
            "z": 3,
            "elements": [
                "appliedenergistics2:quartz_vibrant_glass@0"
            ]
        },
        {
            "x": -1,
            "y": 17,
            "z": 5,
            "elements": [
                "appliedenergistics2:smooth_sky_stone_stairs@3"
            ]
        },
        {
            "x": -1,
            "y": 17,
            "z": 2,
            "elements": [
                "appliedenergistics2:quartz_vibrant_glass@0"
            ]
        },
        {
            "x": -1,
            "y": 17,
            "z": 1,
            "elements": [
                "appliedenergistics2:smooth_sky_stone_stairs@2"
            ]
        },
        {
            "x": -3,
            "y": 1,
            "z": 5,
            "elements": [
                "ic2:fence@0"
            ]
        },
        {
            "x": 1,
            "y": 6,
            "z": 6,
            "elements": [
                "enderio:block_alloy@0"
            ]
        },
        {
            "x": 1,
            "y": 6,
            "z": 5,

            "elements": [
                "mekanism:basicblock2@0"
            ]
        },
        {
            "x": -3,
            "y": 1,
            "z": 1,
            "elements": [
                "ic2:fence@0"
            ]
        },
        {
            "x": -3,
            "y": 1,
            "z": 2,
            "elements": [
                "enderio:block_alloy@0"
            ]
        },
        {
            "x": -3,
            "y": 1,
            "z": 3,

            "elements": [
                "modularmachinery:blockcasing@0",
                "ItemOutput",
                "FluidInput",
                "EnergyInput"
            ]
        },
        {
            "x": 1,
            "y": 6,
            "z": 0,
            "elements": [
                "enderio:block_alloy@0"
            ]
        },
        {
            "x": 1,
            "y": 6,
            "z": 1,

            "elements": [
                "mekanism:basicblock2@0"
            ]
        },
        {
            "x": -3,
            "y": 1,
            "z": 4,
            "elements": [
                "enderio:block_alloy@0"
            ]
        },
        {
            "x": -1,
            "y": 5,
            "z": 1,

            "elements": [
                "mekanism:basicblock2@0"
            ]
        },
        {
            "x": 2,
            "y": 12,
            "z": 6,
            "elements": [
                "ic2:fence@0"
            ]
        },
        {
            "x": -1,
            "y": 5,
            "z": 0,
            "elements": [
                "enderio:block_alloy@0"
            ]
        },
        {
            "x": 2,
            "y": 12,
            "z": 5,

            "elements": [
                "mekanism:basicblock2@0"
            ]
        },
        {
            "x": 2,
            "y": 12,
            "z": 4,

            "elements": [
                "mekanism:basicblock2@0"
            ]
        },
        {
            "x": 2,
            "y": 12,
            "z": 3,

            "elements": [
                "mekanism:basicblock2@0"
            ]
        },
        {
            "x": 2,
            "y": 12,
            "z": 2,

            "elements": [
                "mekanism:basicblock2@0"
            ]
        },
        {
            "x": 2,
            "y": 12,
            "z": 1,

            "elements": [
                "mekanism:basicblock2@0"
            ]
        },
        {
            "x": 2,
            "y": 12,
            "z": 0,
            "elements": [
                "ic2:fence@0"
            ]
        },
        {
            "x": -3,
            "y": 4,
            "z": 5,
            "elements": [
                "ic2:fence@0"
            ]
        },
        {
            "x": -3,
            "y": 4,
            "z": 4,
            "elements": [
                "enderio:block_alloy@0"
            ]
        },
        {
            "x": -3,
            "y": 4,
            "z": 3,

            "elements": [
                "modularmachinery:blockcasing@1"
            ]
        },
        {
            "x": -3,
            "y": 4,
            "z": 2,
            "elements": [
                "enderio:block_alloy@0"
            ]
        },
        {
            "x": -3,
            "y": 4,
            "z": 1,
            "elements": [
                "ic2:fence@0"
            ]
        },
        {
            "x": 2,
            "y": -1,
            "z": 3,
            "elements": [
                "enderio:block_reinforced_obsidian@0"
            ]
        },
        {
            "x": -3,
            "y": 16,
            "z": 1,
            "elements": [
                "appliedenergistics2:smooth_sky_stone_slab@0"
            ]
        },
        {
            "x": 2,
            "y": -1,
            "z": 2,
            "elements": [
                "enderio:block_reinforced_obsidian@0"
            ]
        },
        {
            "x": 2,
            "y": -1,
            "z": 5,
            "elements": [
                "enderio:block_reinforced_obsidian@0"
            ]
        },
        {
            "x": 2,
            "y": -1,
            "z": 4,
            "elements": [
                "enderio:block_reinforced_obsidian@0"
            ]
        },
        {
            "x": 2,
            "y": -1,
            "z": 1,
            "elements": [
                "enderio:block_reinforced_obsidian@0"
            ]
        },
        {
            "x": 2,
            "y": -1,
            "z": 0,
            "elements": [
                "appliedenergistics2:smooth_sky_stone_stairs@1"
            ]
        },
        {
            "x": -2,
            "y": 15,
            "z": 5,

            "elements": [
                "mekanism:basicblock2@0"
            ]
        },
        {
            "x": -2,
            "y": 15,
            "z": 4,

            "elements": [
                "mekanism:basicblock2@0"
            ]
        },
        {
            "x": -2,
            "y": 15,
            "z": 3,

            "elements": [
                "mekanism:basicblock2@0"
            ]
        },
        {
            "x": -2,
            "y": 15,
            "z": 2,

            "elements": [
                "mekanism:basicblock2@0"
            ]
        },
        {
            "x": 2,
            "y": -1,
            "z": 6,
            "elements": [
                "appliedenergistics2:smooth_sky_stone_stairs@1"
            ]
        },
        {
            "x": -2,
            "y": 15,
            "z": 6,
            "elements": [
                "mekanism:basicblock@8"
            ]
        },
        {
            "x": -1,
            "y": 8,
            "z": 0,
            "elements": [
                "ic2:fence@0"
            ]
        },
        {
            "x": -1,
            "y": 8,
            "z": 1,

            "elements": [
                "mekanism:basicblock2@0"
            ]
        },
        {
            "x": -3,
            "y": 16,
            "z": 4,
            "elements": [
                "appliedenergistics2:smooth_sky_stone_slab@0"
            ]
        },
        {
            "x": -2,
            "y": 6,
            "z": 0,
            "elements": [
                "ic2:fence@0"
            ]
        },
        {
            "x": -1,
            "y": 8,
            "z": 6,
            "elements": [
                "ic2:fence@0"
            ]
        },
        {
            "x": 0,
            "y": 4,
            "z": 3,

            "elements": [
                "environmentaltech:lightning_rod_insulated@0"
            ]
        },
        {
            "x": -3,
            "y": 16,
            "z": 5,
            "elements": [
                "appliedenergistics2:smooth_sky_stone_slab@0"
            ]
        },
        {
            "x": -2,
            "y": 6,
            "z": 2,

            "elements": [
                "mekanism:basicblock2@0"
            ]
        },
        {
            "x": 0,
            "y": 4,
            "z": 6,

            "elements": [
                "modularmachinery:blockcasing@1"
            ]
        },
        {
            "x": -3,
            "y": 16,
            "z": 2,
            "elements": [
                "appliedenergistics2:smooth_sky_stone_slab@0"
            ]
        },
        {
            "x": -2,
            "y": 6,
            "z": 1,

            "elements": [
                "mekanism:basicblock2@0"
            ]
        },
        {
            "x": -3,
            "y": 16,
            "z": 3,
            "elements": [
                "appliedenergistics2:smooth_sky_stone_stairs@0"
            ]
        },
        {
            "x": -1,
            "y": 8,
            "z": 5,

            "elements": [
                "mekanism:basicblock2@0"
            ]
        },
        {
            "x": 0,
            "y": 4,
            "z": 5,

            "elements": [
                "mekanism:basicblock2@0"
            ]
        },
        {
            "x": -1,
            "y": 5,
            "z": 6,
            "elements": [
                "enderio:block_alloy@0"
            ]
        },
        {
            "x": -1,
            "y": 5,
            "z": 5,

            "elements": [
                "mekanism:basicblock2@0"
            ]
        },
        {
            "x": 0,
            "y": 17,
            "z": 4,
            "elements": [
                "appliedenergistics2:quartz_vibrant_glass@0"
            ]
        },
        {
            "x": -3,
            "y": 0,
            "z": 2,
            "elements": [
                "enderio:block_alloy@0"
            ]
        },
        {
            "x": -3,
            "y": 0,
            "z": 3,

            "elements": [
                "modularmachinery:blockcasing@0",
                "ItemOutput",
                "FluidInput",
                "EnergyInput"
            ]
        },
        {
            "x": 0,
            "y": 17,
            "z": 5,
            "elements": [
                "appliedenergistics2:smooth_sky_stone_slab@0"
            ]
        },
        {
            "x": 0,
            "y": 17,
            "z": 2,
            "elements": [
                "appliedenergistics2:quartz_vibrant_glass@0"
            ]
        },
        {
            "x": -3,
            "y": 0,
            "z": 4,
            "elements": [
                "enderio:block_alloy@0"
            ]
        },
        {
            "x": -3,
            "y": 0,
            "z": 5,
            "elements": [
                "ic2:fence@0"
            ]
        },
        {
            "x": 0,
            "y": 17,
            "z": 3,
            "elements": [
                "enderio:block_alloy@6"
            ]
        },
        {
            "x": 0,
            "y": 17,
            "z": 1,
            "elements": [
                "appliedenergistics2:smooth_sky_stone_slab@0"
            ]
        },
        {
            "x": -2,
            "y": 8,
            "z": 0,
            "elements": [
                "ic2:fence@0"
            ]
        },
        {
            "x": -1,
            "y": 9,
            "z": 5,

            "elements": [
                "mekanism:basicblock2@0"
            ]
        },
        {
            "x": 3,
            "y": 1,
            "z": 1,
            "elements": [
                "ic2:fence@0"
            ]
        },
        {
            "x": 3,
            "y": 1,
            "z": 2,
            "elements": [
                "enderio:block_alloy@0"
            ]
        },
        {
            "x": -1,
            "y": 9,
            "z": 6,
            "elements": [
                "mekanism:basicblock@8"
            ]
        },
        {
            "x": -1,
            "y": 9,
            "z": 1,

            "elements": [
                "mekanism:basicblock2@0"
            ]
        },
        {
            "x": -1,
            "y": 9,
            "z": 0,
            "elements": [
                "mekanism:basicblock@8"
            ]
        },
        {
            "x": -2,
            "y": 1,
            "z": 6,
            "elements": [
                "ic2:fence@0"
            ]
        },
        {
            "x": -1,
            "y": 16,
            "z": 1,

            "elements": [
                "mekanism:basicblock2@0"
            ]
        },
        {
            "x": -1,
            "y": 16,
            "z": 0,
            "elements": [
                "appliedenergistics2:smooth_sky_stone_slab@0"
            ]
        },
        {
            "x": -2,
            "y": 1,
            "z": 4,

            "elements": [
                "mekanism:basicblock2@0"
            ]
        },
        {
            "x": -2,
            "y": 1,
            "z": 5,

            "elements": [
                "mekanism:basicblock2@0"
            ]
        },
        {
            "x": -2,
            "y": 1,
            "z": 2,

            "elements": [
                "mekanism:basicblock2@0"
            ]
        },
        {
            "x": -1,
            "y": 16,
            "z": 5,

            "elements": [
                "mekanism:basicblock2@0"
            ]
        },
        {
            "x": -2,
            "y": 1,
            "z": 3,

            "elements": [
                "mekanism:basicblock2@0"
            ]
        },
        {
            "x": -2,
            "y": 1,
            "z": 0,
            "elements": [
                "ic2:fence@0"
            ]
        },
        {
            "x": -1,
            "y": 16,
            "z": 6,
            "elements": [
                "appliedenergistics2:smooth_sky_stone_slab@0"
            ]
        },
        {
            "x": -2,
            "y": 1,
            "z": 1,

            "elements": [
                "mekanism:basicblock2@0"
            ]
        },
        {
            "x": -2,
            "y": 8,
            "z": 1,

            "elements": [
                "mekanism:basicblock2@0"
            ]
        },
        {
            "x": -2,
            "y": 8,
            "z": 2,

            "elements": [
                "mekanism:basicblock2@0"
            ]
        },
        {
            "x": -2,
            "y": 8,
            "z": 3,

            "elements": [
                "mekanism:basicblock2@0"
            ]
        },
        {
            "x": -2,
            "y": 8,
            "z": 4,

            "elements": [
                "mekanism:basicblock2@0"
            ]
        },
        {
            "x": -2,
            "y": 8,
            "z": 5,

            "elements": [
                "mekanism:basicblock2@0"
            ]
        },
        {
            "x": -2,
            "y": 8,
            "z": 6,
            "elements": [
                "ic2:fence@0"
            ]
        },
        {
            "x": -3,
            "y": 0,
            "z": 1,
            "elements": [
                "ic2:fence@0"
            ]
        },
        {
            "x": -2,
            "y": 15,
            "z": 1,

            "elements": [
                "mekanism:basicblock2@0"
            ]
        },
        {
            "x": -2,
            "y": 15,
            "z": 0,
            "elements": [
                "mekanism:basicblock@8"
            ]
        },
        {
            "x": -1,
            "y": 3,
            "z": 1,

            "elements": [
                "mekanism:basicblock2@0"
            ]
        },
        {
            "x": -1,
            "y": 3,
            "z": 0,
            "elements": [
                "enderio:block_alloy@0"
            ]
        },
        {
            "x": 3,
            "y": 1,
            "z": 5,
            "elements": [
                "ic2:fence@0"
            ]
        },
        {
            "x": -2,
            "y": 14,
            "z": 0,
            "elements": [
                "ic2:fence@0"
            ]
        },
        {
            "x": 3,
            "y": 1,
            "z": 3,

            "elements": [
                "modularmachinery:blockcasing@0",
                "ItemOutput",
                "FluidInput",
                "EnergyInput"
            ]
        },
        {
            "x": -2,
            "y": 14,
            "z": 1,

            "elements": [
                "mekanism:basicblock2@0"
            ]
        },
        {
            "x": -1,
            "y": 3,
            "z": 6,
            "elements": [
                "enderio:block_alloy@0"
            ]
        },
        {
            "x": 3,
            "y": 1,
            "z": 4,
            "elements": [
                "enderio:block_alloy@0"
            ]
        },
        {
            "x": -2,
            "y": 14,
            "z": 2,

            "elements": [
                "mekanism:basicblock2@0"
            ]
        },
        {
            "x": -1,
            "y": 3,
            "z": 5,

            "elements": [
                "mekanism:basicblock2@0"
            ]
        },
        {
            "x": -2,
            "y": 14,
            "z": 3,

            "elements": [
                "mekanism:basicblock2@0"
            ]
        },
        {
            "x": -2,
            "y": 14,
            "z": 4,

            "elements": [
                "mekanism:basicblock2@0"
            ]
        },
        {
            "x": -2,
            "y": 14,
            "z": 5,

            "elements": [
                "mekanism:basicblock2@0"
            ]
        },
        {
            "x": -2,
            "y": 14,
            "z": 6,
            "elements": [
                "ic2:fence@0"
            ]
        },
        {
            "x": -2,
            "y": 7,
            "z": 6,
            "elements": [
                "mekanism:basicblock@8"
            ]
        },
        {
            "x": -1,
            "y": 15,
            "z": 0,
            "elements": [
                "mekanism:basicblock@8"
            ]
        },
        {
            "x": -2,
            "y": 7,
            "z": 3,

            "elements": [
                "mekanism:basicblock2@0"
            ]
        },
        {
            "x": -2,
            "y": 7,
            "z": 2,

            "elements": [
                "mekanism:basicblock2@0"
            ]
        },
        {
            "x": -2,
            "y": 7,
            "z": 5,

            "elements": [
                "mekanism:basicblock2@0"
            ]
        },
        {
            "x": -2,
            "y": 7,
            "z": 4,

            "elements": [
                "mekanism:basicblock2@0"
            ]
        },
        {
            "x": -1,
            "y": 15,
            "z": 6,
            "elements": [
                "mekanism:basicblock@8"
            ]
        },
        {
            "x": -1,
            "y": 15,
            "z": 5,

            "elements": [
                "mekanism:basicblock2@0"
            ]
        },
        {
            "x": -2,
            "y": 7,
            "z": 1,

            "elements": [
                "mekanism:basicblock2@0"
            ]
        },
        {
            "x": -2,
            "y": 7,
            "z": 0,
            "elements": [
                "mekanism:basicblock@8"
            ]
        },
        {
            "x": -1,
            "y": 15,
            "z": 1,

            "elements": [
                "mekanism:basicblock2@0"
            ]
        },
        {
            "x": 0,
            "y": 11,
            "z": 6,

            "elements": [
                "modularmachinery:blockcasing@0",
                "FluidOutput"
            ]
        },
        {
            "x": 0,
            "y": 11,
            "z": 5,

            "elements": [
                "mekanism:basicblock2@0"
            ]
        },
        {
            "x": 0,
            "y": 11,
            "z": 3,

            "elements": [
                "environmentaltech:lightning_rod_insulated@0"
            ]
        },
        {
            "x": 0,
            "y": 11,
            "z": 1,

            "elements": [
                "mekanism:basicblock2@0"
            ]
        },
        {
            "x": 0,
            "y": 11,
            "z": 0,

            "elements": [
                "modularmachinery:blockcasing@0",
                "FluidOutput"
            ]
        },
        {
            "x": 0,
            "y": 5,
            "z": 3,

            "elements": [
                "environmentaltech:lightning_rod_insulated@0"
            ]
        },
        {
            "x": 0,
            "y": 5,
            "z": 5,

            "elements": [
                "mekanism:basicblock2@0"
            ]
        },
        {
            "x": 0,
            "y": 5,
            "z": 6,

            "elements": [
                "modularmachinery:blockcasing@1"
            ]
        },
        {
            "x": 3,
            "y": 7,
            "z": 5,
            "elements": [
                "mekanism:basicblock@8"
            ]
        },
        {
            "x": 3,
            "y": 7,
            "z": 2,
            "elements": [
                "mekanism:basicblock@8"
            ]
        },
        {
            "x": 3,
            "y": 13,
            "z": 3,

            "elements": [
                "modularmachinery:blockcasing@0",
                "FluidOutput"
            ]
        },
        {
            "x": 3,
            "y": 13,
            "z": 4,
            "elements": [
                "mekanism:basicblock@8"
            ]
        },
        {
            "x": 3,
            "y": 7,
            "z": 1,
            "elements": [
                "mekanism:basicblock@8"
            ]
        },
        {
            "x": 3,
            "y": 13,
            "z": 5,
            "elements": [
                "mekanism:basicblock@8"
            ]
        },
        {
            "x": 3,
            "y": 7,
            "z": 4,
            "elements": [
                "mekanism:basicblock@8"
            ]
        },
        {
            "x": 3,
            "y": 7,
            "z": 3,
            "elements": [
                "enderio:block_alloy@0"
            ]
        },
        {
            "x": 0,
            "y": 5,
            "z": 0,

            "elements": [
                "modularmachinery:blockcasing@1"
            ]
        },
        {
            "x": 3,
            "y": 13,
            "z": 1,
            "elements": [
                "mekanism:basicblock@8"
            ]
        },
        {
            "x": 0,
            "y": 5,
            "z": 1,

            "elements": [
                "mekanism:basicblock2@0"
            ]
        },
        {
            "x": 3,
            "y": 13,
            "z": 2,
            "elements": [
                "mekanism:basicblock@8"
            ]
        },
        {
            "x": -3,
            "y": 6,
            "z": 3,
            "elements": [
                "enderio:block_alloy@0"
            ]
        },
        {
            "x": -3,
            "y": 6,
            "z": 2,
            "elements": [
                "enderio:block_alloy@0"
            ]
        },
        {
            "x": -3,
            "y": 6,
            "z": 1,
            "elements": [
                "ic2:fence@0"
            ]
        },
        {
            "x": -2,
            "y": 2,
            "z": 0,
            "elements": [
                "ic2:fence@0"
            ]
        },
        {
            "x": -2,
            "y": 2,
            "z": 2,

            "elements": [
                "mekanism:basicblock2@0"
            ]
        },
        {
            "x": -2,
            "y": 2,
            "z": 1,

            "elements": [
                "mekanism:basicblock2@0"
            ]
        },
        {
            "x": -2,
            "y": 2,
            "z": 4,

            "elements": [
                "mekanism:basicblock2@0"
            ]
        },
        {
            "x": -2,
            "y": 2,
            "z": 3,

            "elements": [
                "mekanism:basicblock2@0"
            ]
        },
        {
            "x": -3,
            "y": 6,
            "z": 5,
            "elements": [
                "ic2:fence@0"
            ]
        },
        {
            "x": -2,
            "y": 2,
            "z": 6,
            "elements": [
                "ic2:fence@0"
            ]
        },
        {
            "x": -2,
            "y": 2,
            "z": 5,

            "elements": [
                "mekanism:basicblock2@0"
            ]
        },
        {
            "x": -3,
            "y": 6,
            "z": 4,
            "elements": [
                "enderio:block_alloy@0"
            ]
        },
        {
            "x": 0,
            "y": 12,
            "z": 6,
            "elements": [
                "enderio:block_alloy@0"
            ]
        },
        {
            "x": 0,
            "y": 12,
            "z": 5,

            "elements": [
                "mekanism:basicblock2@0"
            ]
        },
        {
            "x": 0,
            "y": 12,
            "z": 3,

            "elements": [
                "environmentaltech:lightning_rod_insulated@0"
            ]
        },
        {
            "x": -3,
            "y": 5,
            "z": 4,
            "elements": [
                "enderio:block_alloy@0"
            ]
        },
        {
            "x": -3,
            "y": 5,
            "z": 3,

            "elements": [
                "modularmachinery:blockcasing@1"
            ]
        },
        {
            "x": -3,
            "y": 5,
            "z": 2,
            "elements": [
                "enderio:block_alloy@0"
            ]
        },
        {
            "x": -3,
            "y": 5,
            "z": 1,
            "elements": [
                "mekanism:basicblock@8"
            ]
        },
        {
            "x": -2,
            "y": 13,
            "z": 0,
            "elements": [
                "mekanism:basicblock@8"
            ]
        },
        {
            "x": -2,
            "y": 13,
            "z": 1,

            "elements": [
                "mekanism:basicblock2@0"
            ]
        },
        {
            "x": 3,
            "y": 6,
            "z": 1,
            "elements": [
                "ic2:fence@0"
            ]
        },
        {
            "x": -2,
            "y": 13,
            "z": 2,

            "elements": [
                "mekanism:basicblock2@0"
            ]
        },
        {
            "x": -2,
            "y": 13,
            "z": 3,

            "elements": [
                "mekanism:basicblock2@0"
            ]
        },
        {
            "x": 3,
            "y": 6,
            "z": 3,
            "elements": [
                "enderio:block_alloy@0"
            ]
        },
        {
            "x": 3,
            "y": 6,
            "z": 2,
            "elements": [
                "enderio:block_alloy@0"
            ]
        },
        {
            "x": 0,
            "y": 12,
            "z": 1,

            "elements": [
                "mekanism:basicblock2@0"
            ]
        },
        {
            "x": 0,
            "y": 12,
            "z": 0,
            "elements": [
                "enderio:block_alloy@0"
            ]
        },
        {
            "x": 3,
            "y": 6,
            "z": 5,
            "elements": [
                "ic2:fence@0"
            ]
        },
        {
            "x": 0,
            "y": -1,
            "z": -1,
            "elements": [
                "appliedenergistics2:smooth_sky_stone_stairs@2"
            ]
        },
        {
            "x": 3,
            "y": 6,
            "z": 4,
            "elements": [
                "enderio:block_alloy@0"
            ]
        },
        {
            "x": -2,
            "y": 13,
            "z": 4,

            "elements": [
                "mekanism:basicblock2@0"
            ]
        },
        {
            "x": -2,
            "y": 13,
            "z": 5,

            "elements": [
                "mekanism:basicblock2@0"
            ]
        },
        {
            "x": -2,
            "y": 13,
            "z": 6,
            "elements": [
                "mekanism:basicblock@8"
            ]
        },
        {
            "x": -1,
            "y": 4,
            "z": 1,

            "elements": [
                "mekanism:basicblock2@0"
            ]
        },
        {
            "x": -1,
            "y": 4,
            "z": 0,
            "elements": [
                "enderio:block_alloy@0"
            ]
        },
        {
            "x": -1,
            "y": 4,
            "z": 6,
            "elements": [
                "enderio:block_alloy@0"
            ]
        },
        {
            "x": -1,
            "y": 4,
            "z": 5,

            "elements": [
                "mekanism:basicblock2@0"
            ]
        },
        {
            "x": -3,
            "y": 5,
            "z": 5,
            "elements": [
                "mekanism:basicblock@8"
            ]
        },
        {
            "x": -3,
            "y": 12,
            "z": 4,
            "elements": [
                "ic2:fence@0"
            ]
        },
        {
            "x": -3,
            "y": 12,
            "z": 5,
            "elements": [
                "ic2:fence@0"
            ]
        },
        {
            "x": -3,
            "y": 12,
            "z": 2,
            "elements": [
                "ic2:fence@0"
            ]
        },
        {
            "x": -3,
            "y": 12,
            "z": 3,
            "elements": [
                "enderio:block_alloy@0"
            ]
        },
        {
            "x": -3,
            "y": 12,
            "z": 1,
            "elements": [
                "ic2:fence@0"
            ]
        },
        {
            "x": 3,
            "y": 12,
            "z": 1,
            "elements": [
                "ic2:fence@0"
            ]
        },
        {
            "x": 3,
            "y": 12,
            "z": 2,
            "elements": [
                "ic2:fence@0"
            ]
        },
        {
            "x": 3,
            "y": 12,
            "z": 3,
            "elements": [
                "enderio:block_alloy@0"
            ]
        },
        {
            "x": 0,
            "y": 6,
            "z": 0,
            "elements": [
                "enderio:block_alloy@0"
            ]
        },
        {
            "x": 3,
            "y": 12,
            "z": 4,
            "elements": [
                "ic2:fence@0"
            ]
        },
        {
            "x": 3,
            "y": 12,
            "z": 5,
            "elements": [
                "ic2:fence@0"
            ]
        },
        {
            "x": 0,
            "y": -1,
            "z": 1,
            "elements": [
                "enderio:block_reinforced_obsidian@0"
            ]
        },
        {
            "x": -3,
            "y": 11,
            "z": 1,
            "elements": [
                "mekanism:basicblock@8"
            ]
        },
        {
            "x": 0,
            "y": 6,
            "z": 5,

            "elements": [
                "mekanism:basicblock2@0"
            ]
        },
        {
            "x": 0,
            "y": -1,
            "z": 0,
            "elements": [
                "enderio:block_reinforced_obsidian@0"
            ]
        },
        {
            "x": 0,
            "y": 6,
            "z": 6,
            "elements": [
                "enderio:block_alloy@0"
            ]
        },
        {
            "x": -3,
            "y": 11,
            "z": 2,
            "elements": [
                "mekanism:basicblock@8"
            ]
        },
        {
            "x": 0,
            "y": -1,
            "z": 3,

            "elements": [
                "mekanismgenerators:generator@9"
            ]
        },
        {
            "x": 0,
            "y": -1,
            "z": 2,

            "elements": [
                "mekanismgenerators:generator@9"
            ]
        },
        {
            "x": 0,
            "y": 6,
            "z": 1,

            "elements": [
                "mekanism:basicblock2@0"
            ]
        },
        {
            "x": 0,
            "y": -1,
            "z": 5,
            "elements": [
                "enderio:block_reinforced_obsidian@0"
            ]
        },
        {
            "x": -3,
            "y": 11,
            "z": 5,
            "elements": [
                "mekanism:basicblock@8"
            ]
        },
        {
            "x": 0,
            "y": -1,
            "z": 4,

            "elements": [
                "mekanismgenerators:generator@9"
            ]
        },
        {
            "x": 0,
            "y": -1,
            "z": 7,
            "elements": [
                "appliedenergistics2:smooth_sky_stone_stairs@3"
            ]
        },
        {
            "x": 0,
            "y": 6,
            "z": 3,

            "elements": [
                "environmentaltech:lightning_rod_insulated@0"
            ]
        },
        {
            "x": -3,
            "y": 11,
            "z": 3,

            "elements": [
                "modularmachinery:blockcasing@0",
                "FluidOutput"
            ]
        },
        {
            "x": 0,
            "y": -1,
            "z": 6,
            "elements": [
                "enderio:block_reinforced_obsidian@0"
            ]
        },
        {
            "x": -3,
            "y": 11,
            "z": 4,
            "elements": [
                "mekanism:basicblock@8"
            ]
        },
        {
            "x": -1,
            "y": 10,
            "z": 6,
            "elements": [
                "ic2:fence@0"
            ]
        },
        {
            "x": -1,
            "y": 10,
            "z": 0,
            "elements": [
                "ic2:fence@0"
            ]
        },
        {
            "x": -1,
            "y": 10,
            "z": 1,

            "elements": [
                "mekanism:basicblock2@0"
            ]
        },
        {
            "x": 3,
            "y": 0,
            "z": 4,
            "elements": [
                "enderio:block_alloy@0"
            ]
        },
        {
            "x": 3,
            "y": 0,
            "z": 5,
            "elements": [
                "ic2:fence@0"
            ]
        },
        {
            "x": -1,
            "y": 10,
            "z": 5,

            "elements": [
                "mekanism:basicblock2@0"
            ]
        },
        {
            "x": 1,
            "y": 14,
            "z": 5,

            "elements": [
                "mekanism:basicblock2@0"
            ]
        },
        {
            "x": 1,
            "y": 14,
            "z": 6,
            "elements": [
                "ic2:fence@0"
            ]
        },
        {
            "x": 3,
            "y": 0,
            "z": 2,
            "elements": [
                "enderio:block_alloy@0"
            ]
        },
        {
            "x": 1,
            "y": 14,
            "z": 1,

            "elements": [
                "mekanism:basicblock2@0"
            ]
        },
        {
            "x": 3,
            "y": 0,
            "z": 3,

            "elements": [
                "modularmachinery:blockcasing@0",
                "ItemOutput",
                "FluidInput",
                "EnergyInput"
            ]
        },
        {
            "x": 1,
            "y": 14,
            "z": 0,
            "elements": [
                "ic2:fence@0"
            ]
        },
        {
            "x": 2,
            "y": 4,
            "z": 0,
            "elements": [
                "ic2:fence@0"
            ]
        },
        {
            "x": 3,
            "y": 0,
            "z": 1,
            "elements": [
                "ic2:fence@0"
            ]
        },
        {
            "x": 2,
            "y": 4,
            "z": 1,

            "elements": [
                "mekanism:basicblock2@0"
            ]
        },
        {
            "x": 2,
            "y": 4,
            "z": 2,

            "elements": [
                "mekanism:basicblock2@0"
            ]
        },
        {
            "x": 2,
            "y": 4,
            "z": 3,

            "elements": [
                "mekanism:basicblock2@0"
            ]
        },
        {
            "x": 2,
            "y": 4,
            "z": 4,

            "elements": [
                "mekanism:basicblock2@0"
            ]
        },
        {
            "x": 2,
            "y": 4,
            "z": 5,

            "elements": [
                "mekanism:basicblock2@0"
            ]
        },
        {
            "x": 2,
            "y": 4,
            "z": 6,
            "elements": [
                "ic2:fence@0"
            ]
        },
        {
            "x": 2,
            "y": 10,
            "z": 2,

            "elements": [
                "mekanism:basicblock2@0"
            ]
        },
        {
            "x": 2,
            "y": 10,
            "z": 1,

            "elements": [
                "mekanism:basicblock2@0"
            ]
        },
        {
            "x": 2,
            "y": 10,
            "z": 0,
            "elements": [
                "ic2:fence@0"
            ]
        },
        {
            "x": 1,
            "y": 8,
            "z": 5,

            "elements": [
                "mekanism:basicblock2@0"
            ]
        },
        {
            "x": 1,
            "y": 8,
            "z": 0,
            "elements": [
                "ic2:fence@0"
            ]
        },
        {
            "x": 2,
            "y": 10,
            "z": 6,
            "elements": [
                "ic2:fence@0"
            ]
        },
        {
            "x": 1,
            "y": 8,
            "z": 1,

            "elements": [
                "mekanism:basicblock2@0"
            ]
        },
        {
            "x": 2,
            "y": 10,
            "z": 5,

            "elements": [
                "mekanism:basicblock2@0"
            ]
        },
        {
            "x": 2,
            "y": 10,
            "z": 4,

            "elements": [
                "mekanism:basicblock2@0"
            ]
        },
        {
            "x": 2,
            "y": 10,
            "z": 3,

            "elements": [
                "mekanism:basicblock2@0"
            ]
        },
        {
            "x": -3,
            "y": -1,
            "z": 1,
            "elements": [
                "appliedenergistics2:smooth_sky_stone_stairs@2"
            ]
        },
        {
            "x": -3,
            "y": -1,
            "z": 2,
            "elements": [
                "enderio:block_reinforced_obsidian@0"
            ]
        },
        {
            "x": -3,
            "y": -1,
            "z": 3,
            "elements": [
                "enderio:block_reinforced_obsidian@0"
            ]
        },
        {
            "x": -3,
            "y": -1,
            "z": 4,
            "elements": [
                "enderio:block_reinforced_obsidian@0"
            ]
        },
        {
            "x": -3,
            "y": -1,
            "z": 5,
            "elements": [
                "appliedenergistics2:smooth_sky_stone_stairs@3"
            ]
        },
        {
            "x": 1,
            "y": 15,
            "z": 0,
            "elements": [
                "mekanism:basicblock@8"
            ]
        },
        {
            "x": 2,
            "y": 3,
            "z": 0,
            "elements": [
                "mekanism:basicblock@8"
            ]
        },
        {
            "x": 2,
            "y": 3,
            "z": 1,

            "elements": [
                "mekanism:basicblock2@0"
            ]
        },
        {
            "x": 1,
            "y": 15,
            "z": 1,

            "elements": [
                "mekanism:basicblock2@0"
            ]
        },
        {
            "x": 1,
            "y": 15,
            "z": 6,
            "elements": [
                "mekanism:basicblock@8"
            ]
        },
        {
            "x": 1,
            "y": 15,
            "z": 5,

            "elements": [
                "mekanism:basicblock2@0"
            ]
        },
        {
            "x": 2,
            "y": 3,
            "z": 6,
            "elements": [
                "mekanism:basicblock@8"
            ]
        },
        {
            "x": -3,
            "y": 10,
            "z": 4,
            "elements": [
                "ic2:fence@0"
            ]
        },
        {
            "x": -3,
            "y": 10,
            "z": 5,
            "elements": [
                "ic2:fence@0"
            ]
        },
        {
            "x": 2,
            "y": 3,
            "z": 2,

            "elements": [
                "mekanism:basicblock2@0"
            ]
        },
        {
            "x": -2,
            "y": 11,
            "z": 6,
            "elements": [
                "mekanism:basicblock@8"
            ]
        },
        {
            "x": -3,
            "y": 10,
            "z": 2,
            "elements": [
                "ic2:fence@0"
            ]
        },
        {
            "x": 2,
            "y": 3,
            "z": 3,

            "elements": [
                "mekanism:basicblock2@0"
            ]
        },
        {
            "x": -3,
            "y": 10,
            "z": 3,
            "elements": [
                "enderio:block_alloy@0"
            ]
        },
        {
            "x": 2,
            "y": 3,
            "z": 4,

            "elements": [
                "mekanism:basicblock2@0"
            ]
        },
        {
            "x": 2,
            "y": 16,
            "z": 5,

            "elements": [
                "mekanism:basicblock2@0"
            ]
        },
        {
            "x": 2,
            "y": 16,
            "z": 6,
            "elements": [
                "appliedenergistics2:smooth_sky_stone_slab@0"
            ]
        },
        {
            "x": -3,
            "y": 10,
            "z": 1,
            "elements": [
                "ic2:fence@0"
            ]
        },
        {
            "x": 2,
            "y": 3,
            "z": 5,

            "elements": [
                "mekanism:basicblock2@0"
            ]
        },
        {
            "x": 3,
            "y": 4,
            "z": 2,
            "elements": [
                "enderio:block_alloy@0"
            ]
        },
        {
            "x": -1,
            "y": -1,
            "z": 1,
            "elements": [
                "enderio:block_reinforced_obsidian@0"
            ]
        },
        {
            "x": 3,
            "y": 4,
            "z": 3,

            "elements": [
                "modularmachinery:blockcasing@1"
            ]
        },
        {
            "x": -1,
            "y": -1,
            "z": 2,
            "elements": [
                "enderio:block_reinforced_obsidian@0"
            ]
        },
        {
            "x": -1,
            "y": -1,
            "z": 3,

            "elements": [
                "mekanismgenerators:generator@9"
            ]
        },
        {
            "x": 3,
            "y": 4,
            "z": 1,
            "elements": [
                "ic2:fence@0"
            ]
        },
        {
            "x": -1,
            "y": -1,
            "z": 4,
            "elements": [
                "enderio:block_reinforced_obsidian@0"
            ]
        },
        {
            "x": -1,
            "y": -1,
            "z": 5,
            "elements": [
                "enderio:block_reinforced_obsidian@0"
            ]
        },
        {
            "x": 0,
            "y": 14,
            "z": 0,
            "elements": [
                "enderio:block_alloy@0"
            ]
        },
        {
            "x": -1,
            "y": -1,
            "z": 6,
            "elements": [
                "enderio:block_reinforced_obsidian@0"
            ]
        },
        {
            "x": -1,
            "y": -1,
            "z": 7,
            "elements": [
                "appliedenergistics2:smooth_sky_stone_slab@0"
            ]
        },
        {
            "x": 3,
            "y": 4,
            "z": 4,
            "elements": [
                "enderio:block_alloy@0"
            ]
        },
        {
            "x": 3,
            "y": 4,
            "z": 5,
            "elements": [
                "ic2:fence@0"
            ]
        },
        {
            "x": 0,
            "y": 14,
            "z": 3,

            "elements": [
                "environmentaltech:lightning_rod_insulated@0"
            ]
        },
        {
            "x": 0,
            "y": 14,
            "z": 1,

            "elements": [
                "mekanism:basicblock2@0"
            ]
        },
        {
            "x": -1,
            "y": -1,
            "z": -1,
            "elements": [
                "appliedenergistics2:smooth_sky_stone_slab@0"
            ]
        },
        {
            "x": 0,
            "y": 14,
            "z": 6,
            "elements": [
                "enderio:block_alloy@0"
            ]
        },
        {
            "x": 0,
            "y": 14,
            "z": 5,

            "elements": [
                "mekanism:basicblock2@0"
            ]
        },
        {
            "x": -1,
            "y": -1,
            "z": 0,
            "elements": [
                "enderio:block_reinforced_obsidian@0"
            ]
        },
        {
            "x": 0,
            "y": 0,
            "z": 4,

            "elements": [
                "mekanism:basicblock2@0"
            ]
        },
        {
            "x": 0,
            "y": 0,
            "z": 3,

            "elements": [
                "mekanismgenerators:generator@9"
            ]
        },
        {
            "x": 0,
            "y": 0,
            "z": 6,

            "elements": [
                "modularmachinery:blockcasing@0",
                "ItemOutput",
                "FluidInput",
                "EnergyInput"
            ]
        },
        {
            "x": 0,
            "y": 0,
            "z": 5,

            "elements": [
                "mekanism:basicblock2@0"
            ]
        },
        {
            "x": 0,
            "y": 0,
            "z": 0,

            "elements": [
                "modularmachinery:blockcontroller@2"
            ]
        },
        {
            "x": 1,
            "y": 2,
            "z": 6,
            "elements": [
                "enderio:block_alloy@0"
            ]
        },
        {
            "x": 1,
            "y": 2,
            "z": 5,

            "elements": [
                "mekanism:basicblock2@0"
            ]
        },
        {
            "x": 0,
            "y": 0,
            "z": 2,

            "elements": [
                "mekanism:basicblock2@0"
            ]
        },
        {
            "x": 0,
            "y": 0,
            "z": 1,

            "elements": [
                "mekanism:basicblock2@0"
            ]
        },
        {
            "x": 1,
            "y": 2,
            "z": 1,

            "elements": [
                "mekanism:basicblock2@0"
            ]
        },
        {
            "x": 1,
            "y": 2,
            "z": 0,
            "elements": [
                "enderio:block_alloy@0"
            ]
        },
        {
            "x": 2,
            "y": 16,
            "z": 3,

            "elements": [
                "mekanism:basicblock2@0"
            ]
        },
        {
            "x": -2,
            "y": 11,
            "z": 2,

            "elements": [
                "mekanism:basicblock2@0"
            ]
        },
        {
            "x": 2,
            "y": 16,
            "z": 4,

            "elements": [
                "mekanism:basicblock2@0"
            ]
        },
        {
            "x": -2,
            "y": 11,
            "z": 3,

            "elements": [
                "mekanism:basicblock2@0"
            ]
        },
        {
            "x": 2,
            "y": 16,
            "z": 1,

            "elements": [
                "mekanism:basicblock2@0"
            ]
        },
        {
            "x": -2,
            "y": 11,
            "z": 4,

            "elements": [
                "mekanism:basicblock2@0"
            ]
        },
        {
            "x": 0,
            "y": 13,
            "z": 6,

            "elements": [
                "modularmachinery:blockcasing@0",
                "FluidOutput"
            ]
        },
        {
            "x": -2,
            "y": 11,
            "z": 5,

            "elements": [
                "mekanism:basicblock2@0"
            ]
        },
        {
            "x": 2,
            "y": 16,
            "z": 2,

            "elements": [
                "mekanism:basicblock2@0"
            ]
        },
        {
            "x": 0,
            "y": 13,
            "z": 5,

            "elements": [
                "mekanism:basicblock2@0"
            ]
        },
        {
            "x": 2,
            "y": 16,
            "z": 0,
            "elements": [
                "appliedenergistics2:smooth_sky_stone_slab@0"
            ]
        },
        {
            "x": -2,
            "y": 11,
            "z": 0,
            "elements": [
                "mekanism:basicblock@8"
            ]
        },
        {
            "x": 0,
            "y": 13,
            "z": 3,

            "elements": [
                "environmentaltech:lightning_rod_insulated@0"
            ]
        },
        {
            "x": -2,
            "y": 11,
            "z": 1,

            "elements": [
                "mekanism:basicblock2@0"
            ]
        },
        {
            "x": 3,
            "y": 5,
            "z": 4,
            "elements": [
                "enderio:block_alloy@0"
            ]
        },
        {
            "x": 3,
            "y": 5,
            "z": 3,

            "elements": [
                "modularmachinery:blockcasing@1"
            ]
        },
        {
            "x": 2,
            "y": 17,
            "z": 4,
            "elements": [
                "appliedenergistics2:smooth_sky_stone_stairs@1"
            ]
        },
        {
            "x": 3,
            "y": 5,
            "z": 5,
            "elements": [
                "mekanism:basicblock@8"
            ]
        },
        {
            "x": 2,
            "y": 17,
            "z": 5,
            "elements": [
                "appliedenergistics2:smooth_sky_stone_slab@0"
            ]
        },
        {
            "x": 3,
            "y": 5,
            "z": 2,
            "elements": [
                "enderio:block_alloy@0"
            ]
        },
        {
            "x": 3,
            "y": 5,
            "z": 1,
            "elements": [
                "mekanism:basicblock@8"
            ]
        },
        {
            "x": -3,
            "y": 9,
            "z": 4,
            "elements": [
                "mekanism:basicblock@8"
            ]
        },
        {
            "x": 1,
            "y": 1,
            "z": 0,
            "elements": [
                "enderio:block_alloy@0"
            ]
        },
        {
            "x": 0,
            "y": 13,
            "z": 1,

            "elements": [
                "mekanism:basicblock2@0"
            ]
        },
        {
            "x": 0,
            "y": 13,
            "z": 0,

            "elements": [
                "modularmachinery:blockcasing@0",
                "FluidOutput"
            ]
        },
        {
            "x": -3,
            "y": 9,
            "z": 3,

            "elements": [
                "modularmachinery:blockcasing@0",
                "FluidOutput"
            ]
        },
        {
            "x": -3,
            "y": 9,
            "z": 2,
            "elements": [
                "mekanism:basicblock@8"
            ]
        },
        {
            "x": -3,
            "y": 9,
            "z": 1,
            "elements": [
                "mekanism:basicblock@8"
            ]
        },
        {
            "x": 2,
            "y": 17,
            "z": 2,
            "elements": [
                "appliedenergistics2:smooth_sky_stone_stairs@1"
            ]
        },
        {
            "x": 2,
            "y": 17,
            "z": 3,
            "elements": [
                "appliedenergistics2:smooth_sky_stone_slab@0"
            ]
        },
        {
            "x": 2,
            "y": 17,
            "z": 1,
            "elements": [
                "appliedenergistics2:smooth_sky_stone_slab@0"
            ]
        },
        {
            "x": -3,
            "y": 9,
            "z": 5,
            "elements": [
                "mekanism:basicblock@8"
            ]
        },
        {
            "x": 1,
            "y": 1,
            "z": 1,

            "elements": [
                "mekanism:basicblock2@0"
            ]
        },
        {
            "x": 1,
            "y": 1,
            "z": 6,
            "elements": [
                "enderio:block_alloy@0"
            ]
        },
        {
            "x": 1,
            "y": 1,
            "z": 5,

            "elements": [
                "mekanism:basicblock2@0"
            ]
        },
        {
            "x": -1,
            "y": 12,
            "z": 6,
            "elements": [
                "ic2:fence@0"
            ]
        },
        {
            "x": -1,
            "y": 12,
            "z": 5,

            "elements": [
                "mekanism:basicblock2@0"
            ]
        },
        {
            "x": -2,
            "y": -1,
            "z": 6,
            "elements": [
                "appliedenergistics2:smooth_sky_stone_stairs@0"
            ]
        },
        {
            "x": -2,
            "y": -1,
            "z": 4,
            "elements": [
                "enderio:block_reinforced_obsidian@0"
            ]
        },
        {
            "x": -2,
            "y": -1,
            "z": 5,
            "elements": [
                "enderio:block_reinforced_obsidian@0"
            ]
        },
        {
            "x": -2,
            "y": -1,
            "z": 2,
            "elements": [
                "enderio:block_reinforced_obsidian@0"
            ]
        },
        {
            "x": -2,
            "y": -1,
            "z": 3,
            "elements": [
                "enderio:block_reinforced_obsidian@0"
            ]
        },
        {
            "x": -2,
            "y": -1,
            "z": 0,
            "elements": [
                "appliedenergistics2:smooth_sky_stone_stairs@0"
            ]
        },
        {
            "x": -2,
            "y": -1,
            "z": 1,
            "elements": [
                "enderio:block_reinforced_obsidian@0"
            ]
        },
        {
            "x": -1,
            "y": 12,
            "z": 0,
            "elements": [
                "ic2:fence@0"
            ]
        },
        {
            "x": -1,
            "y": 12,
            "z": 1,

            "elements": [
                "mekanism:basicblock2@0"
            ]
        },
        {
            "x": 1,
            "y": 0,
            "z": 5,

            "elements": [
                "mekanism:basicblock2@0"
            ]
        },
        {
            "x": 1,
            "y": 0,
            "z": 4,

            "elements": [
                "mekanism:basicblock2@0"
            ]
        },
        {
            "x": 1,
            "y": 0,
            "z": 3,

            "elements": [
                "mekanism:basicblock2@0"
            ]
        },
        {
            "x": 1,
            "y": 0,
            "z": 2,

            "elements": [
                "mekanism:basicblock2@0"
            ]
        },
        {
            "x": 1,
            "y": 0,
            "z": 1,

            "elements": [
                "mekanism:basicblock2@0"
            ]
        },
        {
            "x": 1,
            "y": 0,
            "z": 0,
            "elements": [
                "enderio:block_alloy@0"
            ]
        },
        {
            "x": -1,
            "y": 14,
            "z": 5,

            "elements": [
                "mekanism:basicblock2@0"
            ]
        },
        {
            "x": -1,
            "y": 14,
            "z": 6,
            "elements": [
                "ic2:fence@0"
            ]
        },
        {
            "x": 1,
            "y": 0,
            "z": 6,
            "elements": [
                "enderio:block_alloy@0"
            ]
        },
        {
            "x": -1,
            "y": 11,
            "z": 1,

            "elements": [
                "mekanism:basicblock2@0"
            ]
        },
        {
            "x": -1,
            "y": 11,
            "z": 0,
            "elements": [
                "mekanism:basicblock@8"
            ]
        },
        {
            "x": 1,
            "y": 3,
            "z": 5,

            "elements": [
                "mekanism:basicblock2@0"
            ]
        },
        {
            "x": 1,
            "y": 3,
            "z": 6,
            "elements": [
                "enderio:block_alloy@0"
            ]
        },
        {
            "x": -1,
            "y": 11,
            "z": 5,

            "elements": [
                "mekanism:basicblock2@0"
            ]
        },
        {
            "x": -1,
            "y": 11,
            "z": 6,
            "elements": [
                "mekanism:basicblock@8"
            ]
        },
        {
            "x": -2,
            "y": 0,
            "z": 3,

            "elements": [
                "mekanism:basicblock2@0"
            ]
        },
        {
            "x": 2,
            "y": 5,
            "z": 4,

            "elements": [
                "mekanism:basicblock2@0"
            ]
        },
        {
            "x": 2,
            "y": 15,
            "z": 0,
            "elements": [
                "mekanism:basicblock@8"
            ]
        },
        {
            "x": 2,
            "y": 15,
            "z": 1,

            "elements": [
                "mekanism:basicblock2@0"
            ]
        },
        {
            "x": 2,
            "y": 5,
            "z": 5,

            "elements": [
                "mekanism:basicblock2@0"
            ]
        },
        {
            "x": -2,
            "y": 0,
            "z": 4,

            "elements": [
                "mekanism:basicblock2@0"
            ]
        },
        {
            "x": 2,
            "y": 5,
            "z": 6,
            "elements": [
                "mekanism:basicblock@8"
            ]
        },
        {
            "x": -2,
            "y": 0,
            "z": 1,

            "elements": [
                "mekanism:basicblock2@0"
            ]
        },
        {
            "x": -2,
            "y": 0,
            "z": 2,

            "elements": [
                "mekanism:basicblock2@0"
            ]
        },
        {
            "x": 2,
            "y": 15,
            "z": 4,

            "elements": [
                "mekanism:basicblock2@0"
            ]
        },
        {
            "x": 1,
            "y": 3,
            "z": 1,

            "elements": [
                "mekanism:basicblock2@0"
            ]
        },
        {
            "x": 2,
            "y": 5,
            "z": 0,
            "elements": [
                "mekanism:basicblock@8"
            ]
        },
        {
            "x": 2,
            "y": 5,
            "z": 1,

            "elements": [
                "mekanism:basicblock2@0"
            ]
        },
        {
            "x": 2,
            "y": 15,
            "z": 5,

            "elements": [
                "mekanism:basicblock2@0"
            ]
        },
        {
            "x": -2,
            "y": 0,
            "z": 5,

            "elements": [
                "mekanism:basicblock2@0"
            ]
        },
        {
            "x": 2,
            "y": 5,
            "z": 2,

            "elements": [
                "mekanism:basicblock2@0"
            ]
        },
        {
            "x": 2,
            "y": 15,
            "z": 2,

            "elements": [
                "mekanism:basicblock2@0"
            ]
        },
        {
            "x": 1,
            "y": 13,
            "z": 0,
            "elements": [
                "mekanism:basicblock@8"
            ]
        },
        {
            "x": -2,
            "y": 0,
            "z": 6,
            "elements": [
                "ic2:fence@0"
            ]
        },
        {
            "x": 2,
            "y": 5,
            "z": 3,

            "elements": [
                "mekanism:basicblock2@0"
            ]
        },
        {
            "x": 1,
            "y": 3,
            "z": 0,
            "elements": [
                "enderio:block_alloy@0"
            ]
        },
        {
            "x": 2,
            "y": 15,
            "z": 3,

            "elements": [
                "mekanism:basicblock2@0"
            ]
        },
        {
            "x": 1,
            "y": 13,
            "z": 1,

            "elements": [
                "mekanism:basicblock2@0"
            ]
        },
        {
            "x": 2,
            "y": 15,
            "z": 6,
            "elements": [
                "mekanism:basicblock@8"
            ]
        },
        {
            "x": 1,
            "y": 13,
            "z": 6,
            "elements": [
                "mekanism:basicblock@8"
            ]
        },
        {
            "x": 1,
            "y": 13,
            "z": 5,

            "elements": [
                "mekanism:basicblock2@0"
            ]
        },
        {
            "x": -2,
            "y": 0,
            "z": 0,
            "elements": [
                "ic2:fence@0"
            ]
        },
        {
            "x": 1,
            "y": 16,
            "z": 5,

            "elements": [
                "mekanism:basicblock2@0"
            ]
        },
        {
            "x": 2,
            "y": 2,
            "z": 0,
            "elements": [
                "ic2:fence@0"
            ]
        },
        {
            "x": -1,
            "y": 14,
            "z": 1,

            "elements": [
                "mekanism:basicblock2@0"
            ]
        },
        {
            "x": 2,
            "y": 2,
            "z": 1,

            "elements": [
                "mekanism:basicblock2@0"
            ]
        },
        {
            "x": 1,
            "y": 16,
            "z": 0,
            "elements": [
                "appliedenergistics2:smooth_sky_stone_slab@0"
            ]
        },
        {
            "x": 1,
            "y": 16,
            "z": 1,

            "elements": [
                "mekanism:basicblock2@0"
            ]
        },
        {
            "x": 2,
            "y": 2,
            "z": 2,

            "elements": [
                "mekanism:basicblock2@0"
            ]
        },
        {
            "x": -1,
            "y": 14,
            "z": 0,
            "elements": [
                "ic2:fence@0"
            ]
        },
        {
            "x": 1,
            "y": 16,
            "z": 6,
            "elements": [
                "appliedenergistics2:smooth_sky_stone_slab@0"
            ]
        },
        {
            "x": -2,
            "y": 12,
            "z": 5,

            "elements": [
                "mekanism:basicblock2@0"
            ]
        },
        {
            "x": -2,
            "y": 12,
            "z": 6,
            "elements": [
                "ic2:fence@0"
            ]
        },
        {
            "x": 2,
            "y": 2,
            "z": 3,

            "elements": [
                "mekanism:basicblock2@0"
            ]
        },
        {
            "x": 2,
            "y": 2,
            "z": 4,

            "elements": [
                "mekanism:basicblock2@0"
            ]
        },
        {
            "x": 2,
            "y": 2,
            "z": 5,

            "elements": [
                "mekanism:basicblock2@0"
            ]
        },
        {
            "x": -2,
            "y": 12,
            "z": 0,
            "elements": [
                "ic2:fence@0"
            ]
        },
        {
            "x": 2,
            "y": 2,
            "z": 6,
            "elements": [
                "ic2:fence@0"
            ]
        },
        {
            "x": -2,
            "y": 12,
            "z": 1,

            "elements": [
                "mekanism:basicblock2@0"
            ]
        },
        {
            "x": -2,
            "y": 12,
            "z": 2,

            "elements": [
                "mekanism:basicblock2@0"
            ]
        },
        {
            "x": -2,
            "y": 12,
            "z": 3,

            "elements": [
                "mekanism:basicblock2@0"
            ]
        },
        {
            "x": -2,
            "y": 12,
            "z": 4,

            "elements": [
                "mekanism:basicblock2@0"
            ]
        },
        {
            "x": -1,
            "y": 2,
            "z": 6,
            "elements": [
                "enderio:block_alloy@0"
            ]
        },
        {
            "x": -1,
            "y": 2,
            "z": 1,

            "elements": [
                "mekanism:basicblock2@0"
            ]
        },
        {
            "x": -1,
            "y": 2,
            "z": 0,
            "elements": [
                "enderio:block_alloy@0"
            ]
        },
        {
            "x": -1,
            "y": 2,
            "z": 5,

            "elements": [
                "mekanism:basicblock2@0"
            ]
        },
        {
            "x": 0,
            "y": 1,
            "z": 6,

            "elements": [
                "modularmachinery:blockcasing@0",
                "ItemOutput",
                "FluidInput",
                "EnergyInput"
            ]
        },
        {
            "x": -3,
            "y": 13,
            "z": 5,
            "elements": [
                "mekanism:basicblock@8"
            ]
        },
        {
            "x": -2,
            "y": 9,
            "z": 4,

            "elements": [
                "mekanism:basicblock2@0"
            ]
        },
        {
            "x": -2,
            "y": 9,
            "z": 5,

            "elements": [
                "mekanism:basicblock2@0"
            ]
        },
        {
            "x": -2,
            "y": 9,
            "z": 6,
            "elements": [
                "mekanism:basicblock@8"
            ]
        },
        {
            "x": 0,
            "y": 1,
            "z": 1,

            "elements": [
                "mekanism:basicblock2@0"
            ]
        },
        {
            "x": 0,
            "y": 1,
            "z": 0,

            "elements": [
                "enderio:block_alloy@0"
            ]
        },
        {
            "x": 0,
            "y": 1,
            "z": 3,

            "elements": [
                "environmentaltech:lightning_rod_insulated@0"
            ]
        },
        {
            "x": -3,
            "y": 13,
            "z": 3,

            "elements": [
                "modularmachinery:blockcasing@0",
                "FluidOutput"
            ]
        },
        {
            "x": -2,
            "y": 9,
            "z": 0,
            "elements": [
                "mekanism:basicblock@8"
            ]
        },
        {
            "x": -2,
            "y": 9,
            "z": 1,

            "elements": [
                "mekanism:basicblock2@0"
            ]
        },
        {
            "x": -3,
            "y": 13,
            "z": 4,
            "elements": [
                "mekanism:basicblock@8"
            ]
        },
        {
            "x": 0,
            "y": 1,
            "z": 5,

            "elements": [
                "mekanism:basicblock2@0"
            ]
        },
        {
            "x": -2,
            "y": 9,
            "z": 2,

            "elements": [
                "mekanism:basicblock2@0"
            ]
        },
        {
            "x": -3,
            "y": 13,
            "z": 1,
            "elements": [
                "mekanism:basicblock@8"
            ]
        },
        {
            "x": -3,
            "y": 13,
            "z": 2,
            "elements": [
                "mekanism:basicblock@8"
            ]
        },
        {
            "x": -2,
            "y": 9,
            "z": 3,

            "elements": [
                "mekanism:basicblock2@0"
            ]
        },
        {
            "x": 1,
            "y": 5,
            "z": 1,

            "elements": [
                "mekanism:basicblock2@0"
            ]
        },
        {
            "x": 1,
            "y": 5,
            "z": 5,

            "elements": [
                "mekanism:basicblock2@0"
            ]
        },
        {
            "x": 1,
            "y": 5,
            "z": 6,
            "elements": [
                "enderio:block_alloy@0"
            ]
        },
        {
            "x": 0,
            "y": 4,
            "z": 0,

            "elements": [
                "modularmachinery:blockcasing@1"
            ]
        },
        {
            "x": 0,
            "y": 4,
            "z": 1,

            "elements": [
                "mekanism:basicblock2@0"
            ]
        },
        {
            "x": 3,
            "y": 14,
            "z": 1,
            "elements": [
                "ic2:fence@0"
            ]
        },
        {
            "x": 3,
            "y": 14,
            "z": 2,
            "elements": [
                "ic2:fence@0"
            ]
        },
        {
            "x": -4,
            "y": -1,
            "z": 2,
            "elements": [
                "appliedenergistics2:smooth_sky_stone_slab@0"
            ]
        },
        {
            "x": -4,
            "y": -1,
            "z": 3,
            "elements": [
                "appliedenergistics2:smooth_sky_stone_stairs@0"
            ]
        },
        {
            "x": 3,
            "y": 14,
            "z": 3,
            "elements": [
                "enderio:block_alloy@0"
            ]
        },
        {
            "x": 3,
            "y": 14,
            "z": 4,
            "elements": [
                "ic2:fence@0"
            ]
        },
        {
            "x": 3,
            "y": 14,
            "z": 5,
            "elements": [
                "ic2:fence@0"
            ]
        },
        {
            "x": 2,
            "y": 13,
            "z": 3,

            "elements": [
                "mekanism:basicblock2@0"
            ]
        },
        {
            "x": 2,
            "y": 13,
            "z": 2,

            "elements": [
                "mekanism:basicblock2@0"
            ]
        },
        {
            "x": 2,
            "y": 6,
            "z": 0,
            "elements": [
                "ic2:fence@0"
            ]
        },
        {
            "x": 2,
            "y": 6,
            "z": 1,

            "elements": [
                "mekanism:basicblock2@0"
            ]
        },
        {
            "x": 1,
            "y": 12,
            "z": 1,

            "elements": [
                "mekanism:basicblock2@0"
            ]
        },
        {
            "x": 2,
            "y": 13,
            "z": 1,

            "elements": [
                "mekanism:basicblock2@0"
            ]
        },
        {
            "x": 2,
            "y": 6,
            "z": 2,

            "elements": [
                "mekanism:basicblock2@0"
            ]
        },
        {
            "x": 1,
            "y": 12,
            "z": 0,
            "elements": [
                "ic2:fence@0"
            ]
        },
        {
            "x": 2,
            "y": 13,
            "z": 0,
            "elements": [
                "mekanism:basicblock@8"
            ]
        },
        {
            "x": -3,
            "y": 7,
            "z": 2,
            "elements": [
                "mekanism:basicblock@8"
            ]
        },
        {
            "x": 2,
            "y": 6,
            "z": 3,

            "elements": [
                "mekanism:basicblock2@0"
            ]
        },
        {
            "x": 2,
            "y": 13,
            "z": 6,
            "elements": [
                "mekanism:basicblock@8"
            ]
        },
        {
            "x": 1,
            "y": 5,
            "z": 0,
            "elements": [
                "enderio:block_alloy@0"
            ]
        },
        {
            "x": -3,
            "y": 7,
            "z": 1,
            "elements": [
                "mekanism:basicblock@8"
            ]
        },
        {
            "x": 2,
            "y": 6,
            "z": 4,

            "elements": [
                "mekanism:basicblock2@0"
            ]
        },
        {
            "x": 2,
            "y": 13,
            "z": 5,

            "elements": [
                "mekanism:basicblock2@0"
            ]
        },
        {
            "x": 2,
            "y": 6,
            "z": 5,

            "elements": [
                "mekanism:basicblock2@0"
            ]
        },
        {
            "x": 2,
            "y": 6,
            "z": 6,
            "elements": [
                "ic2:fence@0"
            ]
        },
        {
            "x": 2,
            "y": 13,
            "z": 4,

            "elements": [
                "mekanism:basicblock2@0"
            ]
        },
        {
            "x": 0,
            "y": 10,
            "z": 1,

            "elements": [
                "mekanism:basicblock2@0"
            ]
        },
        {
            "x": 1,
            "y": 12,
            "z": 6,
            "elements": [
                "ic2:fence@0"
            ]
        },
        {
            "x": -3,
            "y": 7,
            "z": 5,
            "elements": [
                "mekanism:basicblock@8"
            ]
        },
        {
            "x": 0,
            "y": 10,
            "z": 3,

            "elements": [
                "environmentaltech:lightning_rod_insulated@0"
            ]
        },
        {
            "x": -3,
            "y": 7,
            "z": 4,
            "elements": [
                "mekanism:basicblock@8"
            ]
        },
        {
            "x": -3,
            "y": 7,
            "z": 3,
            "elements": [
                "enderio:block_alloy@0"
            ]
        },
        {
            "x": 3,
            "y": 8,
            "z": 1,
            "elements": [
                "ic2:fence@0"
            ]
        },
        {
            "x": 1,
            "y": 12,
            "z": 5,

            "elements": [
                "mekanism:basicblock2@0"
            ]
        },
        {
            "x": 3,
            "y": 8,
            "z": 3,
            "elements": [
                "enderio:block_alloy@0"
            ]
        },
        {
            "x": 3,
            "y": 8,
            "z": 2,
            "elements": [
                "ic2:fence@0"
            ]
        },
        {
            "x": 0,
            "y": 10,
            "z": 0,
            "elements": [
                "enderio:block_alloy@0"
            ]
        },
        {
            "x": 0,
            "y": 10,
            "z": 5,

            "elements": [
                "mekanism:basicblock2@0"
            ]
        },
        {
            "x": 0,
            "y": 10,
            "z": 6,
            "elements": [
                "enderio:block_alloy@0"
            ]
        },
        {
            "x": 1,
            "y": -1,
            "z": 2,
            "elements": [
                "enderio:block_reinforced_obsidian@0"
            ]
        },
        {
            "x": 1,
            "y": -1,
            "z": 1,
            "elements": [
                "enderio:block_reinforced_obsidian@0"
            ]
        },
        {
            "x": 1,
            "y": -1,
            "z": 0,
            "elements": [
                "enderio:block_reinforced_obsidian@0"
            ]
        },
        {
            "x": 1,
            "y": -1,
            "z": -1,
            "elements": [
                "appliedenergistics2:smooth_sky_stone_slab@0"
            ]
        },
        {
            "x": 1,
            "y": -1,
            "z": 6,
            "elements": [
                "enderio:block_reinforced_obsidian@0"
            ]
        },
        {
            "x": 1,
            "y": -1,
            "z": 5,
            "elements": [
                "enderio:block_reinforced_obsidian@0"
            ]
        },
        {
            "x": 1,
            "y": -1,
            "z": 4,
            "elements": [
                "enderio:block_reinforced_obsidian@0"
            ]
        },
        {
            "x": 1,
            "y": -1,
            "z": 3,

            "elements": [
                "mekanismgenerators:generator@9"
            ]
        },
        {
            "x": 3,
            "y": 8,
            "z": 5,
            "elements": [
                "ic2:fence@0"
            ]
        },
        {
            "x": 3,
            "y": 8,
            "z": 4,
            "elements": [
                "ic2:fence@0"
            ]
        },
        {
            "x": 3,
            "y": 15,
            "z": 1,
            "elements": [
                "mekanism:basicblock@8"
            ]
        },
        {
            "x": 3,
            "y": 15,
            "z": 2,
            "elements": [
                "mekanism:basicblock@8"
            ]
        },
        {
            "x": 3,
            "y": 15,
            "z": 3,

            "elements": [
                "modularmachinery:blockcasing@0",
                "FluidOutput"
            ]
        },
        {
            "x": 3,
            "y": 15,
            "z": 4,
            "elements": [
                "mekanism:basicblock@8"
            ]
        },
        {
            "x": 0,
            "y": 3,
            "z": 1,

            "elements": [
                "mekanism:basicblock2@0"
            ]
        },
        {
            "x": 0,
            "y": 3,
            "z": 0,
            "elements": [
                "appliedenergistics2:smooth_sky_stone_block@0"
            ]
        },
        {
            "x": 0,
            "y": 3,
            "z": 3,

            "elements": [
                "environmentaltech:lightning_rod_insulated@0"
            ]
        },
        {
            "x": -3,
            "y": 14,
            "z": 4,
            "elements": [
                "ic2:fence@0"
            ]
        },
        {
            "x": -3,
            "y": 14,
            "z": 5,
            "elements": [
                "ic2:fence@0"
            ]
        },
        {
            "x": 0,
            "y": 3,
            "z": 5,

            "elements": [
                "mekanism:basicblock2@0"
            ]
        },
        {
            "x": 1,
            "y": -1,
            "z": 7,
            "elements": [
                "appliedenergistics2:smooth_sky_stone_slab@0"
            ]
        },
        {
            "x": 0,
            "y": 3,
            "z": 6,
            "elements": [
                "appliedenergistics2:smooth_sky_stone_block@0"
            ]
        },
        {
            "x": 0,
            "y": 16,
            "z": 1,

            "elements": [
                "mekanism:basicblock2@0"
            ]
        },
        {
            "x": 0,
            "y": 16,
            "z": 0,
            "elements": [
                "appliedenergistics2:smooth_sky_stone_stairs@2"
            ]
        },
        {
            "x": 0,
            "y": 16,
            "z": 6,
            "elements": [
                "appliedenergistics2:smooth_sky_stone_stairs@3"
            ]
        },
        {
            "x": 3,
            "y": 2,
            "z": 1,
            "elements": [
                "ic2:fence@0"
            ]
        },
        {
            "x": 0,
            "y": 16,
            "z": 5,

            "elements": [
                "mekanism:basicblock2@0"
            ]
        },
        {
            "x": 0,
            "y": 16,
            "z": 3,

            "elements": [
                "environmentaltech:lightning_rod_insulated@0"
            ]
        },
        {
            "x": 3,
            "y": 2,
            "z": 4,
            "elements": [
                "enderio:block_alloy@0"
            ]
        },
        {
            "x": -3,
            "y": 14,
            "z": 2,
            "elements": [
                "ic2:fence@0"
            ]
        },
        {
            "x": 3,
            "y": 2,
            "z": 5,
            "elements": [
                "ic2:fence@0"
            ]
        },
        {
            "x": -3,
            "y": 14,
            "z": 3,
            "elements": [
                "enderio:block_alloy@0"
            ]
        },
        {
            "x": 3,
            "y": 2,
            "z": 2,
            "elements": [
                "enderio:block_alloy@0"
            ]
        },
        {
            "x": -3,
            "y": 14,
            "z": 1,
            "elements": [
                "ic2:fence@0"
            ]
        },
        {
            "x": 3,
            "y": 2,
            "z": 3,
            "elements": [
                "appliedenergistics2:smooth_sky_stone_block@0"
            ]
        },
        {
            "x": 2,
            "y": 0,
            "z": 6,
            "elements": [
                "ic2:fence@0"
            ]
        },
        {
            "x": 2,
            "y": 0,
            "z": 5,

            "elements": [
                "mekanism:basicblock2@0"
            ]
        },
        {
            "x": -4,
            "y": -1,
            "z": 4,
            "elements": [
                "appliedenergistics2:smooth_sky_stone_slab@0"
            ]
        },
        {
            "x": 1,
            "y": 4,
            "z": 0,
            "elements": [
                "enderio:block_alloy@0"
            ]
        },
        {
            "x": -2,
            "y": 16,
            "z": 0,
            "elements": [
                "appliedenergistics2:smooth_sky_stone_slab@0"
            ]
        },
        {
            "x": 1,
            "y": 4,
            "z": 1,

            "elements": [
                "mekanism:basicblock2@0"
            ]
        },
        {
            "x": 2,
            "y": 14,
            "z": 5,

            "elements": [
                "mekanism:basicblock2@0"
            ]
        },
        {
            "x": 2,
            "y": 14,
            "z": 6,
            "elements": [
                "ic2:fence@0"
            ]
        },
        {
            "x": -2,
            "y": 16,
            "z": 6,
            "elements": [
                "appliedenergistics2:smooth_sky_stone_slab@0"
            ]
        },
        {
            "x": 1,
            "y": 4,
            "z": 6,
            "elements": [
                "enderio:block_alloy@0"
            ]
        },
        {
