{
    "registryname": "YMG_Nether_Abyss",
    "localizedname": "§b§lYMG§r§e§l—#C31717§l地狱深渊 §r§e",
    "failure-action": "still",
    "requires-blueprint": false,
    "color": "C31717",
    "parts": [
        {
            "x": 2,
            "y": 3,
            "z": 1,
            "elements": [
                "minecraft:stained_glass@14"
            ]
        },
        {
            "x": -2,
            "y": -2,
            "z": 1,
            "elements": [
                "enderio:block_reinforced_obsidian@0"
            ]
        },
        {
            "x": -2,
            "y": -2,
            "z": 2,
            "elements": [
                "enderio:block_reinforced_obsidian@0"
            ]
        },
        {
            "x": -2,
            "y": -2,
            "z": -1,
            "elements": [
                "minecraft:stone_slab@6"
            ]
        },
        {
            "x": -2,
            "y": -2,
            "z": 0,
            "elements": [
                "enderio:block_reinforced_obsidian@0"
            ]
        },
        {
            "x": -2,
            "y": -2,
            "z": 5,
            "elements": [
                "minecraft:stone_slab@6"
            ]
        },
        {
            "x": -2,
            "y": -2,
            "z": 3,
            "elements": [
                "enderio:block_reinforced_obsidian@0"
            ]
        },
        {
            "x": -2,
            "y": -2,
            "z": 4,
            "elements": [
                "enderio:block_reinforced_obsidian@0"
            ]
        },
        {
            "x": 2,
            "y": 3,
            "z": 2,
            "elements": [
                "minecraft:stained_glass_pane@14"
            ]
        },
        {
            "x": 2,
            "y": 3,
            "z": 3,
            "elements": [
                "minecraft:stained_glass@14"
            ]
        },
        {
            "x": -1,
            "y": -1,
            "z": 1,
            "elements": [
                "minecraft:nether_brick@0"
            ]
        },
        {
            "x": -1,
            "y": 6,
            "z": 4,
            "elements": [
                "minecraft:nether_brick_stairs@3"
            ]
        },
        {
            "x": -1,
            "y": -1,
            "z": 2,
            "elements": [
                "minecraft:nether_brick@0"
            ]
        },
        {
            "x": -1,
            "y": 6,
            "z": 5,
            "elements": [
                "minecraft:nether_brick_fence@0"
            ]
        },
        {
            "x": 3,
            "y": 4,
            "z": 3,
            "elements": [
                "minecraft:stained_glass_pane@14"
            ]
        },
        {
            "x": -1,
            "y": 6,
            "z": 2,
            "elements": [
                "enderio:block_reinforced_obsidian@0"
            ]
        },
        {
            "x": -1,
            "y": -1,
            "z": 3,
            "elements": [
                "minecraft:nether_brick@0"
            ]
        },
        {
            "x": -1,
            "y": -1,
            "z": 4,
            "elements": [
                "minecraft:nether_brick_stairs@3"
            ]
        },
        {
            "x": -1,
            "y": 6,
            "z": 3,
            "elements": [
                "contenttweaker:tungstenblock@0"
            ]
        },
        {
            "x": 3,
            "y": 4,
            "z": 1,
            "elements": [
                "minecraft:stained_glass_pane@14"
            ]
        },
        {
            "x": 0,
            "y": 7,
            "z": -1,
            "elements": [
                "minecraft:nether_brick_stairs@6"
            ]
        },
        {
            "x": 0,
            "y": 7,
            "z": 0,
            "elements": [
                "enderio:block_reinforced_obsidian@0"
            ]
        },
        {
            "x": 0,
            "y": 7,
            "z": 1,
            "elements": [
                "enderio:block_reinforced_obsidian@0"
            ]
        },
        {
            "x": 0,
            "y": 7,
            "z": 2,
            "elements": [
                "enderio:block_reinforced_obsidian@0"
            ]
        },
        {
            "x": 0,
            "y": 7,
            "z": 3,
            "elements": [
                "enderio:block_reinforced_obsidian@0"
            ]
        },
        {
            "x": 0,
            "y": 7,
            "z": 4,
            "elements": [
                "enderio:block_reinforced_obsidian@0"
            ]
        },
        {
            "x": -1,
            "y": 6,
            "z": 0,
            "elements": [
                "minecraft:nether_brick_stairs@2"
            ]
        },
        {
            "x": -1,
            "y": 6,
            "z": 1,
            "elements": [
                "contenttweaker:tungstenblock@0"
            ]
        },
        {
            "x": 0,
            "y": 7,
            "z": 5,
            "elements": [
                "minecraft:nether_brick_stairs@7"
            ]
        },
        {
            "x": -1,
            "y": 6,
            "z": -1,
            "elements": [
                "minecraft:nether_brick_fence@0"
            ]
        },
        {
            "x": -1,
            "y": -1,
            "z": 0,
            "elements": [
                "minecraft:nether_brick_stairs@2"
            ]
        },
        {
            "x": 3,
            "y": -2,
            "z": 1,
            "elements": [
                "minecraft:nether_brick_stairs@2"
            ]
        },
        {
            "x": 0,
            "y": 0,
            "z": 4,

            "elements": [
                "modularmachinery:blockcasing@0",
                "ItemInput",
                "ItemOutput",
                "EnergyInput"
            ]
        },
        {
            "x": 3,
            "y": -2,
            "z": 0,
            "elements": [
                "minecraft:stone_slab@6"
            ]
        },
        {
            "x": 0,
            "y": 0,
            "z": 3,
            "elements": [
                "minecraft:magma@0"
            ]
        },
        {
            "x": 0,
            "y": 0,
            "z": 0,

            "elements": [
                "modularmachinery:blockcontroller@2"
            ]
        },
        {
            "x": 3,
            "y": -2,
            "z": 4,
            "elements": [
                "minecraft:stone_slab@6"
            ]
        },
        {
            "x": 3,
            "y": -2,
            "z": 3,
            "elements": [
                "minecraft:nether_brick_stairs@3"
            ]
        },
        {
            "x": 0,
            "y": 0,
            "z": 2,
            "elements": [
                "minecraft:magma@0"
            ]
        },
        {
            "x": 1,
            "y": 2,
            "z": 4,
            "elements": [
                "minecraft:stained_glass@14"
            ]
        },
        {
            "x": 3,
            "y": -2,
            "z": 2,
            "elements": [
                "enderio:block_reinforced_obsidian@0"
            ]
        },
        {
            "x": 0,
            "y": 0,
            "z": 1,
            "elements": [
                "minecraft:magma@0"
            ]
        },
        {
            "x": 1,
            "y": 2,
            "z": 3,
            "elements": [
                "minecraft:obsidian@0"
            ]
        },
        {
            "x": 1,
            "y": 2,
            "z": 2,
            "elements": [
                "minecraft:air@0"
            ]
        },
        {
            "x": 1,
            "y": 2,
            "z": 1,
            "elements": [
                "minecraft:obsidian@0"
            ]
        },
        {
            "x": 1,
            "y": 2,
            "z": 0,
            "elements": [
                "minecraft:stained_glass@14"
            ]
        },
        {
            "x": -2,
            "y": 4,
            "z": 2,
            "elements": [
                "minecraft:stained_glass_pane@14"
            ]
        },
        {
            "x": -2,
            "y": 4,
            "z": 1,
            "elements": [
                "minecraft:stained_glass@14"
            ]
        },
        {
            "x": -2,
            "y": 4,
            "z": 3,
            "elements": [
                "minecraft:stained_glass@14"
            ]
        },
        {
            "x": 4,
            "y": -2,
            "z": 2,
            "elements": [
                "minecraft:nether_brick_stairs@1"
            ]
        },
        {
            "x": 3,
            "y": 5,
            "z": 3,
            "elements": [
                "minecraft:nether_brick_fence@0"
            ]
        },
        {
            "x": 3,
            "y": 5,
            "z": 1,
            "elements": [
                "minecraft:nether_brick_fence@0"
            ]
        },
        {
            "x": 1,
            "y": 1,
            "z": 0,
            "elements": [
                "minecraft:stained_glass@14"
            ]
        },
        {
            "x": 1,
            "y": 1,
            "z": 4,
            "elements": [
                "minecraft:stained_glass@14"
            ]
        },
        {
            "x": 1,
            "y": 1,
            "z": 3,
            "elements": [
                "minecraft:obsidian@0"
            ]
        },
        {
            "x": 1,
            "y": 1,
            "z": 2,
            "elements": [
                "minecraft:magma@0"
            ]
        },
        {
            "x": 1,
            "y": 1,
            "z": 1,
            "elements": [
                "minecraft:obsidian@0"
            ]
        },
        {
            "x": -2,
            "y": 5,
            "z": 1,
            "elements": [
                "minecraft:stained_glass@14"
            ]
        },
        {
            "x": -1,
            "y": -2,
            "z": -1,
            "elements": [
                "minecraft:nether_brick_stairs@0"
            ]
        },
        {
            "x": -1,
            "y": -2,
            "z": 0,
            "elements": [
                "enderio:block_reinforced_obsidian@0"
            ]
        },
        {
            "x": -2,
            "y": 5,
            "z": 3,
            "elements": [
                "minecraft:stained_glass@14"
            ]
        },
        {
            "x": -1,
            "y": -2,
            "z": 1,
            "elements": [
                "enderio:block_reinforced_obsidian@0"
            ]
        },
        {
            "x": -2,
            "y": 5,
            "z": 2,
            "elements": [
                "minecraft:stained_glass@14"
            ]
        },
        {
            "x": -3,
            "y": 3,
            "z": 3,
            "elements": [
                "minecraft:stained_glass_pane@14"
            ]
        },
        {
            "x": 1,
            "y": 7,
            "z": 1,
            "elements": [
                "enderio:block_reinforced_obsidian@0"
            ]
        },
        {
            "x": 1,
            "y": 7,
            "z": 2,
            "elements": [
                "enderio:block_reinforced_obsidian@0"
            ]
        },
        {
            "x": 1,
            "y": 7,
            "z": -1,
            "elements": [
                "minecraft:nether_brick@0"
            ]
        },
        {
            "x": 1,
            "y": 7,
            "z": 0,
            "elements": [
                "minecraft:nether_brick_stairs@6"
            ]
        },
        {
            "x": -2,
            "y": -1,
            "z": 4,
            "elements": [
                "minecraft:stone_slab@6"
            ]
        },
        {
            "x": 1,
            "y": 7,
            "z": 5,
            "elements": [
                "minecraft:nether_brick@0"
            ]
        },
        {
            "x": -2,
            "y": -1,
            "z": 2,
            "elements": [
                "enderio:block_reinforced_obsidian@0"
            ]
        },
        {
            "x": 1,
            "y": 7,
            "z": 3,
            "elements": [
                "enderio:block_reinforced_obsidian@0"
            ]
        },
        {
            "x": -3,
            "y": 3,
            "z": 1,
            "elements": [
                "minecraft:stained_glass_pane@14"
            ]
        },
        {
            "x": 1,
            "y": 7,
            "z": 4,
            "elements": [
                "minecraft:nether_brick_stairs@7"
            ]
        },
        {
            "x": -2,
            "y": -1,
            "z": 3,
            "elements": [
                "minecraft:nether_brick_stairs@0"
            ]
        },
        {
            "x": -2,
            "y": -1,
            "z": 0,
            "elements": [
                "minecraft:stone_slab@6"
            ]
        },
        {
            "x": -2,
            "y": -1,
            "z": 1,
            "elements": [
                "minecraft:nether_brick_stairs@0"
            ]
        },
        {
            "x": 0,
            "y": 8,
            "z": 3,
            "elements": [
                "minecraft:nether_brick@0"
            ]
        },
        {
            "x": 0,
            "y": 8,
            "z": 4,
            "elements": [
                "minecraft:stone_slab@6"
            ]
        },
        {
            "x": -1,
            "y": -2,
            "z": 2,
            "elements": [
                "enderio:block_reinforced_obsidian@0"
            ]
        },
        {
            "x": 0,
            "y": 8,
            "z": 0,
            "elements": [
                "minecraft:stone_slab@6"
            ]
        },
        {
            "x": -1,
            "y": -2,
            "z": 3,
            "elements": [
                "enderio:block_reinforced_obsidian@0"
            ]
        },
        {
            "x": 0,
            "y": 8,
            "z": 1,
            "elements": [
                "minecraft:nether_brick@0"
            ]
        },
        {
            "x": -1,
            "y": -2,
            "z": 4,
            "elements": [
                "enderio:block_reinforced_obsidian@0"
            ]
        },
        {
            "x": 0,
            "y": 8,
            "z": 2,
            "elements": [
                "minecraft:nether_brick@0"
            ]
        },
        {
            "x": -1,
            "y": -2,
            "z": 5,
            "elements": [
                "minecraft:nether_brick_stairs@0"
            ]
        },
        {
            "x": 1,
            "y": 0,
            "z": 4,
            "elements": [
                "minecraft:nether_brick_stairs@7"
            ]
        },
        {
            "x": 1,
            "y": 0,
            "z": 3,
            "elements": [
                "minecraft:obsidian@0"
            ]
        },
        {
            "x": 1,
            "y": 0,
            "z": 2,
            "elements": [
                "minecraft:magma@0"
            ]
        },
        {
            "x": 1,
            "y": 0,
            "z": 1,
            "elements": [
                "minecraft:obsidian@0"
            ]
        },
        {
            "x": 1,
            "y": 0,
            "z": 0,
            "elements": [
                "minecraft:nether_brick_stairs@6"
            ]
        },
        {
            "x": -2,
            "y": 6,
            "z": 3,
            "elements": [
                "minecraft:nether_brick_stairs@0"
            ]
        },
        {
            "x": 3,
            "y": -1,
            "z": 2,
            "elements": [
                "minecraft:stone_slab@6"
            ]
        },
        {
            "x": -2,
            "y": 3,
            "z": 3,
            "elements": [
                "minecraft:stained_glass@14"
            ]
        },
        {
            "x": -3,
            "y": -2,
            "z": 4,
            "elements": [
                "minecraft:stone_slab@6"
            ]
        },
        {
            "x": 1,
            "y": 3,
            "z": 5,
            "elements": [
                "minecraft:stained_glass_pane@14"
            ]
        },
        {
            "x": -2,
            "y": 3,
            "z": 2,
            "elements": [
                "minecraft:stained_glass_pane@14"
            ]
        },
        {
            "x": 2,
            "y": 8,
            "z": 3,
            "elements": [
                "minecraft:nether_brick_stairs@3"
            ]
        },
        {
            "x": 1,
            "y": 3,
            "z": 3,
            "elements": [
                "minecraft:obsidian@0"
            ]
        },
        {
            "x": 2,
            "y": 8,
            "z": 2,
            "elements": [
                "minecraft:stone_slab@6"
            ]
        },
        {
            "x": 2,
            "y": 8,
            "z": 1,
            "elements": [
                "minecraft:nether_brick_stairs@2"
            ]
        },
        {
            "x": 1,
            "y": 3,
            "z": 4,
            "elements": [
                "minecraft:stained_glass@14"
            ]
        },
        {
            "x": -2,
            "y": 3,
            "z": 1,
            "elements": [
                "minecraft:stained_glass@14"
            ]
        },
        {
            "x": -2,
            "y": 0,
            "z": 3,
            "elements": [
                "minecraft:nether_brick_stairs@4"
            ]
        },
        {
            "x": -2,
            "y": 0,
            "z": 1,
            "elements": [
                "minecraft:nether_brick_stairs@4"
            ]
        },
        {
            "x": -2,
            "y": 0,
            "z": 2,

            "elements": [
                "modularmachinery:blockcasing@0",
                "ItemInput",
                "ItemOutput",
                "EnergyInput"
            ]
        },
        {
            "x": -3,
            "y": -2,
            "z": 0,
            "elements": [
                "minecraft:stone_slab@6"
            ]
        },
        {
            "x": 1,
            "y": 3,
            "z": 1,
            "elements": [
                "minecraft:obsidian@0"
            ]
        },
        {
            "x": -3,
            "y": -2,
            "z": 1,
            "elements": [
                "minecraft:nether_brick_stairs@2"
            ]
        },
        {
            "x": 1,
            "y": 3,
            "z": 2,
            "elements": [
                "minecraft:air@0"
            ]
        },
        {
            "x": 2,
            "y": 5,
            "z": 1,
            "elements": [
                "minecraft:stained_glass@14"
            ]
        },
        {
            "x": -3,
            "y": -2,
            "z": 2,
            "elements": [
                "enderio:block_reinforced_obsidian@0"
            ]
        },
        {
            "x": 2,
            "y": 5,
            "z": 2,
            "elements": [
                "minecraft:stained_glass@14"
            ]
        },
        {
            "x": 1,
            "y": 3,
            "z": -1,
            "elements": [
                "minecraft:stained_glass_pane@14"
            ]
        },
        {
            "x": -3,
            "y": -2,
            "z": 3,
            "elements": [
                "minecraft:nether_brick_stairs@3"
            ]
        },
        {
            "x": 1,
            "y": 3,
            "z": 0,
            "elements": [
                "minecraft:stained_glass@14"
            ]
        },
        {
            "x": 2,
            "y": 5,
            "z": 3,
            "elements": [
                "minecraft:stained_glass@14"
            ]
        },
        {
            "x": 1,
            "y": 6,
            "z": 4,
            "elements": [
                "minecraft:nether_brick_stairs@3"
            ]
        },
        {
            "x": 1,
            "y": 6,
            "z": 5,
            "elements": [
                "minecraft:nether_brick_fence@0"
            ]
        },
        {
            "x": 1,
            "y": 6,
            "z": 2,
            "elements": [
                "enderio:block_reinforced_obsidian@0"
            ]
        },
        {
            "x": 1,
            "y": 6,
            "z": 3,
            "elements": [
                "contenttweaker:tungstenblock@0"
            ]
        },
        {
            "x": 2,
            "y": 2,
            "z": 1,
            "elements": [
                "minecraft:stained_glass@14"
            ]
        },
        {
            "x": 1,
            "y": 6,
            "z": 0,
            "elements": [
                "minecraft:nether_brick_stairs@2"
            ]
        },
        {
            "x": 1,
            "y": 6,
            "z": 1,
            "elements": [
                "contenttweaker:tungstenblock@0"
            ]
        },
        {
            "x": 2,
            "y": 2,
            "z": 2,
            "elements": [
                "minecraft:stained_glass_pane@14"
            ]
        },
        {
            "x": 1,
            "y": 6,
            "z": -1,
            "elements": [
                "minecraft:nether_brick_fence@0"
            ]
        },
        {
            "x": -1,
            "y": 5,
            "z": 2,
            "elements": [
                "contenttweaker:tungstenblock@0"
            ]
        },
        {
            "x": 0,
            "y": -2,
            "z": -2,
            "elements": [
                "minecraft:nether_brick_stairs@2"
            ]
        },
        {
            "x": -1,
            "y": 5,
            "z": 1,
            "elements": [
                "contenttweaker:tungstenblock@0"
            ]
        },
        {
            "x": 0,
            "y": -2,
            "z": 0,
            "elements": [
                "enderio:block_reinforced_obsidian@0"
            ]
        },
        {
            "x": -1,
            "y": 5,
            "z": 0,
            "elements": [
                "minecraft:stained_glass@14"
            ]
        },
        {
            "x": -1,
            "y": 5,
            "z": -1,
            "elements": [
                "minecraft:nether_brick_fence@0"
            ]
        },
        {
            "x": 0,
            "y": -2,
            "z": -1,
            "elements": [
                "enderio:block_reinforced_obsidian@0"
            ]
        },
        {
            "x": 0,
            "y": -2,
            "z": 6,
            "elements": [
                "minecraft:nether_brick_stairs@3"
            ]
        },
        {
            "x": 2,
            "y": 2,
            "z": 3,
            "elements": [
                "minecraft:stained_glass@14"
            ]
        },
        {
            "x": 0,
            "y": -2,
            "z": 5,
            "elements": [
                "enderio:block_reinforced_obsidian@0"
            ]
        },
        {
            "x": -3,
            "y": 4,
            "z": 3,
            "elements": [
                "minecraft:stained_glass_pane@14"
            ]
        },
        {
            "x": 0,
            "y": -2,
            "z": 2,
            "elements": [
                "enderio:block_reinforced_obsidian@0"
            ]
        },
        {
            "x": -3,
            "y": 4,
            "z": 1,
            "elements": [
                "minecraft:stained_glass_pane@14"
            ]
        },
        {
            "x": 0,
            "y": -2,
            "z": 1,
            "elements": [
                "enderio:block_reinforced_obsidian@0"
            ]
        },
        {
            "x": 0,
            "y": -2,
            "z": 4,
            "elements": [
                "enderio:block_reinforced_obsidian@0"
            ]
        },
        {
            "x": 0,
            "y": -2,
            "z": 3,
            "elements": [
                "enderio:block_reinforced_obsidian@0"
            ]
        },
        {
            "x": 2,
            "y": -1,
            "z": 3,
            "elements": [
                "minecraft:nether_brick_stairs@1"
            ]
        },
        {
            "x": 2,
            "y": -1,
            "z": 2,
            "elements": [
                "enderio:block_reinforced_obsidian@0"
            ]
        },
        {
            "x": 2,
            "y": -1,
            "z": 4,
            "elements": [
                "minecraft:stone_slab@6"
            ]
        },
        {
            "x": 2,
            "y": -1,
            "z": 1,
            "elements": [
                "minecraft:nether_brick_stairs@1"
            ]
        },
        {
            "x": 2,
            "y": -1,
            "z": 0,
            "elements": [
                "minecraft:stone_slab@6"
            ]
        },
        {
            "x": -1,
            "y": 2,
            "z": 1,
            "elements": [
                "minecraft:obsidian@0"
            ]
        },
        {
            "x": -1,
            "y": 8,
            "z": 2,
            "elements": [
                "minecraft:nether_brick@0"
            ]
        },
        {
            "x": -1,
            "y": 2,
            "z": 0,
            "elements": [
                "minecraft:stained_glass@14"
            ]
        },
        {
            "x": -1,
            "y": 8,
            "z": 3,
            "elements": [
                "minecraft:nether_brick_stairs@3"
            ]
        },
        {
            "x": -1,
            "y": 8,
            "z": 0,
            "elements": [
                "minecraft:nether_brick_stairs@0"
            ]
        },
        {
            "x": -1,
            "y": 8,
            "z": 1,
            "elements": [
                "minecraft:nether_brick_stairs@2"
            ]
        },
        {
            "x": 0,
            "y": 4,
            "z": 4,
            "elements": [
                "minecraft:stained_glass_pane@14"
            ]
        },
        {
            "x": -1,
            "y": 2,
            "z": 4,
            "elements": [
                "minecraft:stained_glass@14"
            ]
        },
        {
            "x": 0,
            "y": 4,
            "z": 3,
            "elements": [
                "minecraft:air@0"
            ]
        },
        {
            "x": -1,
            "y": 8,
            "z": 4,
            "elements": [
                "minecraft:nether_brick_stairs@0"
            ]
        },
        {
            "x": -2,
            "y": 6,
            "z": 2,

            "elements": [
                "modularmachinery:blockcasing@0",
                "FluidInput"
            ]
        },
        {
            "x": -1,
            "y": 2,
            "z": 3,
            "elements": [
                "minecraft:obsidian@0"
            ]
        },
        {
            "x": -2,
            "y": 6,
            "z": 1,
            "elements": [
                "minecraft:nether_brick_stairs@0"
            ]
        },
        {
            "x": -1,
            "y": 2,
            "z": 2,
            "elements": [
                "minecraft:air@0"
            ]
        },
        {
            "x": 0,
            "y": 1,
            "z": 1,
            "elements": [
                "minecraft:magma@0"
            ]
        },
        {
            "x": 0,
            "y": 1,
            "z": 0,
            "elements": [
                "minecraft:stained_glass@14"
            ]
        },
        {
            "x": 0,
            "y": 1,
            "z": 3,
            "elements": [
                "minecraft:magma@0"
            ]
        },
        {
            "x": 0,
            "y": 1,
            "z": 2,
            "elements": [
                "minecraft:magma@0"
            ]
        },
        {
            "x": -1,
            "y": 5,
            "z": 5,
            "elements": [
                "minecraft:nether_brick_fence@0"
            ]
        },
        {
            "x": -1,
            "y": 5,
            "z": 4,
            "elements": [
                "minecraft:stained_glass@14"
            ]
        },
        {
            "x": 0,
            "y": 1,
            "z": 4,
            "elements": [
                "minecraft:stained_glass@14"
            ]
        },
        {
            "x": -1,
            "y": 5,
            "z": 3,
            "elements": [
                "contenttweaker:tungstenblock@0"
            ]
        },
        {
            "x": 1,
            "y": 5,
            "z": 3,
            "elements": [
                "contenttweaker:tungstenblock@0"
            ]
        },
        {
            "x": 1,
            "y": 5,
            "z": 4,
            "elements": [
                "minecraft:stained_glass@14"
            ]
        },
        {
            "x": 1,
            "y": 5,
            "z": 1,
            "elements": [
                "contenttweaker:tungstenblock@0"
            ]
        },
        {
            "x": 1,
            "y": 5,
            "z": 2,
            "elements": [
                "contenttweaker:tungstenblock@0"
            ]
        },
        {
            "x": 1,
            "y": 5,
            "z": 5,
            "elements": [
                "minecraft:nether_brick_fence@0"
            ]
        },
        {
            "x": 0,
            "y": 4,
            "z": 0,
            "elements": [
                "minecraft:stained_glass_pane@14"
            ]
        },
        {
            "x": 0,
            "y": 4,
            "z": 1,
            "elements": [
                "minecraft:air@0"
            ]
        },
        {
            "x": 0,
            "y": 4,
            "z": 2,
            "elements": [
                "minecraft:air@0"
            ]
        },
        {
            "x": -2,
            "y": 1,
            "z": 2,
            "elements": [
                "minecraft:stained_glass@14"
            ]
        },
        {
            "x": -2,
            "y": 1,
            "z": 3,
            "elements": [
                "minecraft:stained_glass@14"
            ]
        },
        {
            "x": -2,
            "y": 1,
            "z": 1,
            "elements": [
                "minecraft:stained_glass@14"
            ]
        },
        {
            "x": -2,
            "y": 8,
            "z": 1,
            "elements": [
                "minecraft:nether_brick_stairs@2"
            ]
        },
        {
            "x": -2,
            "y": 8,
            "z": 2,
            "elements": [
                "minecraft:stone_slab@6"
            ]
        },
        {
            "x": 2,
            "y": 6,
            "z": 1,
            "elements": [
                "minecraft:nether_brick_stairs@1"
            ]
        },
        {
            "x": 1,
            "y": -2,
            "z": 5,
            "elements": [
                "minecraft:nether_brick_stairs@1"
            ]
        },
        {
            "x": -2,
            "y": 8,
            "z": 3,
            "elements": [
                "minecraft:nether_brick_stairs@3"
            ]
        },
        {
            "x": 2,
            "y": 6,
            "z": 2,

            "elements": [
                "modularmachinery:blockcasing@0",
                "FluidInput"
            ]
        },
        {
            "x": 1,
            "y": -2,
            "z": 4,
            "elements": [
                "enderio:block_reinforced_obsidian@0"
            ]
        },
        {
            "x": 1,
            "y": -2,
            "z": 3,
            "elements": [
                "enderio:block_reinforced_obsidian@0"
            ]
        },
        {
            "x": 1,
            "y": 5,
            "z": -1,
            "elements": [
                "minecraft:nether_brick_fence@0"
            ]
        },
        {
            "x": -3,
            "y": 7,
            "z": 2,
            "elements": [
                "minecraft:nether_brick_stairs@4"
            ]
        },
        {
            "x": 2,
            "y": 6,
            "z": 3,
            "elements": [
                "minecraft:nether_brick_stairs@1"
            ]
        },
        {
            "x": 1,
            "y": -2,
            "z": 2,
            "elements": [
                "enderio:block_reinforced_obsidian@0"
            ]
        },
        {
            "x": 1,
            "y": 5,
            "z": 0,
            "elements": [
                "minecraft:stained_glass@14"
            ]
        },
        {
            "x": -3,
            "y": 7,
            "z": 1,
            "elements": [
                "minecraft:nether_brick@0"
            ]
        },
        {
            "x": 1,
            "y": -2,
            "z": 1,
            "elements": [
                "enderio:block_reinforced_obsidian@0"
            ]
        },
        {
            "x": 1,
            "y": -2,
            "z": 0,
            "elements": [
                "enderio:block_reinforced_obsidian@0"
            ]
        },
        {
            "x": -3,
            "y": 7,
            "z": 3,
            "elements": [
                "minecraft:nether_brick@0"
            ]
        },
        {
            "x": -1,
            "y": 3,
            "z": 4,
            "elements": [
                "minecraft:stained_glass@14"
            ]
        },
        {
            "x": -1,
            "y": 3,
            "z": 3,
            "elements": [
                "minecraft:obsidian@0"
            ]
        },
        {
            "x": -1,
            "y": 3,
            "z": 2,
            "elements": [
                "minecraft:air@0"
            ]
        },
        {
            "x": -1,
            "y": 3,
            "z": 1,
            "elements": [
                "minecraft:obsidian@0"
            ]
        },
        {
            "x": -1,
            "y": 3,
            "z": 0,
            "elements": [
                "minecraft:stained_glass@14"
            ]
        },
        {
            "x": -1,
            "y": 3,
            "z": -1,
            "elements": [
                "minecraft:stained_glass_pane@14"
            ]
        },
        {
            "x": 1,
            "y": -1,
            "z": 2,
            "elements": [
                "minecraft:nether_brick@0"
            ]
        },
        {
            "x": 1,
            "y": -1,
            "z": 1,
            "elements": [
                "minecraft:nether_brick@0"
            ]
        },
        {
            "x": 1,
            "y": -1,
            "z": 0,
            "elements": [
                "minecraft:nether_brick_stairs@2"
            ]
        },
        {
            "x": 1,
            "y": -1,
            "z": 4,
            "elements": [
                "minecraft:nether_brick_stairs@3"
            ]
        },
        {
            "x": -1,
            "y": 3,
            "z": 5,
            "elements": [
                "minecraft:stained_glass_pane@14"
            ]
        },
        {
            "x": 1,
            "y": -1,
            "z": 3,
            "elements": [
                "minecraft:nether_brick@0"
            ]
        },
        {
            "x": -4,
            "y": -2,
            "z": 2,
            "elements": [
                "minecraft:nether_brick_stairs@0"
            ]
        },
        {
            "x": -2,
            "y": 7,
            "z": 3,
            "elements": [
                "minecraft:nether_brick_stairs@4"
            ]
        },
        {
            "x": 0,
            "y": 3,
            "z": 1,
            "elements": [
                "minecraft:air@0"
            ]
        },
        {
            "x": 0,
            "y": 3,
            "z": 0,
            "elements": [
                "minecraft:stained_glass_pane@14"
            ]
        },
        {
            "x": -2,
            "y": 7,
            "z": 2,
            "elements": [
                "enderio:block_reinforced_obsidian@0"
            ]
        },
        {
            "x": 0,
            "y": 3,
            "z": 3,
            "elements": [
                "minecraft:air@0"
            ]
        },
        {
            "x": -2,
            "y": 7,
            "z": 4,
            "elements": [
                "minecraft:stone_slab@14"
            ]
        },
        {
            "x": 0,
            "y": 3,
            "z": 2,
            "elements": [
                "minecraft:air@0"
            ]
        },
        {
            "x": 0,
            "y": 3,
            "z": 4,
            "elements": [
                "minecraft:stained_glass_pane@14"
            ]
        },
        {
            "x": -2,
            "y": 7,
            "z": 1,
            "elements": [
                "minecraft:nether_brick_stairs@4"
            ]
        },
        {
            "x": -2,
            "y": 7,
            "z": 0,
            "elements": [
                "minecraft:stone_slab@14"
            ]
        },
        {
            "x": 0,
            "y": 5,
            "z": 2,
            "elements": [
                "contenttweaker:tungstenblock@0"
            ]
        },
        {
            "x": 1,
            "y": -2,
            "z": -1,
            "elements": [
                "minecraft:nether_brick_stairs@1"
            ]
        },
        {
            "x": 0,
            "y": 5,
            "z": 3,
            "elements": [
                "contenttweaker:tungstenblock@0"
            ]
        },
        {
            "x": 0,
            "y": 5,
            "z": 4,
            "elements": [
                "minecraft:stained_glass@14"
            ]
        },
        {
            "x": 3,
            "y": 7,
            "z": 2,
            "elements": [
                "minecraft:nether_brick_stairs@5"
            ]
        },
        {
            "x": 3,
            "y": 7,
            "z": 1,
            "elements": [
                "minecraft:nether_brick@0"
            ]
        },
        {
            "x": 3,
            "y": 7,
            "z": 3,
            "elements": [
                "minecraft:nether_brick@0"
            ]
        },
        {
            "x": 0,
            "y": 5,
            "z": 0,
            "elements": [
                "minecraft:stained_glass@14"
            ]
        },
        {
            "x": 0,
            "y": 5,
            "z": 1,
            "elements": [
                "contenttweaker:tungstenblock@0"
            ]
        },
        {
            "x": 1,
            "y": 4,
            "z": 0,
            "elements": [
                "minecraft:stained_glass@14"
            ]
        },
        {
            "x": -3,
            "y": 6,
            "z": 3,
            "elements": [
                "minecraft:nether_brick_fence@0"
            ]
        },
        {
            "x": 1,
            "y": 4,
            "z": 1,
            "elements": [
                "minecraft:obsidian@0"
            ]
        },
        {
            "x": -3,
            "y": 6,
            "z": 1,
            "elements": [
                "minecraft:nether_brick_fence@0"
            ]
        },
        {
            "x": 1,
            "y": 4,
            "z": -1,
            "elements": [
                "minecraft:stained_glass_pane@14"
            ]
        },
        {
            "x": -2,
            "y": 2,
            "z": 2,
            "elements": [
                "minecraft:stained_glass_pane@14"
            ]
        },
        {
            "x": -2,
            "y": 2,
            "z": 1,
            "elements": [
                "minecraft:stained_glass@14"
            ]
        },
        {
            "x": 1,
            "y": 4,
            "z": 4,
            "elements": [
                "minecraft:stained_glass@14"
            ]
        },
        {
            "x": 2,
            "y": 0,
            "z": 2,

            "elements": [
                "modularmachinery:blockcasing@0",
                "ItemInput",
                "ItemOutput",
                "EnergyInput"
            ]
        },
        {
            "x": 1,
            "y": 4,
            "z": 5,
            "elements": [
                "minecraft:stained_glass_pane@14"
            ]
        },
        {
            "x": -2,
            "y": 2,
            "z": 3,
            "elements": [
                "minecraft:stained_glass@14"
            ]
        },
        {
            "x": 2,
            "y": 0,
            "z": 1,
            "elements": [
                "minecraft:nether_brick_stairs@5"
            ]
        },
        {
            "x": 1,
            "y": 4,
            "z": 2,
            "elements": [
                "minecraft:air@0"
            ]
        },
        {
            "x": 1,
            "y": 4,
            "z": 3,
            "elements": [
                "minecraft:obsidian@0"
            ]
        },
        {
            "x": 2,
            "y": 0,
            "z": 3,
            "elements": [
                "minecraft:nether_brick_stairs@5"
            ]
        },
        {
            "x": 2,
            "y": -2,
            "z": 0,
            "elements": [
                "enderio:block_reinforced_obsidian@0"
            ]
        },
        {
            "x": 2,
            "y": -2,
            "z": -1,
            "elements": [
                "minecraft:stone_slab@6"
            ]
        },
        {
            "x": 2,
            "y": -2,
            "z": 2,
            "elements": [
                "enderio:block_reinforced_obsidian@0"
            ]
        },
        {
            "x": 2,
            "y": -2,
            "z": 1,
            "elements": [
                "enderio:block_reinforced_obsidian@0"
            ]
        },
        {
            "x": 2,
            "y": -2,
            "z": 4,
            "elements": [
                "enderio:block_reinforced_obsidian@0"
            ]
        },
        {
            "x": 2,
            "y": -2,
            "z": 3,
            "elements": [
                "enderio:block_reinforced_obsidian@0"
            ]
        },
        {
            "x": -3,
            "y": 5,
            "z": 3,
            "elements": [
                "minecraft:nether_brick_fence@0"
            ]
        },
        {
            "x": -3,
            "y": 5,
            "z": 1,
            "elements": [
                "minecraft:nether_brick_fence@0"
            ]
        },
        {
            "x": 2,
            "y": -2,
            "z": 5,
            "elements": [
                "minecraft:stone_slab@6"
            ]
        },
        {
            "x": 3,
            "y": 6,
            "z": 1,
            "elements": [
                "minecraft:nether_brick_fence@0"
            ]
        },
        {
            "x": 3,
            "y": 6,
            "z": 3,
            "elements": [
                "minecraft:nether_brick_fence@0"
            ]
        },
        {
            "x": 0,
            "y": -1,
            "z": -1,
            "elements": [
                "minecraft:stone_slab@6"
            ]
        },
        {
            "x": -1,
            "y": 4,
            "z": -1,
            "elements": [
                "minecraft:stained_glass_pane@14"
            ]
        },
        {
            "x": -1,
            "y": 1,
            "z": 4,
            "elements": [
                "minecraft:stained_glass@14"
            ]
        },
        {
            "x": -1,
            "y": 1,
            "z": 3,
            "elements": [
                "minecraft:obsidian@0"
            ]
        },
        {
            "x": -1,
            "y": 4,
            "z": 3,
            "elements": [
                "minecraft:obsidian@0"
            ]
        },
        {
            "x": -1,
            "y": 1,
            "z": 2,
            "elements": [
                "minecraft:magma@0"
            ]
        },
        {
            "x": -1,
            "y": 4,
            "z": 2,
            "elements": [
                "minecraft:air@0"
            ]
        },
        {
            "x": -1,
            "y": 1,
            "z": 1,
            "elements": [
                "minecraft:obsidian@0"
            ]
        },
        {
            "x": -1,
            "y": 1,
            "z": 0,
            "elements": [
                "minecraft:stained_glass@14"
            ]
        },
        {
            "x": -1,
            "y": 4,
            "z": 1,
            "elements": [
                "minecraft:obsidian@0"
            ]
        },
        {
            "x": -1,
            "y": 4,
            "z": 0,
            "elements": [
                "minecraft:stained_glass@14"
            ]
        },
        {
            "x": 0,
            "y": 2,
            "z": 2,
            "elements": [
                "minecraft:air@0"
            ]
        },
        {
            "x": 0,
            "y": 2,
            "z": 1,
            "elements": [
                "minecraft:air@0"
            ]
        },
        {
            "x": 2,
            "y": 1,
            "z": 1,
            "elements": [
                "minecraft:stained_glass@14"
            ]
        },
        {
            "x": 0,
            "y": 2,
            "z": 4,
            "elements": [
                "minecraft:stained_glass_pane@14"
            ]
        },
        {
            "x": 2,
            "y": 1,
            "z": 2,
            "elements": [
                "minecraft:stained_glass@14"
            ]
        },
        {
            "x": -1,
            "y": 4,
            "z": 5,
            "elements": [
                "minecraft:stained_glass_pane@14"
            ]
        },
        {
            "x": -1,
            "y": 4,
            "z": 4,
            "elements": [
                "minecraft:stained_glass@14"
            ]
        },
        {
            "x": 2,
            "y": 1,
            "z": 3,
            "elements": [
                "minecraft:stained_glass@14"
            ]
        },
        {
            "x": 0,
            "y": 2,
            "z": 3,
            "elements": [
                "minecraft:air@0"
            ]
        },
        {
            "x": 0,
            "y": 2,
            "z": 0,
            "elements": [
                "minecraft:stained_glass_pane@14"
            ]
        },
        {
            "x": -1,
            "y": 7,
            "z": 5,
            "elements": [
                "minecraft:nether_brick@0"
            ]
        },
        {
            "x": -1,
            "y": 7,
            "z": 3,
            "elements": [
                "enderio:block_reinforced_obsidian@0"
            ]
        },
        {
            "x": -1,
            "y": 7,
            "z": 4,
            "elements": [
                "minecraft:nether_brick_stairs@7"
            ]
        },
        {
            "x": -1,
            "y": 7,
            "z": 1,
            "elements": [
                "enderio:block_reinforced_obsidian@0"
            ]
        },
        {
            "x": -1,
            "y": 7,
            "z": 2,
            "elements": [
                "enderio:block_reinforced_obsidian@0"
            ]
        },
        {
            "x": 0,
            "y": 6,
            "z": 0,

            "elements": [
                "modularmachinery:blockcasing@0",
                "FluidInput"
            ]
        },
        {
            "x": 0,
            "y": -1,
            "z": 1,
            "elements": [
                "minecraft:nether_brick@0"
            ]
        },
        {
            "x": 0,
            "y": -1,
            "z": 0,
            "elements": [
                "enderio:block_reinforced_obsidian@0"
            ]
        },
        {
            "x": 0,
            "y": -1,
            "z": 3,
            "elements": [
                "minecraft:nether_brick@0"
            ]
        },
        {
            "x": 0,
            "y": -1,
            "z": 2,
            "elements": [
                "minecraft:nether_brick@0"
            ]
        },
        {
            "x": 0,
            "y": 6,
            "z": 1,
            "elements": [
                "enderio:block_reinforced_obsidian@0"
            ]
        },
        {
            "x": 0,
            "y": -1,
            "z": 5,
            "elements": [
                "minecraft:stone_slab@6"
            ]
        },
        {
            "x": 0,
            "y": 6,
            "z": 2,
            "elements": [
                "enderio:block_reinforced_obsidian@0"
            ]
        },
        {
            "x": 0,
            "y": -1,
            "z": 4,
            "elements": [
                "enderio:block_reinforced_obsidian@0"
            ]
        },
        {
            "x": 0,
            "y": 6,
            "z": 3,
            "elements": [
                "enderio:block_reinforced_obsidian@0"
            ]
        },
        {
            "x": 0,
            "y": 6,
            "z": 4,

            "elements": [
                "modularmachinery:blockcasing@0",
                "FluidInput"
            ]
        },
        {
            "x": -1,
            "y": 7,
            "z": -1,
            "elements": [
                "minecraft:nether_brick@0"
            ]
        },
        {
            "x": -1,
            "y": 7,
            "z": 0,
            "elements": [
                "minecraft:nether_brick_stairs@6"
            ]
        },
        {
            "x": -1,
            "y": 0,
            "z": 3,
            "elements": [
                "minecraft:obsidian@0"
            ]
        },
        {
            "x": -1,
            "y": 0,
            "z": 2,
            "elements": [
                "minecraft:magma@0"
            ]
        },
        {
            "x": -1,
            "y": 0,
            "z": 1,
            "elements": [
                "minecraft:obsidian@0"
            ]
        },
        {
            "x": -1,
            "y": 0,
            "z": 0,
            "elements": [
                "minecraft:nether_brick_stairs@6"
            ]
        },
        {
            "x": -1,
            "y": 0,
            "z": 4,
            "elements": [
                "minecraft:nether_brick_stairs@7"
            ]
        },
        {
            "x": 2,
            "y": 4,
            "z": 1,
            "elements": [
                "minecraft:stained_glass@14"
            ]
        },
        {
            "x": 2,
            "y": 4,
            "z": 2,
            "elements": [
                "minecraft:stained_glass_pane@14"
            ]
        },
        {
            "x": 2,
            "y": 4,
            "z": 3,
            "elements": [
                "minecraft:stained_glass@14"
            ]
        },
        {
            "x": 1,
            "y": 8,
            "z": 4,
            "elements": [
                "minecraft:nether_brick_stairs@1"
            ]
        },
        {
            "x": 1,
            "y": 8,
            "z": 2,
            "elements": [
                "minecraft:nether_brick@0"
            ]
        },
        {
            "x": 1,
            "y": 8,
            "z": 3,
            "elements": [
                "minecraft:nether_brick_stairs@3"
            ]
        },
        {
            "x": 1,
            "y": 8,
            "z": 0,
            "elements": [
                "minecraft:nether_brick_stairs@1"
            ]
        },
        {
            "x": 1,
            "y": 8,
            "z": 1,
            "elements": [
                "minecraft:nether_brick_stairs@2"
            ]
        },
        {
            "x": -3,
            "y": -1,
            "z": 2,
            "elements": [
                "minecraft:stone_slab@6"
            ]
        },
        {
            "x": 2,
            "y": 7,
            "z": 1,
            "elements": [
                "minecraft:nether_brick_stairs@5"
            ]
        },
        {
            "x": 2,
            "y": 7,
            "z": 0,
            "elements": [
                "minecraft:stone_slab@14"
            ]
        },
        {
            "x": 3,
            "y": 3,
            "z": 3,
            "elements": [
                "minecraft:stained_glass_pane@14"
            ]
        },
        {
            "x": 2,
            "y": 7,
            "z": 4,
            "elements": [
                "minecraft:stone_slab@14"
            ]
        },
        {
            "x": 2,
            "y": 7,
            "z": 3,
            "elements": [
                "minecraft:nether_brick_stairs@5"
            ]
        },
        {
            "x": 3,
            "y": 3,
            "z": 1,
            "elements": [
                "minecraft:stained_glass_pane@14"
            ]
        },
        {
            "x": 2,
            "y": 7,
            "z": 2,
            "elements": [
                "enderio:block_reinforced_obsidian@0"
            ]
        }
    ]}