{
    "registryname": "YMG_Tesla",
    "localizedname": "§b§lYMG§r§e§l—#FFFEE8§l特斯拉 §r§e",
    "failure-action": "still",
    "requires-blueprint": false,
    "has-factory": true,
    "factory-only": true,
    "color": "FFFEE8",
    "parts": [
        {
            "x": 4,
            "y": 12,
            "z": 9,
            "elements": [
                "swallowsresourcelibrary:teslashell@0"
            ]
        },
        {
            "x": 4,
            "y": 12,
            "z": 7,
            "elements": [
                "swallowsresourcelibrary:teslashell@0"
            ]
        },
        {
            "x": 4,
            "y": 12,
            "z": 8,
            "elements": [
                "swallowsresourcelibrary:teslacoil@0"
            ]
        },
        {
            "x": -1,
            "y": 6,
            "z": 4,
            "elements": [
                "minecraft:quartz_stairs@4"
            ]
        },
        {
            "x": 3,
            "y": 11,
            "z": 4,
            "elements": [
                "minecraft:stone_slab@15"
            ]
        },
        {
            "x": 5,
            "y": 13,
            "z": 5,
            "elements": [
                "minecraft:stone_slab@7"
            ]
        },
        {
            "x": 4,
            "y": 12,
            "z": 1,
            "elements": [
                "swallowsresourcelibrary:teslashell@0"
            ]
        },
        {
            "x": 5,
            "y": 13,
            "z": 6,
            "elements": [
                "swallowsresourcelibrary:teslashell@0"
            ]
        },
        {
            "x": 4,
            "y": 12,
            "z": 2,
            "elements": [
                "swallowsresourcelibrary:teslashell@0"
            ]
        },
        {
            "x": 5,
            "y": 13,
            "z": 7,
            "elements": [
                "swallowsresourcelibrary:teslashell@0"
            ]
        },
        {
            "x": 4,
            "y": 12,
            "z": -1,
            "elements": [
                "swallowsresourcelibrary:teslashell@0"
            ]
        },
        {
            "x": 4,
            "y": 12,
            "z": 0,
            "elements": [
                "swallowsresourcelibrary:teslacoil@0"
            ]
        },
        {
            "x": 0,
            "y": 7,
            "z": 3,
            "elements": [
                "minecraft:end_rod@1"
            ]
        },
        {
            "x": 3,
            "y": 11,
            "z": -1,
            "elements": [
                "swallowsresourcelibrary:teslashell@0"
            ]
        },
        {
            "x": 4,
            "y": 12,
            "z": 5,
            "elements": [
                "enderio:block_alloy_endergy@3"
            ]
        },
        {
            "x": 0,
            "y": 7,
            "z": 4,
            "elements": [
                "enderio:block_alloy@0"
            ]
        },
        {
            "x": 4,
            "y": 12,
            "z": 6,
            "elements": [
                "swallowsresourcelibrary:teslashell@0"
            ]
        },
        {
            "x": 0,
            "y": 7,
            "z": 5,
            "elements": [
                "minecraft:end_rod@1"
            ]
        },
        {
            "x": 4,
            "y": 12,
            "z": 3,
            "elements": [
                "enderio:block_alloy_endergy@3"
            ]
        },
        {
            "x": 4,
            "y": 12,
            "z": 4,
            "elements": [
                "enderio:block_alloy_endergy@3"
            ]
        },
        {
            "x": 3,
            "y": 11,
            "z": 9,
            "elements": [
                "swallowsresourcelibrary:teslashell@0"
            ]
        },
        {
            "x": -6,
            "y": 13,
            "z": 5,
            "elements": [
                "swallowsresourcelibrary:teslashell@0"
            ]
        },
        {
            "x": -6,
            "y": 13,
            "z": 4,
            "elements": [
                "swallowsresourcelibrary:teslashell@0"
            ]
        },
        {
            "x": 1,
            "y": 9,
            "z": 4,
            "elements": [
                "minecraft:quartz_stairs@1"
            ]
        },
        {
            "x": -6,
            "y": 13,
            "z": 3,
            "elements": [
                "swallowsresourcelibrary:teslashell@0"
            ]
        },
        {
            "x": -6,
            "y": 12,
            "z": 2,
            "elements": [
                "swallowsresourcelibrary:teslashell@0"
            ]
        },
        {
            "x": -6,
            "y": 12,
            "z": 1,
            "elements": [
                "swallowsresourcelibrary:teslashell@0"
            ]
        },
        {
            "x": -6,
            "y": 12,
            "z": 4,
            "elements": [
                "swallowsresourcelibrary:teslacoil@0"
            ]
        },
        {
            "x": -6,
            "y": 12,
            "z": 3,
            "elements": [
                "swallowsresourcelibrary:teslacoil@0"
            ]
        },
        {
            "x": -6,
            "y": 12,
            "z": 6,
            "elements": [
                "swallowsresourcelibrary:teslashell@0"
            ]
        },
        {
            "x": -6,
            "y": 12,
            "z": 5,
            "elements": [
                "swallowsresourcelibrary:teslacoil@0"
            ]
        },
        {
            "x": -6,
            "y": 12,
            "z": 7,
            "elements": [
                "swallowsresourcelibrary:teslashell@0"
            ]
        },
        {
            "x": 4,
            "y": 0,
            "z": 2,
            "elements": [
                "modularmachinery:blockcasing@4",
                "modularmachinery:blockenergyinputhatch@0",
                "modularmachinery:blockenergyinputhatch@1",
                "modularmachinery:blockenergyinputhatch@2",
                "modularmachinery:blockenergyinputhatch@3",
                "modularmachinery:blockenergyinputhatch@4",
                "modularmachinery:blockenergyinputhatch@5",
                "modularmachinery:blockenergyinputhatch@6",
                "modularmachinery:blockenergyinputhatch@7",
                "modularmachinery:blockinputbus@0",
                "modularmachinery:blockinputbus@1",
                "modularmachinery:blockinputbus@2",
                "modularmachinery:blockinputbus@3",
                "modularmachinery:blockinputbus@4",
                "modularmachinery:blockinputbus@5",
                "modularmachinery:blockinputbus@6",
                "modularmachinery:blockmeiteminputbus",
                "modularmachinery:blockoutputbus@0",
                "modularmachinery:blockoutputbus@1",
                "modularmachinery:blockoutputbus@2",
                "modularmachinery:blockoutputbus@3",
                "modularmachinery:blockoutputbus@4",
                "modularmachinery:blockoutputbus@5",
                "modularmachinery:blockoutputbus@6",
                "modularmachinery:blockmeitemoutputbus",
                "modularmachinery:blockfluidinputhatch@0",
                "modularmachinery:blockfluidinputhatch@1",
                "modularmachinery:blockfluidinputhatch@2",
                "modularmachinery:blockfluidinputhatch@3",
                "modularmachinery:blockfluidinputhatch@4",
                "modularmachinery:blockfluidinputhatch@5",
                "modularmachinery:blockfluidinputhatch@6",
                "modularmachinery:blockfluidinputhatch@7",
                "modularmachinery:blockmefluidinputbus",
                "modularmachinery:blockfluidoutputhatch@0",
                "modularmachinery:blockfluidoutputhatch@1",
                "modularmachinery:blockfluidoutputhatch@2",
                "modularmachinery:blockfluidoutputhatch@3",
                "modularmachinery:blockfluidoutputhatch@4",
                "modularmachinery:blockfluidoutputhatch@5",
                "modularmachinery:blockfluidoutputhatch@6",
                "modularmachinery:blockfluidoutputhatch@7",
                "modularmachinery:blockmefluidoutputbus"
            ]
        },
        {
            "x": 5,
            "y": 13,
            "z": 1,
            "elements": [
                "swallowsresourcelibrary:teslashell@0"
            ]
        },
        {
            "x": 5,
            "y": 13,
            "z": 2,
            "elements": [
                "swallowsresourcelibrary:teslashell@0"
            ]
        },
        {
            "x": 5,
            "y": 13,
            "z": 3,
            "elements": [
                "minecraft:stone_slab@7"
            ]
        },
        {
            "x": 5,
            "y": 13,
            "z": 4,
            "elements": [
                "minecraft:stone_slab@7"
            ]
        },
        {
            "x": 2,
            "y": 11,
            "z": -1,
            "elements": [
                "swallowsresourcelibrary:teslashell@0"
            ]
        },
        {
            "x": 1,
            "y": 7,
            "z": 4,
            "elements": [
                "minecraft:end_rod@1"
            ]
        },
        {
            "x": 0,
            "y": 8,
            "z": 3,
            "elements": [
                "minecraft:end_rod@0"
            ]
        },
        {
            "x": 0,
            "y": 8,
            "z": 4,
            "elements": [
                "enderio:block_alloy@0"
            ]
        },
        {
            "x": 0,
            "y": 8,
            "z": 5,
            "elements": [
                "minecraft:end_rod@0"
            ]
        },
        {
            "x": 2,
            "y": 11,
            "z": 4,
            "elements": [
                "minecraft:stone_slab@15"
            ]
        },
        {
            "x": 2,
            "y": 11,
            "z": 9,
            "elements": [
                "swallowsresourcelibrary:teslashell@0"
            ]
        },
        {
            "x": 1,
            "y": 10,
            "z": 4,
            "elements": [
                "minecraft:quartz_stairs@5"
            ]
        },
        {
            "x": -5,
            "y": 12,
            "z": 3,
            "elements": [
                "swallowsresourcelibrary:teslashell@0"
            ]
        },
        {
            "x": -5,
            "y": 12,
            "z": 2,
            "elements": [
                "swallowsresourcelibrary:teslacoil@0"
            ]
        },
        {
            "x": -5,
            "y": 12,
            "z": 1,
            "elements": [
                "swallowsresourcelibrary:teslacoil@0"
            ]
        },
        {
            "x": -5,
            "y": 12,
            "z": 0,
            "elements": [
                "swallowsresourcelibrary:teslashell@0"
            ]
        },
        {
            "x": 4,
            "y": 0,
            "z": 3,
            "elements": [
                "modularmachinery:blockcasing@4",
                "modularmachinery:blockenergyinputhatch@0",
                "modularmachinery:blockenergyinputhatch@1",
                "modularmachinery:blockenergyinputhatch@2",
                "modularmachinery:blockenergyinputhatch@3",
                "modularmachinery:blockenergyinputhatch@4",
                "modularmachinery:blockenergyinputhatch@5",
                "modularmachinery:blockenergyinputhatch@6",
                "modularmachinery:blockenergyinputhatch@7",
                "modularmachinery:blockinputbus@0",
                "modularmachinery:blockinputbus@1",
                "modularmachinery:blockinputbus@2",
                "modularmachinery:blockinputbus@3",
                "modularmachinery:blockinputbus@4",
                "modularmachinery:blockinputbus@5",
                "modularmachinery:blockinputbus@6",
                "modularmachinery:blockmeiteminputbus",
                "modularmachinery:blockoutputbus@0",
                "modularmachinery:blockoutputbus@1",
                "modularmachinery:blockoutputbus@2",
                "modularmachinery:blockoutputbus@3",
                "modularmachinery:blockoutputbus@4",
                "modularmachinery:blockoutputbus@5",
                "modularmachinery:blockoutputbus@6",
                "modularmachinery:blockmeitemoutputbus",
                "modularmachinery:blockfluidinputhatch@0",
                "modularmachinery:blockfluidinputhatch@1",
                "modularmachinery:blockfluidinputhatch@2",
                "modularmachinery:blockfluidinputhatch@3",
                "modularmachinery:blockfluidinputhatch@4",
                "modularmachinery:blockfluidinputhatch@5",
                "modularmachinery:blockfluidinputhatch@6",
                "modularmachinery:blockfluidinputhatch@7",
                "modularmachinery:blockmefluidinputbus",
                "modularmachinery:blockfluidoutputhatch@0",
                "modularmachinery:blockfluidoutputhatch@1",
                "modularmachinery:blockfluidoutputhatch@2",
                "modularmachinery:blockfluidoutputhatch@3",
                "modularmachinery:blockfluidoutputhatch@4",
                "modularmachinery:blockfluidoutputhatch@5",
                "modularmachinery:blockfluidoutputhatch@6",
                "modularmachinery:blockfluidoutputhatch@7",
                "modularmachinery:blockmefluidoutputbus"
            ]
        },
        {
            "x": -5,
            "y": 12,
            "z": 7,
            "elements": [
                "swallowsresourcelibrary:teslacoil@0"
            ]
        },
        {
            "x": -5,
            "y": 12,
            "z": 6,
            "elements": [
                "swallowsresourcelibrary:teslacoil@0"
            ]
        },
        {
            "x": 4,
            "y": 0,
            "z": 4,
            "elements": [
                "modularmachinery:blockcasing@4",
                "modularmachinery:blockenergyinputhatch@0",
                "modularmachinery:blockenergyinputhatch@1",
                "modularmachinery:blockenergyinputhatch@2",
                "modularmachinery:blockenergyinputhatch@3",
                "modularmachinery:blockenergyinputhatch@4",
                "modularmachinery:blockenergyinputhatch@5",
                "modularmachinery:blockenergyinputhatch@6",
                "modularmachinery:blockenergyinputhatch@7",
                "modularmachinery:blockinputbus@0",
                "modularmachinery:blockinputbus@1",
                "modularmachinery:blockinputbus@2",
                "modularmachinery:blockinputbus@3",
                "modularmachinery:blockinputbus@4",
                "modularmachinery:blockinputbus@5",
                "modularmachinery:blockinputbus@6",
                "modularmachinery:blockmeiteminputbus",
                "modularmachinery:blockoutputbus@0",
                "modularmachinery:blockoutputbus@1",
                "modularmachinery:blockoutputbus@2",
                "modularmachinery:blockoutputbus@3",
                "modularmachinery:blockoutputbus@4",
                "modularmachinery:blockoutputbus@5",
                "modularmachinery:blockoutputbus@6",
                "modularmachinery:blockmeitemoutputbus",
                "modularmachinery:blockfluidinputhatch@0",
                "modularmachinery:blockfluidinputhatch@1",
                "modularmachinery:blockfluidinputhatch@2",
                "modularmachinery:blockfluidinputhatch@3",
                "modularmachinery:blockfluidinputhatch@4",
                "modularmachinery:blockfluidinputhatch@5",
                "modularmachinery:blockfluidinputhatch@6",
                "modularmachinery:blockfluidinputhatch@7",
                "modularmachinery:blockmefluidinputbus",
                "modularmachinery:blockfluidoutputhatch@0",
                "modularmachinery:blockfluidoutputhatch@1",
                "modularmachinery:blockfluidoutputhatch@2",
                "modularmachinery:blockfluidoutputhatch@3",
                "modularmachinery:blockfluidoutputhatch@4",
                "modularmachinery:blockfluidoutputhatch@5",
                "modularmachinery:blockfluidoutputhatch@6",
                "modularmachinery:blockfluidoutputhatch@7",
                "modularmachinery:blockmefluidoutputbus"
            ]
        },
        {
            "x": 4,
            "y": 0,
            "z": 5,
            "elements": [
                "modularmachinery:blockcasing@4",
                "modularmachinery:blockenergyinputhatch@0",
                "modularmachinery:blockenergyinputhatch@1",
                "modularmachinery:blockenergyinputhatch@2",
                "modularmachinery:blockenergyinputhatch@3",
                "modularmachinery:blockenergyinputhatch@4",
                "modularmachinery:blockenergyinputhatch@5",
                "modularmachinery:blockenergyinputhatch@6",
                "modularmachinery:blockenergyinputhatch@7",
                "modularmachinery:blockinputbus@0",
                "modularmachinery:blockinputbus@1",
                "modularmachinery:blockinputbus@2",
                "modularmachinery:blockinputbus@3",
                "modularmachinery:blockinputbus@4",
                "modularmachinery:blockinputbus@5",
                "modularmachinery:blockinputbus@6",
                "modularmachinery:blockmeiteminputbus",
                "modularmachinery:blockoutputbus@0",
                "modularmachinery:blockoutputbus@1",
                "modularmachinery:blockoutputbus@2",
                "modularmachinery:blockoutputbus@3",
                "modularmachinery:blockoutputbus@4",
                "modularmachinery:blockoutputbus@5",
                "modularmachinery:blockoutputbus@6",
                "modularmachinery:blockmeitemoutputbus",
                "modularmachinery:blockfluidinputhatch@0",
                "modularmachinery:blockfluidinputhatch@1",
                "modularmachinery:blockfluidinputhatch@2",
                "modularmachinery:blockfluidinputhatch@3",
                "modularmachinery:blockfluidinputhatch@4",
                "modularmachinery:blockfluidinputhatch@5",
                "modularmachinery:blockfluidinputhatch@6",
                "modularmachinery:blockfluidinputhatch@7",
                "modularmachinery:blockmefluidinputbus",
                "modularmachinery:blockfluidoutputhatch@0",
                "modularmachinery:blockfluidoutputhatch@1",
                "modularmachinery:blockfluidoutputhatch@2",
                "modularmachinery:blockfluidoutputhatch@3",
                "modularmachinery:blockfluidoutputhatch@4",
                "modularmachinery:blockfluidoutputhatch@5",
                "modularmachinery:blockfluidoutputhatch@6",
                "modularmachinery:blockfluidoutputhatch@7",
                "modularmachinery:blockmefluidoutputbus"
            ]
        },
        {
            "x": -5,
            "y": 12,
            "z": 5,
            "elements": [
                "swallowsresourcelibrary:teslashell@0"
            ]
        },
        {
            "x": 4,
            "y": 0,
            "z": 6,
            "elements": [
                "modularmachinery:blockcasing@4",
                "modularmachinery:blockenergyinputhatch@0",
                "modularmachinery:blockenergyinputhatch@1",
                "modularmachinery:blockenergyinputhatch@2",
                "modularmachinery:blockenergyinputhatch@3",
                "modularmachinery:blockenergyinputhatch@4",
                "modularmachinery:blockenergyinputhatch@5",
                "modularmachinery:blockenergyinputhatch@6",
                "modularmachinery:blockenergyinputhatch@7",
                "modularmachinery:blockinputbus@0",
                "modularmachinery:blockinputbus@1",
                "modularmachinery:blockinputbus@2",
                "modularmachinery:blockinputbus@3",
                "modularmachinery:blockinputbus@4",
                "modularmachinery:blockinputbus@5",
                "modularmachinery:blockinputbus@6",
                "modularmachinery:blockmeiteminputbus",
                "modularmachinery:blockoutputbus@0",
                "modularmachinery:blockoutputbus@1",
                "modularmachinery:blockoutputbus@2",
                "modularmachinery:blockoutputbus@3",
                "modularmachinery:blockoutputbus@4",
                "modularmachinery:blockoutputbus@5",
                "modularmachinery:blockoutputbus@6",
                "modularmachinery:blockmeitemoutputbus",
                "modularmachinery:blockfluidinputhatch@0",
                "modularmachinery:blockfluidinputhatch@1",
                "modularmachinery:blockfluidinputhatch@2",
                "modularmachinery:blockfluidinputhatch@3",
                "modularmachinery:blockfluidinputhatch@4",
                "modularmachinery:blockfluidinputhatch@5",
                "modularmachinery:blockfluidinputhatch@6",
                "modularmachinery:blockfluidinputhatch@7",
                "modularmachinery:blockmefluidinputbus",
                "modularmachinery:blockfluidoutputhatch@0",
                "modularmachinery:blockfluidoutputhatch@1",
                "modularmachinery:blockfluidoutputhatch@2",
                "modularmachinery:blockfluidoutputhatch@3",
                "modularmachinery:blockfluidoutputhatch@4",
                "modularmachinery:blockfluidoutputhatch@5",
                "modularmachinery:blockfluidoutputhatch@6",
                "modularmachinery:blockfluidoutputhatch@7",
                "modularmachinery:blockmefluidoutputbus"
            ]
        },
        {
            "x": -5,
            "y": 12,
            "z": 4,
            "elements": [
                "swallowsresourcelibrary:teslashell@0"
            ]
        },
        {
            "x": 4,
            "y": 1,
            "z": 3,
            "elements": [
                "minecraft:stone_slab@7"
            ]
        },
        {
            "x": 4,
            "y": 1,
            "z": 5,
            "elements": [
                "minecraft:stone_slab@7"
            ]
        },
        {
            "x": -3,
            "y": 1,
            "z": 5,
            "elements": [
                "minecraft:quartz_stairs@0"
            ]
        },
        {
            "x": -4,
            "y": 1,
            "z": 5,
            "elements": [
                "minecraft:stone_slab@7"
            ]
        },
        {
            "x": -3,
            "y": 1,
            "z": 6,
            "elements": [
                "minecraft:stone_slab@7"
            ]
        },
        {
            "x": 1,
            "y": 6,
            "z": 4,
            "elements": [
                "minecraft:quartz_stairs@5"
            ]
        },
        {
            "x": -4,
            "y": 1,
            "z": 3,
            "elements": [
                "minecraft:stone_slab@7"
            ]
        },
        {
            "x": -3,
            "y": 1,
            "z": 2,
            "elements": [
                "minecraft:stone_slab@7"
            ]
        },
        {
            "x": -3,
            "y": 1,
            "z": 3,
            "elements": [
                "minecraft:quartz_stairs@0"
            ]
        },
        {
            "x": -3,
            "y": 1,
            "z": 4,
            "elements": [
                "minecraft:stone_slab@7"
            ]
        },
        {
            "x": -5,
            "y": 12,
            "z": 8,
            "elements": [
                "swallowsresourcelibrary:teslashell@0"
            ]
        },
        {
            "x": 2,
            "y": 12,
            "z": 8,
            "elements": [
                "swallowsresourcelibrary:teslashell@0"
            ]
        },
        {
            "x": 2,
            "y": 12,
            "z": 5,
            "elements": [
                "minecraft:end_rod@5"
            ]
        },
        {
            "x": 2,
            "y": 12,
            "z": 4,
            "elements": [
                "enderio:block_alloy_endergy@3"
            ]
        },
        {
            "x": 2,
            "y": 12,
            "z": 3,
            "elements": [
                "minecraft:end_rod@5"
            ]
        },
        {
            "x": 2,
            "y": 12,
            "z": 0,
            "elements": [
                "swallowsresourcelibrary:teslashell@0"
            ]
        },
        {
            "x": 2,
            "y": 12,
            "z": -1,
            "elements": [
                "swallowsresourcelibrary:teslacoil@0"
            ]
        },
        {
            "x": 2,
            "y": 12,
            "z": -2,
            "elements": [
                "swallowsresourcelibrary:teslashell@0"
            ]
        },
        {
            "x": 5,
            "y": 12,
            "z": 6,
            "elements": [
                "swallowsresourcelibrary:teslacoil@0"
            ]
        },
        {
            "x": 5,
            "y": 12,
            "z": 7,
            "elements": [
                "swallowsresourcelibrary:teslacoil@0"
            ]
        },
        {
            "x": 5,
            "y": 12,
            "z": 8,
            "elements": [
                "swallowsresourcelibrary:teslashell@0"
            ]
        },
        {
            "x": 5,
            "y": 12,
            "z": 2,
            "elements": [
                "swallowsresourcelibrary:teslacoil@0"
            ]
        },
        {
            "x": 5,
            "y": 12,
            "z": 3,
            "elements": [
                "swallowsresourcelibrary:teslashell@0"
            ]
        },
        {
            "x": 5,
            "y": 12,
            "z": 4,
            "elements": [
                "swallowsresourcelibrary:teslashell@0"
            ]
        },
        {
            "x": 5,
            "y": 12,
            "z": 5,
            "elements": [
                "swallowsresourcelibrary:teslashell@0"
            ]
        },
        {
            "x": 0,
            "y": 4,
            "z": 4,
            "elements": [
                "enderio:block_alloy@0"
            ]
        },
        {
            "x": 0,
            "y": 4,
            "z": 3,
            "elements": [
                "minecraft:end_rod@0"
            ]
        },
        {
            "x": 5,
            "y": 12,
            "z": 0,
            "elements": [
                "swallowsresourcelibrary:teslashell@0"
            ]
        },
        {
            "x": -1,
            "y": 8,
            "z": 4,
            "elements": [
                "minecraft:end_rod@0"
            ]
        },
        {
            "x": 5,
            "y": 12,
            "z": 1,
            "elements": [
                "swallowsresourcelibrary:teslacoil@0"
            ]
        },
        {
            "x": 0,
            "y": 4,
            "z": 5,
            "elements": [
                "minecraft:end_rod@0"
            ]
        },
        {
            "x": 4,
            "y": 13,
            "z": 8,
            "elements": [
                "swallowsresourcelibrary:teslashell@0"
            ]
        },
        {
            "x": 4,
            "y": 13,
            "z": 4,
            "elements": [
                "minecraft:stone_slab@7"
            ]
        },
        {
            "x": 4,
            "y": 13,
            "z": 5,
            "elements": [
                "minecraft:stone_slab@7"
            ]
        },
        {
            "x": 4,
            "y": 13,
            "z": 3,
            "elements": [
                "minecraft:stone_slab@7"
            ]
        },
        {
            "x": 4,
            "y": 13,
            "z": 0,
            "elements": [
                "swallowsresourcelibrary:teslashell@0"
            ]
        },
        {
            "x": -1,
            "y": 5,
            "z": 4,
            "elements": [
                "minecraft:quartz_stairs@0"
            ]
        },
        {
            "x": 0,
            "y": 17,
            "z": 4,
            "elements": [
                "ic2:fence@0"
            ]
        },
        {
            "x": -3,
            "y": 0,
            "z": 2,

            "elements": [
                "modularmachinery:blockcasing@4"
            ]
        },
        {
            "x": -3,
            "y": 0,
            "z": 3,

            "elements": [
                "modularmachinery:blockcasing@4"
            ]
        },
        {
            "x": -3,
            "y": 0,
            "z": 4,

            "elements": [
                "modularmachinery:blockcasing@4"
            ]
        },
        {
            "x": -3,
            "y": 0,
            "z": 5,

            "elements": [
                "modularmachinery:blockcasing@4"
            ]
        },
        {
            "x": -3,
            "y": 0,
            "z": 6,

            "elements": [
                "modularmachinery:blockcasing@4"
            ]
        },
        {
            "x": -3,
            "y": 0,
            "z": 7,
            "elements": [
                "modularmachinery:blockcasing@4",
                "modularmachinery:blockenergyinputhatch@0",
                "modularmachinery:blockenergyinputhatch@1",
                "modularmachinery:blockenergyinputhatch@2",
                "modularmachinery:blockenergyinputhatch@3",
                "modularmachinery:blockenergyinputhatch@4",
                "modularmachinery:blockenergyinputhatch@5",
                "modularmachinery:blockenergyinputhatch@6",
                "modularmachinery:blockenergyinputhatch@7",
                "modularmachinery:blockinputbus@0",
                "modularmachinery:blockinputbus@1",
                "modularmachinery:blockinputbus@2",
                "modularmachinery:blockinputbus@3",
                "modularmachinery:blockinputbus@4",
                "modularmachinery:blockinputbus@5",
                "modularmachinery:blockinputbus@6",
                "modularmachinery:blockmeiteminputbus",
                "modularmachinery:blockoutputbus@0",
                "modularmachinery:blockoutputbus@1",
                "modularmachinery:blockoutputbus@2",
                "modularmachinery:blockoutputbus@3",
                "modularmachinery:blockoutputbus@4",
                "modularmachinery:blockoutputbus@5",
                "modularmachinery:blockoutputbus@6",
                "modularmachinery:blockmeitemoutputbus",
                "modularmachinery:blockfluidinputhatch@0",
                "modularmachinery:blockfluidinputhatch@1",
                "modularmachinery:blockfluidinputhatch@2",
                "modularmachinery:blockfluidinputhatch@3",
                "modularmachinery:blockfluidinputhatch@4",
                "modularmachinery:blockfluidinputhatch@5",
                "modularmachinery:blockfluidinputhatch@6",
                "modularmachinery:blockfluidinputhatch@7",
                "modularmachinery:blockmefluidinputbus",
                "modularmachinery:blockfluidoutputhatch@0",
                "modularmachinery:blockfluidoutputhatch@1",
                "modularmachinery:blockfluidoutputhatch@2",
                "modularmachinery:blockfluidoutputhatch@3",
                "modularmachinery:blockfluidoutputhatch@4",
                "modularmachinery:blockfluidoutputhatch@5",
                "modularmachinery:blockfluidoutputhatch@6",
                "modularmachinery:blockfluidoutputhatch@7",
                "modularmachinery:blockmefluidoutputbus"
            ]
        },
        {
            "x": 3,
            "y": 1,
            "z": 2,
            "elements": [
                "minecraft:stone_slab@7"
            ]
        },
        {
            "x": -1,
            "y": 9,
            "z": 4,
            "elements": [
                "minecraft:quartz_stairs@0"
            ]
        },
        {
            "x": -2,
            "y": 1,
            "z": 6,
            "elements": [
                "extendedcrafting:lamp@1"
            ]
        },
        {
            "x": -2,
            "y": 1,
            "z": 7,
            "elements": [
                "minecraft:stone_slab@7"
            ]
        },
        {
            "x": -2,
            "y": 1,
            "z": 4,
            "elements": [
                "minecraft:quartz_block@0"
            ]
        },
        {
            "x": -2,
            "y": 1,
            "z": 5,
            "elements": [
                "minecraft:stone_slab@7"
            ]
        },
        {
            "x": -2,
            "y": 1,
            "z": 2,
            "elements": [
                "extendedcrafting:lamp@1"
            ]
        },
        {
            "x": -2,
            "y": 1,
            "z": 3,
            "elements": [
                "minecraft:stone_slab@7"
            ]
        },
        {
            "x": -2,
            "y": 1,
            "z": 1,
            "elements": [
                "minecraft:stone_slab@7"
            ]
        },
        {
            "x": -3,
            "y": 0,
            "z": 1,
            "elements": [
                "modularmachinery:blockcasing@4",
                "modularmachinery:blockenergyinputhatch@0",
                "modularmachinery:blockenergyinputhatch@1",
                "modularmachinery:blockenergyinputhatch@2",
                "modularmachinery:blockenergyinputhatch@3",
                "modularmachinery:blockenergyinputhatch@4",
                "modularmachinery:blockenergyinputhatch@5",
                "modularmachinery:blockenergyinputhatch@6",
                "modularmachinery:blockenergyinputhatch@7",
                "modularmachinery:blockinputbus@0",
                "modularmachinery:blockinputbus@1",
                "modularmachinery:blockinputbus@2",
                "modularmachinery:blockinputbus@3",
                "modularmachinery:blockinputbus@4",
                "modularmachinery:blockinputbus@5",
                "modularmachinery:blockinputbus@6",
                "modularmachinery:blockmeiteminputbus",
                "modularmachinery:blockoutputbus@0",
                "modularmachinery:blockoutputbus@1",
                "modularmachinery:blockoutputbus@2",
                "modularmachinery:blockoutputbus@3",
                "modularmachinery:blockoutputbus@4",
                "modularmachinery:blockoutputbus@5",
                "modularmachinery:blockoutputbus@6",
                "modularmachinery:blockmeitemoutputbus",
                "modularmachinery:blockfluidinputhatch@0",
                "modularmachinery:blockfluidinputhatch@1",
                "modularmachinery:blockfluidinputhatch@2",
                "modularmachinery:blockfluidinputhatch@3",
                "modularmachinery:blockfluidinputhatch@4",
                "modularmachinery:blockfluidinputhatch@5",
                "modularmachinery:blockfluidinputhatch@6",
                "modularmachinery:blockfluidinputhatch@7",
                "modularmachinery:blockmefluidinputbus",
                "modularmachinery:blockfluidoutputhatch@0",
                "modularmachinery:blockfluidoutputhatch@1",
                "modularmachinery:blockfluidoutputhatch@2",
                "modularmachinery:blockfluidoutputhatch@3",
                "modularmachinery:blockfluidoutputhatch@4",
                "modularmachinery:blockfluidoutputhatch@5",
                "modularmachinery:blockfluidoutputhatch@6",
                "modularmachinery:blockfluidoutputhatch@7",
                "modularmachinery:blockmefluidoutputbus"
            ]
        },
        {
            "x": -1,
            "y": 3,
            "z": 4,
            "elements": [
                "minecraft:end_rod@1"
            ]
        },
        {
            "x": 3,
            "y": 1,
            "z": 5,
            "elements": [
                "minecraft:quartz_stairs@1"
            ]
        },
        {
            "x": 3,
            "y": 1,
            "z": 6,
            "elements": [
                "minecraft:stone_slab@7"
            ]
        },
        {
            "x": 3,
            "y": 1,
            "z": 3,
            "elements": [
                "minecraft:quartz_stairs@1"
            ]
        },
        {
            "x": 3,
            "y": 1,
            "z": 4,
            "elements": [
                "minecraft:stone_slab@7"
            ]
        },
        {
            "x": 6,
            "y": 12,
            "z": 6,
            "elements": [
                "swallowsresourcelibrary:teslashell@0"
            ]
        },
        {
            "x": 6,
            "y": 12,
            "z": 5,
            "elements": [
                "swallowsresourcelibrary:teslacoil@0"
            ]
        },
        {
            "x": 6,
            "y": 12,
            "z": 7,
            "elements": [
                "swallowsresourcelibrary:teslashell@0"
            ]
        },
        {
            "x": 0,
            "y": 11,
            "z": 10,
            "elements": [
                "swallowsresourcelibrary:teslashell@0"
            ]
        },
        {
            "x": 0,
            "y": 11,
            "z": 9,
            "elements": [
                "minecraft:stone_slab@15"
            ]
        },
        {
            "x": 5,
            "y": 11,
            "z": 1,
            "elements": [
                "swallowsresourcelibrary:teslashell@0"
            ]
        },
        {
            "x": 0,
            "y": 11,
            "z": 8,
            "elements": [
                "minecraft:stone_slab@15"
            ]
        },
        {
            "x": 5,
            "y": 11,
            "z": 2,
            "elements": [
                "swallowsresourcelibrary:teslashell@0"
            ]
        },
        {
            "x": 0,
            "y": 11,
            "z": 7,
            "elements": [
                "minecraft:stone_slab@15"
            ]
        },
        {
            "x": 5,
            "y": 11,
            "z": 3,
            "elements": [
                "minecraft:stone_slab@15"
            ]
        },
        {
            "x": 0,
            "y": 11,
            "z": 6,
            "elements": [
                "minecraft:stone_slab@15"
            ]
        },
        {
            "x": 5,
            "y": 11,
            "z": 4,
            "elements": [
                "minecraft:stone_slab@15"
            ]
        },
        {
            "x": -1,
            "y": 15,
            "z": 4,
            "elements": [
                "minecraft:end_rod@1"
            ]
        },
        {
            "x": 5,
            "y": 11,
            "z": 5,
            "elements": [
                "minecraft:stone_slab@15"
            ]
        },
        {
            "x": 0,
            "y": 11,
            "z": 5,
            "elements": [
                "minecraft:quartz_stairs@6"
            ]
        },
        {
            "x": 5,
            "y": 11,
            "z": 6,
            "elements": [
                "swallowsresourcelibrary:teslashell@0"
            ]
        },
        {
            "x": 0,
            "y": 11,
            "z": 4,
            "elements": [
                "enderio:block_alloy@0"
            ]
        },
        {
            "x": 5,
            "y": 11,
            "z": 7,
            "elements": [
                "swallowsresourcelibrary:teslashell@0"
            ]
        },
        {
            "x": 0,
            "y": 11,
            "z": 3,
            "elements": [
                "minecraft:quartz_stairs@7"
            ]
        },
        {
            "x": 0,
            "y": 11,
            "z": 2,
            "elements": [
                "minecraft:stone_slab@15"
            ]
        },
        {
            "x": 0,
            "y": 11,
            "z": 1,
            "elements": [
                "minecraft:stone_slab@15"
            ]
        },
        {
            "x": 0,
            "y": 11,
            "z": 0,
            "elements": [
                "minecraft:stone_slab@15"
            ]
        },
        {
            "x": 0,
            "y": 11,
            "z": -1,
            "elements": [
                "minecraft:stone_slab@15"
            ]
        },
        {
            "x": 0,
            "y": 11,
            "z": -2,
            "elements": [
                "swallowsresourcelibrary:teslashell@0"
            ]
        },
        {
            "x": -3,
            "y": 12,
            "z": 10,
            "elements": [
                "swallowsresourcelibrary:teslashell@0"
            ]
        },
        {
            "x": -3,
            "y": 12,
            "z": 8,
            "elements": [
                "swallowsresourcelibrary:teslashell@0"
            ]
        },
        {
            "x": -3,
            "y": 12,
            "z": 9,
            "elements": [
                "swallowsresourcelibrary:teslacoil@0"
            ]
        },
        {
            "x": 0,
            "y": 5,
            "z": 3,
            "elements": [
                "minecraft:quartz_stairs@2"
            ]
        },
        {
            "x": 0,
            "y": 5,
            "z": 4,
            "elements": [
                "enderio:block_alloy@0"
            ]
        },
        {
            "x": 0,
            "y": 5,
            "z": 5,
            "elements": [
                "minecraft:quartz_stairs@3"
            ]
        },
        {
            "x": 3,
            "y": 13,
            "z": 4,
            "elements": [
                "minecraft:stone_slab@7"
            ]
        },
        {
            "x": 3,
            "y": 13,
            "z": -1,
            "elements": [
                "swallowsresourcelibrary:teslashell@0"
            ]
        },
        {
            "x": 3,
            "y": 13,
            "z": 9,
            "elements": [
                "swallowsresourcelibrary:teslashell@0"
            ]
        },
        {
            "x": 6,
            "y": 12,
            "z": 2,
            "elements": [
                "swallowsresourcelibrary:teslashell@0"
            ]
        },
        {
            "x": 6,
            "y": 12,
            "z": 1,
            "elements": [
                "swallowsresourcelibrary:teslashell@0"
            ]
        },
        {
            "x": -2,
            "y": 2,
            "z": 2,
            "elements": [
                "minecraft:stone_slab@7"
            ]
        },
        {
            "x": 6,
            "y": 12,
            "z": 4,
            "elements": [
                "swallowsresourcelibrary:teslacoil@0"
            ]
        },
        {
            "x": 6,
            "y": 12,
            "z": 3,
            "elements": [
                "swallowsresourcelibrary:teslacoil@0"
            ]
        },
        {
            "x": -2,
            "y": 2,
            "z": 4,
            "elements": [
                "minecraft:quartz_stairs@0"
            ]
        },
        {
            "x": -2,
            "y": 2,
            "z": 6,
            "elements": [
                "minecraft:stone_slab@7"
            ]
        },
        {
            "x": 0,
            "y": 12,
            "z": 6,
            "elements": [
                "enderio:block_alloy_endergy@3"
            ]
        },
        {
            "x": 0,
            "y": 12,
            "z": 5,
            "elements": [
                "enderio:block_alloy_endergy@3"
            ]
        },
        {
            "x": 0,
            "y": 12,
            "z": 4,
            "elements": [
                "enderio:block_alloy_endergy@3"
            ]
        },
        {
            "x": 0,
            "y": 12,
            "z": 3,
            "elements": [
                "enderio:block_alloy_endergy@3"
            ]
        },
        {
            "x": 0,
            "y": 12,
            "z": 10,
            "elements": [
                "swallowsresourcelibrary:teslacoil@0"
            ]
        },
        {
            "x": 0,
            "y": 12,
            "z": 9,
            "elements": [
                "swallowsresourcelibrary:teslashell@0"
            ]
        },
        {
            "x": 0,
            "y": 12,
            "z": 8,
            "elements": [
                "enderio:block_alloy_endergy@3"
            ]
        },
        {
            "x": 6,
            "y": 13,
            "z": 3,
            "elements": [
                "swallowsresourcelibrary:teslashell@0"
            ]
        },
        {
            "x": 0,
            "y": 12,
            "z": 7,
            "elements": [
                "enderio:block_alloy_endergy@3"
            ]
        },
        {
            "x": 0,
            "y": 12,
            "z": -2,
            "elements": [
                "swallowsresourcelibrary:teslacoil@0"
            ]
        },
        {
            "x": 6,
            "y": 13,
            "z": 5,
            "elements": [
                "swallowsresourcelibrary:teslashell@0"
            ]
        },
        {
            "x": 0,
            "y": 12,
            "z": -3,
            "elements": [
                "swallowsresourcelibrary:teslashell@0"
            ]
        },
        {
            "x": 6,
            "y": 13,
            "z": 4,
            "elements": [
                "swallowsresourcelibrary:teslashell@0"
            ]
        },
        {
            "x": 0,
            "y": 12,
            "z": 2,
            "elements": [
                "enderio:block_alloy_endergy@3"
            ]
        },
        {
            "x": 0,
            "y": 12,
            "z": 1,
            "elements": [
                "enderio:block_alloy_endergy@3"
            ]
        },
        {
            "x": 0,
            "y": 12,
            "z": 0,
            "elements": [
                "enderio:block_alloy_endergy@3"
            ]
        },
        {
            "x": -2,
            "y": 13,
            "z": -1,
            "elements": [
                "swallowsresourcelibrary:teslashell@0"
            ]
        },
        {
            "x": 0,
            "y": 12,
            "z": -1,
            "elements": [
                "swallowsresourcelibrary:teslashell@0"
            ]
        },
        {
            "x": -2,
            "y": 13,
            "z": 9,
            "elements": [
                "swallowsresourcelibrary:teslashell@0"
            ]
        },
        {
            "x": -2,
            "y": 13,
            "z": 4,
            "elements": [
                "minecraft:stone_slab@7"
            ]
        },
        {
            "x": -1,
            "y": 4,
            "z": 4,
            "elements": [
                "minecraft:end_rod@0"
            ]
        },
        {
            "x": 0,
            "y": 12,
            "z": 11,
            "elements": [
                "swallowsresourcelibrary:teslashell@0"
            ]
        },
        {
            "x": 3,
            "y": 12,
            "z": 8,
            "elements": [
                "swallowsresourcelibrary:teslashell@0"
            ]
        },
        {
            "x": -3,
            "y": 12,
            "z": 4,
            "elements": [
                "enderio:block_alloy_endergy@3"
            ]
        },
        {
            "x": -3,
            "y": 12,
            "z": 5,
            "elements": [
                "minecraft:end_rod@5"
            ]
        },
        {
            "x": 3,
            "y": 12,
            "z": 9,
            "elements": [
                "swallowsresourcelibrary:teslacoil@0"
            ]
        },
        {
            "x": 3,
            "y": 12,
            "z": 10,
            "elements": [
                "swallowsresourcelibrary:teslashell@0"
            ]
        },
        {
            "x": -3,
            "y": 12,
            "z": 3,
            "elements": [
                "minecraft:end_rod@5"
            ]
        },
        {
            "x": -3,
            "y": 12,
            "z": 0,
            "elements": [
                "swallowsresourcelibrary:teslashell@0"
            ]
        },
        {
            "x": -3,
            "y": 12,
            "z": -2,
            "elements": [
                "swallowsresourcelibrary:teslashell@0"
            ]
        },
        {
            "x": -3,
            "y": 12,
            "z": -1,
            "elements": [
                "swallowsresourcelibrary:teslacoil@0"
            ]
        },
        {
            "x": 3,
            "y": 12,
            "z": 0,
            "elements": [
                "swallowsresourcelibrary:teslashell@0"
            ]
        },
        {
            "x": 3,
            "y": 12,
            "z": 3,
            "elements": [
                "minecraft:end_rod@4"
            ]
        },
        {
            "x": 3,
            "y": 12,
            "z": 4,
            "elements": [
                "enderio:block_alloy_endergy@3"
            ]
        },
        {
            "x": 3,
            "y": 12,
            "z": 5,
            "elements": [
                "minecraft:end_rod@4"
            ]
        },
        {
            "x": 0,
            "y": 6,
            "z": 5,
            "elements": [
                "minecraft:quartz_stairs@7"
            ]
        },
        {
            "x": -3,
            "y": 11,
            "z": -1,
            "elements": [
                "swallowsresourcelibrary:teslashell@0"
            ]
        },
        {
            "x": 3,
            "y": 12,
            "z": -2,
            "elements": [
                "swallowsresourcelibrary:teslashell@0"
            ]
        },
        {
            "x": 0,
            "y": 6,
            "z": 3,
            "elements": [
                "minecraft:quartz_stairs@6"
            ]
        },
        {
            "x": -3,
            "y": 11,
            "z": 4,
            "elements": [
                "minecraft:stone_slab@15"
            ]
        },
        {
            "x": 3,
            "y": 12,
            "z": -1,
            "elements": [
                "swallowsresourcelibrary:teslacoil@0"
            ]
        },
        {
            "x": 0,
            "y": 6,
            "z": 4,
            "elements": [
                "enderio:block_alloy@0"
            ]
        },
        {
            "x": -3,
            "y": 11,
            "z": 9,
            "elements": [
                "swallowsresourcelibrary:teslashell@0"
            ]
        },
        {
            "x": 3,
            "y": 0,
            "z": 6,

            "elements": [
                "modularmachinery:blockcasing@4"
            ]
        },
        {
            "x": 3,
            "y": 0,
            "z": 7,
            "elements": [
                "modularmachinery:blockcasing@4",
                "modularmachinery:blockenergyinputhatch@0",
                "modularmachinery:blockenergyinputhatch@1",
                "modularmachinery:blockenergyinputhatch@2",
                "modularmachinery:blockenergyinputhatch@3",
                "modularmachinery:blockenergyinputhatch@4",
                "modularmachinery:blockenergyinputhatch@5",
                "modularmachinery:blockenergyinputhatch@6",
                "modularmachinery:blockenergyinputhatch@7",
                "modularmachinery:blockinputbus@0",
                "modularmachinery:blockinputbus@1",
                "modularmachinery:blockinputbus@2",
                "modularmachinery:blockinputbus@3",
                "modularmachinery:blockinputbus@4",
                "modularmachinery:blockinputbus@5",
                "modularmachinery:blockinputbus@6",
                "modularmachinery:blockmeiteminputbus",
                "modularmachinery:blockoutputbus@0",
                "modularmachinery:blockoutputbus@1",
                "modularmachinery:blockoutputbus@2",
                "modularmachinery:blockoutputbus@3",
                "modularmachinery:blockoutputbus@4",
                "modularmachinery:blockoutputbus@5",
                "modularmachinery:blockoutputbus@6",
                "modularmachinery:blockmeitemoutputbus",
                "modularmachinery:blockfluidinputhatch@0",
                "modularmachinery:blockfluidinputhatch@1",
                "modularmachinery:blockfluidinputhatch@2",
                "modularmachinery:blockfluidinputhatch@3",
                "modularmachinery:blockfluidinputhatch@4",
                "modularmachinery:blockfluidinputhatch@5",
                "modularmachinery:blockfluidinputhatch@6",
                "modularmachinery:blockfluidinputhatch@7",
                "modularmachinery:blockmefluidinputbus",
                "modularmachinery:blockfluidoutputhatch@0",
                "modularmachinery:blockfluidoutputhatch@1",
                "modularmachinery:blockfluidoutputhatch@2",
                "modularmachinery:blockfluidoutputhatch@3",
                "modularmachinery:blockfluidoutputhatch@4",
                "modularmachinery:blockfluidoutputhatch@5",
                "modularmachinery:blockfluidoutputhatch@6",
                "modularmachinery:blockfluidoutputhatch@7",
                "modularmachinery:blockmefluidoutputbus"
            ]
        },
        {
            "x": 3,
            "y": 0,
            "z": 4,

            "elements": [
                "modularmachinery:blockcasing@4"
            ]
        },
        {
            "x": 3,
            "y": 0,
            "z": 5,

            "elements": [
                "modularmachinery:blockcasing@4"
            ]
        },
        {
            "x": -1,
            "y": 10,
            "z": 4,
            "elements": [
                "minecraft:quartz_stairs@4"
            ]
        },
        {
            "x": 1,
            "y": 14,
            "z": 4,
            "elements": [
                "ic2:fence@0"
            ]
        },
        {
            "x": 3,
            "y": 0,
            "z": 2,

            "elements": [
                "modularmachinery:blockcasing@4"
            ]
        },
        {
            "x": 3,
            "y": 0,
            "z": 3,

            "elements": [
                "modularmachinery:blockcasing@4"
            ]
        },
        {
            "x": 0,
            "y": 18,
            "z": 4,
            "elements": [
                "minecraft:end_rod@1"
            ]
        },
        {
            "x": 3,
            "y": 0,
            "z": 1,
            "elements": [
                "modularmachinery:blockcasing@4",
                "modularmachinery:blockenergyinputhatch@0",
                "modularmachinery:blockenergyinputhatch@1",
                "modularmachinery:blockenergyinputhatch@2",
                "modularmachinery:blockenergyinputhatch@3",
                "modularmachinery:blockenergyinputhatch@4",
                "modularmachinery:blockenergyinputhatch@5",
                "modularmachinery:blockenergyinputhatch@6",
                "modularmachinery:blockenergyinputhatch@7",
                "modularmachinery:blockinputbus@0",
                "modularmachinery:blockinputbus@1",
                "modularmachinery:blockinputbus@2",
                "modularmachinery:blockinputbus@3",
                "modularmachinery:blockinputbus@4",
                "modularmachinery:blockinputbus@5",
                "modularmachinery:blockinputbus@6",
                "modularmachinery:blockmeiteminputbus",
                "modularmachinery:blockoutputbus@0",
                "modularmachinery:blockoutputbus@1",
                "modularmachinery:blockoutputbus@2",
                "modularmachinery:blockoutputbus@3",
                "modularmachinery:blockoutputbus@4",
                "modularmachinery:blockoutputbus@5",
                "modularmachinery:blockoutputbus@6",
                "modularmachinery:blockmeitemoutputbus",
                "modularmachinery:blockfluidinputhatch@0",
                "modularmachinery:blockfluidinputhatch@1",
                "modularmachinery:blockfluidinputhatch@2",
                "modularmachinery:blockfluidinputhatch@3",
                "modularmachinery:blockfluidinputhatch@4",
                "modularmachinery:blockfluidinputhatch@5",
                "modularmachinery:blockfluidinputhatch@6",
                "modularmachinery:blockfluidinputhatch@7",
                "modularmachinery:blockmefluidinputbus",
                "modularmachinery:blockfluidoutputhatch@0",
                "modularmachinery:blockfluidoutputhatch@1",
                "modularmachinery:blockfluidoutputhatch@2",
                "modularmachinery:blockfluidoutputhatch@3",
                "modularmachinery:blockfluidoutputhatch@4",
                "modularmachinery:blockfluidoutputhatch@5",
                "modularmachinery:blockfluidoutputhatch@6",
                "modularmachinery:blockfluidoutputhatch@7",
                "modularmachinery:blockmefluidoutputbus"
            ]
        },
        {
            "x": -5,
            "y": 13,
            "z": 6,
            "elements": [
                "swallowsresourcelibrary:teslashell@0"
            ]
        },
        {
            "x": -5,
            "y": 13,
            "z": 5,
            "elements": [
                "minecraft:stone_slab@7"
            ]
        },
        {
            "x": -5,
            "y": 13,
            "z": 4,
            "elements": [
                "minecraft:stone_slab@7"
            ]
        },
        {
            "x": -5,
            "y": 13,
            "z": 3,
            "elements": [
                "minecraft:stone_slab@7"
            ]
        },
        {
            "x": -5,
            "y": 13,
            "z": 2,
            "elements": [
                "swallowsresourcelibrary:teslashell@0"
            ]
        },
        {
            "x": -5,
            "y": 13,
            "z": 1,
            "elements": [
                "swallowsresourcelibrary:teslashell@0"
            ]
        },
        {
            "x": -5,
            "y": 13,
            "z": 7,
            "elements": [
                "swallowsresourcelibrary:teslashell@0"
            ]
        },
        {
            "x": 1,
            "y": 8,
            "z": 4,
            "elements": [
                "minecraft:end_rod@0"
            ]
        },
        {
            "x": -6,
            "y": 11,
            "z": 3,
            "elements": [
                "swallowsresourcelibrary:teslashell@0"
            ]
        },
        {
            "x": -6,
            "y": 11,
            "z": 5,
            "elements": [
                "swallowsresourcelibrary:teslashell@0"
            ]
        },
        {
            "x": -6,
            "y": 11,
            "z": 4,
            "elements": [
                "swallowsresourcelibrary:teslashell@0"
            ]
        },
        {
            "x": 1,
            "y": 15,
            "z": 4,
            "elements": [
                "minecraft:end_rod@1"
            ]
        },
        {
            "x": -2,
            "y": 11,
            "z": 9,
            "elements": [
                "swallowsresourcelibrary:teslashell@0"
            ]
        },
        {
            "x": 0,
            "y": 14,
            "z": 4,
            "elements": [
                "enderio:block_alloy@0"
            ]
        },
        {
            "x": 0,
            "y": 14,
            "z": 3,
            "elements": [
                "ic2:fence@0"
            ]
        },
        {
            "x": 0,
            "y": 0,
            "z": 8,
            "elements": [
                "modularmachinery:blockcasing@4",
                "modularmachinery:blockenergyinputhatch@0",
                "modularmachinery:blockenergyinputhatch@1",
                "modularmachinery:blockenergyinputhatch@2",
                "modularmachinery:blockenergyinputhatch@3",
                "modularmachinery:blockenergyinputhatch@4",
                "modularmachinery:blockenergyinputhatch@5",
                "modularmachinery:blockenergyinputhatch@6",
                "modularmachinery:blockenergyinputhatch@7",
                "modularmachinery:blockinputbus@0",
                "modularmachinery:blockinputbus@1",
                "modularmachinery:blockinputbus@2",
                "modularmachinery:blockinputbus@3",
                "modularmachinery:blockinputbus@4",
                "modularmachinery:blockinputbus@5",
                "modularmachinery:blockinputbus@6",
                "modularmachinery:blockmeiteminputbus",
                "modularmachinery:blockoutputbus@0",
                "modularmachinery:blockoutputbus@1",
                "modularmachinery:blockoutputbus@2",
                "modularmachinery:blockoutputbus@3",
                "modularmachinery:blockoutputbus@4",
                "modularmachinery:blockoutputbus@5",
                "modularmachinery:blockoutputbus@6",
                "modularmachinery:blockmeitemoutputbus",
                "modularmachinery:blockfluidinputhatch@0",
                "modularmachinery:blockfluidinputhatch@1",
                "modularmachinery:blockfluidinputhatch@2",
                "modularmachinery:blockfluidinputhatch@3",
                "modularmachinery:blockfluidinputhatch@4",
                "modularmachinery:blockfluidinputhatch@5",
                "modularmachinery:blockfluidinputhatch@6",
                "modularmachinery:blockfluidinputhatch@7",
                "modularmachinery:blockmefluidinputbus",
                "modularmachinery:blockfluidoutputhatch@0",
                "modularmachinery:blockfluidoutputhatch@1",
                "modularmachinery:blockfluidoutputhatch@2",
                "modularmachinery:blockfluidoutputhatch@3",
                "modularmachinery:blockfluidoutputhatch@4",
                "modularmachinery:blockfluidoutputhatch@5",
                "modularmachinery:blockfluidoutputhatch@6",
                "modularmachinery:blockfluidoutputhatch@7",
                "modularmachinery:blockmefluidoutputbus"
            ]
        },
        {
            "x": 0,
            "y": 0,
            "z": 7,

            "elements": [
                "modularmachinery:blockcasing@4"
            ]
        },
        {
            "x": 0,
            "y": 14,
            "z": 5,
            "elements": [
                "ic2:fence@0"
            ]
        },
        {
            "x": 0,
            "y": 0,
            "z": 4,

            "elements": [
                "modularmachinery:blockcasing@4"
            ]
        },
        {
            "x": 0,
            "y": 0,
            "z": 3,

            "elements": [
                "modularmachinery:blockcasing@4"
            ]
        },
        {
            "x": 0,
            "y": 0,
            "z": 6,

            "elements": [
                "modularmachinery:blockcasing@4"
            ]
        },
        {
            "x": 0,
            "y": 0,
            "z": 5,

            "elements": [
                "modularmachinery:blockcasing@4"
            ]
        },
        {
            "x": 0,
            "y": 0,
            "z": 0,

            "elements": [
                "modularmachinery:blockcontroller@2"
            ]
        },
        {
            "x": 0,
            "y": 0,
            "z": 2,

            "elements": [
                "modularmachinery:blockcasing@4"
            ]
        },
        {
            "x": 1,
            "y": 2,
            "z": 4,
            "elements": [
                "minecraft:quartz_stairs@5"
            ]
        },
        {
            "x": 0,
            "y": 0,
            "z": 1,

            "elements": [
                "modularmachinery:blockcasing@4"
            ]
        },
        {
            "x": 0,
            "y": 13,
            "z": 9,
            "elements": [
                "minecraft:stone_slab@7"
            ]
        },
        {
            "x": 0,
            "y": 13,
            "z": 8,
            "elements": [
                "minecraft:stone_slab@7"
            ]
        },
        {
            "x": 0,
            "y": 13,
            "z": 7,
            "elements": [
                "minecraft:stone_slab@7"
            ]
        },
        {
            "x": -2,
            "y": 11,
            "z": 4,
            "elements": [
                "minecraft:stone_slab@15"
            ]
        },
        {
            "x": 0,
            "y": 13,
            "z": 6,
            "elements": [
                "minecraft:stone_slab@7"
            ]
        },
        {
            "x": 0,
            "y": 13,
            "z": 5,
            "elements": [
                "minecraft:quartz_stairs@2"
            ]
        },
        {
            "x": 0,
            "y": 13,
            "z": 4,
            "elements": [
                "enderio:block_alloy@0"
            ]
        },
        {
            "x": -2,
            "y": 11,
            "z": -1,
            "elements": [
                "swallowsresourcelibrary:teslashell@0"
            ]
        },
        {
            "x": 0,
            "y": 13,
            "z": 3,
            "elements": [
                "minecraft:quartz_stairs@3"
            ]
        },
        {
            "x": 0,
            "y": 13,
            "z": 2,
            "elements": [
                "minecraft:stone_slab@7"
            ]
        },
        {
            "x": 0,
            "y": 13,
            "z": 10,
            "elements": [
                "swallowsresourcelibrary:teslashell@0"
            ]
        },
        {
            "x": 1,
            "y": 1,
            "z": 0,
            "elements": [
                "minecraft:stone_slab@7"
            ]
        },
        {
            "x": 0,
            "y": 13,
            "z": 1,
            "elements": [
                "minecraft:stone_slab@7"
            ]
        },
        {
            "x": 0,
            "y": 13,
            "z": 0,
            "elements": [
                "minecraft:stone_slab@7"
            ]
        },
        {
            "x": 0,
            "y": 13,
            "z": -1,
            "elements": [
                "minecraft:stone_slab@7"
            ]
        },
        {
            "x": 0,
            "y": 13,
            "z": -2,
            "elements": [
                "swallowsresourcelibrary:teslashell@0"
            ]
        },
        {
            "x": 1,
            "y": 1,
            "z": 4,
            "elements": [
                "minecraft:quartz_stairs@1"
            ]
        },
        {
            "x": 1,
            "y": 1,
            "z": 3,
            "elements": [
                "minecraft:quartz_stairs@2"
            ]
        },
        {
            "x": 1,
            "y": 1,
            "z": 2,
            "elements": [
                "minecraft:stone_slab@7"
            ]
        },
        {
            "x": 1,
            "y": 1,
            "z": 1,
            "elements": [
                "minecraft:quartz_stairs@2"
            ]
        },
        {
            "x": 1,
            "y": 1,
            "z": 8,
            "elements": [
                "minecraft:stone_slab@7"
            ]
        },
        {
            "x": 1,
            "y": 1,
            "z": 7,
            "elements": [
                "minecraft:quartz_stairs@3"
            ]
        },
        {
            "x": 1,
            "y": 1,
            "z": 6,
            "elements": [
                "minecraft:stone_slab@7"
            ]
        },
        {
            "x": 1,
            "y": 1,
            "z": 5,
            "elements": [
                "minecraft:quartz_stairs@3"
            ]
        },
        {
            "x": -1,
            "y": 12,
            "z": 6,
            "elements": [
                "minecraft:end_rod@3"
            ]
        },
        {
            "x": -1,
            "y": 12,
            "z": 7,
            "elements": [
                "minecraft:end_rod@2"
            ]
        },
        {
            "x": -1,
            "y": 12,
            "z": 4,
            "elements": [
                "enderio:block_alloy_endergy@3"
            ]
        },
        {
            "x": -1,
            "y": 12,
            "z": 5,
            "elements": [
                "enderio:block_alloy_endergy@3"
            ]
        },
        {
            "x": -1,
            "y": 12,
            "z": 10,
            "elements": [
                "swallowsresourcelibrary:teslacoil@0"
            ]
        },
        {
            "x": -1,
            "y": 12,
            "z": 11,
            "elements": [
                "swallowsresourcelibrary:teslashell@0"
            ]
        },
        {
            "x": -1,
            "y": 12,
            "z": 8,
            "elements": [
                "enderio:block_alloy_endergy@3"
            ]
        },
        {
            "x": -1,
            "y": 12,
            "z": 9,
            "elements": [
                "swallowsresourcelibrary:teslashell@0"
            ]
        },
        {
            "x": -1,
            "y": 12,
            "z": -2,
            "elements": [
                "swallowsresourcelibrary:teslacoil@0"
            ]
        },
        {
            "x": -1,
            "y": 12,
            "z": -1,
            "elements": [
                "swallowsresourcelibrary:teslashell@0"
            ]
        },
        {
            "x": -1,
            "y": 12,
            "z": -3,
            "elements": [
                "swallowsresourcelibrary:teslashell@0"
            ]
        },
        {
            "x": -1,
            "y": 12,
            "z": 2,
            "elements": [
                "minecraft:end_rod@2"
            ]
        },
        {
            "x": -1,
            "y": 12,
            "z": 3,
            "elements": [
                "enderio:block_alloy_endergy@3"
            ]
        },
        {
            "x": -1,
            "y": 12,
            "z": 0,
            "elements": [
                "enderio:block_alloy_endergy@3"
            ]
        },
        {
            "x": -1,
            "y": 12,
            "z": 1,
            "elements": [
                "minecraft:end_rod@3"
            ]
        },
        {
            "x": 1,
            "y": 0,
            "z": 5,

            "elements": [
                "modularmachinery:blockcasing@4"
            ]
        },
        {
            "x": 1,
            "y": 0,
            "z": 4,

            "elements": [
                "modularmachinery:blockcasing@4"
            ]
        },
        {
            "x": 1,
            "y": 0,
            "z": 3,

            "elements": [
                "modularmachinery:blockcasing@4"
            ]
        },
        {
            "x": 1,
            "y": 0,
            "z": 2,

            "elements": [
                "modularmachinery:blockcasing@4"
            ]
        },
        {
            "x": 1,
            "y": 0,
            "z": 1,

            "elements": [
                "modularmachinery:blockcasing@4"
            ]
        },
        {
            "x": 1,
            "y": 0,
            "z": 0,
            "elements": [
                "modularmachinery:blockcasing@4",
                "modularmachinery:blockenergyinputhatch@0",
                "modularmachinery:blockenergyinputhatch@1",
                "modularmachinery:blockenergyinputhatch@2",
                "modularmachinery:blockenergyinputhatch@3",
                "modularmachinery:blockenergyinputhatch@4",
                "modularmachinery:blockenergyinputhatch@5",
                "modularmachinery:blockenergyinputhatch@6",
                "modularmachinery:blockenergyinputhatch@7",
                "modularmachinery:blockinputbus@0",
                "modularmachinery:blockinputbus@1",
                "modularmachinery:blockinputbus@2",
                "modularmachinery:blockinputbus@3",
                "modularmachinery:blockinputbus@4",
                "modularmachinery:blockinputbus@5",
                "modularmachinery:blockinputbus@6",
                "modularmachinery:blockmeiteminputbus",
                "modularmachinery:blockoutputbus@0",
                "modularmachinery:blockoutputbus@1",
                "modularmachinery:blockoutputbus@2",
                "modularmachinery:blockoutputbus@3",
                "modularmachinery:blockoutputbus@4",
                "modularmachinery:blockoutputbus@5",
                "modularmachinery:blockoutputbus@6",
                "modularmachinery:blockmeitemoutputbus",
                "modularmachinery:blockfluidinputhatch@0",
                "modularmachinery:blockfluidinputhatch@1",
                "modularmachinery:blockfluidinputhatch@2",
                "modularmachinery:blockfluidinputhatch@3",
                "modularmachinery:blockfluidinputhatch@4",
                "modularmachinery:blockfluidinputhatch@5",
                "modularmachinery:blockfluidinputhatch@6",
                "modularmachinery:blockfluidinputhatch@7",
                "modularmachinery:blockmefluidinputbus",
                "modularmachinery:blockfluidoutputhatch@0",
                "modularmachinery:blockfluidoutputhatch@1",
                "modularmachinery:blockfluidoutputhatch@2",
                "modularmachinery:blockfluidoutputhatch@3",
                "modularmachinery:blockfluidoutputhatch@4",
                "modularmachinery:blockfluidoutputhatch@5",
                "modularmachinery:blockfluidoutputhatch@6",
                "modularmachinery:blockfluidoutputhatch@7",
                "modularmachinery:blockmefluidoutputbus"
            ]
        },
        {
            "x": -1,
            "y": 14,
            "z": 4,
            "elements": [
                "ic2:fence@0"
            ]
        },
        {
            "x": 1,
            "y": 0,
            "z": 8,
            "elements": [
                "modularmachinery:blockcasing@4",
                "modularmachinery:blockenergyinputhatch@0",
                "modularmachinery:blockenergyinputhatch@1",
                "modularmachinery:blockenergyinputhatch@2",
                "modularmachinery:blockenergyinputhatch@3",
                "modularmachinery:blockenergyinputhatch@4",
                "modularmachinery:blockenergyinputhatch@5",
                "modularmachinery:blockenergyinputhatch@6",
                "modularmachinery:blockenergyinputhatch@7",
                "modularmachinery:blockinputbus@0",
                "modularmachinery:blockinputbus@1",
                "modularmachinery:blockinputbus@2",
                "modularmachinery:blockinputbus@3",
                "modularmachinery:blockinputbus@4",
                "modularmachinery:blockinputbus@5",
                "modularmachinery:blockinputbus@6",
                "modularmachinery:blockmeiteminputbus",
                "modularmachinery:blockoutputbus@0",
                "modularmachinery:blockoutputbus@1",
                "modularmachinery:blockoutputbus@2",
                "modularmachinery:blockoutputbus@3",
                "modularmachinery:blockoutputbus@4",
                "modularmachinery:blockoutputbus@5",
                "modularmachinery:blockoutputbus@6",
                "modularmachinery:blockmeitemoutputbus",
                "modularmachinery:blockfluidinputhatch@0",
                "modularmachinery:blockfluidinputhatch@1",
                "modularmachinery:blockfluidinputhatch@2",
                "modularmachinery:blockfluidinputhatch@3",
                "modularmachinery:blockfluidinputhatch@4",
                "modularmachinery:blockfluidinputhatch@5",
                "modularmachinery:blockfluidinputhatch@6",
                "modularmachinery:blockfluidinputhatch@7",
                "modularmachinery:blockmefluidinputbus",
                "modularmachinery:blockfluidoutputhatch@0",
                "modularmachinery:blockfluidoutputhatch@1",
                "modularmachinery:blockfluidoutputhatch@2",
                "modularmachinery:blockfluidoutputhatch@3",
                "modularmachinery:blockfluidoutputhatch@4",
                "modularmachinery:blockfluidoutputhatch@5",
                "modularmachinery:blockfluidoutputhatch@6",
                "modularmachinery:blockfluidoutputhatch@7",
                "modularmachinery:blockmefluidoutputbus"
            ]
        },
        {
            "x": 1,
            "y": 0,
            "z": 7,

            "elements": [
                "modularmachinery:blockcasing@4"
            ]
        },
        {
            "x": 1,
            "y": 0,
            "z": 6,

            "elements": [
                "modularmachinery:blockcasing@4"
            ]
        },
        {
            "x": -1,
            "y": 11,
            "z": 3,
            "elements": [
                "minecraft:stone_slab@15"
            ]
        },
        {
            "x": 1,
            "y": 13,
            "z": 10,
            "elements": [
                "swallowsresourcelibrary:teslashell@0"
            ]
        },
        {
            "x": -1,
            "y": 11,
            "z": 4,
            "elements": [
                "minecraft:quartz_stairs@5"
            ]
        },
        {
            "x": 1,
            "y": 13,
            "z": 9,
            "elements": [
                "minecraft:stone_slab@7"
            ]
        },
        {
            "x": -1,
            "y": 11,
            "z": -1,
            "elements": [
                "minecraft:stone_slab@15"
            ]
        },
        {
            "x": -1,
            "y": 11,
            "z": 0,
            "elements": [
                "minecraft:stone_slab@15"
            ]
        },
        {
            "x": -1,
            "y": 11,
            "z": -2,
            "elements": [
                "swallowsresourcelibrary:teslashell@0"
            ]
        },
        {
            "x": -1,
            "y": 11,
            "z": 9,
            "elements": [
                "minecraft:stone_slab@15"
            ]
        },
        {
            "x": 1,
            "y": 3,
            "z": 4,
            "elements": [
                "minecraft:end_rod@1"
            ]
        },
        {
            "x": -1,
            "y": 11,
            "z": 10,
            "elements": [
                "swallowsresourcelibrary:teslashell@0"
            ]
        },
        {
            "x": -1,
            "y": 11,
            "z": 8,
            "elements": [
                "minecraft:stone_slab@15"
            ]
        },
        {
            "x": -1,
            "y": 11,
            "z": 5,
            "elements": [
                "minecraft:stone_slab@15"
            ]
        },
        {
            "x": -2,
            "y": 0,
            "z": 3,

            "elements": [
                "modularmachinery:blockcasing@4"
            ]
        },
        {
            "x": -2,
            "y": 0,
            "z": 4,

            "elements": [
                "modularmachinery:blockcasing@4"
            ]
        },
        {
            "x": -2,
            "y": 0,
            "z": 1,

            "elements": [
                "modularmachinery:blockcasing@4"
            ]
        },
        {
            "x": -2,
            "y": 0,
            "z": 2,

            "elements": [
                "modularmachinery:blockcasing@4"
            ]
        },
        {
            "x": 1,
            "y": 13,
            "z": -2,
            "elements": [
                "swallowsresourcelibrary:teslashell@0"
            ]
        },
        {
            "x": -2,
            "y": 0,
            "z": 7,

            "elements": [
                "modularmachinery:blockcasing@4"
            ]
        },
        {
            "x": -2,
            "y": 0,
            "z": 8,
            "elements": [
                "modularmachinery:blockcasing@4",
                "modularmachinery:blockenergyinputhatch@0",
                "modularmachinery:blockenergyinputhatch@1",
                "modularmachinery:blockenergyinputhatch@2",
                "modularmachinery:blockenergyinputhatch@3",
                "modularmachinery:blockenergyinputhatch@4",
                "modularmachinery:blockenergyinputhatch@5",
                "modularmachinery:blockenergyinputhatch@6",
                "modularmachinery:blockenergyinputhatch@7",
                "modularmachinery:blockinputbus@0",
                "modularmachinery:blockinputbus@1",
                "modularmachinery:blockinputbus@2",
                "modularmachinery:blockinputbus@3",
                "modularmachinery:blockinputbus@4",
                "modularmachinery:blockinputbus@5",
                "modularmachinery:blockinputbus@6",
                "modularmachinery:blockmeiteminputbus",
                "modularmachinery:blockoutputbus@0",
                "modularmachinery:blockoutputbus@1",
                "modularmachinery:blockoutputbus@2",
                "modularmachinery:blockoutputbus@3",
                "modularmachinery:blockoutputbus@4",
                "modularmachinery:blockoutputbus@5",
                "modularmachinery:blockoutputbus@6",
                "modularmachinery:blockmeitemoutputbus",
                "modularmachinery:blockfluidinputhatch@0",
                "modularmachinery:blockfluidinputhatch@1",
                "modularmachinery:blockfluidinputhatch@2",
                "modularmachinery:blockfluidinputhatch@3",
                "modularmachinery:blockfluidinputhatch@4",
                "modularmachinery:blockfluidinputhatch@5",
                "modularmachinery:blockfluidinputhatch@6",
                "modularmachinery:blockfluidinputhatch@7",
                "modularmachinery:blockmefluidinputbus",
                "modularmachinery:blockfluidoutputhatch@0",
                "modularmachinery:blockfluidoutputhatch@1",
                "modularmachinery:blockfluidoutputhatch@2",
                "modularmachinery:blockfluidoutputhatch@3",
                "modularmachinery:blockfluidoutputhatch@4",
                "modularmachinery:blockfluidoutputhatch@5",
                "modularmachinery:blockfluidoutputhatch@6",
                "modularmachinery:blockfluidoutputhatch@7",
                "modularmachinery:blockmefluidoutputbus"
            ]
        },
        {
            "x": -2,
            "y": 0,
            "z": 5,

            "elements": [
                "modularmachinery:blockcasing@4"
            ]
        },
        {
            "x": 1,
            "y": 13,
            "z": 0,
            "elements": [
                "minecraft:stone_slab@7"
            ]
        },
        {
            "x": -2,
            "y": 0,
            "z": 6,

            "elements": [
                "modularmachinery:blockcasing@4"
            ]
        },
        {
            "x": 1,
            "y": 13,
            "z": -1,
            "elements": [
                "minecraft:stone_slab@7"
            ]
        },
        {
            "x": 1,
            "y": 13,
            "z": 4,
            "elements": [
                "minecraft:quartz_stairs@0"
            ]
        },
        {
            "x": 1,
            "y": 13,
            "z": 3,
            "elements": [
                "minecraft:stone_slab@7"
            ]
        },
        {
            "x": 1,
            "y": 13,
            "z": 5,
            "elements": [
                "minecraft:stone_slab@7"
            ]
        },
        {
            "x": -2,
            "y": 0,
            "z": 0,
            "elements": [
                "modularmachinery:blockcasing@4",
                "modularmachinery:blockenergyinputhatch@0",
                "modularmachinery:blockenergyinputhatch@1",
                "modularmachinery:blockenergyinputhatch@2",
                "modularmachinery:blockenergyinputhatch@3",
                "modularmachinery:blockenergyinputhatch@4",
                "modularmachinery:blockenergyinputhatch@5",
                "modularmachinery:blockenergyinputhatch@6",
                "modularmachinery:blockenergyinputhatch@7",
                "modularmachinery:blockinputbus@0",
                "modularmachinery:blockinputbus@1",
                "modularmachinery:blockinputbus@2",
                "modularmachinery:blockinputbus@3",
                "modularmachinery:blockinputbus@4",
                "modularmachinery:blockinputbus@5",
                "modularmachinery:blockinputbus@6",
                "modularmachinery:blockmeiteminputbus",
                "modularmachinery:blockoutputbus@0",
                "modularmachinery:blockoutputbus@1",
                "modularmachinery:blockoutputbus@2",
                "modularmachinery:blockoutputbus@3",
                "modularmachinery:blockoutputbus@4",
                "modularmachinery:blockoutputbus@5",
                "modularmachinery:blockoutputbus@6",
                "modularmachinery:blockmeitemoutputbus",
                "modularmachinery:blockfluidinputhatch@0",
                "modularmachinery:blockfluidinputhatch@1",
                "modularmachinery:blockfluidinputhatch@2",
                "modularmachinery:blockfluidinputhatch@3",
                "modularmachinery:blockfluidinputhatch@4",
                "modularmachinery:blockfluidinputhatch@5",
                "modularmachinery:blockfluidinputhatch@6",
                "modularmachinery:blockfluidinputhatch@7",
                "modularmachinery:blockmefluidinputbus",
                "modularmachinery:blockfluidoutputhatch@0",
                "modularmachinery:blockfluidoutputhatch@1",
                "modularmachinery:blockfluidoutputhatch@2",
                "modularmachinery:blockfluidoutputhatch@3",
                "modularmachinery:blockfluidoutputhatch@4",
                "modularmachinery:blockfluidoutputhatch@5",
                "modularmachinery:blockfluidoutputhatch@6",
                "modularmachinery:blockfluidoutputhatch@7",
                "modularmachinery:blockmefluidoutputbus"
            ]
        },
        {
            "x": 1,
            "y": 13,
            "z": 8,
            "elements": [
                "minecraft:stone_slab@7"
            ]
        },
        {
            "x": 2,
            "y": 2,
            "z": 2,
            "elements": [
                "minecraft:stone_slab@7"
            ]
        },
        {
            "x": -2,
            "y": 12,
            "z": 5,
            "elements": [
                "minecraft:end_rod@4"
            ]
        },
        {
            "x": -2,
            "y": 12,
            "z": 8,
            "elements": [
                "swallowsresourcelibrary:teslashell@0"
            ]
        },
        {
            "x": -2,
            "y": 12,
            "z": 9,
            "elements": [
                "swallowsresourcelibrary:teslacoil@0"
            ]
        },
        {
            "x": -2,
            "y": 12,
            "z": 10,
            "elements": [
                "swallowsresourcelibrary:teslashell@0"
            ]
        },
        {
            "x": 2,
            "y": 2,
            "z": 4,
            "elements": [
                "minecraft:quartz_stairs@1"
            ]
        },
        {
            "x": -2,
            "y": 12,
            "z": -2,
            "elements": [
                "swallowsresourcelibrary:teslashell@0"
            ]
        },
        {
            "x": -4,
            "y": 11,
            "z": 8,
            "elements": [
                "swallowsresourcelibrary:teslashell@0"
            ]
        },
        {
            "x": -2,
            "y": 12,
            "z": -1,
            "elements": [
                "swallowsresourcelibrary:teslacoil@0"
            ]
        },
        {
            "x": -2,
            "y": 12,
            "z": 0,
            "elements": [
                "swallowsresourcelibrary:teslashell@0"
            ]
        },
        {
            "x": 2,
            "y": 2,
            "z": 6,
            "elements": [
                "minecraft:stone_slab@7"
            ]
        },
        {
            "x": -2,
            "y": 12,
            "z": 3,
            "elements": [
                "minecraft:end_rod@4"
            ]
        },
        {
            "x": -2,
            "y": 12,
            "z": 4,
            "elements": [
                "enderio:block_alloy_endergy@3"
            ]
        },
        {
            "x": -4,
            "y": 11,
            "z": 0,
            "elements": [
                "swallowsresourcelibrary:teslashell@0"
            ]
        },
        {
            "x": -4,
            "y": 11,
            "z": 3,
            "elements": [
                "minecraft:stone_slab@15"
            ]
        },
        {
            "x": -4,
            "y": 11,
            "z": 5,
            "elements": [
                "minecraft:stone_slab@15"
            ]
        },
        {
            "x": -4,
            "y": 11,
            "z": 4,
            "elements": [
                "minecraft:stone_slab@15"
            ]
        },
        {
            "x": -1,
            "y": 2,
            "z": 4,
            "elements": [
                "minecraft:quartz_stairs@4"
            ]
        },
        {
            "x": 0,
            "y": 1,
            "z": 7,
            "elements": [
                "minecraft:stone_slab@7"
            ]
        },
        {
            "x": 0,
            "y": 1,
            "z": 6,
            "elements": [
                "minecraft:quartz_block@0"
            ]
        },
        {
            "x": -3,
            "y": 13,
            "z": 9,
            "elements": [
                "swallowsresourcelibrary:teslashell@0"
            ]
        },
        {
            "x": -3,
            "y": 13,
            "z": -1,
            "elements": [
                "swallowsresourcelibrary:teslashell@0"
            ]
        },
        {
            "x": 0,
            "y": 1,
            "z": 1,
            "elements": [
                "minecraft:stone_slab@7"
            ]
        },
        {
            "x": 0,
            "y": 1,
            "z": 3,
            "elements": [
                "minecraft:quartz_stairs@2"
            ]
        },
        {
            "x": 0,
            "y": 1,
            "z": 2,
            "elements": [
                "minecraft:quartz_block@0"
            ]
        },
        {
            "x": -3,
            "y": 13,
            "z": 4,
            "elements": [
                "minecraft:stone_slab@7"
            ]
        },
        {
            "x": 0,
            "y": 1,
            "z": 5,
            "elements": [
                "minecraft:quartz_stairs@3"
            ]
        },
        {
            "x": 0,
            "y": 1,
            "z": 4,
            "elements": [
                "enderio:block_alloy@0"
            ]
        },
        {
            "x": -4,
            "y": 12,
            "z": 3,
            "elements": [
                "enderio:block_alloy_endergy@3"
            ]
        },
        {
            "x": 1,
            "y": 5,
            "z": 4,
            "elements": [
                "minecraft:quartz_stairs@1"
            ]
        },
        {
            "x": -4,
            "y": 12,
            "z": 4,
            "elements": [
                "enderio:block_alloy_endergy@3"
            ]
        },
        {
            "x": -4,
            "y": 12,
            "z": 5,
            "elements": [
                "enderio:block_alloy_endergy@3"
            ]
        },
        {
            "x": -4,
            "y": 12,
            "z": 6,
            "elements": [
                "swallowsresourcelibrary:teslashell@0"
            ]
        },
        {
            "x": 2,
            "y": 13,
            "z": -1,
            "elements": [
                "swallowsresourcelibrary:teslashell@0"
            ]
        },
        {
            "x": -4,
            "y": 12,
            "z": -1,
            "elements": [
                "swallowsresourcelibrary:teslashell@0"
            ]
        },
        {
            "x": -4,
            "y": 12,
            "z": 0,
            "elements": [
                "swallowsresourcelibrary:teslacoil@0"
            ]
        },
        {
            "x": -4,
            "y": 12,
            "z": 1,
            "elements": [
                "swallowsresourcelibrary:teslashell@0"
            ]
        },
        {
            "x": -4,
            "y": 12,
            "z": 2,
            "elements": [
                "swallowsresourcelibrary:teslashell@0"
            ]
        },
        {
            "x": -4,
            "y": 12,
            "z": 7,
            "elements": [
                "swallowsresourcelibrary:teslashell@0"
            ]
        },
        {
            "x": -4,
            "y": 12,
            "z": 8,
            "elements": [
                "swallowsresourcelibrary:teslacoil@0"
            ]
        },
        {
            "x": -4,
            "y": 12,
            "z": 9,
            "elements": [
                "swallowsresourcelibrary:teslashell@0"
            ]
        },
        {
            "x": 2,
            "y": 13,
            "z": 9,
            "elements": [
                "swallowsresourcelibrary:teslashell@0"
            ]
        },
        {
            "x": 1,
            "y": 12,
            "z": -1,
            "elements": [
                "swallowsresourcelibrary:teslashell@0"
            ]
        },
        {
            "x": 1,
            "y": 12,
            "z": -2,
            "elements": [
                "swallowsresourcelibrary:teslacoil@0"
            ]
        },
        {
            "x": 1,
            "y": 12,
            "z": 1,
            "elements": [
                "minecraft:end_rod@3"
            ]
        },
        {
            "x": 1,
            "y": 12,
            "z": 0,
            "elements": [
                "enderio:block_alloy_endergy@3"
            ]
        },
        {
            "x": 6,
            "y": 11,
            "z": 4,
            "elements": [
                "swallowsresourcelibrary:teslashell@0"
            ]
        },
        {
            "x": 6,
            "y": 11,
            "z": 5,
            "elements": [
                "swallowsresourcelibrary:teslashell@0"
            ]
        },
        {
            "x": 1,
            "y": 12,
            "z": -3,
            "elements": [
                "swallowsresourcelibrary:teslashell@0"
            ]
        },
        {
            "x": 6,
            "y": 11,
            "z": 3,
            "elements": [
                "swallowsresourcelibrary:teslashell@0"
            ]
        },
        {
            "x": 2,
            "y": 13,
            "z": 4,
            "elements": [
                "minecraft:stone_slab@7"
            ]
        },
        {
            "x": 1,
            "y": 12,
            "z": 7,
            "elements": [
                "minecraft:end_rod@2"
            ]
        },
        {
            "x": 1,
            "y": 12,
            "z": 6,
            "elements": [
                "minecraft:end_rod@3"
            ]
        },
        {
            "x": 1,
            "y": 12,
            "z": 9,
            "elements": [
                "swallowsresourcelibrary:teslashell@0"
            ]
        },
        {
            "x": 0,
            "y": 10,
            "z": 3,
            "elements": [
                "minecraft:quartz_stairs@6"
            ]
        },
        {
            "x": 1,
            "y": 12,
            "z": 8,
            "elements": [
                "enderio:block_alloy_endergy@3"
            ]
        },
        {
            "x": 0,
            "y": 10,
            "z": 4,
            "elements": [
                "enderio:block_alloy@0"
            ]
        },
        {
            "x": 1,
            "y": 12,
            "z": 3,
            "elements": [
                "enderio:block_alloy_endergy@3"
            ]
        },
        {
            "x": 1,
            "y": 12,
            "z": 2,
            "elements": [
                "minecraft:end_rod@2"
            ]
        },
        {
            "x": 1,
            "y": 12,
            "z": 5,
            "elements": [
                "enderio:block_alloy_endergy@3"
            ]
        },
        {
            "x": 1,
            "y": 12,
            "z": 4,
            "elements": [
                "enderio:block_alloy_endergy@3"
            ]
        },
        {
            "x": 1,
            "y": 12,
            "z": 11,
            "elements": [
                "swallowsresourcelibrary:teslashell@0"
            ]
        },
        {
            "x": 0,
            "y": 10,
            "z": 5,
            "elements": [
                "minecraft:quartz_stairs@7"
            ]
        },
        {
            "x": 1,
            "y": 12,
            "z": 10,
            "elements": [
                "swallowsresourcelibrary:teslacoil@0"
            ]
        },
        {
            "x": 2,
            "y": 12,
            "z": 10,
            "elements": [
                "swallowsresourcelibrary:teslashell@0"
            ]
        },
        {
            "x": 2,
            "y": 12,
            "z": 9,
            "elements": [
                "swallowsresourcelibrary:teslacoil@0"
            ]
        },
        {
            "x": 0,
            "y": 3,
            "z": 3,
            "elements": [
                "minecraft:end_rod@1"
            ]
        },
        {
            "x": 0,
            "y": 3,
            "z": 5,
            "elements": [
                "minecraft:end_rod@1"
            ]
        },
        {
            "x": 0,
            "y": 3,
            "z": 4,
            "elements": [
                "enderio:block_alloy@0"
            ]
        },
        {
            "x": -4,
            "y": 13,
            "z": 0,
            "elements": [
                "swallowsresourcelibrary:teslashell@0"
            ]
        },
        {
            "x": -4,
            "y": 13,
            "z": 3,
            "elements": [
                "minecraft:stone_slab@7"
            ]
        },
        {
            "x": -4,
            "y": 13,
            "z": 4,
            "elements": [
                "minecraft:stone_slab@7"
            ]
        },
        {
            "x": -4,
            "y": 13,
            "z": 5,
            "elements": [
                "minecraft:stone_slab@7"
            ]
        },
        {
            "x": 0,
            "y": 16,
            "z": 4,
            "elements": [
                "ic2:fence@0"
            ]
        },
        {
            "x": 2,
            "y": 0,
            "z": 6,

            "elements": [
                "modularmachinery:blockcasing@4"
            ]
        },
        {
            "x": 2,
            "y": 0,
            "z": 5,

            "elements": [
                "modularmachinery:blockcasing@4"
            ]
        },
        {
            "x": 2,
            "y": 0,
            "z": 8,
            "elements": [
                "modularmachinery:blockcasing@4",
                "modularmachinery:blockenergyinputhatch@0",
                "modularmachinery:blockenergyinputhatch@1",
                "modularmachinery:blockenergyinputhatch@2",
