{
    "registryname": "YMG_Gemini_Frost",
    "localizedname": "§b§lYMG§r§e§l—#8A4ED5§l双子塔§d§l-#3B78FF§l霜 §r§e",
    "failure-action": "reset",
    "requires-blueprint": false,
    "color": "3B78FF",
    "parts": [
        {
            "x": 5,
            "y": 0,
            "z": 6,
            "elements": [
                "appliedenergistics2:smooth_sky_stone_stairs@1"
            ]
        },
        {
            "x": 5,
            "y": 0,
            "z": 4,
            "elements": [
                "appliedenergistics2:smooth_sky_stone_stairs@1"
            ]
        },
        {
            "x": -1,
            "y": 19,
            "z": 5,
            "elements": [
                "chisel:factory1@1"
            ]
        },
        {
            "x": 5,
            "y": 0,
            "z": 5,
            "elements": [
                "modularmachinery:blockcasing@0",
                "ItemInput",
                "ItemOutput",
                "FluidInput",
                "FluidOutput",
                "EnergyInput"
            ]
        },
        {
            "x": -1,
            "y": 19,
            "z": 6,
            "elements": [
                "minecraft:end_rod@1"
            ]
        },
        {
            "x": -1,
            "y": 19,
            "z": 7,
            "elements": [
                "minecraft:stained_glass_pane@11"
            ]
        },
        {
            "x": -1,
            "y": 6,
            "z": 4,
            "elements": [
                "chisel:factory1@1"
            ]
        },
        {
            "x": -1,
            "y": 6,
            "z": 5,
            "elements": [
                "chisel:factory1@1"
            ]
        },
        {
            "x": -5,
            "y": 1,
            "z": 5,
            "elements": [
                "appliedenergistics2:smooth_sky_stone_slab@0"
            ]
        },
        {
            "x": -1,
            "y": 6,
            "z": 6,
            "elements": [
                "chisel:factory1@1"
            ]
        },
        {
            "x": 1,
            "y": 8,
            "z": 6,
            "elements": [
                "chisel:factory1@1"
            ]
        },
        {
            "x": 0,
            "y": 7,
            "z": 3,
            "elements": [
                "minecraft:stained_glass_pane@11"
            ]
        },
        {
            "x": 0,
            "y": 7,
            "z": 4,
            "elements": [
                "chisel:factory1@1"
            ]
        },
        {
            "x": 0,
            "y": 7,
            "z": 5,
            "elements": [
                "swallowsresourcelibrary:tungstenblock@0"
            ]
        },
        {
            "x": 0,
            "y": 7,
            "z": 6,
            "elements": [
                "chisel:factory1@1"
            ]
        },
        {
            "x": 0,
            "y": 7,
            "z": 7,
            "elements": [
                "minecraft:stained_glass_pane@11"
            ]
        },
        {
            "x": 2,
            "y": 9,
            "z": 6,
            "elements": [
                "minecraft:stained_glass_pane@11"
            ]
        },
        {
            "x": 2,
            "y": 9,
            "z": 5,
            "elements": [
                "minecraft:stained_glass_pane@11"
            ]
        },
        {
            "x": 2,
            "y": 9,
            "z": 4,
            "elements": [
                "minecraft:stained_glass_pane@11"
            ]
        },
        {
            "x": 1,
            "y": 9,
            "z": 4,
            "elements": [
                "minecraft:end_rod@1"
            ]
        },
        {
            "x": 1,
            "y": 9,
            "z": 3,
            "elements": [
                "minecraft:stained_glass_pane@11"
            ]
        },
        {
            "x": 0,
            "y": 20,
            "z": 5,

            "elements": [
                "modularmachinery:blockcasing@1"
            ]
        },
        {
            "x": 1,
            "y": 9,
            "z": 6,
            "elements": [
                "minecraft:end_rod@1"
            ]
        },
        {
            "x": 1,
            "y": 9,
            "z": 5,
            "elements": [
                "chisel:factory1@1"
            ]
        },
        {
            "x": 0,
            "y": 20,
            "z": 6,
            "elements": [
                "chisel:factory1@1"
            ]
        },
        {
            "x": 0,
            "y": 20,
            "z": 4,
            "elements": [
                "chisel:factory1@1"
            ]
        },
        {
            "x": 1,
            "y": 9,
            "z": 7,
            "elements": [
                "minecraft:stained_glass_pane@11"
            ]
        },
        {
            "x": -1,
            "y": 20,
            "z": 4,
            "elements": [
                "minecraft:stained_glass_pane@11"
            ]
        },
        {
            "x": -1,
            "y": 20,
            "z": 5,
            "elements": [
                "chisel:factory1@1"
            ]
        },
        {
            "x": -1,
            "y": 20,
            "z": 6,
            "elements": [
                "minecraft:stained_glass_pane@11"
            ]
        },
        {
            "x": -1,
            "y": 18,
            "z": 6,
            "elements": [
                "chisel:factory1@1"
            ]
        },
        {
            "x": 4,
            "y": 0,
            "z": 2,
            "elements": [
                "appliedenergistics2:smooth_sky_stone_stairs@2"
            ]
        },
        {
            "x": -1,
            "y": 18,
            "z": 5,
            "elements": [
                "chisel:factory1@1"
            ]
        },
        {
            "x": -1,
            "y": 18,
            "z": 4,
            "elements": [
                "chisel:factory1@1"
            ]
        },
        {
            "x": 1,
            "y": 7,
            "z": 7,
            "elements": [
                "minecraft:stained_glass_pane@11"
            ]
        },
        {
            "x": -2,
            "y": 19,
            "z": 6,
            "elements": [
                "minecraft:stained_glass_pane@11"
            ]
        },
        {
            "x": 0,
            "y": 19,
            "z": 6,
            "elements": [
                "chisel:factory1@1"
            ]
        },
        {
            "x": 0,
            "y": 19,
            "z": 7,
            "elements": [
                "minecraft:stained_glass_pane@11"
            ]
        },
        {
            "x": 0,
            "y": 19,
            "z": 4,
            "elements": [
                "chisel:factory1@1"
            ]
        },
        {
            "x": 0,
            "y": 19,
            "z": 5,
            "elements": [
                "swallowsresourcelibrary:tungstenblock@0"
            ]
        },
        {
            "x": 0,
            "y": 19,
            "z": 3,
            "elements": [
                "minecraft:stained_glass_pane@11"
            ]
        },
        {
            "x": -2,
            "y": 5,
            "z": 5,
            "elements": [
                "minecraft:stained_glass_pane@11"
            ]
        },
        {
            "x": 1,
            "y": 7,
            "z": 5,
            "elements": [
                "chisel:factory1@1"
            ]
        },
        {
            "x": -2,
            "y": 19,
            "z": 5,
            "elements": [
                "minecraft:stained_glass_pane@11"
            ]
        },
        {
            "x": -2,
            "y": 5,
            "z": 4,
            "elements": [
                "minecraft:stained_glass_pane@11"
            ]
        },
        {
            "x": -2,
            "y": 19,
            "z": 4,
            "elements": [
                "minecraft:stained_glass_pane@11"
            ]
        },
        {
            "x": 1,
            "y": 7,
            "z": 6,
            "elements": [
                "minecraft:end_rod@1"
            ]
        },
        {
            "x": 1,
            "y": 7,
            "z": 3,
            "elements": [
                "minecraft:stained_glass_pane@11"
            ]
        },
        {
            "x": 1,
            "y": 7,
            "z": 4,
            "elements": [
                "minecraft:end_rod@1"
            ]
        },
        {
            "x": -2,
            "y": 5,
            "z": 6,
            "elements": [
                "minecraft:stained_glass_pane@11"
            ]
        },
        {
            "x": 0,
            "y": 8,
            "z": 4,
            "elements": [
                "chisel:factory1@1"
            ]
        },
        {
            "x": 0,
            "y": 8,
            "z": 5,
            "elements": [
                "swallowsresourcelibrary:tungstenblock@0"
            ]
        },
        {
            "x": 0,
            "y": 8,
            "z": 6,
            "elements": [
                "chisel:factory1@1"
            ]
        },
        {
            "x": -5,
            "y": 0,
            "z": 5,
            "elements": [
                "modularmachinery:blockcasing@0",
                "ItemInput",
                "ItemOutput",
                "FluidInput",
                "FluidOutput",
                "EnergyInput"
            ]
        },
        {
            "x": -5,
            "y": 0,
            "z": 4,
            "elements": [
                "appliedenergistics2:smooth_sky_stone_stairs@0"
            ]
        },
        {
            "x": -5,
            "y": 0,
            "z": 6,
            "elements": [
                "appliedenergistics2:smooth_sky_stone_stairs@0"
            ]
        },
        {
            "x": 2,
            "y": 11,
            "z": 5,
            "elements": [
                "minecraft:stained_glass_pane@11"
            ]
        },
        {
            "x": 2,
            "y": 11,
            "z": 4,
            "elements": [
                "minecraft:stained_glass_pane@11"
            ]
        },
        {
            "x": -2,
            "y": 3,
            "z": 6,
            "elements": [
                "minecraft:stained_glass_pane@11"
            ]
        },
        {
            "x": 2,
            "y": 11,
            "z": 6,
            "elements": [
                "minecraft:stained_glass_pane@11"
            ]
        },
        {
            "x": -2,
            "y": 3,
            "z": 5,
            "elements": [
                "minecraft:stained_glass_pane@11"
            ]
        },
        {
            "x": -2,
            "y": 3,
            "z": 4,
            "elements": [
                "minecraft:stained_glass_pane@11"
            ]
        },
        {
            "x": 1,
            "y": 10,
            "z": 5,
            "elements": [
                "chisel:factory1@1"
            ]
        },
        {
            "x": 1,
            "y": 10,
            "z": 4,
            "elements": [
                "chisel:factory1@1"
            ]
        },
        {
            "x": 1,
            "y": 10,
            "z": 6,
            "elements": [
                "chisel:factory1@1"
            ]
        },
        {
            "x": -1,
            "y": 17,
            "z": 4,
            "elements": [
                "minecraft:end_rod@1"
            ]
        },
        {
            "x": 4,
            "y": 0,
            "z": 7,
            "elements": [
                "modularmachinery:blockcasing@0",
                "ItemInput",
                "ItemOutput",
                "FluidInput",
                "FluidOutput",
                "EnergyInput"
            ]
        },
        {
            "x": -1,
            "y": 17,
            "z": 3,
            "elements": [
                "minecraft:stained_glass_pane@11"
            ]
        },
        {
            "x": 4,
            "y": 0,
            "z": 8,
            "elements": [
                "appliedenergistics2:smooth_sky_stone_stairs@3"
            ]
        },
        {
            "x": -1,
            "y": 17,
            "z": 6,
            "elements": [
                "minecraft:end_rod@1"
            ]
        },
        {
            "x": -1,
            "y": 17,
            "z": 5,
            "elements": [
                "chisel:factory1@1"
            ]
        },
        {
            "x": 4,
            "y": 0,
            "z": 3,
            "elements": [
                "modularmachinery:blockcasing@0",
                "ItemInput",
                "ItemOutput",
                "FluidInput",
                "FluidOutput",
                "EnergyInput"
            ]
        },
        {
            "x": 4,
            "y": 0,
            "z": 4,
            "elements": [
                "enderio:block_reinforced_obsidian@0"
            ]
        },
        {
            "x": 4,
            "y": 0,
            "z": 5,
            "elements": [
                "enderio:block_reinforced_obsidian@0"
            ]
        },
        {
            "x": 4,
            "y": 0,
            "z": 6,
            "elements": [
                "enderio:block_reinforced_obsidian@0"
            ]
        },
        {
            "x": 4,
            "y": 1,
            "z": 4,
            "elements": [
                "appliedenergistics2:smooth_sky_stone_stairs@1"
            ]
        },
        {
            "x": 4,
            "y": 1,
            "z": 5,
            "elements": [
                "appliedenergistics2:smooth_sky_stone_stairs@1"
            ]
        },
        {
            "x": 4,
            "y": 1,
            "z": 6,
            "elements": [
                "appliedenergistics2:smooth_sky_stone_stairs@1"
            ]
        },
        {
            "x": -4,
            "y": 1,
            "z": 4,
            "elements": [
                "appliedenergistics2:smooth_sky_stone_stairs@0"
            ]
        },
        {
            "x": -3,
            "y": 1,
            "z": 5,

            "elements": [
                "modularmachinery:blockcasing@0"
            ]
        },
        {
            "x": 1,
            "y": 6,
            "z": 6,
            "elements": [
                "chisel:factory1@1"
            ]
        },
        {
            "x": -4,
            "y": 1,
            "z": 5,
            "elements": [
                "appliedenergistics2:smooth_sky_stone_stairs@0"
            ]
        },
        {
            "x": -3,
            "y": 1,
            "z": 6,

            "elements": [
                "modularmachinery:blockcasing@0"
            ]
        },
        {
            "x": 1,
            "y": 6,
            "z": 4,
            "elements": [
                "chisel:factory1@1"
            ]
        },
        {
            "x": -3,
            "y": 1,
            "z": 7,
            "elements": [
                "appliedenergistics2:smooth_sky_stone_stairs@0"
            ]
        },
        {
            "x": 1,
            "y": 6,
            "z": 5,
            "elements": [
                "chisel:factory1@1"
            ]
        },
        {
            "x": -3,
            "y": 1,
            "z": 8,
            "elements": [
                "appliedenergistics2:smooth_sky_stone_stairs@0"
            ]
        },
        {
            "x": -3,
            "y": 1,
            "z": 2,
            "elements": [
                "appliedenergistics2:smooth_sky_stone_stairs@0"
            ]
        },
        {
            "x": -3,
            "y": 1,
            "z": 3,
            "elements": [
                "appliedenergistics2:smooth_sky_stone_stairs@0"
            ]
        },
        {
            "x": -4,
            "y": 1,
            "z": 6,
            "elements": [
                "appliedenergistics2:smooth_sky_stone_stairs@0"
            ]
        },
        {
            "x": -3,
            "y": 1,
            "z": 4,

            "elements": [
                "modularmachinery:blockcasing@0"
            ]
        },
        {
            "x": -1,
            "y": 17,
            "z": 7,
            "elements": [
                "minecraft:stained_glass_pane@11"
            ]
        },
        {
            "x": 1,
            "y": 19,
            "z": 3,
            "elements": [
                "minecraft:stained_glass_pane@11"
            ]
        },
        {
            "x": 1,
            "y": 19,
            "z": 4,
            "elements": [
                "minecraft:end_rod@1"
            ]
        },
        {
            "x": 1,
            "y": 19,
            "z": 5,
            "elements": [
                "chisel:factory1@1"
            ]
        },
        {
            "x": 1,
            "y": 19,
            "z": 6,
            "elements": [
                "minecraft:end_rod@1"
            ]
        },
        {
            "x": 1,
            "y": 19,
            "z": 7,
            "elements": [
                "minecraft:stained_glass_pane@11"
            ]
        },
        {
            "x": -2,
            "y": 15,
            "z": 5,
            "elements": [
                "minecraft:stained_glass_pane@11"
            ]
        },
        {
            "x": -2,
            "y": 15,
            "z": 4,
            "elements": [
                "minecraft:stained_glass_pane@11"
            ]
        },
        {
            "x": -2,
            "y": 15,
            "z": 6,
            "elements": [
                "minecraft:stained_glass_pane@11"
            ]
        },
        {
            "x": 0,
            "y": 4,
            "z": 4,
            "elements": [
                "chisel:factory1@1"
            ]
        },
        {
            "x": -1,
            "y": 8,
            "z": 6,
            "elements": [
                "chisel:factory1@1"
            ]
        },
        {
            "x": -1,
            "y": 8,
            "z": 4,
            "elements": [
                "chisel:factory1@1"
            ]
        },
        {
            "x": 0,
            "y": 4,
            "z": 6,
            "elements": [
                "chisel:factory1@1"
            ]
        },
        {
            "x": 0,
            "y": 4,
            "z": 5,
            "elements": [
                "swallowsresourcelibrary:tungstenblock@0"
            ]
        },
        {
            "x": -1,
            "y": 8,
            "z": 5,
            "elements": [
                "chisel:factory1@1"
            ]
        },
        {
            "x": -1,
            "y": 5,
            "z": 7,
            "elements": [
                "minecraft:stained_glass_pane@11"
            ]
        },
        {
            "x": -1,
            "y": 5,
            "z": 6,
            "elements": [
                "minecraft:end_rod@1"
            ]
        },
        {
            "x": -1,
            "y": 5,
            "z": 5,
            "elements": [
                "chisel:factory1@1"
            ]
        },
        {
            "x": -1,
            "y": 5,
            "z": 4,
            "elements": [
                "minecraft:end_rod@1"
            ]
        },
        {
            "x": -1,
            "y": 5,
            "z": 3,
            "elements": [
                "minecraft:stained_glass_pane@11"
            ]
        },
        {
            "x": -3,
            "y": 0,
            "z": 2,
            "elements": [
                "appliedenergistics2:smooth_sky_stone_block@0"
            ]
        },
        {
            "x": 0,
            "y": 17,
            "z": 4,
            "elements": [
                "chisel:factory1@1"
            ]
        },
        {
            "x": -3,
            "y": 0,
            "z": 3,
            "elements": [
                "enderio:block_reinforced_obsidian@0"
            ]
        },
        {
            "x": 0,
            "y": 17,
            "z": 5,
            "elements": [
                "swallowsresourcelibrary:tungstenblock@0"
            ]
        },
        {
            "x": -3,
            "y": 0,
            "z": 4,
            "elements": [
                "enderio:block_alloy@0"
            ]
        },
        {
            "x": 0,
            "y": 17,
            "z": 3,
            "elements": [
                "minecraft:stained_glass_pane@11"
            ]
        },
        {
            "x": -3,
            "y": 0,
            "z": 5,
            "elements": [
                "enderio:block_alloy@0"
            ]
        },
        {
            "x": -3,
            "y": 0,
            "z": 6,
            "elements": [
                "enderio:block_alloy@0"
            ]
        },
        {
            "x": -3,
            "y": 0,
            "z": 7,
            "elements": [
                "enderio:block_reinforced_obsidian@0"
            ]
        },
        {
            "x": -1,
            "y": 9,
            "z": 7,
            "elements": [
                "minecraft:stained_glass_pane@11"
            ]
        },
        {
            "x": -3,
            "y": 0,
            "z": 8,
            "elements": [
                "appliedenergistics2:smooth_sky_stone_block@0"
            ]
        },
        {
            "x": -3,
            "y": 0,
            "z": 9,
            "elements": [
                "appliedenergistics2:smooth_sky_stone_stairs@0"
            ]
        },
        {
            "x": -1,
            "y": 9,
            "z": 5,
            "elements": [
                "chisel:factory1@1"
            ]
        },
        {
            "x": 3,
            "y": 1,
            "z": 2,
            "elements": [
                "appliedenergistics2:smooth_sky_stone_stairs@1"
            ]
        },
        {
            "x": -1,
            "y": 9,
            "z": 6,
            "elements": [
                "minecraft:end_rod@1"
            ]
        },
        {
            "x": -1,
            "y": 9,
            "z": 3,
            "elements": [
                "minecraft:stained_glass_pane@11"
            ]
        },
        {
            "x": -1,
            "y": 9,
            "z": 4,
            "elements": [
                "minecraft:end_rod@1"
            ]
        },
        {
            "x": 0,
            "y": 17,
            "z": 6,
            "elements": [
                "chisel:factory1@1"
            ]
        },
        {
            "x": 0,
            "y": 17,
            "z": 7,
            "elements": [
                "minecraft:stained_glass_pane@11"
            ]
        },
        {
            "x": -2,
            "y": 1,
            "z": 6,

            "elements": [
                "modularmachinery:blockcasing@0"
            ]
        },
        {
            "x": -2,
            "y": 1,
            "z": 7,

            "elements": [
                "modularmachinery:blockcasing@0"
            ]
        },
        {
            "x": -2,
            "y": 1,
            "z": 4,

            "elements": [
                "modularmachinery:blockcasing@0"
            ]
        },
        {
            "x": -2,
            "y": 1,
            "z": 5,
            "elements": [
                "swallowsresourcelibrary:tungstenblock@0"
            ]
        },
        {
            "x": -2,
            "y": 1,
            "z": 2,
            "elements": [
                "appliedenergistics2:smooth_sky_stone_stairs@2"
            ]
        },
        {
            "x": -1,
            "y": 16,
            "z": 5,
            "elements": [
                "chisel:factory1@1"
            ]
        },
        {
            "x": -2,
            "y": 1,
            "z": 3,

            "elements": [
                "modularmachinery:blockcasing@0"
            ]
        },
        {
            "x": -1,
            "y": 16,
            "z": 4,
            "elements": [
                "chisel:factory1@1"
            ]
        },
        {
            "x": -1,
            "y": 16,
            "z": 6,
            "elements": [
                "chisel:factory1@1"
            ]
        },
        {
            "x": -2,
            "y": 1,
            "z": 8,
            "elements": [
                "appliedenergistics2:smooth_sky_stone_stairs@3"
            ]
        },
        {
            "x": -3,
            "y": 0,
            "z": 1,
            "elements": [
                "appliedenergistics2:smooth_sky_stone_stairs@0"
            ]
        },
        {
            "x": -1,
            "y": 3,
            "z": 4,
            "elements": [
                "minecraft:end_rod@1"
            ]
        },
        {
            "x": -1,
            "y": 3,
            "z": 3,
            "elements": [
                "minecraft:stained_glass_pane@11"
            ]
        },
        {
            "x": 3,
            "y": 1,
            "z": 7,
            "elements": [
                "appliedenergistics2:smooth_sky_stone_stairs@1"
            ]
        },
        {
            "x": 3,
            "y": 1,
            "z": 8,
            "elements": [
                "appliedenergistics2:smooth_sky_stone_stairs@3"
            ]
        },
        {
            "x": 3,
            "y": 1,
            "z": 5,

            "elements": [
                "modularmachinery:blockcasing@0"
            ]
        },
        {
            "x": 3,
            "y": 1,
            "z": 6,

            "elements": [
                "modularmachinery:blockcasing@0"
            ]
        },
        {
            "x": -1,
            "y": 3,
            "z": 7,
            "elements": [
                "minecraft:stained_glass_pane@11"
            ]
        },
        {
            "x": 3,
            "y": 1,
            "z": 3,
            "elements": [
                "appliedenergistics2:smooth_sky_stone_stairs@1"
            ]
        },
        {
            "x": -1,
            "y": 3,
            "z": 6,
            "elements": [
                "minecraft:end_rod@1"
            ]
        },
        {
            "x": 3,
            "y": 1,
            "z": 4,

            "elements": [
                "modularmachinery:blockcasing@0"
            ]
        },
        {
            "x": -1,
            "y": 3,
            "z": 5,
            "elements": [
                "chisel:factory1@1"
            ]
        },
        {
            "x": -2,
            "y": 7,
            "z": 6,
            "elements": [
                "minecraft:stained_glass_pane@11"
            ]
        },
        {
            "x": -2,
            "y": 7,
            "z": 5,
            "elements": [
                "minecraft:stained_glass_pane@11"
            ]
        },
        {
            "x": -2,
            "y": 7,
            "z": 4,
            "elements": [
                "minecraft:stained_glass_pane@11"
            ]
        },
        {
            "x": -1,
            "y": 15,
            "z": 6,
            "elements": [
                "minecraft:end_rod@1"
            ]
        },
        {
            "x": -1,
            "y": 15,
            "z": 5,
            "elements": [
                "chisel:factory1@1"
            ]
        },
        {
            "x": -1,
            "y": 15,
            "z": 7,
            "elements": [
                "minecraft:stained_glass_pane@11"
            ]
        },
        {
            "x": 0,
            "y": 11,
            "z": 7,
            "elements": [
                "minecraft:stained_glass_pane@11"
            ]
        },
        {
            "x": 0,
            "y": 11,
            "z": 6,
            "elements": [
                "chisel:factory1@1"
            ]
        },
        {
            "x": -1,
            "y": 15,
            "z": 4,
            "elements": [
                "minecraft:end_rod@1"
            ]
        },
        {
            "x": 0,
            "y": 11,
            "z": 5,
            "elements": [
                "swallowsresourcelibrary:tungstenblock@0"
            ]
        },
        {
            "x": -1,
            "y": 15,
            "z": 3,
            "elements": [
                "minecraft:stained_glass_pane@11"
            ]
        },
        {
            "x": 0,
            "y": 11,
            "z": 4,
            "elements": [
                "chisel:factory1@1"
            ]
        },
        {
            "x": 0,
            "y": 11,
            "z": 3,
            "elements": [
                "minecraft:stained_glass_pane@11"
            ]
        },
        {
            "x": 0,
            "y": 5,
            "z": 3,
            "elements": [
                "minecraft:stained_glass_pane@11"
            ]
        },
        {
            "x": 0,
            "y": 5,
            "z": 4,
            "elements": [
                "chisel:factory1@1"
            ]
        },
        {
            "x": 0,
            "y": 5,
            "z": 5,
            "elements": [
                "swallowsresourcelibrary:tungstenblock@0"
            ]
        },
        {
            "x": 0,
            "y": 5,
            "z": 6,
            "elements": [
                "chisel:factory1@1"
            ]
        },
        {
            "x": 0,
            "y": 5,
            "z": 7,
            "elements": [
                "minecraft:stained_glass_pane@11"
            ]
        },
        {
            "x": 0,
            "y": 12,
            "z": 6,
            "elements": [
                "chisel:factory1@1"
            ]
        },
        {
            "x": 0,
            "y": 12,
            "z": 5,
            "elements": [
                "swallowsresourcelibrary:tungstenblock@0"
            ]
        },
        {
            "x": 0,
            "y": 12,
            "z": 4,
            "elements": [
                "chisel:factory1@1"
            ]
        },
        {
            "x": 1,
            "y": 20,
            "z": 6,
            "elements": [
                "minecraft:stained_glass_pane@11"
            ]
        },
        {
            "x": 1,
            "y": 20,
            "z": 4,
            "elements": [
                "minecraft:stained_glass_pane@11"
            ]
        },
        {
            "x": 1,
            "y": 20,
            "z": 5,
            "elements": [
                "chisel:factory1@1"
            ]
        },
        {
            "x": -2,
            "y": 13,
            "z": 4,
            "elements": [
                "minecraft:stained_glass_pane@11"
            ]
        },
        {
            "x": -2,
            "y": 13,
            "z": 5,
            "elements": [
                "minecraft:stained_glass_pane@11"
            ]
        },
        {
            "x": -2,
            "y": 13,
            "z": 6,
            "elements": [
                "minecraft:stained_glass_pane@11"
            ]
        },
        {
            "x": -1,
            "y": 4,
            "z": 6,
            "elements": [
                "chisel:factory1@1"
            ]
        },
        {
            "x": -1,
            "y": 4,
            "z": 5,
            "elements": [
                "chisel:factory1@1"
            ]
        },
        {
            "x": -1,
            "y": 4,
            "z": 4,
            "elements": [
                "chisel:factory1@1"
            ]
        },
        {
            "x": 0,
            "y": 6,
            "z": 5,
            "elements": [
                "swallowsresourcelibrary:tungstenblock@0"
            ]
        },
        {
            "x": 0,
            "y": 6,
            "z": 6,
            "elements": [
                "chisel:factory1@1"
            ]
        },
        {
            "x": 0,
            "y": 6,
            "z": 4,
            "elements": [
                "chisel:factory1@1"
            ]
        },
        {
            "x": -1,
            "y": 10,
            "z": 6,
            "elements": [
                "chisel:factory1@1"
            ]
        },
        {
            "x": 3,
            "y": 0,
            "z": 6,
            "elements": [
                "enderio:block_alloy@0"
            ]
        },
        {
            "x": 3,
            "y": 0,
            "z": 7,
            "elements": [
                "enderio:block_reinforced_obsidian@0"
            ]
        },
        {
            "x": 3,
            "y": 0,
            "z": 4,
            "elements": [
                "enderio:block_alloy@0"
            ]
        },
        {
            "x": 3,
            "y": 0,
            "z": 5,
            "elements": [
                "enderio:block_alloy@0"
            ]
        },
        {
            "x": -1,
            "y": 10,
            "z": 4,
            "elements": [
                "chisel:factory1@1"
            ]
        },
        {
            "x": -1,
            "y": 10,
            "z": 5,
            "elements": [
                "chisel:factory1@1"
            ]
        },
        {
            "x": 3,
            "y": 0,
            "z": 8,
            "elements": [
                "appliedenergistics2:smooth_sky_stone_block@0"
            ]
        },
        {
            "x": 3,
            "y": 0,
            "z": 9,
            "elements": [
                "appliedenergistics2:smooth_sky_stone_stairs@1"
            ]
        },
        {
            "x": 1,
            "y": 14,
            "z": 5,
            "elements": [
                "chisel:factory1@1"
            ]
        },
        {
            "x": 1,
            "y": 14,
            "z": 4,
            "elements": [
                "chisel:factory1@1"
            ]
        },
        {
            "x": 1,
            "y": 14,
            "z": 6,
            "elements": [
                "chisel:factory1@1"
            ]
        },
        {
            "x": 3,
            "y": 0,
            "z": 2,
            "elements": [
                "appliedenergistics2:smooth_sky_stone_block@0"
            ]
        },
        {
            "x": 3,
            "y": 0,
            "z": 3,
            "elements": [
                "enderio:block_reinforced_obsidian@0"
            ]
        },
        {
            "x": 0,
            "y": 18,
            "z": 4,
            "elements": [
                "chisel:factory1@1"
            ]
        },
        {
            "x": 3,
            "y": 0,
            "z": 1,
            "elements": [
                "appliedenergistics2:smooth_sky_stone_stairs@1"
            ]
        },
        {
            "x": 1,
            "y": 8,
            "z": 4,
            "elements": [
                "chisel:factory1@1"
            ]
        },
        {
            "x": 1,
            "y": 8,
            "z": 5,
            "elements": [
                "chisel:factory1@1"
            ]
        },
        {
            "x": 0,
            "y": 18,
            "z": 5,
            "elements": [
                "swallowsresourcelibrary:tungstenblock@0"
            ]
        },
        {
            "x": 0,
            "y": 18,
            "z": 6,
            "elements": [
                "chisel:factory1@1"
            ]
        },
        {
            "x": 1,
            "y": 15,
            "z": 4,
            "elements": [
                "minecraft:end_rod@1"
            ]
        },
        {
            "x": 1,
            "y": 15,
            "z": 3,
            "elements": [
                "minecraft:stained_glass_pane@11"
            ]
        },
        {
            "x": 1,
            "y": 15,
            "z": 6,
            "elements": [
                "minecraft:end_rod@1"
            ]
        },
        {
            "x": 1,
            "y": 15,
            "z": 5,
            "elements": [
                "chisel:factory1@1"
            ]
        },
        {
            "x": 2,
            "y": 3,
            "z": 6,
            "elements": [
                "minecraft:stained_glass_pane@11"
            ]
        },
        {
            "x": -2,
            "y": 11,
            "z": 6,
            "elements": [
                "minecraft:stained_glass_pane@11"
            ]
        },
        {
            "x": 2,
            "y": 3,
            "z": 4,
            "elements": [
                "minecraft:stained_glass_pane@11"
            ]
        },
        {
            "x": 2,
            "y": 3,
            "z": 5,
            "elements": [
                "minecraft:stained_glass_pane@11"
            ]
        },
        {
            "x": 0,
            "y": 14,
            "z": 4,
            "elements": [
                "chisel:factory1@1"
            ]
        },
        {
            "x": 1,
            "y": 15,
            "z": 7,
            "elements": [
                "minecraft:stained_glass_pane@11"
            ]
        },
        {
            "x": 0,
            "y": 0,
            "z": 8,
            "elements": [
                "enderio:block_alloy@0"
            ]
        },
        {
            "x": 0,
            "y": 0,
            "z": 7,
            "elements": [
                "mekanism:basicblock@8"
            ]
        },
        {
            "x": 0,
            "y": 14,
            "z": 6,
            "elements": [
                "chisel:factory1@1"
            ]
        },
        {
            "x": 0,
            "y": 0,
            "z": 10,
            "elements": [
                "modularmachinery:blockcasing@0",
                "ItemInput",
                "ItemOutput",
                "FluidInput",
                "FluidOutput",
                "EnergyInput"
            ]
        },
        {
            "x": 0,
            "y": 14,
            "z": 5,
            "elements": [
                "swallowsresourcelibrary:tungstenblock@0"
            ]
        },
        {
            "x": 0,
            "y": 0,
            "z": 9,
            "elements": [
                "enderio:block_reinforced_obsidian@0"
            ]
        },
        {
            "x": 0,
            "y": 0,
            "z": 4,
            "elements": [
                "mekanism:basicblock@8"
            ]
        },
        {
            "x": 0,
            "y": 0,
            "z": 3,
            "elements": [
                "mekanism:basicblock@8"
            ]
        },
        {
            "x": 0,
            "y": 0,
            "z": 6,
            "elements": [
                "mekanism:basicblock@8"
            ]
        },
        {
            "x": 0,
            "y": 0,
            "z": 5,
            "elements": [
                "enderio:block_alloy@0"
            ]
        },
        {
            "x": 0,
            "y": 0,
            "z": 0,

            "elements": [
                "modularmachinery:ymg_gemini_frost_controller@2"
            ]
        },
        {
            "x": 1,
            "y": 2,
            "z": 6,
            "elements": [
                "chisel:factory1@1"
            ]
        },
        {
            "x": 0,
            "y": 0,
            "z": 2,
            "elements": [
                "enderio:block_alloy@0"
            ]
        },
        {
            "x": 1,
            "y": 2,
            "z": 5,
            "elements": [
                "chisel:factory1@1"
            ]
        },
        {
            "x": 0,
            "y": 0,
            "z": 1,
            "elements": [
                "enderio:block_reinforced_obsidian@0"
            ]
        },
        {
            "x": 1,
            "y": 2,
            "z": 4,
            "elements": [
                "chisel:factory1@1"
            ]
        },
        {
            "x": -2,
            "y": 11,
            "z": 4,
            "elements": [
                "minecraft:stained_glass_pane@11"
            ]
        },
        {
            "x": 0,
            "y": 13,
            "z": 7,
            "elements": [
                "minecraft:stained_glass_pane@11"
            ]
        },
        {
            "x": -2,
            "y": 11,
            "z": 5,
            "elements": [
                "minecraft:stained_glass_pane@11"
            ]
        },
        {
            "x": 0,
            "y": 13,
            "z": 6,
            "elements": [
                "chisel:factory1@1"
            ]
        },
        {
            "x": 0,
            "y": 13,
            "z": 5,
            "elements": [
                "swallowsresourcelibrary:tungstenblock@0"
            ]
        },
        {
            "x": 0,
            "y": 13,
            "z": 4,
            "elements": [
                "chisel:factory1@1"
            ]
        },
        {
            "x": 0,
            "y": 13,
            "z": 3,
            "elements": [
                "minecraft:stained_glass_pane@11"
            ]
        },
        {
            "x": 2,
            "y": 17,
            "z": 6,
            "elements": [
                "minecraft:stained_glass_pane@11"
            ]
        },
        {
            "x": 2,
            "y": 17,
            "z": 4,
            "elements": [
                "minecraft:stained_glass_pane@11"
            ]
        },
        {
            "x": 2,
            "y": 17,
            "z": 5,
            "elements": [
                "minecraft:stained_glass_pane@11"
            ]
        },
        {
            "x": 1,
            "y": 1,
            "z": 4,
            "elements": [
                "swallowsresourcelibrary:tungstenblock@0"
            ]
        },
        {
            "x": 1,
            "y": 1,
            "z": 3,

            "elements": [
                "modularmachinery:blockcasing@0"
            ]
        },
        {
            "x": 1,
            "y": 1,
            "z": 2,

            "elements": [
                "modularmachinery:blockcasing@0"
            ]
        },
        {
            "x": 1,
            "y": 1,
            "z": 1,
            "elements": [
                "appliedenergistics2:smooth_sky_stone_stairs@2"
            ]
        },
        {
            "x": 1,
            "y": 1,
            "z": 8,

            "elements": [
                "modularmachinery:blockcasing@0"
            ]
        },
        {
            "x": 1,
            "y": 1,
            "z": 7,

            "elements": [
                "modularmachinery:blockcasing@0"
            ]
        },
        {
            "x": 1,
            "y": 1,
            "z": 6,
            "elements": [
                "swallowsresourcelibrary:tungstenblock@0"
            ]
        },
        {
            "x": 1,
            "y": 1,
            "z": 5,
            "elements": [
                "swallowsresourcelibrary:tungstenblock@0"
            ]
        },
        {
            "x": 1,
            "y": 1,
            "z": 9,
            "elements": [
                "appliedenergistics2:smooth_sky_stone_stairs@3"
            ]
        },
        {
            "x": -1,
            "y": 12,
            "z": 6,
            "elements": [
                "chisel:factory1@1"
            ]
        },
        {
            "x": -1,
            "y": 12,
            "z": 4,
            "elements": [
                "chisel:factory1@1"
            ]
        },
        {
            "x": -1,
            "y": 12,
            "z": 5,
            "elements": [
                "chisel:factory1@1"
            ]
        },
        {
            "x": 1,
            "y": 0,
            "z": 5,
            "elements": [
                "mekanism:basicblock@8"
            ]
        },
        {
            "x": 1,
            "y": 0,
            "z": 4,
            "elements": [
                "mekanism:basicblock@8"
            ]
        },
        {
            "x": 1,
            "y": 0,
            "z": 3,
            "elements": [
                "enderio:block_alloy@0"
            ]
        },
        {
            "x": 1,
            "y": 0,
            "z": 2,
            "elements": [
                "enderio:block_alloy@0"
            ]
        },
        {
            "x": 1,
            "y": 0,
            "z": 1,
            "elements": [
                "enderio:block_reinforced_obsidian@0"
            ]
        },
        {
            "x": 1,
            "y": 0,
            "z": 0,
            "elements": [
                "appliedenergistics2:smooth_sky_stone_stairs@2"
            ]
        },
        {
            "x": -1,
            "y": 14,
            "z": 5,
            "elements": [
                "chisel:factory1@1"
            ]
        },
        {
            "x": -1,
            "y": 14,
            "z": 4,
            "elements": [
                "chisel:factory1@1"
            ]
        },
        {
            "x": 1,
            "y": 0,
            "z": 10,
            "elements": [
                "appliedenergistics2:smooth_sky_stone_stairs@3"
            ]
        },
        {
            "x": 1,
            "y": 0,
            "z": 9,
            "elements": [
                "enderio:block_reinforced_obsidian@0"
            ]
        },
        {
            "x": -1,
            "y": 14,
            "z": 6,
            "elements": [
                "chisel:factory1@1"
            ]
        },
        {
            "x": 1,
            "y": 0,
            "z": 8,
            "elements": [
                "enderio:block_alloy@0"
            ]
        },
        {
            "x": 1,
            "y": 0,
            "z": 7,
            "elements": [
                "enderio:block_alloy@0"
            ]
        },
        {
            "x": 1,
            "y": 0,
            "z": 6,
            "elements": [
                "mekanism:basicblock@8"
            ]
        },
        {
            "x": -1,
            "y": 11,
            "z": 3,
            "elements": [
                "minecraft:stained_glass_pane@11"
            ]
        },
        {
            "x": -1,
            "y": 11,
            "z": 4,
            "elements": [
                "minecraft:end_rod@1"
            ]
        },
        {
            "x": 1,
            "y": 3,
            "z": 5,
            "elements": [
                "chisel:factory1@1"
            ]
        },
        {
            "x": 1,
            "y": 3,
            "z": 6,
            "elements": [
                "minecraft:end_rod@1"
            ]
        },
        {
            "x": 1,
            "y": 3,
            "z": 3,
            "elements": [
                "minecraft:stained_glass_pane@11"
            ]
        },
        {
            "x": 1,
            "y": 3,
            "z": 4,
            "elements": [
                "minecraft:end_rod@1"
            ]
        },
        {
            "x": -1,
            "y": 11,
            "z": 7,
            "elements": [
                "minecraft:stained_glass_pane@11"
            ]
        },
        {
            "x": -1,
            "y": 11,
            "z": 5,
            "elements": [
                "chisel:factory1@1"
            ]
        },
        {
            "x": 1,
            "y": 3,
            "z": 7,
            "elements": [
                "minecraft:stained_glass_pane@11"
            ]
        },
        {
            "x": -1,
            "y": 11,
            "z": 6,
            "elements": [
                "minecraft:end_rod@1"
            ]
        },
        {
            "x": -2,
            "y": 0,
            "z": 3,
            "elements": [
                "enderio:block_alloy@0"
            ]
        },
        {
            "x": 2,
            "y": 5,
            "z": 4,
            "elements": [
                "minecraft:stained_glass_pane@11"
            ]
        },
        {
            "x": -2,
            "y": 0,
            "z": 4,
            "elements": [
                "enderio:block_alloy@0"
            ]
        },
        {
            "x": 2,
            "y": 5,
            "z": 5,
            "elements": [
                "minecraft:stained_glass_pane@11"
            ]
        },
        {
            "x": -2,
            "y": 0,
            "z": 1,
            "elements": [
                "modularmachinery:blockcasing@0",
                "ItemInput",
                "ItemOutput",
                "FluidInput",
                "FluidOutput",
                "EnergyInput"
            ]
        },
        {
            "x": 2,
            "y": 5,
            "z": 6,
            "elements": [
                "minecraft:stained_glass_pane@11"
            ]
        },
        {
            "x": -2,
            "y": 0,
            "z": 2,
            "elements": [
                "enderio:block_reinforced_obsidian@0"
            ]
        },
        {
            "x": 2,
            "y": 15,
            "z": 4,
            "elements": [
                "minecraft:stained_glass_pane@11"
            ]
        },
        {
            "x": -2,
            "y": 0,
            "z": 7,
            "elements": [
                "enderio:block_alloy@0"
            ]
        },
        {
            "x": 2,
            "y": 15,
            "z": 5,
            "elements": [
                "minecraft:stained_glass_pane@11"
            ]
        },
        {
            "x": -2,
            "y": 0,
            "z": 8,
            "elements": [
                "enderio:block_reinforced_obsidian@0"
            ]
        },
        {
            "x": -2,
            "y": 0,
            "z": 5,
            "elements": [
                "mekanism:basicblock@8"
            ]
        },
        {
            "x": -2,
            "y": 0,
            "z": 6,
            "elements": [
                "enderio:block_alloy@0"
            ]
        },
        {
            "x": 1,
            "y": 13,
            "z": 4,
            "elements": [
                "minecraft:end_rod@1"
            ]
        },
        {
            "x": 2,
            "y": 15,
            "z": 6,
            "elements": [
                "minecraft:stained_glass_pane@11"
            ]
        },
        {
            "x": 1,
            "y": 13,
            "z": 3,
            "elements": [
                "minecraft:stained_glass_pane@11"
            ]
        },
        {
            "x": 1,
            "y": 13,
            "z": 6,
            "elements": [
                "minecraft:end_rod@1"
            ]
        },
        {
            "x": 1,
            "y": 13,
            "z": 5,
            "elements": [
                "chisel:factory1@1"
            ]
        },
        {
            "x": 1,
            "y": 13,
            "z": 7,
            "elements": [
                "minecraft:stained_glass_pane@11"
            ]
        },
        {
            "x": 1,
            "y": 16,
            "z": 4,
            "elements": [
                "chisel:factory1@1"
            ]
        },
        {
            "x": 1,
            "y": 16,
            "z": 5,
            "elements": [
                "chisel:factory1@1"
            ]
        },
        {
            "x": -2,
            "y": 0,
            "z": 9,
            "elements": [
                "modularmachinery:blockcasing@0",
                "ItemInput",
                "ItemOutput",
                "FluidInput",
                "FluidOutput",
                "EnergyInput"
            ]
        },
        {
            "x": 1,
            "y": 16,
            "z": 6,
            "elements": [
                "chisel:factory1@1"
            ]
        },
        {
            "x": -1,
            "y": 2,
            "z": 6,
            "elements": [
                "chisel:factory1@1"
            ]
        },
        {
            "x": -1,
            "y": 2,
            "z": 5,
            "elements": [
                "chisel:factory1@1"
            ]
        },
        {
            "x": -1,
            "y": 2,
            "z": 4,
            "elements": [
                "chisel:factory1@1"
            ]
        },
        {
            "x": 0,
            "y": 1,
            "z": 7,
            "elements": [
                "swallowsresourcelibrary:tungstenblock@0"
            ]
        },
        {
            "x": 0,
            "y": 1,
            "z": 6,
            "elements": [
                "swallowsresourcelibrary:tungstenblock@0"
            ]
        },
        {
            "x": 0,
            "y": 1,
            "z": 9,
            "elements": [
                "appliedenergistics2:smooth_sky_stone_stairs@3"
            ]
        },
        {
            "x": 0,
            "y": 1,
            "z": 8,

            "elements": [
                "modularmachinery:blockcasing@0"
            ]
        },
        {
            "x": 0,
            "y": 1,
            "z": 10,
            "elements": [
                "appliedenergistics2:smooth_sky_stone_slab@0"
            ]
        },
        {
            "x": -2,
            "y": 9,
            "z": 4,
            "elements": [
                "minecraft:stained_glass_pane@11"
            ]
        },
        {
            "x": -2,
            "y": 9,
            "z": 5,
            "elements": [
                "minecraft:stained_glass_pane@11"
            ]
        },
        {
            "x": 0,
            "y": 1,
            "z": 1,
            "elements": [
                "appliedenergistics2:smooth_sky_stone_stairs@2"
            ]
        },
        {
            "x": -2,
            "y": 9,
            "z": 6,
            "elements": [
                "minecraft:stained_glass_pane@11"
            ]
        },
        {
            "x": 0,
            "y": 1,
            "z": 0,
            "elements": [
                "appliedenergistics2:smooth_sky_stone_slab@0"
            ]
        },
        {
            "x": 0,
            "y": 1,
            "z": 3,
            "elements": [
                "swallowsresourcelibrary:tungstenblock@0"
            ]
        },
        {
            "x": 0,
            "y": 1,
            "z": 2,

            "elements": [
                "modularmachinery:blockcasing@0"
            ]
        },
        {
            "x": 0,
            "y": 1,
            "z": 5,
            "elements": [
                "swallowsresourcelibrary:tungstenblock@0"
            ]
        },
        {
            "x": 0,
            "y": 1,
            "z": 4,
            "elements": [
                "swallowsresourcelibrary:tungstenblock@0"
            ]
        },
        {
            "x": 1,
            "y": 5,
            "z": 3,
            "elements": [
                "minecraft:stained_glass_pane@11"
            ]
        },
        {
            "x": 1,
            "y": 5,
            "z": 4,
            "elements": [
                "minecraft:end_rod@1"
            ]
        },
        {
            "x": 1,
            "y": 5,
            "z": 7,
            "elements": [
                "minecraft:stained_glass_pane@11"
            ]
        },
        {
            "x": 1,
            "y": 5,
            "z": 5,
            "elements": [
                "chisel:factory1@1"
            ]
        },
        {
            "x": 1,
            "y": 5,
            "z": 6,
            "elements": [
                "minecraft:end_rod@1"
            ]
        },
        {
            "x": 2,
            "y": 13,
            "z": 6,
            "elements": [
                "minecraft:stained_glass_pane@11"
            ]
        },
        {
            "x": 2,
            "y": 13,
            "z": 5,
            "elements": [
                "minecraft:stained_glass_pane@11"
            ]
        },
        {
            "x": 2,
            "y": 13,
            "z": 4,
            "elements": [
                "minecraft:stained_glass_pane@11"
            ]
        },
        {
            "x": 1,
            "y": 12,
            "z": 6,
            "elements": [
                "chisel:factory1@1"
            ]
        },
        {
            "x": 0,
            "y": 10,
            "z": 4,
            "elements": [
                "chisel:factory1@1"
            ]
        },
        {
            "x": 1,
            "y": 12,
            "z": 5,
            "elements": [
                "chisel:factory1@1"
            ]
        },
        {
            "x": 1,
            "y": 12,
            "z": 4,
            "elements": [
                "chisel:factory1@1"
            ]
        },
        {
            "x": 0,
            "y": 10,
            "z": 5,
            "elements": [
                "swallowsresourcelibrary:tungstenblock@0"
            ]
        },
        {
            "x": 0,
            "y": 10,
            "z": 6,
            "elements": [
                "chisel:factory1@1"
            ]
        },
        {
            "x": 2,
            "y": 19,
            "z": 4,
            "elements": [
                "minecraft:stained_glass_pane@11"
            ]
        },
        {
            "x": 2,
            "y": 19,
            "z": 5,
            "elements": [
                "minecraft:stained_glass_pane@11"
            ]
        },
        {
            "x": 2,
            "y": 19,
            "z": 6,
            "elements": [
                "minecraft:stained_glass_pane@11"
            ]
        },
        {
            "x": 0,
            "y": 3,
            "z": 3,
            "elements": [
                "minecraft:stained_glass_pane@11"
            ]
        },
        {
            "x": 0,
            "y": 3,
            "z": 5,
            "elements": [
                "swallowsresourcelibrary:tungstenblock@0"
            ]
        },
        {
            "x": 0,
            "y": 3,
            "z": 4,
            "elements": [
                "chisel:factory1@1"
            ]
        },
        {
            "x": 0,
            "y": 3,
            "z": 7,
            "elements": [
                "minecraft:stained_glass_pane@11"
            ]
        },
        {
            "x": 0,
            "y": 3,
            "z": 6,
            "elements": [
                "chisel:factory1@1"
            ]
        },
        {
            "x": 0,
            "y": 16,
            "z": 6,
            "elements": [
                "chisel:factory1@1"
            ]
        },
        {
            "x": 0,
            "y": 16,
            "z": 5,
            "elements": [
                "swallowsresourcelibrary:tungstenblock@0"
            ]
        },
        {
            "x": 0,
            "y": 16,
            "z": 4,
            "elements": [
                "chisel:factory1@1"
            ]
        },
        {
            "x": 2,
            "y": 0,
            "z": 6,
            "elements": [
                "enderio:block_alloy@0"
            ]
        },
        {
            "x": 2,
            "y": 0,
            "z": 5,
            "elements": [
                "mekanism:basicblock@8"
            ]
        },
        {
            "x": 2,
            "y": 0,
            "z": 8,
            "elements": [
                "enderio:block_reinforced_obsidian@0"
            ]
        },
        {
            "x": 2,
            "y": 0,
            "z": 7,
            "elements": [
                "enderio:block_alloy@0"
            ]
        },
        {
            "x": 2,
            "y": 0,
            "z": 9,
            "elements": [
                "modularmachinery:blockcasing@0",
                "ItemInput",
                "ItemOutput",
                "FluidInput",
                "FluidOutput",
                "EnergyInput"
            ]
        },
        {
            "x": -1,
            "y": 1,
            "z": 9,
            "elements": [
                "appliedenergistics2:smooth_sky_stone_stairs@3"
            ]
        },
        {
            "x": -1,
            "y": 1,
            "z": 8,

            "elements": [
                "modularmachinery:blockcasing@0"
            ]
        },
        {
            "x": -1,
            "y": 1,
            "z": 7,

            "elements": [
                "modularmachinery:blockcasing@0"
            ]
        },
        {
            "x": 1,
            "y": 18,
            "z": 4,
            "elements": [
                "chisel:factory1@1"
            ]
        },
        {
            "x": 1,
            "y": 18,
            "z": 5,
            "elements": [
                "chisel:factory1@1"
            ]
        },
        {
            "x": 1,
            "y": 18,
            "z": 6,
            "elements": [
                "chisel:factory1@1"
            ]
        },
        {
            "x": 1,
            "y": 4,
            "z": 6,
            "elements": [
                "chisel:factory1@1"
            ]
        },
        {
            "x": 2,
            "y": 0,
            "z": 2,
            "elements": [
                "enderio:block_reinforced_obsidian@0"
            ]
        },
        {
            "x": 1,
            "y": 4,
            "z": 4,
            "elements": [
                "chisel:factory1@1"
            ]
        },
        {
            "x": 2,
            "y": 0,
            "z": 1,
            "elements": [
                "modularmachinery:blockcasing@0",
                "ItemInput",
                "ItemOutput",
                "FluidInput",
                "FluidOutput",
                "EnergyInput"
            ]
        },
        {
            "x": 1,
            "y": 4,
            "z": 5,
            "elements": [
                "chisel:factory1@1"
            ]
        },
        {
            "x": 2,
            "y": 0,
            "z": 4,
            "elements": [
                "enderio:block_alloy@0"
            ]
        },
        {
            "x": 2,
            "y": 0,
            "z": 3,
            "elements": [
                "enderio:block_alloy@0"
            ]
        },
        {
            "x": 0,
            "y": 2,
            "z": 6,
            "elements": [
                "chisel:factory1@1"
            ]
        },
        {
            "x": 0,
            "y": 2,
            "z": 5,
            "elements": [
                "swallowsresourcelibrary:tungstenblock@0"
            ]
        },
        {
            "x": -1,
            "y": 1,
            "z": 6,
            "elements": [
                "swallowsresourcelibrary:tungstenblock@0"
            ]
        },
        {
            "x": 2,
            "y": 1,
            "z": 8,
            "elements": [
                "appliedenergistics2:smooth_sky_stone_stairs@3"
            ]
        },
        {
            "x": -1,
            "y": 1,
            "z": 5,
            "elements": [
                "swallowsresourcelibrary:tungstenblock@0"
            ]
        },
        {
            "x": -1,
            "y": 1,
            "z": 4,
            "elements": [
                "swallowsresourcelibrary:tungstenblock@0"
            ]
        },
        {
            "x": -1,
            "y": 1,
            "z": 3,

            "elements": [
                "modularmachinery:blockcasing@0"
            ]
        },
        {
            "x": -1,
            "y": 1,
            "z": 2,

            "elements": [
                "modularmachinery:blockcasing@0"
            ]
        },
        {
            "x": 2,
            "y": 1,
            "z": 4,

            "elements": [
                "modularmachinery:blockcasing@0"
            ]
        },
        {
            "x": -1,
            "y": 1,
            "z": 1,
            "elements": [
                "appliedenergistics2:smooth_sky_stone_stairs@2"
            ]
        },
        {
            "x": 0,
            "y": 9,
            "z": 3,
            "elements": [
                "minecraft:stained_glass_pane@11"
            ]
        },
        {
            "x": 2,
            "y": 1,
            "z": 5,
            "elements": [
                "swallowsresourcelibrary:tungstenblock@0"
            ]
        },
        {
            "x": 0,
            "y": 9,
            "z": 4,
            "elements": [
                "chisel:factory1@1"
            ]
        },
        {
            "x": 2,
            "y": 1,
            "z": 6,

            "elements": [
                "modularmachinery:blockcasing@0"
            ]
        },
        {
            "x": 0,
            "y": 9,
            "z": 5,
            "elements": [
                "swallowsresourcelibrary:tungstenblock@0"
            ]
        },
        {
            "x": 2,
            "y": 1,
            "z": 7,

            "elements": [
                "modularmachinery:blockcasing@0"
            ]
        },
        {
            "x": 2,
            "y": 1,
            "z": 2,
            "elements": [
                "appliedenergistics2:smooth_sky_stone_stairs@2"
            ]
        },
        {
            "x": 0,
            "y": 2,
            "z": 4,
            "elements": [
                "chisel:factory1@1"
            ]
        },
        {
            "x": 2,
            "y": 1,
            "z": 3,

            "elements": [
                "modularmachinery:blockcasing@0"
            ]
        },
        {
            "x": 1,
            "y": 17,
            "z": 3,
            "elements": [
                "minecraft:stained_glass_pane@11"
            ]
        },
        {
            "x": 1,
            "y": 17,
            "z": 4,
            "elements": [
                "minecraft:end_rod@1"
            ]
        },
        {
            "x": -1,
            "y": 7,
            "z": 7,
            "elements": [
                "minecraft:stained_glass_pane@11"
            ]
        },
        {
            "x": -1,
            "y": 7,
            "z": 5,
            "elements": [
                "chisel:factory1@1"
            ]
        },
        {
            "x": -1,
            "y": 7,
            "z": 6,
            "elements": [
                "minecraft:end_rod@1"
            ]
        },
        {
            "x": -1,
            "y": 7,
            "z": 3,
            "elements": [
                "minecraft:stained_glass_pane@11"
            ]
        },
        {
            "x": -1,
            "y": 7,
            "z": 4,
            "elements": [
                "minecraft:end_rod@1"
            ]
        },
        {
            "x": 0,
            "y": 9,
            "z": 6,
            "elements": [
                "chisel:factory1@1"
            ]
        },
        {
            "x": 0,
            "y": 9,
            "z": 7,
            "elements": [
                "minecraft:stained_glass_pane@11"
            ]
        },
        {
            "x": -1,
            "y": 0,
            "z": 3,
            "elements": [
                "enderio:block_alloy@0"
            ]
        },
        {
            "x": -1,
            "y": 0,
            "z": 2,
            "elements": [
                "enderio:block_alloy@0"
            ]
        },
        {
            "x": -1,
            "y": 0,
            "z": 1,
            "elements": [
                "enderio:block_reinforced_obsidian@0"
            ]
        },
        {
            "x": -1,
            "y": 0,
            "z": 0,
            "elements": [
                "appliedenergistics2:smooth_sky_stone_stairs@2"
            ]
        },
        {
            "x": 2,
            "y": 7,
            "z": 6,
            "elements": [
                "minecraft:stained_glass_pane@11"
            ]
        },
        {
            "x": -1,
            "y": 0,
            "z": 7,
            "elements": [
                "enderio:block_alloy@0"
            ]
        },
        {
            "x": -1,
            "y": 0,
            "z": 6,
            "elements": [
                "mekanism:basicblock@8"
            ]
        },
        {
            "x": -2,
            "y": 17,
            "z": 6,
            "elements": [
                "minecraft:stained_glass_pane@11"
            ]
        },
        {
            "x": -1,
            "y": 0,
            "z": 5,
            "elements": [
                "mekanism:basicblock@8"
            ]
        },
        {
            "x": -2,
            "y": 17,
            "z": 5,
            "elements": [
                "minecraft:stained_glass_pane@11"
            ]
        },
        {
            "x": -1,
            "y": 0,
            "z": 4,
            "elements": [
                "mekanism:basicblock@8"
            ]
        },
        {
            "x": -2,
            "y": 17,
            "z": 4,
            "elements": [
                "minecraft:stained_glass_pane@11"
            ]
        },
        {
            "x": -1,
            "y": 0,
            "z": 10,
            "elements": [
                "appliedenergistics2:smooth_sky_stone_stairs@3"
            ]
        },
        {
            "x": -1,
            "y": 0,
            "z": 9,
            "elements": [
                "enderio:block_reinforced_obsidian@0"
            ]
        },
        {
            "x": -1,
            "y": 0,
            "z": 8,
            "elements": [
                "enderio:block_alloy@0"
            ]
        },
        {
            "x": -1,
            "y": 13,
            "z": 7,
            "elements": [
                "minecraft:stained_glass_pane@11"
            ]
        },
        {
            "x": -1,
            "y": 13,
            "z": 4,
            "elements": [
                "minecraft:end_rod@1"
            ]
        },
        {
            "x": -1,
            "y": 13,
            "z": 3,
            "elements": [
                "minecraft:stained_glass_pane@11"
            ]
        },
        {
            "x": -1,
            "y": 13,
            "z": 6,
            "elements": [
                "minecraft:end_rod@1"
            ]
        },
        {
            "x": -1,
            "y": 13,
            "z": 5,
            "elements": [
                "chisel:factory1@1"
            ]
        },
        {
            "x": 5,
            "y": 1,
            "z": 5,
            "elements": [
                "appliedenergistics2:smooth_sky_stone_slab@0"
            ]
        },
        {
            "x": 1,
            "y": 17,
            "z": 5,
            "elements": [
                "chisel:factory1@1"
            ]
        },
        {
            "x": -4,
            "y": 0,
            "z": 2,
            "elements": [
                "appliedenergistics2:smooth_sky_stone_stairs@2"
            ]
        },
        {
            "x": 1,
            "y": 17,
            "z": 6,
            "elements": [
                "minecraft:end_rod@1"
            ]
        },
        {
            "x": 1,
            "y": 17,
            "z": 7,
            "elements": [
                "minecraft:stained_glass_pane@11"
            ]
        },
        {
            "x": -4,
            "y": 0,
            "z": 7,
            "elements": [
                "modularmachinery:blockcasing@0",
                "ItemInput",
                "ItemOutput",
                "FluidInput",
                "FluidOutput",
                "EnergyInput"
            ]
        },
        {
            "x": -4,
            "y": 0,
            "z": 8,
            "elements": [
                "appliedenergistics2:smooth_sky_stone_stairs@3"
            ]
        },
        {
            "x": -4,
            "y": 0,
            "z": 5,
            "elements": [
                "enderio:block_reinforced_obsidian@0"
            ]
        },
        {
            "x": -4,
            "y": 0,
            "z": 6,
            "elements": [
                "enderio:block_reinforced_obsidian@0"
            ]
        },
        {
            "x": -4,
            "y": 0,
            "z": 3,
            "elements": [
                "modularmachinery:blockcasing@0",
                "ItemInput",
                "ItemOutput",
                "FluidInput",
                "FluidOutput",
                "EnergyInput"
            ]
        },
        {
            "x": -4,
            "y": 0,
            "z": 4,
            "elements": [
                "enderio:block_reinforced_obsidian@0"
            ]
        },
        {
            "x": 1,
            "y": 11,
            "z": 4,
            "elements": [
                "minecraft:end_rod@1"
            ]
        },
        {
            "x": 1,
            "y": 11,
            "z": 3,
            "elements": [
                "minecraft:stained_glass_pane@11"
            ]
        },
        {
            "x": 1,
            "y": 11,
            "z": 6,
            "elements": [
                "minecraft:end_rod@1"
            ]
        },
        {
            "x": 1,
            "y": 11,
            "z": 5,
            "elements": [
                "chisel:factory1@1"
            ]
        },
        {
            "x": 1,
            "y": 11,
            "z": 7,
            "elements": [
                "minecraft:stained_glass_pane@11"
            ]
        },
        {
            "x": 0,
            "y": 15,
            "z": 7,
            "elements": [
                "minecraft:stained_glass_pane@11"
            ]
        },
        {
            "x": 0,
            "y": 15,
            "z": 6,
            "elements": [
                "chisel:factory1@1"
            ]
        },
        {
            "x": -1,
            "y": 19,
            "z": 3,
            "elements": [
                "minecraft:stained_glass_pane@11"
            ]
        },
        {
            "x": 0,
            "y": 15,
            "z": 5,
            "elements": [
                "swallowsresourcelibrary:tungstenblock@0"
            ]
        },
        {
            "x": 0,
            "y": 15,
            "z": 4,
            "elements": [
                "chisel:factory1@1"
            ]
        },
        {
            "x": -1,
            "y": 19,
            "z": 4,
            "elements": [
                "minecraft:end_rod@1"
            ]
        },
        {
            "x": 0,
            "y": 15,
            "z": 3,
            "elements": [
                "minecraft:stained_glass_pane@11"
            ]
        },
        {
            "x": 2,
            "y": 7,
            "z": 5,
            "elements": [
                "minecraft:stained_glass_pane@11"
            ]
        },
        {
            "x": 2,
            "y": 7,
            "z": 4,
            "elements": [
                "minecraft:stained_glass_pane@11"
            ]
        }
    ]}